E1119 15:56:42.078043  127596 scheduler.go:433] scheduler cache AssumePod failed: pod a6940066-ebd0-11e8-8067-000c299a5e15 is in the cache, so can't be assumed
E1119 15:56:42.078047  127596 factory.go:1465] Error scheduling volume-schedulinga42c7715-ebd0-11e8-8067-000c299a5e15/pod-i-pv-prebound-w-provisioned: pod a6940066-ebd0-11e8-8067-000c299a5e15 is in the cache, so can't be assumed; retrying
I1119 15:56:42.078058  127596 factory.go:1558] Updating pod condition for volume-schedulinga42c7715-ebd0-11e8-8067-000c299a5e15/pod-i-pv-prebound-w-provisioned to (PodScheduled==False)
E1119 15:56:42.078063  127596 scheduler.go:556] error assuming pod: pod a6940066-ebd0-11e8-8067-000c299a5e15 is in the cache, so can't be assumed
I1119 15:56:42.079059  127596 factory.go:1338] About to try and schedule pod volume-schedulinga42c7715-ebd0-11e8-8067-000c299a5e15/pod-i-pv-prebound-w-provisioned
I1119 15:56:42.079069  127596 scheduler.go:508] Attempting to schedule pod: volume-schedulinga42c7715-ebd0-11e8-8067-000c299a5e15/pod-i-pv-prebound-w-provisioned
I1119 15:56:42.079124  127596 scheduler_binder.go:147] FindPodVolumes for pod "volume-schedulinga42c7715-ebd0-11e8-8067-000c299a5e15/pod-i-pv-prebound-w-provisioned", node "node-1"
I1119 15:56:42.079155  127596 scheduler_binder.go:458] PVC "volume-schedulinga42c7715-ebd0-11e8-8067-000c299a5e15/pvc-i-pv-prebound" is fully bound to PV "pv-i-prebound"
I1119 15:56:42.079161  127596 scheduler_binder.go:458] PVC "volume-schedulinga42c7715-ebd0-11e8-8067-000c299a5e15/pvc-canprovision" is fully bound to PV "pvc-a693d4b0-ebd0-11e8-8067-000c299a5e15"
I1119 15:56:42.079174  127596 scheduler_binder.go:529] PersistentVolume "pv-i-prebound", Node "node-1" matches for Pod "volume-schedulinga42c7715-ebd0-11e8-8067-000c299a5e15/pod-i-pv-prebound-w-provisioned"
I1119 15:56:42.079178  127596 scheduler_binder.go:529] PersistentVolume "pvc-a693d4b0-ebd0-11e8-8067-000c299a5e15", Node "node-1" matches for Pod "volume-schedulinga42c7715-ebd0-11e8-8067-000c299a5e15/pod-i-pv-prebound-w-provisioned"
I1119 15:56:42.079183  127596 scheduler_binder.go:532] All bound volumes for Pod "volume-schedulinga42c7715-ebd0-11e8-8067-000c299a5e15/pod-i-pv-prebound-w-provisioned" match with Node "node-1"
I1119 15:56:42.079198  127596 scheduler_binder.go:207] AssumePodVolumes for pod "volume-schedulinga42c7715-ebd0-11e8-8067-000c299a5e15/pod-i-pv-prebound-w-provisioned", node "node-1"
I1119 15:56:42.079203  127596 scheduler_binder.go:458] PVC "volume-schedulinga42c7715-ebd0-11e8-8067-000c299a5e15/pvc-i-pv-prebound" is fully bound to PV "pv-i-prebound"
I1119 15:56:42.079207  127596 scheduler_binder.go:458] PVC "volume-schedulinga42c7715-ebd0-11e8-8067-000c299a5e15/pvc-canprovision" is fully bound to PV "pvc-a693d4b0-ebd0-11e8-8067-000c299a5e15"
I1119 15:56:42.079212  127596 scheduler_binder.go:217] AssumePodVolumes for pod "volume-schedulinga42c7715-ebd0-11e8-8067-000c299a5e15/pod-i-pv-prebound-w-provisioned", node "node-1": all PVCs bound and nothing to do
E1119 15:56:42.079217  127596 scheduler.go:433] scheduler cache AssumePod failed: pod a6940066-ebd0-11e8-8067-000c299a5e15 is in the cache, so can't be assumed
E1119 15:56:42.079221  127596 factory.go:1465] Error scheduling volume-schedulinga42c7715-ebd0-11e8-8067-000c299a5e15/pod-i-pv-prebound-w-provisioned: pod a6940066-ebd0-11e8-8067-000c299a5e15 is in the cache, so can't be assumed; retrying
I1119 15:56:42.079232  127596 factory.go:1558] Updating pod condition for volume-schedulinga42c7715-ebd0-11e8-8067-000c299a5e15/pod-i-pv-prebound-w-provisioned to (PodScheduled==False)
E1119 15:56:42.079239  127596 scheduler.go:556] error assuming pod: pod a6940066-ebd0-11e8-8067-000c299a5e15 is in the cache, so can't be assumed
I1119 15:56:42.080127  127596 factory.go:1338] About to try and schedule pod volume-schedulinga42c7715-ebd0-11e8-8067-000c299a5e15/pod-i-pv-prebound-w-provisioned
I1119 15:56:42.080137  127596 scheduler.go:508] Attempting to schedule pod: volume-schedulinga42c7715-ebd0-11e8-8067-000c299a5e15/pod-i-pv-prebound-w-provisioned
I1119 15:56:42.080170  127596 scheduler_binder.go:147] FindPodVolumes for pod "volume-schedulinga42c7715-ebd0-11e8-8067-000c299a5e15/pod-i-pv-prebound-w-provisioned", node "node-1"
I1119 15:56:42.080182  127596 scheduler_binder.go:458] PVC "volume-schedulinga42c7715-ebd0-11e8-8067-000c299a5e15/pvc-i-pv-prebound" is fully bound to PV "pv-i-prebound"
I1119 15:56:42.080187  127596 scheduler_binder.go:458] PVC "volume-schedulinga42c7715-ebd0-11e8-8067-000c299a5e15/pvc-canprovision" is fully bound to PV "pvc-a693d4b0-ebd0-11e8-8067-000c299a5e15"
I1119 15:56:42.080199  127596 scheduler_binder.go:529] PersistentVolume "pv-i-prebound", Node "node-1" matches for Pod "volume-schedulinga42c7715-ebd0-11e8-8067-000c299a5e15/pod-i-pv-prebound-w-provisioned"
I1119 15:56:42.080203  127596 scheduler_binder.go:529] PersistentVolume "pvc-a693d4b0-ebd0-11e8-8067-000c299a5e15", Node "node-1" matches for Pod "volume-schedulinga42c7715-ebd0-11e8-8067-000c299a5e15/pod-i-pv-prebound-w-provisioned"
I1119 15:56:42.080208  127596 scheduler_binder.go:532] All bound volumes for Pod "volume-schedulinga42c7715-ebd0-11e8-8067-000c299a5e15/pod-i-pv-prebound-w-provisioned" match with Node "node-1"
I1119 15:56:42.080222  127596 scheduler_binder.go:207] AssumePodVolumes for pod "volume-schedulinga42c7715-ebd0-11e8-8067-000c299a5e15/pod-i-pv-prebound-w-provisioned", node "node-1"
I1119 15:56:42.080227  127596 scheduler_binder.go:458] PVC "volume-schedulinga42c7715-ebd0-11e8-8067-000c299a5e15/pvc-i-pv-prebound" is fully bound to PV "pv-i-prebound"
I1119 15:56:42.080231  127596 scheduler_binder.go:458] PVC "volume-schedulinga42c7715-ebd0-11e8-8067-000c299a5e15/pvc-canprovision" is fully bound to PV "pvc-a693d4b0-ebd0-11e8-8067-000c299a5e15"
I1119 15:56:42.080236  127596 scheduler_binder.go:217] AssumePodVolumes for pod "volume-schedulinga42c7715-ebd0-11e8-8067-000c299a5e15/pod-i-pv-prebound-w-provisioned", node "node-1": all PVCs bound and nothing to do
E1119 15:56:42.080241  127596 scheduler.go:433] scheduler cache AssumePod failed: pod a6940066-ebd0-11e8-8067-000c299a5e15 is in the cache, so can't be assumed
E1119 15:56:42.080245  127596 factory.go:1465] Error scheduling volume-schedulinga42c7715-ebd0-11e8-8067-000c299a5e15/pod-i-pv-prebound-w-provisioned: pod a6940066-ebd0-11e8-8067-000c299a5e15 is in the cache, so can't be assumed; retrying
I1119 15:56:42.080256  127596 factory.go:1558] Updating pod condition for volume-schedulinga42c7715-ebd0-11e8-8067-000c299a5e15/pod-i-pv-prebound-w-provisioned to (PodScheduled==False)
E1119 15:56:42.080260  127596 scheduler.go:556] error assuming pod: pod a6940066-ebd0-11e8-8067-000c299a5e15 is in the cache, so can't be assumed
I1119 15:56:42.081116  127596 factory.go:1338] About to try and schedule pod volume-schedulinga42c7715-ebd0-11e8-8067-000c299a5e15/pod-i-pv-prebound-w-provisioned
I1119 15:56:42.081138  127596 scheduler.go:508] Attempting to schedule pod: volume-schedulinga42c7715-ebd0-11e8-8067-000c299a5e15/pod-i-pv-prebound-w-provisioned
I1119 15:56:42.081170  127596 scheduler_binder.go:147] FindPodVolumes for pod "volume-schedulinga42c7715-ebd0-11e8-8067-000c299a5e15/pod-i-pv-prebound-w-provisioned", node "node-1"
I1119 15:56:42.081182  127596 scheduler_binder.go:458] PVC "volume-schedulinga42c7715-ebd0-11e8-8067-000c299a5e15/pvc-i-pv-prebound" is fully bound to PV "pv-i-prebound"
I1119 15:56:42.081187  127596 scheduler_binder.go:458] PVC "volume-schedulinga42c7715-ebd0-11e8-8067-000c299a5e15/pvc-canprovision" is fully bound to PV "pvc-a693d4b0-ebd0-11e8-8067-000c299a5e15"
I1119 15:56:42.081198  127596 scheduler_binder.go:529] PersistentVolume "pv-i-prebound", Node "node-1" matches for Pod "volume-schedulinga42c7715-ebd0-11e8-8067-000c299a5e15/pod-i-pv-prebound-w-provisioned"
I1119 15:56:42.081203  127596 scheduler_binder.go:529] PersistentVolume "pvc-a693d4b0-ebd0-11e8-8067-000c299a5e15", Node "node-1" matches for Pod "volume-schedulinga42c7715-ebd0-11e8-8067-000c299a5e15/pod-i-pv-prebound-w-provisioned"
I1119 15:56:42.081207  127596 scheduler_binder.go:532] All bound volumes for Pod "volume-schedulinga42c7715-ebd0-11e8-8067-000c299a5e15/pod-i-pv-prebound-w-provisioned" match with Node "node-1"
I1119 15:56:42.081221  127596 scheduler_binder.go:207] AssumePodVolumes for pod "volume-schedulinga42c7715-ebd0-11e8-8067-000c299a5e15/pod-i-pv-prebound-w-provisioned", node "node-1"
I1119 15:56:42.081228  127596 scheduler_binder.go:458] PVC "volume-schedulinga42c7715-ebd0-11e8-8067-000c299a5e15/pvc-i-pv-prebound" is fully bound to PV "pv-i-prebound"
I1119 15:56:42.081232  127596 scheduler_binder.go:458] PVC "volume-schedulinga42c7715-ebd0-11e8-8067-000c299a5e15/pvc-canprovision" is fully bound to PV "pvc-a693d4b0-ebd0-11e8-8067-000c299a5e15"
I1119 15:56:42.081237  127596 scheduler_binder.go:217] AssumePodVolumes for pod "volume-schedulinga42c7715-ebd0-11e8-8067-000c299a5e15/pod-i-pv-prebound-w-provisioned", node "node-1": all PVCs bound and nothing to do
E1119 15:56:42.081242  127596 scheduler.go:433] scheduler cache AssumePod failed: pod a6940066-ebd0-11e8-8067-000c299a5e15 is in the cache, so can't be assumed
E1119 15:56:42.081246  127596 factory.go:1465] Error scheduling volume-schedulinga42c7715-ebd0-11e8-8067-000c299a5e15/pod-i-pv-prebound-w-provisioned: pod a6940066-ebd0-11e8-8067-000c299a5e15 is in the cache, so can't be assumed; retrying
I1119 15:56:42.081256  127596 factory.go:1558] Updating pod condition for volume-schedulinga42c7715-ebd0-11e8-8067-000c299a5e15/pod-i-pv-prebound-w-provisioned to (PodScheduled==False)
E1119 15:56:42.081261  127596 scheduler.go:556] error assuming pod: pod a6940066-ebd0-11e8-8067-000c299a5e15 is in the cache, so can't be assumed
I1119 15:56:42.082154  127596 factory.go:1338] About to try and schedule pod volume-schedulinga42c7715-ebd0-11e8-8067-000c299a5e15/pod-i-pv-prebound-w-provisioned
I1119 15:56:42.082178  127596 scheduler.go:508] Attempting to schedule pod: volume-schedulinga42c7715-ebd0-11e8-8067-000c299a5e15/pod-i-pv-prebound-w-provisioned
I1119 15:56:42.082211  127596 scheduler_binder.go:147] FindPodVolumes for pod "volume-schedulinga42c7715-ebd0-11e8-8067-000c299a5e15/pod-i-pv-prebound-w-provisioned", node "node-1"
I1119 15:56:42.082223  127596 scheduler_binder.go:458] PVC "volume-schedulinga42c7715-ebd0-11e8-8067-000c299a5e15/pvc-i-pv-prebound" is fully bound to PV "pv-i-prebound"
I1119 15:56:42.082228  127596 scheduler_binder.go:458] PVC "volume-schedulinga42c7715-ebd0-11e8-8067-000c299a5e15/pvc-canprovision" is fully bound to PV "pvc-a693d4b0-ebd0-11e8-8067-000c299a5e15"
I1119 15:56:42.082240  127596 scheduler_binder.go:529] PersistentVolume "pv-i-prebound", Node "node-1" matches for Pod "volume-schedulinga42c7715-ebd0-11e8-8067-000c299a5e15/pod-i-pv-prebound-w-provisioned"
I1119 15:56:42.082245  127596 scheduler_binder.go:529] PersistentVolume "pvc-a693d4b0-ebd0-11e8-8067-000c299a5e15", Node "node-1" matches for Pod "volume-schedulinga42c7715-ebd0-11e8-8067-000c299a5e15/pod-i-pv-prebound-w-provisioned"
I1119 15:56:42.082249  127596 scheduler_binder.go:532] All bound volumes for Pod "volume-schedulinga42c7715-ebd0-11e8-8067-000c299a5e15/pod-i-pv-prebound-w-provisioned" match with Node "node-1"
I1119 15:56:42.082265  127596 scheduler_binder.go:207] AssumePodVolumes for pod "volume-schedulinga42c7715-ebd0-11e8-8067-000c299a5e15/pod-i-pv-prebound-w-provisioned", node "node-1"
I1119 15:56:42.082270  127596 scheduler_binder.go:458] PVC "volume-schedulinga42c7715-ebd0-11e8-8067-000c299a5e15/pvc-i-pv-prebound" is fully bound to PV "pv-i-prebound"
I1119 15:56:42.082274  127596 scheduler_binder.go:458] PVC "volume-schedulinga42c7715-ebd0-11e8-8067-000c299a5e15/pvc-canprovision" is fully bound to PV "pvc-a693d4b0-ebd0-11e8-8067-000c299a5e15"
I1119 15:56:42.082278  127596 scheduler_binder.go:217] AssumePodVolumes for pod "volume-schedulinga42c7715-ebd0-11e8-8067-000c299a5e15/pod-i-pv-prebound-w-provisioned", node "node-1": all PVCs bound and nothing to do
E1119 15:56:42.082284  127596 scheduler.go:433] scheduler cache AssumePod failed: pod a6940066-ebd0-11e8-8067-000c299a5e15 is in the cache, so can't be assumed
E1119 15:56:42.082288  127596 factory.go:1465] Error scheduling volume-schedulinga42c7715-ebd0-11e8-8067-000c299a5e15/pod-i-pv-prebound-w-provisioned: pod a6940066-ebd0-11e8-8067-000c299a5e15 is in the cache, so can't be assumed; retrying
I1119 15:56:42.082300  127596 factory.go:1558] Updating pod condition for volume-schedulinga42c7715-ebd0-11e8-8067-000c299a5e15/pod-i-pv-prebound-w-provisioned to (PodScheduled==False)
E1119 15:56:42.082307  127596 scheduler.go:556] error assuming pod: pod a6940066-ebd0-11e8-8067-000c299a5e15 is in the cache, so can't be assumed
I1119 15:56:42.083289  127596 factory.go:1338] About to try and schedule pod volume-schedulinga42c7715-ebd0-11e8-8067-000c299a5e15/pod-i-pv-prebound-w-provisioned
I1119 15:56:42.083302  127596 scheduler.go:508] Attempting to schedule pod: volume-schedulinga42c7715-ebd0-11e8-8067-000c299a5e15/pod-i-pv-prebound-w-provisioned
I1119 15:56:42.083347  127596 scheduler_binder.go:147] FindPodVolumes for pod "volume-schedulinga42c7715-ebd0-11e8-8067-000c299a5e15/pod-i-pv-prebound-w-provisioned", node "node-1"
I1119 15:56:42.083363  127596 scheduler_binder.go:458] PVC "volume-schedulinga42c7715-ebd0-11e8-8067-000c299a5e15/pvc-i-pv-prebound" is fully bound to PV "pv-i-prebound"
I1119 15:56:42.083368  127596 scheduler_binder.go:458] PVC "volume-schedulinga42c7715-ebd0-11e8-8067-000c299a5e15/pvc-canprovision" is fully bound to PV "pvc-a693d4b0-ebd0-11e8-8067-000c299a5e15"
I1119 15:56:42.083386  127596 scheduler_binder.go:529] PersistentVolume "pv-i-prebound", Node "node-1" matches for Pod "volume-schedulinga42c7715-ebd0-11e8-8067-000c299a5e15/pod-i-pv-prebound-w-provisioned"
I1119 15:56:42.083391  127596 scheduler_binder.go:529] PersistentVolume "pvc-a693d4b0-ebd0-11e8-8067-000c299a5e15", Node "node-1" matches for Pod "volume-schedulinga42c7715-ebd0-11e8-8067-000c299a5e15/pod-i-pv-prebound-w-provisioned"
I1119 15:56:42.083395  127596 scheduler_binder.go:532] All bound volumes for Pod "volume-schedulinga42c7715-ebd0-11e8-8067-000c299a5e15/pod-i-pv-prebound-w-provisioned" match with Node "node-1"
I1119 15:56:42.083413  127596 scheduler_binder.go:207] AssumePodVolumes for pod "volume-schedulinga42c7715-ebd0-11e8-8067-000c299a5e15/pod-i-pv-prebound-w-provisioned", node "node-1"
I1119 15:56:42.083437  127596 scheduler_binder.go:458] PVC "volume-schedulinga42c7715-ebd0-11e8-8067-000c299a5e15/pvc-i-pv-prebound" is fully bound to PV "pv-i-prebound"
I1119 15:56:42.083443  127596 scheduler_binder.go:458] PVC "volume-schedulinga42c7715-ebd0-11e8-8067-000c299a5e15/pvc-canprovision" is fully bound to PV "pvc-a693d4b0-ebd0-11e8-8067-000c299a5e15"
I1119 15:56:42.083448  127596 scheduler_binder.go:217] AssumePodVolumes for pod "volume-schedulinga42c7715-ebd0-11e8-8067-000c299a5e15/pod-i-pv-prebound-w-provisioned", node "node-1": all PVCs bound and nothing to do
E1119 15:56:42.083455  127596 scheduler.go:433] scheduler cache AssumePod failed: pod a6940066-ebd0-11e8-8067-000c299a5e15 is in the cache, so can't be assumed
E1119 15:56:42.083460  127596 factory.go:1465] Error scheduling volume-schedulinga42c7715-ebd0-11e8-8067-000c299a5e15/pod-i-pv-prebound-w-provisioned: pod a6940066-ebd0-11e8-8067-000c299a5e15 is in the cache, so can't be assumed; retrying
I1119 15:56:42.083475  127596 factory.go:1558] Updating pod condition for volume-schedulinga42c7715-ebd0-11e8-8067-000c299a5e15/pod-i-pv-prebound-w-provisioned to (PodScheduled==False)
E1119 15:56:42.083481  127596 scheduler.go:556] error assuming pod: pod a6940066-ebd0-11e8-8067-000c299a5e15 is in the cache, so can't be assumed
I1119 15:56:42.084748  127596 factory.go:1338] About to try and schedule pod volume-schedulinga42c7715-ebd0-11e8-8067-000c299a5e15/pod-i-pv-prebound-w-provisioned
I1119 15:56:42.084758  127596 scheduler.go:508] Attempting to schedule pod: volume-schedulinga42c7715-ebd0-11e8-8067-000c299a5e15/pod-i-pv-prebound-w-provisioned
I1119 15:56:42.084793  127596 scheduler_binder.go:147] FindPodVolumes for pod "volume-schedulinga42c7715-ebd0-11e8-8067-000c299a5e15/pod-i-pv-prebound-w-provisioned", node "node-1"
I1119 15:56:42.084806  127596 scheduler_binder.go:458] PVC "volume-schedulinga42c7715-ebd0-11e8-8067-000c299a5e15/pvc-i-pv-prebound" is fully bound to PV "pv-i-prebound"
I1119 15:56:42.084811  127596 scheduler_binder.go:458] PVC "volume-schedulinga42c7715-ebd0-11e8-8067-000c299a5e15/pvc-canprovision" is fully bound to PV "pvc-a693d4b0-ebd0-11e8-8067-000c299a5e15"
I1119 15:56:42.084823  127596 scheduler_binder.go:529] PersistentVolume "pv-i-prebound", Node "node-1" matches for Pod "volume-schedulinga42c7715-ebd0-11e8-8067-000c299a5e15/pod-i-pv-prebound-w-provisioned"
I1119 15:56:42.084828  127596 scheduler_binder.go:529] PersistentVolume "pvc-a693d4b0-ebd0-11e8-8067-000c299a5e15", Node "node-1" matches for Pod "volume-schedulinga42c7715-ebd0-11e8-8067-000c299a5e15/pod-i-pv-prebound-w-provisioned"
I1119 15:56:42.084832  127596 scheduler_binder.go:532] All bound volumes for Pod "volume-schedulinga42c7715-ebd0-11e8-8067-000c299a5e15/pod-i-pv-prebound-w-provisioned" match with Node "node-1"
I1119 15:56:42.084847  127596 scheduler_binder.go:207] AssumePodVolumes for pod "volume-schedulinga42c7715-ebd0-11e8-8067-000c299a5e15/pod-i-pv-prebound-w-provisioned", node "node-1"
I1119 15:56:42.084851  127596 scheduler_binder.go:458] PVC "volume-schedulinga42c7715-ebd0-11e8-8067-000c299a5e15/pvc-i-pv-prebound" is fully bound to PV "pv-i-prebound"
I1119 15:56:42.084855  127596 scheduler_binder.go:458] PVC "volume-schedulinga42c7715-ebd0-11e8-8067-000c299a5e15/pvc-canprovision" is fully bound to PV "pvc-a693d4b0-ebd0-11e8-8067-000c299a5e15"
I1119 15:56:42.084860  127596 scheduler_binder.go:217] AssumePodVolumes for pod "volume-schedulinga42c7715-ebd0-11e8-8067-000c299a5e15/pod-i-pv-prebound-w-provisioned", node "node-1": all PVCs bound and nothing to do
E1119 15:56:42.084865  127596 scheduler.go:433] scheduler cache AssumePod failed: pod a6940066-ebd0-11e8-8067-000c299a5e15 is in the cache, so can't be assumed
E1119 15:56:42.084869  127596 factory.go:1465] Error scheduling volume-schedulinga42c7715-ebd0-11e8-8067-000c299a5e15/pod-i-pv-prebound-w-provisioned: pod a6940066-ebd0-11e8-8067-000c299a5e15 is in the cache, so can't be assumed; retrying
I1119 15:56:42.084880  127596 factory.go:1558] Updating pod condition for volume-schedulinga42c7715-ebd0-11e8-8067-000c299a5e15/pod-i-pv-prebound-w-provisioned to (PodScheduled==False)
E1119 15:56:42.084885  127596 scheduler.go:556] error assuming pod: pod a6940066-ebd0-11e8-8067-000c299a5e15 is in the cache, so can't be assumed
I1119 15:56:42.085886  127596 factory.go:1338] About to try and schedule pod volume-schedulinga42c7715-ebd0-11e8-8067-000c299a5e15/pod-i-pv-prebound-w-provisioned
I1119 15:56:42.085896  127596 scheduler.go:508] Attempting to schedule pod: volume-schedulinga42c7715-ebd0-11e8-8067-000c299a5e15/pod-i-pv-prebound-w-provisioned
I1119 15:56:42.085929  127596 scheduler_binder.go:147] FindPodVolumes for pod "volume-schedulinga42c7715-ebd0-11e8-8067-000c299a5e15/pod-i-pv-prebound-w-provisioned", node "node-1"
I1119 15:56:42.085942  127596 scheduler_binder.go:458] PVC "volume-schedulinga42c7715-ebd0-11e8-8067-000c299a5e15/pvc-i-pv-prebound" is fully bound to PV "pv-i-prebound"
I1119 15:56:42.085947  127596 scheduler_binder.go:458] PVC "volume-schedulinga42c7715-ebd0-11e8-8067-000c299a5e15/pvc-canprovision" is fully bound to PV "pvc-a693d4b0-ebd0-11e8-8067-000c299a5e15"
I1119 15:56:42.085960  127596 scheduler_binder.go:529] PersistentVolume "pv-i-prebound", Node "node-1" matches for Pod "volume-schedulinga42c7715-ebd0-11e8-8067-000c299a5e15/pod-i-pv-prebound-w-provisioned"
I1119 15:56:42.085967  127596 scheduler_binder.go:529] PersistentVolume "pvc-a693d4b0-ebd0-11e8-8067-000c299a5e15", Node "node-1" matches for Pod "volume-schedulinga42c7715-ebd0-11e8-8067-000c299a5e15/pod-i-pv-prebound-w-provisioned"
I1119 15:56:42.085971  127596 scheduler_binder.go:532] All bound volumes for Pod "volume-schedulinga42c7715-ebd0-11e8-8067-000c299a5e15/pod-i-pv-prebound-w-provisioned" match with Node "node-1"
I1119 15:56:42.086005  127596 scheduler_binder.go:207] AssumePodVolumes for pod "volume-schedulinga42c7715-ebd0-11e8-8067-000c299a5e15/pod-i-pv-prebound-w-provisioned", node "node-1"
I1119 15:56:42.086026  127596 scheduler_binder.go:458] PVC "volume-schedulinga42c7715-ebd0-11e8-8067-000c299a5e15/pvc-i-pv-prebound" is fully bound to PV "pv-i-prebound"
I1119 15:56:42.086032  127596 scheduler_binder.go:458] PVC "volume-schedulinga42c7715-ebd0-11e8-8067-000c299a5e15/pvc-canprovision" is fully bound to PV "pvc-a693d4b0-ebd0-11e8-8067-000c299a5e15"
I1119 15:56:42.086037  127596 scheduler_binder.go:217] AssumePodVolumes for pod "volume-schedulinga42c7715-ebd0-11e8-8067-000c299a5e15/pod-i-pv-prebound-w-provisioned", node "node-1": all PVCs bound and nothing to do
E1119 15:56:42.086045  127596 scheduler.go:433] scheduler cache AssumePod failed: pod a6940066-ebd0-11e8-8067-000c299a5e15 is in the cache, so can't be assumed
E1119 15:56:42.086049  127596 factory.go:1465] Error scheduling volume-schedulinga42c7715-ebd0-11e8-8067-000c299a5e15/pod-i-pv-prebound-w-provisioned: pod a6940066-ebd0-11e8-8067-000c299a5e15 is in the cache, so can't be assumed; retrying
I1119 15:56:42.086076  127596 factory.go:1558] Updating pod condition for volume-schedulinga42c7715-ebd0-11e8-8067-000c299a5e15/pod-i-pv-prebound-w-provisioned to (PodScheduled==False)
E1119 15:56:42.086083  127596 scheduler.go:556] error assuming pod: pod a6940066-ebd0-11e8-8067-000c299a5e15 is in the cache, so can't be assumed
I1119 15:56:42.087154  127596 factory.go:1338] About to try and schedule pod volume-schedulinga42c7715-ebd0-11e8-8067-000c299a5e15/pod-i-pv-prebound-w-provisioned
I1119 15:56:42.087175  127596 scheduler.go:508] Attempting to schedule pod: volume-schedulinga42c7715-ebd0-11e8-8067-000c299a5e15/pod-i-pv-prebound-w-provisioned
I1119 15:56:42.087228  127596 scheduler_binder.go:147] FindPodVolumes for pod "volume-schedulinga42c7715-ebd0-11e8-8067-000c299a5e15/pod-i-pv-prebound-w-provisioned", node "node-1"
I1119 15:56:42.087245  127596 scheduler_binder.go:458] PVC "volume-schedulinga42c7715-ebd0-11e8-8067-000c299a5e15/pvc-i-pv-prebound" is fully bound to PV "pv-i-prebound"
I1119 15:56:42.087250  127596 scheduler_binder.go:458] PVC "volume-schedulinga42c7715-ebd0-11e8-8067-000c299a5e15/pvc-canprovision" is fully bound to PV "pvc-a693d4b0-ebd0-11e8-8067-000c299a5e15"
I1119 15:56:42.087263  127596 scheduler_binder.go:529] PersistentVolume "pv-i-prebound", Node "node-1" matches for Pod "volume-schedulinga42c7715-ebd0-11e8-8067-000c299a5e15/pod-i-pv-prebound-w-provisioned"
I1119 15:56:42.087268  127596 scheduler_binder.go:529] PersistentVolume "pvc-a693d4b0-ebd0-11e8-8067-000c299a5e15", Node "node-1" matches for Pod "volume-schedulinga42c7715-ebd0-11e8-8067-000c299a5e15/pod-i-pv-prebound-w-provisioned"
I1119 15:56:42.087272  127596 scheduler_binder.go:532] All bound volumes for Pod "volume-schedulinga42c7715-ebd0-11e8-8067-000c299a5e15/pod-i-pv-prebound-w-provisioned" match with Node "node-1"
I1119 15:56:42.087304  127596 scheduler_binder.go:207] AssumePodVolumes for pod "volume-schedulinga42c7715-ebd0-11e8-8067-000c299a5e15/pod-i-pv-prebound-w-provisioned", node "node-1"
I1119 15:56:42.087325  127596 scheduler_binder.go:458] PVC "volume-schedulinga42c7715-ebd0-11e8-8067-000c299a5e15/pvc-i-pv-prebound" is fully bound to PV "pv-i-prebound"
I1119 15:56:42.087331  127596 scheduler_binder.go:458] PVC "volume-schedulinga42c7715-ebd0-11e8-8067-000c299a5e15/pvc-canprovision" is fully bound to PV "pvc-a693d4b0-ebd0-11e8-8067-000c299a5e15"
I1119 15:56:42.087336  127596 scheduler_binder.go:217] AssumePodVolumes for pod "volume-schedulinga42c7715-ebd0-11e8-8067-000c299a5e15/pod-i-pv-prebound-w-provisioned", node "node-1": all PVCs bound and nothing to do
E1119 15:56:42.087342  127596 scheduler.go:433] scheduler cache AssumePod failed: pod a6940066-ebd0-11e8-8067-000c299a5e15 is in the cache, so can't be assumed
E1119 15:56:42.087346  127596 factory.go:1465] Error scheduling volume-schedulinga42c7715-ebd0-11e8-8067-000c299a5e15/pod-i-pv-prebound-w-provisioned: pod a6940066-ebd0-11e8-8067-000c299a5e15 is in the cache, so can't be assumed; retrying
I1119 15:56:42.087378  127596 factory.go:1558] Updating pod condition for volume-schedulinga42c7715-ebd0-11e8-8067-000c299a5e15/pod-i-pv-prebound-w-provisioned to (PodScheduled==False)
E1119 15:56:42.087387  127596 scheduler.go:556] error assuming pod: pod a6940066-ebd0-11e8-8067-000c299a5e15 is in the cache, so can't be assumed
I1119 15:56:42.088468  127596 factory.go:1338] About to try and schedule pod volume-schedulinga42c7715-ebd0-11e8-8067-000c299a5e15/pod-i-pv-prebound-w-provisioned
I1119 15:56:42.088490  127596 scheduler.go:508] Attempting to schedule pod: volume-schedulinga42c7715-ebd0-11e8-8067-000c299a5e15/pod-i-pv-prebound-w-provisioned
I1119 15:56:42.088552  127596 scheduler_binder.go:147] FindPodVolumes for pod "volume-schedulinga42c7715-ebd0-11e8-8067-000c299a5e15/pod-i-pv-prebound-w-provisioned", node "node-1"
I1119 15:56:42.088567  127596 scheduler_binder.go:458] PVC "volume-schedulinga42c7715-ebd0-11e8-8067-000c299a5e15/pvc-i-pv-prebound" is fully bound to PV "pv-i-prebound"
I1119 15:56:42.088572  127596 scheduler_binder.go:458] PVC "volume-schedulinga42c7715-ebd0-11e8-8067-000c299a5e15/pvc-canprovision" is fully bound to PV "pvc-a693d4b0-ebd0-11e8-8067-000c299a5e15"
I1119 15:56:42.088585  127596 scheduler_binder.go:529] PersistentVolume "pv-i-prebound", Node "node-1" matches for Pod "volume-schedulinga42c7715-ebd0-11e8-8067-000c299a5e15/pod-i-pv-prebound-w-provisioned"
I1119 15:56:42.088590  127596 scheduler_binder.go:529] PersistentVolume "pvc-a693d4b0-ebd0-11e8-8067-000c299a5e15", Node "node-1" matches for Pod "volume-schedulinga42c7715-ebd0-11e8-8067-000c299a5e15/pod-i-pv-prebound-w-provisioned"
I1119 15:56:42.088609  127596 scheduler_binder.go:532] All bound volumes for Pod "volume-schedulinga42c7715-ebd0-11e8-8067-000c299a5e15/pod-i-pv-prebound-w-provisioned" match with Node "node-1"
I1119 15:56:42.088643  127596 scheduler_binder.go:207] AssumePodVolumes for pod "volume-schedulinga42c7715-ebd0-11e8-8067-000c299a5e15/pod-i-pv-prebound-w-provisioned", node "node-1"
I1119 15:56:42.088664  127596 scheduler_binder.go:458] PVC "volume-schedulinga42c7715-ebd0-11e8-8067-000c299a5e15/pvc-i-pv-prebound" is fully bound to PV "pv-i-prebound"
I1119 15:56:42.088670  127596 scheduler_binder.go:458] PVC "volume-schedulinga42c7715-ebd0-11e8-8067-000c299a5e15/pvc-canprovision" is fully bound to PV "pvc-a693d4b0-ebd0-11e8-8067-000c299a5e15"
I1119 15:56:42.088675  127596 scheduler_binder.go:217] AssumePodVolumes for pod "volume-schedulinga42c7715-ebd0-11e8-8067-000c299a5e15/pod-i-pv-prebound-w-provisioned", node "node-1": all PVCs bound and nothing to do
E1119 15:56:42.088681  127596 scheduler.go:433] scheduler cache AssumePod failed: pod a6940066-ebd0-11e8-8067-000c299a5e15 is in the cache, so can't be assumed
E1119 15:56:42.088685  127596 factory.go:1465] Error scheduling volume-schedulinga42c7715-ebd0-11e8-8067-000c299a5e15/pod-i-pv-prebound-w-provisioned: pod a6940066-ebd0-11e8-8067-000c299a5e15 is in the cache, so can't be assumed; retrying
I1119 15:56:42.088729  127596 factory.go:1558] Updating pod condition for volume-schedulinga42c7715-ebd0-11e8-8067-000c299a5e15/pod-i-pv-prebound-w-provisioned to (PodScheduled==False)
E1119 15:56:42.088741  127596 scheduler.go:556] error assuming pod: pod a6940066-ebd0-11e8-8067-000c299a5e15 is in the cache, so can't be assumed
I1119 15:56:42.089935  127596 factory.go:1338] About to try and schedule pod volume-schedulinga42c7715-ebd0-11e8-8067-000c299a5e15/pod-i-pv-prebound-w-provisioned
I1119 15:56:42.089957  127596 scheduler.go:508] Attempting to schedule pod: volume-schedulinga42c7715-ebd0-11e8-8067-000c299a5e15/pod-i-pv-prebound-w-provisioned
I1119 15:56:42.090011  127596 scheduler_binder.go:147] FindPodVolumes for pod "volume-schedulinga42c7715-ebd0-11e8-8067-000c299a5e15/pod-i-pv-prebound-w-provisioned", node "node-1"
I1119 15:56:42.090027  127596 scheduler_binder.go:458] PVC "volume-schedulinga42c7715-ebd0-11e8-8067-000c299a5e15/pvc-i-pv-prebound" is fully bound to PV "pv-i-prebound"
I1119 15:56:42.090040  127596 scheduler_binder.go:458] PVC "volume-schedulinga42c7715-ebd0-11e8-8067-000c299a5e15/pvc-canprovision" is fully bound to PV "pvc-a693d4b0-ebd0-11e8-8067-000c299a5e15"
I1119 15:56:42.090054  127596 scheduler_binder.go:529] PersistentVolume "pv-i-prebound", Node "node-1" matches for Pod "volume-schedulinga42c7715-ebd0-11e8-8067-000c299a5e15/pod-i-pv-prebound-w-provisioned"
I1119 15:56:42.090059  127596 scheduler_binder.go:529] PersistentVolume "pvc-a693d4b0-ebd0-11e8-8067-000c299a5e15", Node "node-1" matches for Pod "volume-schedulinga42c7715-ebd0-11e8-8067-000c299a5e15/pod-i-pv-prebound-w-provisioned"
I1119 15:56:42.090063  127596 scheduler_binder.go:532] All bound volumes for Pod "volume-schedulinga42c7715-ebd0-11e8-8067-000c299a5e15/pod-i-pv-prebound-w-provisioned" match with Node "node-1"
I1119 15:56:42.090105  127596 scheduler_binder.go:207] AssumePodVolumes for pod "volume-schedulinga42c7715-ebd0-11e8-8067-000c299a5e15/pod-i-pv-prebound-w-provisioned", node "node-1"
I1119 15:56:42.090127  127596 scheduler_binder.go:458] PVC "volume-schedulinga42c7715-ebd0-11e8-8067-000c299a5e15/pvc-i-pv-prebound" is fully bound to PV "pv-i-prebound"
I1119 15:56:42.090132  127596 scheduler_binder.go:458] PVC "volume-schedulinga42c7715-ebd0-11e8-8067-000c299a5e15/pvc-canprovision" is fully bound to PV "pvc-a693d4b0-ebd0-11e8-8067-000c299a5e15"
I1119 15:56:42.090137  127596 scheduler_binder.go:217] AssumePodVolumes for pod "volume-schedulinga42c7715-ebd0-11e8-8067-000c299a5e15/pod-i-pv-prebound-w-provisioned", node "node-1": all PVCs bound and nothing to do
E1119 15:56:42.090144  127596 scheduler.go:433] scheduler cache AssumePod failed: pod a6940066-ebd0-11e8-8067-000c299a5e15 is in the cache, so can't be assumed
E1119 15:56:42.090148  127596 factory.go:1465] Error scheduling volume-schedulinga42c7715-ebd0-11e8-8067-000c299a5e15/pod-i-pv-prebound-w-provisioned: pod a6940066-ebd0-11e8-8067-000c299a5e15 is in the cache, so can't be assumed; retrying
I1119 15:56:42.090179  127596 factory.go:1558] Updating pod condition for volume-schedulinga42c7715-ebd0-11e8-8067-000c299a5e15/pod-i-pv-prebound-w-provisioned to (PodScheduled==False)
E1119 15:56:42.090190  127596 scheduler.go:556] error assuming pod: pod a6940066-ebd0-11e8-8067-000c299a5e15 is in the cache, so can't be assumed
I1119 15:56:42.091261  127596 factory.go:1338] About to try and schedule pod volume-schedulinga42c7715-ebd0-11e8-8067-000c299a5e15/pod-i-pv-prebound-w-provisioned
I1119 15:56:42.091282  127596 scheduler.go:508] Attempting to schedule pod: volume-schedulinga42c7715-ebd0-11e8-8067-000c299a5e15/pod-i-pv-prebound-w-provisioned
I1119 15:56:42.091332  127596 scheduler_binder.go:147] FindPodVolumes for pod "volume-schedulinga42c7715-ebd0-11e8-8067-000c299a5e15/pod-i-pv-prebound-w-provisioned", node "node-1"
I1119 15:56:42.091347  127596 scheduler_binder.go:458] PVC "volume-schedulinga42c7715-ebd0-11e8-8067-000c299a5e15/pvc-i-pv-prebound" is fully bound to PV "pv-i-prebound"
I1119 15:56:42.091351  127596 scheduler_binder.go:458] PVC "volume-schedulinga42c7715-ebd0-11e8-8067-000c299a5e15/pvc-canprovision" is fully bound to PV "pvc-a693d4b0-ebd0-11e8-8067-000c299a5e15"
I1119 15:56:42.091364  127596 scheduler_binder.go:529] PersistentVolume "pv-i-prebound", Node "node-1" matches for Pod "volume-schedulinga42c7715-ebd0-11e8-8067-000c299a5e15/pod-i-pv-prebound-w-provisioned"
I1119 15:56:42.091369  127596 scheduler_binder.go:529] PersistentVolume "pvc-a693d4b0-ebd0-11e8-8067-000c299a5e15", Node "node-1" matches for Pod "volume-schedulinga42c7715-ebd0-11e8-8067-000c299a5e15/pod-i-pv-prebound-w-provisioned"
I1119 15:56:42.091373  127596 scheduler_binder.go:532] All bound volumes for Pod "volume-schedulinga42c7715-ebd0-11e8-8067-000c299a5e15/pod-i-pv-prebound-w-provisioned" match with Node "node-1"
I1119 15:56:42.091404  127596 scheduler_binder.go:207] AssumePodVolumes for pod "volume-schedulinga42c7715-ebd0-11e8-8067-000c299a5e15/pod-i-pv-prebound-w-provisioned", node "node-1"
I1119 15:56:42.091425  127596 scheduler_binder.go:458] PVC "volume-schedulinga42c7715-ebd0-11e8-8067-000c299a5e15/pvc-i-pv-prebound" is fully bound to PV "pv-i-prebound"
I1119 15:56:42.091430  127596 scheduler_binder.go:458] PVC "volume-schedulinga42c7715-ebd0-11e8-8067-000c299a5e15/pvc-canprovision" is fully bound to PV "pvc-a693d4b0-ebd0-11e8-8067-000c299a5e15"
I1119 15:56:42.091435  127596 scheduler_binder.go:217] AssumePodVolumes for pod "volume-schedulinga42c7715-ebd0-11e8-8067-000c299a5e15/pod-i-pv-prebound-w-provisioned", node "node-1": all PVCs bound and nothing to do
E1119 15:56:42.091441  127596 scheduler.go:433] scheduler cache AssumePod failed: pod a6940066-ebd0-11e8-8067-000c299a5e15 is in the cache, so can't be assumed
E1119 15:56:42.091447  127596 factory.go:1465] Error scheduling volume-schedulinga42c7715-ebd0-11e8-8067-000c299a5e15/pod-i-pv-prebound-w-provisioned: pod a6940066-ebd0-11e8-8067-000c299a5e15 is in the cache, so can't be assumed; retrying
I1119 15:56:42.091478  127596 factory.go:1558] Updating pod condition for volume-schedulinga42c7715-ebd0-11e8-8067-000c299a5e15/pod-i-pv-prebound-w-provisioned to (PodScheduled==False)
E1119 15:56:42.091489  127596 scheduler.go:556] error assuming pod: pod a6940066-ebd0-11e8-8067-000c299a5e15 is in the cache, so can't be assumed
I1119 15:56:42.092717  127596 factory.go:1338] About to try and schedule pod volume-schedulinga42c7715-ebd0-11e8-8067-000c299a5e15/pod-i-pv-prebound-w-provisioned
I1119 15:56:42.092728  127596 scheduler.go:508] Attempting to schedule pod: volume-schedulinga42c7715-ebd0-11e8-8067-000c299a5e15/pod-i-pv-prebound-w-provisioned
I1119 15:56:42.092761  127596 scheduler_binder.go:147] FindPodVolumes for pod "volume-schedulinga42c7715-ebd0-11e8-8067-000c299a5e15/pod-i-pv-prebound-w-provisioned", node "node-1"
I1119 15:56:42.092777  127596 scheduler_binder.go:458] PVC "volume-schedulinga42c7715-ebd0-11e8-8067-000c299a5e15/pvc-i-pv-prebound" is fully bound to PV "pv-i-prebound"
I1119 15:56:42.092786  127596 scheduler_binder.go:458] PVC "volume-schedulinga42c7715-ebd0-11e8-8067-000c299a5e15/pvc-canprovision" is fully bound to PV "pvc-a693d4b0-ebd0-11e8-8067-000c299a5e15"
I1119 15:56:42.092805  127596 scheduler_binder.go:529] PersistentVolume "pv-i-prebound", Node "node-1" matches for Pod "volume-schedulinga42c7715-ebd0-11e8-8067-000c299a5e15/pod-i-pv-prebound-w-provisioned"
I1119 15:56:42.092814  127596 scheduler_binder.go:529] PersistentVolume "pvc-a693d4b0-ebd0-11e8-8067-000c299a5e15", Node "node-1" matches for Pod "volume-schedulinga42c7715-ebd0-11e8-8067-000c299a5e15/pod-i-pv-prebound-w-provisioned"
I1119 15:56:42.092822  127596 scheduler_binder.go:532] All bound volumes for Pod "volume-schedulinga42c7715-ebd0-11e8-8067-000c299a5e15/pod-i-pv-prebound-w-provisioned" match with Node "node-1"
I1119 15:56:42.092843  127596 scheduler_binder.go:207] AssumePodVolumes for pod "volume-schedulinga42c7715-ebd0-11e8-8067-000c299a5e15/pod-i-pv-prebound-w-provisioned", node "node-1"
I1119 15:56:42.092851  127596 scheduler_binder.go:458] PVC "volume-schedulinga42c7715-ebd0-11e8-8067-000c299a5e15/pvc-i-pv-prebound" is fully bound to PV "pv-i-prebound"
I1119 15:56:42.092857  127596 scheduler_binder.go:458] PVC "volume-schedulinga42c7715-ebd0-11e8-8067-000c299a5e15/pvc-canprovision" is fully bound to PV "pvc-a693d4b0-ebd0-11e8-8067-000c299a5e15"
I1119 15:56:42.092864  127596 scheduler_binder.go:217] AssumePodVolumes for pod "volume-schedulinga42c7715-ebd0-11e8-8067-000c299a5e15/pod-i-pv-prebound-w-provisioned", node "node-1": all PVCs bound and nothing to do
E1119 15:56:42.092872  127596 scheduler.go:433] scheduler cache AssumePod failed: pod a6940066-ebd0-11e8-8067-000c299a5e15 is in the cache, so can't be assumed
E1119 15:56:42.092878  127596 factory.go:1465] Error scheduling volume-schedulinga42c7715-ebd0-11e8-8067-000c299a5e15/pod-i-pv-prebound-w-provisioned: pod a6940066-ebd0-11e8-8067-000c299a5e15 is in the cache, so can't be assumed; retrying
I1119 15:56:42.092893  127596 factory.go:1558] Updating pod condition for volume-schedulinga42c7715-ebd0-11e8-8067-000c299a5e15/pod-i-pv-prebound-w-provisioned to (PodScheduled==False)
E1119 15:56:42.092923  127596 scheduler.go:556] error assuming pod: pod a6940066-ebd0-11e8-8067-000c299a5e15 is in the cache, so can't be assumed
I1119 15:56:42.093828  127596 factory.go:1338] About to try and schedule pod volume-schedulinga42c7715-ebd0-11e8-8067-000c299a5e15/pod-i-pv-prebound-w-provisioned
I1119 15:56:42.093852  127596 scheduler.go:508] Attempting to schedule pod: volume-schedulinga42c7715-ebd0-11e8-8067-000c299a5e15/pod-i-pv-prebound-w-provisioned
I1119 15:56:42.093887  127596 scheduler_binder.go:147] FindPodVolumes for pod "volume-schedulinga42c7715-ebd0-11e8-8067-000c299a5e15/pod-i-pv-prebound-w-provisioned", node "node-1"
I1119 15:56:42.093902  127596 scheduler_binder.go:458] PVC "volume-schedulinga42c7715-ebd0-11e8-8067-000c299a5e15/pvc-i-pv-prebound" is fully bound to PV "pv-i-prebound"
I1119 15:56:42.093907  127596 scheduler_binder.go:458] PVC "volume-schedulinga42c7715-ebd0-11e8-8067-000c299a5e15/pvc-canprovision" is fully bound to PV "pvc-a693d4b0-ebd0-11e8-8067-000c299a5e15"
I1119 15:56:42.093919  127596 scheduler_binder.go:529] PersistentVolume "pv-i-prebound", Node "node-1" matches for Pod "volume-schedulinga42c7715-ebd0-11e8-8067-000c299a5e15/pod-i-pv-prebound-w-provisioned"
I1119 15:56:42.093924  127596 scheduler_binder.go:529] PersistentVolume "pvc-a693d4b0-ebd0-11e8-8067-000c299a5e15", Node "node-1" matches for Pod "volume-schedulinga42c7715-ebd0-11e8-8067-000c299a5e15/pod-i-pv-prebound-w-provisioned"
I1119 15:56:42.093928  127596 scheduler_binder.go:532] All bound volumes for Pod "volume-schedulinga42c7715-ebd0-11e8-8067-000c299a5e15/pod-i-pv-prebound-w-provisioned" match with Node "node-1"
I1119 15:56:42.093943  127596 scheduler_binder.go:207] AssumePodVolumes for pod "volume-schedulinga42c7715-ebd0-11e8-8067-000c299a5e15/pod-i-pv-prebound-w-provisioned", node "node-1"
I1119 15:56:42.093951  127596 scheduler_binder.go:458] PVC "volume-schedulinga42c7715-ebd0-11e8-8067-000c299a5e15/pvc-i-pv-prebound" is fully bound to PV "pv-i-prebound"
I1119 15:56:42.093958  127596 scheduler_binder.go:458] PVC "volume-schedulinga42c7715-ebd0-11e8-8067-000c299a5e15/pvc-canprovision" is fully bound to PV "pvc-a693d4b0-ebd0-11e8-8067-000c299a5e15"
I1119 15:56:42.093966  127596 scheduler_binder.go:217] AssumePodVolumes for pod "volume-schedulinga42c7715-ebd0-11e8-8067-000c299a5e15/pod-i-pv-prebound-w-provisioned", node "node-1": all PVCs bound and nothing to do
E1119 15:56:42.093973  127596 scheduler.go:433] scheduler cache AssumePod failed: pod a6940066-ebd0-11e8-8067-000c299a5e15 is in the cache, so can't be assumed
E1119 15:56:42.093978  127596 factory.go:1465] Error scheduling volume-schedulinga42c7715-ebd0-11e8-8067-000c299a5e15/pod-i-pv-prebound-w-provisioned: pod a6940066-ebd0-11e8-8067-000c299a5e15 is in the cache, so can't be assumed; retrying
I1119 15:56:42.093993  127596 factory.go:1558] Updating pod condition for volume-schedulinga42c7715-ebd0-11e8-8067-000c299a5e15/pod-i-pv-prebound-w-provisioned to (PodScheduled==False)
E1119 15:56:42.093999  127596 scheduler.go:556] error assuming pod: pod a6940066-ebd0-11e8-8067-000c299a5e15 is in the cache, so can't be assumed
I1119 15:56:42.095195  127596 factory.go:1338] About to try and schedule pod volume-schedulinga42c7715-ebd0-11e8-8067-000c299a5e15/pod-i-pv-prebound-w-provisioned
I1119 15:56:42.095228  127596 scheduler.go:508] Attempting to schedule pod: volume-schedulinga42c7715-ebd0-11e8-8067-000c299a5e15/pod-i-pv-prebound-w-provisioned
I1119 15:56:42.095328  127596 scheduler_binder.go:147] FindPodVolumes for pod "volume-schedulinga42c7715-ebd0-11e8-8067-000c299a5e15/pod-i-pv-prebound-w-provisioned", node "node-1"
I1119 15:56:42.095365  127596 scheduler_binder.go:458] PVC "volume-schedulinga42c7715-ebd0-11e8-8067-000c299a5e15/pvc-i-pv-prebound" is fully bound to PV "pv-i-prebound"
I1119 15:56:42.095375  127596 scheduler_binder.go:458] PVC "volume-schedulinga42c7715-ebd0-11e8-8067-000c299a5e15/pvc-canprovision" is fully bound to PV "pvc-a693d4b0-ebd0-11e8-8067-000c299a5e15"
I1119 15:56:42.095417  127596 scheduler_binder.go:529] PersistentVolume "pv-i-prebound", Node "node-1" matches for Pod "volume-schedulinga42c7715-ebd0-11e8-8067-000c299a5e15/pod-i-pv-prebound-w-provisioned"
I1119 15:56:42.095429  127596 scheduler_binder.go:529] PersistentVolume "pvc-a693d4b0-ebd0-11e8-8067-000c299a5e15", Node "node-1" matches for Pod "volume-schedulinga42c7715-ebd0-11e8-8067-000c299a5e15/pod-i-pv-prebound-w-provisioned"
I1119 15:56:42.095436  127596 scheduler_binder.go:532] All bound volumes for Pod "volume-schedulinga42c7715-ebd0-11e8-8067-000c299a5e15/pod-i-pv-prebound-w-provisioned" match with Node "node-1"
I1119 15:56:42.095475  127596 scheduler_binder.go:207] AssumePodVolumes for pod "volume-schedulinga42c7715-ebd0-11e8-8067-000c299a5e15/pod-i-pv-prebound-w-provisioned", node "node-1"
I1119 15:56:42.095504  127596 scheduler_binder.go:458] PVC "volume-schedulinga42c7715-ebd0-11e8-8067-000c299a5e15/pvc-i-pv-prebound" is fully bound to PV "pv-i-prebound"
I1119 15:56:42.095513  127596 scheduler_binder.go:458] PVC "volume-schedulinga42c7715-ebd0-11e8-8067-000c299a5e15/pvc-canprovision" is fully bound to PV "pvc-a693d4b0-ebd0-11e8-8067-000c299a5e15"
I1119 15:56:42.095521  127596 scheduler_binder.go:217] AssumePodVolumes for pod "volume-schedulinga42c7715-ebd0-11e8-8067-000c299a5e15/pod-i-pv-prebound-w-provisioned", node "node-1": all PVCs bound and nothing to do
E1119 15:56:42.095531  127596 scheduler.go:433] scheduler cache AssumePod failed: pod a6940066-ebd0-11e8-8067-000c299a5e15 is in the cache, so can't be assumed
E1119 15:56:42.095537  127596 factory.go:1465] Error scheduling volume-schedulinga42c7715-ebd0-11e8-8067-000c299a5e15/pod-i-pv-prebound-w-provisioned: pod a6940066-ebd0-11e8-8067-000c299a5e15 is in the cache, so can't be assumed; retrying
I1119 15:56:42.095555  127596 factory.go:1558] Updating pod condition for volume-schedulinga42c7715-ebd0-11e8-8067-000c299a5e15/pod-i-pv-prebound-w-provisioned to (PodScheduled==False)
E1119 15:56:42.095562  127596 scheduler.go:556] error assuming pod: pod a6940066-ebd0-11e8-8067-000c299a5e15 is in the cache, so can't be assumed
I1119 15:56:42.096714  127596 factory.go:1338] About to try and schedule pod volume-schedulinga42c7715-ebd0-11e8-8067-000c299a5e15/pod-i-pv-prebound-w-provisioned
I1119 15:56:42.096737  127596 scheduler.go:508] Attempting to schedule pod: volume-schedulinga42c7715-ebd0-11e8-8067-000c299a5e15/pod-i-pv-prebound-w-provisioned
I1119 15:56:42.096794  127596 scheduler_binder.go:147] FindPodVolumes for pod "volume-schedulinga42c7715-ebd0-11e8-8067-000c299a5e15/pod-i-pv-prebound-w-provisioned", node "node-1"
I1119 15:56:42.096810  127596 scheduler_binder.go:458] PVC "volume-schedulinga42c7715-ebd0-11e8-8067-000c299a5e15/pvc-i-pv-prebound" is fully bound to PV "pv-i-prebound"
I1119 15:56:42.096815  127596 scheduler_binder.go:458] PVC "volume-schedulinga42c7715-ebd0-11e8-8067-000c299a5e15/pvc-canprovision" is fully bound to PV "pvc-a693d4b0-ebd0-11e8-8067-000c299a5e15"
I1119 15:56:42.096830  127596 scheduler_binder.go:529] PersistentVolume "pv-i-prebound", Node "node-1" matches for Pod "volume-schedulinga42c7715-ebd0-11e8-8067-000c299a5e15/pod-i-pv-prebound-w-provisioned"
I1119 15:56:42.096836  127596 scheduler_binder.go:529] PersistentVolume "pvc-a693d4b0-ebd0-11e8-8067-000c299a5e15", Node "node-1" matches for Pod "volume-schedulinga42c7715-ebd0-11e8-8067-000c299a5e15/pod-i-pv-prebound-w-provisioned"
I1119 15:56:42.096841  127596 scheduler_binder.go:532] All bound volumes for Pod "volume-schedulinga42c7715-ebd0-11e8-8067-000c299a5e15/pod-i-pv-prebound-w-provisioned" match with Node "node-1"
I1119 15:56:42.096875  127596 scheduler_binder.go:207] AssumePodVolumes for pod "volume-schedulinga42c7715-ebd0-11e8-8067-000c299a5e15/pod-i-pv-prebound-w-provisioned", node "node-1"
I1119 15:56:42.096896  127596 scheduler_binder.go:458] PVC "volume-schedulinga42c7715-ebd0-11e8-8067-000c299a5e15/pvc-i-pv-prebound" is fully bound to PV "pv-i-prebound"
I1119 15:56:42.096902  127596 scheduler_binder.go:458] PVC "volume-schedulinga42c7715-ebd0-11e8-8067-000c299a5e15/pvc-canprovision" is fully bound to PV "pvc-a693d4b0-ebd0-11e8-8067-000c299a5e15"
I1119 15:56:42.096907  127596 scheduler_binder.go:217] AssumePodVolumes for pod "volume-schedulinga42c7715-ebd0-11e8-8067-000c299a5e15/pod-i-pv-prebound-w-provisioned", node "node-1": all PVCs bound and nothing to do
E1119 15:56:42.096913  127596 scheduler.go:433] scheduler cache AssumePod failed: pod a6940066-ebd0-11e8-8067-000c299a5e15 is in the cache, so can't be assumed
E1119 15:56:42.096917  127596 factory.go:1465] Error scheduling volume-schedulinga42c7715-ebd0-11e8-8067-000c299a5e15/pod-i-pv-prebound-w-provisioned: pod a6940066-ebd0-11e8-8067-000c299a5e15 is in the cache, so can't be assumed; retrying
I1119 15:56:42.096945  127596 factory.go:1558] Updating pod condition for volume-schedulinga42c7715-ebd0-11e8-8067-000c299a5e15/pod-i-pv-prebound-w-provisioned to (PodScheduled==False)
E1119 15:56:42.096953  127596 scheduler.go:556] error assuming pod: pod a6940066-ebd0-11e8-8067-000c299a5e15 is in the cache, so can't be assumed
I1119 15:56:42.098273  127596 factory.go:1338] About to try and schedule pod volume-schedulinga42c7715-ebd0-11e8-8067-000c299a5e15/pod-i-pv-prebound-w-provisioned
I1119 15:56:42.098303  127596 scheduler.go:508] Attempting to schedule pod: volume-schedulinga42c7715-ebd0-11e8-8067-000c299a5e15/pod-i-pv-prebound-w-provisioned
I1119 15:56:42.098377  127596 scheduler_binder.go:147] FindPodVolumes for pod "volume-schedulinga42c7715-ebd0-11e8-8067-000c299a5e15/pod-i-pv-prebound-w-provisioned", node "node-1"
I1119 15:56:42.098396  127596 scheduler_binder.go:458] PVC "volume-schedulinga42c7715-ebd0-11e8-8067-000c299a5e15/pvc-i-pv-prebound" is fully bound to PV "pv-i-prebound"
I1119 15:56:42.098402  127596 scheduler_binder.go:458] PVC "volume-schedulinga42c7715-ebd0-11e8-8067-000c299a5e15/pvc-canprovision" is fully bound to PV "pvc-a693d4b0-ebd0-11e8-8067-000c299a5e15"
I1119 15:56:42.098422  127596 scheduler_binder.go:529] PersistentVolume "pv-i-prebound", Node "node-1" matches for Pod "volume-schedulinga42c7715-ebd0-11e8-8067-000c299a5e15/pod-i-pv-prebound-w-provisioned"
I1119 15:56:42.098428  127596 scheduler_binder.go:529] PersistentVolume "pvc-a693d4b0-ebd0-11e8-8067-000c299a5e15", Node "node-1" matches for Pod "volume-schedulinga42c7715-ebd0-11e8-8067-000c299a5e15/pod-i-pv-prebound-w-provisioned"
I1119 15:56:42.098435  127596 scheduler_binder.go:532] All bound volumes for Pod "volume-schedulinga42c7715-ebd0-11e8-8067-000c299a5e15/pod-i-pv-prebound-w-provisioned" match with Node "node-1"
I1119 15:56:42.098474  127596 scheduler_binder.go:207] AssumePodVolumes for pod "volume-schedulinga42c7715-ebd0-11e8-8067-000c299a5e15/pod-i-pv-prebound-w-provisioned", node "node-1"
I1119 15:56:42.098495  127596 scheduler_binder.go:458] PVC "volume-schedulinga42c7715-ebd0-11e8-8067-000c299a5e15/pvc-i-pv-prebound" is fully bound to PV "pv-i-prebound"
I1119 15:56:42.098501  127596 scheduler_binder.go:458] PVC "volume-schedulinga42c7715-ebd0-11e8-8067-000c299a5e15/pvc-canprovision" is fully bound to PV "pvc-a693d4b0-ebd0-11e8-8067-000c299a5e15"
I1119 15:56:42.098506  127596 scheduler_binder.go:217] AssumePodVolumes for pod "volume-schedulinga42c7715-ebd0-11e8-8067-000c299a5e15/pod-i-pv-prebound-w-provisioned", node "node-1": all PVCs bound and nothing to do
E1119 15:56:42.098513  127596 scheduler.go:433] scheduler cache AssumePod failed: pod a6940066-ebd0-11e8-8067-000c299a5e15 is in the cache, so can't be assumed
E1119 15:56:42.098519  127596 factory.go:1465] Error scheduling volume-schedulinga42c7715-ebd0-11e8-8067-000c299a5e15/pod-i-pv-prebound-w-provisioned: pod a6940066-ebd0-11e8-8067-000c299a5e15 is in the cache, so can't be assumed; retrying
I1119 15:56:42.098563  127596 factory.go:1558] Updating pod condition for volume-schedulinga42c7715-ebd0-11e8-8067-000c299a5e15/pod-i-pv-prebound-w-provisioned to (PodScheduled==False)
E1119 15:56:42.098573  127596 scheduler.go:556] error assuming pod: pod a6940066-ebd0-11e8-8067-000c299a5e15 is in the cache, so can't be assumed
I1119 15:56:42.100258  127596 factory.go:1338] About to try and schedule pod volume-schedulinga42c7715-ebd0-11e8-8067-000c299a5e15/pod-i-pv-prebound-w-provisioned
I1119 15:56:42.100283  127596 scheduler.go:508] Attempting to schedule pod: volume-schedulinga42c7715-ebd0-11e8-8067-000c299a5e15/pod-i-pv-prebound-w-provisioned
I1119 15:56:42.100328  127596 scheduler_binder.go:147] FindPodVolumes for pod "volume-schedulinga42c7715-ebd0-11e8-8067-000c299a5e15/pod-i-pv-prebound-w-provisioned", node "node-1"
I1119 15:56:42.100343  127596 scheduler_binder.go:458] PVC "volume-schedulinga42c7715-ebd0-11e8-8067-000c299a5e15/pvc-i-pv-prebound" is fully bound to PV "pv-i-prebound"
I1119 15:56:42.100348  127596 scheduler_binder.go:458] PVC "volume-schedulinga42c7715-ebd0-11e8-8067-000c299a5e15/pvc-canprovision" is fully bound to PV "pvc-a693d4b0-ebd0-11e8-8067-000c299a5e15"
I1119 15:56:42.100363  127596 scheduler_binder.go:529] PersistentVolume "pv-i-prebound", Node "node-1" matches for Pod "volume-schedulinga42c7715-ebd0-11e8-8067-000c299a5e15/pod-i-pv-prebound-w-provisioned"
I1119 15:56:42.100368  127596 scheduler_binder.go:529] PersistentVolume "pvc-a693d4b0-ebd0-11e8-8067-000c299a5e15", Node "node-1" matches for Pod "volume-schedulinga42c7715-ebd0-11e8-8067-000c299a5e15/pod-i-pv-prebound-w-provisioned"
I1119 15:56:42.100372  127596 scheduler_binder.go:532] All bound volumes for Pod "volume-schedulinga42c7715-ebd0-11e8-8067-000c299a5e15/pod-i-pv-prebound-w-provisioned" match with Node "node-1"
I1119 15:56:42.100390  127596 scheduler_binder.go:207] AssumePodVolumes for pod "volume-schedulinga42c7715-ebd0-11e8-8067-000c299a5e15/pod-i-pv-prebound-w-provisioned", node "node-1"
I1119 15:56:42.100397  127596 scheduler_binder.go:458] PVC "volume-schedulinga42c7715-ebd0-11e8-8067-000c299a5e15/pvc-i-pv-prebound" is fully bound to PV "pv-i-prebound"
I1119 15:56:42.100401  127596 scheduler_binder.go:458] PVC "volume-schedulinga42c7715-ebd0-11e8-8067-000c299a5e15/pvc-canprovision" is fully bound to PV "pvc-a693d4b0-ebd0-11e8-8067-000c299a5e15"
I1119 15:56:42.100406  127596 scheduler_binder.go:217] AssumePodVolumes for pod "volume-schedulinga42c7715-ebd0-11e8-8067-000c299a5e15/pod-i-pv-prebound-w-provisioned", node "node-1": all PVCs bound and nothing to do
E1119 15:56:42.100411  127596 scheduler.go:433] scheduler cache AssumePod failed: pod a6940066-ebd0-11e8-8067-000c299a5e15 is in the cache, so can't be assumed
E1119 15:56:42.100416  127596 factory.go:1465] Error scheduling volume-schedulinga42c7715-ebd0-11e8-8067-000c299a5e15/pod-i-pv-prebound-w-provisioned: pod a6940066-ebd0-11e8-8067-000c299a5e15 is in the cache, so can't be assumed; retrying
I1119 15:56:42.100431  127596 factory.go:1558] Updating pod condition for volume-schedulinga42c7715-ebd0-11e8-8067-000c299a5e15/pod-i-pv-prebound-w-provisioned to (PodScheduled==False)
E1119 15:56:42.100438  127596 scheduler.go:556] error assuming pod: pod a6940066-ebd0-11e8-8067-000c299a5e15 is in the cache, so can't be assumed
I1119 15:56:42.101404  127596 factory.go:1338] About to try and schedule pod volume-schedulinga42c7715-ebd0-11e8-8067-000c299a5e15/pod-i-pv-prebound-w-provisioned
I1119 15:56:42.101424  127596 scheduler.go:508] Attempting to schedule pod: volume-schedulinga42c7715-ebd0-11e8-8067-000c299a5e15/pod-i-pv-prebound-w-provisioned
I1119 15:56:42.101475  127596 scheduler_binder.go:147] FindPodVolumes for pod "volume-schedulinga42c7715-ebd0-11e8-8067-000c299a5e15/pod-i-pv-prebound-w-provisioned", node "node-1"
I1119 15:56:42.101489  127596 scheduler_binder.go:458] PVC "volume-schedulinga42c7715-ebd0-11e8-8067-000c299a5e15/pvc-i-pv-prebound" is fully bound to PV "pv-i-prebound"
I1119 15:56:42.101494  127596 scheduler_binder.go:458] PVC "volume-schedulinga42c7715-ebd0-11e8-8067-000c299a5e15/pvc-canprovision" is fully bound to PV "pvc-a693d4b0-ebd0-11e8-8067-000c299a5e15"
I1119 15:56:42.101506  127596 scheduler_binder.go:529] PersistentVolume "pv-i-prebound", Node "node-1" matches for Pod "volume-schedulinga42c7715-ebd0-11e8-8067-000c299a5e15/pod-i-pv-prebound-w-provisioned"
I1119 15:56:42.101510  127596 scheduler_binder.go:529] PersistentVolume "pvc-a693d4b0-ebd0-11e8-8067-000c299a5e15", Node "node-1" matches for Pod "volume-schedulinga42c7715-ebd0-11e8-8067-000c299a5e15/pod-i-pv-prebound-w-provisioned"
I1119 15:56:42.101515  127596 scheduler_binder.go:532] All bound volumes for Pod "volume-schedulinga42c7715-ebd0-11e8-8067-000c299a5e15/pod-i-pv-prebound-w-provisioned" match with Node "node-1"
I1119 15:56:42.101556  127596 scheduler_binder.go:207] AssumePodVolumes for pod "volume-schedulinga42c7715-ebd0-11e8-8067-000c299a5e15/pod-i-pv-prebound-w-provisioned", node "node-1"
I1119 15:56:42.101567  127596 scheduler_binder.go:458] PVC "volume-schedulinga42c7715-ebd0-11e8-8067-000c299a5e15/pvc-i-pv-prebound" is fully bound to PV "pv-i-prebound"
I1119 15:56:42.101571  127596 scheduler_binder.go:458] PVC "volume-schedulinga42c7715-ebd0-11e8-8067-000c299a5e15/pvc-canprovision" is fully bound to PV "pvc-a693d4b0-ebd0-11e8-8067-000c299a5e15"
I1119 15:56:42.101575  127596 scheduler_binder.go:217] AssumePodVolumes for pod "volume-schedulinga42c7715-ebd0-11e8-8067-000c299a5e15/pod-i-pv-prebound-w-provisioned", node "node-1": all PVCs bound and nothing to do
E1119 15:56:42.101581  127596 scheduler.go:433] scheduler cache AssumePod failed: pod a6940066-ebd0-11e8-8067-000c299a5e15 is in the cache, so can't be assumed
E1119 15:56:42.101585  127596 factory.go:1465] Error scheduling volume-schedulinga42c7715-ebd0-11e8-8067-000c299a5e15/pod-i-pv-prebound-w-provisioned: pod a6940066-ebd0-11e8-8067-000c299a5e15 is in the cache, so can't be assumed; retrying
I1119 15:56:42.101596  127596 factory.go:1558] Updating pod condition for volume-schedulinga42c7715-ebd0-11e8-8067-000c299a5e15/pod-i-pv-prebound-w-provisioned to (PodScheduled==False)
E1119 15:56:42.101601  127596 scheduler.go:556] error assuming pod: pod a6940066-ebd0-11e8-8067-000c299a5e15 is in the cache, so can't be assumed
I1119 15:56:42.102639  127596 factory.go:1338] About to try and schedule pod volume-schedulinga42c7715-ebd0-11e8-8067-000c299a5e15/pod-i-pv-prebound-w-provisioned
I1119 15:56:42.102649  127596 scheduler.go:508] Attempting to schedule pod: volume-schedulinga42c7715-ebd0-11e8-8067-000c299a5e15/pod-i-pv-prebound-w-provisioned
I1119 15:56:42.102698  127596 scheduler_binder.go:147] FindPodVolumes for pod "volume-schedulinga42c7715-ebd0-11e8-8067-000c299a5e15/pod-i-pv-prebound-w-provisioned", node "node-1"
I1119 15:56:42.102715  127596 scheduler_binder.go:458] PVC "volume-schedulinga42c7715-ebd0-11e8-8067-000c299a5e15/pvc-i-pv-prebound" is fully bound to PV "pv-i-prebound"
I1119 15:56:42.102720  127596 scheduler_binder.go:458] PVC "volume-schedulinga42c7715-ebd0-11e8-8067-000c299a5e15/pvc-canprovision" is fully bound to PV "pvc-a693d4b0-ebd0-11e8-8067-000c299a5e15"
I1119 15:56:42.102733  127596 scheduler_binder.go:529] PersistentVolume "pv-i-prebound", Node "node-1" matches for Pod "volume-schedulinga42c7715-ebd0-11e8-8067-000c299a5e15/pod-i-pv-prebound-w-provisioned"
I1119 15:56:42.102738  127596 scheduler_binder.go:529] PersistentVolume "pvc-a693d4b0-ebd0-11e8-8067-000c299a5e15", Node "node-1" matches for Pod "volume-schedulinga42c7715-ebd0-11e8-8067-000c299a5e15/pod-i-pv-prebound-w-provisioned"
I1119 15:56:42.102742  127596 scheduler_binder.go:532] All bound volumes for Pod "volume-schedulinga42c7715-ebd0-11e8-8067-000c299a5e15/pod-i-pv-prebound-w-provisioned" match with Node "node-1"
I1119 15:56:42.102773  127596 scheduler_binder.go:207] AssumePodVolumes for pod "volume-schedulinga42c7715-ebd0-11e8-8067-000c299a5e15/pod-i-pv-prebound-w-provisioned", node "node-1"
I1119 15:56:42.102793  127596 scheduler_binder.go:458] PVC "volume-schedulinga42c7715-ebd0-11e8-8067-000c299a5e15/pvc-i-pv-prebound" is fully bound to PV "pv-i-prebound"
I1119 15:56:42.102799  127596 scheduler_binder.go:458] PVC "volume-schedulinga42c7715-ebd0-11e8-8067-000c299a5e15/pvc-canprovision" is fully bound to PV "pvc-a693d4b0-ebd0-11e8-8067-000c299a5e15"
I1119 15:56:42.102804  127596 scheduler_binder.go:217] AssumePodVolumes for pod "volume-schedulinga42c7715-ebd0-11e8-8067-000c299a5e15/pod-i-pv-prebound-w-provisioned", node "node-1": all PVCs bound and nothing to do
E1119 15:56:42.102810  127596 scheduler.go:433] scheduler cache AssumePod failed: pod a6940066-ebd0-11e8-8067-000c299a5e15 is in the cache, so can't be assumed
E1119 15:56:42.102813  127596 factory.go:1465] Error scheduling volume-schedulinga42c7715-ebd0-11e8-8067-000c299a5e15/pod-i-pv-prebound-w-provisioned: pod a6940066-ebd0-11e8-8067-000c299a5e15 is in the cache, so can't be assumed; retrying
I1119 15:56:42.102838  127596 factory.go:1558] Updating pod condition for volume-schedulinga42c7715-ebd0-11e8-8067-000c299a5e15/pod-i-pv-prebound-w-provisioned to (PodScheduled==False)
E1119 15:56:42.102846  127596 scheduler.go:556] error assuming pod: pod a6940066-ebd0-11e8-8067-000c299a5e15 is in the cache, so can't be assumed
I1119 15:56:42.103919  127596 factory.go:1338] About to try and schedule pod volume-schedulinga42c7715-ebd0-11e8-8067-000c299a5e15/pod-i-pv-prebound-w-provisioned
I1119 15:56:42.103941  127596 scheduler.go:508] Attempting to schedule pod: volume-schedulinga42c7715-ebd0-11e8-8067-000c299a5e15/pod-i-pv-prebound-w-provisioned
I1119 15:56:42.103991  127596 scheduler_binder.go:147] FindPodVolumes for pod "volume-schedulinga42c7715-ebd0-11e8-8067-000c299a5e15/pod-i-pv-prebound-w-provisioned", node "node-1"
I1119 15:56:42.104006  127596 scheduler_binder.go:458] PVC "volume-schedulinga42c7715-ebd0-11e8-8067-000c299a5e15/pvc-i-pv-prebound" is fully bound to PV "pv-i-prebound"
I1119 15:56:42.104011  127596 scheduler_binder.go:458] PVC "volume-schedulinga42c7715-ebd0-11e8-8067-000c299a5e15/pvc-canprovision" is fully bound to PV "pvc-a693d4b0-ebd0-11e8-8067-000c299a5e15"
I1119 15:56:42.104023  127596 scheduler_binder.go:529] PersistentVolume "pv-i-prebound", Node "node-1" matches for Pod "volume-schedulinga42c7715-ebd0-11e8-8067-000c299a5e15/pod-i-pv-prebound-w-provisioned"
I1119 15:56:42.104028  127596 scheduler_binder.go:529] PersistentVolume "pvc-a693d4b0-ebd0-11e8-8067-000c299a5e15", Node "node-1" matches for Pod "volume-schedulinga42c7715-ebd0-11e8-8067-000c299a5e15/pod-i-pv-prebound-w-provisioned"
I1119 15:56:42.104032  127596 scheduler_binder.go:532] All bound volumes for Pod "volume-schedulinga42c7715-ebd0-11e8-8067-000c299a5e15/pod-i-pv-prebound-w-provisioned" match with Node "node-1"
I1119 15:56:42.104065  127596 scheduler_binder.go:207] AssumePodVolumes for pod "volume-schedulinga42c7715-ebd0-11e8-8067-000c299a5e15/pod-i-pv-prebound-w-provisioned", node "node-1"
I1119 15:56:42.104086  127596 scheduler_binder.go:458] PVC "volume-schedulinga42c7715-ebd0-11e8-8067-000c299a5e15/pvc-i-pv-prebound" is fully bound to PV "pv-i-prebound"
I1119 15:56:42.104094  127596 scheduler_binder.go:458] PVC "volume-schedulinga42c7715-ebd0-11e8-8067-000c299a5e15/pvc-canprovision" is fully bound to PV "pvc-a693d4b0-ebd0-11e8-8067-000c299a5e15"
I1119 15:56:42.104098  127596 scheduler_binder.go:217] AssumePodVolumes for pod "volume-schedulinga42c7715-ebd0-11e8-8067-000c299a5e15/pod-i-pv-prebound-w-provisioned", node "node-1": all PVCs bound and nothing to do
E1119 15:56:42.104105  127596 scheduler.go:433] scheduler cache AssumePod failed: pod a6940066-ebd0-11e8-8067-000c299a5e15 is in the cache, so can't be assumed
E1119 15:56:42.104108  127596 factory.go:1465] Error scheduling volume-schedulinga42c7715-ebd0-11e8-8067-000c299a5e15/pod-i-pv-prebound-w-provisioned: pod a6940066-ebd0-11e8-8067-000c299a5e15 is in the cache, so can't be assumed; retrying
I1119 15:56:42.104135  127596 factory.go:1558] Updating pod condition for volume-schedulinga42c7715-ebd0-11e8-8067-000c299a5e15/pod-i-pv-prebound-w-provisioned to (PodScheduled==False)
E1119 15:56:42.104142  127596 scheduler.go:556] error assuming pod: pod a6940066-ebd0-11e8-8067-000c299a5e15 is in the cache, so can't be assumed
I1119 15:56:42.105085  127596 factory.go:1338] About to try and schedule pod volume-schedulinga42c7715-ebd0-11e8-8067-000c299a5e15/pod-i-pv-prebound-w-provisioned
I1119 15:56:42.105109  127596 scheduler.go:508] Attempting to schedule pod: volume-schedulinga42c7715-ebd0-11e8-8067-000c299a5e15/pod-i-pv-prebound-w-provisioned
I1119 15:56:42.105142  127596 scheduler_binder.go:147] FindPodVolumes for pod "volume-schedulinga42c7715-ebd0-11e8-8067-000c299a5e15/pod-i-pv-prebound-w-provisioned", node "node-1"
I1119 15:56:42.105154  127596 scheduler_binder.go:458] PVC "volume-schedulinga42c7715-ebd0-11e8-8067-000c299a5e15/pvc-i-pv-prebound" is fully bound to PV "pv-i-prebound"
I1119 15:56:42.105159  127596 scheduler_binder.go:458] PVC "volume-schedulinga42c7715-ebd0-11e8-8067-000c299a5e15/pvc-canprovision" is fully bound to PV "pvc-a693d4b0-ebd0-11e8-8067-000c299a5e15"
I1119 15:56:42.105172  127596 scheduler_binder.go:529] PersistentVolume "pv-i-prebound", Node "node-1" matches for Pod "volume-schedulinga42c7715-ebd0-11e8-8067-000c299a5e15/pod-i-pv-prebound-w-provisioned"
I1119 15:56:42.105180  127596 scheduler_binder.go:529] PersistentVolume "pvc-a693d4b0-ebd0-11e8-8067-000c299a5e15", Node "node-1" matches for Pod "volume-schedulinga42c7715-ebd0-11e8-8067-000c299a5e15/pod-i-pv-prebound-w-provisioned"
I1119 15:56:42.105184  127596 scheduler_binder.go:532] All bound volumes for Pod "volume-schedulinga42c7715-ebd0-11e8-8067-000c299a5e15/pod-i-pv-prebound-w-provisioned" match with Node "node-1"
I1119 15:56:42.105199  127596 scheduler_binder.go:207] AssumePodVolumes for pod "volume-schedulinga42c7715-ebd0-11e8-8067-000c299a5e15/pod-i-pv-prebound-w-provisioned", node "node-1"
I1119 15:56:42.105205  127596 scheduler_binder.go:458] PVC "volume-schedulinga42c7715-ebd0-11e8-8067-000c299a5e15/pvc-i-pv-prebound" is fully bound to PV "pv-i-prebound"
I1119 15:56:42.105209  127596 scheduler_binder.go:458] PVC "volume-schedulinga42c7715-ebd0-11e8-8067-000c299a5e15/pvc-canprovision" is fully bound to PV "pvc-a693d4b0-ebd0-11e8-8067-000c299a5e15"
I1119 15:56:42.105216  127596 scheduler_binder.go:217] AssumePodVolumes for pod "volume-schedulinga42c7715-ebd0-11e8-8067-000c299a5e15/pod-i-pv-prebound-w-provisioned", node "node-1": all PVCs bound and nothing to do
E1119 15:56:42.105221  127596 scheduler.go:433] scheduler cache AssumePod failed: pod a6940066-ebd0-11e8-8067-000c299a5e15 is in the cache, so can't be assumed
E1119 15:56:42.105225  127596 factory.go:1465] Error scheduling volume-schedulinga42c7715-ebd0-11e8-8067-000c299a5e15/pod-i-pv-prebound-w-provisioned: pod a6940066-ebd0-11e8-8067-000c299a5e15 is in the cache, so can't be assumed; retrying
I1119 15:56:42.105236  127596 factory.go:1558] Updating pod condition for volume-schedulinga42c7715-ebd0-11e8-8067-000c299a5e15/pod-i-pv-prebound-w-provisioned to (PodScheduled==False)
E1119 15:56:42.105242  127596 scheduler.go:556] error assuming pod: pod a6940066-ebd0-11e8-8067-000c299a5e15 is in the cache, so can't be assumed
I1119 15:56:42.106165  127596 factory.go:1338] About to try and schedule pod volume-schedulinga42c7715-ebd0-11e8-8067-000c299a5e15/pod-i-pv-prebound-w-provisioned
I1119 15:56:42.106188  127596 scheduler.go:508] Attempting to schedule pod: volume-schedulinga42c7715-ebd0-11e8-8067-000c299a5e15/pod-i-pv-prebound-w-provisioned
I1119 15:56:42.106223  127596 scheduler_binder.go:147] FindPodVolumes for pod "volume-schedulinga42c7715-ebd0-11e8-8067-000c299a5e15/pod-i-pv-prebound-w-provisioned", node "node-1"
I1119 15:56:42.106235  127596 scheduler_binder.go:458] PVC "volume-schedulinga42c7715-ebd0-11e8-8067-000c299a5e15/pvc-i-pv-prebound" is fully bound to PV "pv-i-prebound"
I1119 15:56:42.106240  127596 scheduler_binder.go:458] PVC "volume-schedulinga42c7715-ebd0-11e8-8067-000c299a5e15/pvc-canprovision" is fully bound to PV "pvc-a693d4b0-ebd0-11e8-8067-000c299a5e15"
I1119 15:56:42.106251  127596 scheduler_binder.go:529] PersistentVolume "pv-i-prebound", Node "node-1" matches for Pod "volume-schedulinga42c7715-ebd0-11e8-8067-000c299a5e15/pod-i-pv-prebound-w-provisioned"
I1119 15:56:42.106256  127596 scheduler_binder.go:529] PersistentVolume "pvc-a693d4b0-ebd0-11e8-8067-000c299a5e15", Node "node-1" matches for Pod "volume-schedulinga42c7715-ebd0-11e8-8067-000c299a5e15/pod-i-pv-prebound-w-provisioned"
I1119 15:56:42.106260  127596 scheduler_binder.go:532] All bound volumes for Pod "volume-schedulinga42c7715-ebd0-11e8-8067-000c299a5e15/pod-i-pv-prebound-w-provisioned" match with Node "node-1"
I1119 15:56:42.106275  127596 scheduler_binder.go:207] AssumePodVolumes for pod "volume-schedulinga42c7715-ebd0-11e8-8067-000c299a5e15/pod-i-pv-prebound-w-provisioned", node "node-1"
I1119 15:56:42.106283  127596 scheduler_binder.go:458] PVC "volume-schedulinga42c7715-ebd0-11e8-8067-000c299a5e15/pvc-i-pv-prebound" is fully bound to PV "pv-i-prebound"
I1119 15:56:42.106287  127596 scheduler_binder.go:458] PVC "volume-schedulinga42c7715-ebd0-11e8-8067-000c299a5e15/pvc-canprovision" is fully bound to PV "pvc-a693d4b0-ebd0-11e8-8067-000c299a5e15"
I1119 15:56:42.106292  127596 scheduler_binder.go:217] AssumePodVolumes for pod "volume-schedulinga42c7715-ebd0-11e8-8067-000c299a5e15/pod-i-pv-prebound-w-provisioned", node "node-1": all PVCs bound and nothing to do
E1119 15:56:42.106297  127596 scheduler.go:433] scheduler cache AssumePod failed: pod a6940066-ebd0-11e8-8067-000c299a5e15 is in the cache, so can't be assumed
E1119 15:56:42.106300  127596 factory.go:1465] Error scheduling volume-schedulinga42c7715-ebd0-11e8-8067-000c299a5e15/pod-i-pv-prebound-w-provisioned: pod a6940066-ebd0-11e8-8067-000c299a5e15 is in the cache, so can't be assumed; retrying
I1119 15:56:42.106311  127596 factory.go:1558] Updating pod condition for volume-schedulinga42c7715-ebd0-11e8-8067-000c299a5e15/pod-i-pv-prebound-w-provisioned to (PodScheduled==False)
E1119 15:56:42.106315  127596 scheduler.go:556] error assuming pod: pod a6940066-ebd0-11e8-8067-000c299a5e15 is in the cache, so can't be assumed
I1119 15:56:42.111591  127596 factory.go:1338] About to try and schedule pod volume-schedulinga42c7715-ebd0-11e8-8067-000c299a5e15/pod-i-pv-prebound-w-provisioned
I1119 15:56:42.111608  127596 scheduler.go:508] Attempting to schedule pod: volume-schedulinga42c7715-ebd0-11e8-8067-000c299a5e15/pod-i-pv-prebound-w-provisioned
I1119 15:56:42.111672  127596 scheduler_binder.go:147] FindPodVolumes for pod "volume-schedulinga42c7715-ebd0-11e8-8067-000c299a5e15/pod-i-pv-prebound-w-provisioned", node "node-1"
I1119 15:56:42.111686  127596 scheduler_binder.go:458] PVC "volume-schedulinga42c7715-ebd0-11e8-8067-000c299a5e15/pvc-i-pv-prebound" is fully bound to PV "pv-i-prebound"
I1119 15:56:42.111696  127596 scheduler_binder.go:458] PVC "volume-schedulinga42c7715-ebd0-11e8-8067-000c299a5e15/pvc-canprovision" is fully bound to PV "pvc-a693d4b0-ebd0-11e8-8067-000c299a5e15"
I1119 15:56:42.111712  127596 scheduler_binder.go:529] PersistentVolume "pv-i-prebound", Node "node-1" matches for Pod "volume-schedulinga42c7715-ebd0-11e8-8067-000c299a5e15/pod-i-pv-prebound-w-provisioned"
I1119 15:56:42.111717  127596 scheduler_binder.go:529] PersistentVolume "pvc-a693d4b0-ebd0-11e8-8067-000c299a5e15", Node "node-1" matches for Pod "volume-schedulinga42c7715-ebd0-11e8-8067-000c299a5e15/pod-i-pv-prebound-w-provisioned"
I1119 15:56:42.111726  127596 scheduler_binder.go:532] All bound volumes for Pod "volume-schedulinga42c7715-ebd0-11e8-8067-000c299a5e15/pod-i-pv-prebound-w-provisioned" match with Node "node-1"
I1119 15:56:42.111750  127596 scheduler_binder.go:207] AssumePodVolumes for pod "volume-schedulinga42c7715-ebd0-11e8-8067-000c299a5e15/pod-i-pv-prebound-w-provisioned", node "node-1"
I1119 15:56:42.111775  127596 scheduler_binder.go:458] PVC "volume-schedulinga42c7715-ebd0-11e8-8067-000c299a5e15/pvc-i-pv-prebound" is fully bound to PV "pv-i-prebound"
I1119 15:56:42.111786  127596 scheduler_binder.go:458] PVC "volume-schedulinga42c7715-ebd0-11e8-8067-000c299a5e15/pvc-canprovision" is fully bound to PV "pvc-a693d4b0-ebd0-11e8-8067-000c299a5e15"
I1119 15:56:42.111792  127596 scheduler_binder.go:217] AssumePodVolumes for pod "volume-schedulinga42c7715-ebd0-11e8-8067-000c299a5e15/pod-i-pv-prebound-w-provisioned", node "node-1": all PVCs bound and nothing to do
E1119 15:56:42.111799  127596 scheduler.go:433] scheduler cache AssumePod failed: pod a6940066-ebd0-11e8-8067-000c299a5e15 is in the cache, so can't be assumed
E1119 15:56:42.111804  127596 factory.go:1465] Error scheduling volume-schedulinga42c7715-ebd0-11e8-8067-000c299a5e15/pod-i-pv-prebound-w-provisioned: pod a6940066-ebd0-11e8-8067-000c299a5e15 is in the cache, so can't be assumed; retrying
I1119 15:56:42.111824  127596 factory.go:1558] Updating pod condition for volume-schedulinga42c7715-ebd0-11e8-8067-000c299a5e15/pod-i-pv-prebound-w-provisioned to (PodScheduled==False)
E1119 15:56:42.111831  127596 scheduler.go:556] error assuming pod: pod a6940066-ebd0-11e8-8067-000c299a5e15 is in the cache, so can't be assumed
I1119 15:56:42.112858  127596 factory.go:1338] About to try and schedule pod volume-schedulinga42c7715-ebd0-11e8-8067-000c299a5e15/pod-i-pv-prebound-w-provisioned
I1119 15:56:42.112888  127596 scheduler.go:508] Attempting to schedule pod: volume-schedulinga42c7715-ebd0-11e8-8067-000c299a5e15/pod-i-pv-prebound-w-provisioned
I1119 15:56:42.112980  127596 scheduler_binder.go:147] FindPodVolumes for pod "volume-schedulinga42c7715-ebd0-11e8-8067-000c299a5e15/pod-i-pv-prebound-w-provisioned", node "node-1"
I1119 15:56:42.115236  127596 scheduler_binder.go:458] PVC "volume-schedulinga42c7715-ebd0-11e8-8067-000c299a5e15/pvc-i-pv-prebound" is fully bound to PV "pv-i-prebound"
I1119 15:56:42.115312  127596 scheduler_binder.go:458] PVC "volume-schedulinga42c7715-ebd0-11e8-8067-000c299a5e15/pvc-canprovision" is fully bound to PV "pvc-a693d4b0-ebd0-11e8-8067-000c299a5e15"
I1119 15:56:42.115342  127596 scheduler_binder.go:529] PersistentVolume "pv-i-prebound", Node "node-1" matches for Pod "volume-schedulinga42c7715-ebd0-11e8-8067-000c299a5e15/pod-i-pv-prebound-w-provisioned"
I1119 15:56:42.115355  127596 scheduler_binder.go:529] PersistentVolume "pvc-a693d4b0-ebd0-11e8-8067-000c299a5e15", Node "node-1" matches for Pod "volume-schedulinga42c7715-ebd0-11e8-8067-000c299a5e15/pod-i-pv-prebound-w-provisioned"
I1119 15:56:42.115401  127596 scheduler_binder.go:532] All bound volumes for Pod "volume-schedulinga42c7715-ebd0-11e8-8067-000c299a5e15/pod-i-pv-prebound-w-provisioned" match with Node "node-1"
I1119 15:56:42.115706  127596 scheduler_binder.go:207] AssumePodVolumes for pod "volume-schedulinga42c7715-ebd0-11e8-8067-000c299a5e15/pod-i-pv-prebound-w-provisioned", node "node-1"
I1119 15:56:42.115728  127596 scheduler_binder.go:458] PVC "volume-schedulinga42c7715-ebd0-11e8-8067-000c299a5e15/pvc-i-pv-prebound" is fully bound to PV "pv-i-prebound"
I1119 15:56:42.115736  127596 scheduler_binder.go:458] PVC "volume-schedulinga42c7715-ebd0-11e8-8067-000c299a5e15/pvc-canprovision" is fully bound to PV "pvc-a693d4b0-ebd0-11e8-8067-000c299a5e15"
I1119 15:56:42.115743  127596 scheduler_binder.go:217] AssumePodVolumes for pod "volume-schedulinga42c7715-ebd0-11e8-8067-000c299a5e15/pod-i-pv-prebound-w-provisioned", node "node-1": all PVCs bound and nothing to do
E1119 15:56:42.115753  127596 scheduler.go:433] scheduler cache AssumePod failed: pod a6940066-ebd0-11e8-8067-000c299a5e15 is in the cache, so can't be assumed
E1119 15:56:42.115760  127596 factory.go:1465] Error scheduling volume-schedulinga42c7715-ebd0-11e8-8067-000c299a5e15/pod-i-pv-prebound-w-provisioned: pod a6940066-ebd0-11e8-8067-000c299a5e15 is in the cache, so can't be assumed; retrying
I1119 15:56:42.115790  127596 factory.go:1558] Updating pod condition for volume-schedulinga42c7715-ebd0-11e8-8067-000c299a5e15/pod-i-pv-prebound-w-provisioned to (PodScheduled==False)
E1119 15:56:42.115799  127596 scheduler.go:556] error assuming pod: pod a6940066-ebd0-11e8-8067-000c299a5e15 is in the cache, so can't be assumed
I1119 15:56:42.117319  127596 factory.go:1338] About to try and schedule pod volume-schedulinga42c7715-ebd0-11e8-8067-000c299a5e15/pod-i-pv-prebound-w-provisioned
I1119 15:56:42.117344  127596 scheduler.go:508] Attempting to schedule pod: volume-schedulinga42c7715-ebd0-11e8-8067-000c299a5e15/pod-i-pv-prebound-w-provisioned
I1119 15:56:42.117409  127596 scheduler_binder.go:147] FindPodVolumes for pod "volume-schedulinga42c7715-ebd0-11e8-8067-000c299a5e15/pod-i-pv-prebound-w-provisioned", node "node-1"
I1119 15:56:42.117426  127596 scheduler_binder.go:458] PVC "volume-schedulinga42c7715-ebd0-11e8-8067-000c299a5e15/pvc-i-pv-prebound" is fully bound to PV "pv-i-prebound"
I1119 15:56:42.117431  127596 scheduler_binder.go:458] PVC "volume-schedulinga42c7715-ebd0-11e8-8067-000c299a5e15/pvc-canprovision" is fully bound to PV "pvc-a693d4b0-ebd0-11e8-8067-000c299a5e15"
I1119 15:56:42.117446  127596 scheduler_binder.go:529] PersistentVolume "pv-i-prebound", Node "node-1" matches for Pod "volume-schedulinga42c7715-ebd0-11e8-8067-000c299a5e15/pod-i-pv-prebound-w-provisioned"
I1119 15:56:42.117454  127596 scheduler_binder.go:529] PersistentVolume "pvc-a693d4b0-ebd0-11e8-8067-000c299a5e15", Node "node-1" matches for Pod "volume-schedulinga42c7715-ebd0-11e8-8067-000c299a5e15/pod-i-pv-prebound-w-provisioned"
I1119 15:56:42.117458  127596 scheduler_binder.go:532] All bound volumes for Pod "volume-schedulinga42c7715-ebd0-11e8-8067-000c299a5e15/pod-i-pv-prebound-w-provisioned" match with Node "node-1"
I1119 15:56:42.117494  127596 scheduler_binder.go:207] AssumePodVolumes for pod "volume-schedulinga42c7715-ebd0-11e8-8067-000c299a5e15/pod-i-pv-prebound-w-provisioned", node "node-1"
I1119 15:56:42.117503  127596 scheduler_binder.go:458] PVC "volume-schedulinga42c7715-ebd0-11e8-8067-000c299a5e15/pvc-i-pv-prebound" is fully bound to PV "pv-i-prebound"
I1119 15:56:42.117507  127596 scheduler_binder.go:458] PVC "volume-schedulinga42c7715-ebd0-11e8-8067-000c299a5e15/pvc-canprovision" is fully bound to PV "pvc-a693d4b0-ebd0-11e8-8067-000c299a5e15"
I1119 15:56:42.117512  127596 scheduler_binder.go:217] AssumePodVolumes for pod "volume-schedulinga42c7715-ebd0-11e8-8067-000c299a5e15/pod-i-pv-prebound-w-provisioned", node "node-1": all PVCs bound and nothing to do
E1119 15:56:42.117519  127596 scheduler.go:433] scheduler cache AssumePod failed: pod a6940066-ebd0-11e8-8067-000c299a5e15 is in the cache, so can't be assumed
E1119 15:56:42.117535  127596 factory.go:1465] Error scheduling volume-schedulinga42c7715-ebd0-11e8-8067-000c299a5e15/pod-i-pv-prebound-w-provisioned: pod a6940066-ebd0-11e8-8067-000c299a5e15 is in the cache, so can't be assumed; retrying
I1119 15:56:42.117552  127596 factory.go:1558] Updating pod condition for volume-schedulinga42c7715-ebd0-11e8-8067-000c299a5e15/pod-i-pv-prebound-w-provisioned to (PodScheduled==False)
E1119 15:56:42.117557  127596 scheduler.go:556] error assuming pod: pod a6940066-ebd0-11e8-8067-000c299a5e15 is in the cache, so can't be assumed
I1119 15:56:42.118697  127596 factory.go:1338] About to try and schedule pod volume-schedulinga42c7715-ebd0-11e8-8067-000c299a5e15/pod-i-pv-prebound-w-provisioned
I1119 15:56:42.118720  127596 scheduler.go:508] Attempting to schedule pod: volume-schedulinga42c7715-ebd0-11e8-8067-000c299a5e15/pod-i-pv-prebound-w-provisioned
I1119 15:56:42.118759  127596 scheduler_binder.go:147] FindPodVolumes for pod "volume-schedulinga42c7715-ebd0-11e8-8067-000c299a5e15/pod-i-pv-prebound-w-provisioned", node "node-1"
I1119 15:56:42.118773  127596 scheduler_binder.go:458] PVC "volume-schedulinga42c7715-ebd0-11e8-8067-000c299a5e15/pvc-i-pv-prebound" is fully bound to PV "pv-i-prebound"
I1119 15:56:42.118778  127596 scheduler_binder.go:458] PVC "volume-schedulinga42c7715-ebd0-11e8-8067-000c299a5e15/pvc-canprovision" is fully bound to PV "pvc-a693d4b0-ebd0-11e8-8067-000c299a5e15"
I1119 15:56:42.118792  127596 scheduler_binder.go:529] PersistentVolume "pv-i-prebound", Node "node-1" matches for Pod "volume-schedulinga42c7715-ebd0-11e8-8067-000c299a5e15/pod-i-pv-prebound-w-provisioned"
I1119 15:56:42.118796  127596 scheduler_binder.go:529] PersistentVolume "pvc-a693d4b0-ebd0-11e8-8067-000c299a5e15", Node "node-1" matches for Pod "volume-schedulinga42c7715-ebd0-11e8-8067-000c299a5e15/pod-i-pv-prebound-w-provisioned"
I1119 15:56:42.118801  127596 scheduler_binder.go:532] All bound volumes for Pod "volume-schedulinga42c7715-ebd0-11e8-8067-000c299a5e15/pod-i-pv-prebound-w-provisioned" match with Node "node-1"
I1119 15:56:42.118837  127596 scheduler_binder.go:207] AssumePodVolumes for pod "volume-schedulinga42c7715-ebd0-11e8-8067-000c299a5e15/pod-i-pv-prebound-w-provisioned", node "node-1"
I1119 15:56:42.118860  127596 scheduler_binder.go:458] PVC "volume-schedulinga42c7715-ebd0-11e8-8067-000c299a5e15/pvc-i-pv-prebound" is fully bound to PV "pv-i-prebound"
I1119 15:56:42.118866  127596 scheduler_binder.go:458] PVC "volume-schedulinga42c7715-ebd0-11e8-8067-000c299a5e15/pvc-canprovision" is fully bound to PV "pvc-a693d4b0-ebd0-11e8-8067-000c299a5e15"
I1119 15:56:42.118873  127596 scheduler_binder.go:217] AssumePodVolumes for pod "volume-schedulinga42c7715-ebd0-11e8-8067-000c299a5e15/pod-i-pv-prebound-w-provisioned", node "node-1": all PVCs bound and nothing to do
E1119 15:56:42.118879  127596 scheduler.go:433] scheduler cache AssumePod failed: pod a6940066-ebd0-11e8-8067-000c299a5e15 is in the cache, so can't be assumed
E1119 15:56:42.118883  127596 factory.go:1465] Error scheduling volume-schedulinga42c7715-ebd0-11e8-8067-000c299a5e15/pod-i-pv-prebound-w-provisioned: pod a6940066-ebd0-11e8-8067-000c299a5e15 is in the cache, so can't be assumed; retrying
I1119 15:56:42.118912  127596 factory.go:1558] Updating pod condition for volume-schedulinga42c7715-ebd0-11e8-8067-000c299a5e15/pod-i-pv-prebound-w-provisioned to (PodScheduled==False)
E1119 15:56:42.118920  127596 scheduler.go:556] error assuming pod: pod a6940066-ebd0-11e8-8067-000c299a5e15 is in the cache, so can't be assumed
I1119 15:56:42.120047  127596 factory.go:1338] About to try and schedule pod volume-schedulinga42c7715-ebd0-11e8-8067-000c299a5e15/pod-i-pv-prebound-w-provisioned
I1119 15:56:42.120069  127596 scheduler.go:508] Attempting to schedule pod: volume-schedulinga42c7715-ebd0-11e8-8067-000c299a5e15/pod-i-pv-prebound-w-provisioned
I1119 15:56:42.120108  127596 scheduler_binder.go:147] FindPodVolumes for pod "volume-schedulinga42c7715-ebd0-11e8-8067-000c299a5e15/pod-i-pv-prebound-w-provisioned", node "node-1"
I1119 15:56:42.120121  127596 scheduler_binder.go:458] PVC "volume-schedulinga42c7715-ebd0-11e8-8067-000c299a5e15/pvc-i-pv-prebound" is fully bound to PV "pv-i-prebound"
I1119 15:56:42.120126  127596 scheduler_binder.go:458] PVC "volume-schedulinga42c7715-ebd0-11e8-8067-000c299a5e15/pvc-canprovision" is fully bound to PV "pvc-a693d4b0-ebd0-11e8-8067-000c299a5e15"
I1119 15:56:42.120139  127596 scheduler_binder.go:529] PersistentVolume "pv-i-prebound", Node "node-1" matches for Pod "volume-schedulinga42c7715-ebd0-11e8-8067-000c299a5e15/pod-i-pv-prebound-w-provisioned"
I1119 15:56:42.120145  127596 scheduler_binder.go:529] PersistentVolume "pvc-a693d4b0-ebd0-11e8-8067-000c299a5e15", Node "node-1" matches for Pod "volume-schedulinga42c7715-ebd0-11e8-8067-000c299a5e15/pod-i-pv-prebound-w-provisioned"
I1119 15:56:42.120150  127596 scheduler_binder.go:532] All bound volumes for Pod "volume-schedulinga42c7715-ebd0-11e8-8067-000c299a5e15/pod-i-pv-prebound-w-provisioned" match with Node "node-1"
I1119 15:56:42.120166  127596 scheduler_binder.go:207] AssumePodVolumes for pod "volume-schedulinga42c7715-ebd0-11e8-8067-000c299a5e15/pod-i-pv-prebound-w-provisioned", node "node-1"
I1119 15:56:42.120187  127596 scheduler_binder.go:458] PVC "volume-schedulinga42c7715-ebd0-11e8-8067-000c299a5e15/pvc-i-pv-prebound" is fully bound to PV "pv-i-prebound"
I1119 15:56:42.120193  127596 scheduler_binder.go:458] PVC "volume-schedulinga42c7715-ebd0-11e8-8067-000c299a5e15/pvc-canprovision" is fully bound to PV "pvc-a693d4b0-ebd0-11e8-8067-000c299a5e15"
I1119 15:56:42.120198  127596 scheduler_binder.go:217] AssumePodVolumes for pod "volume-schedulinga42c7715-ebd0-11e8-8067-000c299a5e15/pod-i-pv-prebound-w-provisioned", node "node-1": all PVCs bound and nothing to do
E1119 15:56:42.120204  127596 scheduler.go:433] scheduler cache AssumePod failed: pod a6940066-ebd0-11e8-8067-000c299a5e15 is in the cache, so can't be assumed
E1119 15:56:42.120208  127596 factory.go:1465] Error scheduling volume-schedulinga42c7715-ebd0-11e8-8067-000c299a5e15/pod-i-pv-prebound-w-provisioned: pod a6940066-ebd0-11e8-8067-000c299a5e15 is in the cache, so can't be assumed; retrying
I1119 15:56:42.120221  127596 factory.go:1558] Updating pod condition for volume-schedulinga42c7715-ebd0-11e8-8067-000c299a5e15/pod-i-pv-prebound-w-provisioned to (PodScheduled==False)
E1119 15:56:42.120226  127596 scheduler.go:556] error assuming pod: pod a6940066-ebd0-11e8-8067-000c299a5e15 is in the cache, so can't be assumed
I1119 15:56:42.121264  127596 factory.go:1338] About to try and schedule pod volume-schedulinga42c7715-ebd0-11e8-8067-000c299a5e15/pod-i-pv-prebound-w-provisioned
I1119 15:56:42.121286  127596 scheduler.go:508] Attempting to schedule pod: volume-schedulinga42c7715-ebd0-11e8-8067-000c299a5e15/pod-i-pv-prebound-w-provisioned
I1119 15:56:42.121336  127596 scheduler_binder.go:147] FindPodVolumes for pod "volume-schedulinga42c7715-ebd0-11e8-8067-000c299a5e15/pod-i-pv-prebound-w-provisioned", node "node-1"
I1119 15:56:42.121400  127596 scheduler_binder.go:458] PVC "volume-schedulinga42c7715-ebd0-11e8-8067-000c299a5e15/pvc-i-pv-prebound" is fully bound to PV "pv-i-prebound"
I1119 15:56:42.121407  127596 scheduler_binder.go:458] PVC "volume-schedulinga42c7715-ebd0-11e8-8067-000c299a5e15/pvc-canprovision" is fully bound to PV "pvc-a693d4b0-ebd0-11e8-8067-000c299a5e15"
I1119 15:56:42.121420  127596 scheduler_binder.go:529] PersistentVolume "pv-i-prebound", Node "node-1" matches for Pod "volume-schedulinga42c7715-ebd0-11e8-8067-000c299a5e15/pod-i-pv-prebound-w-provisioned"
I1119 15:56:42.121425  127596 scheduler_binder.go:529] PersistentVolume "pvc-a693d4b0-ebd0-11e8-8067-000c299a5e15", Node "node-1" matches for Pod "volume-schedulinga42c7715-ebd0-11e8-8067-000c299a5e15/pod-i-pv-prebound-w-provisioned"
I1119 15:56:42.121429  127596 scheduler_binder.go:532] All bound volumes for Pod "volume-schedulinga42c7715-ebd0-11e8-8067-000c299a5e15/pod-i-pv-prebound-w-provisioned" match with Node "node-1"
I1119 15:56:42.121486  127596 scheduler_binder.go:207] AssumePodVolumes for pod "volume-schedulinga42c7715-ebd0-11e8-8067-000c299a5e15/pod-i-pv-prebound-w-provisioned", node "node-1"
I1119 15:56:42.121507  127596 scheduler_binder.go:458] PVC "volume-schedulinga42c7715-ebd0-11e8-8067-000c299a5e15/pvc-i-pv-prebound" is fully bound to PV "pv-i-prebound"
I1119 15:56:42.121514  127596 scheduler_binder.go:458] PVC "volume-schedulinga42c7715-ebd0-11e8-8067-000c299a5e15/pvc-canprovision" is fully bound to PV "pvc-a693d4b0-ebd0-11e8-8067-000c299a5e15"
I1119 15:56:42.121519  127596 scheduler_binder.go:217] AssumePodVolumes for pod "volume-schedulinga42c7715-ebd0-11e8-8067-000c299a5e15/pod-i-pv-prebound-w-provisioned", node "node-1": all PVCs bound and nothing to do
E1119 15:56:42.121542  127596 scheduler.go:433] scheduler cache AssumePod failed: pod a6940066-ebd0-11e8-8067-000c299a5e15 is in the cache, so can't be assumed
E1119 15:56:42.121547  127596 factory.go:1465] Error scheduling volume-schedulinga42c7715-ebd0-11e8-8067-000c299a5e15/pod-i-pv-prebound-w-provisioned: pod a6940066-ebd0-11e8-8067-000c299a5e15 is in the cache, so can't be assumed; retrying
I1119 15:56:42.121610  127596 factory.go:1558] Updating pod condition for volume-schedulinga42c7715-ebd0-11e8-8067-000c299a5e15/pod-i-pv-prebound-w-provisioned to (PodScheduled==False)
E1119 15:56:42.121619  127596 scheduler.go:556] error assuming pod: pod a6940066-ebd0-11e8-8067-000c299a5e15 is in the cache, so can't be assumed
I1119 15:56:42.122656  127596 factory.go:1338] About to try and schedule pod volume-schedulinga42c7715-ebd0-11e8-8067-000c299a5e15/pod-i-pv-prebound-w-provisioned
I1119 15:56:42.122679  127596 scheduler.go:508] Attempting to schedule pod: volume-schedulinga42c7715-ebd0-11e8-8067-000c299a5e15/pod-i-pv-prebound-w-provisioned
I1119 15:56:42.122730  127596 scheduler_binder.go:147] FindPodVolumes for pod "volume-schedulinga42c7715-ebd0-11e8-8067-000c299a5e15/pod-i-pv-prebound-w-provisioned", node "node-1"
I1119 15:56:42.122745  127596 scheduler_binder.go:458] PVC "volume-schedulinga42c7715-ebd0-11e8-8067-000c299a5e15/pvc-i-pv-prebound" is fully bound to PV "pv-i-prebound"
I1119 15:56:42.122750  127596 scheduler_binder.go:458] PVC "volume-schedulinga42c7715-ebd0-11e8-8067-000c299a5e15/pvc-canprovision" is fully bound to PV "pvc-a693d4b0-ebd0-11e8-8067-000c299a5e15"
I1119 15:56:42.122763  127596 scheduler_binder.go:529] PersistentVolume "pv-i-prebound", Node "node-1" matches for Pod "volume-schedulinga42c7715-ebd0-11e8-8067-000c299a5e15/pod-i-pv-prebound-w-provisioned"
I1119 15:56:42.122769  127596 scheduler_binder.go:529] PersistentVolume "pvc-a693d4b0-ebd0-11e8-8067-000c299a5e15", Node "node-1" matches for Pod "volume-schedulinga42c7715-ebd0-11e8-8067-000c299a5e15/pod-i-pv-prebound-w-provisioned"
I1119 15:56:42.122774  127596 scheduler_binder.go:532] All bound volumes for Pod "volume-schedulinga42c7715-ebd0-11e8-8067-000c299a5e15/pod-i-pv-prebound-w-provisioned" match with Node "node-1"
I1119 15:56:42.122805  127596 scheduler_binder.go:207] AssumePodVolumes for pod "volume-schedulinga42c7715-ebd0-11e8-8067-000c299a5e15/pod-i-pv-prebound-w-provisioned", node "node-1"
I1119 15:56:42.122827  127596 scheduler_binder.go:458] PVC "volume-schedulinga42c7715-ebd0-11e8-8067-000c299a5e15/pvc-i-pv-prebound" is fully bound to PV "pv-i-prebound"
I1119 15:56:42.122833  127596 scheduler_binder.go:458] PVC "volume-schedulinga42c7715-ebd0-11e8-8067-000c299a5e15/pvc-canprovision" is fully bound to PV "pvc-a693d4b0-ebd0-11e8-8067-000c299a5e15"
I1119 15:56:42.122838  127596 scheduler_binder.go:217] AssumePodVolumes for pod "volume-schedulinga42c7715-ebd0-11e8-8067-000c299a5e15/pod-i-pv-prebound-w-provisioned", node "node-1": all PVCs bound and nothing to do
E1119 15:56:42.122844  127596 scheduler.go:433] scheduler cache AssumePod failed: pod a6940066-ebd0-11e8-8067-000c299a5e15 is in the cache, so can't be assumed
E1119 15:56:42.122848  127596 factory.go:1465] Error scheduling volume-schedulinga42c7715-ebd0-11e8-8067-000c299a5e15/pod-i-pv-prebound-w-provisioned: pod a6940066-ebd0-11e8-8067-000c299a5e15 is in the cache, so can't be assumed; retrying
I1119 15:56:42.122876  127596 factory.go:1558] Updating pod condition for volume-schedulinga42c7715-ebd0-11e8-8067-000c299a5e15/pod-i-pv-prebound-w-provisioned to (PodScheduled==False)
E1119 15:56:42.122883  127596 scheduler.go:556] error assuming pod: pod a6940066-ebd0-11e8-8067-000c299a5e15 is in the cache, so can't be assumed
I1119 15:56:42.123905  127596 factory.go:1338] About to try and schedule pod volume-schedulinga42c7715-ebd0-11e8-8067-000c299a5e15/pod-i-pv-prebound-w-provisioned
I1119 15:56:42.123928  127596 scheduler.go:508] Attempting to schedule pod: volume-schedulinga42c7715-ebd0-11e8-8067-000c299a5e15/pod-i-pv-prebound-w-provisioned
I1119 15:56:42.124014  127596 scheduler_binder.go:147] FindPodVolumes for pod "volume-schedulinga42c7715-ebd0-11e8-8067-000c299a5e15/pod-i-pv-prebound-w-provisioned", node "node-1"
I1119 15:56:42.124044  127596 scheduler_binder.go:458] PVC "volume-schedulinga42c7715-ebd0-11e8-8067-000c299a5e15/pvc-i-pv-prebound" is fully bound to PV "pv-i-prebound"
I1119 15:56:42.124051  127596 scheduler_binder.go:458] PVC "volume-schedulinga42c7715-ebd0-11e8-8067-000c299a5e15/pvc-canprovision" is fully bound to PV "pvc-a693d4b0-ebd0-11e8-8067-000c299a5e15"
I1119 15:56:42.124064  127596 scheduler_binder.go:529] PersistentVolume "pv-i-prebound", Node "node-1" matches for Pod "volume-schedulinga42c7715-ebd0-11e8-8067-000c299a5e15/pod-i-pv-prebound-w-provisioned"
I1119 15:56:42.124069  127596 scheduler_binder.go:529] PersistentVolume "pvc-a693d4b0-ebd0-11e8-8067-000c299a5e15", Node "node-1" matches for Pod "volume-schedulinga42c7715-ebd0-11e8-8067-000c299a5e15/pod-i-pv-prebound-w-provisioned"
I1119 15:56:42.124074  127596 scheduler_binder.go:532] All bound volumes for Pod "volume-schedulinga42c7715-ebd0-11e8-8067-000c299a5e15/pod-i-pv-prebound-w-provisioned" match with Node "node-1"
I1119 15:56:42.124139  127596 scheduler_binder.go:207] AssumePodVolumes for pod "volume-schedulinga42c7715-ebd0-11e8-8067-000c299a5e15/pod-i-pv-prebound-w-provisioned", node "node-1"
I1119 15:56:42.124160  127596 scheduler_binder.go:458] PVC "volume-schedulinga42c7715-ebd0-11e8-8067-000c299a5e15/pvc-i-pv-prebound" is fully bound to PV "pv-i-prebound"
I1119 15:56:42.124166  127596 scheduler_binder.go:458] PVC "volume-schedulinga42c7715-ebd0-11e8-8067-000c299a5e15/pvc-canprovision" is fully bound to PV "pvc-a693d4b0-ebd0-11e8-8067-000c299a5e15"
I1119 15:56:42.124172  127596 scheduler_binder.go:217] AssumePodVolumes for pod "volume-schedulinga42c7715-ebd0-11e8-8067-000c299a5e15/pod-i-pv-prebound-w-provisioned", node "node-1": all PVCs bound and nothing to do
E1119 15:56:42.124178  127596 scheduler.go:433] scheduler cache AssumePod failed: pod a6940066-ebd0-11e8-8067-000c299a5e15 is in the cache, so can't be assumed
E1119 15:56:42.124182  127596 factory.go:1465] Error scheduling volume-schedulinga42c7715-ebd0-11e8-8067-000c299a5e15/pod-i-pv-prebound-w-provisioned: pod a6940066-ebd0-11e8-8067-000c299a5e15 is in the cache, so can't be assumed; retrying
I1119 15:56:42.124249  127596 factory.go:1558] Updating pod condition for volume-schedulinga42c7715-ebd0-11e8-8067-000c299a5e15/pod-i-pv-prebound-w-provisioned to (PodScheduled==False)
E1119 15:56:42.124259  127596 scheduler.go:556] error assuming pod: pod a6940066-ebd0-11e8-8067-000c299a5e15 is in the cache, so can't be assumed
I1119 15:56:42.125419  127596 factory.go:1338] About to try and schedule pod volume-schedulinga42c7715-ebd0-11e8-8067-000c299a5e15/pod-i-pv-prebound-w-provisioned
I1119 15:56:42.125444  127596 scheduler.go:508] Attempting to schedule pod: volume-schedulinga42c7715-ebd0-11e8-8067-000c299a5e15/pod-i-pv-prebound-w-provisioned
I1119 15:56:42.125485  127596 scheduler_binder.go:147] FindPodVolumes for pod "volume-schedulinga42c7715-ebd0-11e8-8067-000c299a5e15/pod-i-pv-prebound-w-provisioned", node "node-1"
I1119 15:56:42.125499  127596 scheduler_binder.go:458] PVC "volume-schedulinga42c7715-ebd0-11e8-8067-000c299a5e15/pvc-i-pv-prebound" is fully bound to PV "pv-i-prebound"
I1119 15:56:42.125504  127596 scheduler_binder.go:458] PVC "volume-schedulinga42c7715-ebd0-11e8-8067-000c299a5e15/pvc-canprovision" is fully bound to PV "pvc-a693d4b0-ebd0-11e8-8067-000c299a5e15"
I1119 15:56:42.125517  127596 scheduler_binder.go:529] PersistentVolume "pv-i-prebound", Node "node-1" matches for Pod "volume-schedulinga42c7715-ebd0-11e8-8067-000c299a5e15/pod-i-pv-prebound-w-provisioned"
I1119 15:56:42.125538  127596 scheduler_binder.go:529] PersistentVolume "pvc-a693d4b0-ebd0-11e8-8067-000c299a5e15", Node "node-1" matches for Pod "volume-schedulinga42c7715-ebd0-11e8-8067-000c299a5e15/pod-i-pv-prebound-w-provisioned"
I1119 15:56:42.125544  127596 scheduler_binder.go:532] All bound volumes for Pod "volume-schedulinga42c7715-ebd0-11e8-8067-000c299a5e15/pod-i-pv-prebound-w-provisioned" match with Node "node-1"
I1119 15:56:42.125560  127596 scheduler_binder.go:207] AssumePodVolumes for pod "volume-schedulinga42c7715-ebd0-11e8-8067-000c299a5e15/pod-i-pv-prebound-w-provisioned", node "node-1"
I1119 15:56:42.125566  127596 scheduler_binder.go:458] PVC "volume-schedulinga42c7715-ebd0-11e8-8067-000c299a5e15/pvc-i-pv-prebound" is fully bound to PV "pv-i-prebound"
I1119 15:56:42.125571  127596 scheduler_binder.go:458] PVC "volume-schedulinga42c7715-ebd0-11e8-8067-000c299a5e15/pvc-canprovision" is fully bound to PV "pvc-a693d4b0-ebd0-11e8-8067-000c299a5e15"
I1119 15:56:42.125575  127596 scheduler_binder.go:217] AssumePodVolumes for pod "volume-schedulinga42c7715-ebd0-11e8-8067-000c299a5e15/pod-i-pv-prebound-w-provisioned", node "node-1": all PVCs bound and nothing to do
E1119 15:56:42.125581  127596 scheduler.go:433] scheduler cache AssumePod failed: pod a6940066-ebd0-11e8-8067-000c299a5e15 is in the cache, so can't be assumed
E1119 15:56:42.125585  127596 factory.go:1465] Error scheduling volume-schedulinga42c7715-ebd0-11e8-8067-000c299a5e15/pod-i-pv-prebound-w-provisioned: pod a6940066-ebd0-11e8-8067-000c299a5e15 is in the cache, so can't be assumed; retrying
I1119 15:56:42.125616  127596 factory.go:1558] Updating pod condition for volume-schedulinga42c7715-ebd0-11e8-8067-000c299a5e15/pod-i-pv-prebound-w-provisioned to (PodScheduled==False)
E1119 15:56:42.125637  127596 scheduler.go:556] error assuming pod: pod a6940066-ebd0-11e8-8067-000c299a5e15 is in the cache, so can't be assumed
I1119 15:56:42.126528  127596 factory.go:1338] About to try and schedule pod volume-schedulinga42c7715-ebd0-11e8-8067-000c299a5e15/pod-i-pv-prebound-w-provisioned
I1119 15:56:42.126552  127596 scheduler.go:508] Attempting to schedule pod: volume-schedulinga42c7715-ebd0-11e8-8067-000c299a5e15/pod-i-pv-prebound-w-provisioned
I1119 15:56:42.126607  127596 scheduler_binder.go:147] FindPodVolumes for pod "volume-schedulinga42c7715-ebd0-11e8-8067-000c299a5e15/pod-i-pv-prebound-w-provisioned", node "node-1"
I1119 15:56:42.126623  127596 scheduler_binder.go:458] PVC "volume-schedulinga42c7715-ebd0-11e8-8067-000c299a5e15/pvc-i-pv-prebound" is fully bound to PV "pv-i-prebound"
I1119 15:56:42.126628  127596 scheduler_binder.go:458] PVC "volume-schedulinga42c7715-ebd0-11e8-8067-000c299a5e15/pvc-canprovision" is fully bound to PV "pvc-a693d4b0-ebd0-11e8-8067-000c299a5e15"
I1119 15:56:42.126641  127596 scheduler_binder.go:529] PersistentVolume "pv-i-prebound", Node "node-1" matches for Pod "volume-schedulinga42c7715-ebd0-11e8-8067-000c299a5e15/pod-i-pv-prebound-w-provisioned"
I1119 15:56:42.126648  127596 scheduler_binder.go:529] PersistentVolume "pvc-a693d4b0-ebd0-11e8-8067-000c299a5e15", Node "node-1" matches for Pod "volume-schedulinga42c7715-ebd0-11e8-8067-000c299a5e15/pod-i-pv-prebound-w-provisioned"
I1119 15:56:42.126653  127596 scheduler_binder.go:532] All bound volumes for Pod "volume-schedulinga42c7715-ebd0-11e8-8067-000c299a5e15/pod-i-pv-prebound-w-provisioned" match with Node "node-1"
I1119 15:56:42.126685  127596 scheduler_binder.go:207] AssumePodVolumes for pod "volume-schedulinga42c7715-ebd0-11e8-8067-000c299a5e15/pod-i-pv-prebound-w-provisioned", node "node-1"
I1119 15:56:42.126693  127596 scheduler_binder.go:458] PVC "volume-schedulinga42c7715-ebd0-11e8-8067-000c299a5e15/pvc-i-pv-prebound" is fully bound to PV "pv-i-prebound"
I1119 15:56:42.126698  127596 scheduler_binder.go:458] PVC "volume-schedulinga42c7715-ebd0-11e8-8067-000c299a5e15/pvc-canprovision" is fully bound to PV "pvc-a693d4b0-ebd0-11e8-8067-000c299a5e15"
I1119 15:56:42.126703  127596 scheduler_binder.go:217] AssumePodVolumes for pod "volume-schedulinga42c7715-ebd0-11e8-8067-000c299a5e15/pod-i-pv-prebound-w-provisioned", node "node-1": all PVCs bound and nothing to do
E1119 15:56:42.126708  127596 scheduler.go:433] scheduler cache AssumePod failed: pod a6940066-ebd0-11e8-8067-000c299a5e15 is in the cache, so can't be assumed
E1119 15:56:42.126712  127596 factory.go:1465] Error scheduling volume-schedulinga42c7715-ebd0-11e8-8067-000c299a5e15/pod-i-pv-prebound-w-provisioned: pod a6940066-ebd0-11e8-8067-000c299a5e15 is in the cache, so can't be assumed; retrying
I1119 15:56:42.126741  127596 factory.go:1558] Updating pod condition for volume-schedulinga42c7715-ebd0-11e8-8067-000c299a5e15/pod-i-pv-prebound-w-provisioned to (PodScheduled==False)
E1119 15:56:42.126760  127596 scheduler.go:556] error assuming pod: pod a6940066-ebd0-11e8-8067-000c299a5e15 is in the cache, so can't be assumed
I1119 15:56:42.127766  127596 factory.go:1338] About to try and schedule pod volume-schedulinga42c7715-ebd0-11e8-8067-000c299a5e15/pod-i-pv-prebound-w-provisioned
I1119 15:56:42.127792  127596 scheduler.go:508] Attempting to schedule pod: volume-schedulinga42c7715-ebd0-11e8-8067-000c299a5e15/pod-i-pv-prebound-w-provisioned
I1119 15:56:42.127879  127596 scheduler_binder.go:147] FindPodVolumes for pod "volume-schedulinga42c7715-ebd0-11e8-8067-000c299a5e15/pod-i-pv-prebound-w-provisioned", node "node-1"
I1119 15:56:42.127908  127596 scheduler_binder.go:458] PVC "volume-schedulinga42c7715-ebd0-11e8-8067-000c299a5e15/pvc-i-pv-prebound" is fully bound to PV "pv-i-prebound"
I1119 15:56:42.127915  127596 scheduler_binder.go:458] PVC "volume-schedulinga42c7715-ebd0-11e8-8067-000c299a5e15/pvc-canprovision" is fully bound to PV "pvc-a693d4b0-ebd0-11e8-8067-000c299a5e15"
I1119 15:56:42.127929  127596 scheduler_binder.go:529] PersistentVolume "pv-i-prebound", Node "node-1" matches for Pod "volume-schedulinga42c7715-ebd0-11e8-8067-000c299a5e15/pod-i-pv-prebound-w-provisioned"
I1119 15:56:42.127933  127596 scheduler_binder.go:529] PersistentVolume "pvc-a693d4b0-ebd0-11e8-8067-000c299a5e15", Node "node-1" matches for Pod "volume-schedulinga42c7715-ebd0-11e8-8067-000c299a5e15/pod-i-pv-prebound-w-provisioned"
I1119 15:56:42.127938  127596 scheduler_binder.go:532] All bound volumes for Pod "volume-schedulinga42c7715-ebd0-11e8-8067-000c299a5e15/pod-i-pv-prebound-w-provisioned" match with Node "node-1"
I1119 15:56:42.128017  127596 scheduler_binder.go:207] AssumePodVolumes for pod "volume-schedulinga42c7715-ebd0-11e8-8067-000c299a5e15/pod-i-pv-prebound-w-provisioned", node "node-1"
I1119 15:56:42.128025  127596 scheduler_binder.go:458] PVC "volume-schedulinga42c7715-ebd0-11e8-8067-000c299a5e15/pvc-i-pv-prebound" is fully bound to PV "pv-i-prebound"
I1119 15:56:42.128029  127596 scheduler_binder.go:458] PVC "volume-schedulinga42c7715-ebd0-11e8-8067-000c299a5e15/pvc-canprovision" is fully bound to PV "pvc-a693d4b0-ebd0-11e8-8067-000c299a5e15"
I1119 15:56:42.128034  127596 scheduler_binder.go:217] AssumePodVolumes for pod "volume-schedulinga42c7715-ebd0-11e8-8067-000c299a5e15/pod-i-pv-prebound-w-provisioned", node "node-1": all PVCs bound and nothing to do
E1119 15:56:42.128039  127596 scheduler.go:433] scheduler cache AssumePod failed: pod a6940066-ebd0-11e8-8067-000c299a5e15 is in the cache, so can't be assumed
E1119 15:56:42.128044  127596 factory.go:1465] Error scheduling volume-schedulinga42c7715-ebd0-11e8-8067-000c299a5e15/pod-i-pv-prebound-w-provisioned: pod a6940066-ebd0-11e8-8067-000c299a5e15 is in the cache, so can't be assumed; retrying
I1119 15:56:42.128072  127596 factory.go:1558] Updating pod condition for volume-schedulinga42c7715-ebd0-11e8-8067-000c299a5e15/pod-i-pv-prebound-w-provisioned to (PodScheduled==False)
E1119 15:56:42.128079  127596 scheduler.go:556] error assuming pod: pod a6940066-ebd0-11e8-8067-000c299a5e15 is in the cache, so can't be assumed
I1119 15:56:42.129090  127596 factory.go:1338] About to try and schedule pod volume-schedulinga42c7715-ebd0-11e8-8067-000c299a5e15/pod-i-pv-prebound-w-provisioned
I1119 15:56:42.129112  127596 scheduler.go:508] Attempting to schedule pod: volume-schedulinga42c7715-ebd0-11e8-8067-000c299a5e15/pod-i-pv-prebound-w-provisioned
I1119 15:56:42.129146  127596 scheduler_binder.go:147] FindPodVolumes for pod "volume-schedulinga42c7715-ebd0-11e8-8067-000c299a5e15/pod-i-pv-prebound-w-provisioned", node "node-1"
I1119 15:56:42.129205  127596 scheduler_binder.go:458] PVC "volume-schedulinga42c7715-ebd0-11e8-8067-000c299a5e15/pvc-i-pv-prebound" is fully bound to PV "pv-i-prebound"
I1119 15:56:42.129212  127596 scheduler_binder.go:458] PVC "volume-schedulinga42c7715-ebd0-11e8-8067-000c299a5e15/pvc-canprovision" is fully bound to PV "pvc-a693d4b0-ebd0-11e8-8067-000c299a5e15"
I1119 15:56:42.129224  127596 scheduler_binder.go:529] PersistentVolume "pv-i-prebound", Node "node-1" matches for Pod "volume-schedulinga42c7715-ebd0-11e8-8067-000c299a5e15/pod-i-pv-prebound-w-provisioned"
I1119 15:56:42.129229  127596 scheduler_binder.go:529] PersistentVolume "pvc-a693d4b0-ebd0-11e8-8067-000c299a5e15", Node "node-1" matches for Pod "volume-schedulinga42c7715-ebd0-11e8-8067-000c299a5e15/pod-i-pv-prebound-w-provisioned"
I1119 15:56:42.129233  127596 scheduler_binder.go:532] All bound volumes for Pod "volume-schedulinga42c7715-ebd0-11e8-8067-000c299a5e15/pod-i-pv-prebound-w-provisioned" match with Node "node-1"
I1119 15:56:42.129295  127596 scheduler_binder.go:207] AssumePodVolumes for pod "volume-schedulinga42c7715-ebd0-11e8-8067-000c299a5e15/pod-i-pv-prebound-w-provisioned", node "node-1"
I1119 15:56:42.129305  127596 scheduler_binder.go:458] PVC "volume-schedulinga42c7715-ebd0-11e8-8067-000c299a5e15/pvc-i-pv-prebound" is fully bound to PV "pv-i-prebound"
I1119 15:56:42.129309  127596 scheduler_binder.go:458] PVC "volume-schedulinga42c7715-ebd0-11e8-8067-000c299a5e15/pvc-canprovision" is fully bound to PV "pvc-a693d4b0-ebd0-11e8-8067-000c299a5e15"
I1119 15:56:42.129314  127596 scheduler_binder.go:217] AssumePodVolumes for pod "volume-schedulinga42c7715-ebd0-11e8-8067-000c299a5e15/pod-i-pv-prebound-w-provisioned", node "node-1": all PVCs bound and nothing to do
E1119 15:56:42.129320  127596 scheduler.go:433] scheduler cache AssumePod failed: pod a6940066-ebd0-11e8-8067-000c299a5e15 is in the cache, so can't be assumed
E1119 15:56:42.129324  127596 factory.go:1465] Error scheduling volume-schedulinga42c7715-ebd0-11e8-8067-000c299a5e15/pod-i-pv-prebound-w-provisioned: pod a6940066-ebd0-11e8-8067-000c299a5e15 is in the cache, so can't be assumed; retrying
I1119 15:56:42.129335  127596 factory.go:1558] Updating pod condition for volume-schedulinga42c7715-ebd0-11e8-8067-000c299a5e15/pod-i-pv-prebound-w-provisioned to (PodScheduled==False)
E1119 15:56:42.129339  127596 scheduler.go:556] error assuming pod: pod a6940066-ebd0-11e8-8067-000c299a5e15 is in the cache, so can't be assumed
I1119 15:56:42.130202  127596 factory.go:1338] About to try and schedule pod volume-schedulinga42c7715-ebd0-11e8-8067-000c299a5e15/pod-i-pv-prebound-w-provisioned
I1119 15:56:42.130223  127596 scheduler.go:508] Attempting to schedule pod: volume-schedulinga42c7715-ebd0-11e8-8067-000c299a5e15/pod-i-pv-prebound-w-provisioned
I1119 15:56:42.130271  127596 scheduler_binder.go:147] FindPodVolumes for pod "volume-schedulinga42c7715-ebd0-11e8-8067-000c299a5e15/pod-i-pv-prebound-w-provisioned", node "node-1"
I1119 15:56:42.130286  127596 scheduler_binder.go:458] PVC "volume-schedulinga42c7715-ebd0-11e8-8067-000c299a5e15/pvc-i-pv-prebound" is fully bound to PV "pv-i-prebound"
I1119 15:56:42.130291  127596 scheduler_binder.go:458] PVC "volume-schedulinga42c7715-ebd0-11e8-8067-000c299a5e15/pvc-canprovision" is fully bound to PV "pvc-a693d4b0-ebd0-11e8-8067-000c299a5e15"
I1119 15:56:42.130303  127596 scheduler_binder.go:529] PersistentVolume "pv-i-prebound", Node "node-1" matches for Pod "volume-schedulinga42c7715-ebd0-11e8-8067-000c299a5e15/pod-i-pv-prebound-w-provisioned"
I1119 15:56:42.130310  127596 scheduler_binder.go:529] PersistentVolume "pvc-a693d4b0-ebd0-11e8-8067-000c299a5e15", Node "node-1" matches for Pod "volume-schedulinga42c7715-ebd0-11e8-8067-000c299a5e15/pod-i-pv-prebound-w-provisioned"
I1119 15:56:42.130314  127596 scheduler_binder.go:532] All bound volumes for Pod "volume-schedulinga42c7715-ebd0-11e8-8067-000c299a5e15/pod-i-pv-prebound-w-provisioned" match with Node "node-1"
I1119 15:56:42.130344  127596 scheduler_binder.go:207] AssumePodVolumes for pod "volume-schedulinga42c7715-ebd0-11e8-8067-000c299a5e15/pod-i-pv-prebound-w-provisioned", node "node-1"
I1119 15:56:42.130351  127596 scheduler_binder.go:458] PVC "volume-schedulinga42c7715-ebd0-11e8-8067-000c299a5e15/pvc-i-pv-prebound" is fully bound to PV "pv-i-prebound"
I1119 15:56:42.130355  127596 scheduler_binder.go:458] PVC "volume-schedulinga42c7715-ebd0-11e8-8067-000c299a5e15/pvc-canprovision" is fully bound to PV "pvc-a693d4b0-ebd0-11e8-8067-000c299a5e15"
I1119 15:56:42.130360  127596 scheduler_binder.go:217] AssumePodVolumes for pod "volume-schedulinga42c7715-ebd0-11e8-8067-000c299a5e15/pod-i-pv-prebound-w-provisioned", node "node-1": all PVCs bound and nothing to do
E1119 15:56:42.130365  127596 scheduler.go:433] scheduler cache AssumePod failed: pod a6940066-ebd0-11e8-8067-000c299a5e15 is in the cache, so can't be assumed
E1119 15:56:42.130369  127596 factory.go:1465] Error scheduling volume-schedulinga42c7715-ebd0-11e8-8067-000c299a5e15/pod-i-pv-prebound-w-provisioned: pod a6940066-ebd0-11e8-8067-000c299a5e15 is in the cache, so can't be assumed; retrying
I1119 15:56:42.130395  127596 factory.go:1558] Updating pod condition for volume-schedulinga42c7715-ebd0-11e8-8067-000c299a5e15/pod-i-pv-prebound-w-provisioned to (PodScheduled==False)
E1119 15:56:42.130416  127596 scheduler.go:556] error assuming pod: pod a6940066-ebd0-11e8-8067-000c299a5e15 is in the cache, so can't be assumed
I1119 15:56:42.131364  127596 factory.go:1338] About to try and schedule pod volume-schedulinga42c7715-ebd0-11e8-8067-000c299a5e15/pod-i-pv-prebound-w-provisioned
I1119 15:56:42.131385  127596 scheduler.go:508] Attempting to schedule pod: volume-schedulinga42c7715-ebd0-11e8-8067-000c299a5e15/pod-i-pv-prebound-w-provisioned
I1119 15:56:42.131434  127596 scheduler_binder.go:147] FindPodVolumes for pod "volume-schedulinga42c7715-ebd0-11e8-8067-000c299a5e15/pod-i-pv-prebound-w-provisioned", node "node-1"
I1119 15:56:42.131448  127596 scheduler_binder.go:458] PVC "volume-schedulinga42c7715-ebd0-11e8-8067-000c299a5e15/pvc-i-pv-prebound" is fully bound to PV "pv-i-prebound"
I1119 15:56:42.131452  127596 scheduler_binder.go:458] PVC "volume-schedulinga42c7715-ebd0-11e8-8067-000c299a5e15/pvc-canprovision" is fully bound to PV "pvc-a693d4b0-ebd0-11e8-8067-000c299a5e15"
I1119 15:56:42.131465  127596 scheduler_binder.go:529] PersistentVolume "pv-i-prebound", Node "node-1" matches for Pod "volume-schedulinga42c7715-ebd0-11e8-8067-000c299a5e15/pod-i-pv-prebound-w-provisioned"
I1119 15:56:42.131471  127596 scheduler_binder.go:529] PersistentVolume "pvc-a693d4b0-ebd0-11e8-8067-000c299a5e15", Node "node-1" matches for Pod "volume-schedulinga42c7715-ebd0-11e8-8067-000c299a5e15/pod-i-pv-prebound-w-provisioned"
I1119 15:56:42.131475  127596 scheduler_binder.go:532] All bound volumes for Pod "volume-schedulinga42c7715-ebd0-11e8-8067-000c299a5e15/pod-i-pv-prebound-w-provisioned" match with Node "node-1"
I1119 15:56:42.131506  127596 scheduler_binder.go:207] AssumePodVolumes for pod "volume-schedulinga42c7715-ebd0-11e8-8067-000c299a5e15/pod-i-pv-prebound-w-provisioned", node "node-1"
I1119 15:56:42.131514  127596 scheduler_binder.go:458] PVC "volume-schedulinga42c7715-ebd0-11e8-8067-000c299a5e15/pvc-i-pv-prebound" is fully bound to PV "pv-i-prebound"
I1119 15:56:42.131518  127596 scheduler_binder.go:458] PVC "volume-schedulinga42c7715-ebd0-11e8-8067-000c299a5e15/pvc-canprovision" is fully bound to PV "pvc-a693d4b0-ebd0-11e8-8067-000c299a5e15"
I1119 15:56:42.131523  127596 scheduler_binder.go:217] AssumePodVolumes for pod "volume-schedulinga42c7715-ebd0-11e8-8067-000c299a5e15/pod-i-pv-prebound-w-provisioned", node "node-1": all PVCs bound and nothing to do
E1119 15:56:42.131528  127596 scheduler.go:433] scheduler cache AssumePod failed: pod a6940066-ebd0-11e8-8067-000c299a5e15 is in the cache, so can't be assumed
E1119 15:56:42.131533  127596 factory.go:1465] Error scheduling volume-schedulinga42c7715-ebd0-11e8-8067-000c299a5e15/pod-i-pv-prebound-w-provisioned: pod a6940066-ebd0-11e8-8067-000c299a5e15 is in the cache, so can't be assumed; retrying
I1119 15:56:42.131559  127596 factory.go:1558] Updating pod condition for volume-schedulinga42c7715-ebd0-11e8-8067-000c299a5e15/pod-i-pv-prebound-w-provisioned to (PodScheduled==False)
E1119 15:56:42.131578  127596 scheduler.go:556] error assuming pod: pod a6940066-ebd0-11e8-8067-000c299a5e15 is in the cache, so can't be assumed
I1119 15:56:42.132461  127596 factory.go:1338] About to try and schedule pod volume-schedulinga42c7715-ebd0-11e8-8067-000c299a5e15/pod-i-pv-prebound-w-provisioned
I1119 15:56:42.132481  127596 scheduler.go:508] Attempting to schedule pod: volume-schedulinga42c7715-ebd0-11e8-8067-000c299a5e15/pod-i-pv-prebound-w-provisioned
I1119 15:56:42.132529  127596 scheduler_binder.go:147] FindPodVolumes for pod "volume-schedulinga42c7715-ebd0-11e8-8067-000c299a5e15/pod-i-pv-prebound-w-provisioned", node "node-1"
I1119 15:56:42.132543  127596 scheduler_binder.go:458] PVC "volume-schedulinga42c7715-ebd0-11e8-8067-000c299a5e15/pvc-i-pv-prebound" is fully bound to PV "pv-i-prebound"
I1119 15:56:42.132549  127596 scheduler_binder.go:458] PVC "volume-schedulinga42c7715-ebd0-11e8-8067-000c299a5e15/pvc-canprovision" is fully bound to PV "pvc-a693d4b0-ebd0-11e8-8067-000c299a5e15"
I1119 15:56:42.132561  127596 scheduler_binder.go:529] PersistentVolume "pv-i-prebound", Node "node-1" matches for Pod "volume-schedulinga42c7715-ebd0-11e8-8067-000c299a5e15/pod-i-pv-prebound-w-provisioned"
I1119 15:56:42.132566  127596 scheduler_binder.go:529] PersistentVolume "pvc-a693d4b0-ebd0-11e8-8067-000c299a5e15", Node "node-1" matches for Pod "volume-schedulinga42c7715-ebd0-11e8-8067-000c299a5e15/pod-i-pv-prebound-w-provisioned"
I1119 15:56:42.132570  127596 scheduler_binder.go:532] All bound volumes for Pod "volume-schedulinga42c7715-ebd0-11e8-8067-000c299a5e15/pod-i-pv-prebound-w-provisioned" match with Node "node-1"
I1119 15:56:42.132601  127596 scheduler_binder.go:207] AssumePodVolumes for pod "volume-schedulinga42c7715-ebd0-11e8-8067-000c299a5e15/pod-i-pv-prebound-w-provisioned", node "node-1"
I1119 15:56:42.132622  127596 scheduler_binder.go:458] PVC "volume-schedulinga42c7715-ebd0-11e8-8067-000c299a5e15/pvc-i-pv-prebound" is fully bound to PV "pv-i-prebound"
I1119 15:56:42.132627  127596 scheduler_binder.go:458] PVC "volume-schedulinga42c7715-ebd0-11e8-8067-000c299a5e15/pvc-canprovision" is fully bound to PV "pvc-a693d4b0-ebd0-11e8-8067-000c299a5e15"
I1119 15:56:42.132632  127596 scheduler_binder.go:217] AssumePodVolumes for pod "volume-schedulinga42c7715-ebd0-11e8-8067-000c299a5e15/pod-i-pv-prebound-w-provisioned", node "node-1": all PVCs bound and nothing to do
E1119 15:56:42.132638  127596 scheduler.go:433] scheduler cache AssumePod failed: pod a6940066-ebd0-11e8-8067-000c299a5e15 is in the cache, so can't be assumed
E1119 15:56:42.132642  127596 factory.go:1465] Error scheduling volume-schedulinga42c7715-ebd0-11e8-8067-000c299a5e15/pod-i-pv-prebound-w-provisioned: pod a6940066-ebd0-11e8-8067-000c299a5e15 is in the cache, so can't be assumed; retrying
I1119 15:56:42.132673  127596 factory.go:1558] Updating pod condition for volume-schedulinga42c7715-ebd0-11e8-8067-000c299a5e15/pod-i-pv-prebound-w-provisioned to (PodScheduled==False)
E1119 15:56:42.132682  127596 scheduler.go:556] error assuming pod: pod a6940066-ebd0-11e8-8067-000c299a5e15 is in the cache, so can't be assumed
I1119 15:56:42.133697  127596 factory.go:1338] About to try and schedule pod volume-schedulinga42c7715-ebd0-11e8-8067-000c299a5e15/pod-i-pv-prebound-w-provisioned
I1119 15:56:42.133718  127596 scheduler.go:508] Attempting to schedule pod: volume-schedulinga42c7715-ebd0-11e8-8067-000c299a5e15/pod-i-pv-prebound-w-provisioned
I1119 15:56:42.133767  127596 scheduler_binder.go:147] FindPodVolumes for pod "volume-schedulinga42c7715-ebd0-11e8-8067-000c299a5e15/pod-i-pv-prebound-w-provisioned", node "node-1"
I1119 15:56:42.133781  127596 scheduler_binder.go:458] PVC "volume-schedulinga42c7715-ebd0-11e8-8067-000c299a5e15/pvc-i-pv-prebound" is fully bound to PV "pv-i-prebound"
I1119 15:56:42.133786  127596 scheduler_binder.go:458] PVC "volume-schedulinga42c7715-ebd0-11e8-8067-000c299a5e15/pvc-canprovision" is fully bound to PV "pvc-a693d4b0-ebd0-11e8-8067-000c299a5e15"
I1119 15:56:42.133798  127596 scheduler_binder.go:529] PersistentVolume "pv-i-prebound", Node "node-1" matches for Pod "volume-schedulinga42c7715-ebd0-11e8-8067-000c299a5e15/pod-i-pv-prebound-w-provisioned"
I1119 15:56:42.133804  127596 scheduler_binder.go:529] PersistentVolume "pvc-a693d4b0-ebd0-11e8-8067-000c299a5e15", Node "node-1" matches for Pod "volume-schedulinga42c7715-ebd0-11e8-8067-000c299a5e15/pod-i-pv-prebound-w-provisioned"
I1119 15:56:42.133808  127596 scheduler_binder.go:532] All bound volumes for Pod "volume-schedulinga42c7715-ebd0-11e8-8067-000c299a5e15/pod-i-pv-prebound-w-provisioned" match with Node "node-1"
I1119 15:56:42.133840  127596 scheduler_binder.go:207] AssumePodVolumes for pod "volume-schedulinga42c7715-ebd0-11e8-8067-000c299a5e15/pod-i-pv-prebound-w-provisioned", node "node-1"
I1119 15:56:42.133860  127596 scheduler_binder.go:458] PVC "volume-schedulinga42c7715-ebd0-11e8-8067-000c299a5e15/pvc-i-pv-prebound" is fully bound to PV "pv-i-prebound"
I1119 15:56:42.133866  127596 scheduler_binder.go:458] PVC "volume-schedulinga42c7715-ebd0-11e8-8067-000c299a5e15/pvc-canprovision" is fully bound to PV "pvc-a693d4b0-ebd0-11e8-8067-000c299a5e15"
I1119 15:56:42.133871  127596 scheduler_binder.go:217] AssumePodVolumes for pod "volume-schedulinga42c7715-ebd0-11e8-8067-000c299a5e15/pod-i-pv-prebound-w-provisioned", node "node-1": all PVCs bound and nothing to do
E1119 15:56:42.133877  127596 scheduler.go:433] scheduler cache AssumePod failed: pod a6940066-ebd0-11e8-8067-000c299a5e15 is in the cache, so can't be assumed
E1119 15:56:42.133881  127596 factory.go:1465] Error scheduling volume-schedulinga42c7715-ebd0-11e8-8067-000c299a5e15/pod-i-pv-prebound-w-provisioned: pod a6940066-ebd0-11e8-8067-000c299a5e15 is in the cache, so can't be assumed; retrying
I1119 15:56:42.133907  127596 factory.go:1558] Updating pod condition for volume-schedulinga42c7715-ebd0-11e8-8067-000c299a5e15/pod-i-pv-prebound-w-provisioned to (PodScheduled==False)
E1119 15:56:42.133913  127596 scheduler.go:556] error assuming pod: pod a6940066-ebd0-11e8-8067-000c299a5e15 is in the cache, so can't be assumed
I1119 15:56:42.134976  127596 factory.go:1338] About to try and schedule pod volume-schedulinga42c7715-ebd0-11e8-8067-000c299a5e15/pod-i-pv-prebound-w-provisioned
I1119 15:56:42.135007  127596 scheduler.go:508] Attempting to schedule pod: volume-schedulinga42c7715-ebd0-11e8-8067-000c299a5e15/pod-i-pv-prebound-w-provisioned
I1119 15:56:42.135061  127596 scheduler_binder.go:147] FindPodVolumes for pod "volume-schedulinga42c7715-ebd0-11e8-8067-000c299a5e15/pod-i-pv-prebound-w-provisioned", node "node-1"
I1119 15:56:42.135078  127596 scheduler_binder.go:458] PVC "volume-schedulinga42c7715-ebd0-11e8-8067-000c299a5e15/pvc-i-pv-prebound" is fully bound to PV "pv-i-prebound"
I1119 15:56:42.135085  127596 scheduler_binder.go:458] PVC "volume-schedulinga42c7715-ebd0-11e8-8067-000c299a5e15/pvc-canprovision" is fully bound to PV "pvc-a693d4b0-ebd0-11e8-8067-000c299a5e15"
I1119 15:56:42.135104  127596 scheduler_binder.go:529] PersistentVolume "pv-i-prebound", Node "node-1" matches for Pod "volume-schedulinga42c7715-ebd0-11e8-8067-000c299a5e15/pod-i-pv-prebound-w-provisioned"
I1119 15:56:42.135112  127596 scheduler_binder.go:529] PersistentVolume "pvc-a693d4b0-ebd0-11e8-8067-000c299a5e15", Node "node-1" matches for Pod "volume-schedulinga42c7715-ebd0-11e8-8067-000c299a5e15/pod-i-pv-prebound-w-provisioned"
I1119 15:56:42.135116  127596 scheduler_binder.go:532] All bound volumes for Pod "volume-schedulinga42c7715-ebd0-11e8-8067-000c299a5e15/pod-i-pv-prebound-w-provisioned" match with Node "node-1"
I1119 15:56:42.135140  127596 scheduler_binder.go:207] AssumePodVolumes for pod "volume-schedulinga42c7715-ebd0-11e8-8067-000c299a5e15/pod-i-pv-prebound-w-provisioned", node "node-1"
I1119 15:56:42.135167  127596 scheduler_binder.go:458] PVC "volume-schedulinga42c7715-ebd0-11e8-8067-000c299a5e15/pvc-i-pv-prebound" is fully bound to PV "pv-i-prebound"
I1119 15:56:42.135176  127596 scheduler_binder.go:458] PVC "volume-schedulinga42c7715-ebd0-11e8-8067-000c299a5e15/pvc-canprovision" is fully bound to PV "pvc-a693d4b0-ebd0-11e8-8067-000c299a5e15"
I1119 15:56:42.135185  127596 scheduler_binder.go:217] AssumePodVolumes for pod "volume-schedulinga42c7715-ebd0-11e8-8067-000c299a5e15/pod-i-pv-prebound-w-provisioned", node "node-1": all PVCs bound and nothing to do
E1119 15:56:42.135196  127596 scheduler.go:433] scheduler cache AssumePod failed: pod a6940066-ebd0-11e8-8067-000c299a5e15 is in the cache, so can't be assumed
E1119 15:56:42.135203  127596 factory.go:1465] Error scheduling volume-schedulinga42c7715-ebd0-11e8-8067-000c299a5e15/pod-i-pv-prebound-w-provisioned: pod a6940066-ebd0-11e8-8067-000c299a5e15 is in the cache, so can't be assumed; retrying
I1119 15:56:42.135225  127596 factory.go:1558] Updating pod condition for volume-schedulinga42c7715-ebd0-11e8-8067-000c299a5e15/pod-i-pv-prebound-w-provisioned to (PodScheduled==False)
E1119 15:56:42.135233  127596 scheduler.go:556] error assuming pod: pod a6940066-ebd0-11e8-8067-000c299a5e15 is in the cache, so can't be assumed
I1119 15:56:42.136431  127596 factory.go:1338] About to try and schedule pod volume-schedulinga42c7715-ebd0-11e8-8067-000c299a5e15/pod-i-pv-prebound-w-provisioned
I1119 15:56:42.136452  127596 scheduler.go:508] Attempting to schedule pod: volume-schedulinga42c7715-ebd0-11e8-8067-000c299a5e15/pod-i-pv-prebound-w-provisioned
I1119 15:56:42.136504  127596 scheduler_binder.go:147] FindPodVolumes for pod "volume-schedulinga42c7715-ebd0-11e8-8067-000c299a5e15/pod-i-pv-prebound-w-provisioned", node "node-1"
I1119 15:56:42.136520  127596 scheduler_binder.go:458] PVC "volume-schedulinga42c7715-ebd0-11e8-8067-000c299a5e15/pvc-i-pv-prebound" is fully bound to PV "pv-i-prebound"
I1119 15:56:42.136525  127596 scheduler_binder.go:458] PVC "volume-schedulinga42c7715-ebd0-11e8-8067-000c299a5e15/pvc-canprovision" is fully bound to PV "pvc-a693d4b0-ebd0-11e8-8067-000c299a5e15"
I1119 15:56:42.136538  127596 scheduler_binder.go:529] PersistentVolume "pv-i-prebound", Node "node-1" matches for Pod "volume-schedulinga42c7715-ebd0-11e8-8067-000c299a5e15/pod-i-pv-prebound-w-provisioned"
I1119 15:56:42.136542  127596 scheduler_binder.go:529] PersistentVolume "pvc-a693d4b0-ebd0-11e8-8067-000c299a5e15", Node "node-1" matches for Pod "volume-schedulinga42c7715-ebd0-11e8-8067-000c299a5e15/pod-i-pv-prebound-w-provisioned"
I1119 15:56:42.136547  127596 scheduler_binder.go:532] All bound volumes for Pod "volume-schedulinga42c7715-ebd0-11e8-8067-000c299a5e15/pod-i-pv-prebound-w-provisioned" match with Node "node-1"
I1119 15:56:42.136580  127596 scheduler_binder.go:207] AssumePodVolumes for pod "volume-schedulinga42c7715-ebd0-11e8-8067-000c299a5e15/pod-i-pv-prebound-w-provisioned", node "node-1"
I1119 15:56:42.136600  127596 scheduler_binder.go:458] PVC "volume-schedulinga42c7715-ebd0-11e8-8067-000c299a5e15/pvc-i-pv-prebound" is fully bound to PV "pv-i-prebound"
I1119 15:56:42.136606  127596 scheduler_binder.go:458] PVC "volume-schedulinga42c7715-ebd0-11e8-8067-000c299a5e15/pvc-canprovision" is fully bound to PV "pvc-a693d4b0-ebd0-11e8-8067-000c299a5e15"
I1119 15:56:42.136611  127596 scheduler_binder.go:217] AssumePodVolumes for pod "volume-schedulinga42c7715-ebd0-11e8-8067-000c299a5e15/pod-i-pv-prebound-w-provisioned", node "node-1": all PVCs bound and nothing to do
E1119 15:56:42.136618  127596 scheduler.go:433] scheduler cache AssumePod failed: pod a6940066-ebd0-11e8-8067-000c299a5e15 is in the cache, so can't be assumed
E1119 15:56:42.136622  127596 factory.go:1465] Error scheduling volume-schedulinga42c7715-ebd0-11e8-8067-000c299a5e15/pod-i-pv-prebound-w-provisioned: pod a6940066-ebd0-11e8-8067-000c299a5e15 is in the cache, so can't be assumed; retrying
I1119 15:56:42.136648  127596 factory.go:1558] Updating pod condition for volume-schedulinga42c7715-ebd0-11e8-8067-000c299a5e15/pod-i-pv-prebound-w-provisioned to (PodScheduled==False)
E1119 15:56:42.136655  127596 scheduler.go:556] error assuming pod: pod a6940066-ebd0-11e8-8067-000c299a5e15 is in the cache, so can't be assumed
I1119 15:56:42.137605  127596 factory.go:1338] About to try and schedule pod volume-schedulinga42c7715-ebd0-11e8-8067-000c299a5e15/pod-i-pv-prebound-w-provisioned
I1119 15:56:42.137628  127596 scheduler.go:508] Attempting to schedule pod: volume-schedulinga42c7715-ebd0-11e8-8067-000c299a5e15/pod-i-pv-prebound-w-provisioned
I1119 15:56:42.137678  127596 scheduler_binder.go:147] FindPodVolumes for pod "volume-schedulinga42c7715-ebd0-11e8-8067-000c299a5e15/pod-i-pv-prebound-w-provisioned", node "node-1"
I1119 15:56:42.137693  127596 scheduler_binder.go:458] PVC "volume-schedulinga42c7715-ebd0-11e8-8067-000c299a5e15/pvc-i-pv-prebound" is fully bound to PV "pv-i-prebound"
I1119 15:56:42.137698  127596 scheduler_binder.go:458] PVC "volume-schedulinga42c7715-ebd0-11e8-8067-000c299a5e15/pvc-canprovision" is fully bound to PV "pvc-a693d4b0-ebd0-11e8-8067-000c299a5e15"
I1119 15:56:42.137711  127596 scheduler_binder.go:529] PersistentVolume "pv-i-prebound", Node "node-1" matches for Pod "volume-schedulinga42c7715-ebd0-11e8-8067-000c299a5e15/pod-i-pv-prebound-w-provisioned"
I1119 15:56:42.137715  127596 scheduler_binder.go:529] PersistentVolume "pvc-a693d4b0-ebd0-11e8-8067-000c299a5e15", Node "node-1" matches for Pod "volume-schedulinga42c7715-ebd0-11e8-8067-000c299a5e15/pod-i-pv-prebound-w-provisioned"
I1119 15:56:42.137719  127596 scheduler_binder.go:532] All bound volumes for Pod "volume-schedulinga42c7715-ebd0-11e8-8067-000c299a5e15/pod-i-pv-prebound-w-provisioned" match with Node "node-1"
I1119 15:56:42.137752  127596 scheduler_binder.go:207] AssumePodVolumes for pod "volume-schedulinga42c7715-ebd0-11e8-8067-000c299a5e15/pod-i-pv-prebound-w-provisioned", node "node-1"
I1119 15:56:42.137773  127596 scheduler_binder.go:458] PVC "volume-schedulinga42c7715-ebd0-11e8-8067-000c299a5e15/pvc-i-pv-prebound" is fully bound to PV "pv-i-prebound"
I1119 15:56:42.137778  127596 scheduler_binder.go:458] PVC "volume-schedulinga42c7715-ebd0-11e8-8067-000c299a5e15/pvc-canprovision" is fully bound to PV "pvc-a693d4b0-ebd0-11e8-8067-000c299a5e15"
I1119 15:56:42.137783  127596 scheduler_binder.go:217] AssumePodVolumes for pod "volume-schedulinga42c7715-ebd0-11e8-8067-000c299a5e15/pod-i-pv-prebound-w-provisioned", node "node-1": all PVCs bound and nothing to do
E1119 15:56:42.137789  127596 scheduler.go:433] scheduler cache AssumePod failed: pod a6940066-ebd0-11e8-8067-000c299a5e15 is in the cache, so can't be assumed
E1119 15:56:42.137793  127596 factory.go:1465] Error scheduling volume-schedulinga42c7715-ebd0-11e8-8067-000c299a5e15/pod-i-pv-prebound-w-provisioned: pod a6940066-ebd0-11e8-8067-000c299a5e15 is in the cache, so can't be assumed; retrying
I1119 15:56:42.137820  127596 factory.go:1558] Updating pod condition for volume-schedulinga42c7715-ebd0-11e8-8067-000c299a5e15/pod-i-pv-prebound-w-provisioned to (PodScheduled==False)
E1119 15:56:42.137827  127596 scheduler.go:556] error assuming pod: pod a6940066-ebd0-11e8-8067-000c299a5e15 is in the cache, so can't be assumed
I1119 15:56:42.138782  127596 factory.go:1338] About to try and schedule pod volume-schedulinga42c7715-ebd0-11e8-8067-000c299a5e15/pod-i-pv-prebound-w-provisioned
I1119 15:56:42.138803  127596 scheduler.go:508] Attempting to schedule pod: volume-schedulinga42c7715-ebd0-11e8-8067-000c299a5e15/pod-i-pv-prebound-w-provisioned
I1119 15:56:42.138853  127596 scheduler_binder.go:147] FindPodVolumes for pod "volume-schedulinga42c7715-ebd0-11e8-8067-000c299a5e15/pod-i-pv-prebound-w-provisioned", node "node-1"
I1119 15:56:42.138867  127596 scheduler_binder.go:458] PVC "volume-schedulinga42c7715-ebd0-11e8-8067-000c299a5e15/pvc-i-pv-prebound" is fully bound to PV "pv-i-prebound"
I1119 15:56:42.138872  127596 scheduler_binder.go:458] PVC "volume-schedulinga42c7715-ebd0-11e8-8067-000c299a5e15/pvc-canprovision" is fully bound to PV "pvc-a693d4b0-ebd0-11e8-8067-000c299a5e15"
I1119 15:56:42.138884  127596 scheduler_binder.go:529] PersistentVolume "pv-i-prebound", Node "node-1" matches for Pod "volume-schedulinga42c7715-ebd0-11e8-8067-000c299a5e15/pod-i-pv-prebound-w-provisioned"
I1119 15:56:42.138889  127596 scheduler_binder.go:529] PersistentVolume "pvc-a693d4b0-ebd0-11e8-8067-000c299a5e15", Node "node-1" matches for Pod "volume-schedulinga42c7715-ebd0-11e8-8067-000c299a5e15/pod-i-pv-prebound-w-provisioned"
I1119 15:56:42.138893  127596 scheduler_binder.go:532] All bound volumes for Pod "volume-schedulinga42c7715-ebd0-11e8-8067-000c299a5e15/pod-i-pv-prebound-w-provisioned" match with Node "node-1"
I1119 15:56:42.138925  127596 scheduler_binder.go:207] AssumePodVolumes for pod "volume-schedulinga42c7715-ebd0-11e8-8067-000c299a5e15/pod-i-pv-prebound-w-provisioned", node "node-1"
I1119 15:56:42.138946  127596 scheduler_binder.go:458] PVC "volume-schedulinga42c7715-ebd0-11e8-8067-000c299a5e15/pvc-i-pv-prebound" is fully bound to PV "pv-i-prebound"
I1119 15:56:42.138952  127596 scheduler_binder.go:458] PVC "volume-schedulinga42c7715-ebd0-11e8-8067-000c299a5e15/pvc-canprovision" is fully bound to PV "pvc-a693d4b0-ebd0-11e8-8067-000c299a5e15"
I1119 15:56:42.138956  127596 scheduler_binder.go:217] AssumePodVolumes for pod "volume-schedulinga42c7715-ebd0-11e8-8067-000c299a5e15/pod-i-pv-prebound-w-provisioned", node "node-1": all PVCs bound and nothing to do
E1119 15:56:42.138962  127596 scheduler.go:433] scheduler cache AssumePod failed: pod a6940066-ebd0-11e8-8067-000c299a5e15 is in the cache, so can't be assumed
E1119 15:56:42.138966  127596 factory.go:1465] Error scheduling volume-schedulinga42c7715-ebd0-11e8-8067-000c299a5e15/pod-i-pv-prebound-w-provisioned: pod a6940066-ebd0-11e8-8067-000c299a5e15 is in the cache, so can't be assumed; retrying
I1119 15:56:42.138993  127596 factory.go:1558] Updating pod condition for volume-schedulinga42c7715-ebd0-11e8-8067-000c299a5e15/pod-i-pv-prebound-w-provisioned to (PodScheduled==False)
E1119 15:56:42.139000  127596 scheduler.go:556] error assuming pod: pod a6940066-ebd0-11e8-8067-000c299a5e15 is in the cache, so can't be assumed
I1119 15:56:42.139957  127596 factory.go:1338] About to try and schedule pod volume-schedulinga42c7715-ebd0-11e8-8067-000c299a5e15/pod-i-pv-prebound-w-provisioned
I1119 15:56:42.139978  127596 scheduler.go:508] Attempting to schedule pod: volume-schedulinga42c7715-ebd0-11e8-8067-000c299a5e15/pod-i-pv-prebound-w-provisioned
I1119 15:56:42.140028  127596 scheduler_binder.go:147] FindPodVolumes for pod "volume-schedulinga42c7715-ebd0-11e8-8067-000c299a5e15/pod-i-pv-prebound-w-provisioned", node "node-1"
I1119 15:56:42.140042  127596 scheduler_binder.go:458] PVC "volume-schedulinga42c7715-ebd0-11e8-8067-000c299a5e15/pvc-i-pv-prebound" is fully bound to PV "pv-i-prebound"
I1119 15:56:42.140047  127596 scheduler_binder.go:458] PVC "volume-schedulinga42c7715-ebd0-11e8-8067-000c299a5e15/pvc-canprovision" is fully bound to PV "pvc-a693d4b0-ebd0-11e8-8067-000c299a5e15"
I1119 15:56:42.140059  127596 scheduler_binder.go:529] PersistentVolume "pv-i-prebound", Node "node-1" matches for Pod "volume-schedulinga42c7715-ebd0-11e8-8067-000c299a5e15/pod-i-pv-prebound-w-provisioned"
I1119 15:56:42.140065  127596 scheduler_binder.go:529] PersistentVolume "pvc-a693d4b0-ebd0-11e8-8067-000c299a5e15", Node "node-1" matches for Pod "volume-schedulinga42c7715-ebd0-11e8-8067-000c299a5e15/pod-i-pv-prebound-w-provisioned"
I1119 15:56:42.140069  127596 scheduler_binder.go:532] All bound volumes for Pod "volume-schedulinga42c7715-ebd0-11e8-8067-000c299a5e15/pod-i-pv-prebound-w-provisioned" match with Node "node-1"
I1119 15:56:42.140102  127596 scheduler_binder.go:207] AssumePodVolumes for pod "volume-schedulinga42c7715-ebd0-11e8-8067-000c299a5e15/pod-i-pv-prebound-w-provisioned", node "node-1"
I1119 15:56:42.140123  127596 scheduler_binder.go:458] PVC "volume-schedulinga42c7715-ebd0-11e8-8067-000c299a5e15/pvc-i-pv-prebound" is fully bound to PV "pv-i-prebound"
I1119 15:56:42.140129  127596 scheduler_binder.go:458] PVC "volume-schedulinga42c7715-ebd0-11e8-8067-000c299a5e15/pvc-canprovision" is fully bound to PV "pvc-a693d4b0-ebd0-11e8-8067-000c299a5e15"
I1119 15:56:42.140133  127596 scheduler_binder.go:217] AssumePodVolumes for pod "volume-schedulinga42c7715-ebd0-11e8-8067-000c299a5e15/pod-i-pv-prebound-w-provisioned", node "node-1": all PVCs bound and nothing to do
E1119 15:56:42.140139  127596 scheduler.go:433] scheduler cache AssumePod failed: pod a6940066-ebd0-11e8-8067-000c299a5e15 is in the cache, so can't be assumed
E1119 15:56:42.140143  127596 factory.go:1465] Error scheduling volume-schedulinga42c7715-ebd0-11e8-8067-000c299a5e15/pod-i-pv-prebound-w-provisioned: pod a6940066-ebd0-11e8-8067-000c299a5e15 is in the cache, so can't be assumed; retrying
I1119 15:56:42.140158  127596 factory.go:1558] Updating pod condition for volume-schedulinga42c7715-ebd0-11e8-8067-000c299a5e15/pod-i-pv-prebound-w-provisioned to (PodScheduled==False)
E1119 15:56:42.140163  127596 scheduler.go:556] error assuming pod: pod a6940066-ebd0-11e8-8067-000c299a5e15 is in the cache, so can't be assumed
I1119 15:56:42.141025  127596 factory.go:1338] About to try and schedule pod volume-schedulinga42c7715-ebd0-11e8-8067-000c299a5e15/pod-i-pv-prebound-w-provisioned
I1119 15:56:42.141049  127596 scheduler.go:508] Attempting to schedule pod: volume-schedulinga42c7715-ebd0-11e8-8067-000c299a5e15/pod-i-pv-prebound-w-provisioned
I1119 15:56:42.141132  127596 scheduler_binder.go:147] FindPodVolumes for pod "volume-schedulinga42c7715-ebd0-11e8-8067-000c299a5e15/pod-i-pv-prebound-w-provisioned", node "node-1"
I1119 15:56:42.141161  127596 scheduler_binder.go:458] PVC "volume-schedulinga42c7715-ebd0-11e8-8067-000c299a5e15/pvc-i-pv-prebound" is fully bound to PV "pv-i-prebound"
I1119 15:56:42.141168  127596 scheduler_binder.go:458] PVC "volume-schedulinga42c7715-ebd0-11e8-8067-000c299a5e15/pvc-canprovision" is fully bound to PV "pvc-a693d4b0-ebd0-11e8-8067-000c299a5e15"
I1119 15:56:42.141180  127596 scheduler_binder.go:529] PersistentVolume "pv-i-prebound", Node "node-1" matches for Pod "volume-schedulinga42c7715-ebd0-11e8-8067-000c299a5e15/pod-i-pv-prebound-w-provisioned"
I1119 15:56:42.141185  127596 scheduler_binder.go:529] PersistentVolume "pvc-a693d4b0-ebd0-11e8-8067-000c299a5e15", Node "node-1" matches for Pod "volume-schedulinga42c7715-ebd0-11e8-8067-000c299a5e15/pod-i-pv-prebound-w-provisioned"
I1119 15:56:42.141189  127596 scheduler_binder.go:532] All bound volumes for Pod "volume-schedulinga42c7715-ebd0-11e8-8067-000c299a5e15/pod-i-pv-prebound-w-provisioned" match with Node "node-1"
I1119 15:56:42.141253  127596 scheduler_binder.go:207] AssumePodVolumes for pod "volume-schedulinga42c7715-ebd0-11e8-8067-000c299a5e15/pod-i-pv-prebound-w-provisioned", node "node-1"
I1119 15:56:42.141266  127596 scheduler_binder.go:458] PVC "volume-schedulinga42c7715-ebd0-11e8-8067-000c299a5e15/pvc-i-pv-prebound" is fully bound to PV "pv-i-prebound"
I1119 15:56:42.141271  127596 scheduler_binder.go:458] PVC "volume-schedulinga42c7715-ebd0-11e8-8067-000c299a5e15/pvc-canprovision" is fully bound to PV "pvc-a693d4b0-ebd0-11e8-8067-000c299a5e15"
I1119 15:56:42.141276  127596 scheduler_binder.go:217] AssumePodVolumes for pod "volume-schedulinga42c7715-ebd0-11e8-8067-000c299a5e15/pod-i-pv-prebound-w-provisioned", node "node-1": all PVCs bound and nothing to do
E1119 15:56:42.141282  127596 scheduler.go:433] scheduler cache AssumePod failed: pod a6940066-ebd0-11e8-8067-000c299a5e15 is in the cache, so can't be assumed
E1119 15:56:42.141286  127596 factory.go:1465] Error scheduling volume-schedulinga42c7715-ebd0-11e8-8067-000c299a5e15/pod-i-pv-prebound-w-provisioned: pod a6940066-ebd0-11e8-8067-000c299a5e15 is in the cache, so can't be assumed; retrying
I1119 15:56:42.141298  127596 factory.go:1558] Updating pod condition for volume-schedulinga42c7715-ebd0-11e8-8067-000c299a5e15/pod-i-pv-prebound-w-provisioned to (PodScheduled==False)
E1119 15:56:42.141303  127596 scheduler.go:556] error assuming pod: pod a6940066-ebd0-11e8-8067-000c299a5e15 is in the cache, so can't be assumed
I1119 15:56:42.142183  127596 factory.go:1338] About to try and schedule pod volume-schedulinga42c7715-ebd0-11e8-8067-000c299a5e15/pod-i-pv-prebound-w-provisioned
I1119 15:56:42.142205  127596 scheduler.go:508] Attempting to schedule pod: volume-schedulinga42c7715-ebd0-11e8-8067-000c299a5e15/pod-i-pv-prebound-w-provisioned
I1119 15:56:42.142253  127596 scheduler_binder.go:147] FindPodVolumes for pod "volume-schedulinga42c7715-ebd0-11e8-8067-000c299a5e15/pod-i-pv-prebound-w-provisioned", node "node-1"
I1119 15:56:42.142283  127596 scheduler_binder.go:458] PVC "volume-schedulinga42c7715-ebd0-11e8-8067-000c299a5e15/pvc-i-pv-prebound" is fully bound to PV "pv-i-prebound"
I1119 15:56:42.142290  127596 scheduler_binder.go:458] PVC "volume-schedulinga42c7715-ebd0-11e8-8067-000c299a5e15/pvc-canprovision" is fully bound to PV "pvc-a693d4b0-ebd0-11e8-8067-000c299a5e15"
I1119 15:56:42.142314  127596 scheduler_binder.go:529] PersistentVolume "pv-i-prebound", Node "node-1" matches for Pod "volume-schedulinga42c7715-ebd0-11e8-8067-000c299a5e15/pod-i-pv-prebound-w-provisioned"
I1119 15:56:42.142321  127596 scheduler_binder.go:529] PersistentVolume "pvc-a693d4b0-ebd0-11e8-8067-000c299a5e15", Node "node-1" matches for Pod "volume-schedulinga42c7715-ebd0-11e8-8067-000c299a5e15/pod-i-pv-prebound-w-provisioned"
I1119 15:56:42.142325  127596 scheduler_binder.go:532] All bound volumes for Pod "volume-schedulinga42c7715-ebd0-11e8-8067-000c299a5e15/pod-i-pv-prebound-w-provisioned" match with Node "node-1"
I1119 15:56:42.142358  127596 scheduler_binder.go:207] AssumePodVolumes for pod "volume-schedulinga42c7715-ebd0-11e8-8067-000c299a5e15/pod-i-pv-prebound-w-provisioned", node "node-1"
I1119 15:56:42.142367  127596 scheduler_binder.go:458] PVC "volume-schedulinga42c7715-ebd0-11e8-8067-000c299a5e15/pvc-i-pv-prebound" is fully bound to PV "pv-i-prebound"
I1119 15:56:42.142371  127596 scheduler_binder.go:458] PVC "volume-schedulinga42c7715-ebd0-11e8-8067-000c299a5e15/pvc-canprovision" is fully bound to PV "pvc-a693d4b0-ebd0-11e8-8067-000c299a5e15"
I1119 15:56:42.142376  127596 scheduler_binder.go:217] AssumePodVolumes for pod "volume-schedulinga42c7715-ebd0-11e8-8067-000c299a5e15/pod-i-pv-prebound-w-provisioned", node "node-1": all PVCs bound and nothing to do
E1119 15:56:42.142382  127596 scheduler.go:433] scheduler cache AssumePod failed: pod a6940066-ebd0-11e8-8067-000c299a5e15 is in the cache, so can't be assumed
E1119 15:56:42.142386  127596 factory.go:1465] Error scheduling volume-schedulinga42c7715-ebd0-11e8-8067-000c299a5e15/pod-i-pv-prebound-w-provisioned: pod a6940066-ebd0-11e8-8067-000c299a5e15 is in the cache, so can't be assumed; retrying
I1119 15:56:42.142423  127596 factory.go:1558] Updating pod condition for volume-schedulinga42c7715-ebd0-11e8-8067-000c299a5e15/pod-i-pv-prebound-w-provisioned to (PodScheduled==False)
E1119 15:56:42.142434  127596 scheduler.go:556] error assuming pod: pod a6940066-ebd0-11e8-8067-000c299a5e15 is in the cache, so can't be assumed
I1119 15:56:42.143445  127596 factory.go:1338] About to try and schedule pod volume-schedulinga42c7715-ebd0-11e8-8067-000c299a5e15/pod-i-pv-prebound-w-provisioned
I1119 15:56:42.143466  127596 scheduler.go:508] Attempting to schedule pod: volume-schedulinga42c7715-ebd0-11e8-8067-000c299a5e15/pod-i-pv-prebound-w-provisioned
I1119 15:56:42.143517  127596 scheduler_binder.go:147] FindPodVolumes for pod "volume-schedulinga42c7715-ebd0-11e8-8067-000c299a5e15/pod-i-pv-prebound-w-provisioned", node "node-1"
I1119 15:56:42.143532  127596 scheduler_binder.go:458] PVC "volume-schedulinga42c7715-ebd0-11e8-8067-000c299a5e15/pvc-i-pv-prebound" is fully bound to PV "pv-i-prebound"
I1119 15:56:42.143537  127596 scheduler_binder.go:458] PVC "volume-schedulinga42c7715-ebd0-11e8-8067-000c299a5e15/pvc-canprovision" is fully bound to PV "pvc-a693d4b0-ebd0-11e8-8067-000c299a5e15"
I1119 15:56:42.143550  127596 scheduler_binder.go:529] PersistentVolume "pv-i-prebound", Node "node-1" matches for Pod "volume-schedulinga42c7715-ebd0-11e8-8067-000c299a5e15/pod-i-pv-prebound-w-provisioned"
I1119 15:56:42.143554  127596 scheduler_binder.go:529] PersistentVolume "pvc-a693d4b0-ebd0-11e8-8067-000c299a5e15", Node "node-1" matches for Pod "volume-schedulinga42c7715-ebd0-11e8-8067-000c299a5e15/pod-i-pv-prebound-w-provisioned"
I1119 15:56:42.143559  127596 scheduler_binder.go:532] All bound volumes for Pod "volume-schedulinga42c7715-ebd0-11e8-8067-000c299a5e15/pod-i-pv-prebound-w-provisioned" match with Node "node-1"
I1119 15:56:42.143591  127596 scheduler_binder.go:207] AssumePodVolumes for pod "volume-schedulinga42c7715-ebd0-11e8-8067-000c299a5e15/pod-i-pv-prebound-w-provisioned", node "node-1"
I1119 15:56:42.143600  127596 scheduler_binder.go:458] PVC "volume-schedulinga42c7715-ebd0-11e8-8067-000c299a5e15/pvc-i-pv-prebound" is fully bound to PV "pv-i-prebound"
I1119 15:56:42.143604  127596 scheduler_binder.go:458] PVC "volume-schedulinga42c7715-ebd0-11e8-8067-000c299a5e15/pvc-canprovision" is fully bound to PV "pvc-a693d4b0-ebd0-11e8-8067-000c299a5e15"
I1119 15:56:42.143609  127596 scheduler_binder.go:217] AssumePodVolumes for pod "volume-schedulinga42c7715-ebd0-11e8-8067-000c299a5e15/pod-i-pv-prebound-w-provisioned", node "node-1": all PVCs bound and nothing to do
E1119 15:56:42.143615  127596 scheduler.go:433] scheduler cache AssumePod failed: pod a6940066-ebd0-11e8-8067-000c299a5e15 is in the cache, so can't be assumed
E1119 15:56:42.143619  127596 factory.go:1465] Error scheduling volume-schedulinga42c7715-ebd0-11e8-8067-000c299a5e15/pod-i-pv-prebound-w-provisioned: pod a6940066-ebd0-11e8-8067-000c299a5e15 is in the cache, so can't be assumed; retrying
I1119 15:56:42.143633  127596 factory.go:1558] Updating pod condition for volume-schedulinga42c7715-ebd0-11e8-8067-000c299a5e15/pod-i-pv-prebound-w-provisioned to (PodScheduled==False)
E1119 15:56:42.143638  127596 scheduler.go:556] error assuming pod: pod a6940066-ebd0-11e8-8067-000c299a5e15 is in the cache, so can't be assumed
I1119 15:56:42.144437  127596 factory.go:1338] About to try and schedule pod volume-schedulinga42c7715-ebd0-11e8-8067-000c299a5e15/pod-i-pv-prebound-w-provisioned
I1119 15:56:42.144461  127596 scheduler.go:508] Attempting to schedule pod: volume-schedulinga42c7715-ebd0-11e8-8067-000c299a5e15/pod-i-pv-prebound-w-provisioned
I1119 15:56:42.144495  127596 scheduler_binder.go:147] FindPodVolumes for pod "volume-schedulinga42c7715-ebd0-11e8-8067-000c299a5e15/pod-i-pv-prebound-w-provisioned", node "node-1"
I1119 15:56:42.144507  127596 scheduler_binder.go:458] PVC "volume-schedulinga42c7715-ebd0-11e8-8067-000c299a5e15/pvc-i-pv-prebound" is fully bound to PV "pv-i-prebound"
I1119 15:56:42.144513  127596 scheduler_binder.go:458] PVC "volume-schedulinga42c7715-ebd0-11e8-8067-000c299a5e15/pvc-canprovision" is fully bound to PV "pvc-a693d4b0-ebd0-11e8-8067-000c299a5e15"
I1119 15:56:42.144525  127596 scheduler_binder.go:529] PersistentVolume "pv-i-prebound", Node "node-1" matches for Pod "volume-schedulinga42c7715-ebd0-11e8-8067-000c299a5e15/pod-i-pv-prebound-w-provisioned"
I1119 15:56:42.144529  127596 scheduler_binder.go:529] PersistentVolume "pvc-a693d4b0-ebd0-11e8-8067-000c299a5e15", Node "node-1" matches for Pod "volume-schedulinga42c7715-ebd0-11e8-8067-000c299a5e15/pod-i-pv-prebound-w-provisioned"
I1119 15:56:42.144533  127596 scheduler_binder.go:532] All bound volumes for Pod "volume-schedulinga42c7715-ebd0-11e8-8067-000c299a5e15/pod-i-pv-prebound-w-provisioned" match with Node "node-1"
I1119 15:56:42.144548  127596 scheduler_binder.go:207] AssumePodVolumes for pod "volume-schedulinga42c7715-ebd0-11e8-8067-000c299a5e15/pod-i-pv-prebound-w-provisioned", node "node-1"
I1119 15:56:42.144570  127596 scheduler_binder.go:458] PVC "volume-schedulinga42c7715-ebd0-11e8-8067-000c299a5e15/pvc-i-pv-prebound" is fully bound to PV "pv-i-prebound"
I1119 15:56:42.144576  127596 scheduler_binder.go:458] PVC "volume-schedulinga42c7715-ebd0-11e8-8067-000c299a5e15/pvc-canprovision" is fully bound to PV "pvc-a693d4b0-ebd0-11e8-8067-000c299a5e15"
I1119 15:56:42.144581  127596 scheduler_binder.go:217] AssumePodVolumes for pod "volume-schedulinga42c7715-ebd0-11e8-8067-000c299a5e15/pod-i-pv-prebound-w-provisioned", node "node-1": all PVCs bound and nothing to do
E1119 15:56:42.144587  127596 scheduler.go:433] scheduler cache AssumePod failed: pod a6940066-ebd0-11e8-8067-000c299a5e15 is in the cache, so can't be assumed
E1119 15:56:42.144591  127596 factory.go:1465] Error scheduling volume-schedulinga42c7715-ebd0-11e8-8067-000c299a5e15/pod-i-pv-prebound-w-provisioned: pod a6940066-ebd0-11e8-8067-000c299a5e15 is in the cache, so can't be assumed; retrying
I1119 15:56:42.144603  127596 factory.go:1558] Updating pod condition for volume-schedulinga42c7715-ebd0-11e8-8067-000c299a5e15/pod-i-pv-prebound-w-provisioned to (PodScheduled==False)
E1119 15:56:42.144608  127596 scheduler.go:556] error assuming pod: pod a6940066-ebd0-11e8-8067-000c299a5e15 is in the cache, so can't be assumed
I1119 15:56:42.145592  127596 factory.go:1338] About to try and schedule pod volume-schedulinga42c7715-ebd0-11e8-8067-000c299a5e15/pod-i-pv-prebound-w-provisioned
I1119 15:56:42.145616  127596 scheduler.go:508] Attempting to schedule pod: volume-schedulinga42c7715-ebd0-11e8-8067-000c299a5e15/pod-i-pv-prebound-w-provisioned
I1119 15:56:42.145650  127596 scheduler_binder.go:147] FindPodVolumes for pod "volume-schedulinga42c7715-ebd0-11e8-8067-000c299a5e15/pod-i-pv-prebound-w-provisioned", node "node-1"
I1119 15:56:42.145662  127596 scheduler_binder.go:458] PVC "volume-schedulinga42c7715-ebd0-11e8-8067-000c299a5e15/pvc-i-pv-prebound" is fully bound to PV "pv-i-prebound"
I1119 15:56:42.145667  127596 scheduler_binder.go:458] PVC "volume-schedulinga42c7715-ebd0-11e8-8067-000c299a5e15/pvc-canprovision" is fully bound to PV "pvc-a693d4b0-ebd0-11e8-8067-000c299a5e15"
I1119 15:56:42.145679  127596 scheduler_binder.go:529] PersistentVolume "pv-i-prebound", Node "node-1" matches for Pod "volume-schedulinga42c7715-ebd0-11e8-8067-000c299a5e15/pod-i-pv-prebound-w-provisioned"
I1119 15:56:42.145684  127596 scheduler_binder.go:529] PersistentVolume "pvc-a693d4b0-ebd0-11e8-8067-000c299a5e15", Node "node-1" matches for Pod "volume-schedulinga42c7715-ebd0-11e8-8067-000c299a5e15/pod-i-pv-prebound-w-provisioned"
I1119 15:56:42.145688  127596 scheduler_binder.go:532] All bound volumes for Pod "volume-schedulinga42c7715-ebd0-11e8-8067-000c299a5e15/pod-i-pv-prebound-w-provisioned" match with Node "node-1"
I1119 15:56:42.145703  127596 scheduler_binder.go:207] AssumePodVolumes for pod "volume-schedulinga42c7715-ebd0-11e8-8067-000c299a5e15/pod-i-pv-prebound-w-provisioned", node "node-1"
I1119 15:56:42.145709  127596 scheduler_binder.go:458] PVC "volume-schedulinga42c7715-ebd0-11e8-8067-000c299a5e15/pvc-i-pv-prebound" is fully bound to PV "pv-i-prebound"
I1119 15:56:42.145713  127596 scheduler_binder.go:458] PVC "volume-schedulinga42c7715-ebd0-11e8-8067-000c299a5e15/pvc-canprovision" is fully bound to PV "pvc-a693d4b0-ebd0-11e8-8067-000c299a5e15"
I1119 15:56:42.145718  127596 scheduler_binder.go:217] AssumePodVolumes for pod "volume-schedulinga42c7715-ebd0-11e8-8067-000c299a5e15/pod-i-pv-prebound-w-provisioned", node "node-1": all PVCs bound and nothing to do
E1119 15:56:42.145723  127596 scheduler.go:433] scheduler cache AssumePod failed: pod a6940066-ebd0-11e8-8067-000c299a5e15 is in the cache, so can't be assumed
E1119 15:56:42.145727  127596 factory.go:1465] Error scheduling volume-schedulinga42c7715-ebd0-11e8-8067-000c299a5e15/pod-i-pv-prebound-w-provisioned: pod a6940066-ebd0-11e8-8067-000c299a5e15 is in the cache, so can't be assumed; retrying
I1119 15:56:42.145740  127596 factory.go:1558] Updating pod condition for volume-schedulinga42c7715-ebd0-11e8-8067-000c299a5e15/pod-i-pv-prebound-w-provisioned to (PodScheduled==False)
E1119 15:56:42.145749  127596 scheduler.go:556] error assuming pod: pod a6940066-ebd0-11e8-8067-000c299a5e15 is in the cache, so can't be assumed
I1119 15:56:42.146687  127596 factory.go:1338] About to try and schedule pod volume-schedulinga42c7715-ebd0-11e8-8067-000c299a5e15/pod-i-pv-prebound-w-provisioned
I1119 15:56:42.146709  127596 scheduler.go:508] Attempting to schedule pod: volume-schedulinga42c7715-ebd0-11e8-8067-000c299a5e15/pod-i-pv-prebound-w-provisioned
I1119 15:56:42.146758  127596 scheduler_binder.go:147] FindPodVolumes for pod "volume-schedulinga42c7715-ebd0-11e8-8067-000c299a5e15/pod-i-pv-prebound-w-provisioned", node "node-1"
I1119 15:56:42.146772  127596 scheduler_binder.go:458] PVC "volume-schedulinga42c7715-ebd0-11e8-8067-000c299a5e15/pvc-i-pv-prebound" is fully bound to PV "pv-i-prebound"
I1119 15:56:42.146777  127596 scheduler_binder.go:458] PVC "volume-schedulinga42c7715-ebd0-11e8-8067-000c299a5e15/pvc-canprovision" is fully bound to PV "pvc-a693d4b0-ebd0-11e8-8067-000c299a5e15"
I1119 15:56:42.146790  127596 scheduler_binder.go:529] PersistentVolume "pv-i-prebound", Node "node-1" matches for Pod "volume-schedulinga42c7715-ebd0-11e8-8067-000c299a5e15/pod-i-pv-prebound-w-provisioned"
I1119 15:56:42.146795  127596 scheduler_binder.go:529] PersistentVolume "pvc-a693d4b0-ebd0-11e8-8067-000c299a5e15", Node "node-1" matches for Pod "volume-schedulinga42c7715-ebd0-11e8-8067-000c299a5e15/pod-i-pv-prebound-w-provisioned"
I1119 15:56:42.146800  127596 scheduler_binder.go:532] All bound volumes for Pod "volume-schedulinga42c7715-ebd0-11e8-8067-000c299a5e15/pod-i-pv-prebound-w-provisioned" match with Node "node-1"
I1119 15:56:42.146836  127596 scheduler_binder.go:207] AssumePodVolumes for pod "volume-schedulinga42c7715-ebd0-11e8-8067-000c299a5e15/pod-i-pv-prebound-w-provisioned", node "node-1"
I1119 15:56:42.146864  127596 scheduler_binder.go:458] PVC "volume-schedulinga42c7715-ebd0-11e8-8067-000c299a5e15/pvc-i-pv-prebound" is fully bound to PV "pv-i-prebound"
I1119 15:56:42.146873  127596 scheduler_binder.go:458] PVC "volume-schedulinga42c7715-ebd0-11e8-8067-000c299a5e15/pvc-canprovision" is fully bound to PV "pvc-a693d4b0-ebd0-11e8-8067-000c299a5e15"
I1119 15:56:42.146881  127596 scheduler_binder.go:217] AssumePodVolumes for pod "volume-schedulinga42c7715-ebd0-11e8-8067-000c299a5e15/pod-i-pv-prebound-w-provisioned", node "node-1": all PVCs bound and nothing to do
E1119 15:56:42.146889  127596 scheduler.go:433] scheduler cache AssumePod failed: pod a6940066-ebd0-11e8-8067-000c299a5e15 is in the cache, so can't be assumed
E1119 15:56:42.146893  127596 factory.go:1465] Error scheduling volume-schedulinga42c7715-ebd0-11e8-8067-000c299a5e15/pod-i-pv-prebound-w-provisioned: pod a6940066-ebd0-11e8-8067-000c299a5e15 is in the cache, so can't be assumed; retrying
I1119 15:56:42.146927  127596 factory.go:1558] Updating pod condition for volume-schedulinga42c7715-ebd0-11e8-8067-000c299a5e15/pod-i-pv-prebound-w-provisioned to (PodScheduled==False)
E1119 15:56:42.146936  127596 scheduler.go:556] error assuming pod: pod a6940066-ebd0-11e8-8067-000c299a5e15 is in the cache, so can't be assumed
I1119 15:56:42.147874  127596 factory.go:1338] About to try and schedule pod volume-schedulinga42c7715-ebd0-11e8-8067-000c299a5e15/pod-i-pv-prebound-w-provisioned
I1119 15:56:42.147899  127596 scheduler.go:508] Attempting to schedule pod: volume-schedulinga42c7715-ebd0-11e8-8067-000c299a5e15/pod-i-pv-prebound-w-provisioned
I1119 15:56:42.147951  127596 scheduler_binder.go:147] FindPodVolumes for pod "volume-schedulinga42c7715-ebd0-11e8-8067-000c299a5e15/pod-i-pv-prebound-w-provisioned", node "node-1"
I1119 15:56:42.147967  127596 scheduler_binder.go:458] PVC "volume-schedulinga42c7715-ebd0-11e8-8067-000c299a5e15/pvc-i-pv-prebound" is fully bound to PV "pv-i-prebound"
I1119 15:56:42.147972  127596 scheduler_binder.go:458] PVC "volume-schedulinga42c7715-ebd0-11e8-8067-000c299a5e15/pvc-canprovision" is fully bound to PV "pvc-a693d4b0-ebd0-11e8-8067-000c299a5e15"
I1119 15:56:42.147985  127596 scheduler_binder.go:529] PersistentVolume "pv-i-prebound", Node "node-1" matches for Pod "volume-schedulinga42c7715-ebd0-11e8-8067-000c299a5e15/pod-i-pv-prebound-w-provisioned"
I1119 15:56:42.147989  127596 scheduler_binder.go:529] PersistentVolume "pvc-a693d4b0-ebd0-11e8-8067-000c299a5e15", Node "node-1" matches for Pod "volume-schedulinga42c7715-ebd0-11e8-8067-000c299a5e15/pod-i-pv-prebound-w-provisioned"
I1119 15:56:42.147994  127596 scheduler_binder.go:532] All bound volumes for Pod "volume-schedulinga42c7715-ebd0-11e8-8067-000c299a5e15/pod-i-pv-prebound-w-provisioned" match with Node "node-1"
I1119 15:56:42.148026  127596 scheduler_binder.go:207] AssumePodVolumes for pod "volume-schedulinga42c7715-ebd0-11e8-8067-000c299a5e15/pod-i-pv-prebound-w-provisioned", node "node-1"
I1119 15:56:42.148047  127596 scheduler_binder.go:458] PVC "volume-schedulinga42c7715-ebd0-11e8-8067-000c299a5e15/pvc-i-pv-prebound" is fully bound to PV "pv-i-prebound"
I1119 15:56:42.148053  127596 scheduler_binder.go:458] PVC "volume-schedulinga42c7715-ebd0-11e8-8067-000c299a5e15/pvc-canprovision" is fully bound to PV "pvc-a693d4b0-ebd0-11e8-8067-000c299a5e15"
I1119 15:56:42.148058  127596 scheduler_binder.go:217] AssumePodVolumes for pod "volume-schedulinga42c7715-ebd0-11e8-8067-000c299a5e15/pod-i-pv-prebound-w-provisioned", node "node-1": all PVCs bound and nothing to do
E1119 15:56:42.148064  127596 scheduler.go:433] scheduler cache AssumePod failed: pod a6940066-ebd0-11e8-8067-000c299a5e15 is in the cache, so can't be assumed
E1119 15:56:42.148068  127596 factory.go:1465] Error scheduling volume-schedulinga42c7715-ebd0-11e8-8067-000c299a5e15/pod-i-pv-prebound-w-provisioned: pod a6940066-ebd0-11e8-8067-000c299a5e15 is in the cache, so can't be assumed; retrying
I1119 15:56:42.148095  127596 factory.go:1558] Updating pod condition for volume-schedulinga42c7715-ebd0-11e8-8067-000c299a5e15/pod-i-pv-prebound-w-provisioned to (PodScheduled==False)
E1119 15:56:42.148102  127596 scheduler.go:556] error assuming pod: pod a6940066-ebd0-11e8-8067-000c299a5e15 is in the cache, so can't be assumed
I1119 15:56:42.149129  127596 factory.go:1338] About to try and schedule pod volume-schedulinga42c7715-ebd0-11e8-8067-000c299a5e15/pod-i-pv-prebound-w-provisioned
I1119 15:56:42.149157  127596 scheduler.go:508] Attempting to schedule pod: volume-schedulinga42c7715-ebd0-11e8-8067-000c299a5e15/pod-i-pv-prebound-w-provisioned
I1119 15:56:42.149230  127596 scheduler_binder.go:147] FindPodVolumes for pod "volume-schedulinga42c7715-ebd0-11e8-8067-000c299a5e15/pod-i-pv-prebound-w-provisioned", node "node-1"
I1119 15:56:42.149248  127596 scheduler_binder.go:458] PVC "volume-schedulinga42c7715-ebd0-11e8-8067-000c299a5e15/pvc-i-pv-prebound" is fully bound to PV "pv-i-prebound"
I1119 15:56:42.149253  127596 scheduler_binder.go:458] PVC "volume-schedulinga42c7715-ebd0-11e8-8067-000c299a5e15/pvc-canprovision" is fully bound to PV "pvc-a693d4b0-ebd0-11e8-8067-000c299a5e15"
I1119 15:56:42.149272  127596 scheduler_binder.go:529] PersistentVolume "pv-i-prebound", Node "node-1" matches for Pod "volume-schedulinga42c7715-ebd0-11e8-8067-000c299a5e15/pod-i-pv-prebound-w-provisioned"
I1119 15:56:42.149277  127596 scheduler_binder.go:529] PersistentVolume "pvc-a693d4b0-ebd0-11e8-8067-000c299a5e15", Node "node-1" matches for Pod "volume-schedulinga42c7715-ebd0-11e8-8067-000c299a5e15/pod-i-pv-prebound-w-provisioned"
I1119 15:56:42.149281  127596 scheduler_binder.go:532] All bound volumes for Pod "volume-schedulinga42c7715-ebd0-11e8-8067-000c299a5e15/pod-i-pv-prebound-w-provisioned" match with Node "node-1"
I1119 15:56:42.149323  127596 scheduler_binder.go:207] AssumePodVolumes for pod "volume-schedulinga42c7715-ebd0-11e8-8067-000c299a5e15/pod-i-pv-prebound-w-provisioned", node "node-1"
I1119 15:56:42.149345  127596 scheduler_binder.go:458] PVC "volume-schedulinga42c7715-ebd0-11e8-8067-000c299a5e15/pvc-i-pv-prebound" is fully bound to PV "pv-i-prebound"
I1119 15:56:42.149351  127596 scheduler_binder.go:458] PVC "volume-schedulinga42c7715-ebd0-11e8-8067-000c299a5e15/pvc-canprovision" is fully bound to PV "pvc-a693d4b0-ebd0-11e8-8067-000c299a5e15"
I1119 15:56:42.149356  127596 scheduler_binder.go:217] AssumePodVolumes for pod "volume-schedulinga42c7715-ebd0-11e8-8067-000c299a5e15/pod-i-pv-prebound-w-provisioned", node "node-1": all PVCs bound and nothing to do
E1119 15:56:42.149363  127596 scheduler.go:433] scheduler cache AssumePod failed: pod a6940066-ebd0-11e8-8067-000c299a5e15 is in the cache, so can't be assumed
E1119 15:56:42.149368  127596 factory.go:1465] Error scheduling volume-schedulinga42c7715-ebd0-11e8-8067-000c299a5e15/pod-i-pv-prebound-w-provisioned: pod a6940066-ebd0-11e8-8067-000c299a5e15 is in the cache, so can't be assumed; retrying
I1119 15:56:42.149403  127596 factory.go:1558] Updating pod condition for volume-schedulinga42c7715-ebd0-11e8-8067-000c299a5e15/pod-i-pv-prebound-w-provisioned to (PodScheduled==False)
E1119 15:56:42.149412  127596 scheduler.go:556] error assuming pod: pod a6940066-ebd0-11e8-8067-000c299a5e15 is in the cache, so can't be assumed
I1119 15:56:42.150902  127596 factory.go:1338] About to try and schedule pod volume-schedulinga42c7715-ebd0-11e8-8067-000c299a5e15/pod-i-pv-prebound-w-provisioned
I1119 15:56:42.150933  127596 scheduler.go:508] Attempting to schedule pod: volume-schedulinga42c7715-ebd0-11e8-8067-000c299a5e15/pod-i-pv-prebound-w-provisioned
I1119 15:56:42.151067  127596 scheduler_binder.go:147] FindPodVolumes for pod "volume-schedulinga42c7715-ebd0-11e8-8067-000c299a5e15/pod-i-pv-prebound-w-provisioned", node "node-1"
I1119 15:56:42.151088  127596 scheduler_binder.go:458] PVC "volume-schedulinga42c7715-ebd0-11e8-8067-000c299a5e15/pvc-i-pv-prebound" is fully bound to PV "pv-i-prebound"
I1119 15:56:42.151095  127596 scheduler_binder.go:458] PVC "volume-schedulinga42c7715-ebd0-11e8-8067-000c299a5e15/pvc-canprovision" is fully bound to PV "pvc-a693d4b0-ebd0-11e8-8067-000c299a5e15"
I1119 15:56:42.151156  127596 scheduler_binder.go:529] PersistentVolume "pv-i-prebound", Node "node-1" matches for Pod "volume-schedulinga42c7715-ebd0-11e8-8067-000c299a5e15/pod-i-pv-prebound-w-provisioned"
I1119 15:56:42.151184  127596 scheduler_binder.go:529] PersistentVolume "pvc-a693d4b0-ebd0-11e8-8067-000c299a5e15", Node "node-1" matches for Pod "volume-schedulinga42c7715-ebd0-11e8-8067-000c299a5e15/pod-i-pv-prebound-w-provisioned"
I1119 15:56:42.151192  127596 scheduler_binder.go:532] All bound volumes for Pod "volume-schedulinga42c7715-ebd0-11e8-8067-000c299a5e15/pod-i-pv-prebound-w-provisioned" match with Node "node-1"
I1119 15:56:42.151275  127596 scheduler_binder.go:207] AssumePodVolumes for pod "volume-schedulinga42c7715-ebd0-11e8-8067-000c299a5e15/pod-i-pv-prebound-w-provisioned", node "node-1"
I1119 15:56:42.151302  127596 scheduler_binder.go:458] PVC "volume-schedulinga42c7715-ebd0-11e8-8067-000c299a5e15/pvc-i-pv-prebound" is fully bound to PV "pv-i-prebound"
I1119 15:56:42.151310  127596 scheduler_binder.go:458] PVC "volume-schedulinga42c7715-ebd0-11e8-8067-000c299a5e15/pvc-canprovision" is fully bound to PV "pvc-a693d4b0-ebd0-11e8-8067-000c299a5e15"
I1119 15:56:42.151318  127596 scheduler_binder.go:217] AssumePodVolumes for pod "volume-schedulinga42c7715-ebd0-11e8-8067-000c299a5e15/pod-i-pv-prebound-w-provisioned", node "node-1": all PVCs bound and nothing to do
E1119 15:56:42.151366  127596 scheduler.go:433] scheduler cache AssumePod failed: pod a6940066-ebd0-11e8-8067-000c299a5e15 is in the cache, so can't be assumed
E1119 15:56:42.151379  127596 factory.go:1465] Error scheduling volume-schedulinga42c7715-ebd0-11e8-8067-000c299a5e15/pod-i-pv-prebound-w-provisioned: pod a6940066-ebd0-11e8-8067-000c299a5e15 is in the cache, so can't be assumed; retrying
I1119 15:56:42.151418  127596 factory.go:1558] Updating pod condition for volume-schedulinga42c7715-ebd0-11e8-8067-000c299a5e15/pod-i-pv-prebound-w-provisioned to (PodScheduled==False)
E1119 15:56:42.151426  127596 scheduler.go:556] error assuming pod: pod a6940066-ebd0-11e8-8067-000c299a5e15 is in the cache, so can't be assumed
I1119 15:56:42.152526  127596 factory.go:1338] About to try and schedule pod volume-schedulinga42c7715-ebd0-11e8-8067-000c299a5e15/pod-i-pv-prebound-w-provisioned
I1119 15:56:42.152548  127596 scheduler.go:508] Attempting to schedule pod: volume-schedulinga42c7715-ebd0-11e8-8067-000c299a5e15/pod-i-pv-prebound-w-provisioned
I1119 15:56:42.152599  127596 scheduler_binder.go:147] FindPodVolumes for pod "volume-schedulinga42c7715-ebd0-11e8-8067-000c299a5e15/pod-i-pv-prebound-w-provisioned", node "node-1"
I1119 15:56:42.152629  127596 scheduler_binder.go:458] PVC "volume-schedulinga42c7715-ebd0-11e8-8067-000c299a5e15/pvc-i-pv-prebound" is fully bound to PV "pv-i-prebound"
I1119 15:56:42.152636  127596 scheduler_binder.go:458] PVC "volume-schedulinga42c7715-ebd0-11e8-8067-000c299a5e15/pvc-canprovision" is fully bound to PV "pvc-a693d4b0-ebd0-11e8-8067-000c299a5e15"
I1119 15:56:42.152649  127596 scheduler_binder.go:529] PersistentVolume "pv-i-prebound", Node "node-1" matches for Pod "volume-schedulinga42c7715-ebd0-11e8-8067-000c299a5e15/pod-i-pv-prebound-w-provisioned"
I1119 15:56:42.152654  127596 scheduler_binder.go:529] PersistentVolume "pvc-a693d4b0-ebd0-11e8-8067-000c299a5e15", Node "node-1" matches for Pod "volume-schedulinga42c7715-ebd0-11e8-8067-000c299a5e15/pod-i-pv-prebound-w-provisioned"
I1119 15:56:42.152658  127596 scheduler_binder.go:532] All bound volumes for Pod "volume-schedulinga42c7715-ebd0-11e8-8067-000c299a5e15/pod-i-pv-prebound-w-provisioned" match with Node "node-1"
I1119 15:56:42.152677  127596 scheduler_binder.go:207] AssumePodVolumes for pod "volume-schedulinga42c7715-ebd0-11e8-8067-000c299a5e15/pod-i-pv-prebound-w-provisioned", node "node-1"
I1119 15:56:42.152682  127596 scheduler_binder.go:458] PVC "volume-schedulinga42c7715-ebd0-11e8-8067-000c299a5e15/pvc-i-pv-prebound" is fully bound to PV "pv-i-prebound"
I1119 15:56:42.152686  127596 scheduler_binder.go:458] PVC "volume-schedulinga42c7715-ebd0-11e8-8067-000c299a5e15/pvc-canprovision" is fully bound to PV "pvc-a693d4b0-ebd0-11e8-8067-000c299a5e15"
I1119 15:56:42.152691  127596 scheduler_binder.go:217] AssumePodVolumes for pod "volume-schedulinga42c7715-ebd0-11e8-8067-000c299a5e15/pod-i-pv-prebound-w-provisioned", node "node-1": all PVCs bound and nothing to do
E1119 15:56:42.152696  127596 scheduler.go:433] scheduler cache AssumePod failed: pod a6940066-ebd0-11e8-8067-000c299a5e15 is in the cache, so can't be assumed
E1119 15:56:42.152700  127596 factory.go:1465] Error scheduling volume-schedulinga42c7715-ebd0-11e8-8067-000c299a5e15/pod-i-pv-prebound-w-provisioned: pod a6940066-ebd0-11e8-8067-000c299a5e15 is in the cache, so can't be assumed; retrying
I1119 15:56:42.152712  127596 factory.go:1558] Updating pod condition for volume-schedulinga42c7715-ebd0-11e8-8067-000c299a5e15/pod-i-pv-prebound-w-provisioned to (PodScheduled==False)
E1119 15:56:42.152719  127596 scheduler.go:556] error assuming pod: pod a6940066-ebd0-11e8-8067-000c299a5e15 is in the cache, so can't be assumed
I1119 15:56:42.153735  127596 factory.go:1338] About to try and schedule pod volume-schedulinga42c7715-ebd0-11e8-8067-000c299a5e15/pod-i-pv-prebound-w-provisioned
I1119 15:56:42.153759  127596 scheduler.go:508] Attempting to schedule pod: volume-schedulinga42c7715-ebd0-11e8-8067-000c299a5e15/pod-i-pv-prebound-w-provisioned
I1119 15:56:42.153847  127596 scheduler_binder.go:147] FindPodVolumes for pod "volume-schedulinga42c7715-ebd0-11e8-8067-000c299a5e15/pod-i-pv-prebound-w-provisioned", node "node-1"
I1119 15:56:42.153876  127596 scheduler_binder.go:458] PVC "volume-schedulinga42c7715-ebd0-11e8-8067-000c299a5e15/pvc-i-pv-prebound" is fully bound to PV "pv-i-prebound"
I1119 15:56:42.153882  127596 scheduler_binder.go:458] PVC "volume-schedulinga42c7715-ebd0-11e8-8067-000c299a5e15/pvc-canprovision" is fully bound to PV "pvc-a693d4b0-ebd0-11e8-8067-000c299a5e15"
I1119 15:56:42.153895  127596 scheduler_binder.go:529] PersistentVolume "pv-i-prebound", Node "node-1" matches for Pod "volume-schedulinga42c7715-ebd0-11e8-8067-000c299a5e15/pod-i-pv-prebound-w-provisioned"
I1119 15:56:42.153900  127596 scheduler_binder.go:529] PersistentVolume "pvc-a693d4b0-ebd0-11e8-8067-000c299a5e15", Node "node-1" matches for Pod "volume-schedulinga42c7715-ebd0-11e8-8067-000c299a5e15/pod-i-pv-prebound-w-provisioned"
I1119 15:56:42.153905  127596 scheduler_binder.go:532] All bound volumes for Pod "volume-schedulinga42c7715-ebd0-11e8-8067-000c299a5e15/pod-i-pv-prebound-w-provisioned" match with Node "node-1"
I1119 15:56:42.153961  127596 scheduler_binder.go:207] AssumePodVolumes for pod "volume-schedulinga42c7715-ebd0-11e8-8067-000c299a5e15/pod-i-pv-prebound-w-provisioned", node "node-1"
I1119 15:56:42.153971  127596 scheduler_binder.go:458] PVC "volume-schedulinga42c7715-ebd0-11e8-8067-000c299a5e15/pvc-i-pv-prebound" is fully bound to PV "pv-i-prebound"
I1119 15:56:42.153975  127596 scheduler_binder.go:458] PVC "volume-schedulinga42c7715-ebd0-11e8-8067-000c299a5e15/pvc-canprovision" is fully bound to PV "pvc-a693d4b0-ebd0-11e8-8067-000c299a5e15"
I1119 15:56:42.153980  127596 scheduler_binder.go:217] AssumePodVolumes for pod "volume-schedulinga42c7715-ebd0-11e8-8067-000c299a5e15/pod-i-pv-prebound-w-provisioned", node "node-1": all PVCs bound and nothing to do
E1119 15:56:42.153986  127596 scheduler.go:433] scheduler cache AssumePod failed: pod a6940066-ebd0-11e8-8067-000c299a5e15 is in the cache, so can't be assumed
E1119 15:56:42.153991  127596 factory.go:1465] Error scheduling volume-schedulinga42c7715-ebd0-11e8-8067-000c299a5e15/pod-i-pv-prebound-w-provisioned: pod a6940066-ebd0-11e8-8067-000c299a5e15 is in the cache, so can't be assumed; retrying
I1119 15:56:42.154019  127596 factory.go:1558] Updating pod condition for volume-schedulinga42c7715-ebd0-11e8-8067-000c299a5e15/pod-i-pv-prebound-w-provisioned to (PodScheduled==False)
E1119 15:56:42.154026  127596 scheduler.go:556] error assuming pod: pod a6940066-ebd0-11e8-8067-000c299a5e15 is in the cache, so can't be assumed
I1119 15:56:42.155205  127596 factory.go:1338] About to try and schedule pod volume-schedulinga42c7715-ebd0-11e8-8067-000c299a5e15/pod-i-pv-prebound-w-provisioned
I1119 15:56:42.155225  127596 scheduler.go:508] Attempting to schedule pod: volume-schedulinga42c7715-ebd0-11e8-8067-000c299a5e15/pod-i-pv-prebound-w-provisioned
I1119 15:56:42.155274  127596 scheduler_binder.go:147] FindPodVolumes for pod "volume-schedulinga42c7715-ebd0-11e8-8067-000c299a5e15/pod-i-pv-prebound-w-provisioned", node "node-1"
I1119 15:56:42.155311  127596 scheduler_binder.go:458] PVC "volume-schedulinga42c7715-ebd0-11e8-8067-000c299a5e15/pvc-i-pv-prebound" is fully bound to PV "pv-i-prebound"
I1119 15:56:42.155318  127596 scheduler_binder.go:458] PVC "volume-schedulinga42c7715-ebd0-11e8-8067-000c299a5e15/pvc-canprovision" is fully bound to PV "pvc-a693d4b0-ebd0-11e8-8067-000c299a5e15"
I1119 15:56:42.155331  127596 scheduler_binder.go:529] PersistentVolume "pv-i-prebound", Node "node-1" matches for Pod "volume-schedulinga42c7715-ebd0-11e8-8067-000c299a5e15/pod-i-pv-prebound-w-provisioned"
I1119 15:56:42.155335  127596 scheduler_binder.go:529] PersistentVolume "pvc-a693d4b0-ebd0-11e8-8067-000c299a5e15", Node "node-1" matches for Pod "volume-schedulinga42c7715-ebd0-11e8-8067-000c299a5e15/pod-i-pv-prebound-w-provisioned"
I1119 15:56:42.155340  127596 scheduler_binder.go:532] All bound volumes for Pod "volume-schedulinga42c7715-ebd0-11e8-8067-000c299a5e15/pod-i-pv-prebound-w-provisioned" match with Node "node-1"
I1119 15:56:42.155384  127596 scheduler_binder.go:207] AssumePodVolumes for pod "volume-schedulinga42c7715-ebd0-11e8-8067-000c299a5e15/pod-i-pv-prebound-w-provisioned", node "node-1"
I1119 15:56:42.155404  127596 scheduler_binder.go:458] PVC "volume-schedulinga42c7715-ebd0-11e8-8067-000c299a5e15/pvc-i-pv-prebound" is fully bound to PV "pv-i-prebound"
I1119 15:56:42.155410  127596 scheduler_binder.go:458] PVC "volume-schedulinga42c7715-ebd0-11e8-8067-000c299a5e15/pvc-canprovision" is fully bound to PV "pvc-a693d4b0-ebd0-11e8-8067-000c299a5e15"
I1119 15:56:42.155415  127596 scheduler_binder.go:217] AssumePodVolumes for pod "volume-schedulinga42c7715-ebd0-11e8-8067-000c299a5e15/pod-i-pv-prebound-w-provisioned", node "node-1": all PVCs bound and nothing to do
E1119 15:56:42.155421  127596 scheduler.go:433] scheduler cache AssumePod failed: pod a6940066-ebd0-11e8-8067-000c299a5e15 is in the cache, so can't be assumed
E1119 15:56:42.155424  127596 factory.go:1465] Error scheduling volume-schedulinga42c7715-ebd0-11e8-8067-000c299a5e15/pod-i-pv-prebound-w-provisioned: pod a6940066-ebd0-11e8-8067-000c299a5e15 is in the cache, so can't be assumed; retrying
I1119 15:56:42.155451  127596 factory.go:1558] Updating pod condition for volume-schedulinga42c7715-ebd0-11e8-8067-000c299a5e15/pod-i-pv-prebound-w-provisioned to (PodScheduled==False)
E1119 15:56:42.155470  127596 scheduler.go:556] error assuming pod: pod a6940066-ebd0-11e8-8067-000c299a5e15 is in the cache, so can't be assumed
I1119 15:56:42.156506  127596 factory.go:1338] About to try and schedule pod volume-schedulinga42c7715-ebd0-11e8-8067-000c299a5e15/pod-i-pv-prebound-w-provisioned
I1119 15:56:42.156527  127596 scheduler.go:508] Attempting to schedule pod: volume-schedulinga42c7715-ebd0-11e8-8067-000c299a5e15/pod-i-pv-prebound-w-provisioned
I1119 15:56:42.156575  127596 scheduler_binder.go:147] FindPodVolumes for pod "volume-schedulinga42c7715-ebd0-11e8-8067-000c299a5e15/pod-i-pv-prebound-w-provisioned", node "node-1"
I1119 15:56:42.156589  127596 scheduler_binder.go:458] PVC "volume-schedulinga42c7715-ebd0-11e8-8067-000c299a5e15/pvc-i-pv-prebound" is fully bound to PV "pv-i-prebound"
I1119 15:56:42.156594  127596 scheduler_binder.go:458] PVC "volume-schedulinga42c7715-ebd0-11e8-8067-000c299a5e15/pvc-canprovision" is fully bound to PV "pvc-a693d4b0-ebd0-11e8-8067-000c299a5e15"
I1119 15:56:42.156606  127596 scheduler_binder.go:529] PersistentVolume "pv-i-prebound", Node "node-1" matches for Pod "volume-schedulinga42c7715-ebd0-11e8-8067-000c299a5e15/pod-i-pv-prebound-w-provisioned"
I1119 15:56:42.156610  127596 scheduler_binder.go:529] PersistentVolume "pvc-a693d4b0-ebd0-11e8-8067-000c299a5e15", Node "node-1" matches for Pod "volume-schedulinga42c7715-ebd0-11e8-8067-000c299a5e15/pod-i-pv-prebound-w-provisioned"
I1119 15:56:42.156615  127596 scheduler_binder.go:532] All bound volumes for Pod "volume-schedulinga42c7715-ebd0-11e8-8067-000c299a5e15/pod-i-pv-prebound-w-provisioned" match with Node "node-1"
I1119 15:56:42.156645  127596 scheduler_binder.go:207] AssumePodVolumes for pod "volume-schedulinga42c7715-ebd0-11e8-8067-000c299a5e15/pod-i-pv-prebound-w-provisioned", node "node-1"
I1119 15:56:42.156658  127596 scheduler_binder.go:458] PVC "volume-schedulinga42c7715-ebd0-11e8-8067-000c299a5e15/pvc-i-pv-prebound" is fully bound to PV "pv-i-prebound"
I1119 15:56:42.156663  127596 scheduler_binder.go:458] PVC "volume-schedulinga42c7715-ebd0-11e8-8067-000c299a5e15/pvc-canprovision" is fully bound to PV "pvc-a693d4b0-ebd0-11e8-8067-000c299a5e15"
I1119 15:56:42.156667  127596 scheduler_binder.go:217] AssumePodVolumes for pod "volume-schedulinga42c7715-ebd0-11e8-8067-000c299a5e15/pod-i-pv-prebound-w-provisioned", node "node-1": all PVCs bound and nothing to do
E1119 15:56:42.156673  127596 scheduler.go:433] scheduler cache AssumePod failed: pod a6940066-ebd0-11e8-8067-000c299a5e15 is in the cache, so can't be assumed
E1119 15:56:42.156677  127596 factory.go:1465] Error scheduling volume-schedulinga42c7715-ebd0-11e8-8067-000c299a5e15/pod-i-pv-prebound-w-provisioned: pod a6940066-ebd0-11e8-8067-000c299a5e15 is in the cache, so can't be assumed; retrying
I1119 15:56:42.156707  127596 factory.go:1558] Updating pod condition for volume-schedulinga42c7715-ebd0-11e8-8067-000c299a5e15/pod-i-pv-prebound-w-provisioned to (PodScheduled==False)
E1119 15:56:42.156713  127596 scheduler.go:556] error assuming pod: pod a6940066-ebd0-11e8-8067-000c299a5e15 is in the cache, so can't be assumed
I1119 15:56:42.157561  127596 factory.go:1338] About to try and schedule pod volume-schedulinga42c7715-ebd0-11e8-8067-000c299a5e15/pod-i-pv-prebound-w-provisioned
I1119 15:56:42.157582  127596 scheduler.go:508] Attempting to schedule pod: volume-schedulinga42c7715-ebd0-11e8-8067-000c299a5e15/pod-i-pv-prebound-w-provisioned
I1119 15:56:42.157631  127596 scheduler_binder.go:147] FindPodVolumes for pod "volume-schedulinga42c7715-ebd0-11e8-8067-000c299a5e15/pod-i-pv-prebound-w-provisioned", node "node-1"
I1119 15:56:42.157645  127596 scheduler_binder.go:458] PVC "volume-schedulinga42c7715-ebd0-11e8-8067-000c299a5e15/pvc-i-pv-prebound" is fully bound to PV "pv-i-prebound"
I1119 15:56:42.157650  127596 scheduler_binder.go:458] PVC "volume-schedulinga42c7715-ebd0-11e8-8067-000c299a5e15/pvc-canprovision" is fully bound to PV "pvc-a693d4b0-ebd0-11e8-8067-000c299a5e15"
I1119 15:56:42.157662  127596 scheduler_binder.go:529] PersistentVolume "pv-i-prebound", Node "node-1" matches for Pod "volume-schedulinga42c7715-ebd0-11e8-8067-000c299a5e15/pod-i-pv-prebound-w-provisioned"
I1119 15:56:42.157668  127596 scheduler_binder.go:529] PersistentVolume "pvc-a693d4b0-ebd0-11e8-8067-000c299a5e15", Node "node-1" matches for Pod "volume-schedulinga42c7715-ebd0-11e8-8067-000c299a5e15/pod-i-pv-prebound-w-provisioned"
I1119 15:56:42.157672  127596 scheduler_binder.go:532] All bound volumes for Pod "volume-schedulinga42c7715-ebd0-11e8-8067-000c299a5e15/pod-i-pv-prebound-w-provisioned" match with Node "node-1"
I1119 15:56:42.157706  127596 scheduler_binder.go:207] AssumePodVolumes for pod "volume-schedulinga42c7715-ebd0-11e8-8067-000c299a5e15/pod-i-pv-prebound-w-provisioned", node "node-1"
I1119 15:56:42.157728  127596 scheduler_binder.go:458] PVC "volume-schedulinga42c7715-ebd0-11e8-8067-000c299a5e15/pvc-i-pv-prebound" is fully bound to PV "pv-i-prebound"
I1119 15:56:42.157733  127596 scheduler_binder.go:458] PVC "volume-schedulinga42c7715-ebd0-11e8-8067-000c299a5e15/pvc-canprovision" is fully bound to PV "pvc-a693d4b0-ebd0-11e8-8067-000c299a5e15"
I1119 15:56:42.157738  127596 scheduler_binder.go:217] AssumePodVolumes for pod "volume-schedulinga42c7715-ebd0-11e8-8067-000c299a5e15/pod-i-pv-prebound-w-provisioned", node "node-1": all PVCs bound and nothing to do
E1119 15:56:42.157744  127596 scheduler.go:433] scheduler cache AssumePod failed: pod a6940066-ebd0-11e8-8067-000c299a5e15 is in the cache, so can't be assumed
E1119 15:56:42.157748  127596 factory.go:1465] Error scheduling volume-schedulinga42c7715-ebd0-11e8-8067-000c299a5e15/pod-i-pv-prebound-w-provisioned: pod a6940066-ebd0-11e8-8067-000c299a5e15 is in the cache, so can't be assumed; retrying
I1119 15:56:42.157775  127596 factory.go:1558] Updating pod condition for volume-schedulinga42c7715-ebd0-11e8-8067-000c299a5e15/pod-i-pv-prebound-w-provisioned to (PodScheduled==False)
E1119 15:56:42.157781  127596 scheduler.go:556] error assuming pod: pod a6940066-ebd0-11e8-8067-000c299a5e15 is in the cache, so can't be assumed
I1119 15:56:42.158683  127596 factory.go:1338] About to try and schedule pod volume-schedulinga42c7715-ebd0-11e8-8067-000c299a5e15/pod-i-pv-prebound-w-provisioned
I1119 15:56:42.158705  127596 scheduler.go:508] Attempting to schedule pod: volume-schedulinga42c7715-ebd0-11e8-8067-000c299a5e15/pod-i-pv-prebound-w-provisioned
I1119 15:56:42.158755  127596 scheduler_binder.go:147] FindPodVolumes for pod "volume-schedulinga42c7715-ebd0-11e8-8067-000c299a5e15/pod-i-pv-prebound-w-provisioned", node "node-1"
I1119 15:56:42.158770  127596 scheduler_binder.go:458] PVC "volume-schedulinga42c7715-ebd0-11e8-8067-000c299a5e15/pvc-i-pv-prebound" is fully bound to PV "pv-i-prebound"
I1119 15:56:42.158774  127596 scheduler_binder.go:458] PVC "volume-schedulinga42c7715-ebd0-11e8-8067-000c299a5e15/pvc-canprovision" is fully bound to PV "pvc-a693d4b0-ebd0-11e8-8067-000c299a5e15"
I1119 15:56:42.158786  127596 scheduler_binder.go:529] PersistentVolume "pv-i-prebound", Node "node-1" matches for Pod "volume-schedulinga42c7715-ebd0-11e8-8067-000c299a5e15/pod-i-pv-prebound-w-provisioned"
I1119 15:56:42.158791  127596 scheduler_binder.go:529] PersistentVolume "pvc-a693d4b0-ebd0-11e8-8067-000c299a5e15", Node "node-1" matches for Pod "volume-schedulinga42c7715-ebd0-11e8-8067-000c299a5e15/pod-i-pv-prebound-w-provisioned"
I1119 15:56:42.158795  127596 scheduler_binder.go:532] All bound volumes for Pod "volume-schedulinga42c7715-ebd0-11e8-8067-000c299a5e15/pod-i-pv-prebound-w-provisioned" match with Node "node-1"
I1119 15:56:42.158828  127596 scheduler_binder.go:207] AssumePodVolumes for pod "volume-schedulinga42c7715-ebd0-11e8-8067-000c299a5e15/pod-i-pv-prebound-w-provisioned", node "node-1"
I1119 15:56:42.158848  127596 scheduler_binder.go:458] PVC "volume-schedulinga42c7715-ebd0-11e8-8067-000c299a5e15/pvc-i-pv-prebound" is fully bound to PV "pv-i-prebound"
I1119 15:56:42.158854  127596 scheduler_binder.go:458] PVC "volume-schedulinga42c7715-ebd0-11e8-8067-000c299a5e15/pvc-canprovision" is fully bound to PV "pvc-a693d4b0-ebd0-11e8-8067-000c299a5e15"
I1119 15:56:42.158859  127596 scheduler_binder.go:217] AssumePodVolumes for pod "volume-schedulinga42c7715-ebd0-11e8-8067-000c299a5e15/pod-i-pv-prebound-w-provisioned", node "node-1": all PVCs bound and nothing to do
E1119 15:56:42.158865  127596 scheduler.go:433] scheduler cache AssumePod failed: pod a6940066-ebd0-11e8-8067-000c299a5e15 is in the cache, so can't be assumed
E1119 15:56:42.158868  127596 factory.go:1465] Error scheduling volume-schedulinga42c7715-ebd0-11e8-8067-000c299a5e15/pod-i-pv-prebound-w-provisioned: pod a6940066-ebd0-11e8-8067-000c299a5e15 is in the cache, so can't be assumed; retrying
I1119 15:56:42.158895  127596 factory.go:1558] Updating pod condition for volume-schedulinga42c7715-ebd0-11e8-8067-000c299a5e15/pod-i-pv-prebound-w-provisioned to (PodScheduled==False)
E1119 15:56:42.158901  127596 scheduler.go:556] error assuming pod: pod a6940066-ebd0-11e8-8067-000c299a5e15 is in the cache, so can't be assumed
I1119 15:56:42.159771  127596 factory.go:1338] About to try and schedule pod volume-schedulinga42c7715-ebd0-11e8-8067-000c299a5e15/pod-i-pv-prebound-w-provisioned
I1119 15:56:42.159793  127596 scheduler.go:508] Attempting to schedule pod: volume-schedulinga42c7715-ebd0-11e8-8067-000c299a5e15/pod-i-pv-prebound-w-provisioned
I1119 15:56:42.159842  127596 scheduler_binder.go:147] FindPodVolumes for pod "volume-schedulinga42c7715-ebd0-11e8-8067-000c299a5e15/pod-i-pv-prebound-w-provisioned", node "node-1"
I1119 15:56:42.159857  127596 scheduler_binder.go:458] PVC "volume-schedulinga42c7715-ebd0-11e8-8067-000c299a5e15/pvc-i-pv-prebound" is fully bound to PV "pv-i-prebound"
I1119 15:56:42.159862  127596 scheduler_binder.go:458] PVC "volume-schedulinga42c7715-ebd0-11e8-8067-000c299a5e15/pvc-canprovision" is fully bound to PV "pvc-a693d4b0-ebd0-11e8-8067-000c299a5e15"
I1119 15:56:42.159874  127596 scheduler_binder.go:529] PersistentVolume "pv-i-prebound", Node "node-1" matches for Pod "volume-schedulinga42c7715-ebd0-11e8-8067-000c299a5e15/pod-i-pv-prebound-w-provisioned"
I1119 15:56:42.159878  127596 scheduler_binder.go:529] PersistentVolume "pvc-a693d4b0-ebd0-11e8-8067-000c299a5e15", Node "node-1" matches for Pod "volume-schedulinga42c7715-ebd0-11e8-8067-000c299a5e15/pod-i-pv-prebound-w-provisioned"
I1119 15:56:42.159882  127596 scheduler_binder.go:532] All bound volumes for Pod "volume-schedulinga42c7715-ebd0-11e8-8067-000c299a5e15/pod-i-pv-prebound-w-provisioned" match with Node "node-1"
I1119 15:56:42.159915  127596 scheduler_binder.go:207] AssumePodVolumes for pod "volume-schedulinga42c7715-ebd0-11e8-8067-000c299a5e15/pod-i-pv-prebound-w-provisioned", node "node-1"
I1119 15:56:42.159936  127596 scheduler_binder.go:458] PVC "volume-schedulinga42c7715-ebd0-11e8-8067-000c299a5e15/pvc-i-pv-prebound" is fully bound to PV "pv-i-prebound"
I1119 15:56:42.159942  127596 scheduler_binder.go:458] PVC "volume-schedulinga42c7715-ebd0-11e8-8067-000c299a5e15/pvc-canprovision" is fully bound to PV "pvc-a693d4b0-ebd0-11e8-8067-000c299a5e15"
I1119 15:56:42.159947  127596 scheduler_binder.go:217] AssumePodVolumes for pod "volume-schedulinga42c7715-ebd0-11e8-8067-000c299a5e15/pod-i-pv-prebound-w-provisioned", node "node-1": all PVCs bound and nothing to do
E1119 15:56:42.159953  127596 scheduler.go:433] scheduler cache AssumePod failed: pod a6940066-ebd0-11e8-8067-000c299a5e15 is in the cache, so can't be assumed
E1119 15:56:42.159957  127596 factory.go:1465] Error scheduling volume-schedulinga42c7715-ebd0-11e8-8067-000c299a5e15/pod-i-pv-prebound-w-provisioned: pod a6940066-ebd0-11e8-8067-000c299a5e15 is in the cache, so can't be assumed; retrying
I1119 15:56:42.159972  127596 factory.go:1558] Updating pod condition for volume-schedulinga42c7715-ebd0-11e8-8067-000c299a5e15/pod-i-pv-prebound-w-provisioned to (PodScheduled==False)
E1119 15:56:42.159977  127596 scheduler.go:556] error assuming pod: pod a6940066-ebd0-11e8-8067-000c299a5e15 is in the cache, so can't be assumed
I1119 15:56:42.160912  127596 factory.go:1338] About to try and schedule pod volume-schedulinga42c7715-ebd0-11e8-8067-000c299a5e15/pod-i-pv-prebound-w-provisioned
I1119 15:56:42.160933  127596 scheduler.go:508] Attempting to schedule pod: volume-schedulinga42c7715-ebd0-11e8-8067-000c299a5e15/pod-i-pv-prebound-w-provisioned
I1119 15:56:42.160982  127596 scheduler_binder.go:147] FindPodVolumes for pod "volume-schedulinga42c7715-ebd0-11e8-8067-000c299a5e15/pod-i-pv-prebound-w-provisioned", node "node-1"
I1119 15:56:42.160997  127596 scheduler_binder.go:458] PVC "volume-schedulinga42c7715-ebd0-11e8-8067-000c299a5e15/pvc-i-pv-prebound" is fully bound to PV "pv-i-prebound"
I1119 15:56:42.161001  127596 scheduler_binder.go:458] PVC "volume-schedulinga42c7715-ebd0-11e8-8067-000c299a5e15/pvc-canprovision" is fully bound to PV "pvc-a693d4b0-ebd0-11e8-8067-000c299a5e15"
I1119 15:56:42.161013  127596 scheduler_binder.go:529] PersistentVolume "pv-i-prebound", Node "node-1" matches for Pod "volume-schedulinga42c7715-ebd0-11e8-8067-000c299a5e15/pod-i-pv-prebound-w-provisioned"
I1119 15:56:42.161018  127596 scheduler_binder.go:529] PersistentVolume "pvc-a693d4b0-ebd0-11e8-8067-000c299a5e15", Node "node-1" matches for Pod "volume-schedulinga42c7715-ebd0-11e8-8067-000c299a5e15/pod-i-pv-prebound-w-provisioned"
I1119 15:56:42.161023  127596 scheduler_binder.go:532] All bound volumes for Pod "volume-schedulinga42c7715-ebd0-11e8-8067-000c299a5e15/pod-i-pv-prebound-w-provisioned" match with Node "node-1"
I1119 15:56:42.161054  127596 scheduler_binder.go:207] AssumePodVolumes for pod "volume-schedulinga42c7715-ebd0-11e8-8067-000c299a5e15/pod-i-pv-prebound-w-provisioned", node "node-1"
I1119 15:56:42.161075  127596 scheduler_binder.go:458] PVC "volume-schedulinga42c7715-ebd0-11e8-8067-000c299a5e15/pvc-i-pv-prebound" is fully bound to PV "pv-i-prebound"
I1119 15:56:42.161080  127596 scheduler_binder.go:458] PVC "volume-schedulinga42c7715-ebd0-11e8-8067-000c299a5e15/pvc-canprovision" is fully bound to PV "pvc-a693d4b0-ebd0-11e8-8067-000c299a5e15"
I1119 15:56:42.161085  127596 scheduler_binder.go:217] AssumePodVolumes for pod "volume-schedulinga42c7715-ebd0-11e8-8067-000c299a5e15/pod-i-pv-prebound-w-provisioned", node "node-1": all PVCs bound and nothing to do
E1119 15:56:42.161091  127596 scheduler.go:433] scheduler cache AssumePod failed: pod a6940066-ebd0-11e8-8067-000c299a5e15 is in the cache, so can't be assumed
E1119 15:56:42.161095  127596 factory.go:1465] Error scheduling volume-schedulinga42c7715-ebd0-11e8-8067-000c299a5e15/pod-i-pv-prebound-w-provisioned: pod a6940066-ebd0-11e8-8067-000c299a5e15 is in the cache, so can't be assumed; retrying
I1119 15:56:42.161122  127596 factory.go:1558] Updating pod condition for volume-schedulinga42c7715-ebd0-11e8-8067-000c299a5e15/pod-i-pv-prebound-w-provisioned to (PodScheduled==False)
E1119 15:56:42.161132  127596 scheduler.go:556] error assuming pod: pod a6940066-ebd0-11e8-8067-000c299a5e15 is in the cache, so can't be assumed
I1119 15:56:42.162063  127596 factory.go:1338] About to try and schedule pod volume-schedulinga42c7715-ebd0-11e8-8067-000c299a5e15/pod-i-pv-prebound-w-provisioned
I1119 15:56:42.162088  127596 scheduler.go:508] Attempting to schedule pod: volume-schedulinga42c7715-ebd0-11e8-8067-000c299a5e15/pod-i-pv-prebound-w-provisioned
I1119 15:56:42.162140  127596 scheduler_binder.go:147] FindPodVolumes for pod "volume-schedulinga42c7715-ebd0-11e8-8067-000c299a5e15/pod-i-pv-prebound-w-provisioned", node "node-1"
I1119 15:56:42.162167  127596 scheduler_binder.go:458] PVC "volume-schedulinga42c7715-ebd0-11e8-8067-000c299a5e15/pvc-i-pv-prebound" is fully bound to PV "pv-i-prebound"
I1119 15:56:42.162190  127596 scheduler_binder.go:458] PVC "volume-schedulinga42c7715-ebd0-11e8-8067-000c299a5e15/pvc-canprovision" is fully bound to PV "pvc-a693d4b0-ebd0-11e8-8067-000c299a5e15"
I1119 15:56:42.162204  127596 scheduler_binder.go:529] PersistentVolume "pv-i-prebound", Node "node-1" matches for Pod "volume-schedulinga42c7715-ebd0-11e8-8067-000c299a5e15/pod-i-pv-prebound-w-provisioned"
I1119 15:56:42.162208  127596 scheduler_binder.go:529] PersistentVolume "pvc-a693d4b0-ebd0-11e8-8067-000c299a5e15", Node "node-1" matches for Pod "volume-schedulinga42c7715-ebd0-11e8-8067-000c299a5e15/pod-i-pv-prebound-w-provisioned"
I1119 15:56:42.162213  127596 scheduler_binder.go:532] All bound volumes for Pod "volume-schedulinga42c7715-ebd0-11e8-8067-000c299a5e15/pod-i-pv-prebound-w-provisioned" match with Node "node-1"
I1119 15:56:42.162255  127596 scheduler_binder.go:207] AssumePodVolumes for pod "volume-schedulinga42c7715-ebd0-11e8-8067-000c299a5e15/pod-i-pv-prebound-w-provisioned", node "node-1"
I1119 15:56:42.162277  127596 scheduler_binder.go:458] PVC "volume-schedulinga42c7715-ebd0-11e8-8067-000c299a5e15/pvc-i-pv-prebound" is fully bound to PV "pv-i-prebound"
I1119 15:56:42.162283  127596 scheduler_binder.go:458] PVC "volume-schedulinga42c7715-ebd0-11e8-8067-000c299a5e15/pvc-canprovision" is fully bound to PV "pvc-a693d4b0-ebd0-11e8-8067-000c299a5e15"
I1119 15:56:42.162288  127596 scheduler_binder.go:217] AssumePodVolumes for pod "volume-schedulinga42c7715-ebd0-11e8-8067-000c299a5e15/pod-i-pv-prebound-w-provisioned", node "node-1": all PVCs bound and nothing to do
E1119 15:56:42.162294  127596 scheduler.go:433] scheduler cache AssumePod failed: pod a6940066-ebd0-11e8-8067-000c299a5e15 is in the cache, so can't be assumed
E1119 15:56:42.162298  127596 factory.go:1465] Error scheduling volume-schedulinga42c7715-ebd0-11e8-8067-000c299a5e15/pod-i-pv-prebound-w-provisioned: pod a6940066-ebd0-11e8-8067-000c299a5e15 is in the cache, so can't be assumed; retrying
I1119 15:56:42.162325  127596 factory.go:1558] Updating pod condition for volume-schedulinga42c7715-ebd0-11e8-8067-000c299a5e15/pod-i-pv-prebound-w-provisioned to (PodScheduled==False)
E1119 15:56:42.162331  127596 scheduler.go:556] error assuming pod: pod a6940066-ebd0-11e8-8067-000c299a5e15 is in the cache, so can't be assumed
I1119 15:56:42.163519  127596 factory.go:1338] About to try and schedule pod volume-schedulinga42c7715-ebd0-11e8-8067-000c299a5e15/pod-i-pv-prebound-w-provisioned
I1119 15:56:42.163540  127596 scheduler.go:508] Attempting to schedule pod: volume-schedulinga42c7715-ebd0-11e8-8067-000c299a5e15/pod-i-pv-prebound-w-provisioned
I1119 15:56:42.163588  127596 scheduler_binder.go:147] FindPodVolumes for pod "volume-schedulinga42c7715-ebd0-11e8-8067-000c299a5e15/pod-i-pv-prebound-w-provisioned", node "node-1"
I1119 15:56:42.163602  127596 scheduler_binder.go:458] PVC "volume-schedulinga42c7715-ebd0-11e8-8067-000c299a5e15/pvc-i-pv-prebound" is fully bound to PV "pv-i-prebound"
I1119 15:56:42.163607  127596 scheduler_binder.go:458] PVC "volume-schedulinga42c7715-ebd0-11e8-8067-000c299a5e15/pvc-canprovision" is fully bound to PV "pvc-a693d4b0-ebd0-11e8-8067-000c299a5e15"
I1119 15:56:42.163619  127596 scheduler_binder.go:529] PersistentVolume "pv-i-prebound", Node "node-1" matches for Pod "volume-schedulinga42c7715-ebd0-11e8-8067-000c299a5e15/pod-i-pv-prebound-w-provisioned"
I1119 15:56:42.163624  127596 scheduler_binder.go:529] PersistentVolume "pvc-a693d4b0-ebd0-11e8-8067-000c299a5e15", Node "node-1" matches for Pod "volume-schedulinga42c7715-ebd0-11e8-8067-000c299a5e15/pod-i-pv-prebound-w-provisioned"
I1119 15:56:42.163628  127596 scheduler_binder.go:532] All bound volumes for Pod "volume-schedulinga42c7715-ebd0-11e8-8067-000c299a5e15/pod-i-pv-prebound-w-provisioned" match with Node "node-1"
I1119 15:56:42.163659  127596 scheduler_binder.go:207] AssumePodVolumes for pod "volume-schedulinga42c7715-ebd0-11e8-8067-000c299a5e15/pod-i-pv-prebound-w-provisioned", node "node-1"
I1119 15:56:42.163679  127596 scheduler_binder.go:458] PVC "volume-schedulinga42c7715-ebd0-11e8-8067-000c299a5e15/pvc-i-pv-prebound" is fully bound to PV "pv-i-prebound"
I1119 15:56:42.163685  127596 scheduler_binder.go:458] PVC "volume-schedulinga42c7715-ebd0-11e8-8067-000c299a5e15/pvc-canprovision" is fully bound to PV "pvc-a693d4b0-ebd0-11e8-8067-000c299a5e15"
I1119 15:56:42.163690  127596 scheduler_binder.go:217] AssumePodVolumes for pod "volume-schedulinga42c7715-ebd0-11e8-8067-000c299a5e15/pod-i-pv-prebound-w-provisioned", node "node-1": all PVCs bound and nothing to do
E1119 15:56:42.163696  127596 scheduler.go:433] scheduler cache AssumePod failed: pod a6940066-ebd0-11e8-8067-000c299a5e15 is in the cache, so can't be assumed
E1119 15:56:42.163699  127596 factory.go:1465] Error scheduling volume-schedulinga42c7715-ebd0-11e8-8067-000c299a5e15/pod-i-pv-prebound-w-provisioned: pod a6940066-ebd0-11e8-8067-000c299a5e15 is in the cache, so can't be assumed; retrying
I1119 15:56:42.163725  127596 factory.go:1558] Updating pod condition for volume-schedulinga42c7715-ebd0-11e8-8067-000c299a5e15/pod-i-pv-prebound-w-provisioned to (PodScheduled==False)
E1119 15:56:42.163732  127596 scheduler.go:556] error assuming pod: pod a6940066-ebd0-11e8-8067-000c299a5e15 is in the cache, so can't be assumed
I1119 15:56:42.164692  127596 factory.go:1338] About to try and schedule pod volume-schedulinga42c7715-ebd0-11e8-8067-000c299a5e15/pod-i-pv-prebound-w-provisioned
I1119 15:56:42.164713  127596 scheduler.go:508] Attempting to schedule pod: volume-schedulinga42c7715-ebd0-11e8-8067-000c299a5e15/pod-i-pv-prebound-w-provisioned
I1119 15:56:42.164762  127596 scheduler_binder.go:147] FindPodVolumes for pod "volume-schedulinga42c7715-ebd0-11e8-8067-000c299a5e15/pod-i-pv-prebound-w-provisioned", node "node-1"
I1119 15:56:42.164777  127596 scheduler_binder.go:458] PVC "volume-schedulinga42c7715-ebd0-11e8-8067-000c299a5e15/pvc-i-pv-prebound" is fully bound to PV "pv-i-prebound"
I1119 15:56:42.164783  127596 scheduler_binder.go:458] PVC "volume-schedulinga42c7715-ebd0-11e8-8067-000c299a5e15/pvc-canprovision" is fully bound to PV "pvc-a693d4b0-ebd0-11e8-8067-000c299a5e15"
I1119 15:56:42.164796  127596 scheduler_binder.go:529] PersistentVolume "pv-i-prebound", Node "node-1" matches for Pod "volume-schedulinga42c7715-ebd0-11e8-8067-000c299a5e15/pod-i-pv-prebound-w-provisioned"
I1119 15:56:42.164801  127596 scheduler_binder.go:529] PersistentVolume "pvc-a693d4b0-ebd0-11e8-8067-000c299a5e15", Node "node-1" matches for Pod "volume-schedulinga42c7715-ebd0-11e8-8067-000c299a5e15/pod-i-pv-prebound-w-provisioned"
I1119 15:56:42.164806  127596 scheduler_binder.go:532] All bound volumes for Pod "volume-schedulinga42c7715-ebd0-11e8-8067-000c299a5e15/pod-i-pv-prebound-w-provisioned" match with Node "node-1"
I1119 15:56:42.164837  127596 scheduler_binder.go:207] AssumePodVolumes for pod "volume-schedulinga42c7715-ebd0-11e8-8067-000c299a5e15/pod-i-pv-prebound-w-provisioned", node "node-1"
I1119 15:56:42.164859  127596 scheduler_binder.go:458] PVC "volume-schedulinga42c7715-ebd0-11e8-8067-000c299a5e15/pvc-i-pv-prebound" is fully bound to PV "pv-i-prebound"
I1119 15:56:42.164864  127596 scheduler_binder.go:458] PVC "volume-schedulinga42c7715-ebd0-11e8-8067-000c299a5e15/pvc-canprovision" is fully bound to PV "pvc-a693d4b0-ebd0-11e8-8067-000c299a5e15"
I1119 15:56:42.164869  127596 scheduler_binder.go:217] AssumePodVolumes for pod "volume-schedulinga42c7715-ebd0-11e8-8067-000c299a5e15/pod-i-pv-prebound-w-provisioned", node "node-1": all PVCs bound and nothing to do
E1119 15:56:42.164875  127596 scheduler.go:433] scheduler cache AssumePod failed: pod a6940066-ebd0-11e8-8067-000c299a5e15 is in the cache, so can't be assumed
E1119 15:56:42.164879  127596 factory.go:1465] Error scheduling volume-schedulinga42c7715-ebd0-11e8-8067-000c299a5e15/pod-i-pv-prebound-w-provisioned: pod a6940066-ebd0-11e8-8067-000c299a5e15 is in the cache, so can't be assumed; retrying
I1119 15:56:42.164907  127596 factory.go:1558] Updating pod condition for volume-schedulinga42c7715-ebd0-11e8-8067-000c299a5e15/pod-i-pv-prebound-w-provisioned to (PodScheduled==False)
E1119 15:56:42.164913  127596 scheduler.go:556] error assuming pod: pod a6940066-ebd0-11e8-8067-000c299a5e15 is in the cache, so can't be assumed
I1119 15:56:42.165882  127596 factory.go:1338] About to try and schedule pod volume-schedulinga42c7715-ebd0-11e8-8067-000c299a5e15/pod-i-pv-prebound-w-provisioned
I1119 15:56:42.165914  127596 scheduler.go:508] Attempting to schedule pod: volume-schedulinga42c7715-ebd0-11e8-8067-000c299a5e15/pod-i-pv-prebound-w-provisioned
I1119 15:56:42.165966  127596 scheduler_binder.go:147] FindPodVolumes for pod "volume-schedulinga42c7715-ebd0-11e8-8067-000c299a5e15/pod-i-pv-prebound-w-provisioned", node "node-1"
I1119 15:56:42.165994  127596 scheduler_binder.go:458] PVC "volume-schedulinga42c7715-ebd0-11e8-8067-000c299a5e15/pvc-i-pv-prebound" is fully bound to PV "pv-i-prebound"
I1119 15:56:42.166001  127596 scheduler_binder.go:458] PVC "volume-schedulinga42c7715-ebd0-11e8-8067-000c299a5e15/pvc-canprovision" is fully bound to PV "pvc-a693d4b0-ebd0-11e8-8067-000c299a5e15"
I1119 15:56:42.166014  127596 scheduler_binder.go:529] PersistentVolume "pv-i-prebound", Node "node-1" matches for Pod "volume-schedulinga42c7715-ebd0-11e8-8067-000c299a5e15/pod-i-pv-prebound-w-provisioned"
I1119 15:56:42.166018  127596 scheduler_binder.go:529] PersistentVolume "pvc-a693d4b0-ebd0-11e8-8067-000c299a5e15", Node "node-1" matches for Pod "volume-schedulinga42c7715-ebd0-11e8-8067-000c299a5e15/pod-i-pv-prebound-w-provisioned"
I1119 15:56:42.166023  127596 scheduler_binder.go:532] All bound volumes for Pod "volume-schedulinga42c7715-ebd0-11e8-8067-000c299a5e15/pod-i-pv-prebound-w-provisioned" match with Node "node-1"
I1119 15:56:42.166040  127596 scheduler_binder.go:207] AssumePodVolumes for pod "volume-schedulinga42c7715-ebd0-11e8-8067-000c299a5e15/pod-i-pv-prebound-w-provisioned", node "node-1"
I1119 15:56:42.166045  127596 scheduler_binder.go:458] PVC "volume-schedulinga42c7715-ebd0-11e8-8067-000c299a5e15/pvc-i-pv-prebound" is fully bound to PV "pv-i-prebound"
I1119 15:56:42.166049  127596 scheduler_binder.go:458] PVC "volume-schedulinga42c7715-ebd0-11e8-8067-000c299a5e15/pvc-canprovision" is fully bound to PV "pvc-a693d4b0-ebd0-11e8-8067-000c299a5e15"
I1119 15:56:42.166054  127596 scheduler_binder.go:217] AssumePodVolumes for pod "volume-schedulinga42c7715-ebd0-11e8-8067-000c299a5e15/pod-i-pv-prebound-w-provisioned", node "node-1": all PVCs bound and nothing to do
E1119 15:56:42.166059  127596 scheduler.go:433] scheduler cache AssumePod failed: pod a6940066-ebd0-11e8-8067-000c299a5e15 is in the cache, so can't be assumed
E1119 15:56:42.166063  127596 factory.go:1465] Error scheduling volume-schedulinga42c7715-ebd0-11e8-8067-000c299a5e15/pod-i-pv-prebound-w-provisioned: pod a6940066-ebd0-11e8-8067-000c299a5e15 is in the cache, so can't be assumed; retrying
I1119 15:56:42.166074  127596 factory.go:1558] Updating pod condition for volume-schedulinga42c7715-ebd0-11e8-8067-000c299a5e15/pod-i-pv-prebound-w-provisioned to (PodScheduled==False)
E1119 15:56:42.166079  127596 scheduler.go:556] error assuming pod: pod a6940066-ebd0-11e8-8067-000c299a5e15 is in the cache, so can't be assumed
I1119 15:56:42.167216  127596 factory.go:1338] About to try and schedule pod volume-schedulinga42c7715-ebd0-11e8-8067-000c299a5e15/pod-i-pv-prebound-w-provisioned
I1119 15:56:42.167239  127596 scheduler.go:508] Attempting to schedule pod: volume-schedulinga42c7715-ebd0-11e8-8067-000c299a5e15/pod-i-pv-prebound-w-provisioned
I1119 15:56:42.167292  127596 scheduler_binder.go:147] FindPodVolumes for pod "volume-schedulinga42c7715-ebd0-11e8-8067-000c299a5e15/pod-i-pv-prebound-w-provisioned", node "node-1"
I1119 15:56:42.167307  127596 scheduler_binder.go:458] PVC "volume-schedulinga42c7715-ebd0-11e8-8067-000c299a5e15/pvc-i-pv-prebound" is fully bound to PV "pv-i-prebound"
I1119 15:56:42.167314  127596 scheduler_binder.go:458] PVC "volume-schedulinga42c7715-ebd0-11e8-8067-000c299a5e15/pvc-canprovision" is fully bound to PV "pvc-a693d4b0-ebd0-11e8-8067-000c299a5e15"
I1119 15:56:42.167327  127596 scheduler_binder.go:529] PersistentVolume "pv-i-prebound", Node "node-1" matches for Pod "volume-schedulinga42c7715-ebd0-11e8-8067-000c299a5e15/pod-i-pv-prebound-w-provisioned"
I1119 15:56:42.167332  127596 scheduler_binder.go:529] PersistentVolume "pvc-a693d4b0-ebd0-11e8-8067-000c299a5e15", Node "node-1" matches for Pod "volume-schedulinga42c7715-ebd0-11e8-8067-000c299a5e15/pod-i-pv-prebound-w-provisioned"
I1119 15:56:42.167336  127596 scheduler_binder.go:532] All bound volumes for Pod "volume-schedulinga42c7715-ebd0-11e8-8067-000c299a5e15/pod-i-pv-prebound-w-provisioned" match with Node "node-1"
I1119 15:56:42.167369  127596 scheduler_binder.go:207] AssumePodVolumes for pod "volume-schedulinga42c7715-ebd0-11e8-8067-000c299a5e15/pod-i-pv-prebound-w-provisioned", node "node-1"
I1119 15:56:42.167390  127596 scheduler_binder.go:458] PVC "volume-schedulinga42c7715-ebd0-11e8-8067-000c299a5e15/pvc-i-pv-prebound" is fully bound to PV "pv-i-prebound"
I1119 15:56:42.167396  127596 scheduler_binder.go:458] PVC "volume-schedulinga42c7715-ebd0-11e8-8067-000c299a5e15/pvc-canprovision" is fully bound to PV "pvc-a693d4b0-ebd0-11e8-8067-000c299a5e15"
I1119 15:56:42.167401  127596 scheduler_binder.go:217] AssumePodVolumes for pod "volume-schedulinga42c7715-ebd0-11e8-8067-000c299a5e15/pod-i-pv-prebound-w-provisioned", node "node-1": all PVCs bound and nothing to do
E1119 15:56:42.167407  127596 scheduler.go:433] scheduler cache AssumePod failed: pod a6940066-ebd0-11e8-8067-000c299a5e15 is in the cache, so can't be assumed
E1119 15:56:42.167411  127596 factory.go:1465] Error scheduling volume-schedulinga42c7715-ebd0-11e8-8067-000c299a5e15/pod-i-pv-prebound-w-provisioned: pod a6940066-ebd0-11e8-8067-000c299a5e15 is in the cache, so can't be assumed; retrying
I1119 15:56:42.167454  127596 factory.go:1558] Updating pod condition for volume-schedulinga42c7715-ebd0-11e8-8067-000c299a5e15/pod-i-pv-prebound-w-provisioned to (PodScheduled==False)
E1119 15:56:42.167481  127596 scheduler.go:556] error assuming pod: pod a6940066-ebd0-11e8-8067-000c299a5e15 is in the cache, so can't be assumed
I1119 15:56:42.168571  127596 factory.go:1338] About to try and schedule pod volume-schedulinga42c7715-ebd0-11e8-8067-000c299a5e15/pod-i-pv-prebound-w-provisioned
I1119 15:56:42.168593  127596 scheduler.go:508] Attempting to schedule pod: volume-schedulinga42c7715-ebd0-11e8-8067-000c299a5e15/pod-i-pv-prebound-w-provisioned
I1119 15:56:42.168645  127596 scheduler_binder.go:147] FindPodVolumes for pod "volume-schedulinga42c7715-ebd0-11e8-8067-000c299a5e15/pod-i-pv-prebound-w-provisioned", node "node-1"
I1119 15:56:42.168660  127596 scheduler_binder.go:458] PVC "volume-schedulinga42c7715-ebd0-11e8-8067-000c299a5e15/pvc-i-pv-prebound" is fully bound to PV "pv-i-prebound"
I1119 15:56:42.168667  127596 scheduler_binder.go:458] PVC "volume-schedulinga42c7715-ebd0-11e8-8067-000c299a5e15/pvc-canprovision" is fully bound to PV "pvc-a693d4b0-ebd0-11e8-8067-000c299a5e15"
I1119 15:56:42.168681  127596 scheduler_binder.go:529] PersistentVolume "pv-i-prebound", Node "node-1" matches for Pod "volume-schedulinga42c7715-ebd0-11e8-8067-000c299a5e15/pod-i-pv-prebound-w-provisioned"
I1119 15:56:42.168686  127596 scheduler_binder.go:529] PersistentVolume "pvc-a693d4b0-ebd0-11e8-8067-000c299a5e15", Node "node-1" matches for Pod "volume-schedulinga42c7715-ebd0-11e8-8067-000c299a5e15/pod-i-pv-prebound-w-provisioned"
I1119 15:56:42.168691  127596 scheduler_binder.go:532] All bound volumes for Pod "volume-schedulinga42c7715-ebd0-11e8-8067-000c299a5e15/pod-i-pv-prebound-w-provisioned" match with Node "node-1"
I1119 15:56:42.168725  127596 scheduler_binder.go:207] AssumePodVolumes for pod "volume-schedulinga42c7715-ebd0-11e8-8067-000c299a5e15/pod-i-pv-prebound-w-provisioned", node "node-1"
I1119 15:56:42.168746  127596 scheduler_binder.go:458] PVC "volume-schedulinga42c7715-ebd0-11e8-8067-000c299a5e15/pvc-i-pv-prebound" is fully bound to PV "pv-i-prebound"
I1119 15:56:42.168752  127596 scheduler_binder.go:458] PVC "volume-schedulinga42c7715-ebd0-11e8-8067-000c299a5e15/pvc-canprovision" is fully bound to PV "pvc-a693d4b0-ebd0-11e8-8067-000c299a5e15"
I1119 15:56:42.168756  127596 scheduler_binder.go:217] AssumePodVolumes for pod "volume-schedulinga42c7715-ebd0-11e8-8067-000c299a5e15/pod-i-pv-prebound-w-provisioned", node "node-1": all PVCs bound and nothing to do
E1119 15:56:42.168762  127596 scheduler.go:433] scheduler cache AssumePod failed: pod a6940066-ebd0-11e8-8067-000c299a5e15 is in the cache, so can't be assumed
E1119 15:56:42.168766  127596 factory.go:1465] Error scheduling volume-schedulinga42c7715-ebd0-11e8-8067-000c299a5e15/pod-i-pv-prebound-w-provisioned: pod a6940066-ebd0-11e8-8067-000c299a5e15 is in the cache, so can't be assumed; retrying
I1119 15:56:42.168792  127596 factory.go:1558] Updating pod condition for volume-schedulinga42c7715-ebd0-11e8-8067-000c299a5e15/pod-i-pv-prebound-w-provisioned to (PodScheduled==False)
E1119 15:56:42.168799  127596 scheduler.go:556] error assuming pod: pod a6940066-ebd0-11e8-8067-000c299a5e15 is in the cache, so can't be assumed
I1119 15:56:42.169593  127596 factory.go:1338] About to try and schedule pod volume-schedulinga42c7715-ebd0-11e8-8067-000c299a5e15/pod-i-pv-prebound-w-provisioned
I1119 15:56:42.169629  127596 scheduler.go:508] Attempting to schedule pod: volume-schedulinga42c7715-ebd0-11e8-8067-000c299a5e15/pod-i-pv-prebound-w-provisioned
I1119 15:56:42.169695  127596 scheduler_binder.go:147] FindPodVolumes for pod "volume-schedulinga42c7715-ebd0-11e8-8067-000c299a5e15/pod-i-pv-prebound-w-provisioned", node "node-1"
I1119 15:56:42.169726  127596 scheduler_binder.go:458] PVC "volume-schedulinga42c7715-ebd0-11e8-8067-000c299a5e15/pvc-i-pv-prebound" is fully bound to PV "pv-i-prebound"
I1119 15:56:42.169733  127596 scheduler_binder.go:458] PVC "volume-schedulinga42c7715-ebd0-11e8-8067-000c299a5e15/pvc-canprovision" is fully bound to PV "pvc-a693d4b0-ebd0-11e8-8067-000c299a5e15"
I1119 15:56:42.169745  127596 scheduler_binder.go:529] PersistentVolume "pv-i-prebound", Node "node-1" matches for Pod "volume-schedulinga42c7715-ebd0-11e8-8067-000c299a5e15/pod-i-pv-prebound-w-provisioned"
I1119 15:56:42.169750  127596 scheduler_binder.go:529] PersistentVolume "pvc-a693d4b0-ebd0-11e8-8067-000c299a5e15", Node "node-1" matches for Pod "volume-schedulinga42c7715-ebd0-11e8-8067-000c299a5e15/pod-i-pv-prebound-w-provisioned"
I1119 15:56:42.169754  127596 scheduler_binder.go:532] All bound volumes for Pod "volume-schedulinga42c7715-ebd0-11e8-8067-000c299a5e15/pod-i-pv-prebound-w-provisioned" match with Node "node-1"
I1119 15:56:42.169787  127596 scheduler_binder.go:207] AssumePodVolumes for pod "volume-schedulinga42c7715-ebd0-11e8-8067-000c299a5e15/pod-i-pv-prebound-w-provisioned", node "node-1"
I1119 15:56:42.169797  127596 scheduler_binder.go:458] PVC "volume-schedulinga42c7715-ebd0-11e8-8067-000c299a5e15/pvc-i-pv-prebound" is fully bound to PV "pv-i-prebound"
I1119 15:56:42.169801  127596 scheduler_binder.go:458] PVC "volume-schedulinga42c7715-ebd0-11e8-8067-000c299a5e15/pvc-canprovision" is fully bound to PV "pvc-a693d4b0-ebd0-11e8-8067-000c299a5e15"
I1119 15:56:42.169806  127596 scheduler_binder.go:217] AssumePodVolumes for pod "volume-schedulinga42c7715-ebd0-11e8-8067-000c299a5e15/pod-i-pv-prebound-w-provisioned", node "node-1": all PVCs bound and nothing to do
E1119 15:56:42.169812  127596 scheduler.go:433] scheduler cache AssumePod failed: pod a6940066-ebd0-11e8-8067-000c299a5e15 is in the cache, so can't be assumed
E1119 15:56:42.169816  127596 factory.go:1465] Error scheduling volume-schedulinga42c7715-ebd0-11e8-8067-000c299a5e15/pod-i-pv-prebound-w-provisioned: pod a6940066-ebd0-11e8-8067-000c299a5e15 is in the cache, so can't be assumed; retrying
I1119 15:56:42.169848  127596 factory.go:1558] Updating pod condition for volume-schedulinga42c7715-ebd0-11e8-8067-000c299a5e15/pod-i-pv-prebound-w-provisioned to (PodScheduled==False)
E1119 15:56:42.169856  127596 scheduler.go:556] error assuming pod: pod a6940066-ebd0-11e8-8067-000c299a5e15 is in the cache, so can't be assumed
I1119 15:56:42.170886  127596 factory.go:1338] About to try and schedule pod volume-schedulinga42c7715-ebd0-11e8-8067-000c299a5e15/pod-i-pv-prebound-w-provisioned
I1119 15:56:42.170907  127596 scheduler.go:508] Attempting to schedule pod: volume-schedulinga42c7715-ebd0-11e8-8067-000c299a5e15/pod-i-pv-prebound-w-provisioned
I1119 15:56:42.170956  127596 scheduler_binder.go:147] FindPodVolumes for pod "volume-schedulinga42c7715-ebd0-11e8-8067-000c299a5e15/pod-i-pv-prebound-w-provisioned", node "node-1"
I1119 15:56:42.170985  127596 scheduler_binder.go:458] PVC "volume-schedulinga42c7715-ebd0-11e8-8067-000c299a5e15/pvc-i-pv-prebound" is fully bound to PV "pv-i-prebound"
I1119 15:56:42.170992  127596 scheduler_binder.go:458] PVC "volume-schedulinga42c7715-ebd0-11e8-8067-000c299a5e15/pvc-canprovision" is fully bound to PV "pvc-a693d4b0-ebd0-11e8-8067-000c299a5e15"
I1119 15:56:42.171005  127596 scheduler_binder.go:529] PersistentVolume "pv-i-prebound", Node "node-1" matches for Pod "volume-schedulinga42c7715-ebd0-11e8-8067-000c299a5e15/pod-i-pv-prebound-w-provisioned"
I1119 15:56:42.171010  127596 scheduler_binder.go:529] PersistentVolume "pvc-a693d4b0-ebd0-11e8-8067-000c299a5e15", Node "node-1" matches for Pod "volume-schedulinga42c7715-ebd0-11e8-8067-000c299a5e15/pod-i-pv-prebound-w-provisioned"
I1119 15:56:42.171014  127596 scheduler_binder.go:532] All bound volumes for Pod "volume-schedulinga42c7715-ebd0-11e8-8067-000c299a5e15/pod-i-pv-prebound-w-provisioned" match with Node "node-1"
I1119 15:56:42.171033  127596 scheduler_binder.go:207] AssumePodVolumes for pod "volume-schedulinga42c7715-ebd0-11e8-8067-000c299a5e15/pod-i-pv-prebound-w-provisioned", node "node-1"
I1119 15:56:42.171038  127596 scheduler_binder.go:458] PVC "volume-schedulinga42c7715-ebd0-11e8-8067-000c299a5e15/pvc-i-pv-prebound" is fully bound to PV "pv-i-prebound"
I1119 15:56:42.171042  127596 scheduler_binder.go:458] PVC "volume-schedulinga42c7715-ebd0-11e8-8067-000c299a5e15/pvc-canprovision" is fully bound to PV "pvc-a693d4b0-ebd0-11e8-8067-000c299a5e15"
I1119 15:56:42.171047  127596 scheduler_binder.go:217] AssumePodVolumes for pod "volume-schedulinga42c7715-ebd0-11e8-8067-000c299a5e15/pod-i-pv-prebound-w-provisioned", node "node-1": all PVCs bound and nothing to do
E1119 15:56:42.171052  127596 scheduler.go:433] scheduler cache AssumePod failed: pod a6940066-ebd0-11e8-8067-000c299a5e15 is in the cache, so can't be assumed
E1119 15:56:42.171056  127596 factory.go:1465] Error scheduling volume-schedulinga42c7715-ebd0-11e8-8067-000c299a5e15/pod-i-pv-prebound-w-provisioned: pod a6940066-ebd0-11e8-8067-000c299a5e15 is in the cache, so can't be assumed; retrying
I1119 15:56:42.171068  127596 factory.go:1558] Updating pod condition for volume-schedulinga42c7715-ebd0-11e8-8067-000c299a5e15/pod-i-pv-prebound-w-provisioned to (PodScheduled==False)
E1119 15:56:42.171073  127596 scheduler.go:556] error assuming pod: pod a6940066-ebd0-11e8-8067-000c299a5e15 is in the cache, so can't be assumed
I1119 15:56:42.172064  127596 factory.go:1338] About to try and schedule pod volume-schedulinga42c7715-ebd0-11e8-8067-000c299a5e15/pod-i-pv-prebound-w-provisioned
I1119 15:56:42.172084  127596 scheduler.go:508] Attempting to schedule pod: volume-schedulinga42c7715-ebd0-11e8-8067-000c299a5e15/pod-i-pv-prebound-w-provisioned
I1119 15:56:42.172133  127596 scheduler_binder.go:147] FindPodVolumes for pod "volume-schedulinga42c7715-ebd0-11e8-8067-000c299a5e15/pod-i-pv-prebound-w-provisioned", node "node-1"
I1119 15:56:42.172147  127596 scheduler_binder.go:458] PVC "volume-schedulinga42c7715-ebd0-11e8-8067-000c299a5e15/pvc-i-pv-prebound" is fully bound to PV "pv-i-prebound"
I1119 15:56:42.172151  127596 scheduler_binder.go:458] PVC "volume-schedulinga42c7715-ebd0-11e8-8067-000c299a5e15/pvc-canprovision" is fully bound to PV "pvc-a693d4b0-ebd0-11e8-8067-000c299a5e15"
I1119 15:56:42.172163  127596 scheduler_binder.go:529] PersistentVolume "pv-i-prebound", Node "node-1" matches for Pod "volume-schedulinga42c7715-ebd0-11e8-8067-000c299a5e15/pod-i-pv-prebound-w-provisioned"
I1119 15:56:42.172170  127596 scheduler_binder.go:529] PersistentVolume "pvc-a693d4b0-ebd0-11e8-8067-000c299a5e15", Node "node-1" matches for Pod "volume-schedulinga42c7715-ebd0-11e8-8067-000c299a5e15/pod-i-pv-prebound-w-provisioned"
I1119 15:56:42.172174  127596 scheduler_binder.go:532] All bound volumes for Pod "volume-schedulinga42c7715-ebd0-11e8-8067-000c299a5e15/pod-i-pv-prebound-w-provisioned" match with Node "node-1"
I1119 15:56:42.172205  127596 scheduler_binder.go:207] AssumePodVolumes for pod "volume-schedulinga42c7715-ebd0-11e8-8067-000c299a5e15/pod-i-pv-prebound-w-provisioned", node "node-1"
I1119 15:56:42.172213  127596 scheduler_binder.go:458] PVC "volume-schedulinga42c7715-ebd0-11e8-8067-000c299a5e15/pvc-i-pv-prebound" is fully bound to PV "pv-i-prebound"
I1119 15:56:42.172217  127596 scheduler_binder.go:458] PVC "volume-schedulinga42c7715-ebd0-11e8-8067-000c299a5e15/pvc-canprovision" is fully bound to PV "pvc-a693d4b0-ebd0-11e8-8067-000c299a5e15"
I1119 15:56:42.172221  127596 scheduler_binder.go:217] AssumePodVolumes for pod "volume-schedulinga42c7715-ebd0-11e8-8067-000c299a5e15/pod-i-pv-prebound-w-provisioned", node "node-1": all PVCs bound and nothing to do
E1119 15:56:42.172227  127596 scheduler.go:433] scheduler cache AssumePod failed: pod a6940066-ebd0-11e8-8067-000c299a5e15 is in the cache, so can't be assumed
E1119 15:56:42.172230  127596 factory.go:1465] Error scheduling volume-schedulinga42c7715-ebd0-11e8-8067-000c299a5e15/pod-i-pv-prebound-w-provisioned: pod a6940066-ebd0-11e8-8067-000c299a5e15 is in the cache, so can't be assumed; retrying
I1119 15:56:42.172244  127596 factory.go:1558] Updating pod condition for volume-schedulinga42c7715-ebd0-11e8-8067-000c299a5e15/pod-i-pv-prebound-w-provisioned to (PodScheduled==False)
E1119 15:56:42.172250  127596 scheduler.go:556] error assuming pod: pod a6940066-ebd0-11e8-8067-000c299a5e15 is in the cache, so can't be assumed
I1119 15:56:42.173112  127596 factory.go:1338] About to try and schedule pod volume-schedulinga42c7715-ebd0-11e8-8067-000c299a5e15/pod-i-pv-prebound-w-provisioned
I1119 15:56:42.173135  127596 scheduler.go:508] Attempting to schedule pod: volume-schedulinga42c7715-ebd0-11e8-8067-000c299a5e15/pod-i-pv-prebound-w-provisioned
I1119 15:56:42.173186  127596 scheduler_binder.go:147] FindPodVolumes for pod "volume-schedulinga42c7715-ebd0-11e8-8067-000c299a5e15/pod-i-pv-prebound-w-provisioned", node "node-1"
I1119 15:56:42.173201  127596 scheduler_binder.go:458] PVC "volume-schedulinga42c7715-ebd0-11e8-8067-000c299a5e15/pvc-i-pv-prebound" is fully bound to PV "pv-i-prebound"
I1119 15:56:42.173205  127596 scheduler_binder.go:458] PVC "volume-schedulinga42c7715-ebd0-11e8-8067-000c299a5e15/pvc-canprovision" is fully bound to PV "pvc-a693d4b0-ebd0-11e8-8067-000c299a5e15"
I1119 15:56:42.173218  127596 scheduler_binder.go:529] PersistentVolume "pv-i-prebound", Node "node-1" matches for Pod "volume-schedulinga42c7715-ebd0-11e8-8067-000c299a5e15/pod-i-pv-prebound-w-provisioned"
I1119 15:56:42.173222  127596 scheduler_binder.go:529] PersistentVolume "pvc-a693d4b0-ebd0-11e8-8067-000c299a5e15", Node "node-1" matches for Pod "volume-schedulinga42c7715-ebd0-11e8-8067-000c299a5e15/pod-i-pv-prebound-w-provisioned"
I1119 15:56:42.173227  127596 scheduler_binder.go:532] All bound volumes for Pod "volume-schedulinga42c7715-ebd0-11e8-8067-000c299a5e15/pod-i-pv-prebound-w-provisioned" match with Node "node-1"
I1119 15:56:42.173245  127596 scheduler_binder.go:207] AssumePodVolumes for pod "volume-schedulinga42c7715-ebd0-11e8-8067-000c299a5e15/pod-i-pv-prebound-w-provisioned", node "node-1"
I1119 15:56:42.173251  127596 scheduler_binder.go:458] PVC "volume-schedulinga42c7715-ebd0-11e8-8067-000c299a5e15/pvc-i-pv-prebound" is fully bound to PV "pv-i-prebound"
I1119 15:56:42.173255  127596 scheduler_binder.go:458] PVC "volume-schedulinga42c7715-ebd0-11e8-8067-000c299a5e15/pvc-canprovision" is fully bound to PV "pvc-a693d4b0-ebd0-11e8-8067-000c299a5e15"
I1119 15:56:42.173264  127596 scheduler_binder.go:217] AssumePodVolumes for pod "volume-schedulinga42c7715-ebd0-11e8-8067-000c299a5e15/pod-i-pv-prebound-w-provisioned", node "node-1": all PVCs bound and nothing to do
E1119 15:56:42.173269  127596 scheduler.go:433] scheduler cache AssumePod failed: pod a6940066-ebd0-11e8-8067-000c299a5e15 is in the cache, so can't be assumed
E1119 15:56:42.173273  127596 factory.go:1465] Error scheduling volume-schedulinga42c7715-ebd0-11e8-8067-000c299a5e15/pod-i-pv-prebound-w-provisioned: pod a6940066-ebd0-11e8-8067-000c299a5e15 is in the cache, so can't be assumed; retrying
I1119 15:56:42.173300  127596 factory.go:1558] Updating pod condition for volume-schedulinga42c7715-ebd0-11e8-8067-000c299a5e15/pod-i-pv-prebound-w-provisioned to (PodScheduled==False)
E1119 15:56:42.173308  127596 scheduler.go:556] error assuming pod: pod a6940066-ebd0-11e8-8067-000c299a5e15 is in the cache, so can't be assumed
I1119 15:56:42.174194  127596 factory.go:1338] About to try and schedule pod volume-schedulinga42c7715-ebd0-11e8-8067-000c299a5e15/pod-i-pv-prebound-w-provisioned
I1119 15:56:42.174219  127596 scheduler.go:508] Attempting to schedule pod: volume-schedulinga42c7715-ebd0-11e8-8067-000c299a5e15/pod-i-pv-prebound-w-provisioned
I1119 15:56:42.174270  127596 scheduler_binder.go:147] FindPodVolumes for pod "volume-schedulinga42c7715-ebd0-11e8-8067-000c299a5e15/pod-i-pv-prebound-w-provisioned", node "node-1"
I1119 15:56:42.174284  127596 scheduler_binder.go:458] PVC "volume-schedulinga42c7715-ebd0-11e8-8067-000c299a5e15/pvc-i-pv-prebound" is fully bound to PV "pv-i-prebound"
I1119 15:56:42.174290  127596 scheduler_binder.go:458] PVC "volume-schedulinga42c7715-ebd0-11e8-8067-000c299a5e15/pvc-canprovision" is fully bound to PV "pvc-a693d4b0-ebd0-11e8-8067-000c299a5e15"
I1119 15:56:42.174304  127596 scheduler_binder.go:529] PersistentVolume "pv-i-prebound", Node "node-1" matches for Pod "volume-schedulinga42c7715-ebd0-11e8-8067-000c299a5e15/pod-i-pv-prebound-w-provisioned"
I1119 15:56:42.174311  127596 scheduler_binder.go:529] PersistentVolume "pvc-a693d4b0-ebd0-11e8-8067-000c299a5e15", Node "node-1" matches for Pod "volume-schedulinga42c7715-ebd0-11e8-8067-000c299a5e15/pod-i-pv-prebound-w-provisioned"
I1119 15:56:42.174316  127596 scheduler_binder.go:532] All bound volumes for Pod "volume-schedulinga42c7715-ebd0-11e8-8067-000c299a5e15/pod-i-pv-prebound-w-provisioned" match with Node "node-1"
I1119 15:56:42.174347  127596 scheduler_binder.go:207] AssumePodVolumes for pod "volume-schedulinga42c7715-ebd0-11e8-8067-000c299a5e15/pod-i-pv-prebound-w-provisioned", node "node-1"
I1119 15:56:42.174355  127596 scheduler_binder.go:458] PVC "volume-schedulinga42c7715-ebd0-11e8-8067-000c299a5e15/pvc-i-pv-prebound" is fully bound to PV "pv-i-prebound"
I1119 15:56:42.174359  127596 scheduler_binder.go:458] PVC "volume-schedulinga42c7715-ebd0-11e8-8067-000c299a5e15/pvc-canprovision" is fully bound to PV "pvc-a693d4b0-ebd0-11e8-8067-000c299a5e15"
I1119 15:56:42.174363  127596 scheduler_binder.go:217] AssumePodVolumes for pod "volume-schedulinga42c7715-ebd0-11e8-8067-000c299a5e15/pod-i-pv-prebound-w-provisioned", node "node-1": all PVCs bound and nothing to do
E1119 15:56:42.174369  127596 scheduler.go:433] scheduler cache AssumePod failed: pod a6940066-ebd0-11e8-8067-000c299a5e15 is in the cache, so can't be assumed
E1119 15:56:42.174372  127596 factory.go:1465] Error scheduling volume-schedulinga42c7715-ebd0-11e8-8067-000c299a5e15/pod-i-pv-prebound-w-provisioned: pod a6940066-ebd0-11e8-8067-000c299a5e15 is in the cache, so can't be assumed; retrying
I1119 15:56:42.174387  127596 factory.go:1558] Updating pod condition for volume-schedulinga42c7715-ebd0-11e8-8067-000c299a5e15/pod-i-pv-prebound-w-provisioned to (PodScheduled==False)
E1119 15:56:42.174393  127596 scheduler.go:556] error assuming pod: pod a6940066-ebd0-11e8-8067-000c299a5e15 is in the cache, so can't be assumed
I1119 15:56:42.175275  127596 factory.go:1338] About to try and schedule pod volume-schedulinga42c7715-ebd0-11e8-8067-000c299a5e15/pod-i-pv-prebound-w-provisioned
I1119 15:56:42.175298  127596 scheduler.go:508] Attempting to schedule pod: volume-schedulinga42c7715-ebd0-11e8-8067-000c299a5e15/pod-i-pv-prebound-w-provisioned
I1119 15:56:42.175349  127596 scheduler_binder.go:147] FindPodVolumes for pod "volume-schedulinga42c7715-ebd0-11e8-8067-000c299a5e15/pod-i-pv-prebound-w-provisioned", node "node-1"
I1119 15:56:42.175363  127596 scheduler_binder.go:458] PVC "volume-schedulinga42c7715-ebd0-11e8-8067-000c299a5e15/pvc-i-pv-prebound" is fully bound to PV "pv-i-prebound"
I1119 15:56:42.175369  127596 scheduler_binder.go:458] PVC "volume-schedulinga42c7715-ebd0-11e8-8067-000c299a5e15/pvc-canprovision" is fully bound to PV "pvc-a693d4b0-ebd0-11e8-8067-000c299a5e15"
I1119 15:56:42.175383  127596 scheduler_binder.go:529] PersistentVolume "pv-i-prebound", Node "node-1" matches for Pod "volume-schedulinga42c7715-ebd0-11e8-8067-000c299a5e15/pod-i-pv-prebound-w-provisioned"
I1119 15:56:42.175390  127596 scheduler_binder.go:529] PersistentVolume "pvc-a693d4b0-ebd0-11e8-8067-000c299a5e15", Node "node-1" matches for Pod "volume-schedulinga42c7715-ebd0-11e8-8067-000c299a5e15/pod-i-pv-prebound-w-provisioned"
I1119 15:56:42.175394  127596 scheduler_binder.go:532] All bound volumes for Pod "volume-schedulinga42c7715-ebd0-11e8-8067-000c299a5e15/pod-i-pv-prebound-w-provisioned" match with Node "node-1"
I1119 15:56:42.175411  127596 scheduler_binder.go:207] AssumePodVolumes for pod "volume-schedulinga42c7715-ebd0-11e8-8067-000c299a5e15/pod-i-pv-prebound-w-provisioned", node "node-1"
I1119 15:56:42.175416  127596 scheduler_binder.go:458] PVC "volume-schedulinga42c7715-ebd0-11e8-8067-000c299a5e15/pvc-i-pv-prebound" is fully bound to PV "pv-i-prebound"
I1119 15:56:42.175420  127596 scheduler_binder.go:458] PVC "volume-schedulinga42c7715-ebd0-11e8-8067-000c299a5e15/pvc-canprovision" is fully bound to PV "pvc-a693d4b0-ebd0-11e8-8067-000c299a5e15"
I1119 15:56:42.175424  127596 scheduler_binder.go:217] AssumePodVolumes for pod "volume-schedulinga42c7715-ebd0-11e8-8067-000c299a5e15/pod-i-pv-prebound-w-provisioned", node "node-1": all PVCs bound and nothing to do
E1119 15:56:42.175429  127596 scheduler.go:433] scheduler cache AssumePod failed: pod a6940066-ebd0-11e8-8067-000c299a5e15 is in the cache, so can't be assumed
E1119 15:56:42.175433  127596 factory.go:1465] Error scheduling volume-schedulinga42c7715-ebd0-11e8-8067-000c299a5e15/pod-i-pv-prebound-w-provisioned: pod a6940066-ebd0-11e8-8067-000c299a5e15 is in the cache, so can't be assumed; retrying
I1119 15:56:42.175447  127596 factory.go:1558] Updating pod condition for volume-schedulinga42c7715-ebd0-11e8-8067-000c299a5e15/pod-i-pv-prebound-w-provisioned to (PodScheduled==False)
E1119 15:56:42.175452  127596 scheduler.go:556] error assuming pod: pod a6940066-ebd0-11e8-8067-000c299a5e15 is in the cache, so can't be assumed
I1119 15:56:42.176397  127596 factory.go:1338] About to try and schedule pod volume-schedulinga42c7715-ebd0-11e8-8067-000c299a5e15/pod-i-pv-prebound-w-provisioned
I1119 15:56:42.176418  127596 scheduler.go:508] Attempting to schedule pod: volume-schedulinga42c7715-ebd0-11e8-8067-000c299a5e15/pod-i-pv-prebound-w-provisioned
I1119 15:56:42.176504  127596 scheduler_binder.go:147] FindPodVolumes for pod "volume-schedulinga42c7715-ebd0-11e8-8067-000c299a5e15/pod-i-pv-prebound-w-provisioned", node "node-1"
I1119 15:56:42.176534  127596 scheduler_binder.go:458] PVC "volume-schedulinga42c7715-ebd0-11e8-8067-000c299a5e15/pvc-i-pv-prebound" is fully bound to PV "pv-i-prebound"
I1119 15:56:42.176541  127596 scheduler_binder.go:458] PVC "volume-schedulinga42c7715-ebd0-11e8-8067-000c299a5e15/pvc-canprovision" is fully bound to PV "pvc-a693d4b0-ebd0-11e8-8067-000c299a5e15"
I1119 15:56:42.176553  127596 scheduler_binder.go:529] PersistentVolume "pv-i-prebound", Node "node-1" matches for Pod "volume-schedulinga42c7715-ebd0-11e8-8067-000c299a5e15/pod-i-pv-prebound-w-provisioned"
I1119 15:56:42.176558  127596 scheduler_binder.go:529] PersistentVolume "pvc-a693d4b0-ebd0-11e8-8067-000c299a5e15", Node "node-1" matches for Pod "volume-schedulinga42c7715-ebd0-11e8-8067-000c299a5e15/pod-i-pv-prebound-w-provisioned"
I1119 15:56:42.176562  127596 scheduler_binder.go:532] All bound volumes for Pod "volume-schedulinga42c7715-ebd0-11e8-8067-000c299a5e15/pod-i-pv-prebound-w-provisioned" match with Node "node-1"
I1119 15:56:42.176620  127596 scheduler_binder.go:207] AssumePodVolumes for pod "volume-schedulinga42c7715-ebd0-11e8-8067-000c299a5e15/pod-i-pv-prebound-w-provisioned", node "node-1"
I1119 15:56:42.176626  127596 scheduler_binder.go:458] PVC "volume-schedulinga42c7715-ebd0-11e8-8067-000c299a5e15/pvc-i-pv-prebound" is fully bound to PV "pv-i-prebound"
I1119 15:56:42.176630  127596 scheduler_binder.go:458] PVC "volume-schedulinga42c7715-ebd0-11e8-8067-000c299a5e15/pvc-canprovision" is fully bound to PV "pvc-a693d4b0-ebd0-11e8-8067-000c299a5e15"
I1119 15:56:42.176635  127596 scheduler_binder.go:217] AssumePodVolumes for pod "volume-schedulinga42c7715-ebd0-11e8-8067-000c299a5e15/pod-i-pv-prebound-w-provisioned", node "node-1": all PVCs bound and nothing to do
E1119 15:56:42.176640  127596 scheduler.go:433] scheduler cache AssumePod failed: pod a6940066-ebd0-11e8-8067-000c299a5e15 is in the cache, so can't be assumed
E1119 15:56:42.176644  127596 factory.go:1465] Error scheduling volume-schedulinga42c7715-ebd0-11e8-8067-000c299a5e15/pod-i-pv-prebound-w-provisioned: pod a6940066-ebd0-11e8-8067-000c299a5e15 is in the cache, so can't be assumed; retrying
I1119 15:56:42.176659  127596 factory.go:1558] Updating pod condition for volume-schedulinga42c7715-ebd0-11e8-8067-000c299a5e15/pod-i-pv-prebound-w-provisioned to (PodScheduled==False)
E1119 15:56:42.176709  127596 scheduler.go:556] error assuming pod: pod a6940066-ebd0-11e8-8067-000c299a5e15 is in the cache, so can't be assumed
I1119 15:56:42.177535  127596 factory.go:1338] About to try and schedule pod volume-schedulinga42c7715-ebd0-11e8-8067-000c299a5e15/pod-i-pv-prebound-w-provisioned
I1119 15:56:42.177559  127596 scheduler.go:508] Attempting to schedule pod: volume-schedulinga42c7715-ebd0-11e8-8067-000c299a5e15/pod-i-pv-prebound-w-provisioned
I1119 15:56:42.177592  127596 scheduler_binder.go:147] FindPodVolumes for pod "volume-schedulinga42c7715-ebd0-11e8-8067-000c299a5e15/pod-i-pv-prebound-w-provisioned", node "node-1"
I1119 15:56:42.177605  127596 scheduler_binder.go:458] PVC "volume-schedulinga42c7715-ebd0-11e8-8067-000c299a5e15/pvc-i-pv-prebound" is fully bound to PV "pv-i-prebound"
I1119 15:56:42.177610  127596 scheduler_binder.go:458] PVC "volume-schedulinga42c7715-ebd0-11e8-8067-000c299a5e15/pvc-canprovision" is fully bound to PV "pvc-a693d4b0-ebd0-11e8-8067-000c299a5e15"
I1119 15:56:42.177622  127596 scheduler_binder.go:529] PersistentVolume "pv-i-prebound", Node "node-1" matches for Pod "volume-schedulinga42c7715-ebd0-11e8-8067-000c299a5e15/pod-i-pv-prebound-w-provisioned"
I1119 15:56:42.177627  127596 scheduler_binder.go:529] PersistentVolume "pvc-a693d4b0-ebd0-11e8-8067-000c299a5e15", Node "node-1" matches for Pod "volume-schedulinga42c7715-ebd0-11e8-8067-000c299a5e15/pod-i-pv-prebound-w-provisioned"
I1119 15:56:42.177631  127596 scheduler_binder.go:532] All bound volumes for Pod "volume-schedulinga42c7715-ebd0-11e8-8067-000c299a5e15/pod-i-pv-prebound-w-provisioned" match with Node "node-1"
I1119 15:56:42.177646  127596 scheduler_binder.go:207] AssumePodVolumes for pod "volume-schedulinga42c7715-ebd0-11e8-8067-000c299a5e15/pod-i-pv-prebound-w-provisioned", node "node-1"
I1119 15:56:42.177651  127596 scheduler_binder.go:458] PVC "volume-schedulinga42c7715-ebd0-11e8-8067-000c299a5e15/pvc-i-pv-prebound" is fully bound to PV "pv-i-prebound"
I1119 15:56:42.177655  127596 scheduler_binder.go:458] PVC "volume-schedulinga42c7715-ebd0-11e8-8067-000c299a5e15/pvc-canprovision" is fully bound to PV "pvc-a693d4b0-ebd0-11e8-8067-000c299a5e15"
I1119 15:56:42.177659  127596 scheduler_binder.go:217] AssumePodVolumes for pod "volume-schedulinga42c7715-ebd0-11e8-8067-000c299a5e15/pod-i-pv-prebound-w-provisioned", node "node-1": all PVCs bound and nothing to do
E1119 15:56:42.177664  127596 scheduler.go:433] scheduler cache AssumePod failed: pod a6940066-ebd0-11e8-8067-000c299a5e15 is in the cache, so can't be assumed
E1119 15:56:42.177668  127596 factory.go:1465] Error scheduling volume-schedulinga42c7715-ebd0-11e8-8067-000c299a5e15/pod-i-pv-prebound-w-provisioned: pod a6940066-ebd0-11e8-8067-000c299a5e15 is in the cache, so can't be assumed; retrying
I1119 15:56:42.177680  127596 factory.go:1558] Updating pod condition for volume-schedulinga42c7715-ebd0-11e8-8067-000c299a5e15/pod-i-pv-prebound-w-provisioned to (PodScheduled==False)
E1119 15:56:42.177685  127596 scheduler.go:556] error assuming pod: pod a6940066-ebd0-11e8-8067-000c299a5e15 is in the cache, so can't be assumed
I1119 15:56:42.178597  127596 factory.go:1338] About to try and schedule pod volume-schedulinga42c7715-ebd0-11e8-8067-000c299a5e15/pod-i-pv-prebound-w-provisioned
I1119 15:56:42.178620  127596 scheduler.go:508] Attempting to schedule pod: volume-schedulinga42c7715-ebd0-11e8-8067-000c299a5e15/pod-i-pv-prebound-w-provisioned
I1119 15:56:42.178653  127596 scheduler_binder.go:147] FindPodVolumes for pod "volume-schedulinga42c7715-ebd0-11e8-8067-000c299a5e15/pod-i-pv-prebound-w-provisioned", node "node-1"
I1119 15:56:42.178666  127596 scheduler_binder.go:458] PVC "volume-schedulinga42c7715-ebd0-11e8-8067-000c299a5e15/pvc-i-pv-prebound" is fully bound to PV "pv-i-prebound"
I1119 15:56:42.178671  127596 scheduler_binder.go:458] PVC "volume-schedulinga42c7715-ebd0-11e8-8067-000c299a5e15/pvc-canprovision" is fully bound to PV "pvc-a693d4b0-ebd0-11e8-8067-000c299a5e15"
I1119 15:56:42.178683  127596 scheduler_binder.go:529] PersistentVolume "pv-i-prebound", Node "node-1" matches for Pod "volume-schedulinga42c7715-ebd0-11e8-8067-000c299a5e15/pod-i-pv-prebound-w-provisioned"
I1119 15:56:42.178688  127596 scheduler_binder.go:529] PersistentVolume "pvc-a693d4b0-ebd0-11e8-8067-000c299a5e15", Node "node-1" matches for Pod "volume-schedulinga42c7715-ebd0-11e8-8067-000c299a5e15/pod-i-pv-prebound-w-provisioned"
I1119 15:56:42.178692  127596 scheduler_binder.go:532] All bound volumes for Pod "volume-schedulinga42c7715-ebd0-11e8-8067-000c299a5e15/pod-i-pv-prebound-w-provisioned" match with Node "node-1"
I1119 15:56:42.178709  127596 scheduler_binder.go:207] AssumePodVolumes for pod "volume-schedulinga42c7715-ebd0-11e8-8067-000c299a5e15/pod-i-pv-prebound-w-provisioned", node "node-1"
I1119 15:56:42.178716  127596 scheduler_binder.go:458] PVC "volume-schedulinga42c7715-ebd0-11e8-8067-000c299a5e15/pvc-i-pv-prebound" is fully bound to PV "pv-i-prebound"
I1119 15:56:42.178721  127596 scheduler_binder.go:458] PVC "volume-schedulinga42c7715-ebd0-11e8-8067-000c299a5e15/pvc-canprovision" is fully bound to PV "pvc-a693d4b0-ebd0-11e8-8067-000c299a5e15"
I1119 15:56:42.178726  127596 scheduler_binder.go:217] AssumePodVolumes for pod "volume-schedulinga42c7715-ebd0-11e8-8067-000c299a5e15/pod-i-pv-prebound-w-provisioned", node "node-1": all PVCs bound and nothing to do
E1119 15:56:42.178730  127596 scheduler.go:433] scheduler cache AssumePod failed: pod a6940066-ebd0-11e8-8067-000c299a5e15 is in the cache, so can't be assumed
E1119 15:56:42.178734  127596 factory.go:1465] Error scheduling volume-schedulinga42c7715-ebd0-11e8-8067-000c299a5e15/pod-i-pv-prebound-w-provisioned: pod a6940066-ebd0-11e8-8067-000c299a5e15 is in the cache, so can't be assumed; retrying
I1119 15:56:42.178745  127596 factory.go:1558] Updating pod condition for volume-schedulinga42c7715-ebd0-11e8-8067-000c299a5e15/pod-i-pv-prebound-w-provisioned to (PodScheduled==False)
E1119 15:56:42.178750  127596 scheduler.go:556] error assuming pod: pod a6940066-ebd0-11e8-8067-000c299a5e15 is in the cache, so can't be assumed
I1119 15:56:42.179612  127596 factory.go:1338] About to try and schedule pod volume-schedulinga42c7715-ebd0-11e8-8067-000c299a5e15/pod-i-pv-prebound-w-provisioned
I1119 15:56:42.179636  127596 scheduler.go:508] Attempting to schedule pod: volume-schedulinga42c7715-ebd0-11e8-8067-000c299a5e15/pod-i-pv-prebound-w-provisioned
I1119 15:56:42.179669  127596 scheduler_binder.go:147] FindPodVolumes for pod "volume-schedulinga42c7715-ebd0-11e8-8067-000c299a5e15/pod-i-pv-prebound-w-provisioned", node "node-1"
I1119 15:56:42.179681  127596 scheduler_binder.go:458] PVC "volume-schedulinga42c7715-ebd0-11e8-8067-000c299a5e15/pvc-i-pv-prebound" is fully bound to PV "pv-i-prebound"
I1119 15:56:42.179686  127596 scheduler_binder.go:458] PVC "volume-schedulinga42c7715-ebd0-11e8-8067-000c299a5e15/pvc-canprovision" is fully bound to PV "pvc-a693d4b0-ebd0-11e8-8067-000c299a5e15"
I1119 15:56:42.179697  127596 scheduler_binder.go:529] PersistentVolume "pv-i-prebound", Node "node-1" matches for Pod "volume-schedulinga42c7715-ebd0-11e8-8067-000c299a5e15/pod-i-pv-prebound-w-provisioned"
I1119 15:56:42.179702  127596 scheduler_binder.go:529] PersistentVolume "pvc-a693d4b0-ebd0-11e8-8067-000c299a5e15", Node "node-1" matches for Pod "volume-schedulinga42c7715-ebd0-11e8-8067-000c299a5e15/pod-i-pv-prebound-w-provisioned"
I1119 15:56:42.179706  127596 scheduler_binder.go:532] All bound volumes for Pod "volume-schedulinga42c7715-ebd0-11e8-8067-000c299a5e15/pod-i-pv-prebound-w-provisioned" match with Node "node-1"
I1119 15:56:42.179723  127596 scheduler_binder.go:207] AssumePodVolumes for pod "volume-schedulinga42c7715-ebd0-11e8-8067-000c299a5e15/pod-i-pv-prebound-w-provisioned", node "node-1"
I1119 15:56:42.179730  127596 scheduler_binder.go:458] PVC "volume-schedulinga42c7715-ebd0-11e8-8067-000c299a5e15/pvc-i-pv-prebound" is fully bound to PV "pv-i-prebound"
I1119 15:56:42.179734  127596 scheduler_binder.go:458] PVC "volume-schedulinga42c7715-ebd0-11e8-8067-000c299a5e15/pvc-canprovision" is fully bound to PV "pvc-a693d4b0-ebd0-11e8-8067-000c299a5e15"
I1119 15:56:42.179739  127596 scheduler_binder.go:217] AssumePodVolumes for pod "volume-schedulinga42c7715-ebd0-11e8-8067-000c299a5e15/pod-i-pv-prebound-w-provisioned", node "node-1": all PVCs bound and nothing to do
E1119 15:56:42.179744  127596 scheduler.go:433] scheduler cache AssumePod failed: pod a6940066-ebd0-11e8-8067-000c299a5e15 is in the cache, so can't be assumed
E1119 15:56:42.179748  127596 factory.go:1465] Error scheduling volume-schedulinga42c7715-ebd0-11e8-8067-000c299a5e15/pod-i-pv-prebound-w-provisioned: pod a6940066-ebd0-11e8-8067-000c299a5e15 is in the cache, so can't be assumed; retrying
I1119 15:56:42.179759  127596 factory.go:1558] Updating pod condition for volume-schedulinga42c7715-ebd0-11e8-8067-000c299a5e15/pod-i-pv-prebound-w-provisioned to (PodScheduled==False)
E1119 15:56:42.179764  127596 scheduler.go:556] error assuming pod: pod a6940066-ebd0-11e8-8067-000c299a5e15 is in the cache, so can't be assumed
I1119 15:56:42.180623  127596 factory.go:1338] About to try and schedule pod volume-schedulinga42c7715-ebd0-11e8-8067-000c299a5e15/pod-i-pv-prebound-w-provisioned
I1119 15:56:42.180647  127596 scheduler.go:508] Attempting to schedule pod: volume-schedulinga42c7715-ebd0-11e8-8067-000c299a5e15/pod-i-pv-prebound-w-provisioned
I1119 15:56:42.180680  127596 scheduler_binder.go:147] FindPodVolumes for pod "volume-schedulinga42c7715-ebd0-11e8-8067-000c299a5e15/pod-i-pv-prebound-w-provisioned", node "node-1"
I1119 15:56:42.180692  127596 scheduler_binder.go:458] PVC "volume-schedulinga42c7715-ebd0-11e8-8067-000c299a5e15/pvc-i-pv-prebound" is fully bound to PV "pv-i-prebound"
I1119 15:56:42.180698  127596 scheduler_binder.go:458] PVC "volume-schedulinga42c7715-ebd0-11e8-8067-000c299a5e15/pvc-canprovision" is fully bound to PV "pvc-a693d4b0-ebd0-11e8-8067-000c299a5e15"
I1119 15:56:42.180709  127596 scheduler_binder.go:529] PersistentVolume "pv-i-prebound", Node "node-1" matches for Pod "volume-schedulinga42c7715-ebd0-11e8-8067-000c299a5e15/pod-i-pv-prebound-w-provisioned"
I1119 15:56:42.180716  127596 scheduler_binder.go:529] PersistentVolume "pvc-a693d4b0-ebd0-11e8-8067-000c299a5e15", Node "node-1" matches for Pod "volume-schedulinga42c7715-ebd0-11e8-8067-000c299a5e15/pod-i-pv-prebound-w-provisioned"
I1119 15:56:42.180720  127596 scheduler_binder.go:532] All bound volumes for Pod "volume-schedulinga42c7715-ebd0-11e8-8067-000c299a5e15/pod-i-pv-prebound-w-provisioned" match with Node "node-1"
I1119 15:56:42.180735  127596 scheduler_binder.go:207] AssumePodVolumes for pod "volume-schedulinga42c7715-ebd0-11e8-8067-000c299a5e15/pod-i-pv-prebound-w-provisioned", node "node-1"
I1119 15:56:42.180740  127596 scheduler_binder.go:458] PVC "volume-schedulinga42c7715-ebd0-11e8-8067-000c299a5e15/pvc-i-pv-prebound" is fully bound to PV "pv-i-prebound"
I1119 15:56:42.180743  127596 scheduler_binder.go:458] PVC "volume-schedulinga42c7715-ebd0-11e8-8067-000c299a5e15/pvc-canprovision" is fully bound to PV "pvc-a693d4b0-ebd0-11e8-8067-000c299a5e15"
I1119 15:56:42.180748  127596 scheduler_binder.go:217] AssumePodVolumes for pod "volume-schedulinga42c7715-ebd0-11e8-8067-000c299a5e15/pod-i-pv-prebound-w-provisioned", node "node-1": all PVCs bound and nothing to do
E1119 15:56:42.180753  127596 scheduler.go:433] scheduler cache AssumePod failed: pod a6940066-ebd0-11e8-8067-000c299a5e15 is in the cache, so can't be assumed
E1119 15:56:42.180756  127596 factory.go:1465] Error scheduling volume-schedulinga42c7715-ebd0-11e8-8067-000c299a5e15/pod-i-pv-prebound-w-provisioned: pod a6940066-ebd0-11e8-8067-000c299a5e15 is in the cache, so can't be assumed; retrying
I1119 15:56:42.180769  127596 factory.go:1558] Updating pod condition for volume-schedulinga42c7715-ebd0-11e8-8067-000c299a5e15/pod-i-pv-prebound-w-provisioned to (PodScheduled==False)
E1119 15:56:42.180773  127596 scheduler.go:556] error assuming pod: pod a6940066-ebd0-11e8-8067-000c299a5e15 is in the cache, so can't be assumed
I1119 15:56:42.181615  127596 factory.go:1338] About to try and schedule pod volume-schedulinga42c7715-ebd0-11e8-8067-000c299a5e15/pod-i-pv-prebound-w-provisioned
I1119 15:56:42.181639  127596 scheduler.go:508] Attempting to schedule pod: volume-schedulinga42c7715-ebd0-11e8-8067-000c299a5e15/pod-i-pv-prebound-w-provisioned
I1119 15:56:42.181671  127596 scheduler_binder.go:147] FindPodVolumes for pod "volume-schedulinga42c7715-ebd0-11e8-8067-000c299a5e15/pod-i-pv-prebound-w-provisioned", node "node-1"
I1119 15:56:42.181683  127596 scheduler_binder.go:458] PVC "volume-schedulinga42c7715-ebd0-11e8-8067-000c299a5e15/pvc-i-pv-prebound" is fully bound to PV "pv-i-prebound"
I1119 15:56:42.181688  127596 scheduler_binder.go:458] PVC "volume-schedulinga42c7715-ebd0-11e8-8067-000c299a5e15/pvc-canprovision" is fully bound to PV "pvc-a693d4b0-ebd0-11e8-8067-000c299a5e15"
I1119 15:56:42.181699  127596 scheduler_binder.go:529] PersistentVolume "pv-i-prebound", Node "node-1" matches for Pod "volume-schedulinga42c7715-ebd0-11e8-8067-000c299a5e15/pod-i-pv-prebound-w-provisioned"
I1119 15:56:42.181704  127596 scheduler_binder.go:529] PersistentVolume "pvc-a693d4b0-ebd0-11e8-8067-000c299a5e15", Node "node-1" matches for Pod "volume-schedulinga42c7715-ebd0-11e8-8067-000c299a5e15/pod-i-pv-prebound-w-provisioned"
I1119 15:56:42.181708  127596 scheduler_binder.go:532] All bound volumes for Pod "volume-schedulinga42c7715-ebd0-11e8-8067-000c299a5e15/pod-i-pv-prebound-w-provisioned" match with Node "node-1"
I1119 15:56:42.181724  127596 scheduler_binder.go:207] AssumePodVolumes for pod "volume-schedulinga42c7715-ebd0-11e8-8067-000c299a5e15/pod-i-pv-prebound-w-provisioned", node "node-1"
I1119 15:56:42.181731  127596 scheduler_binder.go:458] PVC "volume-schedulinga42c7715-ebd0-11e8-8067-000c299a5e15/pvc-i-pv-prebound" is fully bound to PV "pv-i-prebound"
I1119 15:56:42.181735  127596 scheduler_binder.go:458] PVC "volume-schedulinga42c7715-ebd0-11e8-8067-000c299a5e15/pvc-canprovision" is fully bound to PV "pvc-a693d4b0-ebd0-11e8-8067-000c299a5e15"
I1119 15:56:42.181740  127596 scheduler_binder.go:217] AssumePodVolumes for pod "volume-schedulinga42c7715-ebd0-11e8-8067-000c299a5e15/pod-i-pv-prebound-w-provisioned", node "node-1": all PVCs bound and nothing to do
E1119 15:56:42.181745  127596 scheduler.go:433] scheduler cache AssumePod failed: pod a6940066-ebd0-11e8-8067-000c299a5e15 is in the cache, so can't be assumed
E1119 15:56:42.181749  127596 factory.go:1465] Error scheduling volume-schedulinga42c7715-ebd0-11e8-8067-000c299a5e15/pod-i-pv-prebound-w-provisioned: pod a6940066-ebd0-11e8-8067-000c299a5e15 is in the cache, so can't be assumed; retrying
I1119 15:56:42.181759  127596 factory.go:1558] Updating pod condition for volume-schedulinga42c7715-ebd0-11e8-8067-000c299a5e15/pod-i-pv-prebound-w-provisioned to (PodScheduled==False)
E1119 15:56:42.181764  127596 scheduler.go:556] error assuming pod: pod a6940066-ebd0-11e8-8067-000c299a5e15 is in the cache, so can't be assumed
I1119 15:56:42.182669  127596 factory.go:1338] About to try and schedule pod volume-schedulinga42c7715-ebd0-11e8-8067-000c299a5e15/pod-i-pv-prebound-w-provisioned
I1119 15:56:42.182691  127596 scheduler.go:508] Attempting to schedule pod: volume-schedulinga42c7715-ebd0-11e8-8067-000c299a5e15/pod-i-pv-prebound-w-provisioned
I1119 15:56:42.182724  127596 scheduler_binder.go:147] FindPodVolumes for pod "volume-schedulinga42c7715-ebd0-11e8-8067-000c299a5e15/pod-i-pv-prebound-w-provisioned", node "node-1"
I1119 15:56:42.182736  127596 scheduler_binder.go:458] PVC "volume-schedulinga42c7715-ebd0-11e8-8067-000c299a5e15/pvc-i-pv-prebound" is fully bound to PV "pv-i-prebound"
I1119 15:56:42.182741  127596 scheduler_binder.go:458] PVC "volume-schedulinga42c7715-ebd0-11e8-8067-000c299a5e15/pvc-canprovision" is fully bound to PV "pvc-a693d4b0-ebd0-11e8-8067-000c299a5e15"
I1119 15:56:42.182752  127596 scheduler_binder.go:529] PersistentVolume "pv-i-prebound", Node "node-1" matches for Pod "volume-schedulinga42c7715-ebd0-11e8-8067-000c299a5e15/pod-i-pv-prebound-w-provisioned"
I1119 15:56:42.182758  127596 scheduler_binder.go:529] PersistentVolume "pvc-a693d4b0-ebd0-11e8-8067-000c299a5e15", Node "node-1" matches for Pod "volume-schedulinga42c7715-ebd0-11e8-8067-000c299a5e15/pod-i-pv-prebound-w-provisioned"
I1119 15:56:42.182762  127596 scheduler_binder.go:532] All bound volumes for Pod "volume-schedulinga42c7715-ebd0-11e8-8067-000c299a5e15/pod-i-pv-prebound-w-provisioned" match with Node "node-1"
I1119 15:56:42.182776  127596 scheduler_binder.go:207] AssumePodVolumes for pod "volume-schedulinga42c7715-ebd0-11e8-8067-000c299a5e15/pod-i-pv-prebound-w-provisioned", node "node-1"
I1119 15:56:42.182796  127596 scheduler_binder.go:458] PVC "volume-schedulinga42c7715-ebd0-11e8-8067-000c299a5e15/pvc-i-pv-prebound" is fully bound to PV "pv-i-prebound"
I1119 15:56:42.182802  127596 scheduler_binder.go:458] PVC "volume-schedulinga42c7715-ebd0-11e8-8067-000c299a5e15/pvc-canprovision" is fully bound to PV "pvc-a693d4b0-ebd0-11e8-8067-000c299a5e15"
I1119 15:56:42.182809  127596 scheduler_binder.go:217] AssumePodVolumes for pod "volume-schedulinga42c7715-ebd0-11e8-8067-000c299a5e15/pod-i-pv-prebound-w-provisioned", node "node-1": all PVCs bound and nothing to do
E1119 15:56:42.182815  127596 scheduler.go:433] scheduler cache AssumePod failed: pod a6940066-ebd0-11e8-8067-000c299a5e15 is in the cache, so can't be assumed
E1119 15:56:42.182819  127596 factory.go:1465] Error scheduling volume-schedulinga42c7715-ebd0-11e8-8067-000c299a5e15/pod-i-pv-prebound-w-provisioned: pod a6940066-ebd0-11e8-8067-000c299a5e15 is in the cache, so can't be assumed; retrying
I1119 15:56:42.182830  127596 factory.go:1558] Updating pod condition for volume-schedulinga42c7715-ebd0-11e8-8067-000c299a5e15/pod-i-pv-prebound-w-provisioned to (PodScheduled==False)
E1119 15:56:42.182834  127596 scheduler.go:556] error assuming pod: pod a6940066-ebd0-11e8-8067-000c299a5e15 is in the cache, so can't be assumed
I1119 15:56:42.183679  127596 factory.go:1338] About to try and schedule pod volume-schedulinga42c7715-ebd0-11e8-8067-000c299a5e15/pod-i-pv-prebound-w-provisioned
I1119 15:56:42.183701  127596 scheduler.go:508] Attempting to schedule pod: volume-schedulinga42c7715-ebd0-11e8-8067-000c299a5e15/pod-i-pv-prebound-w-provisioned
I1119 15:56:42.183734  127596 scheduler_binder.go:147] FindPodVolumes for pod "volume-schedulinga42c7715-ebd0-11e8-8067-000c299a5e15/pod-i-pv-prebound-w-provisioned", node "node-1"
I1119 15:56:42.183746  127596 scheduler_binder.go:458] PVC "volume-schedulinga42c7715-ebd0-11e8-8067-000c299a5e15/pvc-i-pv-prebound" is fully bound to PV "pv-i-prebound"
I1119 15:56:42.183751  127596 scheduler_binder.go:458] PVC "volume-schedulinga42c7715-ebd0-11e8-8067-000c299a5e15/pvc-canprovision" is fully bound to PV "pvc-a693d4b0-ebd0-11e8-8067-000c299a5e15"
I1119 15:56:42.183762  127596 scheduler_binder.go:529] PersistentVolume "pv-i-prebound", Node "node-1" matches for Pod "volume-schedulinga42c7715-ebd0-11e8-8067-000c299a5e15/pod-i-pv-prebound-w-provisioned"
I1119 15:56:42.183767  127596 scheduler_binder.go:529] PersistentVolume "pvc-a693d4b0-ebd0-11e8-8067-000c299a5e15", Node "node-1" matches for Pod "volume-schedulinga42c7715-ebd0-11e8-8067-000c299a5e15/pod-i-pv-prebound-w-provisioned"
I1119 15:56:42.183771  127596 scheduler_binder.go:532] All bound volumes for Pod "volume-schedulinga42c7715-ebd0-11e8-8067-000c299a5e15/pod-i-pv-prebound-w-provisioned" match with Node "node-1"
I1119 15:56:42.183785  127596 scheduler_binder.go:207] AssumePodVolumes for pod "volume-schedulinga42c7715-ebd0-11e8-8067-000c299a5e15/pod-i-pv-prebound-w-provisioned", node "node-1"
I1119 15:56:42.183792  127596 scheduler_binder.go:458] PVC "volume-schedulinga42c7715-ebd0-11e8-8067-000c299a5e15/pvc-i-pv-prebound" is fully bound to PV "pv-i-prebound"
I1119 15:56:42.183796  127596 scheduler_binder.go:458] PVC "volume-schedulinga42c7715-ebd0-11e8-8067-000c299a5e15/pvc-canprovision" is fully bound to PV "pvc-a693d4b0-ebd0-11e8-8067-000c299a5e15"
I1119 15:56:42.183800  127596 scheduler_binder.go:217] AssumePodVolumes for pod "volume-schedulinga42c7715-ebd0-11e8-8067-000c299a5e15/pod-i-pv-prebound-w-provisioned", node "node-1": all PVCs bound and nothing to do
E1119 15:56:42.183805  127596 scheduler.go:433] scheduler cache AssumePod failed: pod a6940066-ebd0-11e8-8067-000c299a5e15 is in the cache, so can't be assumed
E1119 15:56:42.183809  127596 factory.go:1465] Error scheduling volume-schedulinga42c7715-ebd0-11e8-8067-000c299a5e15/pod-i-pv-prebound-w-provisioned: pod a6940066-ebd0-11e8-8067-000c299a5e15 is in the cache, so can't be assumed; retrying
I1119 15:56:42.183820  127596 factory.go:1558] Updating pod condition for volume-schedulinga42c7715-ebd0-11e8-8067-000c299a5e15/pod-i-pv-prebound-w-provisioned to (PodScheduled==False)
E1119 15:56:42.183825  127596 scheduler.go:556] error assuming pod: pod a6940066-ebd0-11e8-8067-000c299a5e15 is in the cache, so can't be assumed
I1119 15:56:42.184765  127596 factory.go:1338] About to try and schedule pod volume-schedulinga42c7715-ebd0-11e8-8067-000c299a5e15/pod-i-pv-prebound-w-provisioned
I1119 15:56:42.184787  127596 scheduler.go:508] Attempting to schedule pod: volume-schedulinga42c7715-ebd0-11e8-8067-000c299a5e15/pod-i-pv-prebound-w-provisioned
I1119 15:56:42.184820  127596 scheduler_binder.go:147] FindPodVolumes for pod "volume-schedulinga42c7715-ebd0-11e8-8067-000c299a5e15/pod-i-pv-prebound-w-provisioned", node "node-1"
I1119 15:56:42.184832  127596 scheduler_binder.go:458] PVC "volume-schedulinga42c7715-ebd0-11e8-8067-000c299a5e15/pvc-i-pv-prebound" is fully bound to PV "pv-i-prebound"
I1119 15:56:42.184837  127596 scheduler_binder.go:458] PVC "volume-schedulinga42c7715-ebd0-11e8-8067-000c299a5e15/pvc-canprovision" is fully bound to PV "pvc-a693d4b0-ebd0-11e8-8067-000c299a5e15"
I1119 15:56:42.184848  127596 scheduler_binder.go:529] PersistentVolume "pv-i-prebound", Node "node-1" matches for Pod "volume-schedulinga42c7715-ebd0-11e8-8067-000c299a5e15/pod-i-pv-prebound-w-provisioned"
I1119 15:56:42.184854  127596 scheduler_binder.go:529] PersistentVolume "pvc-a693d4b0-ebd0-11e8-8067-000c299a5e15", Node "node-1" matches for Pod "volume-schedulinga42c7715-ebd0-11e8-8067-000c299a5e15/pod-i-pv-prebound-w-provisioned"
I1119 15:56:42.184859  127596 scheduler_binder.go:532] All bound volumes for Pod "volume-schedulinga42c7715-ebd0-11e8-8067-000c299a5e15/pod-i-pv-prebound-w-provisioned" match with Node "node-1"
I1119 15:56:42.184873  127596 scheduler_binder.go:207] AssumePodVolumes for pod "volume-schedulinga42c7715-ebd0-11e8-8067-000c299a5e15/pod-i-pv-prebound-w-provisioned", node "node-1"
I1119 15:56:42.184893  127596 scheduler_binder.go:458] PVC "volume-schedulinga42c7715-ebd0-11e8-8067-000c299a5e15/pvc-i-pv-prebound" is fully bound to PV "pv-i-prebound"
I1119 15:56:42.184898  127596 scheduler_binder.go:458] PVC "volume-schedulinga42c7715-ebd0-11e8-8067-000c299a5e15/pvc-canprovision" is fully bound to PV "pvc-a693d4b0-ebd0-11e8-8067-000c299a5e15"
I1119 15:56:42.184903  127596 scheduler_binder.go:217] AssumePodVolumes for pod "volume-schedulinga42c7715-ebd0-11e8-8067-000c299a5e15/pod-i-pv-prebound-w-provisioned", node "node-1": all PVCs bound and nothing to do
E1119 15:56:42.184909  127596 scheduler.go:433] scheduler cache AssumePod failed: pod a6940066-ebd0-11e8-8067-000c299a5e15 is in the cache, so can't be assumed
E1119 15:56:42.184913  127596 factory.go:1465] Error scheduling volume-schedulinga42c7715-ebd0-11e8-8067-000c299a5e15/pod-i-pv-prebound-w-provisioned: pod a6940066-ebd0-11e8-8067-000c299a5e15 is in the cache, so can't be assumed; retrying
I1119 15:56:42.184924  127596 factory.go:1558] Updating pod condition for volume-schedulinga42c7715-ebd0-11e8-8067-000c299a5e15/pod-i-pv-prebound-w-provisioned to (PodScheduled==False)
E1119 15:56:42.184928  127596 scheduler.go:556] error assuming pod: pod a6940066-ebd0-11e8-8067-000c299a5e15 is in the cache, so can't be assumed
I1119 15:56:42.185832  127596 factory.go:1338] About to try and schedule pod volume-schedulinga42c7715-ebd0-11e8-8067-000c299a5e15/pod-i-pv-prebound-w-provisioned
I1119 15:56:42.185859  127596 scheduler.go:508] Attempting to schedule pod: volume-schedulinga42c7715-ebd0-11e8-8067-000c299a5e15/pod-i-pv-prebound-w-provisioned
I1119 15:56:42.185896  127596 scheduler_binder.go:147] FindPodVolumes for pod "volume-schedulinga42c7715-ebd0-11e8-8067-000c299a5e15/pod-i-pv-prebound-w-provisioned", node "node-1"
I1119 15:56:42.185910  127596 scheduler_binder.go:458] PVC "volume-schedulinga42c7715-ebd0-11e8-8067-000c299a5e15/pvc-i-pv-prebound" is fully bound to PV "pv-i-prebound"
I1119 15:56:42.185915  127596 scheduler_binder.go:458] PVC "volume-schedulinga42c7715-ebd0-11e8-8067-000c299a5e15/pvc-canprovision" is fully bound to PV "pvc-a693d4b0-ebd0-11e8-8067-000c299a5e15"
I1119 15:56:42.185929  127596 scheduler_binder.go:529] PersistentVolume "pv-i-prebound", Node "node-1" matches for Pod "volume-schedulinga42c7715-ebd0-11e8-8067-000c299a5e15/pod-i-pv-prebound-w-provisioned"
I1119 15:56:42.185936  127596 scheduler_binder.go:529] PersistentVolume "pvc-a693d4b0-ebd0-11e8-8067-000c299a5e15", Node "node-1" matches for Pod "volume-schedulinga42c7715-ebd0-11e8-8067-000c299a5e15/pod-i-pv-prebound-w-provisioned"
I1119 15:56:42.185940  127596 scheduler_binder.go:532] All bound volumes for Pod "volume-schedulinga42c7715-ebd0-11e8-8067-000c299a5e15/pod-i-pv-prebound-w-provisioned" match with Node "node-1"
I1119 15:56:42.185964  127596 scheduler_binder.go:207] AssumePodVolumes for pod "volume-schedulinga42c7715-ebd0-11e8-8067-000c299a5e15/pod-i-pv-prebound-w-provisioned", node "node-1"
I1119 15:56:42.185969  127596 scheduler_binder.go:458] PVC "volume-schedulinga42c7715-ebd0-11e8-8067-000c299a5e15/pvc-i-pv-prebound" is fully bound to PV "pv-i-prebound"
I1119 15:56:42.185973  127596 scheduler_binder.go:458] PVC "volume-schedulinga42c7715-ebd0-11e8-8067-000c299a5e15/pvc-canprovision" is fully bound to PV "pvc-a693d4b0-ebd0-11e8-8067-000c299a5e15"
I1119 15:56:42.185978  127596 scheduler_binder.go:217] AssumePodVolumes for pod "volume-schedulinga42c7715-ebd0-11e8-8067-000c299a5e15/pod-i-pv-prebound-w-provisioned", node "node-1": all PVCs bound and nothing to do
E1119 15:56:42.185983  127596 scheduler.go:433] scheduler cache AssumePod failed: pod a6940066-ebd0-11e8-8067-000c299a5e15 is in the cache, so can't be assumed
E1119 15:56:42.185987  127596 factory.go:1465] Error scheduling volume-schedulinga42c7715-ebd0-11e8-8067-000c299a5e15/pod-i-pv-prebound-w-provisioned: pod a6940066-ebd0-11e8-8067-000c299a5e15 is in the cache, so can't be assumed; retrying
I1119 15:56:42.186002  127596 factory.go:1558] Updating pod condition for volume-schedulinga42c7715-ebd0-11e8-8067-000c299a5e15/pod-i-pv-prebound-w-provisioned to (PodScheduled==False)
E1119 15:56:42.186009  127596 scheduler.go:556] error assuming pod: pod a6940066-ebd0-11e8-8067-000c299a5e15 is in the cache, so can't be assumed
I1119 15:56:42.187293  127596 factory.go:1338] About to try and schedule pod volume-schedulinga42c7715-ebd0-11e8-8067-000c299a5e15/pod-i-pv-prebound-w-provisioned
I1119 15:56:42.187319  127596 scheduler.go:508] Attempting to schedule pod: volume-schedulinga42c7715-ebd0-11e8-8067-000c299a5e15/pod-i-pv-prebound-w-provisioned
I1119 15:56:42.187418  127596 scheduler_binder.go:147] FindPodVolumes for pod "volume-schedulinga42c7715-ebd0-11e8-8067-000c299a5e15/pod-i-pv-prebound-w-provisioned", node "node-1"
I1119 15:56:42.187451  127596 scheduler_binder.go:458] PVC "volume-schedulinga42c7715-ebd0-11e8-8067-000c299a5e15/pvc-i-pv-prebound" is fully bound to PV "pv-i-prebound"
I1119 15:56:42.187458  127596 scheduler_binder.go:458] PVC "volume-schedulinga42c7715-ebd0-11e8-8067-000c299a5e15/pvc-canprovision" is fully bound to PV "pvc-a693d4b0-ebd0-11e8-8067-000c299a5e15"
I1119 15:56:42.187475  127596 scheduler_binder.go:529] PersistentVolume "pv-i-prebound", Node "node-1" matches for Pod "volume-schedulinga42c7715-ebd0-11e8-8067-000c299a5e15/pod-i-pv-prebound-w-provisioned"
I1119 15:56:42.187499  127596 scheduler_binder.go:529] PersistentVolume "pvc-a693d4b0-ebd0-11e8-8067-000c299a5e15", Node "node-1" matches for Pod "volume-schedulinga42c7715-ebd0-11e8-8067-000c299a5e15/pod-i-pv-prebound-w-provisioned"
I1119 15:56:42.187524  127596 scheduler_binder.go:532] All bound volumes for Pod "volume-schedulinga42c7715-ebd0-11e8-8067-000c299a5e15/pod-i-pv-prebound-w-provisioned" match with Node "node-1"
I1119 15:56:42.187572  127596 scheduler_binder.go:207] AssumePodVolumes for pod "volume-schedulinga42c7715-ebd0-11e8-8067-000c299a5e15/pod-i-pv-prebound-w-provisioned", node "node-1"
I1119 15:56:42.187584  127596 scheduler_binder.go:458] PVC "volume-schedulinga42c7715-ebd0-11e8-8067-000c299a5e15/pvc-i-pv-prebound" is fully bound to PV "pv-i-prebound"
I1119 15:56:42.187591  127596 scheduler_binder.go:458] PVC "volume-schedulinga42c7715-ebd0-11e8-8067-000c299a5e15/pvc-canprovision" is fully bound to PV "pvc-a693d4b0-ebd0-11e8-8067-000c299a5e15"
I1119 15:56:42.187598  127596 scheduler_binder.go:217] AssumePodVolumes for pod "volume-schedulinga42c7715-ebd0-11e8-8067-000c299a5e15/pod-i-pv-prebound-w-provisioned", node "node-1": all PVCs bound and nothing to do
E1119 15:56:42.187606  127596 scheduler.go:433] scheduler cache AssumePod failed: pod a6940066-ebd0-11e8-8067-000c299a5e15 is in the cache, so can't be assumed
E1119 15:56:42.187610  127596 factory.go:1465] Error scheduling volume-schedulinga42c7715-ebd0-11e8-8067-000c299a5e15/pod-i-pv-prebound-w-provisioned: pod a6940066-ebd0-11e8-8067-000c299a5e15 is in the cache, so can't be assumed; retrying
I1119 15:56:42.187644  127596 factory.go:1558] Updating pod condition for volume-schedulinga42c7715-ebd0-11e8-8067-000c299a5e15/pod-i-pv-prebound-w-provisioned to (PodScheduled==False)
E1119 15:56:42.187652  127596 scheduler.go:556] error assuming pod: pod a6940066-ebd0-11e8-8067-000c299a5e15 is in the cache, so can't be assumed
I1119 15:56:42.188645  127596 factory.go:1338] About to try and schedule pod volume-schedulinga42c7715-ebd0-11e8-8067-000c299a5e15/pod-i-pv-prebound-w-provisioned
I1119 15:56:42.188667  127596 scheduler.go:508] Attempting to schedule pod: volume-schedulinga42c7715-ebd0-11e8-8067-000c299a5e15/pod-i-pv-prebound-w-provisioned
I1119 15:56:42.188752  127596 scheduler_binder.go:147] FindPodVolumes for pod "volume-schedulinga42c7715-ebd0-11e8-8067-000c299a5e15/pod-i-pv-prebound-w-provisioned", node "node-1"
I1119 15:56:42.188781  127596 scheduler_binder.go:458] PVC "volume-schedulinga42c7715-ebd0-11e8-8067-000c299a5e15/pvc-i-pv-prebound" is fully bound to PV "pv-i-prebound"
I1119 15:56:42.188788  127596 scheduler_binder.go:458] PVC "volume-schedulinga42c7715-ebd0-11e8-8067-000c299a5e15/pvc-canprovision" is fully bound to PV "pvc-a693d4b0-ebd0-11e8-8067-000c299a5e15"
I1119 15:56:42.188801  127596 scheduler_binder.go:529] PersistentVolume "pv-i-prebound", Node "node-1" matches for Pod "volume-schedulinga42c7715-ebd0-11e8-8067-000c299a5e15/pod-i-pv-prebound-w-provisioned"
I1119 15:56:42.188806  127596 scheduler_binder.go:529] PersistentVolume "pvc-a693d4b0-ebd0-11e8-8067-000c299a5e15", Node "node-1" matches for Pod "volume-schedulinga42c7715-ebd0-11e8-8067-000c299a5e15/pod-i-pv-prebound-w-provisioned"
I1119 15:56:42.188831  127596 scheduler_binder.go:532] All bound volumes for Pod "volume-schedulinga42c7715-ebd0-11e8-8067-000c299a5e15/pod-i-pv-prebound-w-provisioned" match with Node "node-1"
I1119 15:56:42.188909  127596 scheduler_binder.go:207] AssumePodVolumes for pod "volume-schedulinga42c7715-ebd0-11e8-8067-000c299a5e15/pod-i-pv-prebound-w-provisioned", node "node-1"
I1119 15:56:42.188924  127596 scheduler_binder.go:458] PVC "volume-schedulinga42c7715-ebd0-11e8-8067-000c299a5e15/pvc-i-pv-prebound" is fully bound to PV "pv-i-prebound"
I1119 15:56:42.188930  127596 scheduler_binder.go:458] PVC "volume-schedulinga42c7715-ebd0-11e8-8067-000c299a5e15/pvc-canprovision" is fully bound to PV "pvc-a693d4b0-ebd0-11e8-8067-000c299a5e15"
I1119 15:56:42.188936  127596 scheduler_binder.go:217] AssumePodVolumes for pod "volume-schedulinga42c7715-ebd0-11e8-8067-000c299a5e15/pod-i-pv-prebound-w-provisioned", node "node-1": all PVCs bound and nothing to do
E1119 15:56:42.188945  127596 scheduler.go:433] scheduler cache AssumePod failed: pod a6940066-ebd0-11e8-8067-000c299a5e15 is in the cache, so can't be assumed
E1119 15:56:42.188950  127596 factory.go:1465] Error scheduling volume-schedulinga42c7715-ebd0-11e8-8067-000c299a5e15/pod-i-pv-prebound-w-provisioned: pod a6940066-ebd0-11e8-8067-000c299a5e15 is in the cache, so can't be assumed; retrying
I1119 15:56:42.188967  127596 factory.go:1558] Updating pod condition for volume-schedulinga42c7715-ebd0-11e8-8067-000c299a5e15/pod-i-pv-prebound-w-provisioned to (PodScheduled==False)
E1119 15:56:42.188974  127596 scheduler.go:556] error assuming pod: pod a6940066-ebd0-11e8-8067-000c299a5e15 is in the cache, so can't be assumed
I1119 15:56:42.189980  127596 factory.go:1338] About to try and schedule pod volume-schedulinga42c7715-ebd0-11e8-8067-000c299a5e15/pod-i-pv-prebound-w-provisioned
I1119 15:56:42.190005  127596 scheduler.go:508] Attempting to schedule pod: volume-schedulinga42c7715-ebd0-11e8-8067-000c299a5e15/pod-i-pv-prebound-w-provisioned
I1119 15:56:42.190056  127596 scheduler_binder.go:147] FindPodVolumes for pod "volume-schedulinga42c7715-ebd0-11e8-8067-000c299a5e15/pod-i-pv-prebound-w-provisioned", node "node-1"
I1119 15:56:42.190072  127596 scheduler_binder.go:458] PVC "volume-schedulinga42c7715-ebd0-11e8-8067-000c299a5e15/pvc-i-pv-prebound" is fully bound to PV "pv-i-prebound"
I1119 15:56:42.190078  127596 scheduler_binder.go:458] PVC "volume-schedulinga42c7715-ebd0-11e8-8067-000c299a5e15/pvc-canprovision" is fully bound to PV "pvc-a693d4b0-ebd0-11e8-8067-000c299a5e15"
I1119 15:56:42.190091  127596 scheduler_binder.go:529] PersistentVolume "pv-i-prebound", Node "node-1" matches for Pod "volume-schedulinga42c7715-ebd0-11e8-8067-000c299a5e15/pod-i-pv-prebound-w-provisioned"
I1119 15:56:42.190096  127596 scheduler_binder.go:529] PersistentVolume "pvc-a693d4b0-ebd0-11e8-8067-000c299a5e15", Node "node-1" matches for Pod "volume-schedulinga42c7715-ebd0-11e8-8067-000c299a5e15/pod-i-pv-prebound-w-provisioned"
I1119 15:56:42.190100  127596 scheduler_binder.go:532] All bound volumes for Pod "volume-schedulinga42c7715-ebd0-11e8-8067-000c299a5e15/pod-i-pv-prebound-w-provisioned" match with Node "node-1"
I1119 15:56:42.190134  127596 scheduler_binder.go:207] AssumePodVolumes for pod "volume-schedulinga42c7715-ebd0-11e8-8067-000c299a5e15/pod-i-pv-prebound-w-provisioned", node "node-1"
I1119 15:56:42.190162  127596 scheduler_binder.go:458] PVC "volume-schedulinga42c7715-ebd0-11e8-8067-000c299a5e15/pvc-i-pv-prebound" is fully bound to PV "pv-i-prebound"
I1119 15:56:42.190170  127596 scheduler_binder.go:458] PVC "volume-schedulinga42c7715-ebd0-11e8-8067-000c299a5e15/pvc-canprovision" is fully bound to PV "pvc-a693d4b0-ebd0-11e8-8067-000c299a5e15"
I1119 15:56:42.190178  127596 scheduler_binder.go:217] AssumePodVolumes for pod "volume-schedulinga42c7715-ebd0-11e8-8067-000c299a5e15/pod-i-pv-prebound-w-provisioned", node "node-1": all PVCs bound and nothing to do
E1119 15:56:42.190187  127596 scheduler.go:433] scheduler cache AssumePod failed: pod a6940066-ebd0-11e8-8067-000c299a5e15 is in the cache, so can't be assumed
E1119 15:56:42.190192  127596 factory.go:1465] Error scheduling volume-schedulinga42c7715-ebd0-11e8-8067-000c299a5e15/pod-i-pv-prebound-w-provisioned: pod a6940066-ebd0-11e8-8067-000c299a5e15 is in the cache, so can't be assumed; retrying
I1119 15:56:42.190213  127596 factory.go:1558] Updating pod condition for volume-schedulinga42c7715-ebd0-11e8-8067-000c299a5e15/pod-i-pv-prebound-w-provisioned to (PodScheduled==False)
E1119 15:56:42.190235  127596 scheduler.go:556] error assuming pod: pod a6940066-ebd0-11e8-8067-000c299a5e15 is in the cache, so can't be assumed
I1119 15:56:42.191288  127596 factory.go:1338] About to try and schedule pod volume-schedulinga42c7715-ebd0-11e8-8067-000c299a5e15/pod-i-pv-prebound-w-provisioned
I1119 15:56:42.191310  127596 scheduler.go:508] Attempting to schedule pod: volume-schedulinga42c7715-ebd0-11e8-8067-000c299a5e15/pod-i-pv-prebound-w-provisioned
I1119 15:56:42.191360  127596 scheduler_binder.go:147] FindPodVolumes for pod "volume-schedulinga42c7715-ebd0-11e8-8067-000c299a5e15/pod-i-pv-prebound-w-provisioned", node "node-1"
I1119 15:56:42.191390  127596 scheduler_binder.go:458] PVC "volume-schedulinga42c7715-ebd0-11e8-8067-000c299a5e15/pvc-i-pv-prebound" is fully bound to PV "pv-i-prebound"
I1119 15:56:42.191396  127596 scheduler_binder.go:458] PVC "volume-schedulinga42c7715-ebd0-11e8-8067-000c299a5e15/pvc-canprovision" is fully bound to PV "pvc-a693d4b0-ebd0-11e8-8067-000c299a5e15"
I1119 15:56:42.191409  127596 scheduler_binder.go:529] PersistentVolume "pv-i-prebound", Node "node-1" matches for Pod "volume-schedulinga42c7715-ebd0-11e8-8067-000c299a5e15/pod-i-pv-prebound-w-provisioned"
I1119 15:56:42.191414  127596 scheduler_binder.go:529] PersistentVolume "pvc-a693d4b0-ebd0-11e8-8067-000c299a5e15", Node "node-1" matches for Pod "volume-schedulinga42c7715-ebd0-11e8-8067-000c299a5e15/pod-i-pv-prebound-w-provisioned"
I1119 15:56:42.191418  127596 scheduler_binder.go:532] All bound volumes for Pod "volume-schedulinga42c7715-ebd0-11e8-8067-000c299a5e15/pod-i-pv-prebound-w-provisioned" match with Node "node-1"
I1119 15:56:42.191450  127596 scheduler_binder.go:207] AssumePodVolumes for pod "volume-schedulinga42c7715-ebd0-11e8-8067-000c299a5e15/pod-i-pv-prebound-w-provisioned", node "node-1"
I1119 15:56:42.191480  127596 scheduler_binder.go:458] PVC "volume-schedulinga42c7715-ebd0-11e8-8067-000c299a5e15/pvc-i-pv-prebound" is fully bound to PV "pv-i-prebound"
I1119 15:56:42.191491  127596 scheduler_binder.go:458] PVC "volume-schedulinga42c7715-ebd0-11e8-8067-000c299a5e15/pvc-canprovision" is fully bound to PV "pvc-a693d4b0-ebd0-11e8-8067-000c299a5e15"
I1119 15:56:42.191500  127596 scheduler_binder.go:217] AssumePodVolumes for pod "volume-schedulinga42c7715-ebd0-11e8-8067-000c299a5e15/pod-i-pv-prebound-w-provisioned", node "node-1": all PVCs bound and nothing to do
E1119 15:56:42.191509  127596 scheduler.go:433] scheduler cache AssumePod failed: pod a6940066-ebd0-11e8-8067-000c299a5e15 is in the cache, so can't be assumed
E1119 15:56:42.191514  127596 factory.go:1465] Error scheduling volume-schedulinga42c7715-ebd0-11e8-8067-000c299a5e15/pod-i-pv-prebound-w-provisioned: pod a6940066-ebd0-11e8-8067-000c299a5e15 is in the cache, so can't be assumed; retrying
I1119 15:56:42.191546  127596 factory.go:1558] Updating pod condition for volume-schedulinga42c7715-ebd0-11e8-8067-000c299a5e15/pod-i-pv-prebound-w-provisioned to (PodScheduled==False)
E1119 15:56:42.191554  127596 scheduler.go:556] error assuming pod: pod a6940066-ebd0-11e8-8067-000c299a5e15 is in the cache, so can't be assumed
I1119 15:56:42.192474  127596 factory.go:1338] About to try and schedule pod volume-schedulinga42c7715-ebd0-11e8-8067-000c299a5e15/pod-i-pv-prebound-w-provisioned
I1119 15:56:42.192497  127596 scheduler.go:508] Attempting to schedule pod: volume-schedulinga42c7715-ebd0-11e8-8067-000c299a5e15/pod-i-pv-prebound-w-provisioned
I1119 15:56:42.192531  127596 scheduler_binder.go:147] FindPodVolumes for pod "volume-schedulinga42c7715-ebd0-11e8-8067-000c299a5e15/pod-i-pv-prebound-w-provisioned", node "node-1"
I1119 15:56:42.192543  127596 scheduler_binder.go:458] PVC "volume-schedulinga42c7715-ebd0-11e8-8067-000c299a5e15/pvc-i-pv-prebound" is fully bound to PV "pv-i-prebound"
I1119 15:56:42.192548  127596 scheduler_binder.go:458] PVC "volume-schedulinga42c7715-ebd0-11e8-8067-000c299a5e15/pvc-canprovision" is fully bound to PV "pvc-a693d4b0-ebd0-11e8-8067-000c299a5e15"
I1119 15:56:42.192560  127596 scheduler_binder.go:529] PersistentVolume "pv-i-prebound", Node "node-1" matches for Pod "volume-schedulinga42c7715-ebd0-11e8-8067-000c299a5e15/pod-i-pv-prebound-w-provisioned"
I1119 15:56:42.192564  127596 scheduler_binder.go:529] PersistentVolume "pvc-a693d4b0-ebd0-11e8-8067-000c299a5e15", Node "node-1" matches for Pod "volume-schedulinga42c7715-ebd0-11e8-8067-000c299a5e15/pod-i-pv-prebound-w-provisioned"
I1119 15:56:42.192569  127596 scheduler_binder.go:532] All bound volumes for Pod "volume-schedulinga42c7715-ebd0-11e8-8067-000c299a5e15/pod-i-pv-prebound-w-provisioned" match with Node "node-1"
I1119 15:56:42.192603  127596 scheduler_binder.go:207] AssumePodVolumes for pod "volume-schedulinga42c7715-ebd0-11e8-8067-000c299a5e15/pod-i-pv-prebound-w-provisioned", node "node-1"
I1119 15:56:42.192612  127596 scheduler_binder.go:458] PVC "volume-schedulinga42c7715-ebd0-11e8-8067-000c299a5e15/pvc-i-pv-prebound" is fully bound to PV "pv-i-prebound"
I1119 15:56:42.192617  127596 scheduler_binder.go:458] PVC "volume-schedulinga42c7715-ebd0-11e8-8067-000c299a5e15/pvc-canprovision" is fully bound to PV "pvc-a693d4b0-ebd0-11e8-8067-000c299a5e15"
I1119 15:56:42.192621  127596 scheduler_binder.go:217] AssumePodVolumes for pod "volume-schedulinga42c7715-ebd0-11e8-8067-000c299a5e15/pod-i-pv-prebound-w-provisioned", node "node-1": all PVCs bound and nothing to do
E1119 15:56:42.192627  127596 scheduler.go:433] scheduler cache AssumePod failed: pod a6940066-ebd0-11e8-8067-000c299a5e15 is in the cache, so can't be assumed
E1119 15:56:42.192631  127596 factory.go:1465] Error scheduling volume-schedulinga42c7715-ebd0-11e8-8067-000c299a5e15/pod-i-pv-prebound-w-provisioned: pod a6940066-ebd0-11e8-8067-000c299a5e15 is in the cache, so can't be assumed; retrying
I1119 15:56:42.192643  127596 factory.go:1558] Updating pod condition for volume-schedulinga42c7715-ebd0-11e8-8067-000c299a5e15/pod-i-pv-prebound-w-provisioned to (PodScheduled==False)
E1119 15:56:42.192648  127596 scheduler.go:556] error assuming pod: pod a6940066-ebd0-11e8-8067-000c299a5e15 is in the cache, so can't be assumed
I1119 15:56:42.193504  127596 factory.go:1338] About to try and schedule pod volume-schedulinga42c7715-ebd0-11e8-8067-000c299a5e15/pod-i-pv-prebound-w-provisioned
I1119 15:56:42.193541  127596 scheduler.go:508] Attempting to schedule pod: volume-schedulinga42c7715-ebd0-11e8-8067-000c299a5e15/pod-i-pv-prebound-w-provisioned
I1119 15:56:42.193592  127596 scheduler_binder.go:147] FindPodVolumes for pod "volume-schedulinga42c7715-ebd0-11e8-8067-000c299a5e15/pod-i-pv-prebound-w-provisioned", node "node-1"
I1119 15:56:42.193621  127596 scheduler_binder.go:458] PVC "volume-schedulinga42c7715-ebd0-11e8-8067-000c299a5e15/pvc-i-pv-prebound" is fully bound to PV "pv-i-prebound"
I1119 15:56:42.193628  127596 scheduler_binder.go:458] PVC "volume-schedulinga42c7715-ebd0-11e8-8067-000c299a5e15/pvc-canprovision" is fully bound to PV "pvc-a693d4b0-ebd0-11e8-8067-000c299a5e15"
I1119 15:56:42.193640  127596 scheduler_binder.go:529] PersistentVolume "pv-i-prebound", Node "node-1" matches for Pod "volume-schedulinga42c7715-ebd0-11e8-8067-000c299a5e15/pod-i-pv-prebound-w-provisioned"
I1119 15:56:42.193644  127596 scheduler_binder.go:529] PersistentVolume "pvc-a693d4b0-ebd0-11e8-8067-000c299a5e15", Node "node-1" matches for Pod "volume-schedulinga42c7715-ebd0-11e8-8067-000c299a5e15/pod-i-pv-prebound-w-provisioned"
I1119 15:56:42.193649  127596 scheduler_binder.go:532] All bound volumes for Pod "volume-schedulinga42c7715-ebd0-11e8-8067-000c299a5e15/pod-i-pv-prebound-w-provisioned" match with Node "node-1"
I1119 15:56:42.193679  127596 scheduler_binder.go:207] AssumePodVolumes for pod "volume-schedulinga42c7715-ebd0-11e8-8067-000c299a5e15/pod-i-pv-prebound-w-provisioned", node "node-1"
I1119 15:56:42.193699  127596 scheduler_binder.go:458] PVC "volume-schedulinga42c7715-ebd0-11e8-8067-000c299a5e15/pvc-i-pv-prebound" is fully bound to PV "pv-i-prebound"
I1119 15:56:42.193705  127596 scheduler_binder.go:458] PVC "volume-schedulinga42c7715-ebd0-11e8-8067-000c299a5e15/pvc-canprovision" is fully bound to PV "pvc-a693d4b0-ebd0-11e8-8067-000c299a5e15"
I1119 15:56:42.193710  127596 scheduler_binder.go:217] AssumePodVolumes for pod "volume-schedulinga42c7715-ebd0-11e8-8067-000c299a5e15/pod-i-pv-prebound-w-provisioned", node "node-1": all PVCs bound and nothing to do
E1119 15:56:42.193716  127596 scheduler.go:433] scheduler cache AssumePod failed: pod a6940066-ebd0-11e8-8067-000c299a5e15 is in the cache, so can't be assumed
E1119 15:56:42.193719  127596 factory.go:1465] Error scheduling volume-schedulinga42c7715-ebd0-11e8-8067-000c299a5e15/pod-i-pv-prebound-w-provisioned: pod a6940066-ebd0-11e8-8067-000c299a5e15 is in the cache, so can't be assumed; retrying
I1119 15:56:42.193829  127596 factory.go:1558] Updating pod condition for volume-schedulinga42c7715-ebd0-11e8-8067-000c299a5e15/pod-i-pv-prebound-w-provisioned to (PodScheduled==False)
E1119 15:56:42.193839  127596 scheduler.go:556] error assuming pod: pod a6940066-ebd0-11e8-8067-000c299a5e15 is in the cache, so can't be assumed
I1119 15:56:42.194885  127596 factory.go:1338] About to try and schedule pod volume-schedulinga42c7715-ebd0-11e8-8067-000c299a5e15/pod-i-pv-prebound-w-provisioned
I1119 15:56:42.194906  127596 scheduler.go:508] Attempting to schedule pod: volume-schedulinga42c7715-ebd0-11e8-8067-000c299a5e15/pod-i-pv-prebound-w-provisioned
I1119 15:56:42.195015  127596 scheduler_binder.go:147] FindPodVolumes for pod "volume-schedulinga42c7715-ebd0-11e8-8067-000c299a5e15/pod-i-pv-prebound-w-provisioned", node "node-1"
I1119 15:56:42.195032  127596 scheduler_binder.go:458] PVC "volume-schedulinga42c7715-ebd0-11e8-8067-000c299a5e15/pvc-i-pv-prebound" is fully bound to PV "pv-i-prebound"
I1119 15:56:42.195037  127596 scheduler_binder.go:458] PVC "volume-schedulinga42c7715-ebd0-11e8-8067-000c299a5e15/pvc-canprovision" is fully bound to PV "pvc-a693d4b0-ebd0-11e8-8067-000c299a5e15"
I1119 15:56:42.195050  127596 scheduler_binder.go:529] PersistentVolume "pv-i-prebound", Node "node-1" matches for Pod "volume-schedulinga42c7715-ebd0-11e8-8067-000c299a5e15/pod-i-pv-prebound-w-provisioned"
I1119 15:56:42.195054  127596 scheduler_binder.go:529] PersistentVolume "pvc-a693d4b0-ebd0-11e8-8067-000c299a5e15", Node "node-1" matches for Pod "volume-schedulinga42c7715-ebd0-11e8-8067-000c299a5e15/pod-i-pv-prebound-w-provisioned"
I1119 15:56:42.195059  127596 scheduler_binder.go:532] All bound volumes for Pod "volume-schedulinga42c7715-ebd0-11e8-8067-000c299a5e15/pod-i-pv-prebound-w-provisioned" match with Node "node-1"
I1119 15:56:42.195120  127596 scheduler_binder.go:207] AssumePodVolumes for pod "volume-schedulinga42c7715-ebd0-11e8-8067-000c299a5e15/pod-i-pv-prebound-w-provisioned", node "node-1"
I1119 15:56:42.195133  127596 scheduler_binder.go:458] PVC "volume-schedulinga42c7715-ebd0-11e8-8067-000c299a5e15/pvc-i-pv-prebound" is fully bound to PV "pv-i-prebound"
I1119 15:56:42.195138  127596 scheduler_binder.go:458] PVC "volume-schedulinga42c7715-ebd0-11e8-8067-000c299a5e15/pvc-canprovision" is fully bound to PV "pvc-a693d4b0-ebd0-11e8-8067-000c299a5e15"
I1119 15:56:42.195142  127596 scheduler_binder.go:217] AssumePodVolumes for pod "volume-schedulinga42c7715-ebd0-11e8-8067-000c299a5e15/pod-i-pv-prebound-w-provisioned", node "node-1": all PVCs bound and nothing to do
E1119 15:56:42.195148  127596 scheduler.go:433] scheduler cache AssumePod failed: pod a6940066-ebd0-11e8-8067-000c299a5e15 is in the cache, so can't be assumed
E1119 15:56:42.195152  127596 factory.go:1465] Error scheduling volume-schedulinga42c7715-ebd0-11e8-8067-000c299a5e15/pod-i-pv-prebound-w-provisioned: pod a6940066-ebd0-11e8-8067-000c299a5e15 is in the cache, so can't be assumed; retrying
I1119 15:56:42.195213  127596 factory.go:1558] Updating pod condition for volume-schedulinga42c7715-ebd0-11e8-8067-000c299a5e15/pod-i-pv-prebound-w-provisioned to (PodScheduled==False)
E1119 15:56:42.195224  127596 scheduler.go:556] error assuming pod: pod a6940066-ebd0-11e8-8067-000c299a5e15 is in the cache, so can't be assumed
I1119 15:56:42.196267  127596 factory.go:1338] About to try and schedule pod volume-schedulinga42c7715-ebd0-11e8-8067-000c299a5e15/pod-i-pv-prebound-w-provisioned
I1119 15:56:42.196288  127596 scheduler.go:508] Attempting to schedule pod: volume-schedulinga42c7715-ebd0-11e8-8067-000c299a5e15/pod-i-pv-prebound-w-provisioned
I1119 15:56:42.196337  127596 scheduler_binder.go:147] FindPodVolumes for pod "volume-schedulinga42c7715-ebd0-11e8-8067-000c299a5e15/pod-i-pv-prebound-w-provisioned", node "node-1"
I1119 15:56:42.196353  127596 scheduler_binder.go:458] PVC "volume-schedulinga42c7715-ebd0-11e8-8067-000c299a5e15/pvc-i-pv-prebound" is fully bound to PV "pv-i-prebound"
I1119 15:56:42.196358  127596 scheduler_binder.go:458] PVC "volume-schedulinga42c7715-ebd0-11e8-8067-000c299a5e15/pvc-canprovision" is fully bound to PV "pvc-a693d4b0-ebd0-11e8-8067-000c299a5e15"
I1119 15:56:42.196370  127596 scheduler_binder.go:529] PersistentVolume "pv-i-prebound", Node "node-1" matches for Pod "volume-schedulinga42c7715-ebd0-11e8-8067-000c299a5e15/pod-i-pv-prebound-w-provisioned"
I1119 15:56:42.196374  127596 scheduler_binder.go:529] PersistentVolume "pvc-a693d4b0-ebd0-11e8-8067-000c299a5e15", Node "node-1" matches for Pod "volume-schedulinga42c7715-ebd0-11e8-8067-000c299a5e15/pod-i-pv-prebound-w-provisioned"
I1119 15:56:42.196379  127596 scheduler_binder.go:532] All bound volumes for Pod "volume-schedulinga42c7715-ebd0-11e8-8067-000c299a5e15/pod-i-pv-prebound-w-provisioned" match with Node "node-1"
I1119 15:56:42.196396  127596 scheduler_binder.go:207] AssumePodVolumes for pod "volume-schedulinga42c7715-ebd0-11e8-8067-000c299a5e15/pod-i-pv-prebound-w-provisioned", node "node-1"
I1119 15:56:42.196401  127596 scheduler_binder.go:458] PVC "volume-schedulinga42c7715-ebd0-11e8-8067-000c299a5e15/pvc-i-pv-prebound" is fully bound to PV "pv-i-prebound"
I1119 15:56:42.196404  127596 scheduler_binder.go:458] PVC "volume-schedulinga42c7715-ebd0-11e8-8067-000c299a5e15/pvc-canprovision" is fully bound to PV "pvc-a693d4b0-ebd0-11e8-8067-000c299a5e15"
I1119 15:56:42.196409  127596 scheduler_binder.go:217] AssumePodVolumes for pod "volume-schedulinga42c7715-ebd0-11e8-8067-000c299a5e15/pod-i-pv-prebound-w-provisioned", node "node-1": all PVCs bound and nothing to do
E1119 15:56:42.196415  127596 scheduler.go:433] scheduler cache AssumePod failed: pod a6940066-ebd0-11e8-8067-000c299a5e15 is in the cache, so can't be assumed
E1119 15:56:42.196419  127596 factory.go:1465] Error scheduling volume-schedulinga42c7715-ebd0-11e8-8067-000c299a5e15/pod-i-pv-prebound-w-provisioned: pod a6940066-ebd0-11e8-8067-000c299a5e15 is in the cache, so can't be assumed; retrying
I1119 15:56:42.196432  127596 factory.go:1558] Updating pod condition for volume-schedulinga42c7715-ebd0-11e8-8067-000c299a5e15/pod-i-pv-prebound-w-provisioned to (PodScheduled==False)
E1119 15:56:42.196438  127596 scheduler.go:556] error assuming pod: pod a6940066-ebd0-11e8-8067-000c299a5e15 is in the cache, so can't be assumed
I1119 15:56:42.197357  127596 factory.go:1338] About to try and schedule pod volume-schedulinga42c7715-ebd0-11e8-8067-000c299a5e15/pod-i-pv-prebound-w-provisioned
I1119 15:56:42.197378  127596 scheduler.go:508] Attempting to schedule pod: volume-schedulinga42c7715-ebd0-11e8-8067-000c299a5e15/pod-i-pv-prebound-w-provisioned
I1119 15:56:42.197427  127596 scheduler_binder.go:147] FindPodVolumes for pod "volume-schedulinga42c7715-ebd0-11e8-8067-000c299a5e15/pod-i-pv-prebound-w-provisioned", node "node-1"
I1119 15:56:42.197443  127596 scheduler_binder.go:458] PVC "volume-schedulinga42c7715-ebd0-11e8-8067-000c299a5e15/pvc-i-pv-prebound" is fully bound to PV "pv-i-prebound"
I1119 15:56:42.197450  127596 scheduler_binder.go:458] PVC "volume-schedulinga42c7715-ebd0-11e8-8067-000c299a5e15/pvc-canprovision" is fully bound to PV "pvc-a693d4b0-ebd0-11e8-8067-000c299a5e15"
I1119 15:56:42.197462  127596 scheduler_binder.go:529] PersistentVolume "pv-i-prebound", Node "node-1" matches for Pod "volume-schedulinga42c7715-ebd0-11e8-8067-000c299a5e15/pod-i-pv-prebound-w-provisioned"
I1119 15:56:42.197467  127596 scheduler_binder.go:529] PersistentVolume "pvc-a693d4b0-ebd0-11e8-8067-000c299a5e15", Node "node-1" matches for Pod "volume-schedulinga42c7715-ebd0-11e8-8067-000c299a5e15/pod-i-pv-prebound-w-provisioned"
I1119 15:56:42.197472  127596 scheduler_binder.go:532] All bound volumes for Pod "volume-schedulinga42c7715-ebd0-11e8-8067-000c299a5e15/pod-i-pv-prebound-w-provisioned" match with Node "node-1"
I1119 15:56:42.197502  127596 scheduler_binder.go:207] AssumePodVolumes for pod "volume-schedulinga42c7715-ebd0-11e8-8067-000c299a5e15/pod-i-pv-prebound-w-provisioned", node "node-1"
I1119 15:56:42.197536  127596 scheduler_binder.go:458] PVC "volume-schedulinga42c7715-ebd0-11e8-8067-000c299a5e15/pvc-i-pv-prebound" is fully bound to PV "pv-i-prebound"
I1119 15:56:42.197542  127596 scheduler_binder.go:458] PVC "volume-schedulinga42c7715-ebd0-11e8-8067-000c299a5e15/pvc-canprovision" is fully bound to PV "pvc-a693d4b0-ebd0-11e8-8067-000c299a5e15"
I1119 15:56:42.197547  127596 scheduler_binder.go:217] AssumePodVolumes for pod "volume-schedulinga42c7715-ebd0-11e8-8067-000c299a5e15/pod-i-pv-prebound-w-provisioned", node "node-1": all PVCs bound and nothing to do
E1119 15:56:42.197553  127596 scheduler.go:433] scheduler cache AssumePod failed: pod a6940066-ebd0-11e8-8067-000c299a5e15 is in the cache, so can't be assumed
E1119 15:56:42.197557  127596 factory.go:1465] Error scheduling volume-schedulinga42c7715-ebd0-11e8-8067-000c299a5e15/pod-i-pv-prebound-w-provisioned: pod a6940066-ebd0-11e8-8067-000c299a5e15 is in the cache, so can't be assumed; retrying
I1119 15:56:42.197584  127596 factory.go:1558] Updating pod condition for volume-schedulinga42c7715-ebd0-11e8-8067-000c299a5e15/pod-i-pv-prebound-w-provisioned to (PodScheduled==False)
E1119 15:56:42.197592  127596 scheduler.go:556] error assuming pod: pod a6940066-ebd0-11e8-8067-000c299a5e15 is in the cache, so can't be assumed
I1119 15:56:42.198545  127596 factory.go:1338] About to try and schedule pod volume-schedulinga42c7715-ebd0-11e8-8067-000c299a5e15/pod-i-pv-prebound-w-provisioned
I1119 15:56:42.198568  127596 scheduler.go:508] Attempting to schedule pod: volume-schedulinga42c7715-ebd0-11e8-8067-000c299a5e15/pod-i-pv-prebound-w-provisioned
I1119 15:56:42.198614  127596 scheduler_binder.go:147] FindPodVolumes for pod "volume-schedulinga42c7715-ebd0-11e8-8067-000c299a5e15/pod-i-pv-prebound-w-provisioned", node "node-1"
I1119 15:56:42.198629  127596 scheduler_binder.go:458] PVC "volume-schedulinga42c7715-ebd0-11e8-8067-000c299a5e15/pvc-i-pv-prebound" is fully bound to PV "pv-i-prebound"
I1119 15:56:42.198633  127596 scheduler_binder.go:458] PVC "volume-schedulinga42c7715-ebd0-11e8-8067-000c299a5e15/pvc-canprovision" is fully bound to PV "pvc-a693d4b0-ebd0-11e8-8067-000c299a5e15"
I1119 15:56:42.198646  127596 scheduler_binder.go:529] PersistentVolume "pv-i-prebound", Node "node-1" matches for Pod "volume-schedulinga42c7715-ebd0-11e8-8067-000c299a5e15/pod-i-pv-prebound-w-provisioned"
I1119 15:56:42.198650  127596 scheduler_binder.go:529] PersistentVolume "pvc-a693d4b0-ebd0-11e8-8067-000c299a5e15", Node "node-1" matches for Pod "volume-schedulinga42c7715-ebd0-11e8-8067-000c299a5e15/pod-i-pv-prebound-w-provisioned"
I1119 15:56:42.198654  127596 scheduler_binder.go:532] All bound volumes for Pod "volume-schedulinga42c7715-ebd0-11e8-8067-000c299a5e15/pod-i-pv-prebound-w-provisioned" match with Node "node-1"
I1119 15:56:42.198693  127596 scheduler_binder.go:207] AssumePodVolumes for pod "volume-schedulinga42c7715-ebd0-11e8-8067-000c299a5e15/pod-i-pv-prebound-w-provisioned", node "node-1"
I1119 15:56:42.198721  127596 scheduler_binder.go:458] PVC "volume-schedulinga42c7715-ebd0-11e8-8067-000c299a5e15/pvc-i-pv-prebound" is fully bound to PV "pv-i-prebound"
I1119 15:56:42.198729  127596 scheduler_binder.go:458] PVC "volume-schedulinga42c7715-ebd0-11e8-8067-000c299a5e15/pvc-canprovision" is fully bound to PV "pvc-a693d4b0-ebd0-11e8-8067-000c299a5e15"
I1119 15:56:42.198737  127596 scheduler_binder.go:217] AssumePodVolumes for pod "volume-schedulinga42c7715-ebd0-11e8-8067-000c299a5e15/pod-i-pv-prebound-w-provisioned", node "node-1": all PVCs bound and nothing to do
E1119 15:56:42.198746  127596 scheduler.go:433] scheduler cache AssumePod failed: pod a6940066-ebd0-11e8-8067-000c299a5e15 is in the cache, so can't be assumed
E1119 15:56:42.198751  127596 factory.go:1465] Error scheduling volume-schedulinga42c7715-ebd0-11e8-8067-000c299a5e15/pod-i-pv-prebound-w-provisioned: pod a6940066-ebd0-11e8-8067-000c299a5e15 is in the cache, so can't be assumed; retrying
I1119 15:56:42.198771  127596 factory.go:1558] Updating pod condition for volume-schedulinga42c7715-ebd0-11e8-8067-000c299a5e15/pod-i-pv-prebound-w-provisioned to (PodScheduled==False)
E1119 15:56:42.198778  127596 scheduler.go:556] error assuming pod: pod a6940066-ebd0-11e8-8067-000c299a5e15 is in the cache, so can't be assumed
I1119 15:56:42.199788  127596 factory.go:1338] About to try and schedule pod volume-schedulinga42c7715-ebd0-11e8-8067-000c299a5e15/pod-i-pv-prebound-w-provisioned
I1119 15:56:42.199812  127596 scheduler.go:508] Attempting to schedule pod: volume-schedulinga42c7715-ebd0-11e8-8067-000c299a5e15/pod-i-pv-prebound-w-provisioned
I1119 15:56:42.199847  127596 scheduler_binder.go:147] FindPodVolumes for pod "volume-schedulinga42c7715-ebd0-11e8-8067-000c299a5e15/pod-i-pv-prebound-w-provisioned", node "node-1"
I1119 15:56:42.199860  127596 scheduler_binder.go:458] PVC "volume-schedulinga42c7715-ebd0-11e8-8067-000c299a5e15/pvc-i-pv-prebound" is fully bound to PV "pv-i-prebound"
I1119 15:56:42.199865  127596 scheduler_binder.go:458] PVC "volume-schedulinga42c7715-ebd0-11e8-8067-000c299a5e15/pvc-canprovision" is fully bound to PV "pvc-a693d4b0-ebd0-11e8-8067-000c299a5e15"
I1119 15:56:42.199878  127596 scheduler_binder.go:529] PersistentVolume "pv-i-prebound", Node "node-1" matches for Pod "volume-schedulinga42c7715-ebd0-11e8-8067-000c299a5e15/pod-i-pv-prebound-w-provisioned"
I1119 15:56:42.199882  127596 scheduler_binder.go:529] PersistentVolume "pvc-a693d4b0-ebd0-11e8-8067-000c299a5e15", Node "node-1" matches for Pod "volume-schedulinga42c7715-ebd0-11e8-8067-000c299a5e15/pod-i-pv-prebound-w-provisioned"
I1119 15:56:42.199887  127596 scheduler_binder.go:532] All bound volumes for Pod "volume-schedulinga42c7715-ebd0-11e8-8067-000c299a5e15/pod-i-pv-prebound-w-provisioned" match with Node "node-1"
I1119 15:56:42.199905  127596 scheduler_binder.go:207] AssumePodVolumes for pod "volume-schedulinga42c7715-ebd0-11e8-8067-000c299a5e15/pod-i-pv-prebound-w-provisioned", node "node-1"
I1119 15:56:42.199929  127596 scheduler_binder.go:458] PVC "volume-schedulinga42c7715-ebd0-11e8-8067-000c299a5e15/pvc-i-pv-prebound" is fully bound to PV "pv-i-prebound"
I1119 15:56:42.199939  127596 scheduler_binder.go:458] PVC "volume-schedulinga42c7715-ebd0-11e8-8067-000c299a5e15/pvc-canprovision" is fully bound to PV "pvc-a693d4b0-ebd0-11e8-8067-000c299a5e15"
I1119 15:56:42.199946  127596 scheduler_binder.go:217] AssumePodVolumes for pod "volume-schedulinga42c7715-ebd0-11e8-8067-000c299a5e15/pod-i-pv-prebound-w-provisioned", node "node-1": all PVCs bound and nothing to do
E1119 15:56:42.199955  127596 scheduler.go:433] scheduler cache AssumePod failed: pod a6940066-ebd0-11e8-8067-000c299a5e15 is in the cache, so can't be assumed
E1119 15:56:42.199960  127596 factory.go:1465] Error scheduling volume-schedulinga42c7715-ebd0-11e8-8067-000c299a5e15/pod-i-pv-prebound-w-provisioned: pod a6940066-ebd0-11e8-8067-000c299a5e15 is in the cache, so can't be assumed; retrying
I1119 15:56:42.199997  127596 factory.go:1558] Updating pod condition for volume-schedulinga42c7715-ebd0-11e8-8067-000c299a5e15/pod-i-pv-prebound-w-provisioned to (PodScheduled==False)
E1119 15:56:42.200006  127596 scheduler.go:556] error assuming pod: pod a6940066-ebd0-11e8-8067-000c299a5e15 is in the cache, so can't be assumed
I1119 15:56:42.201343  127596 factory.go:1338] About to try and schedule pod volume-schedulinga42c7715-ebd0-11e8-8067-000c299a5e15/pod-i-pv-prebound-w-provisioned
I1119 15:56:42.201373  127596 scheduler.go:508] Attempting to schedule pod: volume-schedulinga42c7715-ebd0-11e8-8067-000c299a5e15/pod-i-pv-prebound-w-provisioned
I1119 15:56:42.201454  127596 scheduler_binder.go:147] FindPodVolumes for pod "volume-schedulinga42c7715-ebd0-11e8-8067-000c299a5e15/pod-i-pv-prebound-w-provisioned", node "node-1"
I1119 15:56:42.201473  127596 scheduler_binder.go:458] PVC "volume-schedulinga42c7715-ebd0-11e8-8067-000c299a5e15/pvc-i-pv-prebound" is fully bound to PV "pv-i-prebound"
I1119 15:56:42.201479  127596 scheduler_binder.go:458] PVC "volume-schedulinga42c7715-ebd0-11e8-8067-000c299a5e15/pvc-canprovision" is fully bound to PV "pvc-a693d4b0-ebd0-11e8-8067-000c299a5e15"
I1119 15:56:42.201498  127596 scheduler_binder.go:529] PersistentVolume "pv-i-prebound", Node "node-1" matches for Pod "volume-schedulinga42c7715-ebd0-11e8-8067-000c299a5e15/pod-i-pv-prebound-w-provisioned"
I1119 15:56:42.201503  127596 scheduler_binder.go:529] PersistentVolume "pvc-a693d4b0-ebd0-11e8-8067-000c299a5e15", Node "node-1" matches for Pod "volume-schedulinga42c7715-ebd0-11e8-8067-000c299a5e15/pod-i-pv-prebound-w-provisioned"
I1119 15:56:42.201508  127596 scheduler_binder.go:532] All bound volumes for Pod "volume-schedulinga42c7715-ebd0-11e8-8067-000c299a5e15/pod-i-pv-prebound-w-provisioned" match with Node "node-1"
I1119 15:56:42.201559  127596 scheduler_binder.go:207] AssumePodVolumes for pod "volume-schedulinga42c7715-ebd0-11e8-8067-000c299a5e15/pod-i-pv-prebound-w-provisioned", node "node-1"
I1119 15:56:42.201586  127596 scheduler_binder.go:458] PVC "volume-schedulinga42c7715-ebd0-11e8-8067-000c299a5e15/pvc-i-pv-prebound" is fully bound to PV "pv-i-prebound"
I1119 15:56:42.201593  127596 scheduler_binder.go:458] PVC "volume-schedulinga42c7715-ebd0-11e8-8067-000c299a5e15/pvc-canprovision" is fully bound to PV "pvc-a693d4b0-ebd0-11e8-8067-000c299a5e15"
I1119 15:56:42.201598  127596 scheduler_binder.go:217] AssumePodVolumes for pod "volume-schedulinga42c7715-ebd0-11e8-8067-000c299a5e15/pod-i-pv-prebound-w-provisioned", node "node-1": all PVCs bound and nothing to do
E1119 15:56:42.201607  127596 scheduler.go:433] scheduler cache AssumePod failed: pod a6940066-ebd0-11e8-8067-000c299a5e15 is in the cache, so can't be assumed
E1119 15:56:42.201614  127596 factory.go:1465] Error scheduling volume-schedulinga42c7715-ebd0-11e8-8067-000c299a5e15/pod-i-pv-prebound-w-provisioned: pod a6940066-ebd0-11e8-8067-000c299a5e15 is in the cache, so can't be assumed; retrying
I1119 15:56:42.201636  127596 factory.go:1558] Updating pod condition for volume-schedulinga42c7715-ebd0-11e8-8067-000c299a5e15/pod-i-pv-prebound-w-provisioned to (PodScheduled==False)
E1119 15:56:42.201643  127596 scheduler.go:556] error assuming pod: pod a6940066-ebd0-11e8-8067-000c299a5e15 is in the cache, so can't be assumed
I1119 15:56:42.203202  127596 factory.go:1338] About to try and schedule pod volume-schedulinga42c7715-ebd0-11e8-8067-000c299a5e15/pod-i-pv-prebound-w-provisioned
I1119 15:56:42.203228  127596 scheduler.go:508] Attempting to schedule pod: volume-schedulinga42c7715-ebd0-11e8-8067-000c299a5e15/pod-i-pv-prebound-w-provisioned
I1119 15:56:42.203293  127596 scheduler_binder.go:147] FindPodVolumes for pod "volume-schedulinga42c7715-ebd0-11e8-8067-000c299a5e15/pod-i-pv-prebound-w-provisioned", node "node-1"
I1119 15:56:42.203310  127596 scheduler_binder.go:458] PVC "volume-schedulinga42c7715-ebd0-11e8-8067-000c299a5e15/pvc-i-pv-prebound" is fully bound to PV "pv-i-prebound"
I1119 15:56:42.203315  127596 scheduler_binder.go:458] PVC "volume-schedulinga42c7715-ebd0-11e8-8067-000c299a5e15/pvc-canprovision" is fully bound to PV "pvc-a693d4b0-ebd0-11e8-8067-000c299a5e15"
I1119 15:56:42.203332  127596 scheduler_binder.go:529] PersistentVolume "pv-i-prebound", Node "node-1" matches for Pod "volume-schedulinga42c7715-ebd0-11e8-8067-000c299a5e15/pod-i-pv-prebound-w-provisioned"
I1119 15:56:42.203337  127596 scheduler_binder.go:529] PersistentVolume "pvc-a693d4b0-ebd0-11e8-8067-000c299a5e15", Node "node-1" matches for Pod "volume-schedulinga42c7715-ebd0-11e8-8067-000c299a5e15/pod-i-pv-prebound-w-provisioned"
I1119 15:56:42.203341  127596 scheduler_binder.go:532] All bound volumes for Pod "volume-schedulinga42c7715-ebd0-11e8-8067-000c299a5e15/pod-i-pv-prebound-w-provisioned" match with Node "node-1"
I1119 15:56:42.203379  127596 scheduler_binder.go:207] AssumePodVolumes for pod "volume-schedulinga42c7715-ebd0-11e8-8067-000c299a5e15/pod-i-pv-prebound-w-provisioned", node "node-1"
I1119 15:56:42.203401  127596 scheduler_binder.go:458] PVC "volume-schedulinga42c7715-ebd0-11e8-8067-000c299a5e15/pvc-i-pv-prebound" is fully bound to PV "pv-i-prebound"
I1119 15:56:42.203406  127596 scheduler_binder.go:458] PVC "volume-schedulinga42c7715-ebd0-11e8-8067-000c299a5e15/pvc-canprovision" is fully bound to PV "pvc-a693d4b0-ebd0-11e8-8067-000c299a5e15"
I1119 15:56:42.203411  127596 scheduler_binder.go:217] AssumePodVolumes for pod "volume-schedulinga42c7715-ebd0-11e8-8067-000c299a5e15/pod-i-pv-prebound-w-provisioned", node "node-1": all PVCs bound and nothing to do
E1119 15:56:42.203418  127596 scheduler.go:433] scheduler cache AssumePod failed: pod a6940066-ebd0-11e8-8067-000c299a5e15 is in the cache, so can't be assumed
E1119 15:56:42.203422  127596 factory.go:1465] Error scheduling volume-schedulinga42c7715-ebd0-11e8-8067-000c299a5e15/pod-i-pv-prebound-w-provisioned: pod a6940066-ebd0-11e8-8067-000c299a5e15 is in the cache, so can't be assumed; retrying
I1119 15:56:42.203438  127596 factory.go:1558] Updating pod condition for volume-schedulinga42c7715-ebd0-11e8-8067-000c299a5e15/pod-i-pv-prebound-w-provisioned to (PodScheduled==False)
E1119 15:56:42.203444  127596 scheduler.go:556] error assuming pod: pod a6940066-ebd0-11e8-8067-000c299a5e15 is in the cache, so can't be assumed
I1119 15:56:42.204611  127596 factory.go:1338] About to try and schedule pod volume-schedulinga42c7715-ebd0-11e8-8067-000c299a5e15/pod-i-pv-prebound-w-provisioned
I1119 15:56:42.204633  127596 scheduler.go:508] Attempting to schedule pod: volume-schedulinga42c7715-ebd0-11e8-8067-000c299a5e15/pod-i-pv-prebound-w-provisioned
I1119 15:56:42.204751  127596 scheduler_binder.go:147] FindPodVolumes for pod "volume-schedulinga42c7715-ebd0-11e8-8067-000c299a5e15/pod-i-pv-prebound-w-provisioned", node "node-1"
I1119 15:56:42.204782  127596 scheduler_binder.go:458] PVC "volume-schedulinga42c7715-ebd0-11e8-8067-000c299a5e15/pvc-i-pv-prebound" is fully bound to PV "pv-i-prebound"
I1119 15:56:42.204789  127596 scheduler_binder.go:458] PVC "volume-schedulinga42c7715-ebd0-11e8-8067-000c299a5e15/pvc-canprovision" is fully bound to PV "pvc-a693d4b0-ebd0-11e8-8067-000c299a5e15"
I1119 15:56:42.204802  127596 scheduler_binder.go:529] PersistentVolume "pv-i-prebound", Node "node-1" matches for Pod "volume-schedulinga42c7715-ebd0-11e8-8067-000c299a5e15/pod-i-pv-prebound-w-provisioned"
I1119 15:56:42.204807  127596 scheduler_binder.go:529] PersistentVolume "pvc-a693d4b0-ebd0-11e8-8067-000c299a5e15", Node "node-1" matches for Pod "volume-schedulinga42c7715-ebd0-11e8-8067-000c299a5e15/pod-i-pv-prebound-w-provisioned"
I1119 15:56:42.204845  127596 scheduler_binder.go:532] All bound volumes for Pod "volume-schedulinga42c7715-ebd0-11e8-8067-000c299a5e15/pod-i-pv-prebound-w-provisioned" match with Node "node-1"
I1119 15:56:42.204891  127596 scheduler_binder.go:207] AssumePodVolumes for pod "volume-schedulinga42c7715-ebd0-11e8-8067-000c299a5e15/pod-i-pv-prebound-w-provisioned", node "node-1"
I1119 15:56:42.204899  127596 scheduler_binder.go:458] PVC "volume-schedulinga42c7715-ebd0-11e8-8067-000c299a5e15/pvc-i-pv-prebound" is fully bound to PV "pv-i-prebound"
I1119 15:56:42.204903  127596 scheduler_binder.go:458] PVC "volume-schedulinga42c7715-ebd0-11e8-8067-000c299a5e15/pvc-canprovision" is fully bound to PV "pvc-a693d4b0-ebd0-11e8-8067-000c299a5e15"
I1119 15:56:42.204938  127596 scheduler_binder.go:217] AssumePodVolumes for pod "volume-schedulinga42c7715-ebd0-11e8-8067-000c299a5e15/pod-i-pv-prebound-w-provisioned", node "node-1": all PVCs bound and nothing to do
E1119 15:56:42.204960  127596 scheduler.go:433] scheduler cache AssumePod failed: pod a6940066-ebd0-11e8-8067-000c299a5e15 is in the cache, so can't be assumed
E1119 15:56:42.204966  127596 factory.go:1465] Error scheduling volume-schedulinga42c7715-ebd0-11e8-8067-000c299a5e15/pod-i-pv-prebound-w-provisioned: pod a6940066-ebd0-11e8-8067-000c299a5e15 is in the cache, so can't be assumed; retrying
I1119 15:56:42.204993  127596 factory.go:1558] Updating pod condition for volume-schedulinga42c7715-ebd0-11e8-8067-000c299a5e15/pod-i-pv-prebound-w-provisioned to (PodScheduled==False)
E1119 15:56:42.205030  127596 scheduler.go:556] error assuming pod: pod a6940066-ebd0-11e8-8067-000c299a5e15 is in the cache, so can't be assumed
I1119 15:56:42.205975  127596 factory.go:1338] About to try and schedule pod volume-schedulinga42c7715-ebd0-11e8-8067-000c299a5e15/pod-i-pv-prebound-w-provisioned
I1119 15:56:42.205999  127596 scheduler.go:508] Attempting to schedule pod: volume-schedulinga42c7715-ebd0-11e8-8067-000c299a5e15/pod-i-pv-prebound-w-provisioned
I1119 15:56:42.206086  127596 scheduler_binder.go:147] FindPodVolumes for pod "volume-schedulinga42c7715-ebd0-11e8-8067-000c299a5e15/pod-i-pv-prebound-w-provisioned", node "node-1"
I1119 15:56:42.206115  127596 scheduler_binder.go:458] PVC "volume-schedulinga42c7715-ebd0-11e8-8067-000c299a5e15/pvc-i-pv-prebound" is fully bound to PV "pv-i-prebound"
I1119 15:56:42.206122  127596 scheduler_binder.go:458] PVC "volume-schedulinga42c7715-ebd0-11e8-8067-000c299a5e15/pvc-canprovision" is fully bound to PV "pvc-a693d4b0-ebd0-11e8-8067-000c299a5e15"
I1119 15:56:42.206134  127596 scheduler_binder.go:529] PersistentVolume "pv-i-prebound", Node "node-1" matches for Pod "volume-schedulinga42c7715-ebd0-11e8-8067-000c299a5e15/pod-i-pv-prebound-w-provisioned"
I1119 15:56:42.206139  127596 scheduler_binder.go:529] PersistentVolume "pvc-a693d4b0-ebd0-11e8-8067-000c299a5e15", Node "node-1" matches for Pod "volume-schedulinga42c7715-ebd0-11e8-8067-000c299a5e15/pod-i-pv-prebound-w-provisioned"
I1119 15:56:42.206143  127596 scheduler_binder.go:532] All bound volumes for Pod "volume-schedulinga42c7715-ebd0-11e8-8067-000c299a5e15/pod-i-pv-prebound-w-provisioned" match with Node "node-1"
I1119 15:56:42.206229  127596 scheduler_binder.go:207] AssumePodVolumes for pod "volume-schedulinga42c7715-ebd0-11e8-8067-000c299a5e15/pod-i-pv-prebound-w-provisioned", node "node-1"
I1119 15:56:42.206240  127596 scheduler_binder.go:458] PVC "volume-schedulinga42c7715-ebd0-11e8-8067-000c299a5e15/pvc-i-pv-prebound" is fully bound to PV "pv-i-prebound"
I1119 15:56:42.206247  127596 scheduler_binder.go:458] PVC "volume-schedulinga42c7715-ebd0-11e8-8067-000c299a5e15/pvc-canprovision" is fully bound to PV "pvc-a693d4b0-ebd0-11e8-8067-000c299a5e15"
I1119 15:56:42.206254  127596 scheduler_binder.go:217] AssumePodVolumes for pod "volume-schedulinga42c7715-ebd0-11e8-8067-000c299a5e15/pod-i-pv-prebound-w-provisioned", node "node-1": all PVCs bound and nothing to do
E1119 15:56:42.206263  127596 scheduler.go:433] scheduler cache AssumePod failed: pod a6940066-ebd0-11e8-8067-000c299a5e15 is in the cache, so can't be assumed
E1119 15:56:42.206268  127596 factory.go:1465] Error scheduling volume-schedulinga42c7715-ebd0-11e8-8067-000c299a5e15/pod-i-pv-prebound-w-provisioned: pod a6940066-ebd0-11e8-8067-000c299a5e15 is in the cache, so can't be assumed; retrying
I1119 15:56:42.206300  127596 factory.go:1558] Updating pod condition for volume-schedulinga42c7715-ebd0-11e8-8067-000c299a5e15/pod-i-pv-prebound-w-provisioned to (PodScheduled==False)
E1119 15:56:42.206308  127596 scheduler.go:556] error assuming pod: pod a6940066-ebd0-11e8-8067-000c299a5e15 is in the cache, so can't be assumed
I1119 15:56:42.207230  127596 factory.go:1338] About to try and schedule pod volume-schedulinga42c7715-ebd0-11e8-8067-000c299a5e15/pod-i-pv-prebound-w-provisioned
I1119 15:56:42.207250  127596 scheduler.go:508] Attempting to schedule pod: volume-schedulinga42c7715-ebd0-11e8-8067-000c299a5e15/pod-i-pv-prebound-w-provisioned
I1119 15:56:42.207333  127596 scheduler_binder.go:147] FindPodVolumes for pod "volume-schedulinga42c7715-ebd0-11e8-8067-000c299a5e15/pod-i-pv-prebound-w-provisioned", node "node-1"
I1119 15:56:42.207361  127596 scheduler_binder.go:458] PVC "volume-schedulinga42c7715-ebd0-11e8-8067-000c299a5e15/pvc-i-pv-prebound" is fully bound to PV "pv-i-prebound"
I1119 15:56:42.207367  127596 scheduler_binder.go:458] PVC "volume-schedulinga42c7715-ebd0-11e8-8067-000c299a5e15/pvc-canprovision" is fully bound to PV "pvc-a693d4b0-ebd0-11e8-8067-000c299a5e15"
I1119 15:56:42.207380  127596 scheduler_binder.go:529] PersistentVolume "pv-i-prebound", Node "node-1" matches for Pod "volume-schedulinga42c7715-ebd0-11e8-8067-000c299a5e15/pod-i-pv-prebound-w-provisioned"
I1119 15:56:42.207384  127596 scheduler_binder.go:529] PersistentVolume "pvc-a693d4b0-ebd0-11e8-8067-000c299a5e15", Node "node-1" matches for Pod "volume-schedulinga42c7715-ebd0-11e8-8067-000c299a5e15/pod-i-pv-prebound-w-provisioned"
I1119 15:56:42.207389  127596 scheduler_binder.go:532] All bound volumes for Pod "volume-schedulinga42c7715-ebd0-11e8-8067-000c299a5e15/pod-i-pv-prebound-w-provisioned" match with Node "node-1"
I1119 15:56:42.207455  127596 scheduler_binder.go:207] AssumePodVolumes for pod "volume-schedulinga42c7715-ebd0-11e8-8067-000c299a5e15/pod-i-pv-prebound-w-provisioned", node "node-1"
I1119 15:56:42.207468  127596 scheduler_binder.go:458] PVC "volume-schedulinga42c7715-ebd0-11e8-8067-000c299a5e15/pvc-i-pv-prebound" is fully bound to PV "pv-i-prebound"
I1119 15:56:42.207473  127596 scheduler_binder.go:458] PVC "volume-schedulinga42c7715-ebd0-11e8-8067-000c299a5e15/pvc-canprovision" is fully bound to PV "pvc-a693d4b0-ebd0-11e8-8067-000c299a5e15"
I1119 15:56:42.207478  127596 scheduler_binder.go:217] AssumePodVolumes for pod "volume-schedulinga42c7715-ebd0-11e8-8067-000c299a5e15/pod-i-pv-prebound-w-provisioned", node "node-1": all PVCs bound and nothing to do
E1119 15:56:42.207484  127596 scheduler.go:433] scheduler cache AssumePod failed: pod a6940066-ebd0-11e8-8067-000c299a5e15 is in the cache, so can't be assumed
E1119 15:56:42.207488  127596 factory.go:1465] Error scheduling volume-schedulinga42c7715-ebd0-11e8-8067-000c299a5e15/pod-i-pv-prebound-w-provisioned: pod a6940066-ebd0-11e8-8067-000c299a5e15 is in the cache, so can't be assumed; retrying
I1119 15:56:42.207499  127596 factory.go:1558] Updating pod condition for volume-schedulinga42c7715-ebd0-11e8-8067-000c299a5e15/pod-i-pv-prebound-w-provisioned to (PodScheduled==False)
E1119 15:56:42.207504  127596 scheduler.go:556] error assuming pod: pod a6940066-ebd0-11e8-8067-000c299a5e15 is in the cache, so can't be assumed
I1119 15:56:42.208531  127596 factory.go:1338] About to try and schedule pod volume-schedulinga42c7715-ebd0-11e8-8067-000c299a5e15/pod-i-pv-prebound-w-provisioned
I1119 15:56:42.208552  127596 scheduler.go:508] Attempting to schedule pod: volume-schedulinga42c7715-ebd0-11e8-8067-000c299a5e15/pod-i-pv-prebound-w-provisioned
I1119 15:56:42.208601  127596 scheduler_binder.go:147] FindPodVolumes for pod "volume-schedulinga42c7715-ebd0-11e8-8067-000c299a5e15/pod-i-pv-prebound-w-provisioned", node "node-1"
I1119 15:56:42.208629  127596 scheduler_binder.go:458] PVC "volume-schedulinga42c7715-ebd0-11e8-8067-000c299a5e15/pvc-i-pv-prebound" is fully bound to PV "pv-i-prebound"
I1119 15:56:42.208636  127596 scheduler_binder.go:458] PVC "volume-schedulinga42c7715-ebd0-11e8-8067-000c299a5e15/pvc-canprovision" is fully bound to PV "pvc-a693d4b0-ebd0-11e8-8067-000c299a5e15"
I1119 15:56:42.208648  127596 scheduler_binder.go:529] PersistentVolume "pv-i-prebound", Node "node-1" matches for Pod "volume-schedulinga42c7715-ebd0-11e8-8067-000c299a5e15/pod-i-pv-prebound-w-provisioned"
I1119 15:56:42.208653  127596 scheduler_binder.go:529] PersistentVolume "pvc-a693d4b0-ebd0-11e8-8067-000c299a5e15", Node "node-1" matches for Pod "volume-schedulinga42c7715-ebd0-11e8-8067-000c299a5e15/pod-i-pv-prebound-w-provisioned"
I1119 15:56:42.208657  127596 scheduler_binder.go:532] All bound volumes for Pod "volume-schedulinga42c7715-ebd0-11e8-8067-000c299a5e15/pod-i-pv-prebound-w-provisioned" match with Node "node-1"
I1119 15:56:42.208674  127596 scheduler_binder.go:207] AssumePodVolumes for pod "volume-schedulinga42c7715-ebd0-11e8-8067-000c299a5e15/pod-i-pv-prebound-w-provisioned", node "node-1"
I1119 15:56:42.208679  127596 scheduler_binder.go:458] PVC "volume-schedulinga42c7715-ebd0-11e8-8067-000c299a5e15/pvc-i-pv-prebound" is fully bound to PV "pv-i-prebound"
I1119 15:56:42.208683  127596 scheduler_binder.go:458] PVC "volume-schedulinga42c7715-ebd0-11e8-8067-000c299a5e15/pvc-canprovision" is fully bound to PV "pvc-a693d4b0-ebd0-11e8-8067-000c299a5e15"
I1119 15:56:42.208688  127596 scheduler_binder.go:217] AssumePodVolumes for pod "volume-schedulinga42c7715-ebd0-11e8-8067-000c299a5e15/pod-i-pv-prebound-w-provisioned", node "node-1": all PVCs bound and nothing to do
E1119 15:56:42.208693  127596 scheduler.go:433] scheduler cache AssumePod failed: pod a6940066-ebd0-11e8-8067-000c299a5e15 is in the cache, so can't be assumed
E1119 15:56:42.208697  127596 factory.go:1465] Error scheduling volume-schedulinga42c7715-ebd0-11e8-8067-000c299a5e15/pod-i-pv-prebound-w-provisioned: pod a6940066-ebd0-11e8-8067-000c299a5e15 is in the cache, so can't be assumed; retrying
I1119 15:56:42.208708  127596 factory.go:1558] Updating pod condition for volume-schedulinga42c7715-ebd0-11e8-8067-000c299a5e15/pod-i-pv-prebound-w-provisioned to (PodScheduled==False)
E1119 15:56:42.208713  127596 scheduler.go:556] error assuming pod: pod a6940066-ebd0-11e8-8067-000c299a5e15 is in the cache, so can't be assumed
I1119 15:56:42.209676  127596 factory.go:1338] About to try and schedule pod volume-schedulinga42c7715-ebd0-11e8-8067-000c299a5e15/pod-i-pv-prebound-w-provisioned
I1119 15:56:42.209698  127596 scheduler.go:508] Attempting to schedule pod: volume-schedulinga42c7715-ebd0-11e8-8067-000c299a5e15/pod-i-pv-prebound-w-provisioned
I1119 15:56:42.209748  127596 scheduler_binder.go:147] FindPodVolumes for pod "volume-schedulinga42c7715-ebd0-11e8-8067-000c299a5e15/pod-i-pv-prebound-w-provisioned", node "node-1"
I1119 15:56:42.209777  127596 scheduler_binder.go:458] PVC "volume-schedulinga42c7715-ebd0-11e8-8067-000c299a5e15/pvc-i-pv-prebound" is fully bound to PV "pv-i-prebound"
I1119 15:56:42.209783  127596 scheduler_binder.go:458] PVC "volume-schedulinga42c7715-ebd0-11e8-8067-000c299a5e15/pvc-canprovision" is fully bound to PV "pvc-a693d4b0-ebd0-11e8-8067-000c299a5e15"
I1119 15:56:42.209796  127596 scheduler_binder.go:529] PersistentVolume "pv-i-prebound", Node "node-1" matches for Pod "volume-schedulinga42c7715-ebd0-11e8-8067-000c299a5e15/pod-i-pv-prebound-w-provisioned"
I1119 15:56:42.209800  127596 scheduler_binder.go:529] PersistentVolume "pvc-a693d4b0-ebd0-11e8-8067-000c299a5e15", Node "node-1" matches for Pod "volume-schedulinga42c7715-ebd0-11e8-8067-000c299a5e15/pod-i-pv-prebound-w-provisioned"
I1119 15:56:42.209804  127596 scheduler_binder.go:532] All bound volumes for Pod "volume-schedulinga42c7715-ebd0-11e8-8067-000c299a5e15/pod-i-pv-prebound-w-provisioned" match with Node "node-1"
I1119 15:56:42.209825  127596 scheduler_binder.go:207] AssumePodVolumes for pod "volume-schedulinga42c7715-ebd0-11e8-8067-000c299a5e15/pod-i-pv-prebound-w-provisioned", node "node-1"
I1119 15:56:42.209830  127596 scheduler_binder.go:458] PVC "volume-schedulinga42c7715-ebd0-11e8-8067-000c299a5e15/pvc-i-pv-prebound" is fully bound to PV "pv-i-prebound"
I1119 15:56:42.209834  127596 scheduler_binder.go:458] PVC "volume-schedulinga42c7715-ebd0-11e8-8067-000c299a5e15/pvc-canprovision" is fully bound to PV "pvc-a693d4b0-ebd0-11e8-8067-000c299a5e15"
I1119 15:56:42.209839  127596 scheduler_binder.go:217] AssumePodVolumes for pod "volume-schedulinga42c7715-ebd0-11e8-8067-000c299a5e15/pod-i-pv-prebound-w-provisioned", node "node-1": all PVCs bound and nothing to do
E1119 15:56:42.209844  127596 scheduler.go:433] scheduler cache AssumePod failed: pod a6940066-ebd0-11e8-8067-000c299a5e15 is in the cache, so can't be assumed
E1119 15:56:42.209848  127596 factory.go:1465] Error scheduling volume-schedulinga42c7715-ebd0-11e8-8067-000c299a5e15/pod-i-pv-prebound-w-provisioned: pod a6940066-ebd0-11e8-8067-000c299a5e15 is in the cache, so can't be assumed; retrying
I1119 15:56:42.209860  127596 factory.go:1558] Updating pod condition for volume-schedulinga42c7715-ebd0-11e8-8067-000c299a5e15/pod-i-pv-prebound-w-provisioned to (PodScheduled==False)
E1119 15:56:42.209865  127596 scheduler.go:556] error assuming pod: pod a6940066-ebd0-11e8-8067-000c299a5e15 is in the cache, so can't be assumed
I1119 15:56:42.210891  127596 factory.go:1338] About to try and schedule pod volume-schedulinga42c7715-ebd0-11e8-8067-000c299a5e15/pod-i-pv-prebound-w-provisioned
I1119 15:56:42.210911  127596 scheduler.go:508] Attempting to schedule pod: volume-schedulinga42c7715-ebd0-11e8-8067-000c299a5e15/pod-i-pv-prebound-w-provisioned
I1119 15:56:42.210994  127596 scheduler_binder.go:147] FindPodVolumes for pod "volume-schedulinga42c7715-ebd0-11e8-8067-000c299a5e15/pod-i-pv-prebound-w-provisioned", node "node-1"
I1119 15:56:42.211022  127596 scheduler_binder.go:458] PVC "volume-schedulinga42c7715-ebd0-11e8-8067-000c299a5e15/pvc-i-pv-prebound" is fully bound to PV "pv-i-prebound"
I1119 15:56:42.211029  127596 scheduler_binder.go:458] PVC "volume-schedulinga42c7715-ebd0-11e8-8067-000c299a5e15/pvc-canprovision" is fully bound to PV "pvc-a693d4b0-ebd0-11e8-8067-000c299a5e15"
I1119 15:56:42.211041  127596 scheduler_binder.go:529] PersistentVolume "pv-i-prebound", Node "node-1" matches for Pod "volume-schedulinga42c7715-ebd0-11e8-8067-000c299a5e15/pod-i-pv-prebound-w-provisioned"
I1119 15:56:42.211045  127596 scheduler_binder.go:529] PersistentVolume "pvc-a693d4b0-ebd0-11e8-8067-000c299a5e15", Node "node-1" matches for Pod "volume-schedulinga42c7715-ebd0-11e8-8067-000c299a5e15/pod-i-pv-prebound-w-provisioned"
I1119 15:56:42.211050  127596 scheduler_binder.go:532] All bound volumes for Pod "volume-schedulinga42c7715-ebd0-11e8-8067-000c299a5e15/pod-i-pv-prebound-w-provisioned" match with Node "node-1"
I1119 15:56:42.211111  127596 scheduler_binder.go:207] AssumePodVolumes for pod "volume-schedulinga42c7715-ebd0-11e8-8067-000c299a5e15/pod-i-pv-prebound-w-provisioned", node "node-1"
I1119 15:56:42.211121  127596 scheduler_binder.go:458] PVC "volume-schedulinga42c7715-ebd0-11e8-8067-000c299a5e15/pvc-i-pv-prebound" is fully bound to PV "pv-i-prebound"
I1119 15:56:42.211126  127596 scheduler_binder.go:458] PVC "volume-schedulinga42c7715-ebd0-11e8-8067-000c299a5e15/pvc-canprovision" is fully bound to PV "pvc-a693d4b0-ebd0-11e8-8067-000c299a5e15"
I1119 15:56:42.211131  127596 scheduler_binder.go:217] AssumePodVolumes for pod "volume-schedulinga42c7715-ebd0-11e8-8067-000c299a5e15/pod-i-pv-prebound-w-provisioned", node "node-1": all PVCs bound and nothing to do
E1119 15:56:42.211137  127596 scheduler.go:433] scheduler cache AssumePod failed: pod a6940066-ebd0-11e8-8067-000c299a5e15 is in the cache, so can't be assumed
E1119 15:56:42.211141  127596 factory.go:1465] Error scheduling volume-schedulinga42c7715-ebd0-11e8-8067-000c299a5e15/pod-i-pv-prebound-w-provisioned: pod a6940066-ebd0-11e8-8067-000c299a5e15 is in the cache, so can't be assumed; retrying
I1119 15:56:42.211171  127596 factory.go:1558] Updating pod condition for volume-schedulinga42c7715-ebd0-11e8-8067-000c299a5e15/pod-i-pv-prebound-w-provisioned to (PodScheduled==False)
E1119 15:56:42.211180  127596 scheduler.go:556] error assuming pod: pod a6940066-ebd0-11e8-8067-000c299a5e15 is in the cache, so can't be assumed
I1119 15:56:42.212274  127596 factory.go:1338] About to try and schedule pod volume-schedulinga42c7715-ebd0-11e8-8067-000c299a5e15/pod-i-pv-prebound-w-provisioned
I1119 15:56:42.212295  127596 scheduler.go:508] Attempting to schedule pod: volume-schedulinga42c7715-ebd0-11e8-8067-000c299a5e15/pod-i-pv-prebound-w-provisioned
I1119 15:56:42.212380  127596 scheduler_binder.go:147] FindPodVolumes for pod "volume-schedulinga42c7715-ebd0-11e8-8067-000c299a5e15/pod-i-pv-prebound-w-provisioned", node "node-1"
I1119 15:56:42.212412  127596 scheduler_binder.go:458] PVC "volume-schedulinga42c7715-ebd0-11e8-8067-000c299a5e15/pvc-i-pv-prebound" is fully bound to PV "pv-i-prebound"
I1119 15:56:42.212418  127596 scheduler_binder.go:458] PVC "volume-schedulinga42c7715-ebd0-11e8-8067-000c299a5e15/pvc-canprovision" is fully bound to PV "pvc-a693d4b0-ebd0-11e8-8067-000c299a5e15"
I1119 15:56:42.212431  127596 scheduler_binder.go:529] PersistentVolume "pv-i-prebound", Node "node-1" matches for Pod "volume-schedulinga42c7715-ebd0-11e8-8067-000c299a5e15/pod-i-pv-prebound-w-provisioned"
I1119 15:56:42.212435  127596 scheduler_binder.go:529] PersistentVolume "pvc-a693d4b0-ebd0-11e8-8067-000c299a5e15", Node "node-1" matches for Pod "volume-schedulinga42c7715-ebd0-11e8-8067-000c299a5e15/pod-i-pv-prebound-w-provisioned"
I1119 15:56:42.212440  127596 scheduler_binder.go:532] All bound volumes for Pod "volume-schedulinga42c7715-ebd0-11e8-8067-000c299a5e15/pod-i-pv-prebound-w-provisioned" match with Node "node-1"
I1119 15:56:42.212523  127596 scheduler_binder.go:207] AssumePodVolumes for pod "volume-schedulinga42c7715-ebd0-11e8-8067-000c299a5e15/pod-i-pv-prebound-w-provisioned", node "node-1"
I1119 15:56:42.212533  127596 scheduler_binder.go:458] PVC "volume-schedulinga42c7715-ebd0-11e8-8067-000c299a5e15/pvc-i-pv-prebound" is fully bound to PV "pv-i-prebound"
I1119 15:56:42.212538  127596 scheduler_binder.go:458] PVC "volume-schedulinga42c7715-ebd0-11e8-8067-000c299a5e15/pvc-canprovision" is fully bound to PV "pvc-a693d4b0-ebd0-11e8-8067-000c299a5e15"
I1119 15:56:42.212542  127596 scheduler_binder.go:217] AssumePodVolumes for pod "volume-schedulinga42c7715-ebd0-11e8-8067-000c299a5e15/pod-i-pv-prebound-w-provisioned", node "node-1": all PVCs bound and nothing to do
E1119 15:56:42.212548  127596 scheduler.go:433] scheduler cache AssumePod failed: pod a6940066-ebd0-11e8-8067-000c299a5e15 is in the cache, so can't be assumed
E1119 15:56:42.212551  127596 factory.go:1465] Error scheduling volume-schedulinga42c7715-ebd0-11e8-8067-000c299a5e15/pod-i-pv-prebound-w-provisioned: pod a6940066-ebd0-11e8-8067-000c299a5e15 is in the cache, so can't be assumed; retrying
I1119 15:56:42.212621  127596 factory.go:1558] Updating pod condition for volume-schedulinga42c7715-ebd0-11e8-8067-000c299a5e15/pod-i-pv-prebound-w-provisioned to (PodScheduled==False)
E1119 15:56:42.212642  127596 scheduler.go:556] error assuming pod: pod a6940066-ebd0-11e8-8067-000c299a5e15 is in the cache, so can't be assumed
I1119 15:56:42.213634  127596 factory.go:1338] About to try and schedule pod volume-schedulinga42c7715-ebd0-11e8-8067-000c299a5e15/pod-i-pv-prebound-w-provisioned
I1119 15:56:42.213658  127596 scheduler.go:508] Attempting to schedule pod: volume-schedulinga42c7715-ebd0-11e8-8067-000c299a5e15/pod-i-pv-prebound-w-provisioned
I1119 15:56:42.213741  127596 scheduler_binder.go:147] FindPodVolumes for pod "volume-schedulinga42c7715-ebd0-11e8-8067-000c299a5e15/pod-i-pv-prebound-w-provisioned", node "node-1"
I1119 15:56:42.213769  127596 scheduler_binder.go:458] PVC "volume-schedulinga42c7715-ebd0-11e8-8067-000c299a5e15/pvc-i-pv-prebound" is fully bound to PV "pv-i-prebound"
I1119 15:56:42.213776  127596 scheduler_binder.go:458] PVC "volume-schedulinga42c7715-ebd0-11e8-8067-000c299a5e15/pvc-canprovision" is fully bound to PV "pvc-a693d4b0-ebd0-11e8-8067-000c299a5e15"
I1119 15:56:42.213788  127596 scheduler_binder.go:529] PersistentVolume "pv-i-prebound", Node "node-1" matches for Pod "volume-schedulinga42c7715-ebd0-11e8-8067-000c299a5e15/pod-i-pv-prebound-w-provisioned"
I1119 15:56:42.213793  127596 scheduler_binder.go:529] PersistentVolume "pvc-a693d4b0-ebd0-11e8-8067-000c299a5e15", Node "node-1" matches for Pod "volume-schedulinga42c7715-ebd0-11e8-8067-000c299a5e15/pod-i-pv-prebound-w-provisioned"
I1119 15:56:42.213797  127596 scheduler_binder.go:532] All bound volumes for Pod "volume-schedulinga42c7715-ebd0-11e8-8067-000c299a5e15/pod-i-pv-prebound-w-provisioned" match with Node "node-1"
I1119 15:56:42.213869  127596 scheduler_binder.go:207] AssumePodVolumes for pod "volume-schedulinga42c7715-ebd0-11e8-8067-000c299a5e15/pod-i-pv-prebound-w-provisioned", node "node-1"
I1119 15:56:42.213883  127596 scheduler_binder.go:458] PVC "volume-schedulinga42c7715-ebd0-11e8-8067-000c299a5e15/pvc-i-pv-prebound" is fully bound to PV "pv-i-prebound"
I1119 15:56:42.213890  127596 scheduler_binder.go:458] PVC "volume-schedulinga42c7715-ebd0-11e8-8067-000c299a5e15/pvc-canprovision" is fully bound to PV "pvc-a693d4b0-ebd0-11e8-8067-000c299a5e15"
I1119 15:56:42.213897  127596 scheduler_binder.go:217] AssumePodVolumes for pod "volume-schedulinga42c7715-ebd0-11e8-8067-000c299a5e15/pod-i-pv-prebound-w-provisioned", node "node-1": all PVCs bound and nothing to do
E1119 15:56:42.213905  127596 scheduler.go:433] scheduler cache AssumePod failed: pod a6940066-ebd0-11e8-8067-000c299a5e15 is in the cache, so can't be assumed
E1119 15:56:42.213910  127596 factory.go:1465] Error scheduling volume-schedulinga42c7715-ebd0-11e8-8067-000c299a5e15/pod-i-pv-prebound-w-provisioned: pod a6940066-ebd0-11e8-8067-000c299a5e15 is in the cache, so can't be assumed; retrying
I1119 15:56:42.213943  127596 factory.go:1558] Updating pod condition for volume-schedulinga42c7715-ebd0-11e8-8067-000c299a5e15/pod-i-pv-prebound-w-provisioned to (PodScheduled==False)
E1119 15:56:42.213950  127596 scheduler.go:556] error assuming pod: pod a6940066-ebd0-11e8-8067-000c299a5e15 is in the cache, so can't be assumed
I1119 15:56:42.215002  127596 factory.go:1338] About to try and schedule pod volume-schedulinga42c7715-ebd0-11e8-8067-000c299a5e15/pod-i-pv-prebound-w-provisioned
I1119 15:56:42.215023  127596 scheduler.go:508] Attempting to schedule pod: volume-schedulinga42c7715-ebd0-11e8-8067-000c299a5e15/pod-i-pv-prebound-w-provisioned
I1119 15:56:42.215074  127596 scheduler_binder.go:147] FindPodVolumes for pod "volume-schedulinga42c7715-ebd0-11e8-8067-000c299a5e15/pod-i-pv-prebound-w-provisioned", node "node-1"
I1119 15:56:42.215089  127596 scheduler_binder.go:458] PVC "volume-schedulinga42c7715-ebd0-11e8-8067-000c299a5e15/pvc-i-pv-prebound" is fully bound to PV "pv-i-prebound"
I1119 15:56:42.215095  127596 scheduler_binder.go:458] PVC "volume-schedulinga42c7715-ebd0-11e8-8067-000c299a5e15/pvc-canprovision" is fully bound to PV "pvc-a693d4b0-ebd0-11e8-8067-000c299a5e15"
I1119 15:56:42.215107  127596 scheduler_binder.go:529] PersistentVolume "pv-i-prebound", Node "node-1" matches for Pod "volume-schedulinga42c7715-ebd0-11e8-8067-000c299a5e15/pod-i-pv-prebound-w-provisioned"
I1119 15:56:42.215113  127596 scheduler_binder.go:529] PersistentVolume "pvc-a693d4b0-ebd0-11e8-8067-000c299a5e15", Node "node-1" matches for Pod "volume-schedulinga42c7715-ebd0-11e8-8067-000c299a5e15/pod-i-pv-prebound-w-provisioned"
I1119 15:56:42.215117  127596 scheduler_binder.go:532] All bound volumes for Pod "volume-schedulinga42c7715-ebd0-11e8-8067-000c299a5e15/pod-i-pv-prebound-w-provisioned" match with Node "node-1"
I1119 15:56:42.215149  127596 scheduler_binder.go:207] AssumePodVolumes for pod "volume-schedulinga42c7715-ebd0-11e8-8067-000c299a5e15/pod-i-pv-prebound-w-provisioned", node "node-1"
I1119 15:56:42.215159  127596 scheduler_binder.go:458] PVC "volume-schedulinga42c7715-ebd0-11e8-8067-000c299a5e15/pvc-i-pv-prebound" is fully bound to PV "pv-i-prebound"
I1119 15:56:42.215163  127596 scheduler_binder.go:458] PVC "volume-schedulinga42c7715-ebd0-11e8-8067-000c299a5e15/pvc-canprovision" is fully bound to PV "pvc-a693d4b0-ebd0-11e8-8067-000c299a5e15"
I1119 15:56:42.215168  127596 scheduler_binder.go:217] AssumePodVolumes for pod "volume-schedulinga42c7715-ebd0-11e8-8067-000c299a5e15/pod-i-pv-prebound-w-provisioned", node "node-1": all PVCs bound and nothing to do
E1119 15:56:42.215173  127596 scheduler.go:433] scheduler cache AssumePod failed: pod a6940066-ebd0-11e8-8067-000c299a5e15 is in the cache, so can't be assumed
E1119 15:56:42.215177  127596 factory.go:1465] Error scheduling volume-schedulinga42c7715-ebd0-11e8-8067-000c299a5e15/pod-i-pv-prebound-w-provisioned: pod a6940066-ebd0-11e8-8067-000c299a5e15 is in the cache, so can't be assumed; retrying
I1119 15:56:42.215204  127596 factory.go:1558] Updating pod condition for volume-schedulinga42c7715-ebd0-11e8-8067-000c299a5e15/pod-i-pv-prebound-w-provisioned to (PodScheduled==False)
E1119 15:56:42.215213  127596 scheduler.go:556] error assuming pod: pod a6940066-ebd0-11e8-8067-000c299a5e15 is in the cache, so can't be assumed
I1119 15:56:42.216183  127596 factory.go:1338] About to try and schedule pod volume-schedulinga42c7715-ebd0-11e8-8067-000c299a5e15/pod-i-pv-prebound-w-provisioned
I1119 15:56:42.216204  127596 scheduler.go:508] Attempting to schedule pod: volume-schedulinga42c7715-ebd0-11e8-8067-000c299a5e15/pod-i-pv-prebound-w-provisioned
I1119 15:56:42.216254  127596 scheduler_binder.go:147] FindPodVolumes for pod "volume-schedulinga42c7715-ebd0-11e8-8067-000c299a5e15/pod-i-pv-prebound-w-provisioned", node "node-1"
I1119 15:56:42.216269  127596 scheduler_binder.go:458] PVC "volume-schedulinga42c7715-ebd0-11e8-8067-000c299a5e15/pvc-i-pv-prebound" is fully bound to PV "pv-i-prebound"
I1119 15:56:42.216275  127596 scheduler_binder.go:458] PVC "volume-schedulinga42c7715-ebd0-11e8-8067-000c299a5e15/pvc-canprovision" is fully bound to PV "pvc-a693d4b0-ebd0-11e8-8067-000c299a5e15"
I1119 15:56:42.216288  127596 scheduler_binder.go:529] PersistentVolume "pv-i-prebound", Node "node-1" matches for Pod "volume-schedulinga42c7715-ebd0-11e8-8067-000c299a5e15/pod-i-pv-prebound-w-provisioned"
I1119 15:56:42.216293  127596 scheduler_binder.go:529] PersistentVolume "pvc-a693d4b0-ebd0-11e8-8067-000c299a5e15", Node "node-1" matches for Pod "volume-schedulinga42c7715-ebd0-11e8-8067-000c299a5e15/pod-i-pv-prebound-w-provisioned"
I1119 15:56:42.216298  127596 scheduler_binder.go:532] All bound volumes for Pod "volume-schedulinga42c7715-ebd0-11e8-8067-000c299a5e15/pod-i-pv-prebound-w-provisioned" match with Node "node-1"
I1119 15:56:42.216328  127596 scheduler_binder.go:207] AssumePodVolumes for pod "volume-schedulinga42c7715-ebd0-11e8-8067-000c299a5e15/pod-i-pv-prebound-w-provisioned", node "node-1"
I1119 15:56:42.216338  127596 scheduler_binder.go:458] PVC "volume-schedulinga42c7715-ebd0-11e8-8067-000c299a5e15/pvc-i-pv-prebound" is fully bound to PV "pv-i-prebound"
I1119 15:56:42.216342  127596 scheduler_binder.go:458] PVC "volume-schedulinga42c7715-ebd0-11e8-8067-000c299a5e15/pvc-canprovision" is fully bound to PV "pvc-a693d4b0-ebd0-11e8-8067-000c299a5e15"
I1119 15:56:42.216346  127596 scheduler_binder.go:217] AssumePodVolumes for pod "volume-schedulinga42c7715-ebd0-11e8-8067-000c299a5e15/pod-i-pv-prebound-w-provisioned", node "node-1": all PVCs bound and nothing to do
E1119 15:56:42.216352  127596 scheduler.go:433] scheduler cache AssumePod failed: pod a6940066-ebd0-11e8-8067-000c299a5e15 is in the cache, so can't be assumed
E1119 15:56:42.216356  127596 factory.go:1465] Error scheduling volume-schedulinga42c7715-ebd0-11e8-8067-000c299a5e15/pod-i-pv-prebound-w-provisioned: pod a6940066-ebd0-11e8-8067-000c299a5e15 is in the cache, so can't be assumed; retrying
I1119 15:56:42.216384  127596 factory.go:1558] Updating pod condition for volume-schedulinga42c7715-ebd0-11e8-8067-000c299a5e15/pod-i-pv-prebound-w-provisioned to (PodScheduled==False)
E1119 15:56:42.216392  127596 scheduler.go:556] error assuming pod: pod a6940066-ebd0-11e8-8067-000c299a5e15 is in the cache, so can't be assumed
I1119 15:56:42.217418  127596 factory.go:1338] About to try and schedule pod volume-schedulinga42c7715-ebd0-11e8-8067-000c299a5e15/pod-i-pv-prebound-w-provisioned
I1119 15:56:42.217442  127596 scheduler.go:508] Attempting to schedule pod: volume-schedulinga42c7715-ebd0-11e8-8067-000c299a5e15/pod-i-pv-prebound-w-provisioned
I1119 15:56:42.217545  127596 scheduler_binder.go:147] FindPodVolumes for pod "volume-schedulinga42c7715-ebd0-11e8-8067-000c299a5e15/pod-i-pv-prebound-w-provisioned", node "node-1"
I1119 15:56:42.217563  127596 scheduler_binder.go:458] PVC "volume-schedulinga42c7715-ebd0-11e8-8067-000c299a5e15/pvc-i-pv-prebound" is fully bound to PV "pv-i-prebound"
I1119 15:56:42.217568  127596 scheduler_binder.go:458] PVC "volume-schedulinga42c7715-ebd0-11e8-8067-000c299a5e15/pvc-canprovision" is fully bound to PV "pvc-a693d4b0-ebd0-11e8-8067-000c299a5e15"
I1119 15:56:42.217582  127596 scheduler_binder.go:529] PersistentVolume "pv-i-prebound", Node "node-1" matches for Pod "volume-schedulinga42c7715-ebd0-11e8-8067-000c299a5e15/pod-i-pv-prebound-w-provisioned"
I1119 15:56:42.217586  127596 scheduler_binder.go:529] PersistentVolume "pvc-a693d4b0-ebd0-11e8-8067-000c299a5e15", Node "node-1" matches for Pod "volume-schedulinga42c7715-ebd0-11e8-8067-000c299a5e15/pod-i-pv-prebound-w-provisioned"
I1119 15:56:42.217629  127596 scheduler_binder.go:532] All bound volumes for Pod "volume-schedulinga42c7715-ebd0-11e8-8067-000c299a5e15/pod-i-pv-prebound-w-provisioned" match with Node "node-1"
I1119 15:56:42.217662  127596 scheduler_binder.go:207] AssumePodVolumes for pod "volume-schedulinga42c7715-ebd0-11e8-8067-000c299a5e15/pod-i-pv-prebound-w-provisioned", node "node-1"
I1119 15:56:42.217670  127596 scheduler_binder.go:458] PVC "volume-schedulinga42c7715-ebd0-11e8-8067-000c299a5e15/pvc-i-pv-prebound" is fully bound to PV "pv-i-prebound"
I1119 15:56:42.217674  127596 scheduler_binder.go:458] PVC "volume-schedulinga42c7715-ebd0-11e8-8067-000c299a5e15/pvc-canprovision" is fully bound to PV "pvc-a693d4b0-ebd0-11e8-8067-000c299a5e15"
I1119 15:56:42.217679  127596 scheduler_binder.go:217] AssumePodVolumes for pod "volume-schedulinga42c7715-ebd0-11e8-8067-000c299a5e15/pod-i-pv-prebound-w-provisioned", node "node-1": all PVCs bound and nothing to do
E1119 15:56:42.217732  127596 scheduler.go:433] scheduler cache AssumePod failed: pod a6940066-ebd0-11e8-8067-000c299a5e15 is in the cache, so can't be assumed
E1119 15:56:42.217738  127596 factory.go:1465] Error scheduling volume-schedulinga42c7715-ebd0-11e8-8067-000c299a5e15/pod-i-pv-prebound-w-provisioned: pod a6940066-ebd0-11e8-8067-000c299a5e15 is in the cache, so can't be assumed; retrying
I1119 15:56:42.217766  127596 factory.go:1558] Updating pod condition for volume-schedulinga42c7715-ebd0-11e8-8067-000c299a5e15/pod-i-pv-prebound-w-provisioned to (PodScheduled==False)
E1119 15:56:42.217773  127596 scheduler.go:556] error assuming pod: pod a6940066-ebd0-11e8-8067-000c299a5e15 is in the cache, so can't be assumed
I1119 15:56:42.218774  127596 factory.go:1338] About to try and schedule pod volume-schedulinga42c7715-ebd0-11e8-8067-000c299a5e15/pod-i-pv-prebound-w-provisioned
I1119 15:56:42.218796  127596 scheduler.go:508] Attempting to schedule pod: volume-schedulinga42c7715-ebd0-11e8-8067-000c299a5e15/pod-i-pv-prebound-w-provisioned
I1119 15:56:42.218848  127596 scheduler_binder.go:147] FindPodVolumes for pod "volume-schedulinga42c7715-ebd0-11e8-8067-000c299a5e15/pod-i-pv-prebound-w-provisioned", node "node-1"
I1119 15:56:42.218864  127596 scheduler_binder.go:458] PVC "volume-schedulinga42c7715-ebd0-11e8-8067-000c299a5e15/pvc-i-pv-prebound" is fully bound to PV "pv-i-prebound"
I1119 15:56:42.218868  127596 scheduler_binder.go:458] PVC "volume-schedulinga42c7715-ebd0-11e8-8067-000c299a5e15/pvc-canprovision" is fully bound to PV "pvc-a693d4b0-ebd0-11e8-8067-000c299a5e15"
I1119 15:56:42.218882  127596 scheduler_binder.go:529] PersistentVolume "pv-i-prebound", Node "node-1" matches for Pod "volume-schedulinga42c7715-ebd0-11e8-8067-000c299a5e15/pod-i-pv-prebound-w-provisioned"
I1119 15:56:42.218887  127596 scheduler_binder.go:529] PersistentVolume "pvc-a693d4b0-ebd0-11e8-8067-000c299a5e15", Node "node-1" matches for Pod "volume-schedulinga42c7715-ebd0-11e8-8067-000c299a5e15/pod-i-pv-prebound-w-provisioned"
I1119 15:56:42.218891  127596 scheduler_binder.go:532] All bound volumes for Pod "volume-schedulinga42c7715-ebd0-11e8-8067-000c299a5e15/pod-i-pv-prebound-w-provisioned" match with Node "node-1"
I1119 15:56:42.218923  127596 scheduler_binder.go:207] AssumePodVolumes for pod "volume-schedulinga42c7715-ebd0-11e8-8067-000c299a5e15/pod-i-pv-prebound-w-provisioned", node "node-1"
I1119 15:56:42.218946  127596 scheduler_binder.go:458] PVC "volume-schedulinga42c7715-ebd0-11e8-8067-000c299a5e15/pvc-i-pv-prebound" is fully bound to PV "pv-i-prebound"
I1119 15:56:42.218951  127596 scheduler_binder.go:458] PVC "volume-schedulinga42c7715-ebd0-11e8-8067-000c299a5e15/pvc-canprovision" is fully bound to PV "pvc-a693d4b0-ebd0-11e8-8067-000c299a5e15"
I1119 15:56:42.218956  127596 scheduler_binder.go:217] AssumePodVolumes for pod "volume-schedulinga42c7715-ebd0-11e8-8067-000c299a5e15/pod-i-pv-prebound-w-provisioned", node "node-1": all PVCs bound and nothing to do
E1119 15:56:42.218962  127596 scheduler.go:433] scheduler cache AssumePod failed: pod a6940066-ebd0-11e8-8067-000c299a5e15 is in the cache, so can't be assumed
E1119 15:56:42.218966  127596 factory.go:1465] Error scheduling volume-schedulinga42c7715-ebd0-11e8-8067-000c299a5e15/pod-i-pv-prebound-w-provisioned: pod a6940066-ebd0-11e8-8067-000c299a5e15 is in the cache, so can't be assumed; retrying
I1119 15:56:42.218980  127596 factory.go:1558] Updating pod condition for volume-schedulinga42c7715-ebd0-11e8-8067-000c299a5e15/pod-i-pv-prebound-w-provisioned to (PodScheduled==False)
E1119 15:56:42.218986  127596 scheduler.go:556] error assuming pod: pod a6940066-ebd0-11e8-8067-000c299a5e15 is in the cache, so can't be assumed
I1119 15:56:42.219859  127596 factory.go:1338] About to try and schedule pod volume-schedulinga42c7715-ebd0-11e8-8067-000c299a5e15/pod-i-pv-prebound-w-provisioned
I1119 15:56:42.219882  127596 scheduler.go:508] Attempting to schedule pod: volume-schedulinga42c7715-ebd0-11e8-8067-000c299a5e15/pod-i-pv-prebound-w-provisioned
I1119 15:56:42.219917  127596 scheduler_binder.go:147] FindPodVolumes for pod "volume-schedulinga42c7715-ebd0-11e8-8067-000c299a5e15/pod-i-pv-prebound-w-provisioned", node "node-1"
I1119 15:56:42.219930  127596 scheduler_binder.go:458] PVC "volume-schedulinga42c7715-ebd0-11e8-8067-000c299a5e15/pvc-i-pv-prebound" is fully bound to PV "pv-i-prebound"
I1119 15:56:42.219934  127596 scheduler_binder.go:458] PVC "volume-schedulinga42c7715-ebd0-11e8-8067-000c299a5e15/pvc-canprovision" is fully bound to PV "pvc-a693d4b0-ebd0-11e8-8067-000c299a5e15"
I1119 15:56:42.219947  127596 scheduler_binder.go:529] PersistentVolume "pv-i-prebound", Node "node-1" matches for Pod "volume-schedulinga42c7715-ebd0-11e8-8067-000c299a5e15/pod-i-pv-prebound-w-provisioned"
I1119 15:56:42.219953  127596 scheduler_binder.go:529] PersistentVolume "pvc-a693d4b0-ebd0-11e8-8067-000c299a5e15", Node "node-1" matches for Pod "volume-schedulinga42c7715-ebd0-11e8-8067-000c299a5e15/pod-i-pv-prebound-w-provisioned"
I1119 15:56:42.219957  127596 scheduler_binder.go:532] All bound volumes for Pod "volume-schedulinga42c7715-ebd0-11e8-8067-000c299a5e15/pod-i-pv-prebound-w-provisioned" match with Node "node-1"
I1119 15:56:42.219971  127596 scheduler_binder.go:207] AssumePodVolumes for pod "volume-schedulinga42c7715-ebd0-11e8-8067-000c299a5e15/pod-i-pv-prebound-w-provisioned", node "node-1"
I1119 15:56:42.219992  127596 scheduler_binder.go:458] PVC "volume-schedulinga42c7715-ebd0-11e8-8067-000c299a5e15/pvc-i-pv-prebound" is fully bound to PV "pv-i-prebound"
I1119 15:56:42.219998  127596 scheduler_binder.go:458] PVC "volume-schedulinga42c7715-ebd0-11e8-8067-000c299a5e15/pvc-canprovision" is fully bound to PV "pvc-a693d4b0-ebd0-11e8-8067-000c299a5e15"
I1119 15:56:42.220003  127596 scheduler_binder.go:217] AssumePodVolumes for pod "volume-schedulinga42c7715-ebd0-11e8-8067-000c299a5e15/pod-i-pv-prebound-w-provisioned", node "node-1": all PVCs bound and nothing to do
E1119 15:56:42.220009  127596 scheduler.go:433] scheduler cache AssumePod failed: pod a6940066-ebd0-11e8-8067-000c299a5e15 is in the cache, so can't be assumed
E1119 15:56:42.220013  127596 factory.go:1465] Error scheduling volume-schedulinga42c7715-ebd0-11e8-8067-000c299a5e15/pod-i-pv-prebound-w-provisioned: pod a6940066-ebd0-11e8-8067-000c299a5e15 is in the cache, so can't be assumed; retrying
I1119 15:56:42.220026  127596 factory.go:1558] Updating pod condition for volume-schedulinga42c7715-ebd0-11e8-8067-000c299a5e15/pod-i-pv-prebound-w-provisioned to (PodScheduled==False)
E1119 15:56:42.220030  127596 scheduler.go:556] error assuming pod: pod a6940066-ebd0-11e8-8067-000c299a5e15 is in the cache, so can't be assumed
I1119 15:56:42.220918  127596 factory.go:1338] About to try and schedule pod volume-schedulinga42c7715-ebd0-11e8-8067-000c299a5e15/pod-i-pv-prebound-w-provisioned
I1119 15:56:42.220942  127596 scheduler.go:508] Attempting to schedule pod: volume-schedulinga42c7715-ebd0-11e8-8067-000c299a5e15/pod-i-pv-prebound-w-provisioned
I1119 15:56:42.220975  127596 scheduler_binder.go:147] FindPodVolumes for pod "volume-schedulinga42c7715-ebd0-11e8-8067-000c299a5e15/pod-i-pv-prebound-w-provisioned", node "node-1"
I1119 15:56:42.220987  127596 scheduler_binder.go:458] PVC "volume-schedulinga42c7715-ebd0-11e8-8067-000c299a5e15/pvc-i-pv-prebound" is fully bound to PV "pv-i-prebound"
I1119 15:56:42.220992  127596 scheduler_binder.go:458] PVC "volume-schedulinga42c7715-ebd0-11e8-8067-000c299a5e15/pvc-canprovision" is fully bound to PV "pvc-a693d4b0-ebd0-11e8-8067-000c299a5e15"
I1119 15:56:42.221004  127596 scheduler_binder.go:529] PersistentVolume "pv-i-prebound", Node "node-1" matches for Pod "volume-schedulinga42c7715-ebd0-11e8-8067-000c299a5e15/pod-i-pv-prebound-w-provisioned"
I1119 15:56:42.221011  127596 scheduler_binder.go:529] PersistentVolume "pvc-a693d4b0-ebd0-11e8-8067-000c299a5e15", Node "node-1" matches for Pod "volume-schedulinga42c7715-ebd0-11e8-8067-000c299a5e15/pod-i-pv-prebound-w-provisioned"
I1119 15:56:42.221015  127596 scheduler_binder.go:532] All bound volumes for Pod "volume-schedulinga42c7715-ebd0-11e8-8067-000c299a5e15/pod-i-pv-prebound-w-provisioned" match with Node "node-1"
I1119 15:56:42.221030  127596 scheduler_binder.go:207] AssumePodVolumes for pod "volume-schedulinga42c7715-ebd0-11e8-8067-000c299a5e15/pod-i-pv-prebound-w-provisioned", node "node-1"
I1119 15:56:42.221035  127596 scheduler_binder.go:458] PVC "volume-schedulinga42c7715-ebd0-11e8-8067-000c299a5e15/pvc-i-pv-prebound" is fully bound to PV "pv-i-prebound"
I1119 15:56:42.221039  127596 scheduler_binder.go:458] PVC "volume-schedulinga42c7715-ebd0-11e8-8067-000c299a5e15/pvc-canprovision" is fully bound to PV "pvc-a693d4b0-ebd0-11e8-8067-000c299a5e15"
I1119 15:56:42.221043  127596 scheduler_binder.go:217] AssumePodVolumes for pod "volume-schedulinga42c7715-ebd0-11e8-8067-000c299a5e15/pod-i-pv-prebound-w-provisioned", node "node-1": all PVCs bound and nothing to do
E1119 15:56:42.221048  127596 scheduler.go:433] scheduler cache AssumePod failed: pod a6940066-ebd0-11e8-8067-000c299a5e15 is in the cache, so can't be assumed
E1119 15:56:42.221052  127596 factory.go:1465] Error scheduling volume-schedulinga42c7715-ebd0-11e8-8067-000c299a5e15/pod-i-pv-prebound-w-provisioned: pod a6940066-ebd0-11e8-8067-000c299a5e15 is in the cache, so can't be assumed; retrying
I1119 15:56:42.221063  127596 factory.go:1558] Updating pod condition for volume-schedulinga42c7715-ebd0-11e8-8067-000c299a5e15/pod-i-pv-prebound-w-provisioned to (PodScheduled==False)
E1119 15:56:42.221068  127596 scheduler.go:556] error assuming pod: pod a6940066-ebd0-11e8-8067-000c299a5e15 is in the cache, so can't be assumed
I1119 15:56:42.221882  127596 factory.go:1338] About to try and schedule pod volume-schedulinga42c7715-ebd0-11e8-8067-000c299a5e15/pod-i-pv-prebound-w-provisioned
I1119 15:56:42.221906  127596 scheduler.go:508] Attempting to schedule pod: volume-schedulinga42c7715-ebd0-11e8-8067-000c299a5e15/pod-i-pv-prebound-w-provisioned
I1119 15:56:42.221938  127596 scheduler_binder.go:147] FindPodVolumes for pod "volume-schedulinga42c7715-ebd0-11e8-8067-000c299a5e15/pod-i-pv-prebound-w-provisioned", node "node-1"
I1119 15:56:42.221951  127596 scheduler_binder.go:458] PVC "volume-schedulinga42c7715-ebd0-11e8-8067-000c299a5e15/pvc-i-pv-prebound" is fully bound to PV "pv-i-prebound"
I1119 15:56:42.221956  127596 scheduler_binder.go:458] PVC "volume-schedulinga42c7715-ebd0-11e8-8067-000c299a5e15/pvc-canprovision" is fully bound to PV "pvc-a693d4b0-ebd0-11e8-8067-000c299a5e15"
I1119 15:56:42.221968  127596 scheduler_binder.go:529] PersistentVolume "pv-i-prebound", Node "node-1" matches for Pod "volume-schedulinga42c7715-ebd0-11e8-8067-000c299a5e15/pod-i-pv-prebound-w-provisioned"
I1119 15:56:42.221972  127596 scheduler_binder.go:529] PersistentVolume "pvc-a693d4b0-ebd0-11e8-8067-000c299a5e15", Node "node-1" matches for Pod "volume-schedulinga42c7715-ebd0-11e8-8067-000c299a5e15/pod-i-pv-prebound-w-provisioned"
I1119 15:56:42.221977  127596 scheduler_binder.go:532] All bound volumes for Pod "volume-schedulinga42c7715-ebd0-11e8-8067-000c299a5e15/pod-i-pv-prebound-w-provisioned" match with Node "node-1"
I1119 15:56:42.221992  127596 scheduler_binder.go:207] AssumePodVolumes for pod "volume-schedulinga42c7715-ebd0-11e8-8067-000c299a5e15/pod-i-pv-prebound-w-provisioned", node "node-1"
I1119 15:56:42.222013  127596 scheduler_binder.go:458] PVC "volume-schedulinga42c7715-ebd0-11e8-8067-000c299a5e15/pvc-i-pv-prebound" is fully bound to PV "pv-i-prebound"
I1119 15:56:42.222018  127596 scheduler_binder.go:458] PVC "volume-schedulinga42c7715-ebd0-11e8-8067-000c299a5e15/pvc-canprovision" is fully bound to PV "pvc-a693d4b0-ebd0-11e8-8067-000c299a5e15"
I1119 15:56:42.222023  127596 scheduler_binder.go:217] AssumePodVolumes for pod "volume-schedulinga42c7715-ebd0-11e8-8067-000c299a5e15/pod-i-pv-prebound-w-provisioned", node "node-1": all PVCs bound and nothing to do
E1119 15:56:42.222029  127596 scheduler.go:433] scheduler cache AssumePod failed: pod a6940066-ebd0-11e8-8067-000c299a5e15 is in the cache, so can't be assumed
E1119 15:56:42.222033  127596 factory.go:1465] Error scheduling volume-schedulinga42c7715-ebd0-11e8-8067-000c299a5e15/pod-i-pv-prebound-w-provisioned: pod a6940066-ebd0-11e8-8067-000c299a5e15 is in the cache, so can't be assumed; retrying
I1119 15:56:42.222044  127596 factory.go:1558] Updating pod condition for volume-schedulinga42c7715-ebd0-11e8-8067-000c299a5e15/pod-i-pv-prebound-w-provisioned to (PodScheduled==False)
E1119 15:56:42.222048  127596 scheduler.go:556] error assuming pod: pod a6940066-ebd0-11e8-8067-000c299a5e15 is in the cache, so can't be assumed
I1119 15:56:42.222931  127596 factory.go:1338] About to try and schedule pod volume-schedulinga42c7715-ebd0-11e8-8067-000c299a5e15/pod-i-pv-prebound-w-provisioned
I1119 15:56:42.222955  127596 scheduler.go:508] Attempting to schedule pod: volume-schedulinga42c7715-ebd0-11e8-8067-000c299a5e15/pod-i-pv-prebound-w-provisioned
I1119 15:56:42.222989  127596 scheduler_binder.go:147] FindPodVolumes for pod "volume-schedulinga42c7715-ebd0-11e8-8067-000c299a5e15/pod-i-pv-prebound-w-provisioned", node "node-1"
I1119 15:56:42.223001  127596 scheduler_binder.go:458] PVC "volume-schedulinga42c7715-ebd0-11e8-8067-000c299a5e15/pvc-i-pv-prebound" is fully bound to PV "pv-i-prebound"
I1119 15:56:42.223006  127596 scheduler_binder.go:458] PVC "volume-schedulinga42c7715-ebd0-11e8-8067-000c299a5e15/pvc-canprovision" is fully bound to PV "pvc-a693d4b0-ebd0-11e8-8067-000c299a5e15"
I1119 15:56:42.223018  127596 scheduler_binder.go:529] PersistentVolume "pv-i-prebound", Node "node-1" matches for Pod "volume-schedulinga42c7715-ebd0-11e8-8067-000c299a5e15/pod-i-pv-prebound-w-provisioned"
I1119 15:56:42.223022  127596 scheduler_binder.go:529] PersistentVolume "pvc-a693d4b0-ebd0-11e8-8067-000c299a5e15", Node "node-1" matches for Pod "volume-schedulinga42c7715-ebd0-11e8-8067-000c299a5e15/pod-i-pv-prebound-w-provisioned"
I1119 15:56:42.223027  127596 scheduler_binder.go:532] All bound volumes for Pod "volume-schedulinga42c7715-ebd0-11e8-8067-000c299a5e15/pod-i-pv-prebound-w-provisioned" match with Node "node-1"
I1119 15:56:42.223041  127596 scheduler_binder.go:207] AssumePodVolumes for pod "volume-schedulinga42c7715-ebd0-11e8-8067-000c299a5e15/pod-i-pv-prebound-w-provisioned", node "node-1"
I1119 15:56:42.223045  127596 scheduler_binder.go:458] PVC "volume-schedulinga42c7715-ebd0-11e8-8067-000c299a5e15/pvc-i-pv-prebound" is fully bound to PV "pv-i-prebound"
I1119 15:56:42.223049  127596 scheduler_binder.go:458] PVC "volume-schedulinga42c7715-ebd0-11e8-8067-000c299a5e15/pvc-canprovision" is fully bound to PV "pvc-a693d4b0-ebd0-11e8-8067-000c299a5e15"
I1119 15:56:42.223054  127596 scheduler_binder.go:217] AssumePodVolumes for pod "volume-schedulinga42c7715-ebd0-11e8-8067-000c299a5e15/pod-i-pv-prebound-w-provisioned", node "node-1": all PVCs bound and nothing to do
E1119 15:56:42.223059  127596 scheduler.go:433] scheduler cache AssumePod failed: pod a6940066-ebd0-11e8-8067-000c299a5e15 is in the cache, so can't be assumed
E1119 15:56:42.223063  127596 factory.go:1465] Error scheduling volume-schedulinga42c7715-ebd0-11e8-8067-000c299a5e15/pod-i-pv-prebound-w-provisioned: pod a6940066-ebd0-11e8-8067-000c299a5e15 is in the cache, so can't be assumed; retrying
I1119 15:56:42.223073  127596 factory.go:1558] Updating pod condition for volume-schedulinga42c7715-ebd0-11e8-8067-000c299a5e15/pod-i-pv-prebound-w-provisioned to (PodScheduled==False)
E1119 15:56:42.223077  127596 scheduler.go:556] error assuming pod: pod a6940066-ebd0-11e8-8067-000c299a5e15 is in the cache, so can't be assumed
I1119 15:56:42.224067  127596 factory.go:1338] About to try and schedule pod volume-schedulinga42c7715-ebd0-11e8-8067-000c299a5e15/pod-i-pv-prebound-w-provisioned
I1119 15:56:42.224088  127596 scheduler.go:508] Attempting to schedule pod: volume-schedulinga42c7715-ebd0-11e8-8067-000c299a5e15/pod-i-pv-prebound-w-provisioned
I1119 15:56:42.224136  127596 scheduler_binder.go:147] FindPodVolumes for pod "volume-schedulinga42c7715-ebd0-11e8-8067-000c299a5e15/pod-i-pv-prebound-w-provisioned", node "node-1"
I1119 15:56:42.224151  127596 scheduler_binder.go:458] PVC "volume-schedulinga42c7715-ebd0-11e8-8067-000c299a5e15/pvc-i-pv-prebound" is fully bound to PV "pv-i-prebound"
I1119 15:56:42.224156  127596 scheduler_binder.go:458] PVC "volume-schedulinga42c7715-ebd0-11e8-8067-000c299a5e15/pvc-canprovision" is fully bound to PV "pvc-a693d4b0-ebd0-11e8-8067-000c299a5e15"
I1119 15:56:42.224168  127596 scheduler_binder.go:529] PersistentVolume "pv-i-prebound", Node "node-1" matches for Pod "volume-schedulinga42c7715-ebd0-11e8-8067-000c299a5e15/pod-i-pv-prebound-w-provisioned"
I1119 15:56:42.224173  127596 scheduler_binder.go:529] PersistentVolume "pvc-a693d4b0-ebd0-11e8-8067-000c299a5e15", Node "node-1" matches for Pod "volume-schedulinga42c7715-ebd0-11e8-8067-000c299a5e15/pod-i-pv-prebound-w-provisioned"
I1119 15:56:42.224177  127596 scheduler_binder.go:532] All bound volumes for Pod "volume-schedulinga42c7715-ebd0-11e8-8067-000c299a5e15/pod-i-pv-prebound-w-provisioned" match with Node "node-1"
I1119 15:56:42.224208  127596 scheduler_binder.go:207] AssumePodVolumes for pod "volume-schedulinga42c7715-ebd0-11e8-8067-000c299a5e15/pod-i-pv-prebound-w-provisioned", node "node-1"
I1119 15:56:42.224216  127596 scheduler_binder.go:458] PVC "volume-schedulinga42c7715-ebd0-11e8-8067-000c299a5e15/pvc-i-pv-prebound" is fully bound to PV "pv-i-prebound"
I1119 15:56:42.224220  127596 scheduler_binder.go:458] PVC "volume-schedulinga42c7715-ebd0-11e8-8067-000c299a5e15/pvc-canprovision" is fully bound to PV "pvc-a693d4b0-ebd0-11e8-8067-000c299a5e15"
I1119 15:56:42.224225  127596 scheduler_binder.go:217] AssumePodVolumes for pod "volume-schedulinga42c7715-ebd0-11e8-8067-000c299a5e15/pod-i-pv-prebound-w-provisioned", node "node-1": all PVCs bound and nothing to do
E1119 15:56:42.224230  127596 scheduler.go:433] scheduler cache AssumePod failed: pod a6940066-ebd0-11e8-8067-000c299a5e15 is in the cache, so can't be assumed
E1119 15:56:42.224234  127596 factory.go:1465] Error scheduling volume-schedulinga42c7715-ebd0-11e8-8067-000c299a5e15/pod-i-pv-prebound-w-provisioned: pod a6940066-ebd0-11e8-8067-000c299a5e15 is in the cache, so can't be assumed; retrying
I1119 15:56:42.224262  127596 factory.go:1558] Updating pod condition for volume-schedulinga42c7715-ebd0-11e8-8067-000c299a5e15/pod-i-pv-prebound-w-provisioned to (PodScheduled==False)
E1119 15:56:42.224270  127596 scheduler.go:556] error assuming pod: pod a6940066-ebd0-11e8-8067-000c299a5e15 is in the cache, so can't be assumed
I1119 15:56:42.225202  127596 factory.go:1338] About to try and schedule pod volume-schedulinga42c7715-ebd0-11e8-8067-000c299a5e15/pod-i-pv-prebound-w-provisioned
I1119 15:56:42.225222  127596 scheduler.go:508] Attempting to schedule pod: volume-schedulinga42c7715-ebd0-11e8-8067-000c299a5e15/pod-i-pv-prebound-w-provisioned
I1119 15:56:42.225305  127596 scheduler_binder.go:147] FindPodVolumes for pod "volume-schedulinga42c7715-ebd0-11e8-8067-000c299a5e15/pod-i-pv-prebound-w-provisioned", node "node-1"
I1119 15:56:42.225334  127596 scheduler_binder.go:458] PVC "volume-schedulinga42c7715-ebd0-11e8-8067-000c299a5e15/pvc-i-pv-prebound" is fully bound to PV "pv-i-prebound"
I1119 15:56:42.225340  127596 scheduler_binder.go:458] PVC "volume-schedulinga42c7715-ebd0-11e8-8067-000c299a5e15/pvc-canprovision" is fully bound to PV "pvc-a693d4b0-ebd0-11e8-8067-000c299a5e15"
I1119 15:56:42.225352  127596 scheduler_binder.go:529] PersistentVolume "pv-i-prebound", Node "node-1" matches for Pod "volume-schedulinga42c7715-ebd0-11e8-8067-000c299a5e15/pod-i-pv-prebound-w-provisioned"
I1119 15:56:42.225359  127596 scheduler_binder.go:529] PersistentVolume "pvc-a693d4b0-ebd0-11e8-8067-000c299a5e15", Node "node-1" matches for Pod "volume-schedulinga42c7715-ebd0-11e8-8067-000c299a5e15/pod-i-pv-prebound-w-provisioned"
I1119 15:56:42.225364  127596 scheduler_binder.go:532] All bound volumes for Pod "volume-schedulinga42c7715-ebd0-11e8-8067-000c299a5e15/pod-i-pv-prebound-w-provisioned" match with Node "node-1"
I1119 15:56:42.225405  127596 scheduler_binder.go:207] AssumePodVolumes for pod "volume-schedulinga42c7715-ebd0-11e8-8067-000c299a5e15/pod-i-pv-prebound-w-provisioned", node "node-1"
I1119 15:56:42.225428  127596 scheduler_binder.go:458] PVC "volume-schedulinga42c7715-ebd0-11e8-8067-000c299a5e15/pvc-i-pv-prebound" is fully bound to PV "pv-i-prebound"
I1119 15:56:42.225434  127596 scheduler_binder.go:458] PVC "volume-schedulinga42c7715-ebd0-11e8-8067-000c299a5e15/pvc-canprovision" is fully bound to PV "pvc-a693d4b0-ebd0-11e8-8067-000c299a5e15"
I1119 15:56:42.225439  127596 scheduler_binder.go:217] AssumePodVolumes for pod "volume-schedulinga42c7715-ebd0-11e8-8067-000c299a5e15/pod-i-pv-prebound-w-provisioned", node "node-1": all PVCs bound and nothing to do
E1119 15:56:42.225445  127596 scheduler.go:433] scheduler cache AssumePod failed: pod a6940066-ebd0-11e8-8067-000c299a5e15 is in the cache, so can't be assumed
E1119 15:56:42.225448  127596 factory.go:1465] Error scheduling volume-schedulinga42c7715-ebd0-11e8-8067-000c299a5e15/pod-i-pv-prebound-w-provisioned: pod a6940066-ebd0-11e8-8067-000c299a5e15 is in the cache, so can't be assumed; retrying
I1119 15:56:42.225461  127596 factory.go:1558] Updating pod condition for volume-schedulinga42c7715-ebd0-11e8-8067-000c299a5e15/pod-i-pv-prebound-w-provisioned to (PodScheduled==False)
E1119 15:56:42.225466  127596 scheduler.go:556] error assuming pod: pod a6940066-ebd0-11e8-8067-000c299a5e15 is in the cache, so can't be assumed
I1119 15:56:42.226787  127596 factory.go:1338] About to try and schedule pod volume-schedulinga42c7715-ebd0-11e8-8067-000c299a5e15/pod-i-pv-prebound-w-provisioned
I1119 15:56:42.226808  127596 scheduler.go:508] Attempting to schedule pod: volume-schedulinga42c7715-ebd0-11e8-8067-000c299a5e15/pod-i-pv-prebound-w-provisioned
I1119 15:56:42.226860  127596 scheduler_binder.go:147] FindPodVolumes for pod "volume-schedulinga42c7715-ebd0-11e8-8067-000c299a5e15/pod-i-pv-prebound-w-provisioned", node "node-1"
I1119 15:56:42.226889  127596 scheduler_binder.go:458] PVC "volume-schedulinga42c7715-ebd0-11e8-8067-000c299a5e15/pvc-i-pv-prebound" is fully bound to PV "pv-i-prebound"
I1119 15:56:42.226896  127596 scheduler_binder.go:458] PVC "volume-schedulinga42c7715-ebd0-11e8-8067-000c299a5e15/pvc-canprovision" is fully bound to PV "pvc-a693d4b0-ebd0-11e8-8067-000c299a5e15"
I1119 15:56:42.226908  127596 scheduler_binder.go:529] PersistentVolume "pv-i-prebound", Node "node-1" matches for Pod "volume-schedulinga42c7715-ebd0-11e8-8067-000c299a5e15/pod-i-pv-prebound-w-provisioned"
I1119 15:56:42.226913  127596 scheduler_binder.go:529] PersistentVolume "pvc-a693d4b0-ebd0-11e8-8067-000c299a5e15", Node "node-1" matches for Pod "volume-schedulinga42c7715-ebd0-11e8-8067-000c299a5e15/pod-i-pv-prebound-w-provisioned"
I1119 15:56:42.226917  127596 scheduler_binder.go:532] All bound volumes for Pod "volume-schedulinga42c7715-ebd0-11e8-8067-000c299a5e15/pod-i-pv-prebound-w-provisioned" match with Node "node-1"
I1119 15:56:42.226935  127596 scheduler_binder.go:207] AssumePodVolumes for pod "volume-schedulinga42c7715-ebd0-11e8-8067-000c299a5e15/pod-i-pv-prebound-w-provisioned", node "node-1"
I1119 15:56:42.226940  127596 scheduler_binder.go:458] PVC "volume-schedulinga42c7715-ebd0-11e8-8067-000c299a5e15/pvc-i-pv-prebound" is fully bound to PV "pv-i-prebound"
I1119 15:56:42.226944  127596 scheduler_binder.go:458] PVC "volume-schedulinga42c7715-ebd0-11e8-8067-000c299a5e15/pvc-canprovision" is fully bound to PV "pvc-a693d4b0-ebd0-11e8-8067-000c299a5e15"
I1119 15:56:42.226948  127596 scheduler_binder.go:217] AssumePodVolumes for pod "volume-schedulinga42c7715-ebd0-11e8-8067-000c299a5e15/pod-i-pv-prebound-w-provisioned", node "node-1": all PVCs bound and nothing to do
E1119 15:56:42.226954  127596 scheduler.go:433] scheduler cache AssumePod failed: pod a6940066-ebd0-11e8-8067-000c299a5e15 is in the cache, so can't be assumed
E1119 15:56:42.226957  127596 factory.go:1465] Error scheduling volume-schedulinga42c7715-ebd0-11e8-8067-000c299a5e15/pod-i-pv-prebound-w-provisioned: pod a6940066-ebd0-11e8-8067-000c299a5e15 is in the cache, so can't be assumed; retrying
I1119 15:56:42.226969  127596 factory.go:1558] Updating pod condition for volume-schedulinga42c7715-ebd0-11e8-8067-000c299a5e15/pod-i-pv-prebound-w-provisioned to (PodScheduled==False)
E1119 15:56:42.226980  127596 scheduler.go:556] error assuming pod: pod a6940066-ebd0-11e8-8067-000c299a5e15 is in the cache, so can't be assumed
I1119 15:56:42.227952  127596 factory.go:1338] About to try and schedule pod volume-schedulinga42c7715-ebd0-11e8-8067-000c299a5e15/pod-i-pv-prebound-w-provisioned
I1119 15:56:42.227973  127596 scheduler.go:508] Attempting to schedule pod: volume-schedulinga42c7715-ebd0-11e8-8067-000c299a5e15/pod-i-pv-prebound-w-provisioned
I1119 15:56:42.228022  127596 scheduler_binder.go:147] FindPodVolumes for pod "volume-schedulinga42c7715-ebd0-11e8-8067-000c299a5e15/pod-i-pv-prebound-w-provisioned", node "node-1"
I1119 15:56:42.228036  127596 scheduler_binder.go:458] PVC "volume-schedulinga42c7715-ebd0-11e8-8067-000c299a5e15/pvc-i-pv-prebound" is fully bound to PV "pv-i-prebound"
I1119 15:56:42.228041  127596 scheduler_binder.go:458] PVC "volume-schedulinga42c7715-ebd0-11e8-8067-000c299a5e15/pvc-canprovision" is fully bound to PV "pvc-a693d4b0-ebd0-11e8-8067-000c299a5e15"
I1119 15:56:42.228053  127596 scheduler_binder.go:529] PersistentVolume "pv-i-prebound", Node "node-1" matches for Pod "volume-schedulinga42c7715-ebd0-11e8-8067-000c299a5e15/pod-i-pv-prebound-w-provisioned"
I1119 15:56:42.228060  127596 scheduler_binder.go:529] PersistentVolume "pvc-a693d4b0-ebd0-11e8-8067-000c299a5e15", Node "node-1" matches for Pod "volume-schedulinga42c7715-ebd0-11e8-8067-000c299a5e15/pod-i-pv-prebound-w-provisioned"
I1119 15:56:42.228064  127596 scheduler_binder.go:532] All bound volumes for Pod "volume-schedulinga42c7715-ebd0-11e8-8067-000c299a5e15/pod-i-pv-prebound-w-provisioned" match with Node "node-1"
I1119 15:56:42.228096  127596 scheduler_binder.go:207] AssumePodVolumes for pod "volume-schedulinga42c7715-ebd0-11e8-8067-000c299a5e15/pod-i-pv-prebound-w-provisioned", node "node-1"
I1119 15:56:42.228103  127596 scheduler_binder.go:458] PVC "volume-schedulinga42c7715-ebd0-11e8-8067-000c299a5e15/pvc-i-pv-prebound" is fully bound to PV "pv-i-prebound"
I1119 15:56:42.228107  127596 scheduler_binder.go:458] PVC "volume-schedulinga42c7715-ebd0-11e8-8067-000c299a5e15/pvc-canprovision" is fully bound to PV "pvc-a693d4b0-ebd0-11e8-8067-000c299a5e15"
I1119 15:56:42.228112  127596 scheduler_binder.go:217] AssumePodVolumes for pod "volume-schedulinga42c7715-ebd0-11e8-8067-000c299a5e15/pod-i-pv-prebound-w-provisioned", node "node-1": all PVCs bound and nothing to do
E1119 15:56:42.228117  127596 scheduler.go:433] scheduler cache AssumePod failed: pod a6940066-ebd0-11e8-8067-000c299a5e15 is in the cache, so can't be assumed
E1119 15:56:42.228121  127596 factory.go:1465] Error scheduling volume-schedulinga42c7715-ebd0-11e8-8067-000c299a5e15/pod-i-pv-prebound-w-provisioned: pod a6940066-ebd0-11e8-8067-000c299a5e15 is in the cache, so can't be assumed; retrying
I1119 15:56:42.228148  127596 factory.go:1558] Updating pod condition for volume-schedulinga42c7715-ebd0-11e8-8067-000c299a5e15/pod-i-pv-prebound-w-provisioned to (PodScheduled==False)
E1119 15:56:42.228156  127596 scheduler.go:556] error assuming pod: pod a6940066-ebd0-11e8-8067-000c299a5e15 is in the cache, so can't be assumed
I1119 15:56:42.229084  127596 factory.go:1338] About to try and schedule pod volume-schedulinga42c7715-ebd0-11e8-8067-000c299a5e15/pod-i-pv-prebound-w-provisioned
I1119 15:56:42.229105  127596 scheduler.go:508] Attempting to schedule pod: volume-schedulinga42c7715-ebd0-11e8-8067-000c299a5e15/pod-i-pv-prebound-w-provisioned
I1119 15:56:42.229156  127596 scheduler_binder.go:147] FindPodVolumes for pod "volume-schedulinga42c7715-ebd0-11e8-8067-000c299a5e15/pod-i-pv-prebound-w-provisioned", node "node-1"
I1119 15:56:42.229171  127596 scheduler_binder.go:458] PVC "volume-schedulinga42c7715-ebd0-11e8-8067-000c299a5e15/pvc-i-pv-prebound" is fully bound to PV "pv-i-prebound"
I1119 15:56:42.229178  127596 scheduler_binder.go:458] PVC "volume-schedulinga42c7715-ebd0-11e8-8067-000c299a5e15/pvc-canprovision" is fully bound to PV "pvc-a693d4b0-ebd0-11e8-8067-000c299a5e15"
I1119 15:56:42.229191  127596 scheduler_binder.go:529] PersistentVolume "pv-i-prebound", Node "node-1" matches for Pod "volume-schedulinga42c7715-ebd0-11e8-8067-000c299a5e15/pod-i-pv-prebound-w-provisioned"
I1119 15:56:42.229195  127596 scheduler_binder.go:529] PersistentVolume "pvc-a693d4b0-ebd0-11e8-8067-000c299a5e15", Node "node-1" matches for Pod "volume-schedulinga42c7715-ebd0-11e8-8067-000c299a5e15/pod-i-pv-prebound-w-provisioned"
I1119 15:56:42.229200  127596 scheduler_binder.go:532] All bound volumes for Pod "volume-schedulinga42c7715-ebd0-11e8-8067-000c299a5e15/pod-i-pv-prebound-w-provisioned" match with Node "node-1"
I1119 15:56:42.229233  127596 scheduler_binder.go:207] AssumePodVolumes for pod "volume-schedulinga42c7715-ebd0-11e8-8067-000c299a5e15/pod-i-pv-prebound-w-provisioned", node "node-1"
I1119 15:56:42.229242  127596 scheduler_binder.go:458] PVC "volume-schedulinga42c7715-ebd0-11e8-8067-000c299a5e15/pvc-i-pv-prebound" is fully bound to PV "pv-i-prebound"
I1119 15:56:42.229246  127596 scheduler_binder.go:458] PVC "volume-schedulinga42c7715-ebd0-11e8-8067-000c299a5e15/pvc-canprovision" is fully bound to PV "pvc-a693d4b0-ebd0-11e8-8067-000c299a5e15"
I1119 15:56:42.229251  127596 scheduler_binder.go:217] AssumePodVolumes for pod "volume-schedulinga42c7715-ebd0-11e8-8067-000c299a5e15/pod-i-pv-prebound-w-provisioned", node "node-1": all PVCs bound and nothing to do
E1119 15:56:42.229256  127596 scheduler.go:433] scheduler cache AssumePod failed: pod a6940066-ebd0-11e8-8067-000c299a5e15 is in the cache, so can't be assumed
E1119 15:56:42.229260  127596 factory.go:1465] Error scheduling volume-schedulinga42c7715-ebd0-11e8-8067-000c299a5e15/pod-i-pv-prebound-w-provisioned: pod a6940066-ebd0-11e8-8067-000c299a5e15 is in the cache, so can't be assumed; retrying
I1119 15:56:42.229287  127596 factory.go:1558] Updating pod condition for volume-schedulinga42c7715-ebd0-11e8-8067-000c299a5e15/pod-i-pv-prebound-w-provisioned to (PodScheduled==False)
E1119 15:56:42.229294  127596 scheduler.go:556] error assuming pod: pod a6940066-ebd0-11e8-8067-000c299a5e15 is in the cache, so can't be assumed
I1119 15:56:42.230432  127596 factory.go:1338] About to try and schedule pod volume-schedulinga42c7715-ebd0-11e8-8067-000c299a5e15/pod-i-pv-prebound-w-provisioned
I1119 15:56:42.230453  127596 scheduler.go:508] Attempting to schedule pod: volume-schedulinga42c7715-ebd0-11e8-8067-000c299a5e15/pod-i-pv-prebound-w-provisioned
I1119 15:56:42.230536  127596 scheduler_binder.go:147] FindPodVolumes for pod "volume-schedulinga42c7715-ebd0-11e8-8067-000c299a5e15/pod-i-pv-prebound-w-provisioned", node "node-1"
I1119 15:56:42.230564  127596 scheduler_binder.go:458] PVC "volume-schedulinga42c7715-ebd0-11e8-8067-000c299a5e15/pvc-i-pv-prebound" is fully bound to PV "pv-i-prebound"
I1119 15:56:42.230571  127596 scheduler_binder.go:458] PVC "volume-schedulinga42c7715-ebd0-11e8-8067-000c299a5e15/pvc-canprovision" is fully bound to PV "pvc-a693d4b0-ebd0-11e8-8067-000c299a5e15"
I1119 15:56:42.230584  127596 scheduler_binder.go:529] PersistentVolume "pv-i-prebound", Node "node-1" matches for Pod "volume-schedulinga42c7715-ebd0-11e8-8067-000c299a5e15/pod-i-pv-prebound-w-provisioned"
I1119 15:56:42.230588  127596 scheduler_binder.go:529] PersistentVolume "pvc-a693d4b0-ebd0-11e8-8067-000c299a5e15", Node "node-1" matches for Pod "volume-schedulinga42c7715-ebd0-11e8-8067-000c299a5e15/pod-i-pv-prebound-w-provisioned"
I1119 15:56:42.230593  127596 scheduler_binder.go:532] All bound volumes for Pod "volume-schedulinga42c7715-ebd0-11e8-8067-000c299a5e15/pod-i-pv-prebound-w-provisioned" match with Node "node-1"
I1119 15:56:42.230647  127596 scheduler_binder.go:207] AssumePodVolumes for pod "volume-schedulinga42c7715-ebd0-11e8-8067-000c299a5e15/pod-i-pv-prebound-w-provisioned", node "node-1"
I1119 15:56:42.230657  127596 scheduler_binder.go:458] PVC "volume-schedulinga42c7715-ebd0-11e8-8067-000c299a5e15/pvc-i-pv-prebound" is fully bound to PV "pv-i-prebound"
I1119 15:56:42.230661  127596 scheduler_binder.go:458] PVC "volume-schedulinga42c7715-ebd0-11e8-8067-000c299a5e15/pvc-canprovision" is fully bound to PV "pvc-a693d4b0-ebd0-11e8-8067-000c299a5e15"
I1119 15:56:42.230665  127596 scheduler_binder.go:217] AssumePodVolumes for pod "volume-schedulinga42c7715-ebd0-11e8-8067-000c299a5e15/pod-i-pv-prebound-w-provisioned", node "node-1": all PVCs bound and nothing to do
E1119 15:56:42.230673  127596 scheduler.go:433] scheduler cache AssumePod failed: pod a6940066-ebd0-11e8-8067-000c299a5e15 is in the cache, so can't be assumed
E1119 15:56:42.230677  127596 factory.go:1465] Error scheduling volume-schedulinga42c7715-ebd0-11e8-8067-000c299a5e15/pod-i-pv-prebound-w-provisioned: pod a6940066-ebd0-11e8-8067-000c299a5e15 is in the cache, so can't be assumed; retrying
I1119 15:56:42.230704  127596 factory.go:1558] Updating pod condition for volume-schedulinga42c7715-ebd0-11e8-8067-000c299a5e15/pod-i-pv-prebound-w-provisioned to (PodScheduled==False)
E1119 15:56:42.230710  127596 scheduler.go:556] error assuming pod: pod a6940066-ebd0-11e8-8067-000c299a5e15 is in the cache, so can't be assumed
I1119 15:56:42.231680  127596 factory.go:1338] About to try and schedule pod volume-schedulinga42c7715-ebd0-11e8-8067-000c299a5e15/pod-i-pv-prebound-w-provisioned
I1119 15:56:42.231700  127596 scheduler.go:508] Attempting to schedule pod: volume-schedulinga42c7715-ebd0-11e8-8067-000c299a5e15/pod-i-pv-prebound-w-provisioned
I1119 15:56:42.231749  127596 scheduler_binder.go:147] FindPodVolumes for pod "volume-schedulinga42c7715-ebd0-11e8-8067-000c299a5e15/pod-i-pv-prebound-w-provisioned", node "node-1"
I1119 15:56:42.231778  127596 scheduler_binder.go:458] PVC "volume-schedulinga42c7715-ebd0-11e8-8067-000c299a5e15/pvc-i-pv-prebound" is fully bound to PV "pv-i-prebound"
I1119 15:56:42.231784  127596 scheduler_binder.go:458] PVC "volume-schedulinga42c7715-ebd0-11e8-8067-000c299a5e15/pvc-canprovision" is fully bound to PV "pvc-a693d4b0-ebd0-11e8-8067-000c299a5e15"
I1119 15:56:42.231797  127596 scheduler_binder.go:529] PersistentVolume "pv-i-prebound", Node "node-1" matches for Pod "volume-schedulinga42c7715-ebd0-11e8-8067-000c299a5e15/pod-i-pv-prebound-w-provisioned"
I1119 15:56:42.231801  127596 scheduler_binder.go:529] PersistentVolume "pvc-a693d4b0-ebd0-11e8-8067-000c299a5e15", Node "node-1" matches for Pod "volume-schedulinga42c7715-ebd0-11e8-8067-000c299a5e15/pod-i-pv-prebound-w-provisioned"
I1119 15:56:42.231805  127596 scheduler_binder.go:532] All bound volumes for Pod "volume-schedulinga42c7715-ebd0-11e8-8067-000c299a5e15/pod-i-pv-prebound-w-provisioned" match with Node "node-1"
I1119 15:56:42.231822  127596 scheduler_binder.go:207] AssumePodVolumes for pod "volume-schedulinga42c7715-ebd0-11e8-8067-000c299a5e15/pod-i-pv-prebound-w-provisioned", node "node-1"
I1119 15:56:42.231828  127596 scheduler_binder.go:458] PVC "volume-schedulinga42c7715-ebd0-11e8-8067-000c299a5e15/pvc-i-pv-prebound" is fully bound to PV "pv-i-prebound"
I1119 15:56:42.231832  127596 scheduler_binder.go:458] PVC "volume-schedulinga42c7715-ebd0-11e8-8067-000c299a5e15/pvc-canprovision" is fully bound to PV "pvc-a693d4b0-ebd0-11e8-8067-000c299a5e15"
I1119 15:56:42.231836  127596 scheduler_binder.go:217] AssumePodVolumes for pod "volume-schedulinga42c7715-ebd0-11e8-8067-000c299a5e15/pod-i-pv-prebound-w-provisioned", node "node-1": all PVCs bound and nothing to do
E1119 15:56:42.231842  127596 scheduler.go:433] scheduler cache AssumePod failed: pod a6940066-ebd0-11e8-8067-000c299a5e15 is in the cache, so can't be assumed
E1119 15:56:42.231846  127596 factory.go:1465] Error scheduling volume-schedulinga42c7715-ebd0-11e8-8067-000c299a5e15/pod-i-pv-prebound-w-provisioned: pod a6940066-ebd0-11e8-8067-000c299a5e15 is in the cache, so can't be assumed; retrying
I1119 15:56:42.231857  127596 factory.go:1558] Updating pod condition for volume-schedulinga42c7715-ebd0-11e8-8067-000c299a5e15/pod-i-pv-prebound-w-provisioned to (PodScheduled==False)
E1119 15:56:42.231862  127596 scheduler.go:556] error assuming pod: pod a6940066-ebd0-11e8-8067-000c299a5e15 is in the cache, so can't be assumed
I1119 15:56:42.232814  127596 factory.go:1338] About to try and schedule pod volume-schedulinga42c7715-ebd0-11e8-8067-000c299a5e15/pod-i-pv-prebound-w-provisioned
I1119 15:56:42.232837  127596 scheduler.go:508] Attempting to schedule pod: volume-schedulinga42c7715-ebd0-11e8-8067-000c299a5e15/pod-i-pv-prebound-w-provisioned
I1119 15:56:42.232870  127596 scheduler_binder.go:147] FindPodVolumes for pod "volume-schedulinga42c7715-ebd0-11e8-8067-000c299a5e15/pod-i-pv-prebound-w-provisioned", node "node-1"
I1119 15:56:42.232882  127596 scheduler_binder.go:458] PVC "volume-schedulinga42c7715-ebd0-11e8-8067-000c299a5e15/pvc-i-pv-prebound" is fully bound to PV "pv-i-prebound"
I1119 15:56:42.232886  127596 scheduler_binder.go:458] PVC "volume-schedulinga42c7715-ebd0-11e8-8067-000c299a5e15/pvc-canprovision" is fully bound to PV "pvc-a693d4b0-ebd0-11e8-8067-000c299a5e15"
I1119 15:56:42.232898  127596 scheduler_binder.go:529] PersistentVolume "pv-i-prebound", Node "node-1" matches for Pod "volume-schedulinga42c7715-ebd0-11e8-8067-000c299a5e15/pod-i-pv-prebound-w-provisioned"
I1119 15:56:42.232902  127596 scheduler_binder.go:529] PersistentVolume "pvc-a693d4b0-ebd0-11e8-8067-000c299a5e15", Node "node-1" matches for Pod "volume-schedulinga42c7715-ebd0-11e8-8067-000c299a5e15/pod-i-pv-prebound-w-provisioned"
I1119 15:56:42.232907  127596 scheduler_binder.go:532] All bound volumes for Pod "volume-schedulinga42c7715-ebd0-11e8-8067-000c299a5e15/pod-i-pv-prebound-w-provisioned" match with Node "node-1"
I1119 15:56:42.232921  127596 scheduler_binder.go:207] AssumePodVolumes for pod "volume-schedulinga42c7715-ebd0-11e8-8067-000c299a5e15/pod-i-pv-prebound-w-provisioned", node "node-1"
I1119 15:56:42.232925  127596 scheduler_binder.go:458] PVC "volume-schedulinga42c7715-ebd0-11e8-8067-000c299a5e15/pvc-i-pv-prebound" is fully bound to PV "pv-i-prebound"
I1119 15:56:42.232929  127596 scheduler_binder.go:458] PVC "volume-schedulinga42c7715-ebd0-11e8-8067-000c299a5e15/pvc-canprovision" is fully bound to PV "pvc-a693d4b0-ebd0-11e8-8067-000c299a5e15"
I1119 15:56:42.232936  127596 scheduler_binder.go:217] AssumePodVolumes for pod "volume-schedulinga42c7715-ebd0-11e8-8067-000c299a5e15/pod-i-pv-prebound-w-provisioned", node "node-1": all PVCs bound and nothing to do
E1119 15:56:42.232941  127596 scheduler.go:433] scheduler cache AssumePod failed: pod a6940066-ebd0-11e8-8067-000c299a5e15 is in the cache, so can't be assumed
E1119 15:56:42.232945  127596 factory.go:1465] Error scheduling volume-schedulinga42c7715-ebd0-11e8-8067-000c299a5e15/pod-i-pv-prebound-w-provisioned: pod a6940066-ebd0-11e8-8067-000c299a5e15 is in the cache, so can't be assumed; retrying
I1119 15:56:42.232955  127596 factory.go:1558] Updating pod condition for volume-schedulinga42c7715-ebd0-11e8-8067-000c299a5e15/pod-i-pv-prebound-w-provisioned to (PodScheduled==False)
E1119 15:56:42.232960  127596 scheduler.go:556] error assuming pod: pod a6940066-ebd0-11e8-8067-000c299a5e15 is in the cache, so can't be assumed
I1119 15:56:42.233906  127596 factory.go:1338] About to try and schedule pod volume-schedulinga42c7715-ebd0-11e8-8067-000c299a5e15/pod-i-pv-prebound-w-provisioned
I1119 15:56:42.233928  127596 scheduler.go:508] Attempting to schedule pod: volume-schedulinga42c7715-ebd0-11e8-8067-000c299a5e15/pod-i-pv-prebound-w-provisioned
I1119 15:56:42.233977  127596 scheduler_binder.go:147] FindPodVolumes for pod "volume-schedulinga42c7715-ebd0-11e8-8067-000c299a5e15/pod-i-pv-prebound-w-provisioned", node "node-1"
I1119 15:56:42.233991  127596 scheduler_binder.go:458] PVC "volume-schedulinga42c7715-ebd0-11e8-8067-000c299a5e15/pvc-i-pv-prebound" is fully bound to PV "pv-i-prebound"
I1119 15:56:42.233995  127596 scheduler_binder.go:458] PVC "volume-schedulinga42c7715-ebd0-11e8-8067-000c299a5e15/pvc-canprovision" is fully bound to PV "pvc-a693d4b0-ebd0-11e8-8067-000c299a5e15"
I1119 15:56:42.234008  127596 scheduler_binder.go:529] PersistentVolume "pv-i-prebound", Node "node-1" matches for Pod "volume-schedulinga42c7715-ebd0-11e8-8067-000c299a5e15/pod-i-pv-prebound-w-provisioned"
I1119 15:56:42.234013  127596 scheduler_binder.go:529] PersistentVolume "pvc-a693d4b0-ebd0-11e8-8067-000c299a5e15", Node "node-1" matches for Pod "volume-schedulinga42c7715-ebd0-11e8-8067-000c299a5e15/pod-i-pv-prebound-w-provisioned"
I1119 15:56:42.234017  127596 scheduler_binder.go:532] All bound volumes for Pod "volume-schedulinga42c7715-ebd0-11e8-8067-000c299a5e15/pod-i-pv-prebound-w-provisioned" match with Node "node-1"
I1119 15:56:42.234048  127596 scheduler_binder.go:207] AssumePodVolumes for pod "volume-schedulinga42c7715-ebd0-11e8-8067-000c299a5e15/pod-i-pv-prebound-w-provisioned", node "node-1"
I1119 15:56:42.234057  127596 scheduler_binder.go:458] PVC "volume-schedulinga42c7715-ebd0-11e8-8067-000c299a5e15/pvc-i-pv-prebound" is fully bound to PV "pv-i-prebound"
I1119 15:56:42.234062  127596 scheduler_binder.go:458] PVC "volume-schedulinga42c7715-ebd0-11e8-8067-000c299a5e15/pvc-canprovision" is fully bound to PV "pvc-a693d4b0-ebd0-11e8-8067-000c299a5e15"
I1119 15:56:42.234066  127596 scheduler_binder.go:217] AssumePodVolumes for pod "volume-schedulinga42c7715-ebd0-11e8-8067-000c299a5e15/pod-i-pv-prebound-w-provisioned", node "node-1": all PVCs bound and nothing to do
E1119 15:56:42.234072  127596 scheduler.go:433] scheduler cache AssumePod failed: pod a6940066-ebd0-11e8-8067-000c299a5e15 is in the cache, so can't be assumed
E1119 15:56:42.234076  127596 factory.go:1465] Error scheduling volume-schedulinga42c7715-ebd0-11e8-8067-000c299a5e15/pod-i-pv-prebound-w-provisioned: pod a6940066-ebd0-11e8-8067-000c299a5e15 is in the cache, so can't be assumed; retrying
I1119 15:56:42.234102  127596 factory.go:1558] Updating pod condition for volume-schedulinga42c7715-ebd0-11e8-8067-000c299a5e15/pod-i-pv-prebound-w-provisioned to (PodScheduled==False)
E1119 15:56:42.234124  127596 scheduler.go:556] error assuming pod: pod a6940066-ebd0-11e8-8067-000c299a5e15 is in the cache, so can't be assumed
I1119 15:56:42.235126  127596 factory.go:1338] About to try and schedule pod volume-schedulinga42c7715-ebd0-11e8-8067-000c299a5e15/pod-i-pv-prebound-w-provisioned
I1119 15:56:42.235147  127596 scheduler.go:508] Attempting to schedule pod: volume-schedulinga42c7715-ebd0-11e8-8067-000c299a5e15/pod-i-pv-prebound-w-provisioned
I1119 15:56:42.235233  127596 scheduler_binder.go:147] FindPodVolumes for pod "volume-schedulinga42c7715-ebd0-11e8-8067-000c299a5e15/pod-i-pv-prebound-w-provisioned", node "node-1"
I1119 15:56:42.235264  127596 scheduler_binder.go:458] PVC "volume-schedulinga42c7715-ebd0-11e8-8067-000c299a5e15/pvc-i-pv-prebound" is fully bound to PV "pv-i-prebound"
I1119 15:56:42.235271  127596 scheduler_binder.go:458] PVC "volume-schedulinga42c7715-ebd0-11e8-8067-000c299a5e15/pvc-canprovision" is fully bound to PV "pvc-a693d4b0-ebd0-11e8-8067-000c299a5e15"
I1119 15:56:42.235284  127596 scheduler_binder.go:529] PersistentVolume "pv-i-prebound", Node "node-1" matches for Pod "volume-schedulinga42c7715-ebd0-11e8-8067-000c299a5e15/pod-i-pv-prebound-w-provisioned"
I1119 15:56:42.235289  127596 scheduler_binder.go:529] PersistentVolume "pvc-a693d4b0-ebd0-11e8-8067-000c299a5e15", Node "node-1" matches for Pod "volume-schedulinga42c7715-ebd0-11e8-8067-000c299a5e15/pod-i-pv-prebound-w-provisioned"
I1119 15:56:42.235327  127596 scheduler_binder.go:532] All bound volumes for Pod "volume-schedulinga42c7715-ebd0-11e8-8067-000c299a5e15/pod-i-pv-prebound-w-provisioned" match with Node "node-1"
I1119 15:56:42.235365  127596 scheduler_binder.go:207] AssumePodVolumes for pod "volume-schedulinga42c7715-ebd0-11e8-8067-000c299a5e15/pod-i-pv-prebound-w-provisioned", node "node-1"
I1119 15:56:42.235373  127596 scheduler_binder.go:458] PVC "volume-schedulinga42c7715-ebd0-11e8-8067-000c299a5e15/pvc-i-pv-prebound" is fully bound to PV "pv-i-prebound"
I1119 15:56:42.235377  127596 scheduler_binder.go:458] PVC "volume-schedulinga42c7715-ebd0-11e8-8067-000c299a5e15/pvc-canprovision" is fully bound to PV "pvc-a693d4b0-ebd0-11e8-8067-000c299a5e15"
I1119 15:56:42.235382  127596 scheduler_binder.go:217] AssumePodVolumes for pod "volume-schedulinga42c7715-ebd0-11e8-8067-000c299a5e15/pod-i-pv-prebound-w-provisioned", node "node-1": all PVCs bound and nothing to do
E1119 15:56:42.235387  127596 scheduler.go:433] scheduler cache AssumePod failed: pod a6940066-ebd0-11e8-8067-000c299a5e15 is in the cache, so can't be assumed
E1119 15:56:42.235391  127596 factory.go:1465] Error scheduling volume-schedulinga42c7715-ebd0-11e8-8067-000c299a5e15/pod-i-pv-prebound-w-provisioned: pod a6940066-ebd0-11e8-8067-000c299a5e15 is in the cache, so can't be assumed; retrying
I1119 15:56:42.235419  127596 factory.go:1558] Updating pod condition for volume-schedulinga42c7715-ebd0-11e8-8067-000c299a5e15/pod-i-pv-prebound-w-provisioned to (PodScheduled==False)
E1119 15:56:42.235426  127596 scheduler.go:556] error assuming pod: pod a6940066-ebd0-11e8-8067-000c299a5e15 is in the cache, so can't be assumed
I1119 15:56:42.236356  127596 factory.go:1338] About to try and schedule pod volume-schedulinga42c7715-ebd0-11e8-8067-000c299a5e15/pod-i-pv-prebound-w-provisioned
I1119 15:56:42.236377  127596 scheduler.go:508] Attempting to schedule pod: volume-schedulinga42c7715-ebd0-11e8-8067-000c299a5e15/pod-i-pv-prebound-w-provisioned
I1119 15:56:42.236459  127596 scheduler_binder.go:147] FindPodVolumes for pod "volume-schedulinga42c7715-ebd0-11e8-8067-000c299a5e15/pod-i-pv-prebound-w-provisioned", node "node-1"
I1119 15:56:42.236487  127596 scheduler_binder.go:458] PVC "volume-schedulinga42c7715-ebd0-11e8-8067-000c299a5e15/pvc-i-pv-prebound" is fully bound to PV "pv-i-prebound"
I1119 15:56:42.236494  127596 scheduler_binder.go:458] PVC "volume-schedulinga42c7715-ebd0-11e8-8067-000c299a5e15/pvc-canprovision" is fully bound to PV "pvc-a693d4b0-ebd0-11e8-8067-000c299a5e15"
I1119 15:56:42.236506  127596 scheduler_binder.go:529] PersistentVolume "pv-i-prebound", Node "node-1" matches for Pod "volume-schedulinga42c7715-ebd0-11e8-8067-000c299a5e15/pod-i-pv-prebound-w-provisioned"
I1119 15:56:42.236511  127596 scheduler_binder.go:529] PersistentVolume "pvc-a693d4b0-ebd0-11e8-8067-000c299a5e15", Node "node-1" matches for Pod "volume-schedulinga42c7715-ebd0-11e8-8067-000c299a5e15/pod-i-pv-prebound-w-provisioned"
I1119 15:56:42.236516  127596 scheduler_binder.go:532] All bound volumes for Pod "volume-schedulinga42c7715-ebd0-11e8-8067-000c299a5e15/pod-i-pv-prebound-w-provisioned" match with Node "node-1"
I1119 15:56:42.236578  127596 scheduler_binder.go:207] AssumePodVolumes for pod "volume-schedulinga42c7715-ebd0-11e8-8067-000c299a5e15/pod-i-pv-prebound-w-provisioned", node "node-1"
I1119 15:56:42.236588  127596 scheduler_binder.go:458] PVC "volume-schedulinga42c7715-ebd0-11e8-8067-000c299a5e15/pvc-i-pv-prebound" is fully bound to PV "pv-i-prebound"
I1119 15:56:42.236592  127596 scheduler_binder.go:458] PVC "volume-schedulinga42c7715-ebd0-11e8-8067-000c299a5e15/pvc-canprovision" is fully bound to PV "pvc-a693d4b0-ebd0-11e8-8067-000c299a5e15"
I1119 15:56:42.236597  127596 scheduler_binder.go:217] AssumePodVolumes for pod "volume-schedulinga42c7715-ebd0-11e8-8067-000c299a5e15/pod-i-pv-prebound-w-provisioned", node "node-1": all PVCs bound and nothing to do
E1119 15:56:42.236602  127596 scheduler.go:433] scheduler cache AssumePod failed: pod a6940066-ebd0-11e8-8067-000c299a5e15 is in the cache, so can't be assumed
E1119 15:56:42.236606  127596 factory.go:1465] Error scheduling volume-schedulinga42c7715-ebd0-11e8-8067-000c299a5e15/pod-i-pv-prebound-w-provisioned: pod a6940066-ebd0-11e8-8067-000c299a5e15 is in the cache, so can't be assumed; retrying
I1119 15:56:42.236617  127596 factory.go:1558] Updating pod condition for volume-schedulinga42c7715-ebd0-11e8-8067-000c299a5e15/pod-i-pv-prebound-w-provisioned to (PodScheduled==False)
E1119 15:56:42.236622  127596 scheduler.go:556] error assuming pod: pod a6940066-ebd0-11e8-8067-000c299a5e15 is in the cache, so can't be assumed
I1119 15:56:42.237761  127596 factory.go:1338] About to try and schedule pod volume-schedulinga42c7715-ebd0-11e8-8067-000c299a5e15/pod-i-pv-prebound-w-provisioned
I1119 15:56:42.237791  127596 scheduler.go:508] Attempting to schedule pod: volume-schedulinga42c7715-ebd0-11e8-8067-000c299a5e15/pod-i-pv-prebound-w-provisioned
I1119 15:56:42.237855  127596 scheduler_binder.go:147] FindPodVolumes for pod "volume-schedulinga42c7715-ebd0-11e8-8067-000c299a5e15/pod-i-pv-prebound-w-provisioned", node "node-1"
I1119 15:56:42.237889  127596 scheduler_binder.go:458] PVC "volume-schedulinga42c7715-ebd0-11e8-8067-000c299a5e15/pvc-i-pv-prebound" is fully bound to PV "pv-i-prebound"
I1119 15:56:42.237896  127596 scheduler_binder.go:458] PVC "volume-schedulinga42c7715-ebd0-11e8-8067-000c299a5e15/pvc-canprovision" is fully bound to PV "pvc-a693d4b0-ebd0-11e8-8067-000c299a5e15"
I1119 15:56:42.237913  127596 scheduler_binder.go:529] PersistentVolume "pv-i-prebound", Node "node-1" matches for Pod "volume-schedulinga42c7715-ebd0-11e8-8067-000c299a5e15/pod-i-pv-prebound-w-provisioned"
I1119 15:56:42.237917  127596 scheduler_binder.go:529] PersistentVolume "pvc-a693d4b0-ebd0-11e8-8067-000c299a5e15", Node "node-1" matches for Pod "volume-schedulinga42c7715-ebd0-11e8-8067-000c299a5e15/pod-i-pv-prebound-w-provisioned"
I1119 15:56:42.237922  127596 scheduler_binder.go:532] All bound volumes for Pod "volume-schedulinga42c7715-ebd0-11e8-8067-000c299a5e15/pod-i-pv-prebound-w-provisioned" match with Node "node-1"
I1119 15:56:42.237958  127596 scheduler_binder.go:207] AssumePodVolumes for pod "volume-schedulinga42c7715-ebd0-11e8-8067-000c299a5e15/pod-i-pv-prebound-w-provisioned", node "node-1"
I1119 15:56:42.237980  127596 scheduler_binder.go:458] PVC "volume-schedulinga42c7715-ebd0-11e8-8067-000c299a5e15/pvc-i-pv-prebound" is fully bound to PV "pv-i-prebound"
I1119 15:56:42.237986  127596 scheduler_binder.go:458] PVC "volume-schedulinga42c7715-ebd0-11e8-8067-000c299a5e15/pvc-canprovision" is fully bound to PV "pvc-a693d4b0-ebd0-11e8-8067-000c299a5e15"
I1119 15:56:42.237991  127596 scheduler_binder.go:217] AssumePodVolumes for pod "volume-schedulinga42c7715-ebd0-11e8-8067-000c299a5e15/pod-i-pv-prebound-w-provisioned", node "node-1": all PVCs bound and nothing to do
E1119 15:56:42.237998  127596 scheduler.go:433] scheduler cache AssumePod failed: pod a6940066-ebd0-11e8-8067-000c299a5e15 is in the cache, so can't be assumed
E1119 15:56:42.238003  127596 factory.go:1465] Error scheduling volume-schedulinga42c7715-ebd0-11e8-8067-000c299a5e15/pod-i-pv-prebound-w-provisioned: pod a6940066-ebd0-11e8-8067-000c299a5e15 is in the cache, so can't be assumed; retrying
I1119 15:56:42.238033  127596 factory.go:1558] Updating pod condition for volume-schedulinga42c7715-ebd0-11e8-8067-000c299a5e15/pod-i-pv-prebound-w-provisioned to (PodScheduled==False)
E1119 15:56:42.238041  127596 scheduler.go:556] error assuming pod: pod a6940066-ebd0-11e8-8067-000c299a5e15 is in the cache, so can't be assumed
I1119 15:56:42.239302  127596 factory.go:1338] About to try and schedule pod volume-schedulinga42c7715-ebd0-11e8-8067-000c299a5e15/pod-i-pv-prebound-w-provisioned
I1119 15:56:42.239324  127596 scheduler.go:508] Attempting to schedule pod: volume-schedulinga42c7715-ebd0-11e8-8067-000c299a5e15/pod-i-pv-prebound-w-provisioned
I1119 15:56:42.239376  127596 scheduler_binder.go:147] FindPodVolumes for pod "volume-schedulinga42c7715-ebd0-11e8-8067-000c299a5e15/pod-i-pv-prebound-w-provisioned", node "node-1"
I1119 15:56:42.239391  127596 scheduler_binder.go:458] PVC "volume-schedulinga42c7715-ebd0-11e8-8067-000c299a5e15/pvc-i-pv-prebound" is fully bound to PV "pv-i-prebound"
I1119 15:56:42.239396  127596 scheduler_binder.go:458] PVC "volume-schedulinga42c7715-ebd0-11e8-8067-000c299a5e15/pvc-canprovision" is fully bound to PV "pvc-a693d4b0-ebd0-11e8-8067-000c299a5e15"
I1119 15:56:42.239410  127596 scheduler_binder.go:529] PersistentVolume "pv-i-prebound", Node "node-1" matches for Pod "volume-schedulinga42c7715-ebd0-11e8-8067-000c299a5e15/pod-i-pv-prebound-w-provisioned"
I1119 15:56:42.239416  127596 scheduler_binder.go:529] PersistentVolume "pvc-a693d4b0-ebd0-11e8-8067-000c299a5e15", Node "node-1" matches for Pod "volume-schedulinga42c7715-ebd0-11e8-8067-000c299a5e15/pod-i-pv-prebound-w-provisioned"
I1119 15:56:42.239421  127596 scheduler_binder.go:532] All bound volumes for Pod "volume-schedulinga42c7715-ebd0-11e8-8067-000c299a5e15/pod-i-pv-prebound-w-provisioned" match with Node "node-1"
I1119 15:56:42.239453  127596 scheduler_binder.go:207] AssumePodVolumes for pod "volume-schedulinga42c7715-ebd0-11e8-8067-000c299a5e15/pod-i-pv-prebound-w-provisioned", node "node-1"
I1119 15:56:42.239461  127596 scheduler_binder.go:458] PVC "volume-schedulinga42c7715-ebd0-11e8-8067-000c299a5e15/pvc-i-pv-prebound" is fully bound to PV "pv-i-prebound"
I1119 15:56:42.239465  127596 scheduler_binder.go:458] PVC "volume-schedulinga42c7715-ebd0-11e8-8067-000c299a5e15/pvc-canprovision" is fully bound to PV "pvc-a693d4b0-ebd0-11e8-8067-000c299a5e15"
I1119 15:56:42.239470  127596 scheduler_binder.go:217] AssumePodVolumes for pod "volume-schedulinga42c7715-ebd0-11e8-8067-000c299a5e15/pod-i-pv-prebound-w-provisioned", node "node-1": all PVCs bound and nothing to do
E1119 15:56:42.239476  127596 scheduler.go:433] scheduler cache AssumePod failed: pod a6940066-ebd0-11e8-8067-000c299a5e15 is in the cache, so can't be assumed
E1119 15:56:42.239479  127596 factory.go:1465] Error scheduling volume-schedulinga42c7715-ebd0-11e8-8067-000c299a5e15/pod-i-pv-prebound-w-provisioned: pod a6940066-ebd0-11e8-8067-000c299a5e15 is in the cache, so can't be assumed; retrying
I1119 15:56:42.239513  127596 factory.go:1558] Updating pod condition for volume-schedulinga42c7715-ebd0-11e8-8067-000c299a5e15/pod-i-pv-prebound-w-provisioned to (PodScheduled==False)
E1119 15:56:42.239539  127596 scheduler.go:556] error assuming pod: pod a6940066-ebd0-11e8-8067-000c299a5e15 is in the cache, so can't be assumed
I1119 15:56:42.240573  127596 factory.go:1338] About to try and schedule pod volume-schedulinga42c7715-ebd0-11e8-8067-000c299a5e15/pod-i-pv-prebound-w-provisioned
I1119 15:56:42.240596  127596 scheduler.go:508] Attempting to schedule pod: volume-schedulinga42c7715-ebd0-11e8-8067-000c299a5e15/pod-i-pv-prebound-w-provisioned
I1119 15:56:42.240650  127596 scheduler_binder.go:147] FindPodVolumes for pod "volume-schedulinga42c7715-ebd0-11e8-8067-000c299a5e15/pod-i-pv-prebound-w-provisioned", node "node-1"
I1119 15:56:42.240680  127596 scheduler_binder.go:458] PVC "volume-schedulinga42c7715-ebd0-11e8-8067-000c299a5e15/pvc-i-pv-prebound" is fully bound to PV "pv-i-prebound"
I1119 15:56:42.240687  127596 scheduler_binder.go:458] PVC "volume-schedulinga42c7715-ebd0-11e8-8067-000c299a5e15/pvc-canprovision" is fully bound to PV "pvc-a693d4b0-ebd0-11e8-8067-000c299a5e15"
I1119 15:56:42.240703  127596 scheduler_binder.go:529] PersistentVolume "pv-i-prebound", Node "node-1" matches for Pod "volume-schedulinga42c7715-ebd0-11e8-8067-000c299a5e15/pod-i-pv-prebound-w-provisioned"
I1119 15:56:42.240711  127596 scheduler_binder.go:529] PersistentVolume "pvc-a693d4b0-ebd0-11e8-8067-000c299a5e15", Node "node-1" matches for Pod "volume-schedulinga42c7715-ebd0-11e8-8067-000c299a5e15/pod-i-pv-prebound-w-provisioned"
I1119 15:56:42.240718  127596 scheduler_binder.go:532] All bound volumes for Pod "volume-schedulinga42c7715-ebd0-11e8-8067-000c299a5e15/pod-i-pv-prebound-w-provisioned" match with Node "node-1"
I1119 15:56:42.240756  127596 scheduler_binder.go:207] AssumePodVolumes for pod "volume-schedulinga42c7715-ebd0-11e8-8067-000c299a5e15/pod-i-pv-prebound-w-provisioned", node "node-1"
I1119 15:56:42.240778  127596 scheduler_binder.go:458] PVC "volume-schedulinga42c7715-ebd0-11e8-8067-000c299a5e15/pvc-i-pv-prebound" is fully bound to PV "pv-i-prebound"
I1119 15:56:42.240787  127596 scheduler_binder.go:458] PVC "volume-schedulinga42c7715-ebd0-11e8-8067-000c299a5e15/pvc-canprovision" is fully bound to PV "pvc-a693d4b0-ebd0-11e8-8067-000c299a5e15"
I1119 15:56:42.240795  127596 scheduler_binder.go:217] AssumePodVolumes for pod "volume-schedulinga42c7715-ebd0-11e8-8067-000c299a5e15/pod-i-pv-prebound-w-provisioned", node "node-1": all PVCs bound and nothing to do
E1119 15:56:42.240804  127596 scheduler.go:433] scheduler cache AssumePod failed: pod a6940066-ebd0-11e8-8067-000c299a5e15 is in the cache, so can't be assumed
E1119 15:56:42.240810  127596 factory.go:1465] Error scheduling volume-schedulinga42c7715-ebd0-11e8-8067-000c299a5e15/pod-i-pv-prebound-w-provisioned: pod a6940066-ebd0-11e8-8067-000c299a5e15 is in the cache, so can't be assumed; retrying
I1119 15:56:42.240846  127596 factory.go:1558] Updating pod condition for volume-schedulinga42c7715-ebd0-11e8-8067-000c299a5e15/pod-i-pv-prebound-w-provisioned to (PodScheduled==False)
E1119 15:56:42.240855  127596 scheduler.go:556] error assuming pod: pod a6940066-ebd0-11e8-8067-000c299a5e15 is in the cache, so can't be assumed
I1119 15:56:42.241971  127596 factory.go:1338] About to try and schedule pod volume-schedulinga42c7715-ebd0-11e8-8067-000c299a5e15/pod-i-pv-prebound-w-provisioned
I1119 15:56:42.241996  127596 scheduler.go:508] Attempting to schedule pod: volume-schedulinga42c7715-ebd0-11e8-8067-000c299a5e15/pod-i-pv-prebound-w-provisioned
I1119 15:56:42.242081  127596 scheduler_binder.go:147] FindPodVolumes for pod "volume-schedulinga42c7715-ebd0-11e8-8067-000c299a5e15/pod-i-pv-prebound-w-provisioned", node "node-1"
I1119 15:56:42.242109  127596 scheduler_binder.go:458] PVC "volume-schedulinga42c7715-ebd0-11e8-8067-000c299a5e15/pvc-i-pv-prebound" is fully bound to PV "pv-i-prebound"
I1119 15:56:42.242116  127596 scheduler_binder.go:458] PVC "volume-schedulinga42c7715-ebd0-11e8-8067-000c299a5e15/pvc-canprovision" is fully bound to PV "pvc-a693d4b0-ebd0-11e8-8067-000c299a5e15"
I1119 15:56:42.242129  127596 scheduler_binder.go:529] PersistentVolume "pv-i-prebound", Node "node-1" matches for Pod "volume-schedulinga42c7715-ebd0-11e8-8067-000c299a5e15/pod-i-pv-prebound-w-provisioned"
I1119 15:56:42.242133  127596 scheduler_binder.go:529] PersistentVolume "pvc-a693d4b0-ebd0-11e8-8067-000c299a5e15", Node "node-1" matches for Pod "volume-schedulinga42c7715-ebd0-11e8-8067-000c299a5e15/pod-i-pv-prebound-w-provisioned"
I1119 15:56:42.242138  127596 scheduler_binder.go:532] All bound volumes for Pod "volume-schedulinga42c7715-ebd0-11e8-8067-000c299a5e15/pod-i-pv-prebound-w-provisioned" match with Node "node-1"
I1119 15:56:42.242206  127596 scheduler_binder.go:207] AssumePodVolumes for pod "volume-schedulinga42c7715-ebd0-11e8-8067-000c299a5e15/pod-i-pv-prebound-w-provisioned", node "node-1"
I1119 15:56:42.242215  127596 scheduler_binder.go:458] PVC "volume-schedulinga42c7715-ebd0-11e8-8067-000c299a5e15/pvc-i-pv-prebound" is fully bound to PV "pv-i-prebound"
I1119 15:56:42.242220  127596 scheduler_binder.go:458] PVC "volume-schedulinga42c7715-ebd0-11e8-8067-000c299a5e15/pvc-canprovision" is fully bound to PV "pvc-a693d4b0-ebd0-11e8-8067-000c299a5e15"
I1119 15:56:42.242224  127596 scheduler_binder.go:217] AssumePodVolumes for pod "volume-schedulinga42c7715-ebd0-11e8-8067-000c299a5e15/pod-i-pv-prebound-w-provisioned", node "node-1": all PVCs bound and nothing to do
E1119 15:56:42.242230  127596 scheduler.go:433] scheduler cache AssumePod failed: pod a6940066-ebd0-11e8-8067-000c299a5e15 is in the cache, so can't be assumed
E1119 15:56:42.242234  127596 factory.go:1465] Error scheduling volume-schedulinga42c7715-ebd0-11e8-8067-000c299a5e15/pod-i-pv-prebound-w-provisioned: pod a6940066-ebd0-11e8-8067-000c299a5e15 is in the cache, so can't be assumed; retrying
I1119 15:56:42.242263  127596 factory.go:1558] Updating pod condition for volume-schedulinga42c7715-ebd0-11e8-8067-000c299a5e15/pod-i-pv-prebound-w-provisioned to (PodScheduled==False)
E1119 15:56:42.242270  127596 scheduler.go:556] error assuming pod: pod a6940066-ebd0-11e8-8067-000c299a5e15 is in the cache, so can't be assumed
I1119 15:56:42.243342  127596 factory.go:1338] About to try and schedule pod volume-schedulinga42c7715-ebd0-11e8-8067-000c299a5e15/pod-i-pv-prebound-w-provisioned
I1119 15:56:42.243364  127596 scheduler.go:508] Attempting to schedule pod: volume-schedulinga42c7715-ebd0-11e8-8067-000c299a5e15/pod-i-pv-prebound-w-provisioned
I1119 15:56:42.243415  127596 scheduler_binder.go:147] FindPodVolumes for pod "volume-schedulinga42c7715-ebd0-11e8-8067-000c299a5e15/pod-i-pv-prebound-w-provisioned", node "node-1"
I1119 15:56:42.243429  127596 scheduler_binder.go:458] PVC "volume-schedulinga42c7715-ebd0-11e8-8067-000c299a5e15/pvc-i-pv-prebound" is fully bound to PV "pv-i-prebound"
I1119 15:56:42.243434  127596 scheduler_binder.go:458] PVC "volume-schedulinga42c7715-ebd0-11e8-8067-000c299a5e15/pvc-canprovision" is fully bound to PV "pvc-a693d4b0-ebd0-11e8-8067-000c299a5e15"
I1119 15:56:42.243447  127596 scheduler_binder.go:529] PersistentVolume "pv-i-prebound", Node "node-1" matches for Pod "volume-schedulinga42c7715-ebd0-11e8-8067-000c299a5e15/pod-i-pv-prebound-w-provisioned"
I1119 15:56:42.243452  127596 scheduler_binder.go:529] PersistentVolume "pvc-a693d4b0-ebd0-11e8-8067-000c299a5e15", Node "node-1" matches for Pod "volume-schedulinga42c7715-ebd0-11e8-8067-000c299a5e15/pod-i-pv-prebound-w-provisioned"
I1119 15:56:42.243456  127596 scheduler_binder.go:532] All bound volumes for Pod "volume-schedulinga42c7715-ebd0-11e8-8067-000c299a5e15/pod-i-pv-prebound-w-provisioned" match with Node "node-1"
I1119 15:56:42.243489  127596 scheduler_binder.go:207] AssumePodVolumes for pod "volume-schedulinga42c7715-ebd0-11e8-8067-000c299a5e15/pod-i-pv-prebound-w-provisioned", node "node-1"
I1119 15:56:42.243496  127596 scheduler_binder.go:458] PVC "volume-schedulinga42c7715-ebd0-11e8-8067-000c299a5e15/pvc-i-pv-prebound" is fully bound to PV "pv-i-prebound"
I1119 15:56:42.243501  127596 scheduler_binder.go:458] PVC "volume-schedulinga42c7715-ebd0-11e8-8067-000c299a5e15/pvc-canprovision" is fully bound to PV "pvc-a693d4b0-ebd0-11e8-8067-000c299a5e15"
I1119 15:56:42.243505  127596 scheduler_binder.go:217] AssumePodVolumes for pod "volume-schedulinga42c7715-ebd0-11e8-8067-000c299a5e15/pod-i-pv-prebound-w-provisioned", node "node-1": all PVCs bound and nothing to do
E1119 15:56:42.243511  127596 scheduler.go:433] scheduler cache AssumePod failed: pod a6940066-ebd0-11e8-8067-000c299a5e15 is in the cache, so can't be assumed
E1119 15:56:42.243515  127596 factory.go:1465] Error scheduling volume-schedulinga42c7715-ebd0-11e8-8067-000c299a5e15/pod-i-pv-prebound-w-provisioned: pod a6940066-ebd0-11e8-8067-000c299a5e15 is in the cache, so can't be assumed; retrying
I1119 15:56:42.243542  127596 factory.go:1558] Updating pod condition for volume-schedulinga42c7715-ebd0-11e8-8067-000c299a5e15/pod-i-pv-prebound-w-provisioned to (PodScheduled==False)
E1119 15:56:42.243560  127596 scheduler.go:556] error assuming pod: pod a6940066-ebd0-11e8-8067-000c299a5e15 is in the cache, so can't be assumed
I1119 15:56:42.244617  127596 factory.go:1338] About to try and schedule pod volume-schedulinga42c7715-ebd0-11e8-8067-000c299a5e15/pod-i-pv-prebound-w-provisioned
I1119 15:56:42.244640  127596 scheduler.go:508] Attempting to schedule pod: volume-schedulinga42c7715-ebd0-11e8-8067-000c299a5e15/pod-i-pv-prebound-w-provisioned
I1119 15:56:42.244698  127596 scheduler_binder.go:147] FindPodVolumes for pod "volume-schedulinga42c7715-ebd0-11e8-8067-000c299a5e15/pod-i-pv-prebound-w-provisioned", node "node-1"
I1119 15:56:42.244716  127596 scheduler_binder.go:458] PVC "volume-schedulinga42c7715-ebd0-11e8-8067-000c299a5e15/pvc-i-pv-prebound" is fully bound to PV "pv-i-prebound"
I1119 15:56:42.244723  127596 scheduler_binder.go:458] PVC "volume-schedulinga42c7715-ebd0-11e8-8067-000c299a5e15/pvc-canprovision" is fully bound to PV "pvc-a693d4b0-ebd0-11e8-8067-000c299a5e15"
I1119 15:56:42.244736  127596 scheduler_binder.go:529] PersistentVolume "pv-i-prebound", Node "node-1" matches for Pod "volume-schedulinga42c7715-ebd0-11e8-8067-000c299a5e15/pod-i-pv-prebound-w-provisioned"
I1119 15:56:42.244743  127596 scheduler_binder.go:529] PersistentVolume "pvc-a693d4b0-ebd0-11e8-8067-000c299a5e15", Node "node-1" matches for Pod "volume-schedulinga42c7715-ebd0-11e8-8067-000c299a5e15/pod-i-pv-prebound-w-provisioned"
I1119 15:56:42.244747  127596 scheduler_binder.go:532] All bound volumes for Pod "volume-schedulinga42c7715-ebd0-11e8-8067-000c299a5e15/pod-i-pv-prebound-w-provisioned" match with Node "node-1"
I1119 15:56:42.244788  127596 scheduler_binder.go:207] AssumePodVolumes for pod "volume-schedulinga42c7715-ebd0-11e8-8067-000c299a5e15/pod-i-pv-prebound-w-provisioned", node "node-1"
I1119 15:56:42.244818  127596 scheduler_binder.go:458] PVC "volume-schedulinga42c7715-ebd0-11e8-8067-000c299a5e15/pvc-i-pv-prebound" is fully bound to PV "pv-i-prebound"
I1119 15:56:42.244825  127596 scheduler_binder.go:458] PVC "volume-schedulinga42c7715-ebd0-11e8-8067-000c299a5e15/pvc-canprovision" is fully bound to PV "pvc-a693d4b0-ebd0-11e8-8067-000c299a5e15"
I1119 15:56:42.244830  127596 scheduler_binder.go:217] AssumePodVolumes for pod "volume-schedulinga42c7715-ebd0-11e8-8067-000c299a5e15/pod-i-pv-prebound-w-provisioned", node "node-1": all PVCs bound and nothing to do
E1119 15:56:42.244836  127596 scheduler.go:433] scheduler cache AssumePod failed: pod a6940066-ebd0-11e8-8067-000c299a5e15 is in the cache, so can't be assumed
E1119 15:56:42.244840  127596 factory.go:1465] Error scheduling volume-schedulinga42c7715-ebd0-11e8-8067-000c299a5e15/pod-i-pv-prebound-w-provisioned: pod a6940066-ebd0-11e8-8067-000c299a5e15 is in the cache, so can't be assumed; retrying
I1119 15:56:42.244875  127596 factory.go:1558] Updating pod condition for volume-schedulinga42c7715-ebd0-11e8-8067-000c299a5e15/pod-i-pv-prebound-w-provisioned to (PodScheduled==False)
E1119 15:56:42.244901  127596 scheduler.go:556] error assuming pod: pod a6940066-ebd0-11e8-8067-000c299a5e15 is in the cache, so can't be assumed
I1119 15:56:42.245878  127596 factory.go:1338] About to try and schedule pod volume-schedulinga42c7715-ebd0-11e8-8067-000c299a5e15/pod-i-pv-prebound-w-provisioned
I1119 15:56:42.245902  127596 scheduler.go:508] Attempting to schedule pod: volume-schedulinga42c7715-ebd0-11e8-8067-000c299a5e15/pod-i-pv-prebound-w-provisioned
I1119 15:56:42.245935  127596 scheduler_binder.go:147] FindPodVolumes for pod "volume-schedulinga42c7715-ebd0-11e8-8067-000c299a5e15/pod-i-pv-prebound-w-provisioned", node "node-1"
I1119 15:56:42.245950  127596 scheduler_binder.go:458] PVC "volume-schedulinga42c7715-ebd0-11e8-8067-000c299a5e15/pvc-i-pv-prebound" is fully bound to PV "pv-i-prebound"
I1119 15:56:42.245954  127596 scheduler_binder.go:458] PVC "volume-schedulinga42c7715-ebd0-11e8-8067-000c299a5e15/pvc-canprovision" is fully bound to PV "pvc-a693d4b0-ebd0-11e8-8067-000c299a5e15"
I1119 15:56:42.245966  127596 scheduler_binder.go:529] PersistentVolume "pv-i-prebound", Node "node-1" matches for Pod "volume-schedulinga42c7715-ebd0-11e8-8067-000c299a5e15/pod-i-pv-prebound-w-provisioned"
I1119 15:56:42.245971  127596 scheduler_binder.go:529] PersistentVolume "pvc-a693d4b0-ebd0-11e8-8067-000c299a5e15", Node "node-1" matches for Pod "volume-schedulinga42c7715-ebd0-11e8-8067-000c299a5e15/pod-i-pv-prebound-w-provisioned"
I1119 15:56:42.245975  127596 scheduler_binder.go:532] All bound volumes for Pod "volume-schedulinga42c7715-ebd0-11e8-8067-000c299a5e15/pod-i-pv-prebound-w-provisioned" match with Node "node-1"
I1119 15:56:42.245991  127596 scheduler_binder.go:207] AssumePodVolumes for pod "volume-schedulinga42c7715-ebd0-11e8-8067-000c299a5e15/pod-i-pv-prebound-w-provisioned", node "node-1"
I1119 15:56:42.245999  127596 scheduler_binder.go:458] PVC "volume-schedulinga42c7715-ebd0-11e8-8067-000c299a5e15/pvc-i-pv-prebound" is fully bound to PV "pv-i-prebound"
I1119 15:56:42.246006  127596 scheduler_binder.go:458] PVC "volume-schedulinga42c7715-ebd0-11e8-8067-000c299a5e15/pvc-canprovision" is fully bound to PV "pvc-a693d4b0-ebd0-11e8-8067-000c299a5e15"
I1119 15:56:42.246014  127596 scheduler_binder.go:217] AssumePodVolumes for pod "volume-schedulinga42c7715-ebd0-11e8-8067-000c299a5e15/pod-i-pv-prebound-w-provisioned", node "node-1": all PVCs bound and nothing to do
E1119 15:56:42.246021  127596 scheduler.go:433] scheduler cache AssumePod failed: pod a6940066-ebd0-11e8-8067-000c299a5e15 is in the cache, so can't be assumed
E1119 15:56:42.246027  127596 factory.go:1465] Error scheduling volume-schedulinga42c7715-ebd0-11e8-8067-000c299a5e15/pod-i-pv-prebound-w-provisioned: pod a6940066-ebd0-11e8-8067-000c299a5e15 is in the cache, so can't be assumed; retrying
I1119 15:56:42.246043  127596 factory.go:1558] Updating pod condition for volume-schedulinga42c7715-ebd0-11e8-8067-000c299a5e15/pod-i-pv-prebound-w-provisioned to (PodScheduled==False)
E1119 15:56:42.246049  127596 scheduler.go:556] error assuming pod: pod a6940066-ebd0-11e8-8067-000c299a5e15 is in the cache, so can't be assumed
I1119 15:56:42.247559  127596 factory.go:1338] About to try and schedule pod volume-schedulinga42c7715-ebd0-11e8-8067-000c299a5e15/pod-i-pv-prebound-w-provisioned
I1119 15:56:42.247581  127596 scheduler.go:508] Attempting to schedule pod: volume-schedulinga42c7715-ebd0-11e8-8067-000c299a5e15/pod-i-pv-prebound-w-provisioned
I1119 15:56:42.247665  127596 scheduler_binder.go:147] FindPodVolumes for pod "volume-schedulinga42c7715-ebd0-11e8-8067-000c299a5e15/pod-i-pv-prebound-w-provisioned", node "node-1"
I1119 15:56:42.247700  127596 scheduler_binder.go:458] PVC "volume-schedulinga42c7715-ebd0-11e8-8067-000c299a5e15/pvc-i-pv-prebound" is fully bound to PV "pv-i-prebound"
I1119 15:56:42.247710  127596 scheduler_binder.go:458] PVC "volume-schedulinga42c7715-ebd0-11e8-8067-000c299a5e15/pvc-canprovision" is fully bound to PV "pvc-a693d4b0-ebd0-11e8-8067-000c299a5e15"
I1119 15:56:42.247727  127596 scheduler_binder.go:529] PersistentVolume "pv-i-prebound", Node "node-1" matches for Pod "volume-schedulinga42c7715-ebd0-11e8-8067-000c299a5e15/pod-i-pv-prebound-w-provisioned"
I1119 15:56:42.247773  127596 scheduler_binder.go:529] PersistentVolume "pvc-a693d4b0-ebd0-11e8-8067-000c299a5e15", Node "node-1" matches for Pod "volume-schedulinga42c7715-ebd0-11e8-8067-000c299a5e15/pod-i-pv-prebound-w-provisioned"
I1119 15:56:42.247800  127596 scheduler_binder.go:532] All bound volumes for Pod "volume-schedulinga42c7715-ebd0-11e8-8067-000c299a5e15/pod-i-pv-prebound-w-provisioned" match with Node "node-1"
I1119 15:56:42.247836  127596 scheduler_binder.go:207] AssumePodVolumes for pod "volume-schedulinga42c7715-ebd0-11e8-8067-000c299a5e15/pod-i-pv-prebound-w-provisioned", node "node-1"
I1119 15:56:42.247889  127596 scheduler_binder.go:458] PVC "volume-schedulinga42c7715-ebd0-11e8-8067-000c299a5e15/pvc-i-pv-prebound" is fully bound to PV "pv-i-prebound"
I1119 15:56:42.247898  127596 scheduler_binder.go:458] PVC "volume-schedulinga42c7715-ebd0-11e8-8067-000c299a5e15/pvc-canprovision" is fully bound to PV "pvc-a693d4b0-ebd0-11e8-8067-000c299a5e15"
I1119 15:56:42.247906  127596 scheduler_binder.go:217] AssumePodVolumes for pod "volume-schedulinga42c7715-ebd0-11e8-8067-000c299a5e15/pod-i-pv-prebound-w-provisioned", node "node-1": all PVCs bound and nothing to do
E1119 15:56:42.247915  127596 scheduler.go:433] scheduler cache AssumePod failed: pod a6940066-ebd0-11e8-8067-000c299a5e15 is in the cache, so can't be assumed
E1119 15:56:42.247920  127596 factory.go:1465] Error scheduling volume-schedulinga42c7715-ebd0-11e8-8067-000c299a5e15/pod-i-pv-prebound-w-provisioned: pod a6940066-ebd0-11e8-8067-000c299a5e15 is in the cache, so can't be assumed; retrying
I1119 15:56:42.247986  127596 factory.go:1558] Updating pod condition for volume-schedulinga42c7715-ebd0-11e8-8067-000c299a5e15/pod-i-pv-prebound-w-provisioned to (PodScheduled==False)
E1119 15:56:42.248010  127596 scheduler.go:556] error assuming pod: pod a6940066-ebd0-11e8-8067-000c299a5e15 is in the cache, so can't be assumed
I1119 15:56:42.249105  127596 factory.go:1338] About to try and schedule pod volume-schedulinga42c7715-ebd0-11e8-8067-000c299a5e15/pod-i-pv-prebound-w-provisioned
I1119 15:56:42.249127  127596 scheduler.go:508] Attempting to schedule pod: volume-schedulinga42c7715-ebd0-11e8-8067-000c299a5e15/pod-i-pv-prebound-w-provisioned
I1119 15:56:42.249213  127596 scheduler_binder.go:147] FindPodVolumes for pod "volume-schedulinga42c7715-ebd0-11e8-8067-000c299a5e15/pod-i-pv-prebound-w-provisioned", node "node-1"
I1119 15:56:42.249242  127596 scheduler_binder.go:458] PVC "volume-schedulinga42c7715-ebd0-11e8-8067-000c299a5e15/pvc-i-pv-prebound" is fully bound to PV "pv-i-prebound"
I1119 15:56:42.249249  127596 scheduler_binder.go:458] PVC "volume-schedulinga42c7715-ebd0-11e8-8067-000c299a5e15/pvc-canprovision" is fully bound to PV "pvc-a693d4b0-ebd0-11e8-8067-000c299a5e15"
I1119 15:56:42.249262  127596 scheduler_binder.go:529] PersistentVolume "pv-i-prebound", Node "node-1" matches for Pod "volume-schedulinga42c7715-ebd0-11e8-8067-000c299a5e15/pod-i-pv-prebound-w-provisioned"
I1119 15:56:42.249267  127596 scheduler_binder.go:529] PersistentVolume "pvc-a693d4b0-ebd0-11e8-8067-000c299a5e15", Node "node-1" matches for Pod "volume-schedulinga42c7715-ebd0-11e8-8067-000c299a5e15/pod-i-pv-prebound-w-provisioned"
I1119 15:56:42.249271  127596 scheduler_binder.go:532] All bound volumes for Pod "volume-schedulinga42c7715-ebd0-11e8-8067-000c299a5e15/pod-i-pv-prebound-w-provisioned" match with Node "node-1"
I1119 15:56:42.249303  127596 scheduler_binder.go:207] AssumePodVolumes for pod "volume-schedulinga42c7715-ebd0-11e8-8067-000c299a5e15/pod-i-pv-prebound-w-provisioned", node "node-1"
I1119 15:56:42.249358  127596 scheduler_binder.go:458] PVC "volume-schedulinga42c7715-ebd0-11e8-8067-000c299a5e15/pvc-i-pv-prebound" is fully bound to PV "pv-i-prebound"
I1119 15:56:42.249365  127596 scheduler_binder.go:458] PVC "volume-schedulinga42c7715-ebd0-11e8-8067-000c299a5e15/pvc-canprovision" is fully bound to PV "pvc-a693d4b0-ebd0-11e8-8067-000c299a5e15"
I1119 15:56:42.249369  127596 scheduler_binder.go:217] AssumePodVolumes for pod "volume-schedulinga42c7715-ebd0-11e8-8067-000c299a5e15/pod-i-pv-prebound-w-provisioned", node "node-1": all PVCs bound and nothing to do
E1119 15:56:42.249376  127596 scheduler.go:433] scheduler cache AssumePod failed: pod a6940066-ebd0-11e8-8067-000c299a5e15 is in the cache, so can't be assumed
E1119 15:56:42.249380  127596 factory.go:1465] Error scheduling volume-schedulinga42c7715-ebd0-11e8-8067-000c299a5e15/pod-i-pv-prebound-w-provisioned: pod a6940066-ebd0-11e8-8067-000c299a5e15 is in the cache, so can't be assumed; retrying
I1119 15:56:42.249407  127596 factory.go:1558] Updating pod condition for volume-schedulinga42c7715-ebd0-11e8-8067-000c299a5e15/pod-i-pv-prebound-w-provisioned to (PodScheduled==False)
E1119 15:56:42.249460  127596 scheduler.go:556] error assuming pod: pod a6940066-ebd0-11e8-8067-000c299a5e15 is in the cache, so can't be assumed
I1119 15:56:42.250463  127596 factory.go:1338] About to try and schedule pod volume-schedulinga42c7715-ebd0-11e8-8067-000c299a5e15/pod-i-pv-prebound-w-provisioned
I1119 15:56:42.250486  127596 scheduler.go:508] Attempting to schedule pod: volume-schedulinga42c7715-ebd0-11e8-8067-000c299a5e15/pod-i-pv-prebound-w-provisioned
I1119 15:56:42.250540  127596 scheduler_binder.go:147] FindPodVolumes for pod "volume-schedulinga42c7715-ebd0-11e8-8067-000c299a5e15/pod-i-pv-prebound-w-provisioned", node "node-1"
I1119 15:56:42.250557  127596 scheduler_binder.go:458] PVC "volume-schedulinga42c7715-ebd0-11e8-8067-000c299a5e15/pvc-i-pv-prebound" is fully bound to PV "pv-i-prebound"
I1119 15:56:42.250562  127596 scheduler_binder.go:458] PVC "volume-schedulinga42c7715-ebd0-11e8-8067-000c299a5e15/pvc-canprovision" is fully bound to PV "pvc-a693d4b0-ebd0-11e8-8067-000c299a5e15"
I1119 15:56:42.250575  127596 scheduler_binder.go:529] PersistentVolume "pv-i-prebound", Node "node-1" matches for Pod "volume-schedulinga42c7715-ebd0-11e8-8067-000c299a5e15/pod-i-pv-prebound-w-provisioned"
I1119 15:56:42.250580  127596 scheduler_binder.go:529] PersistentVolume "pvc-a693d4b0-ebd0-11e8-8067-000c299a5e15", Node "node-1" matches for Pod "volume-schedulinga42c7715-ebd0-11e8-8067-000c299a5e15/pod-i-pv-prebound-w-provisioned"
I1119 15:56:42.250585  127596 scheduler_binder.go:532] All bound volumes for Pod "volume-schedulinga42c7715-ebd0-11e8-8067-000c299a5e15/pod-i-pv-prebound-w-provisioned" match with Node "node-1"
I1119 15:56:42.250616  127596 scheduler_binder.go:207] AssumePodVolumes for pod "volume-schedulinga42c7715-ebd0-11e8-8067-000c299a5e15/pod-i-pv-prebound-w-provisioned", node "node-1"
I1119 15:56:42.250637  127596 scheduler_binder.go:458] PVC "volume-schedulinga42c7715-ebd0-11e8-8067-000c299a5e15/pvc-i-pv-prebound" is fully bound to PV "pv-i-prebound"
I1119 15:56:42.250643  127596 scheduler_binder.go:458] PVC "volume-schedulinga42c7715-ebd0-11e8-8067-000c299a5e15/pvc-canprovision" is fully bound to PV "pvc-a693d4b0-ebd0-11e8-8067-000c299a5e15"
I1119 15:56:42.250647  127596 scheduler_binder.go:217] AssumePodVolumes for pod "volume-schedulinga42c7715-ebd0-11e8-8067-000c299a5e15/pod-i-pv-prebound-w-provisioned", node "node-1": all PVCs bound and nothing to do
E1119 15:56:42.250653  127596 scheduler.go:433] scheduler cache AssumePod failed: pod a6940066-ebd0-11e8-8067-000c299a5e15 is in the cache, so can't be assumed
E1119 15:56:42.250657  127596 factory.go:1465] Error scheduling volume-schedulinga42c7715-ebd0-11e8-8067-000c299a5e15/pod-i-pv-prebound-w-provisioned: pod a6940066-ebd0-11e8-8067-000c299a5e15 is in the cache, so can't be assumed; retrying
I1119 15:56:42.250685  127596 factory.go:1558] Updating pod condition for volume-schedulinga42c7715-ebd0-11e8-8067-000c299a5e15/pod-i-pv-prebound-w-provisioned to (PodScheduled==False)
E1119 15:56:42.250692  127596 scheduler.go:556] error assuming pod: pod a6940066-ebd0-11e8-8067-000c299a5e15 is in the cache, so can't be assumed
I1119 15:56:42.251828  127596 factory.go:1338] About to try and schedule pod volume-schedulinga42c7715-ebd0-11e8-8067-000c299a5e15/pod-i-pv-prebound-w-provisioned
I1119 15:56:42.251855  127596 scheduler.go:508] Attempting to schedule pod: volume-schedulinga42c7715-ebd0-11e8-8067-000c299a5e15/pod-i-pv-prebound-w-provisioned
I1119 15:56:42.251927  127596 scheduler_binder.go:147] FindPodVolumes for pod "volume-schedulinga42c7715-ebd0-11e8-8067-000c299a5e15/pod-i-pv-prebound-w-provisioned", node "node-1"
I1119 15:56:42.251962  127596 scheduler_binder.go:458] PVC "volume-schedulinga42c7715-ebd0-11e8-8067-000c299a5e15/pvc-i-pv-prebound" is fully bound to PV "pv-i-prebound"
I1119 15:56:42.251970  127596 scheduler_binder.go:458] PVC "volume-schedulinga42c7715-ebd0-11e8-8067-000c299a5e15/pvc-canprovision" is fully bound to PV "pvc-a693d4b0-ebd0-11e8-8067-000c299a5e15"
I1119 15:56:42.251986  127596 scheduler_binder.go:529] PersistentVolume "pv-i-prebound", Node "node-1" matches for Pod "volume-schedulinga42c7715-ebd0-11e8-8067-000c299a5e15/pod-i-pv-prebound-w-provisioned"
I1119 15:56:42.251991  127596 scheduler_binder.go:529] PersistentVolume "pvc-a693d4b0-ebd0-11e8-8067-000c299a5e15", Node "node-1" matches for Pod "volume-schedulinga42c7715-ebd0-11e8-8067-000c299a5e15/pod-i-pv-prebound-w-provisioned"
I1119 15:56:42.251999  127596 scheduler_binder.go:532] All bound volumes for Pod "volume-schedulinga42c7715-ebd0-11e8-8067-000c299a5e15/pod-i-pv-prebound-w-provisioned" match with Node "node-1"
I1119 15:56:42.252039  127596 scheduler_binder.go:207] AssumePodVolumes for pod "volume-schedulinga42c7715-ebd0-11e8-8067-000c299a5e15/pod-i-pv-prebound-w-provisioned", node "node-1"
I1119 15:56:42.252062  127596 scheduler_binder.go:458] PVC "volume-schedulinga42c7715-ebd0-11e8-8067-000c299a5e15/pvc-i-pv-prebound" is fully bound to PV "pv-i-prebound"
I1119 15:56:42.252068  127596 scheduler_binder.go:458] PVC "volume-schedulinga42c7715-ebd0-11e8-8067-000c299a5e15/pvc-canprovision" is fully bound to PV "pvc-a693d4b0-ebd0-11e8-8067-000c299a5e15"
I1119 15:56:42.252073  127596 scheduler_binder.go:217] AssumePodVolumes for pod "volume-schedulinga42c7715-ebd0-11e8-8067-000c299a5e15/pod-i-pv-prebound-w-provisioned", node "node-1": all PVCs bound and nothing to do
E1119 15:56:42.252080  127596 scheduler.go:433] scheduler cache AssumePod failed: pod a6940066-ebd0-11e8-8067-000c299a5e15 is in the cache, so can't be assumed
E1119 15:56:42.252085  127596 factory.go:1465] Error scheduling volume-schedulinga42c7715-ebd0-11e8-8067-000c299a5e15/pod-i-pv-prebound-w-provisioned: pod a6940066-ebd0-11e8-8067-000c299a5e15 is in the cache, so can't be assumed; retrying
I1119 15:56:42.252103  127596 factory.go:1558] Updating pod condition for volume-schedulinga42c7715-ebd0-11e8-8067-000c299a5e15/pod-i-pv-prebound-w-provisioned to (PodScheduled==False)
