I0125 15:54:27.518444   59701 feature_gate.go:226] feature gates: &{map[MountContainers:false APIResponseCompression:false DynamicAuditing:false RunAsGroup:false DebugContainers:false KubeletPodResources:false ServiceNodeExclusion:false ValidateProxyRedirects:false CSIDriverRegistry:false VolumeSubpathEnvExpansion:false ProcMountType:false RuntimeClass:false TTLAfterFinished:false HyperVContainer:false CustomResourceWebhookConversion:false BoundServiceAccountTokenVolume:false CSIBlockVolume:false CustomCPUCFSQuotaPeriod:false VolumeSnapshotDataSource:false ExperimentalCriticalPodAnnotation:false CSINodeInfo:false AllAlpha:false Initializers:false BalanceAttachedNodeVolumes:false SCTPSupport:false ExpandInUsePersistentVolumes:false QOSReserved:false ResourceLimitsPriorityFunction:false]}
I0125 15:54:27.518519   59701 flags.go:33] FLAG: --address="0.0.0.0"
I0125 15:54:27.518525   59701 flags.go:33] FLAG: --algorithm-provider=""
I0125 15:54:27.518527   59701 flags.go:33] FLAG: --alsologtostderr="false"
I0125 15:54:27.518531   59701 flags.go:33] FLAG: --application-metrics-count-limit="100"
I0125 15:54:27.518534   59701 flags.go:33] FLAG: --authentication-kubeconfig=""
I0125 15:54:27.518536   59701 flags.go:33] FLAG: --authentication-skip-lookup="false"
I0125 15:54:27.518539   59701 flags.go:33] FLAG: --authentication-token-webhook-cache-ttl="10s"
I0125 15:54:27.518542   59701 flags.go:33] FLAG: --authentication-tolerate-lookup-failure="true"
I0125 15:54:27.518544   59701 flags.go:33] FLAG: --authorization-always-allow-paths="[/healthz]"
I0125 15:54:27.518549   59701 flags.go:33] FLAG: --authorization-kubeconfig=""
I0125 15:54:27.518551   59701 flags.go:33] FLAG: --authorization-webhook-cache-authorized-ttl="10s"
I0125 15:54:27.518554   59701 flags.go:33] FLAG: --authorization-webhook-cache-unauthorized-ttl="10s"
I0125 15:54:27.518556   59701 flags.go:33] FLAG: --azure-container-registry-config=""
I0125 15:54:27.518558   59701 flags.go:33] FLAG: --bind-address="0.0.0.0"
I0125 15:54:27.518561   59701 flags.go:33] FLAG: --boot-id-file="/proc/sys/kernel/random/boot_id"
I0125 15:54:27.518563   59701 flags.go:33] FLAG: --cert-dir=""
I0125 15:54:27.518565   59701 flags.go:33] FLAG: --client-ca-file=""
I0125 15:54:27.518567   59701 flags.go:33] FLAG: --cloud-provider-gce-lb-src-cidrs="130.211.0.0/22,209.85.152.0/22,209.85.204.0/22,35.191.0.0/16"
I0125 15:54:27.518571   59701 flags.go:33] FLAG: --config=""
I0125 15:54:27.518574   59701 flags.go:33] FLAG: --container-hints="/etc/cadvisor/container_hints.json"
I0125 15:54:27.518576   59701 flags.go:33] FLAG: --containerd="unix:///var/run/containerd.sock"
I0125 15:54:27.518579   59701 flags.go:33] FLAG: --contention-profiling="false"
I0125 15:54:27.518581   59701 flags.go:33] FLAG: --default-not-ready-toleration-seconds="300"
I0125 15:54:27.518583   59701 flags.go:33] FLAG: --default-unreachable-toleration-seconds="300"
I0125 15:54:27.518585   59701 flags.go:33] FLAG: --docker="unix:///var/run/docker.sock"
I0125 15:54:27.518588   59701 flags.go:33] FLAG: --docker-env-metadata-whitelist=""
I0125 15:54:27.518590   59701 flags.go:33] FLAG: --docker-only="false"
I0125 15:54:27.518592   59701 flags.go:33] FLAG: --docker-root="/var/lib/docker"
I0125 15:54:27.518594   59701 flags.go:33] FLAG: --docker-tls="false"
I0125 15:54:27.518596   59701 flags.go:33] FLAG: --docker-tls-ca="ca.pem"
I0125 15:54:27.518598   59701 flags.go:33] FLAG: --docker-tls-cert="cert.pem"
I0125 15:54:27.518600   59701 flags.go:33] FLAG: --docker-tls-key="key.pem"
I0125 15:54:27.518602   59701 flags.go:33] FLAG: --enable-load-reader="false"
I0125 15:54:27.518605   59701 flags.go:33] FLAG: --event-storage-age-limit="default=0"
I0125 15:54:27.518607   59701 flags.go:33] FLAG: --event-storage-event-limit="default=0"
I0125 15:54:27.518609   59701 flags.go:33] FLAG: --failure-domains="kubernetes.io/hostname,failure-domain.beta.kubernetes.io/zone,failure-domain.beta.kubernetes.io/region"
I0125 15:54:27.518613   59701 flags.go:33] FLAG: --feature-gates="APIResponseCompression=false,AllAlpha=false,BalanceAttachedNodeVolumes=false,BoundServiceAccountTokenVolume=false,CSIBlockVolume=false,CSIDriverRegistry=false,CSINodeInfo=false,CustomCPUCFSQuotaPeriod=false,CustomResourceWebhookConversion=false,DebugContainers=false,DynamicAuditing=false,ExpandInUsePersistentVolumes=false,ExperimentalCriticalPodAnnotation=false,HyperVContainer=false,Initializers=false,KubeletPodResources=false,MountContainers=false,ProcMountType=false,QOSReserved=false,ResourceLimitsPriorityFunction=false,RunAsGroup=false,RuntimeClass=false,SCTPSupport=false,ServiceNodeExclusion=false,TTLAfterFinished=false,ValidateProxyRedirects=false,VolumeSnapshotDataSource=false,VolumeSubpathEnvExpansion=false"
I0125 15:54:27.518643   59701 flags.go:33] FLAG: --global-housekeeping-interval="1m0s"
I0125 15:54:27.518647   59701 flags.go:33] FLAG: --hard-pod-affinity-symmetric-weight="1"
I0125 15:54:27.518650   59701 flags.go:33] FLAG: --help="false"
I0125 15:54:27.518653   59701 flags.go:33] FLAG: --housekeeping-interval="10s"
I0125 15:54:27.518655   59701 flags.go:33] FLAG: --http2-max-streams-per-connection="0"
I0125 15:54:27.518658   59701 flags.go:33] FLAG: --kube-api-burst="100"
I0125 15:54:27.518660   59701 flags.go:33] FLAG: --kube-api-content-type="application/vnd.kubernetes.protobuf"
I0125 15:54:27.518663   59701 flags.go:33] FLAG: --kube-api-qps="50"
I0125 15:54:27.518666   59701 flags.go:33] FLAG: --kubeconfig="/var/run/kubernetes/scheduler.kubeconfig"
I0125 15:54:27.518669   59701 flags.go:33] FLAG: --leader-elect="false"
I0125 15:54:27.518671   59701 flags.go:33] FLAG: --leader-elect-lease-duration="15s"
I0125 15:54:27.518673   59701 flags.go:33] FLAG: --leader-elect-renew-deadline="10s"
I0125 15:54:27.518675   59701 flags.go:33] FLAG: --leader-elect-resource-lock="endpoints"
I0125 15:54:27.518677   59701 flags.go:33] FLAG: --leader-elect-retry-period="2s"
I0125 15:54:27.518680   59701 flags.go:33] FLAG: --lock-object-name="kube-scheduler"
I0125 15:54:27.518682   59701 flags.go:33] FLAG: --lock-object-namespace="kube-system"
I0125 15:54:27.518684   59701 flags.go:33] FLAG: --log-backtrace-at=":0"
I0125 15:54:27.518687   59701 flags.go:33] FLAG: --log-cadvisor-usage="false"
I0125 15:54:27.518689   59701 flags.go:33] FLAG: --log-dir=""
I0125 15:54:27.518691   59701 flags.go:33] FLAG: --log-file=""
I0125 15:54:27.518693   59701 flags.go:33] FLAG: --log-flush-frequency="5s"
I0125 15:54:27.518695   59701 flags.go:33] FLAG: --logtostderr="true"
I0125 15:54:27.518697   59701 flags.go:33] FLAG: --machine-id-file="/etc/machine-id,/var/lib/dbus/machine-id"
I0125 15:54:27.518700   59701 flags.go:33] FLAG: --master="https://localhost:6443"
I0125 15:54:27.518702   59701 flags.go:33] FLAG: --mesos-agent="127.0.0.1:5051"
I0125 15:54:27.518705   59701 flags.go:33] FLAG: --mesos-agent-timeout="10s"
I0125 15:54:27.518707   59701 flags.go:33] FLAG: --policy-config-file=""
I0125 15:54:27.518709   59701 flags.go:33] FLAG: --policy-configmap=""
I0125 15:54:27.518711   59701 flags.go:33] FLAG: --policy-configmap-namespace="kube-system"
I0125 15:54:27.518713   59701 flags.go:33] FLAG: --port="10251"
I0125 15:54:27.518716   59701 flags.go:33] FLAG: --profiling="false"
I0125 15:54:27.518718   59701 flags.go:33] FLAG: --requestheader-allowed-names="[]"
I0125 15:54:27.518721   59701 flags.go:33] FLAG: --requestheader-client-ca-file=""
I0125 15:54:27.518723   59701 flags.go:33] FLAG: --requestheader-extra-headers-prefix="[x-remote-extra-]"
I0125 15:54:27.518727   59701 flags.go:33] FLAG: --requestheader-group-headers="[x-remote-group]"
I0125 15:54:27.518730   59701 flags.go:33] FLAG: --requestheader-username-headers="[x-remote-user]"
I0125 15:54:27.518732   59701 flags.go:33] FLAG: --scheduler-name="default-scheduler"
I0125 15:54:27.518735   59701 flags.go:33] FLAG: --secure-port="10259"
I0125 15:54:27.518737   59701 flags.go:33] FLAG: --skip-headers="false"
I0125 15:54:27.518739   59701 flags.go:33] FLAG: --stderrthreshold="2"
I0125 15:54:27.518741   59701 flags.go:33] FLAG: --storage-driver-buffer-duration="1m0s"
I0125 15:54:27.518744   59701 flags.go:33] FLAG: --storage-driver-db="cadvisor"
I0125 15:54:27.518746   59701 flags.go:33] FLAG: --storage-driver-host="localhost:8086"
I0125 15:54:27.518750   59701 flags.go:33] FLAG: --storage-driver-password="root"
I0125 15:54:27.518752   59701 flags.go:33] FLAG: --storage-driver-secure="false"
I0125 15:54:27.518754   59701 flags.go:33] FLAG: --storage-driver-table="stats"
I0125 15:54:27.518757   59701 flags.go:33] FLAG: --storage-driver-user="root"
I0125 15:54:27.518759   59701 flags.go:33] FLAG: --tls-cert-file=""
I0125 15:54:27.518761   59701 flags.go:33] FLAG: --tls-cipher-suites="[]"
I0125 15:54:27.518764   59701 flags.go:33] FLAG: --tls-min-version=""
I0125 15:54:27.518766   59701 flags.go:33] FLAG: --tls-private-key-file=""
I0125 15:54:27.518768   59701 flags.go:33] FLAG: --tls-sni-cert-key="[]"
I0125 15:54:27.518771   59701 flags.go:33] FLAG: --use-legacy-policy-config="false"
I0125 15:54:27.518773   59701 flags.go:33] FLAG: --v="5"
I0125 15:54:27.518776   59701 flags.go:33] FLAG: --version="false"
I0125 15:54:27.518779   59701 flags.go:33] FLAG: --vmodule=""
I0125 15:54:27.518782   59701 flags.go:33] FLAG: --write-config-to=""
I0125 15:54:27.790690   59701 serving.go:318] Generated self-signed cert in-memory
W0125 15:54:28.164559   59701 authentication.go:249] No authentication-kubeconfig provided in order to lookup client-ca-file in configmap/extension-apiserver-authentication in kube-system, so client certificate authentication won't work.
W0125 15:54:28.164590   59701 authentication.go:252] No authentication-kubeconfig provided in order to lookup requestheader-client-ca-file in configmap/extension-apiserver-authentication in kube-system, so request-header client certificate authentication won't work.
W0125 15:54:28.164637   59701 authorization.go:146] No authorization-kubeconfig provided, so SubjectAccessReview of authorization tokens won't work.
I0125 15:54:28.169846   59701 server.go:141] Version: v1.14.0-alpha.1.1+f2c3d7e5bc544a
I0125 15:54:28.169893   59701 defaults.go:87] TaintNodesByCondition is enabled, PodToleratesNodeTaints predicate is mandatory
I0125 15:54:28.170249   59701 factory.go:751] Creating scheduler from algorithm provider 'DefaultProvider'
I0125 15:54:28.170260   59701 factory.go:832] Creating scheduler with fit predicates 'map[MaxEBSVolumeCount:{} GeneralPredicates:{} CheckNodeUnschedulable:{} MatchInterPodAffinity:{} NoDiskConflict:{} CheckVolumeBinding:{} NoVolumeZoneConflict:{} MaxAzureDiskVolumeCount:{} MaxCSIVolumeCountPred:{} PodToleratesNodeTaints:{} MaxGCEPDVolumeCount:{}]' and priority functions 'map[TaintTolerationPriority:{} ImageLocalityPriority:{} SelectorSpreadPriority:{} InterPodAffinityPriority:{} LeastRequestedPriority:{} BalancedResourceAllocation:{} NodePreferAvoidPodsPriority:{} NodeAffinityPriority:{}]'
I0125 15:54:28.170529   59701 healthz.go:112] No default health checks specified. Installing the ping handler.
I0125 15:54:28.170540   59701 healthz.go:116] Installing healthz checkers:"ping"
W0125 15:54:28.171027   59701 authorization.go:47] Authorization is disabled
W0125 15:54:28.171036   59701 authentication.go:55] Authentication is disabled
I0125 15:54:28.171045   59701 deprecated_insecure_serving.go:49] Serving healthz insecurely on [::]:10251
I0125 15:54:28.171058   59701 healthz.go:112] No default health checks specified. Installing the ping handler.
I0125 15:54:28.171062   59701 healthz.go:116] Installing healthz checkers:"ping"
I0125 15:54:28.171467   59701 secure_serving.go:116] Serving securely on [::]:10259
I0125 15:54:28.171815   59701 reflector.go:131] Starting reflector *v1.PersistentVolumeClaim (0s) from k8s.io/client-go/informers/factory.go:132
I0125 15:54:28.171831   59701 reflector.go:169] Listing and watching *v1.PersistentVolumeClaim from k8s.io/client-go/informers/factory.go:132
I0125 15:54:28.171867   59701 reflector.go:131] Starting reflector *v1.Node (0s) from k8s.io/client-go/informers/factory.go:132
I0125 15:54:28.171880   59701 reflector.go:169] Listing and watching *v1.Node from k8s.io/client-go/informers/factory.go:132
I0125 15:54:28.172151   59701 reflector.go:131] Starting reflector *v1.Service (0s) from k8s.io/client-go/informers/factory.go:132
I0125 15:54:28.172168   59701 reflector.go:169] Listing and watching *v1.Service from k8s.io/client-go/informers/factory.go:132
I0125 15:54:28.172466   59701 reflector.go:131] Starting reflector *v1.ReplicaSet (0s) from k8s.io/client-go/informers/factory.go:132
I0125 15:54:28.172480   59701 reflector.go:169] Listing and watching *v1.ReplicaSet from k8s.io/client-go/informers/factory.go:132
I0125 15:54:28.173081   59701 reflector.go:131] Starting reflector *v1.StatefulSet (0s) from k8s.io/client-go/informers/factory.go:132
I0125 15:54:28.173095   59701 reflector.go:169] Listing and watching *v1.StatefulSet from k8s.io/client-go/informers/factory.go:132
I0125 15:54:28.173221   59701 reflector.go:131] Starting reflector *v1.PersistentVolume (0s) from k8s.io/client-go/informers/factory.go:132
I0125 15:54:28.173234   59701 reflector.go:169] Listing and watching *v1.PersistentVolume from k8s.io/client-go/informers/factory.go:132
I0125 15:54:28.174447   59701 reflector.go:131] Starting reflector *v1.Pod (0s) from k8s.io/kubernetes/cmd/kube-scheduler/app/server.go:218
I0125 15:54:28.174462   59701 reflector.go:169] Listing and watching *v1.Pod from k8s.io/kubernetes/cmd/kube-scheduler/app/server.go:218
I0125 15:54:28.174576   59701 reflector.go:131] Starting reflector *v1.ReplicationController (0s) from k8s.io/client-go/informers/factory.go:132
I0125 15:54:28.174588   59701 reflector.go:169] Listing and watching *v1.ReplicationController from k8s.io/client-go/informers/factory.go:132
I0125 15:54:28.174850   59701 reflector.go:131] Starting reflector *v1beta1.PodDisruptionBudget (0s) from k8s.io/client-go/informers/factory.go:132
I0125 15:54:28.174863   59701 reflector.go:169] Listing and watching *v1beta1.PodDisruptionBudget from k8s.io/client-go/informers/factory.go:132
I0125 15:54:28.174950   59701 reflector.go:131] Starting reflector *v1.StorageClass (0s) from k8s.io/client-go/informers/factory.go:132
I0125 15:54:28.174963   59701 reflector.go:169] Listing and watching *v1.StorageClass from k8s.io/client-go/informers/factory.go:132
I0125 15:54:28.196724   59701 node_tree.go:93] Added node 127.0.0.1 in group  to NodeTree
I0125 15:54:28.272587   59701 shared_informer.go:123] caches populated
I0125 15:54:28.373208   59701 shared_informer.go:123] caches populated
I0125 15:54:28.473489   59701 shared_informer.go:123] caches populated
I0125 15:54:28.577135   59701 shared_informer.go:123] caches populated
I0125 15:54:28.677402   59701 shared_informer.go:123] caches populated
I0125 15:54:28.777846   59701 shared_informer.go:123] caches populated
I0125 15:54:28.878136   59701 shared_informer.go:123] caches populated
I0125 15:54:28.978654   59701 shared_informer.go:123] caches populated
I0125 15:54:29.079062   59701 shared_informer.go:123] caches populated
I0125 15:54:29.079108   59701 controller_utils.go:1021] Waiting for caches to sync for scheduler controller
I0125 15:54:29.180619   59701 shared_informer.go:123] caches populated
I0125 15:54:29.180675   59701 controller_utils.go:1028] Caches are synced for scheduler controller
I0125 15:54:29.281185   59701 shared_informer.go:123] caches populated
I0125 15:54:34.044968   59701 scheduling_queue.go:821] About to try and schedule pod kube-system/kube-dns-8f7866879-mjnq7
I0125 15:54:34.044981   59701 scheduler.go:451] Attempting to schedule pod: kube-system/kube-dns-8f7866879-mjnq7
I0125 15:54:34.045055   59701 generic_scheduler.go:623] since alwaysCheckAllPredicates has not been set, the predicate evaluation is short circuited and there are chances of other predicates failing as well.
I0125 15:54:34.045088   59701 factory.go:1076] Unable to schedule kube-system/kube-dns-8f7866879-mjnq7: no fit: 0/1 nodes are available: 1 node(s) had taints that the pod didn't tolerate.; waiting
I0125 15:54:34.045119   59701 factory.go:1170] Updating pod condition for kube-system/kube-dns-8f7866879-mjnq7 to (PodScheduled==False, Reason=Unschedulable)
I0125 15:54:34.053861   59701 generic_scheduler.go:305] Preemption will not help schedule pod kube-system/kube-dns-8f7866879-mjnq7 on any node.
I0125 15:54:34.054043   59701 scheduling_queue.go:821] About to try and schedule pod kube-system/kube-dns-8f7866879-mjnq7
I0125 15:54:34.054053   59701 scheduler.go:451] Attempting to schedule pod: kube-system/kube-dns-8f7866879-mjnq7
I0125 15:54:34.054175   59701 generic_scheduler.go:623] since alwaysCheckAllPredicates has not been set, the predicate evaluation is short circuited and there are chances of other predicates failing as well.
I0125 15:54:34.054228   59701 factory.go:1076] Unable to schedule kube-system/kube-dns-8f7866879-mjnq7: no fit: 0/1 nodes are available: 1 node(s) had taints that the pod didn't tolerate.; waiting
I0125 15:54:34.054251   59701 factory.go:1170] Updating pod condition for kube-system/kube-dns-8f7866879-mjnq7 to (PodScheduled==False, Reason=Unschedulable)
I0125 15:54:34.060546   59701 generic_scheduler.go:305] Preemption will not help schedule pod kube-system/kube-dns-8f7866879-mjnq7 on any node.
I0125 15:54:38.059055   59701 scheduling_queue.go:821] About to try and schedule pod kube-system/kube-dns-8f7866879-mjnq7
I0125 15:54:38.059072   59701 scheduler.go:451] Attempting to schedule pod: kube-system/kube-dns-8f7866879-mjnq7
I0125 15:54:38.059183   59701 generic_scheduler.go:623] since alwaysCheckAllPredicates has not been set, the predicate evaluation is short circuited and there are chances of other predicates failing as well.
I0125 15:54:38.059293   59701 factory.go:1076] Unable to schedule kube-system/kube-dns-8f7866879-mjnq7: no fit: 0/1 nodes are available: 1 node(s) had taints that the pod didn't tolerate.; waiting
I0125 15:54:38.059379   59701 factory.go:1170] Updating pod condition for kube-system/kube-dns-8f7866879-mjnq7 to (PodScheduled==False, Reason=Unschedulable)
I0125 15:54:38.061926   59701 backoff_utils.go:79] Backing off 2s
I0125 15:54:38.063610   59701 generic_scheduler.go:305] Preemption will not help schedule pod kube-system/kube-dns-8f7866879-mjnq7 on any node.
I0125 15:54:40.114505   59701 scheduling_queue.go:821] About to try and schedule pod default/bb-65fd577957-vlvq5
I0125 15:54:40.114515   59701 scheduler.go:451] Attempting to schedule pod: default/bb-65fd577957-vlvq5
I0125 15:54:40.114563   59701 predicates.go:431] PVC default/pvc-vault-ro is not bound, assuming PVC matches predicate when counting limits
I0125 15:54:40.114608   59701 predicates.go:431] PVC default/pvc-vault-ro is not bound, assuming PVC matches predicate when counting limits
I0125 15:54:40.114614   59701 predicates.go:431] PVC default/pvc-vault-ro is not bound, assuming PVC matches predicate when counting limits
I0125 15:54:40.114619   59701 scheduler_binder.go:173] FindPodVolumes for pod "default/bb-65fd577957-vlvq5", node "127.0.0.1"
I0125 15:54:40.114625   59701 scheduler_binder.go:576] PVC "default/pvc-vault-ro" is not bound
E0125 15:54:40.114662   59701 factory.go:1089] Error scheduling default/bb-65fd577957-vlvq5: pod has unbound immediate PersistentVolumeClaims; retrying
I0125 15:54:40.114677   59701 factory.go:1170] Updating pod condition for default/bb-65fd577957-vlvq5 to (PodScheduled==False, Reason=Unschedulable)
E0125 15:54:40.116545   59701 scheduler.go:478] error selecting node for pod: pod has unbound immediate PersistentVolumeClaims
I0125 15:54:40.117021   59701 scheduling_queue.go:821] About to try and schedule pod default/bb-65fd577957-vlvq5
I0125 15:54:40.117030   59701 scheduler.go:451] Attempting to schedule pod: default/bb-65fd577957-vlvq5
I0125 15:54:40.117075   59701 predicates.go:431] PVC default/pvc-vault-ro is not bound, assuming PVC matches predicate when counting limits
I0125 15:54:40.117121   59701 predicates.go:431] PVC default/pvc-vault-ro is not bound, assuming PVC matches predicate when counting limits
I0125 15:54:40.117127   59701 predicates.go:431] PVC default/pvc-vault-ro is not bound, assuming PVC matches predicate when counting limits
I0125 15:54:40.117132   59701 scheduler_binder.go:173] FindPodVolumes for pod "default/bb-65fd577957-vlvq5", node "127.0.0.1"
I0125 15:54:40.117139   59701 scheduler_binder.go:576] PVC "default/pvc-vault-ro" is not bound
E0125 15:54:40.117173   59701 factory.go:1089] Error scheduling default/bb-65fd577957-vlvq5: pod has unbound immediate PersistentVolumeClaims; retrying
I0125 15:54:40.117189   59701 factory.go:1170] Updating pod condition for default/bb-65fd577957-vlvq5 to (PodScheduled==False, Reason=Unschedulable)
E0125 15:54:40.120061   59701 scheduler.go:478] error selecting node for pod: pod has unbound immediate PersistentVolumeClaims
I0125 15:54:40.120077   59701 scheduling_queue.go:821] About to try and schedule pod default/bb-65fd577957-29tb5
I0125 15:54:40.120081   59701 scheduler.go:451] Attempting to schedule pod: default/bb-65fd577957-29tb5
I0125 15:54:40.120122   59701 predicates.go:431] PVC default/pvc-vault-ro is not bound, assuming PVC matches predicate when counting limits
I0125 15:54:40.120161   59701 predicates.go:431] PVC default/pvc-vault-ro is not bound, assuming PVC matches predicate when counting limits
I0125 15:54:40.120167   59701 predicates.go:431] PVC default/pvc-vault-ro is not bound, assuming PVC matches predicate when counting limits
I0125 15:54:40.120173   59701 scheduler_binder.go:173] FindPodVolumes for pod "default/bb-65fd577957-29tb5", node "127.0.0.1"
I0125 15:54:40.120178   59701 scheduler_binder.go:576] PVC "default/pvc-vault-ro" is not bound
E0125 15:54:40.120202   59701 factory.go:1089] Error scheduling default/bb-65fd577957-29tb5: pod has unbound immediate PersistentVolumeClaims; retrying
I0125 15:54:40.120218   59701 factory.go:1170] Updating pod condition for default/bb-65fd577957-29tb5 to (PodScheduled==False, Reason=Unschedulable)
E0125 15:54:40.123417   59701 scheduler.go:478] error selecting node for pod: pod has unbound immediate PersistentVolumeClaims
I0125 15:54:40.123436   59701 scheduling_queue.go:821] About to try and schedule pod default/bb-65fd577957-q9p8j
I0125 15:54:40.123440   59701 scheduler.go:451] Attempting to schedule pod: default/bb-65fd577957-q9p8j
I0125 15:54:40.123488   59701 predicates.go:431] PVC default/pvc-vault-ro is not bound, assuming PVC matches predicate when counting limits
I0125 15:54:40.123528   59701 predicates.go:431] PVC default/pvc-vault-ro is not bound, assuming PVC matches predicate when counting limits
I0125 15:54:40.123534   59701 predicates.go:431] PVC default/pvc-vault-ro is not bound, assuming PVC matches predicate when counting limits
I0125 15:54:40.123539   59701 scheduler_binder.go:173] FindPodVolumes for pod "default/bb-65fd577957-q9p8j", node "127.0.0.1"
I0125 15:54:40.123545   59701 scheduler_binder.go:576] PVC "default/pvc-vault-ro" is not bound
E0125 15:54:40.123571   59701 factory.go:1089] Error scheduling default/bb-65fd577957-q9p8j: pod has unbound immediate PersistentVolumeClaims; retrying
I0125 15:54:40.123585   59701 factory.go:1170] Updating pod condition for default/bb-65fd577957-q9p8j to (PodScheduled==False, Reason=Unschedulable)
E0125 15:54:40.125779   59701 scheduler.go:478] error selecting node for pod: pod has unbound immediate PersistentVolumeClaims
I0125 15:54:40.125917   59701 scheduling_queue.go:821] About to try and schedule pod default/bb-65fd577957-t9wcq
I0125 15:54:40.125925   59701 scheduler.go:451] Attempting to schedule pod: default/bb-65fd577957-t9wcq
I0125 15:54:40.125969   59701 predicates.go:431] PVC default/pvc-vault-ro is not bound, assuming PVC matches predicate when counting limits
I0125 15:54:40.126014   59701 predicates.go:431] PVC default/pvc-vault-ro is not bound, assuming PVC matches predicate when counting limits
I0125 15:54:40.126020   59701 predicates.go:431] PVC default/pvc-vault-ro is not bound, assuming PVC matches predicate when counting limits
I0125 15:54:40.126026   59701 scheduler_binder.go:173] FindPodVolumes for pod "default/bb-65fd577957-t9wcq", node "127.0.0.1"
I0125 15:54:40.126032   59701 scheduler_binder.go:576] PVC "default/pvc-vault-ro" is not bound
E0125 15:54:40.126065   59701 factory.go:1089] Error scheduling default/bb-65fd577957-t9wcq: pod has unbound immediate PersistentVolumeClaims; retrying
I0125 15:54:40.126078   59701 factory.go:1170] Updating pod condition for default/bb-65fd577957-t9wcq to (PodScheduled==False, Reason=Unschedulable)
E0125 15:54:40.128084   59701 scheduler.go:478] error selecting node for pod: pod has unbound immediate PersistentVolumeClaims
I0125 15:54:40.128451   59701 scheduling_queue.go:821] About to try and schedule pod default/bb-65fd577957-c2cnl
I0125 15:54:40.128460   59701 scheduler.go:451] Attempting to schedule pod: default/bb-65fd577957-c2cnl
I0125 15:54:40.128506   59701 predicates.go:431] PVC default/pvc-vault-ro is not bound, assuming PVC matches predicate when counting limits
I0125 15:54:40.128547   59701 predicates.go:431] PVC default/pvc-vault-ro is not bound, assuming PVC matches predicate when counting limits
I0125 15:54:40.128553   59701 predicates.go:431] PVC default/pvc-vault-ro is not bound, assuming PVC matches predicate when counting limits
I0125 15:54:40.128558   59701 scheduler_binder.go:173] FindPodVolumes for pod "default/bb-65fd577957-c2cnl", node "127.0.0.1"
I0125 15:54:40.128564   59701 scheduler_binder.go:576] PVC "default/pvc-vault-ro" is not bound
E0125 15:54:40.128599   59701 factory.go:1089] Error scheduling default/bb-65fd577957-c2cnl: pod has unbound immediate PersistentVolumeClaims; retrying
I0125 15:54:40.128625   59701 factory.go:1170] Updating pod condition for default/bb-65fd577957-c2cnl to (PodScheduled==False, Reason=Unschedulable)
E0125 15:54:40.134084   59701 scheduler.go:478] error selecting node for pod: pod has unbound immediate PersistentVolumeClaims
I0125 15:54:40.134107   59701 scheduling_queue.go:821] About to try and schedule pod default/bb-65fd577957-knpvn
I0125 15:54:40.134111   59701 scheduler.go:451] Attempting to schedule pod: default/bb-65fd577957-knpvn
I0125 15:54:40.134178   59701 predicates.go:431] PVC default/pvc-vault-ro is not bound, assuming PVC matches predicate when counting limits
I0125 15:54:40.134222   59701 predicates.go:431] PVC default/pvc-vault-ro is not bound, assuming PVC matches predicate when counting limits
I0125 15:54:40.134228   59701 predicates.go:431] PVC default/pvc-vault-ro is not bound, assuming PVC matches predicate when counting limits
I0125 15:54:40.134233   59701 scheduler_binder.go:173] FindPodVolumes for pod "default/bb-65fd577957-knpvn", node "127.0.0.1"
I0125 15:54:40.134239   59701 scheduler_binder.go:576] PVC "default/pvc-vault-ro" is not bound
E0125 15:54:40.134287   59701 factory.go:1089] Error scheduling default/bb-65fd577957-knpvn: pod has unbound immediate PersistentVolumeClaims; retrying
I0125 15:54:40.134304   59701 factory.go:1170] Updating pod condition for default/bb-65fd577957-knpvn to (PodScheduled==False, Reason=Unschedulable)
E0125 15:54:40.139261   59701 scheduler.go:478] error selecting node for pod: pod has unbound immediate PersistentVolumeClaims
I0125 15:54:40.139283   59701 scheduling_queue.go:821] About to try and schedule pod default/bb-65fd577957-gtvtl
I0125 15:54:40.139287   59701 scheduler.go:451] Attempting to schedule pod: default/bb-65fd577957-gtvtl
I0125 15:54:40.139356   59701 predicates.go:431] PVC default/pvc-vault-ro is not bound, assuming PVC matches predicate when counting limits
I0125 15:54:40.139471   59701 predicates.go:431] PVC default/pvc-vault-ro is not bound, assuming PVC matches predicate when counting limits
I0125 15:54:40.139480   59701 predicates.go:431] PVC default/pvc-vault-ro is not bound, assuming PVC matches predicate when counting limits
I0125 15:54:40.139485   59701 scheduler_binder.go:173] FindPodVolumes for pod "default/bb-65fd577957-gtvtl", node "127.0.0.1"
I0125 15:54:40.139491   59701 scheduler_binder.go:576] PVC "default/pvc-vault-ro" is not bound
E0125 15:54:40.139525   59701 factory.go:1089] Error scheduling default/bb-65fd577957-gtvtl: pod has unbound immediate PersistentVolumeClaims; retrying
I0125 15:54:40.139540   59701 factory.go:1170] Updating pod condition for default/bb-65fd577957-gtvtl to (PodScheduled==False, Reason=Unschedulable)
E0125 15:54:40.141541   59701 scheduler.go:478] error selecting node for pod: pod has unbound immediate PersistentVolumeClaims
I0125 15:54:40.141566   59701 scheduling_queue.go:821] About to try and schedule pod default/bb-65fd577957-knpvn
I0125 15:54:40.141574   59701 scheduler.go:451] Attempting to schedule pod: default/bb-65fd577957-knpvn
I0125 15:54:40.141632   59701 predicates.go:431] PVC default/pvc-vault-ro is not bound, assuming PVC matches predicate when counting limits
I0125 15:54:40.141671   59701 predicates.go:431] PVC default/pvc-vault-ro is not bound, assuming PVC matches predicate when counting limits
I0125 15:54:40.141677   59701 predicates.go:431] PVC default/pvc-vault-ro is not bound, assuming PVC matches predicate when counting limits
I0125 15:54:40.141682   59701 scheduler_binder.go:173] FindPodVolumes for pod "default/bb-65fd577957-knpvn", node "127.0.0.1"
I0125 15:54:40.141687   59701 scheduler_binder.go:576] PVC "default/pvc-vault-ro" is not bound
E0125 15:54:40.141714   59701 factory.go:1089] Error scheduling default/bb-65fd577957-knpvn: pod has unbound immediate PersistentVolumeClaims; retrying
I0125 15:54:40.141728   59701 factory.go:1170] Updating pod condition for default/bb-65fd577957-knpvn to (PodScheduled==False, Reason=Unschedulable)
E0125 15:54:40.143431   59701 scheduler.go:478] error selecting node for pod: pod has unbound immediate PersistentVolumeClaims
I0125 15:54:40.143505   59701 scheduling_queue.go:821] About to try and schedule pod default/bb-65fd577957-5hmdw
I0125 15:54:40.143512   59701 scheduler.go:451] Attempting to schedule pod: default/bb-65fd577957-5hmdw
I0125 15:54:40.143550   59701 predicates.go:431] PVC default/pvc-vault-ro is not bound, assuming PVC matches predicate when counting limits
I0125 15:54:40.143596   59701 predicates.go:431] PVC default/pvc-vault-ro is not bound, assuming PVC matches predicate when counting limits
I0125 15:54:40.143602   59701 predicates.go:431] PVC default/pvc-vault-ro is not bound, assuming PVC matches predicate when counting limits
I0125 15:54:40.143607   59701 scheduler_binder.go:173] FindPodVolumes for pod "default/bb-65fd577957-5hmdw", node "127.0.0.1"
I0125 15:54:40.143612   59701 scheduler_binder.go:576] PVC "default/pvc-vault-ro" is not bound
E0125 15:54:40.143637   59701 factory.go:1089] Error scheduling default/bb-65fd577957-5hmdw: pod has unbound immediate PersistentVolumeClaims; retrying
I0125 15:54:40.143650   59701 factory.go:1170] Updating pod condition for default/bb-65fd577957-5hmdw to (PodScheduled==False, Reason=Unschedulable)
E0125 15:54:40.146533   59701 scheduler.go:478] error selecting node for pod: pod has unbound immediate PersistentVolumeClaims
I0125 15:54:40.146563   59701 scheduling_queue.go:821] About to try and schedule pod default/bb-65fd577957-gtvtl
I0125 15:54:40.146570   59701 scheduler.go:451] Attempting to schedule pod: default/bb-65fd577957-gtvtl
I0125 15:54:40.146617   59701 predicates.go:431] PVC default/pvc-vault-ro is not bound, assuming PVC matches predicate when counting limits
I0125 15:54:40.146658   59701 predicates.go:431] PVC default/pvc-vault-ro is not bound, assuming PVC matches predicate when counting limits
I0125 15:54:40.146664   59701 predicates.go:431] PVC default/pvc-vault-ro is not bound, assuming PVC matches predicate when counting limits
I0125 15:54:40.146669   59701 scheduler_binder.go:173] FindPodVolumes for pod "default/bb-65fd577957-gtvtl", node "127.0.0.1"
I0125 15:54:40.146676   59701 scheduler_binder.go:576] PVC "default/pvc-vault-ro" is not bound
E0125 15:54:40.146706   59701 factory.go:1089] Error scheduling default/bb-65fd577957-gtvtl: pod has unbound immediate PersistentVolumeClaims; retrying
I0125 15:54:40.146723   59701 factory.go:1170] Updating pod condition for default/bb-65fd577957-gtvtl to (PodScheduled==False, Reason=Unschedulable)
E0125 15:54:40.148992   59701 scheduler.go:478] error selecting node for pod: pod has unbound immediate PersistentVolumeClaims
I0125 15:54:40.149059   59701 scheduling_queue.go:821] About to try and schedule pod default/bb-65fd577957-dzqkl
I0125 15:54:40.149066   59701 scheduler.go:451] Attempting to schedule pod: default/bb-65fd577957-dzqkl
I0125 15:54:40.149121   59701 predicates.go:431] PVC default/pvc-vault-ro is not bound, assuming PVC matches predicate when counting limits
I0125 15:54:40.149168   59701 predicates.go:431] PVC default/pvc-vault-ro is not bound, assuming PVC matches predicate when counting limits
I0125 15:54:40.149175   59701 predicates.go:431] PVC default/pvc-vault-ro is not bound, assuming PVC matches predicate when counting limits
I0125 15:54:40.149180   59701 scheduler_binder.go:173] FindPodVolumes for pod "default/bb-65fd577957-dzqkl", node "127.0.0.1"
I0125 15:54:40.149186   59701 scheduler_binder.go:576] PVC "default/pvc-vault-ro" is not bound
E0125 15:54:40.149237   59701 factory.go:1089] Error scheduling default/bb-65fd577957-dzqkl: pod has unbound immediate PersistentVolumeClaims; retrying
I0125 15:54:40.149255   59701 factory.go:1170] Updating pod condition for default/bb-65fd577957-dzqkl to (PodScheduled==False, Reason=Unschedulable)
E0125 15:54:40.151140   59701 scheduler.go:478] error selecting node for pod: pod has unbound immediate PersistentVolumeClaims
I0125 15:54:40.151199   59701 scheduling_queue.go:821] About to try and schedule pod default/bb-65fd577957-5hmdw
I0125 15:54:40.151205   59701 scheduler.go:451] Attempting to schedule pod: default/bb-65fd577957-5hmdw
I0125 15:54:40.151247   59701 predicates.go:431] PVC default/pvc-vault-ro is not bound, assuming PVC matches predicate when counting limits
I0125 15:54:40.151294   59701 predicates.go:431] PVC default/pvc-vault-ro is not bound, assuming PVC matches predicate when counting limits
I0125 15:54:40.151301   59701 predicates.go:431] PVC default/pvc-vault-ro is not bound, assuming PVC matches predicate when counting limits
I0125 15:54:40.151306   59701 scheduler_binder.go:173] FindPodVolumes for pod "default/bb-65fd577957-5hmdw", node "127.0.0.1"
I0125 15:54:40.151312   59701 scheduler_binder.go:576] PVC "default/pvc-vault-ro" is not bound
E0125 15:54:40.151341   59701 factory.go:1089] Error scheduling default/bb-65fd577957-5hmdw: pod has unbound immediate PersistentVolumeClaims; retrying
I0125 15:54:40.151359   59701 factory.go:1170] Updating pod condition for default/bb-65fd577957-5hmdw to (PodScheduled==False, Reason=Unschedulable)
E0125 15:54:40.153772   59701 scheduler.go:478] error selecting node for pod: pod has unbound immediate PersistentVolumeClaims
I0125 15:54:40.153882   59701 scheduling_queue.go:821] About to try and schedule pod default/bb-65fd577957-dzqkl
I0125 15:54:40.153891   59701 scheduler.go:451] Attempting to schedule pod: default/bb-65fd577957-dzqkl
I0125 15:54:40.153937   59701 predicates.go:431] PVC default/pvc-vault-ro is not bound, assuming PVC matches predicate when counting limits
I0125 15:54:40.153972   59701 predicates.go:431] PVC default/pvc-vault-ro is not bound, assuming PVC matches predicate when counting limits
I0125 15:54:40.153978   59701 predicates.go:431] PVC default/pvc-vault-ro is not bound, assuming PVC matches predicate when counting limits
I0125 15:54:40.153990   59701 scheduler_binder.go:173] FindPodVolumes for pod "default/bb-65fd577957-dzqkl", node "127.0.0.1"
I0125 15:54:40.153996   59701 scheduler_binder.go:576] PVC "default/pvc-vault-ro" is not bound
E0125 15:54:40.154044   59701 factory.go:1089] Error scheduling default/bb-65fd577957-dzqkl: pod has unbound immediate PersistentVolumeClaims; retrying
I0125 15:54:40.154061   59701 factory.go:1170] Updating pod condition for default/bb-65fd577957-dzqkl to (PodScheduled==False, Reason=Unschedulable)
E0125 15:54:40.155893   59701 scheduler.go:478] error selecting node for pod: pod has unbound immediate PersistentVolumeClaims
I0125 15:54:40.155976   59701 scheduling_queue.go:821] About to try and schedule pod default/bb-65fd577957-jtbpw
I0125 15:54:40.155985   59701 scheduler.go:451] Attempting to schedule pod: default/bb-65fd577957-jtbpw
I0125 15:54:40.156045   59701 predicates.go:431] PVC default/pvc-vault-ro is not bound, assuming PVC matches predicate when counting limits
I0125 15:54:40.156083   59701 predicates.go:431] PVC default/pvc-vault-ro is not bound, assuming PVC matches predicate when counting limits
I0125 15:54:40.156093   59701 predicates.go:431] PVC default/pvc-vault-ro is not bound, assuming PVC matches predicate when counting limits
I0125 15:54:40.156098   59701 scheduler_binder.go:173] FindPodVolumes for pod "default/bb-65fd577957-jtbpw", node "127.0.0.1"
I0125 15:54:40.156104   59701 scheduler_binder.go:576] PVC "default/pvc-vault-ro" is not bound
E0125 15:54:40.156150   59701 factory.go:1089] Error scheduling default/bb-65fd577957-jtbpw: pod has unbound immediate PersistentVolumeClaims; retrying
I0125 15:54:40.156166   59701 factory.go:1170] Updating pod condition for default/bb-65fd577957-jtbpw to (PodScheduled==False, Reason=Unschedulable)
E0125 15:54:40.158028   59701 scheduler.go:478] error selecting node for pod: pod has unbound immediate PersistentVolumeClaims
I0125 15:54:40.158123   59701 scheduling_queue.go:821] About to try and schedule pod default/bb-65fd577957-9kqpw
I0125 15:54:40.158131   59701 scheduler.go:451] Attempting to schedule pod: default/bb-65fd577957-9kqpw
I0125 15:54:40.158425   59701 predicates.go:431] PVC default/pvc-vault-ro is not bound, assuming PVC matches predicate when counting limits
I0125 15:54:40.158467   59701 predicates.go:431] PVC default/pvc-vault-ro is not bound, assuming PVC matches predicate when counting limits
I0125 15:54:40.158474   59701 predicates.go:431] PVC default/pvc-vault-ro is not bound, assuming PVC matches predicate when counting limits
I0125 15:54:40.158479   59701 scheduler_binder.go:173] FindPodVolumes for pod "default/bb-65fd577957-9kqpw", node "127.0.0.1"
I0125 15:54:40.158484   59701 scheduler_binder.go:576] PVC "default/pvc-vault-ro" is not bound
E0125 15:54:40.158531   59701 factory.go:1089] Error scheduling default/bb-65fd577957-9kqpw: pod has unbound immediate PersistentVolumeClaims; retrying
I0125 15:54:40.158547   59701 factory.go:1170] Updating pod condition for default/bb-65fd577957-9kqpw to (PodScheduled==False, Reason=Unschedulable)
E0125 15:54:40.160495   59701 scheduler.go:478] error selecting node for pod: pod has unbound immediate PersistentVolumeClaims
I0125 15:54:40.160565   59701 scheduling_queue.go:821] About to try and schedule pod default/bb-65fd577957-jtbpw
I0125 15:54:40.160575   59701 scheduler.go:451] Attempting to schedule pod: default/bb-65fd577957-jtbpw
I0125 15:54:40.160625   59701 predicates.go:431] PVC default/pvc-vault-ro is not bound, assuming PVC matches predicate when counting limits
I0125 15:54:40.160677   59701 predicates.go:431] PVC default/pvc-vault-ro is not bound, assuming PVC matches predicate when counting limits
I0125 15:54:40.160686   59701 predicates.go:431] PVC default/pvc-vault-ro is not bound, assuming PVC matches predicate when counting limits
I0125 15:54:40.160693   59701 scheduler_binder.go:173] FindPodVolumes for pod "default/bb-65fd577957-jtbpw", node "127.0.0.1"
I0125 15:54:40.160701   59701 scheduler_binder.go:576] PVC "default/pvc-vault-ro" is not bound
E0125 15:54:40.160758   59701 factory.go:1089] Error scheduling default/bb-65fd577957-jtbpw: pod has unbound immediate PersistentVolumeClaims; retrying
I0125 15:54:40.160797   59701 factory.go:1170] Updating pod condition for default/bb-65fd577957-jtbpw to (PodScheduled==False, Reason=Unschedulable)
E0125 15:54:40.164478   59701 scheduler.go:478] error selecting node for pod: pod has unbound immediate PersistentVolumeClaims
I0125 15:54:40.164596   59701 scheduling_queue.go:821] About to try and schedule pod default/bb-65fd577957-9kqpw
I0125 15:54:40.164604   59701 scheduler.go:451] Attempting to schedule pod: default/bb-65fd577957-9kqpw
I0125 15:54:40.164663   59701 predicates.go:431] PVC default/pvc-vault-ro is not bound, assuming PVC matches predicate when counting limits
I0125 15:54:40.164725   59701 predicates.go:431] PVC default/pvc-vault-ro is not bound, assuming PVC matches predicate when counting limits
I0125 15:54:40.164731   59701 predicates.go:431] PVC default/pvc-vault-ro is not bound, assuming PVC matches predicate when counting limits
I0125 15:54:40.164737   59701 scheduler_binder.go:173] FindPodVolumes for pod "default/bb-65fd577957-9kqpw", node "127.0.0.1"
I0125 15:54:40.164748   59701 scheduler_binder.go:576] PVC "default/pvc-vault-ro" is not bound
E0125 15:54:40.164779   59701 factory.go:1089] Error scheduling default/bb-65fd577957-9kqpw: pod has unbound immediate PersistentVolumeClaims; retrying
I0125 15:54:40.164797   59701 factory.go:1170] Updating pod condition for default/bb-65fd577957-9kqpw to (PodScheduled==False, Reason=Unschedulable)
E0125 15:54:40.166628   59701 scheduler.go:478] error selecting node for pod: pod has unbound immediate PersistentVolumeClaims
I0125 15:54:40.166658   59701 scheduling_queue.go:821] About to try and schedule pod default/bb-65fd577957-q2jcl
I0125 15:54:40.166665   59701 scheduler.go:451] Attempting to schedule pod: default/bb-65fd577957-q2jcl
I0125 15:54:40.166732   59701 predicates.go:431] PVC default/pvc-vault-ro is not bound, assuming PVC matches predicate when counting limits
I0125 15:54:40.166789   59701 predicates.go:431] PVC default/pvc-vault-ro is not bound, assuming PVC matches predicate when counting limits
I0125 15:54:40.166800   59701 predicates.go:431] PVC default/pvc-vault-ro is not bound, assuming PVC matches predicate when counting limits
I0125 15:54:40.166807   59701 scheduler_binder.go:173] FindPodVolumes for pod "default/bb-65fd577957-q2jcl", node "127.0.0.1"
I0125 15:54:40.166813   59701 scheduler_binder.go:576] PVC "default/pvc-vault-ro" is not bound
E0125 15:54:40.166846   59701 factory.go:1089] Error scheduling default/bb-65fd577957-q2jcl: pod has unbound immediate PersistentVolumeClaims; retrying
I0125 15:54:40.166869   59701 factory.go:1170] Updating pod condition for default/bb-65fd577957-q2jcl to (PodScheduled==False, Reason=Unschedulable)
E0125 15:54:40.169264   59701 scheduler.go:478] error selecting node for pod: pod has unbound immediate PersistentVolumeClaims
I0125 15:54:40.169372   59701 scheduling_queue.go:821] About to try and schedule pod default/bb-65fd577957-ndj6t
I0125 15:54:40.169383   59701 scheduler.go:451] Attempting to schedule pod: default/bb-65fd577957-ndj6t
I0125 15:54:40.169445   59701 predicates.go:431] PVC default/pvc-vault-ro is not bound, assuming PVC matches predicate when counting limits
I0125 15:54:40.169490   59701 predicates.go:431] PVC default/pvc-vault-ro is not bound, assuming PVC matches predicate when counting limits
I0125 15:54:40.169496   59701 predicates.go:431] PVC default/pvc-vault-ro is not bound, assuming PVC matches predicate when counting limits
I0125 15:54:40.169502   59701 scheduler_binder.go:173] FindPodVolumes for pod "default/bb-65fd577957-ndj6t", node "127.0.0.1"
I0125 15:54:40.169509   59701 scheduler_binder.go:576] PVC "default/pvc-vault-ro" is not bound
E0125 15:54:40.169564   59701 factory.go:1089] Error scheduling default/bb-65fd577957-ndj6t: pod has unbound immediate PersistentVolumeClaims; retrying
I0125 15:54:40.169584   59701 factory.go:1170] Updating pod condition for default/bb-65fd577957-ndj6t to (PodScheduled==False, Reason=Unschedulable)
E0125 15:54:40.172403   59701 scheduler.go:478] error selecting node for pod: pod has unbound immediate PersistentVolumeClaims
I0125 15:54:40.172569   59701 scheduling_queue.go:821] About to try and schedule pod default/bb-65fd577957-66rqt
I0125 15:54:40.172578   59701 scheduler.go:451] Attempting to schedule pod: default/bb-65fd577957-66rqt
I0125 15:54:40.172637   59701 predicates.go:431] PVC default/pvc-vault-ro is not bound, assuming PVC matches predicate when counting limits
I0125 15:54:40.172696   59701 predicates.go:431] PVC default/pvc-vault-ro is not bound, assuming PVC matches predicate when counting limits
I0125 15:54:40.172704   59701 predicates.go:431] PVC default/pvc-vault-ro is not bound, assuming PVC matches predicate when counting limits
I0125 15:54:40.172710   59701 scheduler_binder.go:173] FindPodVolumes for pod "default/bb-65fd577957-66rqt", node "127.0.0.1"
I0125 15:54:40.172717   59701 scheduler_binder.go:576] PVC "default/pvc-vault-ro" is not bound
E0125 15:54:40.172775   59701 factory.go:1089] Error scheduling default/bb-65fd577957-66rqt: pod has unbound immediate PersistentVolumeClaims; retrying
I0125 15:54:40.172801   59701 factory.go:1170] Updating pod condition for default/bb-65fd577957-66rqt to (PodScheduled==False, Reason=Unschedulable)
E0125 15:54:40.174754   59701 scheduler.go:478] error selecting node for pod: pod has unbound immediate PersistentVolumeClaims
I0125 15:54:40.174858   59701 scheduling_queue.go:821] About to try and schedule pod default/bb-65fd577957-ndj6t
I0125 15:54:40.174866   59701 scheduler.go:451] Attempting to schedule pod: default/bb-65fd577957-ndj6t
I0125 15:54:40.174931   59701 predicates.go:431] PVC default/pvc-vault-ro is not bound, assuming PVC matches predicate when counting limits
I0125 15:54:40.174978   59701 predicates.go:431] PVC default/pvc-vault-ro is not bound, assuming PVC matches predicate when counting limits
I0125 15:54:40.174985   59701 predicates.go:431] PVC default/pvc-vault-ro is not bound, assuming PVC matches predicate when counting limits
I0125 15:54:40.174991   59701 scheduler_binder.go:173] FindPodVolumes for pod "default/bb-65fd577957-ndj6t", node "127.0.0.1"
I0125 15:54:40.174997   59701 scheduler_binder.go:576] PVC "default/pvc-vault-ro" is not bound
E0125 15:54:40.175044   59701 factory.go:1089] Error scheduling default/bb-65fd577957-ndj6t: pod has unbound immediate PersistentVolumeClaims; retrying
I0125 15:54:40.175062   59701 factory.go:1170] Updating pod condition for default/bb-65fd577957-ndj6t to (PodScheduled==False, Reason=Unschedulable)
E0125 15:54:40.177041   59701 scheduler.go:478] error selecting node for pod: pod has unbound immediate PersistentVolumeClaims
I0125 15:54:40.177080   59701 scheduling_queue.go:821] About to try and schedule pod default/bb-65fd577957-66rqt
I0125 15:54:40.177086   59701 scheduler.go:451] Attempting to schedule pod: default/bb-65fd577957-66rqt
I0125 15:54:40.177127   59701 predicates.go:431] PVC default/pvc-vault-ro is not bound, assuming PVC matches predicate when counting limits
I0125 15:54:40.177164   59701 predicates.go:431] PVC default/pvc-vault-ro is not bound, assuming PVC matches predicate when counting limits
I0125 15:54:40.177170   59701 predicates.go:431] PVC default/pvc-vault-ro is not bound, assuming PVC matches predicate when counting limits
I0125 15:54:40.177176   59701 scheduler_binder.go:173] FindPodVolumes for pod "default/bb-65fd577957-66rqt", node "127.0.0.1"
I0125 15:54:40.177182   59701 scheduler_binder.go:576] PVC "default/pvc-vault-ro" is not bound
E0125 15:54:40.177228   59701 factory.go:1089] Error scheduling default/bb-65fd577957-66rqt: pod has unbound immediate PersistentVolumeClaims; retrying
I0125 15:54:40.177244   59701 factory.go:1170] Updating pod condition for default/bb-65fd577957-66rqt to (PodScheduled==False, Reason=Unschedulable)
E0125 15:54:40.178973   59701 scheduler.go:478] error selecting node for pod: pod has unbound immediate PersistentVolumeClaims
I0125 15:54:40.179014   59701 scheduling_queue.go:821] About to try and schedule pod default/bb-65fd577957-q2jcl
I0125 15:54:40.179021   59701 scheduler.go:451] Attempting to schedule pod: default/bb-65fd577957-q2jcl
I0125 15:54:40.179085   59701 predicates.go:431] PVC default/pvc-vault-ro is not bound, assuming PVC matches predicate when counting limits
I0125 15:54:40.179129   59701 predicates.go:431] PVC default/pvc-vault-ro is not bound, assuming PVC matches predicate when counting limits
I0125 15:54:40.179135   59701 predicates.go:431] PVC default/pvc-vault-ro is not bound, assuming PVC matches predicate when counting limits
I0125 15:54:40.179140   59701 scheduler_binder.go:173] FindPodVolumes for pod "default/bb-65fd577957-q2jcl", node "127.0.0.1"
I0125 15:54:40.179147   59701 scheduler_binder.go:576] PVC "default/pvc-vault-ro" is not bound
E0125 15:54:40.179193   59701 factory.go:1089] Error scheduling default/bb-65fd577957-q2jcl: pod has unbound immediate PersistentVolumeClaims; retrying
I0125 15:54:40.179213   59701 factory.go:1170] Updating pod condition for default/bb-65fd577957-q2jcl to (PodScheduled==False, Reason=Unschedulable)
E0125 15:54:40.181812   59701 scheduler.go:478] error selecting node for pod: pod has unbound immediate PersistentVolumeClaims
I0125 15:54:40.181876   59701 scheduling_queue.go:821] About to try and schedule pod kube-system/kube-dns-8f7866879-mjnq7
I0125 15:54:40.181886   59701 scheduler.go:451] Attempting to schedule pod: kube-system/kube-dns-8f7866879-mjnq7
I0125 15:54:40.181938   59701 scheduler_binder.go:173] FindPodVolumes for pod "kube-system/kube-dns-8f7866879-mjnq7", node "127.0.0.1"
I0125 15:54:40.181953   59701 predicates.go:1645] All PVCs found matches for pod kube-system/kube-dns-8f7866879-mjnq7, node "127.0.0.1"
I0125 15:54:40.182005   59701 scheduler_binder.go:256] AssumePodVolumes for pod "kube-system/kube-dns-8f7866879-mjnq7", node "127.0.0.1"
I0125 15:54:40.182014   59701 scheduler_binder.go:266] AssumePodVolumes for pod "kube-system/kube-dns-8f7866879-mjnq7", node "127.0.0.1": all PVCs bound and nothing to do
I0125 15:54:40.182059   59701 scheduling_queue.go:821] About to try and schedule pod default/bb-65fd577957-s8f8k
I0125 15:54:40.182068   59701 scheduler.go:451] Attempting to schedule pod: default/bb-65fd577957-s8f8k
I0125 15:54:40.182088   59701 factory.go:1161] Attempting to bind kube-dns-8f7866879-mjnq7 to 127.0.0.1
I0125 15:54:40.182130   59701 predicates.go:431] PVC default/pvc-vault-ro is not bound, assuming PVC matches predicate when counting limits
I0125 15:54:40.182247   59701 predicates.go:431] PVC default/pvc-vault-ro is not bound, assuming PVC matches predicate when counting limits
I0125 15:54:40.182260   59701 predicates.go:431] PVC default/pvc-vault-ro is not bound, assuming PVC matches predicate when counting limits
I0125 15:54:40.182268   59701 scheduler_binder.go:173] FindPodVolumes for pod "default/bb-65fd577957-s8f8k", node "127.0.0.1"
I0125 15:54:40.182275   59701 scheduler_binder.go:576] PVC "default/pvc-vault-ro" is not bound
E0125 15:54:40.182328   59701 factory.go:1089] Error scheduling default/bb-65fd577957-s8f8k: pod has unbound immediate PersistentVolumeClaims; retrying
I0125 15:54:40.182368   59701 factory.go:1170] Updating pod condition for default/bb-65fd577957-s8f8k to (PodScheduled==False, Reason=Unschedulable)
I0125 15:54:40.185127   59701 cache.go:209] Finished binding for pod 744526fc-2076-11e9-b9a0-000c299a5e15. Can be expired.
I0125 15:54:40.185165   59701 scheduler.go:569] pod kube-system/kube-dns-8f7866879-mjnq7 is bound successfully on node 127.0.0.1, 1 nodes evaluated, 1 nodes were found feasible
E0125 15:54:40.185172   59701 scheduler.go:478] error selecting node for pod: pod has unbound immediate PersistentVolumeClaims
I0125 15:54:40.185205   59701 scheduling_queue.go:821] About to try and schedule pod default/bb-65fd577957-c2cnl
I0125 15:54:40.185215   59701 scheduler.go:451] Attempting to schedule pod: default/bb-65fd577957-c2cnl
I0125 15:54:40.185272   59701 predicates.go:431] PVC default/pvc-vault-ro is not bound, assuming PVC matches predicate when counting limits
I0125 15:54:40.185321   59701 predicates.go:431] PVC default/pvc-vault-ro is not bound, assuming PVC matches predicate when counting limits
I0125 15:54:40.185329   59701 predicates.go:431] PVC default/pvc-vault-ro is not bound, assuming PVC matches predicate when counting limits
I0125 15:54:40.185335   59701 scheduler_binder.go:173] FindPodVolumes for pod "default/bb-65fd577957-c2cnl", node "127.0.0.1"
I0125 15:54:40.185343   59701 scheduler_binder.go:576] PVC "default/pvc-vault-ro" is not bound
E0125 15:54:40.185385   59701 factory.go:1089] Error scheduling default/bb-65fd577957-c2cnl: pod has unbound immediate PersistentVolumeClaims; retrying
I0125 15:54:40.185435   59701 factory.go:1170] Updating pod condition for default/bb-65fd577957-c2cnl to (PodScheduled==False, Reason=Unschedulable)
E0125 15:54:40.188385   59701 scheduler.go:478] error selecting node for pod: pod has unbound immediate PersistentVolumeClaims
I0125 15:54:40.188519   59701 scheduling_queue.go:821] About to try and schedule pod default/bb-65fd577957-s8f8k
I0125 15:54:40.188532   59701 scheduler.go:451] Attempting to schedule pod: default/bb-65fd577957-s8f8k
I0125 15:54:40.188604   59701 predicates.go:431] PVC default/pvc-vault-ro is not bound, assuming PVC matches predicate when counting limits
I0125 15:54:40.188658   59701 predicates.go:431] PVC default/pvc-vault-ro is not bound, assuming PVC matches predicate when counting limits
I0125 15:54:40.188668   59701 predicates.go:431] PVC default/pvc-vault-ro is not bound, assuming PVC matches predicate when counting limits
I0125 15:54:40.188676   59701 scheduler_binder.go:173] FindPodVolumes for pod "default/bb-65fd577957-s8f8k", node "127.0.0.1"
I0125 15:54:40.188685   59701 scheduler_binder.go:576] PVC "default/pvc-vault-ro" is not bound
E0125 15:54:40.188722   59701 factory.go:1089] Error scheduling default/bb-65fd577957-s8f8k: pod has unbound immediate PersistentVolumeClaims; retrying
I0125 15:54:40.188747   59701 factory.go:1170] Updating pod condition for default/bb-65fd577957-s8f8k to (PodScheduled==False, Reason=Unschedulable)
E0125 15:54:40.190764   59701 scheduler.go:478] error selecting node for pod: pod has unbound immediate PersistentVolumeClaims
I0125 15:54:40.190812   59701 scheduling_queue.go:821] About to try and schedule pod default/bb-65fd577957-xhgt7
I0125 15:54:40.190819   59701 scheduler.go:451] Attempting to schedule pod: default/bb-65fd577957-xhgt7
I0125 15:54:40.190862   59701 predicates.go:431] PVC default/pvc-vault-ro is not bound, assuming PVC matches predicate when counting limits
I0125 15:54:40.190903   59701 predicates.go:431] PVC default/pvc-vault-ro is not bound, assuming PVC matches predicate when counting limits
I0125 15:54:40.190909   59701 predicates.go:431] PVC default/pvc-vault-ro is not bound, assuming PVC matches predicate when counting limits
I0125 15:54:40.190915   59701 scheduler_binder.go:173] FindPodVolumes for pod "default/bb-65fd577957-xhgt7", node "127.0.0.1"
I0125 15:54:40.190921   59701 scheduler_binder.go:576] PVC "default/pvc-vault-ro" is not bound
E0125 15:54:40.190974   59701 factory.go:1089] Error scheduling default/bb-65fd577957-xhgt7: pod has unbound immediate PersistentVolumeClaims; retrying
I0125 15:54:40.190991   59701 factory.go:1170] Updating pod condition for default/bb-65fd577957-xhgt7 to (PodScheduled==False, Reason=Unschedulable)
E0125 15:54:40.194022   59701 scheduler.go:478] error selecting node for pod: pod has unbound immediate PersistentVolumeClaims
I0125 15:54:40.194081   59701 scheduling_queue.go:821] About to try and schedule pod default/bb-65fd577957-q9p8j
I0125 15:54:40.194088   59701 scheduler.go:451] Attempting to schedule pod: default/bb-65fd577957-q9p8j
I0125 15:54:40.194135   59701 predicates.go:431] PVC default/pvc-vault-ro is not bound, assuming PVC matches predicate when counting limits
I0125 15:54:40.194173   59701 predicates.go:431] PVC default/pvc-vault-ro is not bound, assuming PVC matches predicate when counting limits
I0125 15:54:40.194179   59701 predicates.go:431] PVC default/pvc-vault-ro is not bound, assuming PVC matches predicate when counting limits
I0125 15:54:40.194184   59701 scheduler_binder.go:173] FindPodVolumes for pod "default/bb-65fd577957-q9p8j", node "127.0.0.1"
I0125 15:54:40.194191   59701 scheduler_binder.go:576] PVC "default/pvc-vault-ro" is not bound
E0125 15:54:40.194221   59701 factory.go:1089] Error scheduling default/bb-65fd577957-q9p8j: pod has unbound immediate PersistentVolumeClaims; retrying
I0125 15:54:40.194252   59701 factory.go:1170] Updating pod condition for default/bb-65fd577957-q9p8j to (PodScheduled==False, Reason=Unschedulable)
E0125 15:54:40.200571   59701 scheduler.go:478] error selecting node for pod: pod has unbound immediate PersistentVolumeClaims
I0125 15:54:40.200634   59701 scheduling_queue.go:821] About to try and schedule pod default/bb-65fd577957-xhgt7
I0125 15:54:40.200643   59701 scheduler.go:451] Attempting to schedule pod: default/bb-65fd577957-xhgt7
I0125 15:54:40.200710   59701 predicates.go:431] PVC default/pvc-vault-ro is not bound, assuming PVC matches predicate when counting limits
I0125 15:54:40.200761   59701 predicates.go:431] PVC default/pvc-vault-ro is not bound, assuming PVC matches predicate when counting limits
I0125 15:54:40.200775   59701 predicates.go:431] PVC default/pvc-vault-ro is not bound, assuming PVC matches predicate when counting limits
I0125 15:54:40.200782   59701 scheduler_binder.go:173] FindPodVolumes for pod "default/bb-65fd577957-xhgt7", node "127.0.0.1"
I0125 15:54:40.200790   59701 scheduler_binder.go:576] PVC "default/pvc-vault-ro" is not bound
E0125 15:54:40.200846   59701 factory.go:1089] Error scheduling default/bb-65fd577957-xhgt7: pod has unbound immediate PersistentVolumeClaims; retrying
I0125 15:54:40.201017   59701 factory.go:1170] Updating pod condition for default/bb-65fd577957-xhgt7 to (PodScheduled==False, Reason=Unschedulable)
E0125 15:54:40.202508   59701 scheduler.go:478] error selecting node for pod: pod has unbound immediate PersistentVolumeClaims
I0125 15:54:40.202592   59701 scheduling_queue.go:821] About to try and schedule pod default/bb-65fd577957-2lj99
I0125 15:54:40.202601   59701 scheduler.go:451] Attempting to schedule pod: default/bb-65fd577957-2lj99
I0125 15:54:40.202652   59701 predicates.go:431] PVC default/pvc-vault-ro is not bound, assuming PVC matches predicate when counting limits
I0125 15:54:40.202690   59701 predicates.go:431] PVC default/pvc-vault-ro is not bound, assuming PVC matches predicate when counting limits
I0125 15:54:40.202696   59701 predicates.go:431] PVC default/pvc-vault-ro is not bound, assuming PVC matches predicate when counting limits
I0125 15:54:40.202701   59701 scheduler_binder.go:173] FindPodVolumes for pod "default/bb-65fd577957-2lj99", node "127.0.0.1"
I0125 15:54:40.202707   59701 scheduler_binder.go:576] PVC "default/pvc-vault-ro" is not bound
E0125 15:54:40.202732   59701 factory.go:1089] Error scheduling default/bb-65fd577957-2lj99: pod has unbound immediate PersistentVolumeClaims; retrying
I0125 15:54:40.202746   59701 factory.go:1170] Updating pod condition for default/bb-65fd577957-2lj99 to (PodScheduled==False, Reason=Unschedulable)
E0125 15:54:40.204483   59701 scheduler.go:478] error selecting node for pod: pod has unbound immediate PersistentVolumeClaims
I0125 15:54:40.204570   59701 scheduling_queue.go:821] About to try and schedule pod default/bb-65fd577957-xhgt7
I0125 15:54:40.204578   59701 scheduler.go:451] Attempting to schedule pod: default/bb-65fd577957-xhgt7
I0125 15:54:40.204626   59701 predicates.go:431] PVC default/pvc-vault-ro is not bound, assuming PVC matches predicate when counting limits
I0125 15:54:40.204662   59701 predicates.go:431] PVC default/pvc-vault-ro is not bound, assuming PVC matches predicate when counting limits
I0125 15:54:40.204669   59701 predicates.go:431] PVC default/pvc-vault-ro is not bound, assuming PVC matches predicate when counting limits
I0125 15:54:40.204674   59701 scheduler_binder.go:173] FindPodVolumes for pod "default/bb-65fd577957-xhgt7", node "127.0.0.1"
I0125 15:54:40.204680   59701 scheduler_binder.go:576] PVC "default/pvc-vault-ro" is not bound
E0125 15:54:40.204705   59701 factory.go:1089] Error scheduling default/bb-65fd577957-xhgt7: pod has unbound immediate PersistentVolumeClaims; retrying
I0125 15:54:40.204718   59701 factory.go:1170] Updating pod condition for default/bb-65fd577957-xhgt7 to (PodScheduled==False, Reason=Unschedulable)
E0125 15:54:40.206242   59701 scheduler.go:478] error selecting node for pod: pod has unbound immediate PersistentVolumeClaims
I0125 15:54:40.206296   59701 scheduling_queue.go:821] About to try and schedule pod default/bb-65fd577957-2lj99
I0125 15:54:40.206301   59701 scheduler.go:451] Attempting to schedule pod: default/bb-65fd577957-2lj99
I0125 15:54:40.206337   59701 predicates.go:431] PVC default/pvc-vault-ro is not bound, assuming PVC matches predicate when counting limits
I0125 15:54:40.206372   59701 predicates.go:431] PVC default/pvc-vault-ro is not bound, assuming PVC matches predicate when counting limits
I0125 15:54:40.206378   59701 predicates.go:431] PVC default/pvc-vault-ro is not bound, assuming PVC matches predicate when counting limits
I0125 15:54:40.206383   59701 scheduler_binder.go:173] FindPodVolumes for pod "default/bb-65fd577957-2lj99", node "127.0.0.1"
I0125 15:54:40.206392   59701 scheduler_binder.go:576] PVC "default/pvc-vault-ro" is not bound
E0125 15:54:40.206415   59701 factory.go:1089] Error scheduling default/bb-65fd577957-2lj99: pod has unbound immediate PersistentVolumeClaims; retrying
I0125 15:54:40.206427   59701 factory.go:1170] Updating pod condition for default/bb-65fd577957-2lj99 to (PodScheduled==False, Reason=Unschedulable)
E0125 15:54:40.208049   59701 scheduler.go:478] error selecting node for pod: pod has unbound immediate PersistentVolumeClaims
I0125 15:54:40.208160   59701 scheduling_queue.go:821] About to try and schedule pod default/bb-65fd577957-7vs4j
I0125 15:54:40.208184   59701 scheduler.go:451] Attempting to schedule pod: default/bb-65fd577957-7vs4j
I0125 15:54:40.208271   59701 predicates.go:431] PVC default/pvc-vault-ro is not bound, assuming PVC matches predicate when counting limits
I0125 15:54:40.208363   59701 predicates.go:431] PVC default/pvc-vault-ro is not bound, assuming PVC matches predicate when counting limits
I0125 15:54:40.208401   59701 predicates.go:431] PVC default/pvc-vault-ro is not bound, assuming PVC matches predicate when counting limits
I0125 15:54:40.208410   59701 scheduler_binder.go:173] FindPodVolumes for pod "default/bb-65fd577957-7vs4j", node "127.0.0.1"
I0125 15:54:40.208415   59701 scheduler_binder.go:576] PVC "default/pvc-vault-ro" is not bound
E0125 15:54:40.208461   59701 factory.go:1089] Error scheduling default/bb-65fd577957-7vs4j: pod has unbound immediate PersistentVolumeClaims; retrying
I0125 15:54:40.208484   59701 factory.go:1170] Updating pod condition for default/bb-65fd577957-7vs4j to (PodScheduled==False, Reason=Unschedulable)
E0125 15:54:40.210705   59701 scheduler.go:478] error selecting node for pod: pod has unbound immediate PersistentVolumeClaims
I0125 15:54:40.210723   59701 scheduling_queue.go:821] About to try and schedule pod default/bb-65fd577957-qfgh6
I0125 15:54:40.210726   59701 scheduler.go:451] Attempting to schedule pod: default/bb-65fd577957-qfgh6
I0125 15:54:40.210764   59701 predicates.go:431] PVC default/pvc-vault-ro is not bound, assuming PVC matches predicate when counting limits
I0125 15:54:40.210805   59701 predicates.go:431] PVC default/pvc-vault-ro is not bound, assuming PVC matches predicate when counting limits
I0125 15:54:40.210811   59701 predicates.go:431] PVC default/pvc-vault-ro is not bound, assuming PVC matches predicate when counting limits
I0125 15:54:40.210816   59701 scheduler_binder.go:173] FindPodVolumes for pod "default/bb-65fd577957-qfgh6", node "127.0.0.1"
I0125 15:54:40.210822   59701 scheduler_binder.go:576] PVC "default/pvc-vault-ro" is not bound
E0125 15:54:40.210845   59701 factory.go:1089] Error scheduling default/bb-65fd577957-qfgh6: pod has unbound immediate PersistentVolumeClaims; retrying
I0125 15:54:40.210857   59701 factory.go:1170] Updating pod condition for default/bb-65fd577957-qfgh6 to (PodScheduled==False, Reason=Unschedulable)
E0125 15:54:40.212952   59701 scheduler.go:478] error selecting node for pod: pod has unbound immediate PersistentVolumeClaims
I0125 15:54:40.213071   59701 scheduling_queue.go:821] About to try and schedule pod default/bb-65fd577957-7vs4j
I0125 15:54:40.213079   59701 scheduler.go:451] Attempting to schedule pod: default/bb-65fd577957-7vs4j
I0125 15:54:40.213121   59701 predicates.go:431] PVC default/pvc-vault-ro is not bound, assuming PVC matches predicate when counting limits
I0125 15:54:40.213161   59701 predicates.go:431] PVC default/pvc-vault-ro is not bound, assuming PVC matches predicate when counting limits
I0125 15:54:40.213168   59701 predicates.go:431] PVC default/pvc-vault-ro is not bound, assuming PVC matches predicate when counting limits
I0125 15:54:40.213173   59701 scheduler_binder.go:173] FindPodVolumes for pod "default/bb-65fd577957-7vs4j", node "127.0.0.1"
I0125 15:54:40.213178   59701 scheduler_binder.go:576] PVC "default/pvc-vault-ro" is not bound
E0125 15:54:40.213219   59701 factory.go:1089] Error scheduling default/bb-65fd577957-7vs4j: pod has unbound immediate PersistentVolumeClaims; retrying
I0125 15:54:40.213239   59701 factory.go:1170] Updating pod condition for default/bb-65fd577957-7vs4j to (PodScheduled==False, Reason=Unschedulable)
E0125 15:54:40.215153   59701 scheduler.go:478] error selecting node for pod: pod has unbound immediate PersistentVolumeClaims
I0125 15:54:40.215170   59701 scheduling_queue.go:821] About to try and schedule pod default/bb-65fd577957-b6xmp
I0125 15:54:40.215174   59701 scheduler.go:451] Attempting to schedule pod: default/bb-65fd577957-b6xmp
I0125 15:54:40.215211   59701 predicates.go:431] PVC default/pvc-vault-ro is not bound, assuming PVC matches predicate when counting limits
I0125 15:54:40.215246   59701 predicates.go:431] PVC default/pvc-vault-ro is not bound, assuming PVC matches predicate when counting limits
I0125 15:54:40.215252   59701 predicates.go:431] PVC default/pvc-vault-ro is not bound, assuming PVC matches predicate when counting limits
I0125 15:54:40.215257   59701 scheduler_binder.go:173] FindPodVolumes for pod "default/bb-65fd577957-b6xmp", node "127.0.0.1"
I0125 15:54:40.215263   59701 scheduler_binder.go:576] PVC "default/pvc-vault-ro" is not bound
E0125 15:54:40.215313   59701 factory.go:1089] Error scheduling default/bb-65fd577957-b6xmp: pod has unbound immediate PersistentVolumeClaims; retrying
I0125 15:54:40.215329   59701 factory.go:1170] Updating pod condition for default/bb-65fd577957-b6xmp to (PodScheduled==False, Reason=Unschedulable)
E0125 15:54:40.217358   59701 scheduler.go:478] error selecting node for pod: pod has unbound immediate PersistentVolumeClaims
I0125 15:54:40.217376   59701 scheduling_queue.go:821] About to try and schedule pod default/bb-65fd577957-l9llg
I0125 15:54:40.217379   59701 scheduler.go:451] Attempting to schedule pod: default/bb-65fd577957-l9llg
I0125 15:54:40.217416   59701 predicates.go:431] PVC default/pvc-vault-ro is not bound, assuming PVC matches predicate when counting limits
I0125 15:54:40.217450   59701 predicates.go:431] PVC default/pvc-vault-ro is not bound, assuming PVC matches predicate when counting limits
I0125 15:54:40.217455   59701 predicates.go:431] PVC default/pvc-vault-ro is not bound, assuming PVC matches predicate when counting limits
I0125 15:54:40.217460   59701 scheduler_binder.go:173] FindPodVolumes for pod "default/bb-65fd577957-l9llg", node "127.0.0.1"
I0125 15:54:40.217466   59701 scheduler_binder.go:576] PVC "default/pvc-vault-ro" is not bound
E0125 15:54:40.217489   59701 factory.go:1089] Error scheduling default/bb-65fd577957-l9llg: pod has unbound immediate PersistentVolumeClaims; retrying
I0125 15:54:40.217501   59701 factory.go:1170] Updating pod condition for default/bb-65fd577957-l9llg to (PodScheduled==False, Reason=Unschedulable)
E0125 15:54:40.219444   59701 scheduler.go:478] error selecting node for pod: pod has unbound immediate PersistentVolumeClaims
I0125 15:54:40.219461   59701 scheduling_queue.go:821] About to try and schedule pod default/bb-65fd577957-b6xmp
I0125 15:54:40.219465   59701 scheduler.go:451] Attempting to schedule pod: default/bb-65fd577957-b6xmp
I0125 15:54:40.219504   59701 predicates.go:431] PVC default/pvc-vault-ro is not bound, assuming PVC matches predicate when counting limits
I0125 15:54:40.219537   59701 predicates.go:431] PVC default/pvc-vault-ro is not bound, assuming PVC matches predicate when counting limits
I0125 15:54:40.219543   59701 predicates.go:431] PVC default/pvc-vault-ro is not bound, assuming PVC matches predicate when counting limits
I0125 15:54:40.219548   59701 scheduler_binder.go:173] FindPodVolumes for pod "default/bb-65fd577957-b6xmp", node "127.0.0.1"
I0125 15:54:40.219554   59701 scheduler_binder.go:576] PVC "default/pvc-vault-ro" is not bound
E0125 15:54:40.219576   59701 factory.go:1089] Error scheduling default/bb-65fd577957-b6xmp: pod has unbound immediate PersistentVolumeClaims; retrying
I0125 15:54:40.219590   59701 factory.go:1170] Updating pod condition for default/bb-65fd577957-b6xmp to (PodScheduled==False, Reason=Unschedulable)
E0125 15:54:40.221448   59701 scheduler.go:478] error selecting node for pod: pod has unbound immediate PersistentVolumeClaims
I0125 15:54:40.221494   59701 scheduling_queue.go:821] About to try and schedule pod default/bb-65fd577957-l9llg
I0125 15:54:40.221501   59701 scheduler.go:451] Attempting to schedule pod: default/bb-65fd577957-l9llg
I0125 15:54:40.221542   59701 predicates.go:431] PVC default/pvc-vault-ro is not bound, assuming PVC matches predicate when counting limits
I0125 15:54:40.221581   59701 predicates.go:431] PVC default/pvc-vault-ro is not bound, assuming PVC matches predicate when counting limits
I0125 15:54:40.221587   59701 predicates.go:431] PVC default/pvc-vault-ro is not bound, assuming PVC matches predicate when counting limits
I0125 15:54:40.221592   59701 scheduler_binder.go:173] FindPodVolumes for pod "default/bb-65fd577957-l9llg", node "127.0.0.1"
I0125 15:54:40.221597   59701 scheduler_binder.go:576] PVC "default/pvc-vault-ro" is not bound
E0125 15:54:40.221623   59701 factory.go:1089] Error scheduling default/bb-65fd577957-l9llg: pod has unbound immediate PersistentVolumeClaims; retrying
I0125 15:54:40.221638   59701 factory.go:1170] Updating pod condition for default/bb-65fd577957-l9llg to (PodScheduled==False, Reason=Unschedulable)
E0125 15:54:40.223417   59701 scheduler.go:478] error selecting node for pod: pod has unbound immediate PersistentVolumeClaims
I0125 15:54:40.223518   59701 scheduling_queue.go:821] About to try and schedule pod default/bb-65fd577957-29tb5
I0125 15:54:40.223526   59701 scheduler.go:451] Attempting to schedule pod: default/bb-65fd577957-29tb5
I0125 15:54:40.223565   59701 predicates.go:431] PVC default/pvc-vault-ro is not bound, assuming PVC matches predicate when counting limits
I0125 15:54:40.223601   59701 predicates.go:431] PVC default/pvc-vault-ro is not bound, assuming PVC matches predicate when counting limits
I0125 15:54:40.223607   59701 predicates.go:431] PVC default/pvc-vault-ro is not bound, assuming PVC matches predicate when counting limits
I0125 15:54:40.223611   59701 scheduler_binder.go:173] FindPodVolumes for pod "default/bb-65fd577957-29tb5", node "127.0.0.1"
I0125 15:54:40.223617   59701 scheduler_binder.go:576] PVC "default/pvc-vault-ro" is not bound
E0125 15:54:40.223645   59701 factory.go:1089] Error scheduling default/bb-65fd577957-29tb5: pod has unbound immediate PersistentVolumeClaims; retrying
I0125 15:54:40.223658   59701 factory.go:1170] Updating pod condition for default/bb-65fd577957-29tb5 to (PodScheduled==False, Reason=Unschedulable)
E0125 15:54:40.225689   59701 scheduler.go:478] error selecting node for pod: pod has unbound immediate PersistentVolumeClaims
I0125 15:54:40.225780   59701 scheduling_queue.go:821] About to try and schedule pod default/bb-65fd577957-g85fs
I0125 15:54:40.225788   59701 scheduler.go:451] Attempting to schedule pod: default/bb-65fd577957-g85fs
I0125 15:54:40.225829   59701 predicates.go:431] PVC default/pvc-vault-ro is not bound, assuming PVC matches predicate when counting limits
I0125 15:54:40.225869   59701 predicates.go:431] PVC default/pvc-vault-ro is not bound, assuming PVC matches predicate when counting limits
I0125 15:54:40.225875   59701 predicates.go:431] PVC default/pvc-vault-ro is not bound, assuming PVC matches predicate when counting limits
I0125 15:54:40.225880   59701 scheduler_binder.go:173] FindPodVolumes for pod "default/bb-65fd577957-g85fs", node "127.0.0.1"
I0125 15:54:40.225886   59701 scheduler_binder.go:576] PVC "default/pvc-vault-ro" is not bound
E0125 15:54:40.225913   59701 factory.go:1089] Error scheduling default/bb-65fd577957-g85fs: pod has unbound immediate PersistentVolumeClaims; retrying
I0125 15:54:40.225943   59701 factory.go:1170] Updating pod condition for default/bb-65fd577957-g85fs to (PodScheduled==False, Reason=Unschedulable)
E0125 15:54:40.227986   59701 scheduler.go:478] error selecting node for pod: pod has unbound immediate PersistentVolumeClaims
I0125 15:54:40.228100   59701 scheduling_queue.go:821] About to try and schedule pod default/bb-65fd577957-qfmf5
I0125 15:54:40.228109   59701 scheduler.go:451] Attempting to schedule pod: default/bb-65fd577957-qfmf5
I0125 15:54:40.228157   59701 predicates.go:431] PVC default/pvc-vault-ro is not bound, assuming PVC matches predicate when counting limits
I0125 15:54:40.228197   59701 predicates.go:431] PVC default/pvc-vault-ro is not bound, assuming PVC matches predicate when counting limits
I0125 15:54:40.228202   59701 predicates.go:431] PVC default/pvc-vault-ro is not bound, assuming PVC matches predicate when counting limits
I0125 15:54:40.228207   59701 scheduler_binder.go:173] FindPodVolumes for pod "default/bb-65fd577957-qfmf5", node "127.0.0.1"
I0125 15:54:40.228213   59701 scheduler_binder.go:576] PVC "default/pvc-vault-ro" is not bound
E0125 15:54:40.228237   59701 factory.go:1089] Error scheduling default/bb-65fd577957-qfmf5: pod has unbound immediate PersistentVolumeClaims; retrying
I0125 15:54:40.228250   59701 factory.go:1170] Updating pod condition for default/bb-65fd577957-qfmf5 to (PodScheduled==False, Reason=Unschedulable)
E0125 15:54:40.230030   59701 scheduler.go:478] error selecting node for pod: pod has unbound immediate PersistentVolumeClaims
I0125 15:54:40.230046   59701 scheduling_queue.go:821] About to try and schedule pod default/bb-65fd577957-g85fs
I0125 15:54:40.230050   59701 scheduler.go:451] Attempting to schedule pod: default/bb-65fd577957-g85fs
I0125 15:54:40.230087   59701 predicates.go:431] PVC default/pvc-vault-ro is not bound, assuming PVC matches predicate when counting limits
I0125 15:54:40.230120   59701 predicates.go:431] PVC default/pvc-vault-ro is not bound, assuming PVC matches predicate when counting limits
I0125 15:54:40.230127   59701 predicates.go:431] PVC default/pvc-vault-ro is not bound, assuming PVC matches predicate when counting limits
I0125 15:54:40.230131   59701 scheduler_binder.go:173] FindPodVolumes for pod "default/bb-65fd577957-g85fs", node "127.0.0.1"
I0125 15:54:40.230137   59701 scheduler_binder.go:576] PVC "default/pvc-vault-ro" is not bound
E0125 15:54:40.230166   59701 factory.go:1089] Error scheduling default/bb-65fd577957-g85fs: pod has unbound immediate PersistentVolumeClaims; retrying
I0125 15:54:40.230179   59701 factory.go:1170] Updating pod condition for default/bb-65fd577957-g85fs to (PodScheduled==False, Reason=Unschedulable)
E0125 15:54:40.231478   59701 scheduler.go:478] error selecting node for pod: pod has unbound immediate PersistentVolumeClaims
I0125 15:54:40.231591   59701 scheduling_queue.go:821] About to try and schedule pod default/bb-65fd577957-qfmf5
I0125 15:54:40.231600   59701 scheduler.go:451] Attempting to schedule pod: default/bb-65fd577957-qfmf5
I0125 15:54:40.231640   59701 predicates.go:431] PVC default/pvc-vault-ro is not bound, assuming PVC matches predicate when counting limits
I0125 15:54:40.231680   59701 predicates.go:431] PVC default/pvc-vault-ro is not bound, assuming PVC matches predicate when counting limits
I0125 15:54:40.231686   59701 predicates.go:431] PVC default/pvc-vault-ro is not bound, assuming PVC matches predicate when counting limits
I0125 15:54:40.231690   59701 scheduler_binder.go:173] FindPodVolumes for pod "default/bb-65fd577957-qfmf5", node "127.0.0.1"
I0125 15:54:40.231696   59701 scheduler_binder.go:576] PVC "default/pvc-vault-ro" is not bound
E0125 15:54:40.231720   59701 factory.go:1089] Error scheduling default/bb-65fd577957-qfmf5: pod has unbound immediate PersistentVolumeClaims; retrying
I0125 15:54:40.231750   59701 factory.go:1170] Updating pod condition for default/bb-65fd577957-qfmf5 to (PodScheduled==False, Reason=Unschedulable)
E0125 15:54:40.233569   59701 scheduler.go:478] error selecting node for pod: pod has unbound immediate PersistentVolumeClaims
I0125 15:54:40.233604   59701 scheduling_queue.go:821] About to try and schedule pod default/bb-65fd577957-l5g6b
I0125 15:54:40.233610   59701 scheduler.go:451] Attempting to schedule pod: default/bb-65fd577957-l5g6b
I0125 15:54:40.233649   59701 predicates.go:431] PVC default/pvc-vault-ro is not bound, assuming PVC matches predicate when counting limits
I0125 15:54:40.233689   59701 predicates.go:431] PVC default/pvc-vault-ro is not bound, assuming PVC matches predicate when counting limits
I0125 15:54:40.233698   59701 predicates.go:431] PVC default/pvc-vault-ro is not bound, assuming PVC matches predicate when counting limits
I0125 15:54:40.233703   59701 scheduler_binder.go:173] FindPodVolumes for pod "default/bb-65fd577957-l5g6b", node "127.0.0.1"
I0125 15:54:40.233708   59701 scheduler_binder.go:576] PVC "default/pvc-vault-ro" is not bound
E0125 15:54:40.233750   59701 factory.go:1089] Error scheduling default/bb-65fd577957-l5g6b: pod has unbound immediate PersistentVolumeClaims; retrying
I0125 15:54:40.233767   59701 factory.go:1170] Updating pod condition for default/bb-65fd577957-l5g6b to (PodScheduled==False, Reason=Unschedulable)
E0125 15:54:40.235257   59701 scheduler.go:478] error selecting node for pod: pod has unbound immediate PersistentVolumeClaims
I0125 15:54:40.235341   59701 scheduling_queue.go:821] About to try and schedule pod default/bb-65fd577957-qhg7m
I0125 15:54:40.235348   59701 scheduler.go:451] Attempting to schedule pod: default/bb-65fd577957-qhg7m
I0125 15:54:40.235386   59701 predicates.go:431] PVC default/pvc-vault-ro is not bound, assuming PVC matches predicate when counting limits
I0125 15:54:40.235419   59701 predicates.go:431] PVC default/pvc-vault-ro is not bound, assuming PVC matches predicate when counting limits
I0125 15:54:40.235425   59701 predicates.go:431] PVC default/pvc-vault-ro is not bound, assuming PVC matches predicate when counting limits
I0125 15:54:40.235429   59701 scheduler_binder.go:173] FindPodVolumes for pod "default/bb-65fd577957-qhg7m", node "127.0.0.1"
I0125 15:54:40.235434   59701 scheduler_binder.go:576] PVC "default/pvc-vault-ro" is not bound
E0125 15:54:40.235458   59701 factory.go:1089] Error scheduling default/bb-65fd577957-qhg7m: pod has unbound immediate PersistentVolumeClaims; retrying
I0125 15:54:40.235472   59701 factory.go:1170] Updating pod condition for default/bb-65fd577957-qhg7m to (PodScheduled==False, Reason=Unschedulable)
E0125 15:54:40.237268   59701 scheduler.go:478] error selecting node for pod: pod has unbound immediate PersistentVolumeClaims
I0125 15:54:40.237351   59701 scheduling_queue.go:821] About to try and schedule pod default/bb-65fd577957-l5g6b
I0125 15:54:40.237358   59701 scheduler.go:451] Attempting to schedule pod: default/bb-65fd577957-l5g6b
I0125 15:54:40.237394   59701 predicates.go:431] PVC default/pvc-vault-ro is not bound, assuming PVC matches predicate when counting limits
I0125 15:54:40.237426   59701 predicates.go:431] PVC default/pvc-vault-ro is not bound, assuming PVC matches predicate when counting limits
I0125 15:54:40.237432   59701 predicates.go:431] PVC default/pvc-vault-ro is not bound, assuming PVC matches predicate when counting limits
I0125 15:54:40.237436   59701 scheduler_binder.go:173] FindPodVolumes for pod "default/bb-65fd577957-l5g6b", node "127.0.0.1"
I0125 15:54:40.237442   59701 scheduler_binder.go:576] PVC "default/pvc-vault-ro" is not bound
E0125 15:54:40.237465   59701 factory.go:1089] Error scheduling default/bb-65fd577957-l5g6b: pod has unbound immediate PersistentVolumeClaims; retrying
I0125 15:54:40.237496   59701 factory.go:1170] Updating pod condition for default/bb-65fd577957-l5g6b to (PodScheduled==False, Reason=Unschedulable)
E0125 15:54:40.238890   59701 scheduler.go:478] error selecting node for pod: pod has unbound immediate PersistentVolumeClaims
I0125 15:54:40.238997   59701 scheduling_queue.go:821] About to try and schedule pod default/bb-65fd577957-qhg7m
I0125 15:54:40.239005   59701 scheduler.go:451] Attempting to schedule pod: default/bb-65fd577957-qhg7m
I0125 15:54:40.239041   59701 predicates.go:431] PVC default/pvc-vault-ro is not bound, assuming PVC matches predicate when counting limits
I0125 15:54:40.239073   59701 predicates.go:431] PVC default/pvc-vault-ro is not bound, assuming PVC matches predicate when counting limits
I0125 15:54:40.239079   59701 predicates.go:431] PVC default/pvc-vault-ro is not bound, assuming PVC matches predicate when counting limits
I0125 15:54:40.239088   59701 scheduler_binder.go:173] FindPodVolumes for pod "default/bb-65fd577957-qhg7m", node "127.0.0.1"
I0125 15:54:40.239093   59701 scheduler_binder.go:576] PVC "default/pvc-vault-ro" is not bound
E0125 15:54:40.239138   59701 factory.go:1089] Error scheduling default/bb-65fd577957-qhg7m: pod has unbound immediate PersistentVolumeClaims; retrying
I0125 15:54:40.239153   59701 factory.go:1170] Updating pod condition for default/bb-65fd577957-qhg7m to (PodScheduled==False, Reason=Unschedulable)
E0125 15:54:40.241048   59701 scheduler.go:478] error selecting node for pod: pod has unbound immediate PersistentVolumeClaims
I0125 15:54:40.267893   59701 scheduling_queue.go:821] About to try and schedule pod default/bb-65fd577957-ph2ct
I0125 15:54:40.267908   59701 scheduler.go:451] Attempting to schedule pod: default/bb-65fd577957-ph2ct
I0125 15:54:40.267967   59701 predicates.go:431] PVC default/pvc-vault-ro is not bound, assuming PVC matches predicate when counting limits
I0125 15:54:40.268023   59701 predicates.go:431] PVC default/pvc-vault-ro is not bound, assuming PVC matches predicate when counting limits
I0125 15:54:40.268034   59701 predicates.go:431] PVC default/pvc-vault-ro is not bound, assuming PVC matches predicate when counting limits
I0125 15:54:40.268041   59701 scheduler_binder.go:173] FindPodVolumes for pod "default/bb-65fd577957-ph2ct", node "127.0.0.1"
I0125 15:54:40.268050   59701 scheduler_binder.go:576] PVC "default/pvc-vault-ro" is not bound
E0125 15:54:40.268093   59701 factory.go:1089] Error scheduling default/bb-65fd577957-ph2ct: pod has unbound immediate PersistentVolumeClaims; retrying
I0125 15:54:40.268113   59701 factory.go:1170] Updating pod condition for default/bb-65fd577957-ph2ct to (PodScheduled==False, Reason=Unschedulable)
E0125 15:54:40.270559   59701 scheduler.go:478] error selecting node for pod: pod has unbound immediate PersistentVolumeClaims
I0125 15:54:40.270742   59701 scheduling_queue.go:821] About to try and schedule pod default/bb-65fd577957-ph2ct
I0125 15:54:40.270782   59701 scheduler.go:451] Attempting to schedule pod: default/bb-65fd577957-ph2ct
I0125 15:54:40.270918   59701 predicates.go:431] PVC default/pvc-vault-ro is not bound, assuming PVC matches predicate when counting limits
I0125 15:54:40.271030   59701 predicates.go:431] PVC default/pvc-vault-ro is not bound, assuming PVC matches predicate when counting limits
I0125 15:54:40.271044   59701 predicates.go:431] PVC default/pvc-vault-ro is not bound, assuming PVC matches predicate when counting limits
I0125 15:54:40.271054   59701 scheduler_binder.go:173] FindPodVolumes for pod "default/bb-65fd577957-ph2ct", node "127.0.0.1"
I0125 15:54:40.271110   59701 scheduler_binder.go:576] PVC "default/pvc-vault-ro" is not bound
E0125 15:54:40.271168   59701 factory.go:1089] Error scheduling default/bb-65fd577957-ph2ct: pod has unbound immediate PersistentVolumeClaims; retrying
I0125 15:54:40.271193   59701 factory.go:1170] Updating pod condition for default/bb-65fd577957-ph2ct to (PodScheduled==False, Reason=Unschedulable)
E0125 15:54:40.274211   59701 scheduler.go:478] error selecting node for pod: pod has unbound immediate PersistentVolumeClaims
I0125 15:54:40.316969   59701 scheduling_queue.go:821] About to try and schedule pod default/bb-65fd577957-t77cf
I0125 15:54:40.316985   59701 scheduler.go:451] Attempting to schedule pod: default/bb-65fd577957-t77cf
I0125 15:54:40.317104   59701 predicates.go:431] PVC default/pvc-vault-ro is not bound, assuming PVC matches predicate when counting limits
I0125 15:54:40.317160   59701 predicates.go:431] PVC default/pvc-vault-ro is not bound, assuming PVC matches predicate when counting limits
I0125 15:54:40.317168   59701 predicates.go:431] PVC default/pvc-vault-ro is not bound, assuming PVC matches predicate when counting limits
I0125 15:54:40.317176   59701 scheduler_binder.go:173] FindPodVolumes for pod "default/bb-65fd577957-t77cf", node "127.0.0.1"
I0125 15:54:40.317185   59701 scheduler_binder.go:576] PVC "default/pvc-vault-ro" is not bound
E0125 15:54:40.317267   59701 factory.go:1089] Error scheduling default/bb-65fd577957-t77cf: pod has unbound immediate PersistentVolumeClaims; retrying
I0125 15:54:40.317293   59701 factory.go:1170] Updating pod condition for default/bb-65fd577957-t77cf to (PodScheduled==False, Reason=Unschedulable)
E0125 15:54:40.320235   59701 scheduler.go:478] error selecting node for pod: pod has unbound immediate PersistentVolumeClaims
I0125 15:54:40.320339   59701 scheduling_queue.go:821] About to try and schedule pod default/bb-65fd577957-t77cf
I0125 15:54:40.320351   59701 scheduler.go:451] Attempting to schedule pod: default/bb-65fd577957-t77cf
I0125 15:54:40.320461   59701 predicates.go:431] PVC default/pvc-vault-ro is not bound, assuming PVC matches predicate when counting limits
I0125 15:54:40.320516   59701 predicates.go:431] PVC default/pvc-vault-ro is not bound, assuming PVC matches predicate when counting limits
I0125 15:54:40.320525   59701 predicates.go:431] PVC default/pvc-vault-ro is not bound, assuming PVC matches predicate when counting limits
I0125 15:54:40.320532   59701 scheduler_binder.go:173] FindPodVolumes for pod "default/bb-65fd577957-t77cf", node "127.0.0.1"
I0125 15:54:40.320541   59701 scheduler_binder.go:576] PVC "default/pvc-vault-ro" is not bound
E0125 15:54:40.320603   59701 factory.go:1089] Error scheduling default/bb-65fd577957-t77cf: pod has unbound immediate PersistentVolumeClaims; retrying
I0125 15:54:40.320626   59701 factory.go:1170] Updating pod condition for default/bb-65fd577957-t77cf to (PodScheduled==False, Reason=Unschedulable)
E0125 15:54:40.322873   59701 scheduler.go:478] error selecting node for pod: pod has unbound immediate PersistentVolumeClaims
I0125 15:54:40.365773   59701 scheduling_queue.go:821] About to try and schedule pod default/bb-65fd577957-rd7w2
I0125 15:54:40.365789   59701 scheduler.go:451] Attempting to schedule pod: default/bb-65fd577957-rd7w2
I0125 15:54:40.365848   59701 predicates.go:431] PVC default/pvc-vault-ro is not bound, assuming PVC matches predicate when counting limits
I0125 15:54:40.365903   59701 predicates.go:431] PVC default/pvc-vault-ro is not bound, assuming PVC matches predicate when counting limits
I0125 15:54:40.365911   59701 predicates.go:431] PVC default/pvc-vault-ro is not bound, assuming PVC matches predicate when counting limits
I0125 15:54:40.365919   59701 scheduler_binder.go:173] FindPodVolumes for pod "default/bb-65fd577957-rd7w2", node "127.0.0.1"
I0125 15:54:40.365928   59701 scheduler_binder.go:576] PVC "default/pvc-vault-ro" is not bound
E0125 15:54:40.366014   59701 factory.go:1089] Error scheduling default/bb-65fd577957-rd7w2: pod has unbound immediate PersistentVolumeClaims; retrying
I0125 15:54:40.366040   59701 factory.go:1170] Updating pod condition for default/bb-65fd577957-rd7w2 to (PodScheduled==False, Reason=Unschedulable)
E0125 15:54:40.368675   59701 scheduler.go:478] error selecting node for pod: pod has unbound immediate PersistentVolumeClaims
I0125 15:54:40.368711   59701 scheduling_queue.go:821] About to try and schedule pod default/bb-65fd577957-rd7w2
I0125 15:54:40.368716   59701 scheduler.go:451] Attempting to schedule pod: default/bb-65fd577957-rd7w2
I0125 15:54:40.368785   59701 predicates.go:431] PVC default/pvc-vault-ro is not bound, assuming PVC matches predicate when counting limits
I0125 15:54:40.368831   59701 predicates.go:431] PVC default/pvc-vault-ro is not bound, assuming PVC matches predicate when counting limits
I0125 15:54:40.368838   59701 predicates.go:431] PVC default/pvc-vault-ro is not bound, assuming PVC matches predicate when counting limits
I0125 15:54:40.368844   59701 scheduler_binder.go:173] FindPodVolumes for pod "default/bb-65fd577957-rd7w2", node "127.0.0.1"
I0125 15:54:40.368851   59701 scheduler_binder.go:576] PVC "default/pvc-vault-ro" is not bound
E0125 15:54:40.368879   59701 factory.go:1089] Error scheduling default/bb-65fd577957-rd7w2: pod has unbound immediate PersistentVolumeClaims; retrying
I0125 15:54:40.368895   59701 factory.go:1170] Updating pod condition for default/bb-65fd577957-rd7w2 to (PodScheduled==False, Reason=Unschedulable)
E0125 15:54:40.371173   59701 scheduler.go:478] error selecting node for pod: pod has unbound immediate PersistentVolumeClaims
I0125 15:54:40.371281   59701 scheduling_queue.go:821] About to try and schedule pod default/bb-65fd577957-rd7w2
I0125 15:54:40.371290   59701 scheduler.go:451] Attempting to schedule pod: default/bb-65fd577957-rd7w2
I0125 15:54:40.371336   59701 predicates.go:431] PVC default/pvc-vault-ro is not bound, assuming PVC matches predicate when counting limits
I0125 15:54:40.371452   59701 predicates.go:431] PVC default/pvc-vault-ro is not bound, assuming PVC matches predicate when counting limits
I0125 15:54:40.371463   59701 predicates.go:431] PVC default/pvc-vault-ro is not bound, assuming PVC matches predicate when counting limits
I0125 15:54:40.371469   59701 scheduler_binder.go:173] FindPodVolumes for pod "default/bb-65fd577957-rd7w2", node "127.0.0.1"
I0125 15:54:40.371476   59701 scheduler_binder.go:576] PVC "default/pvc-vault-ro" is not bound
E0125 15:54:40.371506   59701 factory.go:1089] Error scheduling default/bb-65fd577957-rd7w2: pod has unbound immediate PersistentVolumeClaims; retrying
I0125 15:54:40.371522   59701 factory.go:1170] Updating pod condition for default/bb-65fd577957-rd7w2 to (PodScheduled==False, Reason=Unschedulable)
E0125 15:54:40.373855   59701 scheduler.go:478] error selecting node for pod: pod has unbound immediate PersistentVolumeClaims
I0125 15:54:40.415237   59701 scheduling_queue.go:821] About to try and schedule pod default/bb-65fd577957-jflrz
I0125 15:54:40.415257   59701 scheduler.go:451] Attempting to schedule pod: default/bb-65fd577957-jflrz
I0125 15:54:40.415338   59701 predicates.go:431] PVC default/pvc-vault-ro is not bound, assuming PVC matches predicate when counting limits
I0125 15:54:40.419115   59701 predicates.go:431] PVC default/pvc-vault-ro is not bound, assuming PVC matches predicate when counting limits
I0125 15:54:40.419137   59701 predicates.go:431] PVC default/pvc-vault-ro is not bound, assuming PVC matches predicate when counting limits
I0125 15:54:40.419144   59701 scheduler_binder.go:173] FindPodVolumes for pod "default/bb-65fd577957-jflrz", node "127.0.0.1"
I0125 15:54:40.419151   59701 scheduler_binder.go:576] PVC "default/pvc-vault-ro" is not bound
E0125 15:54:40.419192   59701 factory.go:1089] Error scheduling default/bb-65fd577957-jflrz: pod has unbound immediate PersistentVolumeClaims; retrying
I0125 15:54:40.419215   59701 factory.go:1170] Updating pod condition for default/bb-65fd577957-jflrz to (PodScheduled==False, Reason=Unschedulable)
E0125 15:54:40.421781   59701 scheduler.go:478] error selecting node for pod: pod has unbound immediate PersistentVolumeClaims
I0125 15:54:40.421932   59701 scheduling_queue.go:821] About to try and schedule pod default/bb-65fd577957-jflrz
I0125 15:54:40.421943   59701 scheduler.go:451] Attempting to schedule pod: default/bb-65fd577957-jflrz
I0125 15:54:40.422010   59701 predicates.go:431] PVC default/pvc-vault-ro is not bound, assuming PVC matches predicate when counting limits
I0125 15:54:40.422063   59701 predicates.go:431] PVC default/pvc-vault-ro is not bound, assuming PVC matches predicate when counting limits
I0125 15:54:40.422069   59701 predicates.go:431] PVC default/pvc-vault-ro is not bound, assuming PVC matches predicate when counting limits
I0125 15:54:40.422074   59701 scheduler_binder.go:173] FindPodVolumes for pod "default/bb-65fd577957-jflrz", node "127.0.0.1"
I0125 15:54:40.422082   59701 scheduler_binder.go:576] PVC "default/pvc-vault-ro" is not bound
E0125 15:54:40.422131   59701 factory.go:1089] Error scheduling default/bb-65fd577957-jflrz: pod has unbound immediate PersistentVolumeClaims; retrying
I0125 15:54:40.422149   59701 factory.go:1170] Updating pod condition for default/bb-65fd577957-jflrz to (PodScheduled==False, Reason=Unschedulable)
E0125 15:54:40.437229   59701 scheduler.go:478] error selecting node for pod: pod has unbound immediate PersistentVolumeClaims
I0125 15:54:40.469575   59701 scheduling_queue.go:821] About to try and schedule pod default/bb-65fd577957-gqwk5
I0125 15:54:40.469603   59701 scheduler.go:451] Attempting to schedule pod: default/bb-65fd577957-gqwk5
I0125 15:54:40.469776   59701 predicates.go:431] PVC default/pvc-vault-ro is not bound, assuming PVC matches predicate when counting limits
I0125 15:54:40.469865   59701 predicates.go:431] PVC default/pvc-vault-ro is not bound, assuming PVC matches predicate when counting limits
I0125 15:54:40.469872   59701 predicates.go:431] PVC default/pvc-vault-ro is not bound, assuming PVC matches predicate when counting limits
I0125 15:54:40.469881   59701 scheduler_binder.go:173] FindPodVolumes for pod "default/bb-65fd577957-gqwk5", node "127.0.0.1"
I0125 15:54:40.469889   59701 scheduler_binder.go:576] PVC "default/pvc-vault-ro" is not bound
E0125 15:54:40.469943   59701 factory.go:1089] Error scheduling default/bb-65fd577957-gqwk5: pod has unbound immediate PersistentVolumeClaims; retrying
I0125 15:54:40.469971   59701 factory.go:1170] Updating pod condition for default/bb-65fd577957-gqwk5 to (PodScheduled==False, Reason=Unschedulable)
E0125 15:54:40.478615   59701 scheduler.go:478] error selecting node for pod: pod has unbound immediate PersistentVolumeClaims
I0125 15:54:40.479133   59701 scheduling_queue.go:821] About to try and schedule pod default/bb-65fd577957-gqwk5
I0125 15:54:40.479153   59701 scheduler.go:451] Attempting to schedule pod: default/bb-65fd577957-gqwk5
I0125 15:54:40.479226   59701 predicates.go:431] PVC default/pvc-vault-ro is not bound, assuming PVC matches predicate when counting limits
I0125 15:54:40.479295   59701 predicates.go:431] PVC default/pvc-vault-ro is not bound, assuming PVC matches predicate when counting limits
I0125 15:54:40.479307   59701 predicates.go:431] PVC default/pvc-vault-ro is not bound, assuming PVC matches predicate when counting limits
I0125 15:54:40.479335   59701 scheduler_binder.go:173] FindPodVolumes for pod "default/bb-65fd577957-gqwk5", node "127.0.0.1"
I0125 15:54:40.479350   59701 scheduler_binder.go:576] PVC "default/pvc-vault-ro" is not bound
E0125 15:54:40.479400   59701 factory.go:1089] Error scheduling default/bb-65fd577957-gqwk5: pod has unbound immediate PersistentVolumeClaims; retrying
I0125 15:54:40.479428   59701 factory.go:1170] Updating pod condition for default/bb-65fd577957-gqwk5 to (PodScheduled==False, Reason=Unschedulable)
E0125 15:54:40.517500   59701 scheduler.go:478] error selecting node for pod: pod has unbound immediate PersistentVolumeClaims
I0125 15:54:40.535254   59701 request.go:530] Throttling request took 55.73146ms, request: GET:https://localhost:6443/api/v1/namespaces/default/pods/bb-65fd577957-gqwk5
I0125 15:54:40.565648   59701 scheduling_queue.go:821] About to try and schedule pod default/bb-65fd577957-7mdpb
I0125 15:54:40.565669   59701 scheduler.go:451] Attempting to schedule pod: default/bb-65fd577957-7mdpb
I0125 15:54:40.565746   59701 predicates.go:431] PVC default/pvc-vault-ro is not bound, assuming PVC matches predicate when counting limits
I0125 15:54:40.565814   59701 predicates.go:431] PVC default/pvc-vault-ro is not bound, assuming PVC matches predicate when counting limits
I0125 15:54:40.565821   59701 predicates.go:431] PVC default/pvc-vault-ro is not bound, assuming PVC matches predicate when counting limits
I0125 15:54:40.565829   59701 scheduler_binder.go:173] FindPodVolumes for pod "default/bb-65fd577957-7mdpb", node "127.0.0.1"
I0125 15:54:40.565837   59701 scheduler_binder.go:576] PVC "default/pvc-vault-ro" is not bound
E0125 15:54:40.565888   59701 factory.go:1089] Error scheduling default/bb-65fd577957-7mdpb: pod has unbound immediate PersistentVolumeClaims; retrying
I0125 15:54:40.565913   59701 factory.go:1170] Updating pod condition for default/bb-65fd577957-7mdpb to (PodScheduled==False, Reason=Unschedulable)
E0125 15:54:40.569578   59701 scheduler.go:478] error selecting node for pod: pod has unbound immediate PersistentVolumeClaims
I0125 15:54:40.569828   59701 scheduling_queue.go:821] About to try and schedule pod default/bb-65fd577957-7mdpb
I0125 15:54:40.569841   59701 scheduler.go:451] Attempting to schedule pod: default/bb-65fd577957-7mdpb
I0125 15:54:40.569897   59701 predicates.go:431] PVC default/pvc-vault-ro is not bound, assuming PVC matches predicate when counting limits
I0125 15:54:40.570261   59701 predicates.go:431] PVC default/pvc-vault-ro is not bound, assuming PVC matches predicate when counting limits
I0125 15:54:40.570278   59701 predicates.go:431] PVC default/pvc-vault-ro is not bound, assuming PVC matches predicate when counting limits
I0125 15:54:40.570286   59701 scheduler_binder.go:173] FindPodVolumes for pod "default/bb-65fd577957-7mdpb", node "127.0.0.1"
I0125 15:54:40.570294   59701 scheduler_binder.go:576] PVC "default/pvc-vault-ro" is not bound
E0125 15:54:40.570339   59701 factory.go:1089] Error scheduling default/bb-65fd577957-7mdpb: pod has unbound immediate PersistentVolumeClaims; retrying
I0125 15:54:40.570361   59701 factory.go:1170] Updating pod condition for default/bb-65fd577957-7mdpb to (PodScheduled==False, Reason=Unschedulable)
E0125 15:54:40.617602   59701 scheduler.go:478] error selecting node for pod: pod has unbound immediate PersistentVolumeClaims
I0125 15:54:40.664383   59701 scheduling_queue.go:821] About to try and schedule pod default/bb-65fd577957-l8c52
I0125 15:54:40.664392   59701 scheduler.go:451] Attempting to schedule pod: default/bb-65fd577957-l8c52
I0125 15:54:40.664435   59701 predicates.go:431] PVC default/pvc-vault-ro is not bound, assuming PVC matches predicate when counting limits
I0125 15:54:40.664492   59701 predicates.go:431] PVC default/pvc-vault-ro is not bound, assuming PVC matches predicate when counting limits
I0125 15:54:40.664502   59701 predicates.go:431] PVC default/pvc-vault-ro is not bound, assuming PVC matches predicate when counting limits
I0125 15:54:40.664507   59701 scheduler_binder.go:173] FindPodVolumes for pod "default/bb-65fd577957-l8c52", node "127.0.0.1"
I0125 15:54:40.664513   59701 scheduler_binder.go:576] PVC "default/pvc-vault-ro" is not bound
E0125 15:54:40.664544   59701 factory.go:1089] Error scheduling default/bb-65fd577957-l8c52: pod has unbound immediate PersistentVolumeClaims; retrying
I0125 15:54:40.664559   59701 factory.go:1170] Updating pod condition for default/bb-65fd577957-l8c52 to (PodScheduled==False, Reason=Unschedulable)
E0125 15:54:40.667442   59701 scheduler.go:478] error selecting node for pod: pod has unbound immediate PersistentVolumeClaims
I0125 15:54:40.667516   59701 scheduling_queue.go:821] About to try and schedule pod default/bb-65fd577957-l8c52
I0125 15:54:40.667525   59701 scheduler.go:451] Attempting to schedule pod: default/bb-65fd577957-l8c52
I0125 15:54:40.667597   59701 predicates.go:431] PVC default/pvc-vault-ro is not bound, assuming PVC matches predicate when counting limits
I0125 15:54:40.667646   59701 predicates.go:431] PVC default/pvc-vault-ro is not bound, assuming PVC matches predicate when counting limits
I0125 15:54:40.667652   59701 predicates.go:431] PVC default/pvc-vault-ro is not bound, assuming PVC matches predicate when counting limits
I0125 15:54:40.667657   59701 scheduler_binder.go:173] FindPodVolumes for pod "default/bb-65fd577957-l8c52", node "127.0.0.1"
I0125 15:54:40.667663   59701 scheduler_binder.go:576] PVC "default/pvc-vault-ro" is not bound
E0125 15:54:40.667696   59701 factory.go:1089] Error scheduling default/bb-65fd577957-l8c52: pod has unbound immediate PersistentVolumeClaims; retrying
I0125 15:54:40.667712   59701 factory.go:1170] Updating pod condition for default/bb-65fd577957-l8c52 to (PodScheduled==False, Reason=Unschedulable)
E0125 15:54:40.676603   59701 scheduler.go:478] error selecting node for pod: pod has unbound immediate PersistentVolumeClaims
I0125 15:54:40.676695   59701 scheduling_queue.go:821] About to try and schedule pod default/bb-65fd577957-l8c52
I0125 15:54:40.676705   59701 scheduler.go:451] Attempting to schedule pod: default/bb-65fd577957-l8c52
I0125 15:54:40.676771   59701 predicates.go:431] PVC default/pvc-vault-ro is not bound, assuming PVC matches predicate when counting limits
I0125 15:54:40.676822   59701 predicates.go:431] PVC default/pvc-vault-ro is not bound, assuming PVC matches predicate when counting limits
I0125 15:54:40.676828   59701 predicates.go:431] PVC default/pvc-vault-ro is not bound, assuming PVC matches predicate when counting limits
I0125 15:54:40.676833   59701 scheduler_binder.go:173] FindPodVolumes for pod "default/bb-65fd577957-l8c52", node "127.0.0.1"
I0125 15:54:40.676839   59701 scheduler_binder.go:576] PVC "default/pvc-vault-ro" is not bound
E0125 15:54:40.676888   59701 factory.go:1089] Error scheduling default/bb-65fd577957-l8c52: pod has unbound immediate PersistentVolumeClaims; retrying
I0125 15:54:40.676908   59701 factory.go:1170] Updating pod condition for default/bb-65fd577957-l8c52 to (PodScheduled==False, Reason=Unschedulable)
E0125 15:54:40.716619   59701 scheduler.go:478] error selecting node for pod: pod has unbound immediate PersistentVolumeClaims
I0125 15:54:40.716668   59701 scheduling_queue.go:821] About to try and schedule pod default/bb-65fd577957-92x9g
I0125 15:54:40.716674   59701 scheduler.go:451] Attempting to schedule pod: default/bb-65fd577957-92x9g
I0125 15:54:40.716734   59701 predicates.go:431] PVC default/pvc-vault-ro is not bound, assuming PVC matches predicate when counting limits
I0125 15:54:40.716776   59701 predicates.go:431] PVC default/pvc-vault-ro is not bound, assuming PVC matches predicate when counting limits
I0125 15:54:40.716782   59701 predicates.go:431] PVC default/pvc-vault-ro is not bound, assuming PVC matches predicate when counting limits
I0125 15:54:40.716787   59701 scheduler_binder.go:173] FindPodVolumes for pod "default/bb-65fd577957-92x9g", node "127.0.0.1"
I0125 15:54:40.716793   59701 scheduler_binder.go:576] PVC "default/pvc-vault-ro" is not bound
E0125 15:54:40.716836   59701 factory.go:1089] Error scheduling default/bb-65fd577957-92x9g: pod has unbound immediate PersistentVolumeClaims; retrying
I0125 15:54:40.716851   59701 factory.go:1170] Updating pod condition for default/bb-65fd577957-92x9g to (PodScheduled==False, Reason=Unschedulable)
I0125 15:54:40.735084   59701 request.go:530] Throttling request took 58.083657ms, request: GET:https://localhost:6443/api/v1/namespaces/default/pods/bb-65fd577957-l8c52
E0125 15:54:40.759806   59701 scheduler.go:478] error selecting node for pod: pod has unbound immediate PersistentVolumeClaims
I0125 15:54:40.759857   59701 scheduling_queue.go:821] About to try and schedule pod default/bb-65fd577957-92x9g
I0125 15:54:40.759869   59701 scheduler.go:451] Attempting to schedule pod: default/bb-65fd577957-92x9g
I0125 15:54:40.759960   59701 predicates.go:431] PVC default/pvc-vault-ro is not bound, assuming PVC matches predicate when counting limits
I0125 15:54:40.760025   59701 predicates.go:431] PVC default/pvc-vault-ro is not bound, assuming PVC matches predicate when counting limits
I0125 15:54:40.760034   59701 predicates.go:431] PVC default/pvc-vault-ro is not bound, assuming PVC matches predicate when counting limits
I0125 15:54:40.760043   59701 scheduler_binder.go:173] FindPodVolumes for pod "default/bb-65fd577957-92x9g", node "127.0.0.1"
I0125 15:54:40.760051   59701 scheduler_binder.go:576] PVC "default/pvc-vault-ro" is not bound
E0125 15:54:40.760121   59701 factory.go:1089] Error scheduling default/bb-65fd577957-92x9g: pod has unbound immediate PersistentVolumeClaims; retrying
I0125 15:54:40.760153   59701 factory.go:1170] Updating pod condition for default/bb-65fd577957-92x9g to (PodScheduled==False, Reason=Unschedulable)
I0125 15:54:40.775161   59701 request.go:530] Throttling request took 58.221321ms, request: GET:https://localhost:6443/api/v1/namespaces/default/pods/bb-65fd577957-92x9g
E0125 15:54:40.798959   59701 scheduler.go:478] error selecting node for pod: pod has unbound immediate PersistentVolumeClaims
I0125 15:54:40.799095   59701 scheduling_queue.go:821] About to try and schedule pod default/bb-65fd577957-8npmd
I0125 15:54:40.799106   59701 scheduler.go:451] Attempting to schedule pod: default/bb-65fd577957-8npmd
I0125 15:54:40.799166   59701 predicates.go:431] PVC default/pvc-vault-ro is not bound, assuming PVC matches predicate when counting limits
I0125 15:54:40.799230   59701 predicates.go:431] PVC default/pvc-vault-ro is not bound, assuming PVC matches predicate when counting limits
I0125 15:54:40.799240   59701 predicates.go:431] PVC default/pvc-vault-ro is not bound, assuming PVC matches predicate when counting limits
I0125 15:54:40.799247   59701 scheduler_binder.go:173] FindPodVolumes for pod "default/bb-65fd577957-8npmd", node "127.0.0.1"
I0125 15:54:40.799256   59701 scheduler_binder.go:576] PVC "default/pvc-vault-ro" is not bound
E0125 15:54:40.799324   59701 factory.go:1089] Error scheduling default/bb-65fd577957-8npmd: pod has unbound immediate PersistentVolumeClaims; retrying
I0125 15:54:40.799349   59701 factory.go:1170] Updating pod condition for default/bb-65fd577957-8npmd to (PodScheduled==False, Reason=Unschedulable)
I0125 15:54:40.814918   59701 request.go:530] Throttling request took 54.693258ms, request: GET:https://localhost:6443/api/v1/namespaces/default/pods/bb-65fd577957-92x9g
E0125 15:54:40.837016   59701 scheduler.go:478] error selecting node for pod: pod has unbound immediate PersistentVolumeClaims
I0125 15:54:40.837157   59701 scheduling_queue.go:821] About to try and schedule pod default/bb-65fd577957-btnr8
I0125 15:54:40.837165   59701 scheduler.go:451] Attempting to schedule pod: default/bb-65fd577957-btnr8
I0125 15:54:40.837237   59701 predicates.go:431] PVC default/pvc-vault-ro is not bound, assuming PVC matches predicate when counting limits
I0125 15:54:40.837279   59701 predicates.go:431] PVC default/pvc-vault-ro is not bound, assuming PVC matches predicate when counting limits
I0125 15:54:40.837285   59701 predicates.go:431] PVC default/pvc-vault-ro is not bound, assuming PVC matches predicate when counting limits
I0125 15:54:40.837290   59701 scheduler_binder.go:173] FindPodVolumes for pod "default/bb-65fd577957-btnr8", node "127.0.0.1"
I0125 15:54:40.837296   59701 scheduler_binder.go:576] PVC "default/pvc-vault-ro" is not bound
E0125 15:54:40.837342   59701 factory.go:1089] Error scheduling default/bb-65fd577957-btnr8: pod has unbound immediate PersistentVolumeClaims; retrying
I0125 15:54:40.837359   59701 factory.go:1170] Updating pod condition for default/bb-65fd577957-btnr8 to (PodScheduled==False, Reason=Unschedulable)
I0125 15:54:40.855059   59701 request.go:530] Throttling request took 55.622002ms, request: GET:https://localhost:6443/api/v1/namespaces/default/pods/bb-65fd577957-8npmd
I0125 15:54:40.895023   59701 request.go:530] Throttling request took 57.610208ms, request: PUT:https://localhost:6443/api/v1/namespaces/default/pods/bb-65fd577957-btnr8/status
E0125 15:54:40.898824   59701 scheduler.go:478] error selecting node for pod: pod has unbound immediate PersistentVolumeClaims
I0125 15:54:40.899048   59701 scheduling_queue.go:821] About to try and schedule pod default/bb-65fd577957-8npmd
I0125 15:54:40.899057   59701 scheduler.go:451] Attempting to schedule pod: default/bb-65fd577957-8npmd
I0125 15:54:40.899101   59701 predicates.go:431] PVC default/pvc-vault-ro is not bound, assuming PVC matches predicate when counting limits
I0125 15:54:40.899140   59701 predicates.go:431] PVC default/pvc-vault-ro is not bound, assuming PVC matches predicate when counting limits
I0125 15:54:40.899146   59701 predicates.go:431] PVC default/pvc-vault-ro is not bound, assuming PVC matches predicate when counting limits
I0125 15:54:40.899151   59701 scheduler_binder.go:173] FindPodVolumes for pod "default/bb-65fd577957-8npmd", node "127.0.0.1"
I0125 15:54:40.899156   59701 scheduler_binder.go:576] PVC "default/pvc-vault-ro" is not bound
E0125 15:54:40.899180   59701 factory.go:1089] Error scheduling default/bb-65fd577957-8npmd: pod has unbound immediate PersistentVolumeClaims; retrying
I0125 15:54:40.899195   59701 factory.go:1170] Updating pod condition for default/bb-65fd577957-8npmd to (PodScheduled==False, Reason=Unschedulable)
E0125 15:54:40.917390   59701 scheduler.go:478] error selecting node for pod: pod has unbound immediate PersistentVolumeClaims
I0125 15:54:40.917508   59701 scheduling_queue.go:821] About to try and schedule pod default/bb-65fd577957-btnr8
I0125 15:54:40.917516   59701 scheduler.go:451] Attempting to schedule pod: default/bb-65fd577957-btnr8
I0125 15:54:40.917577   59701 predicates.go:431] PVC default/pvc-vault-ro is not bound, assuming PVC matches predicate when counting limits
I0125 15:54:40.917628   59701 predicates.go:431] PVC default/pvc-vault-ro is not bound, assuming PVC matches predicate when counting limits
I0125 15:54:40.917634   59701 predicates.go:431] PVC default/pvc-vault-ro is not bound, assuming PVC matches predicate when counting limits
I0125 15:54:40.917639   59701 scheduler_binder.go:173] FindPodVolumes for pod "default/bb-65fd577957-btnr8", node "127.0.0.1"
I0125 15:54:40.917646   59701 scheduler_binder.go:576] PVC "default/pvc-vault-ro" is not bound
E0125 15:54:40.917680   59701 factory.go:1089] Error scheduling default/bb-65fd577957-btnr8: pod has unbound immediate PersistentVolumeClaims; retrying
I0125 15:54:40.917702   59701 factory.go:1170] Updating pod condition for default/bb-65fd577957-btnr8 to (PodScheduled==False, Reason=Unschedulable)
E0125 15:54:40.957962   59701 scheduler.go:478] error selecting node for pod: pod has unbound immediate PersistentVolumeClaims
I0125 15:54:40.958066   59701 scheduling_queue.go:821] About to try and schedule pod default/bb-65fd577957-dg54f
I0125 15:54:40.958076   59701 scheduler.go:451] Attempting to schedule pod: default/bb-65fd577957-dg54f
I0125 15:54:40.958201   59701 predicates.go:431] PVC default/pvc-vault-ro is not bound, assuming PVC matches predicate when counting limits
I0125 15:54:40.958342   59701 predicates.go:431] PVC default/pvc-vault-ro is not bound, assuming PVC matches predicate when counting limits
I0125 15:54:40.958358   59701 predicates.go:431] PVC default/pvc-vault-ro is not bound, assuming PVC matches predicate when counting limits
I0125 15:54:40.958366   59701 scheduler_binder.go:173] FindPodVolumes for pod "default/bb-65fd577957-dg54f", node "127.0.0.1"
I0125 15:54:40.958376   59701 scheduler_binder.go:576] PVC "default/pvc-vault-ro" is not bound
E0125 15:54:40.958432   59701 factory.go:1089] Error scheduling default/bb-65fd577957-dg54f: pod has unbound immediate PersistentVolumeClaims; retrying
I0125 15:54:40.958453   59701 factory.go:1170] Updating pod condition for default/bb-65fd577957-dg54f to (PodScheduled==False, Reason=Unschedulable)
I0125 15:54:40.975010   59701 request.go:530] Throttling request took 57.102116ms, request: GET:https://localhost:6443/api/v1/namespaces/default/pods/bb-65fd577957-btnr8
E0125 15:54:40.997976   59701 scheduler.go:478] error selecting node for pod: pod has unbound immediate PersistentVolumeClaims
I0125 15:54:40.998090   59701 scheduling_queue.go:821] About to try and schedule pod default/bb-65fd577957-z458j
I0125 15:54:40.998117   59701 scheduler.go:451] Attempting to schedule pod: default/bb-65fd577957-z458j
I0125 15:54:40.998177   59701 predicates.go:431] PVC default/pvc-vault-ro is not bound, assuming PVC matches predicate when counting limits
I0125 15:54:40.998233   59701 predicates.go:431] PVC default/pvc-vault-ro is not bound, assuming PVC matches predicate when counting limits
I0125 15:54:40.998240   59701 predicates.go:431] PVC default/pvc-vault-ro is not bound, assuming PVC matches predicate when counting limits
I0125 15:54:40.998246   59701 scheduler_binder.go:173] FindPodVolumes for pod "default/bb-65fd577957-z458j", node "127.0.0.1"
I0125 15:54:40.998253   59701 scheduler_binder.go:576] PVC "default/pvc-vault-ro" is not bound
E0125 15:54:40.998316   59701 factory.go:1089] Error scheduling default/bb-65fd577957-z458j: pod has unbound immediate PersistentVolumeClaims; retrying
I0125 15:54:40.998339   59701 factory.go:1170] Updating pod condition for default/bb-65fd577957-z458j to (PodScheduled==False, Reason=Unschedulable)
I0125 15:54:41.015077   59701 request.go:530] Throttling request took 56.542912ms, request: GET:https://localhost:6443/api/v1/namespaces/default/pods/bb-65fd577957-dg54f
E0125 15:54:41.038870   59701 scheduler.go:478] error selecting node for pod: pod has unbound immediate PersistentVolumeClaims
I0125 15:54:41.039013   59701 scheduling_queue.go:821] About to try and schedule pod default/bb-65fd577957-xktdz
I0125 15:54:41.039025   59701 scheduler.go:451] Attempting to schedule pod: default/bb-65fd577957-xktdz
I0125 15:54:41.039092   59701 predicates.go:431] PVC default/pvc-vault-ro is not bound, assuming PVC matches predicate when counting limits
I0125 15:54:41.039147   59701 predicates.go:431] PVC default/pvc-vault-ro is not bound, assuming PVC matches predicate when counting limits
I0125 15:54:41.039154   59701 predicates.go:431] PVC default/pvc-vault-ro is not bound, assuming PVC matches predicate when counting limits
I0125 15:54:41.039161   59701 scheduler_binder.go:173] FindPodVolumes for pod "default/bb-65fd577957-xktdz", node "127.0.0.1"
I0125 15:54:41.039169   59701 scheduler_binder.go:576] PVC "default/pvc-vault-ro" is not bound
E0125 15:54:41.039234   59701 factory.go:1089] Error scheduling default/bb-65fd577957-xktdz: pod has unbound immediate PersistentVolumeClaims; retrying
I0125 15:54:41.039276   59701 factory.go:1170] Updating pod condition for default/bb-65fd577957-xktdz to (PodScheduled==False, Reason=Unschedulable)
I0125 15:54:41.054938   59701 request.go:530] Throttling request took 56.449742ms, request: GET:https://localhost:6443/api/v1/namespaces/default/pods/bb-65fd577957-z458j
I0125 15:54:41.095696   59701 request.go:530] Throttling request took 56.306582ms, request: PUT:https://localhost:6443/api/v1/namespaces/default/pods/bb-65fd577957-xktdz/status
E0125 15:54:41.098757   59701 scheduler.go:478] error selecting node for pod: pod has unbound immediate PersistentVolumeClaims
I0125 15:54:41.098877   59701 scheduling_queue.go:821] About to try and schedule pod default/bb-65fd577957-z458j
I0125 15:54:41.098887   59701 scheduler.go:451] Attempting to schedule pod: default/bb-65fd577957-z458j
I0125 15:54:41.098948   59701 predicates.go:431] PVC default/pvc-vault-ro is not bound, assuming PVC matches predicate when counting limits
I0125 15:54:41.098997   59701 predicates.go:431] PVC default/pvc-vault-ro is not bound, assuming PVC matches predicate when counting limits
I0125 15:54:41.099005   59701 predicates.go:431] PVC default/pvc-vault-ro is not bound, assuming PVC matches predicate when counting limits
I0125 15:54:41.099011   59701 scheduler_binder.go:173] FindPodVolumes for pod "default/bb-65fd577957-z458j", node "127.0.0.1"
I0125 15:54:41.099019   59701 scheduler_binder.go:576] PVC "default/pvc-vault-ro" is not bound
E0125 15:54:41.099076   59701 factory.go:1089] Error scheduling default/bb-65fd577957-z458j: pod has unbound immediate PersistentVolumeClaims; retrying
I0125 15:54:41.099099   59701 factory.go:1170] Updating pod condition for default/bb-65fd577957-z458j to (PodScheduled==False, Reason=Unschedulable)
E0125 15:54:41.117054   59701 scheduler.go:478] error selecting node for pod: pod has unbound immediate PersistentVolumeClaims
I0125 15:54:41.117217   59701 scheduling_queue.go:821] About to try and schedule pod default/bb-65fd577957-dg54f
I0125 15:54:41.117229   59701 scheduler.go:451] Attempting to schedule pod: default/bb-65fd577957-dg54f
I0125 15:54:41.117293   59701 predicates.go:431] PVC default/pvc-vault-ro is not bound, assuming PVC matches predicate when counting limits
I0125 15:54:41.117340   59701 predicates.go:431] PVC default/pvc-vault-ro is not bound, assuming PVC matches predicate when counting limits
I0125 15:54:41.117348   59701 predicates.go:431] PVC default/pvc-vault-ro is not bound, assuming PVC matches predicate when counting limits
I0125 15:54:41.117354   59701 scheduler_binder.go:173] FindPodVolumes for pod "default/bb-65fd577957-dg54f", node "127.0.0.1"
I0125 15:54:41.117361   59701 scheduler_binder.go:576] PVC "default/pvc-vault-ro" is not bound
E0125 15:54:41.117394   59701 factory.go:1089] Error scheduling default/bb-65fd577957-dg54f: pod has unbound immediate PersistentVolumeClaims; retrying
I0125 15:54:41.117414   59701 factory.go:1170] Updating pod condition for default/bb-65fd577957-dg54f to (PodScheduled==False, Reason=Unschedulable)
E0125 15:54:41.157178   59701 scheduler.go:478] error selecting node for pod: pod has unbound immediate PersistentVolumeClaims
I0125 15:54:41.157315   59701 scheduling_queue.go:821] About to try and schedule pod default/bb-65fd577957-z458j
I0125 15:54:41.157324   59701 scheduler.go:451] Attempting to schedule pod: default/bb-65fd577957-z458j
I0125 15:54:41.157393   59701 predicates.go:431] PVC default/pvc-vault-ro is not bound, assuming PVC matches predicate when counting limits
I0125 15:54:41.157440   59701 predicates.go:431] PVC default/pvc-vault-ro is not bound, assuming PVC matches predicate when counting limits
I0125 15:54:41.157446   59701 predicates.go:431] PVC default/pvc-vault-ro is not bound, assuming PVC matches predicate when counting limits
I0125 15:54:41.157451   59701 scheduler_binder.go:173] FindPodVolumes for pod "default/bb-65fd577957-z458j", node "127.0.0.1"
I0125 15:54:41.157457   59701 scheduler_binder.go:576] PVC "default/pvc-vault-ro" is not bound
E0125 15:54:41.157506   59701 factory.go:1089] Error scheduling default/bb-65fd577957-z458j: pod has unbound immediate PersistentVolumeClaims; retrying
I0125 15:54:41.157527   59701 factory.go:1170] Updating pod condition for default/bb-65fd577957-z458j to (PodScheduled==False, Reason=Unschedulable)
I0125 15:54:41.175096   59701 request.go:530] Throttling request took 57.548833ms, request: GET:https://localhost:6443/api/v1/namespaces/default/pods/bb-65fd577957-dg54f
E0125 15:54:41.198984   59701 scheduler.go:478] error selecting node for pod: pod has unbound immediate PersistentVolumeClaims
I0125 15:54:41.199088   59701 scheduling_queue.go:821] About to try and schedule pod default/bb-65fd577957-vlvq5
I0125 15:54:41.199097   59701 scheduler.go:451] Attempting to schedule pod: default/bb-65fd577957-vlvq5
I0125 15:54:41.199154   59701 predicates.go:431] PVC default/pvc-vault-ro is not bound, assuming PVC matches predicate when counting limits
I0125 15:54:41.199209   59701 predicates.go:431] PVC default/pvc-vault-ro is not bound, assuming PVC matches predicate when counting limits
I0125 15:54:41.199216   59701 predicates.go:431] PVC default/pvc-vault-ro is not bound, assuming PVC matches predicate when counting limits
I0125 15:54:41.199223   59701 scheduler_binder.go:173] FindPodVolumes for pod "default/bb-65fd577957-vlvq5", node "127.0.0.1"
I0125 15:54:41.199230   59701 scheduler_binder.go:576] PVC "default/pvc-vault-ro" is not bound
E0125 15:54:41.199263   59701 factory.go:1089] Error scheduling default/bb-65fd577957-vlvq5: pod has unbound immediate PersistentVolumeClaims; retrying
I0125 15:54:41.199281   59701 factory.go:1170] Updating pod condition for default/bb-65fd577957-vlvq5 to (PodScheduled==False, Reason=Unschedulable)
I0125 15:54:41.214937   59701 request.go:530] Throttling request took 57.347203ms, request: GET:https://localhost:6443/api/v1/namespaces/default/pods/bb-65fd577957-z458j
E0125 15:54:41.240968   59701 scheduler.go:478] error selecting node for pod: pod has unbound immediate PersistentVolumeClaims
I0125 15:54:41.241084   59701 scheduling_queue.go:821] About to try and schedule pod default/bb-65fd577957-t9wcq
I0125 15:54:41.241095   59701 scheduler.go:451] Attempting to schedule pod: default/bb-65fd577957-t9wcq
I0125 15:54:41.241158   59701 predicates.go:431] PVC default/pvc-vault-ro is not bound, assuming PVC matches predicate when counting limits
I0125 15:54:41.241210   59701 predicates.go:431] PVC default/pvc-vault-ro is not bound, assuming PVC matches predicate when counting limits
I0125 15:54:41.241217   59701 predicates.go:431] PVC default/pvc-vault-ro is not bound, assuming PVC matches predicate when counting limits
I0125 15:54:41.241224   59701 scheduler_binder.go:173] FindPodVolumes for pod "default/bb-65fd577957-t9wcq", node "127.0.0.1"
I0125 15:54:41.241232   59701 scheduler_binder.go:576] PVC "default/pvc-vault-ro" is not bound
E0125 15:54:41.241291   59701 factory.go:1089] Error scheduling default/bb-65fd577957-t9wcq: pod has unbound immediate PersistentVolumeClaims; retrying
I0125 15:54:41.241322   59701 factory.go:1170] Updating pod condition for default/bb-65fd577957-t9wcq to (PodScheduled==False, Reason=Unschedulable)
I0125 15:54:41.254829   59701 request.go:530] Throttling request took 55.41797ms, request: GET:https://localhost:6443/api/v1/namespaces/default/pods/bb-65fd577957-vlvq5
E0125 15:54:41.277951   59701 scheduler.go:478] error selecting node for pod: pod has unbound immediate PersistentVolumeClaims
I0125 15:54:41.278069   59701 scheduling_queue.go:821] About to try and schedule pod default/bb-65fd577957-vlvq5
I0125 15:54:41.278080   59701 scheduler.go:451] Attempting to schedule pod: default/bb-65fd577957-vlvq5
I0125 15:54:41.278135   59701 predicates.go:431] PVC default/pvc-vault-ro is not bound, assuming PVC matches predicate when counting limits
I0125 15:54:41.278268   59701 predicates.go:431] PVC default/pvc-vault-ro is not bound, assuming PVC matches predicate when counting limits
I0125 15:54:41.278279   59701 predicates.go:431] PVC default/pvc-vault-ro is not bound, assuming PVC matches predicate when counting limits
I0125 15:54:41.278285   59701 scheduler_binder.go:173] FindPodVolumes for pod "default/bb-65fd577957-vlvq5", node "127.0.0.1"
I0125 15:54:41.278291   59701 scheduler_binder.go:576] PVC "default/pvc-vault-ro" is not bound
E0125 15:54:41.278346   59701 factory.go:1089] Error scheduling default/bb-65fd577957-vlvq5: pod has unbound immediate PersistentVolumeClaims; retrying
I0125 15:54:41.278367   59701 factory.go:1170] Updating pod condition for default/bb-65fd577957-vlvq5 to (PodScheduled==False, Reason=Unschedulable)
I0125 15:54:41.295167   59701 request.go:530] Throttling request took 53.667779ms, request: GET:https://localhost:6443/api/v1/namespaces/default/pods/bb-65fd577957-t9wcq
E0125 15:54:41.317245   59701 scheduler.go:478] error selecting node for pod: pod has unbound immediate PersistentVolumeClaims
I0125 15:54:41.317290   59701 scheduling_queue.go:821] About to try and schedule pod default/bb-65fd577957-t9wcq
I0125 15:54:41.317301   59701 scheduler.go:451] Attempting to schedule pod: default/bb-65fd577957-t9wcq
I0125 15:54:41.317372   59701 predicates.go:431] PVC default/pvc-vault-ro is not bound, assuming PVC matches predicate when counting limits
I0125 15:54:41.317424   59701 predicates.go:431] PVC default/pvc-vault-ro is not bound, assuming PVC matches predicate when counting limits
I0125 15:54:41.317432   59701 predicates.go:431] PVC default/pvc-vault-ro is not bound, assuming PVC matches predicate when counting limits
I0125 15:54:41.317438   59701 scheduler_binder.go:173] FindPodVolumes for pod "default/bb-65fd577957-t9wcq", node "127.0.0.1"
I0125 15:54:41.317445   59701 scheduler_binder.go:576] PVC "default/pvc-vault-ro" is not bound
E0125 15:54:41.317503   59701 factory.go:1089] Error scheduling default/bb-65fd577957-t9wcq: pod has unbound immediate PersistentVolumeClaims; retrying
I0125 15:54:41.317522   59701 factory.go:1170] Updating pod condition for default/bb-65fd577957-t9wcq to (PodScheduled==False, Reason=Unschedulable)
I0125 15:54:41.334900   59701 request.go:530] Throttling request took 56.387529ms, request: GET:https://localhost:6443/api/v1/namespaces/default/pods/bb-65fd577957-vlvq5
I0125 15:54:41.338198   59701 backoff_utils.go:79] Backing off 2s
E0125 15:54:41.357747   59701 scheduler.go:478] error selecting node for pod: pod has unbound immediate PersistentVolumeClaims
I0125 15:54:41.357805   59701 scheduling_queue.go:821] About to try and schedule pod default/bb-65fd577957-6bjzp
I0125 15:54:41.357816   59701 scheduler.go:451] Attempting to schedule pod: default/bb-65fd577957-6bjzp
I0125 15:54:41.357905   59701 predicates.go:431] PVC default/pvc-vault-ro is not bound, assuming PVC matches predicate when counting limits
I0125 15:54:41.357958   59701 predicates.go:431] PVC default/pvc-vault-ro is not bound, assuming PVC matches predicate when counting limits
I0125 15:54:41.357966   59701 predicates.go:431] PVC default/pvc-vault-ro is not bound, assuming PVC matches predicate when counting limits
I0125 15:54:41.357980   59701 scheduler_binder.go:173] FindPodVolumes for pod "default/bb-65fd577957-6bjzp", node "127.0.0.1"
I0125 15:54:41.357988   59701 scheduler_binder.go:576] PVC "default/pvc-vault-ro" is not bound
E0125 15:54:41.358046   59701 factory.go:1089] Error scheduling default/bb-65fd577957-6bjzp: pod has unbound immediate PersistentVolumeClaims; retrying
I0125 15:54:41.358076   59701 factory.go:1170] Updating pod condition for default/bb-65fd577957-6bjzp to (PodScheduled==False, Reason=Unschedulable)
I0125 15:54:41.375078   59701 request.go:530] Throttling request took 57.4685ms, request: GET:https://localhost:6443/api/v1/namespaces/default/pods/bb-65fd577957-t9wcq
I0125 15:54:41.377289   59701 backoff_utils.go:79] Backing off 2s
E0125 15:54:41.399542   59701 scheduler.go:478] error selecting node for pod: pod has unbound immediate PersistentVolumeClaims
I0125 15:54:41.399684   59701 scheduling_queue.go:821] About to try and schedule pod default/bb-65fd577957-qhw28
I0125 15:54:41.399698   59701 scheduler.go:451] Attempting to schedule pod: default/bb-65fd577957-qhw28
I0125 15:54:41.399763   59701 predicates.go:431] PVC default/pvc-vault-ro is not bound, assuming PVC matches predicate when counting limits
I0125 15:54:41.399823   59701 predicates.go:431] PVC default/pvc-vault-ro is not bound, assuming PVC matches predicate when counting limits
I0125 15:54:41.399832   59701 predicates.go:431] PVC default/pvc-vault-ro is not bound, assuming PVC matches predicate when counting limits
I0125 15:54:41.399839   59701 scheduler_binder.go:173] FindPodVolumes for pod "default/bb-65fd577957-qhw28", node "127.0.0.1"
I0125 15:54:41.399848   59701 scheduler_binder.go:576] PVC "default/pvc-vault-ro" is not bound
E0125 15:54:41.399918   59701 factory.go:1089] Error scheduling default/bb-65fd577957-qhw28: pod has unbound immediate PersistentVolumeClaims; retrying
I0125 15:54:41.399946   59701 factory.go:1170] Updating pod condition for default/bb-65fd577957-qhw28 to (PodScheduled==False, Reason=Unschedulable)
I0125 15:54:41.414864   59701 request.go:530] Throttling request took 56.645137ms, request: GET:https://localhost:6443/api/v1/namespaces/default/pods/bb-65fd577957-6bjzp
I0125 15:54:41.456586   59701 request.go:530] Throttling request took 56.564023ms, request: PUT:https://localhost:6443/api/v1/namespaces/default/pods/bb-65fd577957-qhw28/status
E0125 15:54:41.459015   59701 scheduler.go:478] error selecting node for pod: pod has unbound immediate PersistentVolumeClaims
I0125 15:54:41.459066   59701 scheduling_queue.go:821] About to try and schedule pod default/bb-65fd577957-6bjzp
I0125 15:54:41.459075   59701 scheduler.go:451] Attempting to schedule pod: default/bb-65fd577957-6bjzp
I0125 15:54:41.459125   59701 predicates.go:431] PVC default/pvc-vault-ro is not bound, assuming PVC matches predicate when counting limits
I0125 15:54:41.459165   59701 predicates.go:431] PVC default/pvc-vault-ro is not bound, assuming PVC matches predicate when counting limits
I0125 15:54:41.459172   59701 predicates.go:431] PVC default/pvc-vault-ro is not bound, assuming PVC matches predicate when counting limits
I0125 15:54:41.459177   59701 scheduler_binder.go:173] FindPodVolumes for pod "default/bb-65fd577957-6bjzp", node "127.0.0.1"
I0125 15:54:41.459184   59701 scheduler_binder.go:576] PVC "default/pvc-vault-ro" is not bound
E0125 15:54:41.459282   59701 factory.go:1089] Error scheduling default/bb-65fd577957-6bjzp: pod has unbound immediate PersistentVolumeClaims; retrying
I0125 15:54:41.459318   59701 factory.go:1170] Updating pod condition for default/bb-65fd577957-6bjzp to (PodScheduled==False, Reason=Unschedulable)
E0125 15:54:41.497778   59701 scheduler.go:478] error selecting node for pod: pod has unbound immediate PersistentVolumeClaims
I0125 15:54:41.497845   59701 scheduling_queue.go:821] About to try and schedule pod default/bb-65fd577957-qhw28
I0125 15:54:41.497852   59701 scheduler.go:451] Attempting to schedule pod: default/bb-65fd577957-qhw28
I0125 15:54:41.497908   59701 predicates.go:431] PVC default/pvc-vault-ro is not bound, assuming PVC matches predicate when counting limits
I0125 15:54:41.497955   59701 predicates.go:431] PVC default/pvc-vault-ro is not bound, assuming PVC matches predicate when counting limits
I0125 15:54:41.497961   59701 predicates.go:431] PVC default/pvc-vault-ro is not bound, assuming PVC matches predicate when counting limits
I0125 15:54:41.497966   59701 scheduler_binder.go:173] FindPodVolumes for pod "default/bb-65fd577957-qhw28", node "127.0.0.1"
I0125 15:54:41.497973   59701 scheduler_binder.go:576] PVC "default/pvc-vault-ro" is not bound
E0125 15:54:41.498018   59701 factory.go:1089] Error scheduling default/bb-65fd577957-qhw28: pod has unbound immediate PersistentVolumeClaims; retrying
I0125 15:54:41.498037   59701 factory.go:1170] Updating pod condition for default/bb-65fd577957-qhw28 to (PodScheduled==False, Reason=Unschedulable)
E0125 15:54:41.520570   59701 scheduler.go:478] error selecting node for pod: pod has unbound immediate PersistentVolumeClaims
I0125 15:54:41.520701   59701 scheduling_queue.go:821] About to try and schedule pod default/bb-65fd577957-cddxl
I0125 15:54:41.520710   59701 scheduler.go:451] Attempting to schedule pod: default/bb-65fd577957-cddxl
I0125 15:54:41.520772   59701 predicates.go:431] PVC default/pvc-vault-ro is not bound, assuming PVC matches predicate when counting limits
I0125 15:54:41.520815   59701 predicates.go:431] PVC default/pvc-vault-ro is not bound, assuming PVC matches predicate when counting limits
I0125 15:54:41.520821   59701 predicates.go:431] PVC default/pvc-vault-ro is not bound, assuming PVC matches predicate when counting limits
I0125 15:54:41.520827   59701 scheduler_binder.go:173] FindPodVolumes for pod "default/bb-65fd577957-cddxl", node "127.0.0.1"
I0125 15:54:41.520833   59701 scheduler_binder.go:576] PVC "default/pvc-vault-ro" is not bound
E0125 15:54:41.520867   59701 factory.go:1089] Error scheduling default/bb-65fd577957-cddxl: pod has unbound immediate PersistentVolumeClaims; retrying
I0125 15:54:41.520883   59701 factory.go:1170] Updating pod condition for default/bb-65fd577957-cddxl to (PodScheduled==False, Reason=Unschedulable)
E0125 15:54:41.557089   59701 scheduler.go:478] error selecting node for pod: pod has unbound immediate PersistentVolumeClaims
I0125 15:54:41.557123   59701 scheduling_queue.go:821] About to try and schedule pod default/bb-65fd577957-z28hj
I0125 15:54:41.557127   59701 scheduler.go:451] Attempting to schedule pod: default/bb-65fd577957-z28hj
I0125 15:54:41.557174   59701 predicates.go:431] PVC default/pvc-vault-ro is not bound, assuming PVC matches predicate when counting limits
I0125 15:54:41.557216   59701 predicates.go:431] PVC default/pvc-vault-ro is not bound, assuming PVC matches predicate when counting limits
I0125 15:54:41.557222   59701 predicates.go:431] PVC default/pvc-vault-ro is not bound, assuming PVC matches predicate when counting limits
I0125 15:54:41.557226   59701 scheduler_binder.go:173] FindPodVolumes for pod "default/bb-65fd577957-z28hj", node "127.0.0.1"
I0125 15:54:41.557232   59701 scheduler_binder.go:576] PVC "default/pvc-vault-ro" is not bound
E0125 15:54:41.557280   59701 factory.go:1089] Error scheduling default/bb-65fd577957-z28hj: pod has unbound immediate PersistentVolumeClaims; retrying
I0125 15:54:41.557296   59701 factory.go:1170] Updating pod condition for default/bb-65fd577957-z28hj to (PodScheduled==False, Reason=Unschedulable)
I0125 15:54:41.574798   59701 request.go:530] Throttling request took 53.753166ms, request: GET:https://localhost:6443/api/v1/namespaces/default/pods/bb-65fd577957-cddxl
E0125 15:54:41.597476   59701 scheduler.go:478] error selecting node for pod: pod has unbound immediate PersistentVolumeClaims
I0125 15:54:41.597726   59701 scheduling_queue.go:821] About to try and schedule pod default/bb-65fd577957-cddxl
I0125 15:54:41.597734   59701 scheduler.go:451] Attempting to schedule pod: default/bb-65fd577957-cddxl
I0125 15:54:41.597816   59701 predicates.go:431] PVC default/pvc-vault-ro is not bound, assuming PVC matches predicate when counting limits
I0125 15:54:41.597893   59701 predicates.go:431] PVC default/pvc-vault-ro is not bound, assuming PVC matches predicate when counting limits
I0125 15:54:41.597905   59701 predicates.go:431] PVC default/pvc-vault-ro is not bound, assuming PVC matches predicate when counting limits
I0125 15:54:41.597912   59701 scheduler_binder.go:173] FindPodVolumes for pod "default/bb-65fd577957-cddxl", node "127.0.0.1"
I0125 15:54:41.597940   59701 scheduler_binder.go:576] PVC "default/pvc-vault-ro" is not bound
E0125 15:54:41.597981   59701 factory.go:1089] Error scheduling default/bb-65fd577957-cddxl: pod has unbound immediate PersistentVolumeClaims; retrying
I0125 15:54:41.598035   59701 factory.go:1170] Updating pod condition for default/bb-65fd577957-cddxl to (PodScheduled==False, Reason=Unschedulable)
I0125 15:54:41.615015   59701 request.go:530] Throttling request took 57.647109ms, request: GET:https://localhost:6443/api/v1/namespaces/default/pods/bb-65fd577957-z28hj
I0125 15:54:41.655170   59701 request.go:530] Throttling request took 57.038915ms, request: PUT:https://localhost:6443/api/v1/namespaces/default/pods/bb-65fd577957-cddxl/status
E0125 15:54:41.657871   59701 scheduler.go:478] error selecting node for pod: pod has unbound immediate PersistentVolumeClaims
I0125 15:54:41.658001   59701 scheduling_queue.go:821] About to try and schedule pod default/bb-65fd577957-z28hj
I0125 15:54:41.658008   59701 scheduler.go:451] Attempting to schedule pod: default/bb-65fd577957-z28hj
I0125 15:54:41.658075   59701 predicates.go:431] PVC default/pvc-vault-ro is not bound, assuming PVC matches predicate when counting limits
I0125 15:54:41.658119   59701 predicates.go:431] PVC default/pvc-vault-ro is not bound, assuming PVC matches predicate when counting limits
I0125 15:54:41.658125   59701 predicates.go:431] PVC default/pvc-vault-ro is not bound, assuming PVC matches predicate when counting limits
I0125 15:54:41.658130   59701 scheduler_binder.go:173] FindPodVolumes for pod "default/bb-65fd577957-z28hj", node "127.0.0.1"
I0125 15:54:41.658135   59701 scheduler_binder.go:576] PVC "default/pvc-vault-ro" is not bound
E0125 15:54:41.658178   59701 factory.go:1089] Error scheduling default/bb-65fd577957-z28hj: pod has unbound immediate PersistentVolumeClaims; retrying
I0125 15:54:41.658209   59701 factory.go:1170] Updating pod condition for default/bb-65fd577957-z28hj to (PodScheduled==False, Reason=Unschedulable)
E0125 15:54:41.696929   59701 scheduler.go:478] error selecting node for pod: pod has unbound immediate PersistentVolumeClaims
I0125 15:54:41.697056   59701 scheduling_queue.go:821] About to try and schedule pod default/bb-65fd577957-vqdgt
I0125 15:54:41.697064   59701 scheduler.go:451] Attempting to schedule pod: default/bb-65fd577957-vqdgt
I0125 15:54:41.697108   59701 predicates.go:431] PVC default/pvc-vault-ro is not bound, assuming PVC matches predicate when counting limits
I0125 15:54:41.697146   59701 predicates.go:431] PVC default/pvc-vault-ro is not bound, assuming PVC matches predicate when counting limits
I0125 15:54:41.697152   59701 predicates.go:431] PVC default/pvc-vault-ro is not bound, assuming PVC matches predicate when counting limits
I0125 15:54:41.697158   59701 scheduler_binder.go:173] FindPodVolumes for pod "default/bb-65fd577957-vqdgt", node "127.0.0.1"
I0125 15:54:41.697163   59701 scheduler_binder.go:576] PVC "default/pvc-vault-ro" is not bound
E0125 15:54:41.697189   59701 factory.go:1089] Error scheduling default/bb-65fd577957-vqdgt: pod has unbound immediate PersistentVolumeClaims; retrying
I0125 15:54:41.697203   59701 factory.go:1170] Updating pod condition for default/bb-65fd577957-vqdgt to (PodScheduled==False, Reason=Unschedulable)
E0125 15:54:41.718256   59701 scheduler.go:478] error selecting node for pod: pod has unbound immediate PersistentVolumeClaims
I0125 15:54:41.718356   59701 scheduling_queue.go:821] About to try and schedule pod default/bb-65fd577957-tg5wt
I0125 15:54:41.718363   59701 scheduler.go:451] Attempting to schedule pod: default/bb-65fd577957-tg5wt
I0125 15:54:41.718431   59701 predicates.go:431] PVC default/pvc-vault-ro is not bound, assuming PVC matches predicate when counting limits
I0125 15:54:41.718473   59701 predicates.go:431] PVC default/pvc-vault-ro is not bound, assuming PVC matches predicate when counting limits
I0125 15:54:41.718479   59701 predicates.go:431] PVC default/pvc-vault-ro is not bound, assuming PVC matches predicate when counting limits
I0125 15:54:41.718484   59701 scheduler_binder.go:173] FindPodVolumes for pod "default/bb-65fd577957-tg5wt", node "127.0.0.1"
I0125 15:54:41.718489   59701 scheduler_binder.go:576] PVC "default/pvc-vault-ro" is not bound
E0125 15:54:41.718534   59701 factory.go:1089] Error scheduling default/bb-65fd577957-tg5wt: pod has unbound immediate PersistentVolumeClaims; retrying
I0125 15:54:41.718550   59701 factory.go:1170] Updating pod condition for default/bb-65fd577957-tg5wt to (PodScheduled==False, Reason=Unschedulable)
E0125 15:54:41.758153   59701 scheduler.go:478] error selecting node for pod: pod has unbound immediate PersistentVolumeClaims
I0125 15:54:41.758289   59701 scheduling_queue.go:821] About to try and schedule pod default/bb-65fd577957-vqdgt
I0125 15:54:41.758297   59701 scheduler.go:451] Attempting to schedule pod: default/bb-65fd577957-vqdgt
I0125 15:54:41.758339   59701 predicates.go:431] PVC default/pvc-vault-ro is not bound, assuming PVC matches predicate when counting limits
I0125 15:54:41.758383   59701 predicates.go:431] PVC default/pvc-vault-ro is not bound, assuming PVC matches predicate when counting limits
I0125 15:54:41.758389   59701 predicates.go:431] PVC default/pvc-vault-ro is not bound, assuming PVC matches predicate when counting limits
I0125 15:54:41.758393   59701 scheduler_binder.go:173] FindPodVolumes for pod "default/bb-65fd577957-vqdgt", node "127.0.0.1"
I0125 15:54:41.758399   59701 scheduler_binder.go:576] PVC "default/pvc-vault-ro" is not bound
E0125 15:54:41.758423   59701 factory.go:1089] Error scheduling default/bb-65fd577957-vqdgt: pod has unbound immediate PersistentVolumeClaims; retrying
I0125 15:54:41.758437   59701 factory.go:1170] Updating pod condition for default/bb-65fd577957-vqdgt to (PodScheduled==False, Reason=Unschedulable)
I0125 15:54:41.775097   59701 request.go:530] Throttling request took 56.462984ms, request: GET:https://localhost:6443/api/v1/namespaces/default/pods/bb-65fd577957-tg5wt
E0125 15:54:41.796813   59701 scheduler.go:478] error selecting node for pod: pod has unbound immediate PersistentVolumeClaims
I0125 15:54:41.796857   59701 scheduling_queue.go:821] About to try and schedule pod default/bb-65fd577957-tg5wt
I0125 15:54:41.796861   59701 scheduler.go:451] Attempting to schedule pod: default/bb-65fd577957-tg5wt
I0125 15:54:41.796910   59701 predicates.go:431] PVC default/pvc-vault-ro is not bound, assuming PVC matches predicate when counting limits
I0125 15:54:41.796949   59701 predicates.go:431] PVC default/pvc-vault-ro is not bound, assuming PVC matches predicate when counting limits
I0125 15:54:41.796955   59701 predicates.go:431] PVC default/pvc-vault-ro is not bound, assuming PVC matches predicate when counting limits
I0125 15:54:41.796960   59701 scheduler_binder.go:173] FindPodVolumes for pod "default/bb-65fd577957-tg5wt", node "127.0.0.1"
I0125 15:54:41.796966   59701 scheduler_binder.go:576] PVC "default/pvc-vault-ro" is not bound
E0125 15:54:41.796993   59701 factory.go:1089] Error scheduling default/bb-65fd577957-tg5wt: pod has unbound immediate PersistentVolumeClaims; retrying
I0125 15:54:41.797010   59701 factory.go:1170] Updating pod condition for default/bb-65fd577957-tg5wt to (PodScheduled==False, Reason=Unschedulable)
I0125 15:54:41.814885   59701 request.go:530] Throttling request took 56.188919ms, request: GET:https://localhost:6443/api/v1/namespaces/default/pods/bb-65fd577957-vqdgt
E0125 15:54:41.836821   59701 scheduler.go:478] error selecting node for pod: pod has unbound immediate PersistentVolumeClaims
I0125 15:54:41.836842   59701 scheduling_queue.go:821] About to try and schedule pod default/bb-65fd577957-k7xx6
I0125 15:54:41.836849   59701 scheduler.go:451] Attempting to schedule pod: default/bb-65fd577957-k7xx6
I0125 15:54:41.836892   59701 predicates.go:431] PVC default/pvc-vault-ro is not bound, assuming PVC matches predicate when counting limits
I0125 15:54:41.836929   59701 predicates.go:431] PVC default/pvc-vault-ro is not bound, assuming PVC matches predicate when counting limits
I0125 15:54:41.836935   59701 predicates.go:431] PVC default/pvc-vault-ro is not bound, assuming PVC matches predicate when counting limits
I0125 15:54:41.836940   59701 scheduler_binder.go:173] FindPodVolumes for pod "default/bb-65fd577957-k7xx6", node "127.0.0.1"
I0125 15:54:41.836945   59701 scheduler_binder.go:576] PVC "default/pvc-vault-ro" is not bound
E0125 15:54:41.836969   59701 factory.go:1089] Error scheduling default/bb-65fd577957-k7xx6: pod has unbound immediate PersistentVolumeClaims; retrying
I0125 15:54:41.836983   59701 factory.go:1170] Updating pod condition for default/bb-65fd577957-k7xx6 to (PodScheduled==False, Reason=Unschedulable)
I0125 15:54:41.855095   59701 request.go:530] Throttling request took 58.01824ms, request: GET:https://localhost:6443/api/v1/namespaces/default/pods/bb-65fd577957-tg5wt
E0125 15:54:41.876620   59701 scheduler.go:478] error selecting node for pod: pod has unbound immediate PersistentVolumeClaims
I0125 15:54:41.876641   59701 scheduling_queue.go:821] About to try and schedule pod default/bb-65fd577957-8tstx
I0125 15:54:41.876644   59701 scheduler.go:451] Attempting to schedule pod: default/bb-65fd577957-8tstx
I0125 15:54:41.876686   59701 predicates.go:431] PVC default/pvc-vault-ro is not bound, assuming PVC matches predicate when counting limits
I0125 15:54:41.876726   59701 predicates.go:431] PVC default/pvc-vault-ro is not bound, assuming PVC matches predicate when counting limits
I0125 15:54:41.876732   59701 predicates.go:431] PVC default/pvc-vault-ro is not bound, assuming PVC matches predicate when counting limits
I0125 15:54:41.876737   59701 scheduler_binder.go:173] FindPodVolumes for pod "default/bb-65fd577957-8tstx", node "127.0.0.1"
I0125 15:54:41.876743   59701 scheduler_binder.go:576] PVC "default/pvc-vault-ro" is not bound
E0125 15:54:41.876767   59701 factory.go:1089] Error scheduling default/bb-65fd577957-8tstx: pod has unbound immediate PersistentVolumeClaims; retrying
I0125 15:54:41.876781   59701 factory.go:1170] Updating pod condition for default/bb-65fd577957-8tstx to (PodScheduled==False, Reason=Unschedulable)
I0125 15:54:41.895341   59701 request.go:530] Throttling request took 58.248242ms, request: GET:https://localhost:6443/api/v1/namespaces/default/pods/bb-65fd577957-k7xx6
E0125 15:54:41.918254   59701 scheduler.go:478] error selecting node for pod: pod has unbound immediate PersistentVolumeClaims
I0125 15:54:41.918285   59701 scheduling_queue.go:821] About to try and schedule pod default/bb-65fd577957-lvzk8
I0125 15:54:41.918289   59701 scheduler.go:451] Attempting to schedule pod: default/bb-65fd577957-lvzk8
I0125 15:54:41.918348   59701 predicates.go:431] PVC default/pvc-vault-ro is not bound, assuming PVC matches predicate when counting limits
I0125 15:54:41.918404   59701 predicates.go:431] PVC default/pvc-vault-ro is not bound, assuming PVC matches predicate when counting limits
I0125 15:54:41.918413   59701 predicates.go:431] PVC default/pvc-vault-ro is not bound, assuming PVC matches predicate when counting limits
I0125 15:54:41.918421   59701 scheduler_binder.go:173] FindPodVolumes for pod "default/bb-65fd577957-lvzk8", node "127.0.0.1"
I0125 15:54:41.918430   59701 scheduler_binder.go:576] PVC "default/pvc-vault-ro" is not bound
E0125 15:54:41.918501   59701 factory.go:1089] Error scheduling default/bb-65fd577957-lvzk8: pod has unbound immediate PersistentVolumeClaims; retrying
I0125 15:54:41.918526   59701 factory.go:1170] Updating pod condition for default/bb-65fd577957-lvzk8 to (PodScheduled==False, Reason=Unschedulable)
I0125 15:54:41.934915   59701 request.go:530] Throttling request took 58.006416ms, request: GET:https://localhost:6443/api/v1/namespaces/default/pods/bb-65fd577957-8tstx
I0125 15:54:41.976099   59701 request.go:530] Throttling request took 57.47196ms, request: PUT:https://localhost:6443/api/v1/namespaces/default/pods/bb-65fd577957-lvzk8/status
E0125 15:54:41.980564   59701 scheduler.go:478] error selecting node for pod: pod has unbound immediate PersistentVolumeClaims
I0125 15:54:41.980753   59701 scheduling_queue.go:821] About to try and schedule pod default/bb-65fd577957-k7xx6
I0125 15:54:41.980764   59701 scheduler.go:451] Attempting to schedule pod: default/bb-65fd577957-k7xx6
I0125 15:54:41.980836   59701 predicates.go:431] PVC default/pvc-vault-ro is not bound, assuming PVC matches predicate when counting limits
I0125 15:54:41.980896   59701 predicates.go:431] PVC default/pvc-vault-ro is not bound, assuming PVC matches predicate when counting limits
I0125 15:54:41.980905   59701 predicates.go:431] PVC default/pvc-vault-ro is not bound, assuming PVC matches predicate when counting limits
I0125 15:54:41.980913   59701 scheduler_binder.go:173] FindPodVolumes for pod "default/bb-65fd577957-k7xx6", node "127.0.0.1"
I0125 15:54:41.980921   59701 scheduler_binder.go:576] PVC "default/pvc-vault-ro" is not bound
E0125 15:54:41.980987   59701 factory.go:1089] Error scheduling default/bb-65fd577957-k7xx6: pod has unbound immediate PersistentVolumeClaims; retrying
I0125 15:54:41.981012   59701 factory.go:1170] Updating pod condition for default/bb-65fd577957-k7xx6 to (PodScheduled==False, Reason=Unschedulable)
E0125 15:54:41.999498   59701 scheduler.go:478] error selecting node for pod: pod has unbound immediate PersistentVolumeClaims
I0125 15:54:41.999535   59701 scheduling_queue.go:821] About to try and schedule pod default/bb-65fd577957-lvzk8
I0125 15:54:41.999541   59701 scheduler.go:451] Attempting to schedule pod: default/bb-65fd577957-lvzk8
I0125 15:54:41.999619   59701 predicates.go:431] PVC default/pvc-vault-ro is not bound, assuming PVC matches predicate when counting limits
I0125 15:54:41.999677   59701 predicates.go:431] PVC default/pvc-vault-ro is not bound, assuming PVC matches predicate when counting limits
I0125 15:54:41.999686   59701 predicates.go:431] PVC default/pvc-vault-ro is not bound, assuming PVC matches predicate when counting limits
I0125 15:54:41.999694   59701 scheduler_binder.go:173] FindPodVolumes for pod "default/bb-65fd577957-lvzk8", node "127.0.0.1"
I0125 15:54:41.999702   59701 scheduler_binder.go:576] PVC "default/pvc-vault-ro" is not bound
E0125 15:54:41.999771   59701 factory.go:1089] Error scheduling default/bb-65fd577957-lvzk8: pod has unbound immediate PersistentVolumeClaims; retrying
I0125 15:54:41.999799   59701 factory.go:1170] Updating pod condition for default/bb-65fd577957-lvzk8 to (PodScheduled==False, Reason=Unschedulable)
E0125 15:54:42.037920   59701 scheduler.go:478] error selecting node for pod: pod has unbound immediate PersistentVolumeClaims
I0125 15:54:42.037996   59701 scheduling_queue.go:821] About to try and schedule pod default/bb-65fd577957-8tstx
I0125 15:54:42.038004   59701 scheduler.go:451] Attempting to schedule pod: default/bb-65fd577957-8tstx
I0125 15:54:42.038062   59701 predicates.go:431] PVC default/pvc-vault-ro is not bound, assuming PVC matches predicate when counting limits
I0125 15:54:42.038112   59701 predicates.go:431] PVC default/pvc-vault-ro is not bound, assuming PVC matches predicate when counting limits
I0125 15:54:42.038119   59701 predicates.go:431] PVC default/pvc-vault-ro is not bound, assuming PVC matches predicate when counting limits
I0125 15:54:42.038125   59701 scheduler_binder.go:173] FindPodVolumes for pod "default/bb-65fd577957-8tstx", node "127.0.0.1"
I0125 15:54:42.038133   59701 scheduler_binder.go:576] PVC "default/pvc-vault-ro" is not bound
E0125 15:54:42.038189   59701 factory.go:1089] Error scheduling default/bb-65fd577957-8tstx: pod has unbound immediate PersistentVolumeClaims; retrying
I0125 15:54:42.038211   59701 factory.go:1170] Updating pod condition for default/bb-65fd577957-8tstx to (PodScheduled==False, Reason=Unschedulable)
I0125 15:54:42.055131   59701 request.go:530] Throttling request took 55.167332ms, request: GET:https://localhost:6443/api/v1/namespaces/default/pods/bb-65fd577957-lvzk8
E0125 15:54:42.078531   59701 scheduler.go:478] error selecting node for pod: pod has unbound immediate PersistentVolumeClaims
I0125 15:54:42.078654   59701 scheduling_queue.go:821] About to try and schedule pod default/bb-65fd577957-nbncn
I0125 15:54:42.078666   59701 scheduler.go:451] Attempting to schedule pod: default/bb-65fd577957-nbncn
I0125 15:54:42.078742   59701 predicates.go:431] PVC default/pvc-vault-ro is not bound, assuming PVC matches predicate when counting limits
I0125 15:54:42.078857   59701 predicates.go:431] PVC default/pvc-vault-ro is not bound, assuming PVC matches predicate when counting limits
I0125 15:54:42.078875   59701 predicates.go:431] PVC default/pvc-vault-ro is not bound, assuming PVC matches predicate when counting limits
I0125 15:54:42.078897   59701 scheduler_binder.go:173] FindPodVolumes for pod "default/bb-65fd577957-nbncn", node "127.0.0.1"
I0125 15:54:42.078914   59701 scheduler_binder.go:576] PVC "default/pvc-vault-ro" is not bound
E0125 15:54:42.079003   59701 factory.go:1089] Error scheduling default/bb-65fd577957-nbncn: pod has unbound immediate PersistentVolumeClaims; retrying
I0125 15:54:42.079032   59701 factory.go:1170] Updating pod condition for default/bb-65fd577957-nbncn to (PodScheduled==False, Reason=Unschedulable)
I0125 15:54:42.095526   59701 request.go:530] Throttling request took 57.168361ms, request: GET:https://localhost:6443/api/v1/namespaces/default/pods/bb-65fd577957-8tstx
I0125 15:54:42.135528   59701 request.go:530] Throttling request took 56.338999ms, request: PUT:https://localhost:6443/api/v1/namespaces/default/pods/bb-65fd577957-nbncn/status
E0125 15:54:42.140099   59701 scheduler.go:478] error selecting node for pod: pod has unbound immediate PersistentVolumeClaims
I0125 15:54:42.140137   59701 scheduling_queue.go:821] About to try and schedule pod default/bb-65fd577957-jm62w
I0125 15:54:42.140143   59701 scheduler.go:451] Attempting to schedule pod: default/bb-65fd577957-jm62w
I0125 15:54:42.140218   59701 predicates.go:431] PVC default/pvc-vault-ro is not bound, assuming PVC matches predicate when counting limits
I0125 15:54:42.140287   59701 predicates.go:431] PVC default/pvc-vault-ro is not bound, assuming PVC matches predicate when counting limits
I0125 15:54:42.140297   59701 predicates.go:431] PVC default/pvc-vault-ro is not bound, assuming PVC matches predicate when counting limits
I0125 15:54:42.140306   59701 scheduler_binder.go:173] FindPodVolumes for pod "default/bb-65fd577957-jm62w", node "127.0.0.1"
I0125 15:54:42.140316   59701 scheduler_binder.go:576] PVC "default/pvc-vault-ro" is not bound
E0125 15:54:42.140362   59701 factory.go:1089] Error scheduling default/bb-65fd577957-jm62w: pod has unbound immediate PersistentVolumeClaims; retrying
I0125 15:54:42.140447   59701 factory.go:1170] Updating pod condition for default/bb-65fd577957-jm62w to (PodScheduled==False, Reason=Unschedulable)
E0125 15:54:42.158415   59701 scheduler.go:478] error selecting node for pod: pod has unbound immediate PersistentVolumeClaims
I0125 15:54:42.158483   59701 scheduling_queue.go:821] About to try and schedule pod default/bb-65fd577957-xktdz
I0125 15:54:42.158491   59701 scheduler.go:451] Attempting to schedule pod: default/bb-65fd577957-xktdz
I0125 15:54:42.158570   59701 predicates.go:431] PVC default/pvc-vault-ro is not bound, assuming PVC matches predicate when counting limits
I0125 15:54:42.158629   59701 predicates.go:431] PVC default/pvc-vault-ro is not bound, assuming PVC matches predicate when counting limits
I0125 15:54:42.158636   59701 predicates.go:431] PVC default/pvc-vault-ro is not bound, assuming PVC matches predicate when counting limits
I0125 15:54:42.158643   59701 scheduler_binder.go:173] FindPodVolumes for pod "default/bb-65fd577957-xktdz", node "127.0.0.1"
I0125 15:54:42.158650   59701 scheduler_binder.go:576] PVC "default/pvc-vault-ro" is not bound
E0125 15:54:42.158704   59701 factory.go:1089] Error scheduling default/bb-65fd577957-xktdz: pod has unbound immediate PersistentVolumeClaims; retrying
I0125 15:54:42.158732   59701 factory.go:1170] Updating pod condition for default/bb-65fd577957-xktdz to (PodScheduled==False, Reason=Unschedulable)
E0125 15:54:42.198907   59701 scheduler.go:478] error selecting node for pod: pod has unbound immediate PersistentVolumeClaims
I0125 15:54:42.198997   59701 scheduling_queue.go:821] About to try and schedule pod default/bb-65fd577957-6njf6
I0125 15:54:42.199007   59701 scheduler.go:451] Attempting to schedule pod: default/bb-65fd577957-6njf6
I0125 15:54:42.199064   59701 predicates.go:431] PVC default/pvc-vault-ro is not bound, assuming PVC matches predicate when counting limits
I0125 15:54:42.199113   59701 predicates.go:431] PVC default/pvc-vault-ro is not bound, assuming PVC matches predicate when counting limits
I0125 15:54:42.199121   59701 predicates.go:431] PVC default/pvc-vault-ro is not bound, assuming PVC matches predicate when counting limits
I0125 15:54:42.199127   59701 scheduler_binder.go:173] FindPodVolumes for pod "default/bb-65fd577957-6njf6", node "127.0.0.1"
I0125 15:54:42.199134   59701 scheduler_binder.go:576] PVC "default/pvc-vault-ro" is not bound
E0125 15:54:42.199191   59701 factory.go:1089] Error scheduling default/bb-65fd577957-6njf6: pod has unbound immediate PersistentVolumeClaims; retrying
I0125 15:54:42.199213   59701 factory.go:1170] Updating pod condition for default/bb-65fd577957-6njf6 to (PodScheduled==False, Reason=Unschedulable)
I0125 15:54:42.214909   59701 request.go:530] Throttling request took 56.104248ms, request: GET:https://localhost:6443/api/v1/namespaces/default/pods/bb-65fd577957-xktdz
E0125 15:54:42.237813   59701 scheduler.go:478] error selecting node for pod: pod has unbound immediate PersistentVolumeClaims
I0125 15:54:42.237879   59701 scheduling_queue.go:821] About to try and schedule pod default/bb-65fd577957-dg54f
I0125 15:54:42.237890   59701 scheduler.go:451] Attempting to schedule pod: default/bb-65fd577957-dg54f
I0125 15:54:42.237972   59701 predicates.go:431] PVC default/pvc-vault-ro is not bound, assuming PVC matches predicate when counting limits
I0125 15:54:42.238024   59701 predicates.go:431] PVC default/pvc-vault-ro is not bound, assuming PVC matches predicate when counting limits
I0125 15:54:42.238031   59701 predicates.go:431] PVC default/pvc-vault-ro is not bound, assuming PVC matches predicate when counting limits
I0125 15:54:42.238038   59701 scheduler_binder.go:173] FindPodVolumes for pod "default/bb-65fd577957-dg54f", node "127.0.0.1"
I0125 15:54:42.238045   59701 scheduler_binder.go:576] PVC "default/pvc-vault-ro" is not bound
E0125 15:54:42.238100   59701 factory.go:1089] Error scheduling default/bb-65fd577957-dg54f: pod has unbound immediate PersistentVolumeClaims; retrying
I0125 15:54:42.238123   59701 factory.go:1170] Updating pod condition for default/bb-65fd577957-dg54f to (PodScheduled==False, Reason=Unschedulable)
I0125 15:54:42.256217   59701 request.go:530] Throttling request took 56.811886ms, request: GET:https://localhost:6443/api/v1/namespaces/default/pods/bb-65fd577957-6njf6
E0125 15:54:42.280658   59701 scheduler.go:478] error selecting node for pod: pod has unbound immediate PersistentVolumeClaims
I0125 15:54:42.280687   59701 scheduling_queue.go:821] About to try and schedule pod default/bb-65fd577957-6njf6
I0125 15:54:42.280693   59701 scheduler.go:451] Attempting to schedule pod: default/bb-65fd577957-6njf6
I0125 15:54:42.280785   59701 predicates.go:431] PVC default/pvc-vault-ro is not bound, assuming PVC matches predicate when counting limits
I0125 15:54:42.280845   59701 predicates.go:431] PVC default/pvc-vault-ro is not bound, assuming PVC matches predicate when counting limits
I0125 15:54:42.280855   59701 predicates.go:431] PVC default/pvc-vault-ro is not bound, assuming PVC matches predicate when counting limits
I0125 15:54:42.280862   59701 scheduler_binder.go:173] FindPodVolumes for pod "default/bb-65fd577957-6njf6", node "127.0.0.1"
I0125 15:54:42.280871   59701 scheduler_binder.go:576] PVC "default/pvc-vault-ro" is not bound
E0125 15:54:42.280941   59701 factory.go:1089] Error scheduling default/bb-65fd577957-6njf6: pod has unbound immediate PersistentVolumeClaims; retrying
I0125 15:54:42.280966   59701 factory.go:1170] Updating pod condition for default/bb-65fd577957-6njf6 to (PodScheduled==False, Reason=Unschedulable)
I0125 15:54:42.295874   59701 request.go:530] Throttling request took 57.568587ms, request: GET:https://localhost:6443/api/v1/namespaces/default/pods/bb-65fd577957-dg54f
E0125 15:54:42.318844   59701 scheduler.go:478] error selecting node for pod: pod has unbound immediate PersistentVolumeClaims
I0125 15:54:42.318946   59701 scheduling_queue.go:821] About to try and schedule pod default/bb-65fd577957-dg54f
I0125 15:54:42.318959   59701 scheduler.go:451] Attempting to schedule pod: default/bb-65fd577957-dg54f
I0125 15:54:42.319108   59701 predicates.go:431] PVC default/pvc-vault-ro is not bound, assuming PVC matches predicate when counting limits
I0125 15:54:42.319178   59701 predicates.go:431] PVC default/pvc-vault-ro is not bound, assuming PVC matches predicate when counting limits
I0125 15:54:42.319216   59701 predicates.go:431] PVC default/pvc-vault-ro is not bound, assuming PVC matches predicate when counting limits
I0125 15:54:42.319228   59701 scheduler_binder.go:173] FindPodVolumes for pod "default/bb-65fd577957-dg54f", node "127.0.0.1"
I0125 15:54:42.319237   59701 scheduler_binder.go:576] PVC "default/pvc-vault-ro" is not bound
E0125 15:54:42.319314   59701 factory.go:1089] Error scheduling default/bb-65fd577957-dg54f: pod has unbound immediate PersistentVolumeClaims; retrying
I0125 15:54:42.319342   59701 factory.go:1170] Updating pod condition for default/bb-65fd577957-dg54f to (PodScheduled==False, Reason=Unschedulable)
I0125 15:54:42.335147   59701 request.go:530] Throttling request took 54.060949ms, request: GET:https://localhost:6443/api/v1/namespaces/default/pods/bb-65fd577957-6njf6
E0125 15:54:42.359683   59701 scheduler.go:478] error selecting node for pod: pod has unbound immediate PersistentVolumeClaims
I0125 15:54:42.359920   59701 scheduling_queue.go:821] About to try and schedule pod default/bb-65fd577957-nbncn
I0125 15:54:42.359939   59701 scheduler.go:451] Attempting to schedule pod: default/bb-65fd577957-nbncn
I0125 15:54:42.360049   59701 predicates.go:431] PVC default/pvc-vault-ro is not bound, assuming PVC matches predicate when counting limits
I0125 15:54:42.360115   59701 predicates.go:431] PVC default/pvc-vault-ro is not bound, assuming PVC matches predicate when counting limits
I0125 15:54:42.360124   59701 predicates.go:431] PVC default/pvc-vault-ro is not bound, assuming PVC matches predicate when counting limits
I0125 15:54:42.360132   59701 scheduler_binder.go:173] FindPodVolumes for pod "default/bb-65fd577957-nbncn", node "127.0.0.1"
I0125 15:54:42.360140   59701 scheduler_binder.go:576] PVC "default/pvc-vault-ro" is not bound
E0125 15:54:42.360211   59701 factory.go:1089] Error scheduling default/bb-65fd577957-nbncn: pod has unbound immediate PersistentVolumeClaims; retrying
I0125 15:54:42.360237   59701 factory.go:1170] Updating pod condition for default/bb-65fd577957-nbncn to (PodScheduled==False, Reason=Unschedulable)
I0125 15:54:42.375829   59701 request.go:530] Throttling request took 56.381785ms, request: GET:https://localhost:6443/api/v1/namespaces/default/pods/bb-65fd577957-dg54f
E0125 15:54:42.400524   59701 scheduler.go:478] error selecting node for pod: pod has unbound immediate PersistentVolumeClaims
I0125 15:54:42.400826   59701 scheduling_queue.go:821] About to try and schedule pod default/bb-65fd577957-8tstx
I0125 15:54:42.400841   59701 scheduler.go:451] Attempting to schedule pod: default/bb-65fd577957-8tstx
I0125 15:54:42.400912   59701 predicates.go:431] PVC default/pvc-vault-ro is not bound, assuming PVC matches predicate when counting limits
I0125 15:54:42.400971   59701 predicates.go:431] PVC default/pvc-vault-ro is not bound, assuming PVC matches predicate when counting limits
I0125 15:54:42.400980   59701 predicates.go:431] PVC default/pvc-vault-ro is not bound, assuming PVC matches predicate when counting limits
I0125 15:54:42.401000   59701 scheduler_binder.go:173] FindPodVolumes for pod "default/bb-65fd577957-8tstx", node "127.0.0.1"
I0125 15:54:42.401009   59701 scheduler_binder.go:576] PVC "default/pvc-vault-ro" is not bound
E0125 15:54:42.401076   59701 factory.go:1089] Error scheduling default/bb-65fd577957-8tstx: pod has unbound immediate PersistentVolumeClaims; retrying
I0125 15:54:42.401109   59701 factory.go:1170] Updating pod condition for default/bb-65fd577957-8tstx to (PodScheduled==False, Reason=Unschedulable)
I0125 15:54:42.415182   59701 request.go:530] Throttling request took 54.73072ms, request: GET:https://localhost:6443/api/v1/namespaces/default/pods/bb-65fd577957-nbncn
E0125 15:54:42.439655   59701 scheduler.go:478] error selecting node for pod: pod has unbound immediate PersistentVolumeClaims
I0125 15:54:42.439883   59701 scheduling_queue.go:821] About to try and schedule pod default/bb-65fd577957-xktdz
I0125 15:54:42.439898   59701 scheduler.go:451] Attempting to schedule pod: default/bb-65fd577957-xktdz
I0125 15:54:42.439967   59701 predicates.go:431] PVC default/pvc-vault-ro is not bound, assuming PVC matches predicate when counting limits
I0125 15:54:42.440022   59701 predicates.go:431] PVC default/pvc-vault-ro is not bound, assuming PVC matches predicate when counting limits
I0125 15:54:42.440031   59701 predicates.go:431] PVC default/pvc-vault-ro is not bound, assuming PVC matches predicate when counting limits
I0125 15:54:42.440039   59701 scheduler_binder.go:173] FindPodVolumes for pod "default/bb-65fd577957-xktdz", node "127.0.0.1"
I0125 15:54:42.440048   59701 scheduler_binder.go:576] PVC "default/pvc-vault-ro" is not bound
E0125 15:54:42.440254   59701 factory.go:1089] Error scheduling default/bb-65fd577957-xktdz: pod has unbound immediate PersistentVolumeClaims; retrying
I0125 15:54:42.440288   59701 factory.go:1170] Updating pod condition for default/bb-65fd577957-xktdz to (PodScheduled==False, Reason=Unschedulable)
I0125 15:54:42.455522   59701 request.go:530] Throttling request took 54.26484ms, request: GET:https://localhost:6443/api/v1/namespaces/default/pods/bb-65fd577957-8tstx
E0125 15:54:42.476570   59701 scheduler.go:478] error selecting node for pod: pod has unbound immediate PersistentVolumeClaims
I0125 15:54:42.476659   59701 scheduling_queue.go:821] About to try and schedule pod default/bb-65fd577957-jm62w
I0125 15:54:42.476668   59701 scheduler.go:451] Attempting to schedule pod: default/bb-65fd577957-jm62w
I0125 15:54:42.476714   59701 predicates.go:431] PVC default/pvc-vault-ro is not bound, assuming PVC matches predicate when counting limits
I0125 15:54:42.476753   59701 predicates.go:431] PVC default/pvc-vault-ro is not bound, assuming PVC matches predicate when counting limits
I0125 15:54:42.476759   59701 predicates.go:431] PVC default/pvc-vault-ro is not bound, assuming PVC matches predicate when counting limits
I0125 15:54:42.476764   59701 scheduler_binder.go:173] FindPodVolumes for pod "default/bb-65fd577957-jm62w", node "127.0.0.1"
I0125 15:54:42.476770   59701 scheduler_binder.go:576] PVC "default/pvc-vault-ro" is not bound
E0125 15:54:42.476814   59701 factory.go:1089] Error scheduling default/bb-65fd577957-jm62w: pod has unbound immediate PersistentVolumeClaims; retrying
I0125 15:54:42.476831   59701 factory.go:1170] Updating pod condition for default/bb-65fd577957-jm62w to (PodScheduled==False, Reason=Unschedulable)
I0125 15:54:42.495202   59701 request.go:530] Throttling request took 54.81562ms, request: GET:https://localhost:6443/api/v1/namespaces/default/pods/bb-65fd577957-xktdz
E0125 15:54:42.517770   59701 scheduler.go:478] error selecting node for pod: pod has unbound immediate PersistentVolumeClaims
I0125 15:54:42.535291   59701 request.go:530] Throttling request took 58.377659ms, request: GET:https://localhost:6443/api/v1/namespaces/default/pods/bb-65fd577957-jm62w
I0125 15:54:48.940629   59701 scheduling_queue.go:821] About to try and schedule pod default/bb-65fd577957-jtbpw
I0125 15:54:48.940645   59701 scheduler.go:451] Attempting to schedule pod: default/bb-65fd577957-jtbpw
I0125 15:54:48.940695   59701 predicates.go:431] PVC default/pvc-vault-ro is not bound, assuming PVC matches predicate when counting limits
I0125 15:54:48.940744   59701 predicates.go:431] PVC default/pvc-vault-ro is not bound, assuming PVC matches predicate when counting limits
I0125 15:54:48.940751   59701 predicates.go:431] PVC default/pvc-vault-ro is not bound, assuming PVC matches predicate when counting limits
I0125 15:54:48.940757   59701 scheduler_binder.go:173] FindPodVolumes for pod "default/bb-65fd577957-jtbpw", node "127.0.0.1"
I0125 15:54:48.940764   59701 scheduler_binder.go:576] PVC "default/pvc-vault-ro" is not bound
E0125 15:54:48.940826   59701 factory.go:1089] Error scheduling default/bb-65fd577957-jtbpw: pod has unbound immediate PersistentVolumeClaims; retrying
I0125 15:54:48.940846   59701 factory.go:1170] Updating pod condition for default/bb-65fd577957-jtbpw to (PodScheduled==False, Reason=Unschedulable)
E0125 15:54:48.942902   59701 scheduler.go:478] error selecting node for pod: pod has unbound immediate PersistentVolumeClaims
I0125 15:54:48.942935   59701 scheduling_queue.go:821] About to try and schedule pod default/bb-65fd577957-66rqt
I0125 15:54:48.942942   59701 scheduler.go:451] Attempting to schedule pod: default/bb-65fd577957-66rqt
I0125 15:54:48.943021   59701 predicates.go:431] PVC default/pvc-vault-ro is not bound, assuming PVC matches predicate when counting limits
I0125 15:54:48.943103   59701 predicates.go:431] PVC default/pvc-vault-ro is not bound, assuming PVC matches predicate when counting limits
I0125 15:54:48.943118   59701 predicates.go:431] PVC default/pvc-vault-ro is not bound, assuming PVC matches predicate when counting limits
I0125 15:54:48.943142   59701 scheduler_binder.go:173] FindPodVolumes for pod "default/bb-65fd577957-66rqt", node "127.0.0.1"
I0125 15:54:48.943158   59701 scheduler_binder.go:576] PVC "default/pvc-vault-ro" is not bound
E0125 15:54:48.943238   59701 factory.go:1089] Error scheduling default/bb-65fd577957-66rqt: pod has unbound immediate PersistentVolumeClaims; retrying
I0125 15:54:48.943264   59701 factory.go:1170] Updating pod condition for default/bb-65fd577957-66rqt to (PodScheduled==False, Reason=Unschedulable)
E0125 15:54:48.945965   59701 scheduler.go:478] error selecting node for pod: pod has unbound immediate PersistentVolumeClaims
I0125 15:54:48.945992   59701 scheduling_queue.go:821] About to try and schedule pod default/bb-65fd577957-l8c52
I0125 15:54:48.945997   59701 scheduler.go:451] Attempting to schedule pod: default/bb-65fd577957-l8c52
I0125 15:54:48.946050   59701 scheduler_binder.go:173] FindPodVolumes for pod "default/bb-65fd577957-l8c52", node "127.0.0.1"
I0125 15:54:48.946067   59701 scheduler_binder.go:571] PVC "default/pvc-vault-ro" is fully bound to PV "pv-vault-ro"
I0125 15:54:48.946072   59701 scheduler_binder.go:646] PersistentVolume "pv-vault-ro", Node "127.0.0.1" matches for Pod "default/bb-65fd577957-l8c52"
I0125 15:54:48.946077   59701 scheduler_binder.go:649] All bound volumes for Pod "default/bb-65fd577957-l8c52" match with Node "127.0.0.1"
I0125 15:54:48.946085   59701 predicates.go:1645] All PVCs found matches for pod default/bb-65fd577957-l8c52, node "127.0.0.1"
I0125 15:54:48.946106   59701 scheduler_binder.go:256] AssumePodVolumes for pod "default/bb-65fd577957-l8c52", node "127.0.0.1"
I0125 15:54:48.946111   59701 scheduler_binder.go:571] PVC "default/pvc-vault-ro" is fully bound to PV "pv-vault-ro"
I0125 15:54:48.946116   59701 scheduler_binder.go:266] AssumePodVolumes for pod "default/bb-65fd577957-l8c52", node "127.0.0.1": all PVCs bound and nothing to do
I0125 15:54:48.946134   59701 scheduling_queue.go:821] About to try and schedule pod default/bb-65fd577957-l9llg
I0125 15:54:48.946138   59701 scheduler.go:451] Attempting to schedule pod: default/bb-65fd577957-l9llg
I0125 15:54:48.946167   59701 scheduler_binder.go:173] FindPodVolumes for pod "default/bb-65fd577957-l9llg", node "127.0.0.1"
I0125 15:54:48.946182   59701 scheduler_binder.go:571] PVC "default/pvc-vault-ro" is fully bound to PV "pv-vault-ro"
I0125 15:54:48.946187   59701 scheduler_binder.go:646] PersistentVolume "pv-vault-ro", Node "127.0.0.1" matches for Pod "default/bb-65fd577957-l9llg"
I0125 15:54:48.946192   59701 scheduler_binder.go:649] All bound volumes for Pod "default/bb-65fd577957-l9llg" match with Node "127.0.0.1"
I0125 15:54:48.946198   59701 predicates.go:1645] All PVCs found matches for pod default/bb-65fd577957-l9llg, node "127.0.0.1"
I0125 15:54:48.946212   59701 scheduler_binder.go:256] AssumePodVolumes for pod "default/bb-65fd577957-l9llg", node "127.0.0.1"
I0125 15:54:48.946217   59701 scheduler_binder.go:571] PVC "default/pvc-vault-ro" is fully bound to PV "pv-vault-ro"
I0125 15:54:48.946222   59701 scheduler_binder.go:266] AssumePodVolumes for pod "default/bb-65fd577957-l9llg", node "127.0.0.1": all PVCs bound and nothing to do
I0125 15:54:48.946235   59701 scheduling_queue.go:821] About to try and schedule pod default/bb-65fd577957-g85fs
I0125 15:54:48.946239   59701 scheduler.go:451] Attempting to schedule pod: default/bb-65fd577957-g85fs
I0125 15:54:48.946269   59701 scheduler_binder.go:173] FindPodVolumes for pod "default/bb-65fd577957-g85fs", node "127.0.0.1"
I0125 15:54:48.946279   59701 scheduler_binder.go:571] PVC "default/pvc-vault-ro" is fully bound to PV "pv-vault-ro"
I0125 15:54:48.946284   59701 scheduler_binder.go:646] PersistentVolume "pv-vault-ro", Node "127.0.0.1" matches for Pod "default/bb-65fd577957-g85fs"
I0125 15:54:48.946288   59701 scheduler_binder.go:649] All bound volumes for Pod "default/bb-65fd577957-g85fs" match with Node "127.0.0.1"
I0125 15:54:48.946294   59701 predicates.go:1645] All PVCs found matches for pod default/bb-65fd577957-g85fs, node "127.0.0.1"
I0125 15:54:48.946306   59701 scheduler_binder.go:256] AssumePodVolumes for pod "default/bb-65fd577957-g85fs", node "127.0.0.1"
I0125 15:54:48.946312   59701 scheduler_binder.go:571] PVC "default/pvc-vault-ro" is fully bound to PV "pv-vault-ro"
I0125 15:54:48.946317   59701 scheduler_binder.go:266] AssumePodVolumes for pod "default/bb-65fd577957-g85fs", node "127.0.0.1": all PVCs bound and nothing to do
I0125 15:54:48.946326   59701 scheduling_queue.go:821] About to try and schedule pod default/bb-65fd577957-qhg7m
I0125 15:54:48.946330   59701 scheduler.go:451] Attempting to schedule pod: default/bb-65fd577957-qhg7m
I0125 15:54:48.946357   59701 scheduler_binder.go:173] FindPodVolumes for pod "default/bb-65fd577957-qhg7m", node "127.0.0.1"
I0125 15:54:48.946367   59701 scheduler_binder.go:571] PVC "default/pvc-vault-ro" is fully bound to PV "pv-vault-ro"
I0125 15:54:48.946371   59701 scheduler_binder.go:646] PersistentVolume "pv-vault-ro", Node "127.0.0.1" matches for Pod "default/bb-65fd577957-qhg7m"
I0125 15:54:48.946375   59701 scheduler_binder.go:649] All bound volumes for Pod "default/bb-65fd577957-qhg7m" match with Node "127.0.0.1"
I0125 15:54:48.946381   59701 predicates.go:1645] All PVCs found matches for pod default/bb-65fd577957-qhg7m, node "127.0.0.1"
I0125 15:54:48.946392   59701 scheduler_binder.go:256] AssumePodVolumes for pod "default/bb-65fd577957-qhg7m", node "127.0.0.1"
I0125 15:54:48.946397   59701 scheduler_binder.go:571] PVC "default/pvc-vault-ro" is fully bound to PV "pv-vault-ro"
I0125 15:54:48.946401   59701 scheduler_binder.go:266] AssumePodVolumes for pod "default/bb-65fd577957-qhg7m", node "127.0.0.1": all PVCs bound and nothing to do
I0125 15:54:48.946413   59701 scheduling_queue.go:821] About to try and schedule pod default/bb-65fd577957-gqwk5
I0125 15:54:48.946417   59701 scheduler.go:451] Attempting to schedule pod: default/bb-65fd577957-gqwk5
I0125 15:54:48.946440   59701 scheduler_binder.go:173] FindPodVolumes for pod "default/bb-65fd577957-gqwk5", node "127.0.0.1"
I0125 15:54:48.946450   59701 scheduler_binder.go:571] PVC "default/pvc-vault-ro" is fully bound to PV "pv-vault-ro"
I0125 15:54:48.946454   59701 scheduler_binder.go:646] PersistentVolume "pv-vault-ro", Node "127.0.0.1" matches for Pod "default/bb-65fd577957-gqwk5"
I0125 15:54:48.946461   59701 scheduler_binder.go:649] All bound volumes for Pod "default/bb-65fd577957-gqwk5" match with Node "127.0.0.1"
I0125 15:54:48.946467   59701 predicates.go:1645] All PVCs found matches for pod default/bb-65fd577957-gqwk5, node "127.0.0.1"
I0125 15:54:48.946479   59701 scheduler_binder.go:256] AssumePodVolumes for pod "default/bb-65fd577957-gqwk5", node "127.0.0.1"
I0125 15:54:48.946484   59701 scheduler_binder.go:571] PVC "default/pvc-vault-ro" is fully bound to PV "pv-vault-ro"
I0125 15:54:48.946488   59701 scheduler_binder.go:266] AssumePodVolumes for pod "default/bb-65fd577957-gqwk5", node "127.0.0.1": all PVCs bound and nothing to do
I0125 15:54:48.946499   59701 scheduling_queue.go:821] About to try and schedule pod default/bb-65fd577957-ndj6t
I0125 15:54:48.946502   59701 scheduler.go:451] Attempting to schedule pod: default/bb-65fd577957-ndj6t
I0125 15:54:48.946529   59701 scheduler_binder.go:173] FindPodVolumes for pod "default/bb-65fd577957-ndj6t", node "127.0.0.1"
I0125 15:54:48.946539   59701 scheduler_binder.go:571] PVC "default/pvc-vault-ro" is fully bound to PV "pv-vault-ro"
I0125 15:54:48.946544   59701 scheduler_binder.go:646] PersistentVolume "pv-vault-ro", Node "127.0.0.1" matches for Pod "default/bb-65fd577957-ndj6t"
I0125 15:54:48.946548   59701 scheduler_binder.go:649] All bound volumes for Pod "default/bb-65fd577957-ndj6t" match with Node "127.0.0.1"
I0125 15:54:48.946553   59701 predicates.go:1645] All PVCs found matches for pod default/bb-65fd577957-ndj6t, node "127.0.0.1"
I0125 15:54:48.946567   59701 scheduler_binder.go:256] AssumePodVolumes for pod "default/bb-65fd577957-ndj6t", node "127.0.0.1"
I0125 15:54:48.946572   59701 scheduler_binder.go:571] PVC "default/pvc-vault-ro" is fully bound to PV "pv-vault-ro"
I0125 15:54:48.946576   59701 scheduler_binder.go:266] AssumePodVolumes for pod "default/bb-65fd577957-ndj6t", node "127.0.0.1": all PVCs bound and nothing to do
I0125 15:54:48.946586   59701 scheduling_queue.go:821] About to try and schedule pod default/bb-65fd577957-5hmdw
I0125 15:54:48.946590   59701 scheduler.go:451] Attempting to schedule pod: default/bb-65fd577957-5hmdw
I0125 15:54:48.946612   59701 scheduler_binder.go:173] FindPodVolumes for pod "default/bb-65fd577957-5hmdw", node "127.0.0.1"
I0125 15:54:48.946623   59701 scheduler_binder.go:571] PVC "default/pvc-vault-ro" is fully bound to PV "pv-vault-ro"
I0125 15:54:48.946627   59701 scheduler_binder.go:646] PersistentVolume "pv-vault-ro", Node "127.0.0.1" matches for Pod "default/bb-65fd577957-5hmdw"
I0125 15:54:48.946631   59701 scheduler_binder.go:649] All bound volumes for Pod "default/bb-65fd577957-5hmdw" match with Node "127.0.0.1"
I0125 15:54:48.946637   59701 predicates.go:1645] All PVCs found matches for pod default/bb-65fd577957-5hmdw, node "127.0.0.1"
I0125 15:54:48.946648   59701 scheduler_binder.go:256] AssumePodVolumes for pod "default/bb-65fd577957-5hmdw", node "127.0.0.1"
I0125 15:54:48.946653   59701 scheduler_binder.go:571] PVC "default/pvc-vault-ro" is fully bound to PV "pv-vault-ro"
I0125 15:54:48.946657   59701 scheduler_binder.go:266] AssumePodVolumes for pod "default/bb-65fd577957-5hmdw", node "127.0.0.1": all PVCs bound and nothing to do
I0125 15:54:48.946666   59701 scheduling_queue.go:821] About to try and schedule pod default/bb-65fd577957-btnr8
I0125 15:54:48.946669   59701 scheduler.go:451] Attempting to schedule pod: default/bb-65fd577957-btnr8
I0125 15:54:48.946695   59701 scheduler_binder.go:173] FindPodVolumes for pod "default/bb-65fd577957-btnr8", node "127.0.0.1"
I0125 15:54:48.946705   59701 scheduler_binder.go:571] PVC "default/pvc-vault-ro" is fully bound to PV "pv-vault-ro"
I0125 15:54:48.946709   59701 scheduler_binder.go:646] PersistentVolume "pv-vault-ro", Node "127.0.0.1" matches for Pod "default/bb-65fd577957-btnr8"
I0125 15:54:48.946713   59701 scheduler_binder.go:649] All bound volumes for Pod "default/bb-65fd577957-btnr8" match with Node "127.0.0.1"
I0125 15:54:48.946718   59701 predicates.go:1645] All PVCs found matches for pod default/bb-65fd577957-btnr8, node "127.0.0.1"
I0125 15:54:48.946734   59701 scheduler_binder.go:256] AssumePodVolumes for pod "default/bb-65fd577957-btnr8", node "127.0.0.1"
I0125 15:54:48.946739   59701 scheduler_binder.go:571] PVC "default/pvc-vault-ro" is fully bound to PV "pv-vault-ro"
I0125 15:54:48.946743   59701 scheduler_binder.go:266] AssumePodVolumes for pod "default/bb-65fd577957-btnr8", node "127.0.0.1": all PVCs bound and nothing to do
I0125 15:54:48.946756   59701 scheduling_queue.go:821] About to try and schedule pod default/bb-65fd577957-xhgt7
I0125 15:54:48.946760   59701 scheduler.go:451] Attempting to schedule pod: default/bb-65fd577957-xhgt7
I0125 15:54:48.946785   59701 scheduler_binder.go:173] FindPodVolumes for pod "default/bb-65fd577957-xhgt7", node "127.0.0.1"
I0125 15:54:48.946795   59701 scheduler_binder.go:571] PVC "default/pvc-vault-ro" is fully bound to PV "pv-vault-ro"
I0125 15:54:48.946800   59701 scheduler_binder.go:646] PersistentVolume "pv-vault-ro", Node "127.0.0.1" matches for Pod "default/bb-65fd577957-xhgt7"
I0125 15:54:48.946804   59701 scheduler_binder.go:649] All bound volumes for Pod "default/bb-65fd577957-xhgt7" match with Node "127.0.0.1"
I0125 15:54:48.946809   59701 predicates.go:1645] All PVCs found matches for pod default/bb-65fd577957-xhgt7, node "127.0.0.1"
I0125 15:54:48.946820   59701 scheduler_binder.go:256] AssumePodVolumes for pod "default/bb-65fd577957-xhgt7", node "127.0.0.1"
I0125 15:54:48.946825   59701 scheduler_binder.go:571] PVC "default/pvc-vault-ro" is fully bound to PV "pv-vault-ro"
I0125 15:54:48.946829   59701 scheduler_binder.go:266] AssumePodVolumes for pod "default/bb-65fd577957-xhgt7", node "127.0.0.1": all PVCs bound and nothing to do
I0125 15:54:48.946842   59701 scheduling_queue.go:821] About to try and schedule pod default/bb-65fd577957-s8f8k
I0125 15:54:48.946845   59701 scheduler.go:451] Attempting to schedule pod: default/bb-65fd577957-s8f8k
I0125 15:54:48.946869   59701 scheduler_binder.go:173] FindPodVolumes for pod "default/bb-65fd577957-s8f8k", node "127.0.0.1"
I0125 15:54:48.946878   59701 scheduler_binder.go:571] PVC "default/pvc-vault-ro" is fully bound to PV "pv-vault-ro"
I0125 15:54:48.946882   59701 scheduler_binder.go:646] PersistentVolume "pv-vault-ro", Node "127.0.0.1" matches for Pod "default/bb-65fd577957-s8f8k"
I0125 15:54:48.946886   59701 scheduler_binder.go:649] All bound volumes for Pod "default/bb-65fd577957-s8f8k" match with Node "127.0.0.1"
I0125 15:54:48.946892   59701 predicates.go:1645] All PVCs found matches for pod default/bb-65fd577957-s8f8k, node "127.0.0.1"
I0125 15:54:48.946903   59701 scheduler_binder.go:256] AssumePodVolumes for pod "default/bb-65fd577957-s8f8k", node "127.0.0.1"
I0125 15:54:48.946908   59701 scheduler_binder.go:571] PVC "default/pvc-vault-ro" is fully bound to PV "pv-vault-ro"
I0125 15:54:48.946913   59701 scheduler_binder.go:266] AssumePodVolumes for pod "default/bb-65fd577957-s8f8k", node "127.0.0.1": all PVCs bound and nothing to do
I0125 15:54:48.946922   59701 scheduling_queue.go:821] About to try and schedule pod default/bb-65fd577957-29tb5
I0125 15:54:48.946926   59701 scheduler.go:451] Attempting to schedule pod: default/bb-65fd577957-29tb5
I0125 15:54:48.946950   59701 scheduler_binder.go:173] FindPodVolumes for pod "default/bb-65fd577957-29tb5", node "127.0.0.1"
I0125 15:54:48.946960   59701 scheduler_binder.go:571] PVC "default/pvc-vault-ro" is fully bound to PV "pv-vault-ro"
I0125 15:54:48.946964   59701 scheduler_binder.go:646] PersistentVolume "pv-vault-ro", Node "127.0.0.1" matches for Pod "default/bb-65fd577957-29tb5"
I0125 15:54:48.946968   59701 scheduler_binder.go:649] All bound volumes for Pod "default/bb-65fd577957-29tb5" match with Node "127.0.0.1"
I0125 15:54:48.946974   59701 predicates.go:1645] All PVCs found matches for pod default/bb-65fd577957-29tb5, node "127.0.0.1"
I0125 15:54:48.946986   59701 scheduler_binder.go:256] AssumePodVolumes for pod "default/bb-65fd577957-29tb5", node "127.0.0.1"
I0125 15:54:48.946991   59701 scheduler_binder.go:571] PVC "default/pvc-vault-ro" is fully bound to PV "pv-vault-ro"
I0125 15:54:48.946998   59701 scheduler_binder.go:266] AssumePodVolumes for pod "default/bb-65fd577957-29tb5", node "127.0.0.1": all PVCs bound and nothing to do
I0125 15:54:48.947009   59701 scheduling_queue.go:821] About to try and schedule pod default/bb-65fd577957-dzqkl
I0125 15:54:48.947013   59701 scheduler.go:451] Attempting to schedule pod: default/bb-65fd577957-dzqkl
I0125 15:54:48.947038   59701 scheduler_binder.go:173] FindPodVolumes for pod "default/bb-65fd577957-dzqkl", node "127.0.0.1"
I0125 15:54:48.947048   59701 scheduler_binder.go:571] PVC "default/pvc-vault-ro" is fully bound to PV "pv-vault-ro"
I0125 15:54:48.947053   59701 scheduler_binder.go:646] PersistentVolume "pv-vault-ro", Node "127.0.0.1" matches for Pod "default/bb-65fd577957-dzqkl"
I0125 15:54:48.947057   59701 scheduler_binder.go:649] All bound volumes for Pod "default/bb-65fd577957-dzqkl" match with Node "127.0.0.1"
I0125 15:54:48.947062   59701 predicates.go:1645] All PVCs found matches for pod default/bb-65fd577957-dzqkl, node "127.0.0.1"
I0125 15:54:48.947075   59701 scheduler_binder.go:256] AssumePodVolumes for pod "default/bb-65fd577957-dzqkl", node "127.0.0.1"
I0125 15:54:48.947080   59701 scheduler_binder.go:571] PVC "default/pvc-vault-ro" is fully bound to PV "pv-vault-ro"
I0125 15:54:48.947084   59701 scheduler_binder.go:266] AssumePodVolumes for pod "default/bb-65fd577957-dzqkl", node "127.0.0.1": all PVCs bound and nothing to do
I0125 15:54:48.947094   59701 scheduling_queue.go:821] About to try and schedule pod default/bb-65fd577957-ph2ct
I0125 15:54:48.947098   59701 scheduler.go:451] Attempting to schedule pod: default/bb-65fd577957-ph2ct
I0125 15:54:48.947120   59701 scheduler_binder.go:173] FindPodVolumes for pod "default/bb-65fd577957-ph2ct", node "127.0.0.1"
I0125 15:54:48.947129   59701 scheduler_binder.go:571] PVC "default/pvc-vault-ro" is fully bound to PV "pv-vault-ro"
I0125 15:54:48.947134   59701 scheduler_binder.go:646] PersistentVolume "pv-vault-ro", Node "127.0.0.1" matches for Pod "default/bb-65fd577957-ph2ct"
I0125 15:54:48.947138   59701 scheduler_binder.go:649] All bound volumes for Pod "default/bb-65fd577957-ph2ct" match with Node "127.0.0.1"
I0125 15:54:48.947143   59701 predicates.go:1645] All PVCs found matches for pod default/bb-65fd577957-ph2ct, node "127.0.0.1"
I0125 15:54:48.947154   59701 scheduler_binder.go:256] AssumePodVolumes for pod "default/bb-65fd577957-ph2ct", node "127.0.0.1"
I0125 15:54:48.947159   59701 scheduler_binder.go:571] PVC "default/pvc-vault-ro" is fully bound to PV "pv-vault-ro"
I0125 15:54:48.947163   59701 scheduler_binder.go:266] AssumePodVolumes for pod "default/bb-65fd577957-ph2ct", node "127.0.0.1": all PVCs bound and nothing to do
I0125 15:54:48.947175   59701 scheduling_queue.go:821] About to try and schedule pod default/bb-65fd577957-jflrz
I0125 15:54:48.947178   59701 scheduler.go:451] Attempting to schedule pod: default/bb-65fd577957-jflrz
I0125 15:54:48.947200   59701 scheduler_binder.go:173] FindPodVolumes for pod "default/bb-65fd577957-jflrz", node "127.0.0.1"
I0125 15:54:48.947210   59701 scheduler_binder.go:571] PVC "default/pvc-vault-ro" is fully bound to PV "pv-vault-ro"
I0125 15:54:48.947215   59701 scheduler_binder.go:646] PersistentVolume "pv-vault-ro", Node "127.0.0.1" matches for Pod "default/bb-65fd577957-jflrz"
I0125 15:54:48.947219   59701 scheduler_binder.go:649] All bound volumes for Pod "default/bb-65fd577957-jflrz" match with Node "127.0.0.1"
I0125 15:54:48.947225   59701 predicates.go:1645] All PVCs found matches for pod default/bb-65fd577957-jflrz, node "127.0.0.1"
I0125 15:54:48.947235   59701 scheduler_binder.go:256] AssumePodVolumes for pod "default/bb-65fd577957-jflrz", node "127.0.0.1"
I0125 15:54:48.947240   59701 scheduler_binder.go:571] PVC "default/pvc-vault-ro" is fully bound to PV "pv-vault-ro"
I0125 15:54:48.947244   59701 scheduler_binder.go:266] AssumePodVolumes for pod "default/bb-65fd577957-jflrz", node "127.0.0.1": all PVCs bound and nothing to do
I0125 15:54:48.947256   59701 scheduling_queue.go:821] About to try and schedule pod default/bb-65fd577957-q2jcl
I0125 15:54:48.947263   59701 scheduler.go:451] Attempting to schedule pod: default/bb-65fd577957-q2jcl
I0125 15:54:48.947288   59701 scheduler_binder.go:173] FindPodVolumes for pod "default/bb-65fd577957-q2jcl", node "127.0.0.1"
I0125 15:54:48.947298   59701 scheduler_binder.go:571] PVC "default/pvc-vault-ro" is fully bound to PV "pv-vault-ro"
I0125 15:54:48.947302   59701 scheduler_binder.go:646] PersistentVolume "pv-vault-ro", Node "127.0.0.1" matches for Pod "default/bb-65fd577957-q2jcl"
I0125 15:54:48.947306   59701 scheduler_binder.go:649] All bound volumes for Pod "default/bb-65fd577957-q2jcl" match with Node "127.0.0.1"
I0125 15:54:48.947311   59701 predicates.go:1645] All PVCs found matches for pod default/bb-65fd577957-q2jcl, node "127.0.0.1"
I0125 15:54:48.947324   59701 scheduler_binder.go:256] AssumePodVolumes for pod "default/bb-65fd577957-q2jcl", node "127.0.0.1"
I0125 15:54:48.947329   59701 scheduler_binder.go:571] PVC "default/pvc-vault-ro" is fully bound to PV "pv-vault-ro"
I0125 15:54:48.947333   59701 scheduler_binder.go:266] AssumePodVolumes for pod "default/bb-65fd577957-q2jcl", node "127.0.0.1": all PVCs bound and nothing to do
I0125 15:54:48.947343   59701 scheduling_queue.go:821] About to try and schedule pod default/bb-65fd577957-q9p8j
I0125 15:54:48.947347   59701 scheduler.go:451] Attempting to schedule pod: default/bb-65fd577957-q9p8j
I0125 15:54:48.947371   59701 scheduler_binder.go:173] FindPodVolumes for pod "default/bb-65fd577957-q9p8j", node "127.0.0.1"
I0125 15:54:48.947381   59701 scheduler_binder.go:571] PVC "default/pvc-vault-ro" is fully bound to PV "pv-vault-ro"
I0125 15:54:48.947385   59701 scheduler_binder.go:646] PersistentVolume "pv-vault-ro", Node "127.0.0.1" matches for Pod "default/bb-65fd577957-q9p8j"
I0125 15:54:48.947389   59701 scheduler_binder.go:649] All bound volumes for Pod "default/bb-65fd577957-q9p8j" match with Node "127.0.0.1"
I0125 15:54:48.947394   59701 predicates.go:1645] All PVCs found matches for pod default/bb-65fd577957-q9p8j, node "127.0.0.1"
I0125 15:54:48.947406   59701 scheduler_binder.go:256] AssumePodVolumes for pod "default/bb-65fd577957-q9p8j", node "127.0.0.1"
I0125 15:54:48.947411   59701 scheduler_binder.go:571] PVC "default/pvc-vault-ro" is fully bound to PV "pv-vault-ro"
I0125 15:54:48.947415   59701 scheduler_binder.go:266] AssumePodVolumes for pod "default/bb-65fd577957-q9p8j", node "127.0.0.1": all PVCs bound and nothing to do
I0125 15:54:48.947426   59701 scheduling_queue.go:821] About to try and schedule pod default/bb-65fd577957-qfmf5
I0125 15:54:48.947429   59701 scheduler.go:451] Attempting to schedule pod: default/bb-65fd577957-qfmf5
I0125 15:54:48.947452   59701 scheduler_binder.go:173] FindPodVolumes for pod "default/bb-65fd577957-qfmf5", node "127.0.0.1"
I0125 15:54:48.947462   59701 scheduler_binder.go:571] PVC "default/pvc-vault-ro" is fully bound to PV "pv-vault-ro"
I0125 15:54:48.947467   59701 scheduler_binder.go:646] PersistentVolume "pv-vault-ro", Node "127.0.0.1" matches for Pod "default/bb-65fd577957-qfmf5"
I0125 15:54:48.947471   59701 scheduler_binder.go:649] All bound volumes for Pod "default/bb-65fd577957-qfmf5" match with Node "127.0.0.1"
I0125 15:54:48.947476   59701 predicates.go:1645] All PVCs found matches for pod default/bb-65fd577957-qfmf5, node "127.0.0.1"
I0125 15:54:48.947488   59701 scheduler_binder.go:256] AssumePodVolumes for pod "default/bb-65fd577957-qfmf5", node "127.0.0.1"
I0125 15:54:48.947493   59701 scheduler_binder.go:571] PVC "default/pvc-vault-ro" is fully bound to PV "pv-vault-ro"
I0125 15:54:48.947497   59701 scheduler_binder.go:266] AssumePodVolumes for pod "default/bb-65fd577957-qfmf5", node "127.0.0.1": all PVCs bound and nothing to do
I0125 15:54:48.947507   59701 scheduling_queue.go:821] About to try and schedule pod default/bb-65fd577957-c2cnl
I0125 15:54:48.947510   59701 scheduler.go:451] Attempting to schedule pod: default/bb-65fd577957-c2cnl
I0125 15:54:48.947535   59701 scheduler_binder.go:173] FindPodVolumes for pod "default/bb-65fd577957-c2cnl", node "127.0.0.1"
I0125 15:54:48.947547   59701 scheduler_binder.go:571] PVC "default/pvc-vault-ro" is fully bound to PV "pv-vault-ro"
I0125 15:54:48.947551   59701 scheduler_binder.go:646] PersistentVolume "pv-vault-ro", Node "127.0.0.1" matches for Pod "default/bb-65fd577957-c2cnl"
I0125 15:54:48.947555   59701 scheduler_binder.go:649] All bound volumes for Pod "default/bb-65fd577957-c2cnl" match with Node "127.0.0.1"
I0125 15:54:48.947560   59701 predicates.go:1645] All PVCs found matches for pod default/bb-65fd577957-c2cnl, node "127.0.0.1"
I0125 15:54:48.947572   59701 scheduler_binder.go:256] AssumePodVolumes for pod "default/bb-65fd577957-c2cnl", node "127.0.0.1"
I0125 15:54:48.947577   59701 scheduler_binder.go:571] PVC "default/pvc-vault-ro" is fully bound to PV "pv-vault-ro"
I0125 15:54:48.947581   59701 scheduler_binder.go:266] AssumePodVolumes for pod "default/bb-65fd577957-c2cnl", node "127.0.0.1": all PVCs bound and nothing to do
I0125 15:54:48.947590   59701 scheduling_queue.go:821] About to try and schedule pod default/bb-65fd577957-2lj99
I0125 15:54:48.947593   59701 scheduler.go:451] Attempting to schedule pod: default/bb-65fd577957-2lj99
I0125 15:54:48.947617   59701 scheduler_binder.go:173] FindPodVolumes for pod "default/bb-65fd577957-2lj99", node "127.0.0.1"
I0125 15:54:48.947626   59701 scheduler_binder.go:571] PVC "default/pvc-vault-ro" is fully bound to PV "pv-vault-ro"
I0125 15:54:48.947631   59701 scheduler_binder.go:646] PersistentVolume "pv-vault-ro", Node "127.0.0.1" matches for Pod "default/bb-65fd577957-2lj99"
I0125 15:54:48.947635   59701 scheduler_binder.go:649] All bound volumes for Pod "default/bb-65fd577957-2lj99" match with Node "127.0.0.1"
I0125 15:54:48.947640   59701 predicates.go:1645] All PVCs found matches for pod default/bb-65fd577957-2lj99, node "127.0.0.1"
I0125 15:54:48.947653   59701 scheduler_binder.go:256] AssumePodVolumes for pod "default/bb-65fd577957-2lj99", node "127.0.0.1"
I0125 15:54:48.947658   59701 scheduler_binder.go:571] PVC "default/pvc-vault-ro" is fully bound to PV "pv-vault-ro"
I0125 15:54:48.947662   59701 scheduler_binder.go:266] AssumePodVolumes for pod "default/bb-65fd577957-2lj99", node "127.0.0.1": all PVCs bound and nothing to do
I0125 15:54:48.947671   59701 scheduling_queue.go:821] About to try and schedule pod default/bb-65fd577957-gtvtl
I0125 15:54:48.947675   59701 scheduler.go:451] Attempting to schedule pod: default/bb-65fd577957-gtvtl
I0125 15:54:48.947699   59701 scheduler_binder.go:173] FindPodVolumes for pod "default/bb-65fd577957-gtvtl", node "127.0.0.1"
I0125 15:54:48.947708   59701 scheduler_binder.go:571] PVC "default/pvc-vault-ro" is fully bound to PV "pv-vault-ro"
I0125 15:54:48.947712   59701 scheduler_binder.go:646] PersistentVolume "pv-vault-ro", Node "127.0.0.1" matches for Pod "default/bb-65fd577957-gtvtl"
I0125 15:54:48.947716   59701 scheduler_binder.go:649] All bound volumes for Pod "default/bb-65fd577957-gtvtl" match with Node "127.0.0.1"
I0125 15:54:48.947721   59701 predicates.go:1645] All PVCs found matches for pod default/bb-65fd577957-gtvtl, node "127.0.0.1"
I0125 15:54:48.947732   59701 scheduler_binder.go:256] AssumePodVolumes for pod "default/bb-65fd577957-gtvtl", node "127.0.0.1"
I0125 15:54:48.947738   59701 scheduler_binder.go:571] PVC "default/pvc-vault-ro" is fully bound to PV "pv-vault-ro"
I0125 15:54:48.947742   59701 scheduler_binder.go:266] AssumePodVolumes for pod "default/bb-65fd577957-gtvtl", node "127.0.0.1": all PVCs bound and nothing to do
I0125 15:54:48.947753   59701 scheduling_queue.go:821] About to try and schedule pod default/bb-65fd577957-knpvn
I0125 15:54:48.947757   59701 scheduler.go:451] Attempting to schedule pod: default/bb-65fd577957-knpvn
I0125 15:54:48.947780   59701 scheduler_binder.go:173] FindPodVolumes for pod "default/bb-65fd577957-knpvn", node "127.0.0.1"
I0125 15:54:48.947790   59701 scheduler_binder.go:571] PVC "default/pvc-vault-ro" is fully bound to PV "pv-vault-ro"
I0125 15:54:48.947794   59701 scheduler_binder.go:646] PersistentVolume "pv-vault-ro", Node "127.0.0.1" matches for Pod "default/bb-65fd577957-knpvn"
I0125 15:54:48.947801   59701 scheduler_binder.go:649] All bound volumes for Pod "default/bb-65fd577957-knpvn" match with Node "127.0.0.1"
I0125 15:54:48.947806   59701 predicates.go:1645] All PVCs found matches for pod default/bb-65fd577957-knpvn, node "127.0.0.1"
I0125 15:54:48.947817   59701 scheduler_binder.go:256] AssumePodVolumes for pod "default/bb-65fd577957-knpvn", node "127.0.0.1"
I0125 15:54:48.947821   59701 scheduler_binder.go:571] PVC "default/pvc-vault-ro" is fully bound to PV "pv-vault-ro"
I0125 15:54:48.947826   59701 scheduler_binder.go:266] AssumePodVolumes for pod "default/bb-65fd577957-knpvn", node "127.0.0.1": all PVCs bound and nothing to do
I0125 15:54:48.947836   59701 scheduling_queue.go:821] About to try and schedule pod default/bb-65fd577957-9kqpw
I0125 15:54:48.947839   59701 scheduler.go:451] Attempting to schedule pod: default/bb-65fd577957-9kqpw
I0125 15:54:48.947864   59701 scheduler_binder.go:173] FindPodVolumes for pod "default/bb-65fd577957-9kqpw", node "127.0.0.1"
I0125 15:54:48.947873   59701 scheduler_binder.go:571] PVC "default/pvc-vault-ro" is fully bound to PV "pv-vault-ro"
I0125 15:54:48.947877   59701 scheduler_binder.go:646] PersistentVolume "pv-vault-ro", Node "127.0.0.1" matches for Pod "default/bb-65fd577957-9kqpw"
I0125 15:54:48.947881   59701 scheduler_binder.go:649] All bound volumes for Pod "default/bb-65fd577957-9kqpw" match with Node "127.0.0.1"
I0125 15:54:48.947887   59701 predicates.go:1645] All PVCs found matches for pod default/bb-65fd577957-9kqpw, node "127.0.0.1"
I0125 15:54:48.947943   59701 scheduler_binder.go:256] AssumePodVolumes for pod "default/bb-65fd577957-9kqpw", node "127.0.0.1"
I0125 15:54:48.947953   59701 scheduler_binder.go:571] PVC "default/pvc-vault-ro" is fully bound to PV "pv-vault-ro"
I0125 15:54:48.947958   59701 scheduler_binder.go:266] AssumePodVolumes for pod "default/bb-65fd577957-9kqpw", node "127.0.0.1": all PVCs bound and nothing to do
I0125 15:54:48.947972   59701 scheduling_queue.go:821] About to try and schedule pod default/bb-65fd577957-8npmd
I0125 15:54:48.947976   59701 scheduler.go:451] Attempting to schedule pod: default/bb-65fd577957-8npmd
I0125 15:54:48.948006   59701 scheduler_binder.go:173] FindPodVolumes for pod "default/bb-65fd577957-8npmd", node "127.0.0.1"
I0125 15:54:48.948016   59701 scheduler_binder.go:571] PVC "default/pvc-vault-ro" is fully bound to PV "pv-vault-ro"
I0125 15:54:48.948021   59701 scheduler_binder.go:646] PersistentVolume "pv-vault-ro", Node "127.0.0.1" matches for Pod "default/bb-65fd577957-8npmd"
I0125 15:54:48.948025   59701 scheduler_binder.go:649] All bound volumes for Pod "default/bb-65fd577957-8npmd" match with Node "127.0.0.1"
I0125 15:54:48.948031   59701 predicates.go:1645] All PVCs found matches for pod default/bb-65fd577957-8npmd, node "127.0.0.1"
I0125 15:54:48.948045   59701 scheduler_binder.go:256] AssumePodVolumes for pod "default/bb-65fd577957-8npmd", node "127.0.0.1"
I0125 15:54:48.948050   59701 scheduler_binder.go:571] PVC "default/pvc-vault-ro" is fully bound to PV "pv-vault-ro"
I0125 15:54:48.948054   59701 scheduler_binder.go:266] AssumePodVolumes for pod "default/bb-65fd577957-8npmd", node "127.0.0.1": all PVCs bound and nothing to do
I0125 15:54:48.948064   59701 scheduling_queue.go:821] About to try and schedule pod default/bb-65fd577957-92x9g
I0125 15:54:48.948068   59701 scheduler.go:451] Attempting to schedule pod: default/bb-65fd577957-92x9g
I0125 15:54:48.948090   59701 scheduler_binder.go:173] FindPodVolumes for pod "default/bb-65fd577957-92x9g", node "127.0.0.1"
I0125 15:54:48.948101   59701 scheduler_binder.go:571] PVC "default/pvc-vault-ro" is fully bound to PV "pv-vault-ro"
I0125 15:54:48.948105   59701 scheduler_binder.go:646] PersistentVolume "pv-vault-ro", Node "127.0.0.1" matches for Pod "default/bb-65fd577957-92x9g"
I0125 15:54:48.948109   59701 scheduler_binder.go:649] All bound volumes for Pod "default/bb-65fd577957-92x9g" match with Node "127.0.0.1"
I0125 15:54:48.948114   59701 predicates.go:1645] All PVCs found matches for pod default/bb-65fd577957-92x9g, node "127.0.0.1"
I0125 15:54:48.948137   59701 scheduler_binder.go:256] AssumePodVolumes for pod "default/bb-65fd577957-92x9g", node "127.0.0.1"
I0125 15:54:48.948142   59701 scheduler_binder.go:571] PVC "default/pvc-vault-ro" is fully bound to PV "pv-vault-ro"
I0125 15:54:48.948146   59701 scheduler_binder.go:266] AssumePodVolumes for pod "default/bb-65fd577957-92x9g", node "127.0.0.1": all PVCs bound and nothing to do
I0125 15:54:48.948156   59701 scheduling_queue.go:821] About to try and schedule pod default/bb-65fd577957-rd7w2
I0125 15:54:48.948160   59701 scheduler.go:451] Attempting to schedule pod: default/bb-65fd577957-rd7w2
I0125 15:54:48.948183   59701 scheduler_binder.go:173] FindPodVolumes for pod "default/bb-65fd577957-rd7w2", node "127.0.0.1"
I0125 15:54:48.948193   59701 scheduler_binder.go:571] PVC "default/pvc-vault-ro" is fully bound to PV "pv-vault-ro"
I0125 15:54:48.948197   59701 scheduler_binder.go:646] PersistentVolume "pv-vault-ro", Node "127.0.0.1" matches for Pod "default/bb-65fd577957-rd7w2"
I0125 15:54:48.948201   59701 scheduler_binder.go:649] All bound volumes for Pod "default/bb-65fd577957-rd7w2" match with Node "127.0.0.1"
I0125 15:54:48.948207   59701 predicates.go:1645] All PVCs found matches for pod default/bb-65fd577957-rd7w2, node "127.0.0.1"
I0125 15:54:48.948218   59701 scheduler_binder.go:256] AssumePodVolumes for pod "default/bb-65fd577957-rd7w2", node "127.0.0.1"
I0125 15:54:48.948222   59701 scheduler_binder.go:571] PVC "default/pvc-vault-ro" is fully bound to PV "pv-vault-ro"
I0125 15:54:48.948226   59701 scheduler_binder.go:266] AssumePodVolumes for pod "default/bb-65fd577957-rd7w2", node "127.0.0.1": all PVCs bound and nothing to do
I0125 15:54:48.948235   59701 scheduling_queue.go:821] About to try and schedule pod default/bb-65fd577957-7vs4j
I0125 15:54:48.948239   59701 scheduler.go:451] Attempting to schedule pod: default/bb-65fd577957-7vs4j
I0125 15:54:48.948274   59701 scheduler_binder.go:173] FindPodVolumes for pod "default/bb-65fd577957-7vs4j", node "127.0.0.1"
I0125 15:54:48.948284   59701 scheduler_binder.go:571] PVC "default/pvc-vault-ro" is fully bound to PV "pv-vault-ro"
I0125 15:54:48.948288   59701 scheduler_binder.go:646] PersistentVolume "pv-vault-ro", Node "127.0.0.1" matches for Pod "default/bb-65fd577957-7vs4j"
I0125 15:54:48.948292   59701 scheduler_binder.go:649] All bound volumes for Pod "default/bb-65fd577957-7vs4j" match with Node "127.0.0.1"
I0125 15:54:48.948297   59701 predicates.go:1645] All PVCs found matches for pod default/bb-65fd577957-7vs4j, node "127.0.0.1"
I0125 15:54:48.948308   59701 scheduler_binder.go:256] AssumePodVolumes for pod "default/bb-65fd577957-7vs4j", node "127.0.0.1"
I0125 15:54:48.948314   59701 scheduler_binder.go:571] PVC "default/pvc-vault-ro" is fully bound to PV "pv-vault-ro"
I0125 15:54:48.948332   59701 scheduler_binder.go:266] AssumePodVolumes for pod "default/bb-65fd577957-7vs4j", node "127.0.0.1": all PVCs bound and nothing to do
I0125 15:54:48.948344   59701 scheduling_queue.go:821] About to try and schedule pod default/bb-65fd577957-qfgh6
I0125 15:54:48.948348   59701 scheduler.go:451] Attempting to schedule pod: default/bb-65fd577957-qfgh6
I0125 15:54:48.948370   59701 scheduler_binder.go:173] FindPodVolumes for pod "default/bb-65fd577957-qfgh6", node "127.0.0.1"
I0125 15:54:48.948438   59701 scheduler_binder.go:571] PVC "default/pvc-vault-ro" is fully bound to PV "pv-vault-ro"
I0125 15:54:48.948444   59701 scheduler_binder.go:646] PersistentVolume "pv-vault-ro", Node "127.0.0.1" matches for Pod "default/bb-65fd577957-qfgh6"
I0125 15:54:48.948448   59701 scheduler_binder.go:649] All bound volumes for Pod "default/bb-65fd577957-qfgh6" match with Node "127.0.0.1"
I0125 15:54:48.948454   59701 predicates.go:1645] All PVCs found matches for pod default/bb-65fd577957-qfgh6, node "127.0.0.1"
I0125 15:54:48.948471   59701 scheduler_binder.go:256] AssumePodVolumes for pod "default/bb-65fd577957-qfgh6", node "127.0.0.1"
I0125 15:54:48.948476   59701 scheduler_binder.go:571] PVC "default/pvc-vault-ro" is fully bound to PV "pv-vault-ro"
I0125 15:54:48.948484   59701 scheduler_binder.go:266] AssumePodVolumes for pod "default/bb-65fd577957-qfgh6", node "127.0.0.1": all PVCs bound and nothing to do
I0125 15:54:48.948500   59701 scheduling_queue.go:821] About to try and schedule pod default/bb-65fd577957-l5g6b
I0125 15:54:48.948503   59701 scheduler.go:451] Attempting to schedule pod: default/bb-65fd577957-l5g6b
I0125 15:54:48.948532   59701 scheduler_binder.go:173] FindPodVolumes for pod "default/bb-65fd577957-l5g6b", node "127.0.0.1"
I0125 15:54:48.948542   59701 scheduler_binder.go:571] PVC "default/pvc-vault-ro" is fully bound to PV "pv-vault-ro"
I0125 15:54:48.948546   59701 scheduler_binder.go:646] PersistentVolume "pv-vault-ro", Node "127.0.0.1" matches for Pod "default/bb-65fd577957-l5g6b"
I0125 15:54:48.948550   59701 scheduler_binder.go:649] All bound volumes for Pod "default/bb-65fd577957-l5g6b" match with Node "127.0.0.1"
I0125 15:54:48.948555   59701 predicates.go:1645] All PVCs found matches for pod default/bb-65fd577957-l5g6b, node "127.0.0.1"
I0125 15:54:48.948567   59701 scheduler_binder.go:256] AssumePodVolumes for pod "default/bb-65fd577957-l5g6b", node "127.0.0.1"
I0125 15:54:48.948572   59701 scheduler_binder.go:571] PVC "default/pvc-vault-ro" is fully bound to PV "pv-vault-ro"
I0125 15:54:48.948576   59701 scheduler_binder.go:266] AssumePodVolumes for pod "default/bb-65fd577957-l5g6b", node "127.0.0.1": all PVCs bound and nothing to do
I0125 15:54:48.948586   59701 scheduling_queue.go:821] About to try and schedule pod default/bb-65fd577957-b6xmp
I0125 15:54:48.948590   59701 scheduler.go:451] Attempting to schedule pod: default/bb-65fd577957-b6xmp
I0125 15:54:48.948613   59701 scheduler_binder.go:173] FindPodVolumes for pod "default/bb-65fd577957-b6xmp", node "127.0.0.1"
I0125 15:54:48.948622   59701 scheduler_binder.go:571] PVC "default/pvc-vault-ro" is fully bound to PV "pv-vault-ro"
I0125 15:54:48.948626   59701 scheduler_binder.go:646] PersistentVolume "pv-vault-ro", Node "127.0.0.1" matches for Pod "default/bb-65fd577957-b6xmp"
I0125 15:54:48.948630   59701 scheduler_binder.go:649] All bound volumes for Pod "default/bb-65fd577957-b6xmp" match with Node "127.0.0.1"
I0125 15:54:48.948635   59701 predicates.go:1645] All PVCs found matches for pod default/bb-65fd577957-b6xmp, node "127.0.0.1"
I0125 15:54:48.948647   59701 scheduler_binder.go:256] AssumePodVolumes for pod "default/bb-65fd577957-b6xmp", node "127.0.0.1"
I0125 15:54:48.948652   59701 scheduler_binder.go:571] PVC "default/pvc-vault-ro" is fully bound to PV "pv-vault-ro"
I0125 15:54:48.948656   59701 scheduler_binder.go:266] AssumePodVolumes for pod "default/bb-65fd577957-b6xmp", node "127.0.0.1": all PVCs bound and nothing to do
I0125 15:54:48.948665   59701 scheduling_queue.go:821] About to try and schedule pod default/bb-65fd577957-t77cf
I0125 15:54:48.948668   59701 scheduler.go:451] Attempting to schedule pod: default/bb-65fd577957-t77cf
I0125 15:54:48.948690   59701 scheduler_binder.go:173] FindPodVolumes for pod "default/bb-65fd577957-t77cf", node "127.0.0.1"
I0125 15:54:48.948699   59701 scheduler_binder.go:571] PVC "default/pvc-vault-ro" is fully bound to PV "pv-vault-ro"
I0125 15:54:48.948703   59701 scheduler_binder.go:646] PersistentVolume "pv-vault-ro", Node "127.0.0.1" matches for Pod "default/bb-65fd577957-t77cf"
I0125 15:54:48.948707   59701 scheduler_binder.go:649] All bound volumes for Pod "default/bb-65fd577957-t77cf" match with Node "127.0.0.1"
I0125 15:54:48.948712   59701 predicates.go:1645] All PVCs found matches for pod default/bb-65fd577957-t77cf, node "127.0.0.1"
I0125 15:54:48.948722   59701 scheduler_binder.go:256] AssumePodVolumes for pod "default/bb-65fd577957-t77cf", node "127.0.0.1"
I0125 15:54:48.948727   59701 scheduler_binder.go:571] PVC "default/pvc-vault-ro" is fully bound to PV "pv-vault-ro"
I0125 15:54:48.948731   59701 scheduler_binder.go:266] AssumePodVolumes for pod "default/bb-65fd577957-t77cf", node "127.0.0.1": all PVCs bound and nothing to do
I0125 15:54:48.948741   59701 scheduling_queue.go:821] About to try and schedule pod default/bb-65fd577957-7mdpb
I0125 15:54:48.948745   59701 scheduler.go:451] Attempting to schedule pod: default/bb-65fd577957-7mdpb
I0125 15:54:48.948767   59701 scheduler_binder.go:173] FindPodVolumes for pod "default/bb-65fd577957-7mdpb", node "127.0.0.1"
I0125 15:54:48.948776   59701 scheduler_binder.go:571] PVC "default/pvc-vault-ro" is fully bound to PV "pv-vault-ro"
I0125 15:54:48.948780   59701 scheduler_binder.go:646] PersistentVolume "pv-vault-ro", Node "127.0.0.1" matches for Pod "default/bb-65fd577957-7mdpb"
I0125 15:54:48.948784   59701 scheduler_binder.go:649] All bound volumes for Pod "default/bb-65fd577957-7mdpb" match with Node "127.0.0.1"
I0125 15:54:48.948789   59701 predicates.go:1645] All PVCs found matches for pod default/bb-65fd577957-7mdpb, node "127.0.0.1"
I0125 15:54:48.948800   59701 scheduler_binder.go:256] AssumePodVolumes for pod "default/bb-65fd577957-7mdpb", node "127.0.0.1"
I0125 15:54:48.948804   59701 scheduler_binder.go:571] PVC "default/pvc-vault-ro" is fully bound to PV "pv-vault-ro"
I0125 15:54:48.948808   59701 scheduler_binder.go:266] AssumePodVolumes for pod "default/bb-65fd577957-7mdpb", node "127.0.0.1": all PVCs bound and nothing to do
I0125 15:54:48.948816   59701 scheduling_queue.go:821] About to try and schedule pod default/bb-65fd577957-6bjzp
I0125 15:54:48.948820   59701 scheduler.go:451] Attempting to schedule pod: default/bb-65fd577957-6bjzp
I0125 15:54:48.948841   59701 scheduler_binder.go:173] FindPodVolumes for pod "default/bb-65fd577957-6bjzp", node "127.0.0.1"
I0125 15:54:48.948850   59701 scheduler_binder.go:571] PVC "default/pvc-vault-ro" is fully bound to PV "pv-vault-ro"
I0125 15:54:48.948854   59701 scheduler_binder.go:646] PersistentVolume "pv-vault-ro", Node "127.0.0.1" matches for Pod "default/bb-65fd577957-6bjzp"
I0125 15:54:48.948859   59701 scheduler_binder.go:649] All bound volumes for Pod "default/bb-65fd577957-6bjzp" match with Node "127.0.0.1"
I0125 15:54:48.948864   59701 predicates.go:1645] All PVCs found matches for pod default/bb-65fd577957-6bjzp, node "127.0.0.1"
I0125 15:54:48.948874   59701 scheduler_binder.go:256] AssumePodVolumes for pod "default/bb-65fd577957-6bjzp", node "127.0.0.1"
I0125 15:54:48.948878   59701 scheduler_binder.go:571] PVC "default/pvc-vault-ro" is fully bound to PV "pv-vault-ro"
I0125 15:54:48.948882   59701 scheduler_binder.go:266] AssumePodVolumes for pod "default/bb-65fd577957-6bjzp", node "127.0.0.1": all PVCs bound and nothing to do
I0125 15:54:48.948892   59701 scheduling_queue.go:821] About to try and schedule pod default/bb-65fd577957-qhw28
I0125 15:54:48.948896   59701 scheduler.go:451] Attempting to schedule pod: default/bb-65fd577957-qhw28
I0125 15:54:48.948918   59701 scheduler_binder.go:173] FindPodVolumes for pod "default/bb-65fd577957-qhw28", node "127.0.0.1"
I0125 15:54:48.948927   59701 scheduler_binder.go:571] PVC "default/pvc-vault-ro" is fully bound to PV "pv-vault-ro"
I0125 15:54:48.948931   59701 scheduler_binder.go:646] PersistentVolume "pv-vault-ro", Node "127.0.0.1" matches for Pod "default/bb-65fd577957-qhw28"
I0125 15:54:48.948935   59701 scheduler_binder.go:649] All bound volumes for Pod "default/bb-65fd577957-qhw28" match with Node "127.0.0.1"
I0125 15:54:48.948940   59701 predicates.go:1645] All PVCs found matches for pod default/bb-65fd577957-qhw28, node "127.0.0.1"
I0125 15:54:48.948953   59701 scheduler_binder.go:256] AssumePodVolumes for pod "default/bb-65fd577957-qhw28", node "127.0.0.1"
I0125 15:54:48.948958   59701 scheduler_binder.go:571] PVC "default/pvc-vault-ro" is fully bound to PV "pv-vault-ro"
I0125 15:54:48.948962   59701 scheduler_binder.go:266] AssumePodVolumes for pod "default/bb-65fd577957-qhw28", node "127.0.0.1": all PVCs bound and nothing to do
I0125 15:54:48.948971   59701 scheduling_queue.go:821] About to try and schedule pod default/bb-65fd577957-tg5wt
I0125 15:54:48.948974   59701 scheduler.go:451] Attempting to schedule pod: default/bb-65fd577957-tg5wt
I0125 15:54:48.948996   59701 scheduler_binder.go:173] FindPodVolumes for pod "default/bb-65fd577957-tg5wt", node "127.0.0.1"
I0125 15:54:48.949008   59701 scheduler_binder.go:571] PVC "default/pvc-vault-ro" is fully bound to PV "pv-vault-ro"
I0125 15:54:48.949012   59701 scheduler_binder.go:646] PersistentVolume "pv-vault-ro", Node "127.0.0.1" matches for Pod "default/bb-65fd577957-tg5wt"
I0125 15:54:48.949016   59701 scheduler_binder.go:649] All bound volumes for Pod "default/bb-65fd577957-tg5wt" match with Node "127.0.0.1"
I0125 15:54:48.949021   59701 predicates.go:1645] All PVCs found matches for pod default/bb-65fd577957-tg5wt, node "127.0.0.1"
I0125 15:54:48.949032   59701 scheduler_binder.go:256] AssumePodVolumes for pod "default/bb-65fd577957-tg5wt", node "127.0.0.1"
I0125 15:54:48.949037   59701 scheduler_binder.go:571] PVC "default/pvc-vault-ro" is fully bound to PV "pv-vault-ro"
I0125 15:54:48.949041   59701 scheduler_binder.go:266] AssumePodVolumes for pod "default/bb-65fd577957-tg5wt", node "127.0.0.1": all PVCs bound and nothing to do
I0125 15:54:48.949050   59701 scheduling_queue.go:821] About to try and schedule pod default/bb-65fd577957-k7xx6
I0125 15:54:48.949053   59701 scheduler.go:451] Attempting to schedule pod: default/bb-65fd577957-k7xx6
I0125 15:54:48.949077   59701 scheduler_binder.go:173] FindPodVolumes for pod "default/bb-65fd577957-k7xx6", node "127.0.0.1"
I0125 15:54:48.949086   59701 scheduler_binder.go:571] PVC "default/pvc-vault-ro" is fully bound to PV "pv-vault-ro"
I0125 15:54:48.949091   59701 scheduler_binder.go:646] PersistentVolume "pv-vault-ro", Node "127.0.0.1" matches for Pod "default/bb-65fd577957-k7xx6"
I0125 15:54:48.949094   59701 scheduler_binder.go:649] All bound volumes for Pod "default/bb-65fd577957-k7xx6" match with Node "127.0.0.1"
I0125 15:54:48.949099   59701 predicates.go:1645] All PVCs found matches for pod default/bb-65fd577957-k7xx6, node "127.0.0.1"
I0125 15:54:48.949111   59701 scheduler_binder.go:256] AssumePodVolumes for pod "default/bb-65fd577957-k7xx6", node "127.0.0.1"
I0125 15:54:48.949115   59701 scheduler_binder.go:571] PVC "default/pvc-vault-ro" is fully bound to PV "pv-vault-ro"
I0125 15:54:48.949119   59701 scheduler_binder.go:266] AssumePodVolumes for pod "default/bb-65fd577957-k7xx6", node "127.0.0.1": all PVCs bound and nothing to do
I0125 15:54:48.949128   59701 scheduling_queue.go:821] About to try and schedule pod default/bb-65fd577957-t9wcq
I0125 15:54:48.949132   59701 scheduler.go:451] Attempting to schedule pod: default/bb-65fd577957-t9wcq
I0125 15:54:48.949156   59701 scheduler_binder.go:173] FindPodVolumes for pod "default/bb-65fd577957-t9wcq", node "127.0.0.1"
I0125 15:54:48.949165   59701 scheduler_binder.go:571] PVC "default/pvc-vault-ro" is fully bound to PV "pv-vault-ro"
I0125 15:54:48.949169   59701 scheduler_binder.go:646] PersistentVolume "pv-vault-ro", Node "127.0.0.1" matches for Pod "default/bb-65fd577957-t9wcq"
I0125 15:54:48.949173   59701 scheduler_binder.go:649] All bound volumes for Pod "default/bb-65fd577957-t9wcq" match with Node "127.0.0.1"
I0125 15:54:48.949178   59701 predicates.go:1645] All PVCs found matches for pod default/bb-65fd577957-t9wcq, node "127.0.0.1"
I0125 15:54:48.949188   59701 scheduler_binder.go:256] AssumePodVolumes for pod "default/bb-65fd577957-t9wcq", node "127.0.0.1"
I0125 15:54:48.949193   59701 scheduler_binder.go:571] PVC "default/pvc-vault-ro" is fully bound to PV "pv-vault-ro"
I0125 15:54:48.949197   59701 scheduler_binder.go:266] AssumePodVolumes for pod "default/bb-65fd577957-t9wcq", node "127.0.0.1": all PVCs bound and nothing to do
I0125 15:54:48.949206   59701 scheduling_queue.go:821] About to try and schedule pod default/bb-65fd577957-cddxl
I0125 15:54:48.949210   59701 scheduler.go:451] Attempting to schedule pod: default/bb-65fd577957-cddxl
I0125 15:54:48.949232   59701 scheduler_binder.go:173] FindPodVolumes for pod "default/bb-65fd577957-cddxl", node "127.0.0.1"
I0125 15:54:48.949240   59701 scheduler_binder.go:571] PVC "default/pvc-vault-ro" is fully bound to PV "pv-vault-ro"
I0125 15:54:48.949245   59701 scheduler_binder.go:646] PersistentVolume "pv-vault-ro", Node "127.0.0.1" matches for Pod "default/bb-65fd577957-cddxl"
I0125 15:54:48.949251   59701 scheduler_binder.go:649] All bound volumes for Pod "default/bb-65fd577957-cddxl" match with Node "127.0.0.1"
I0125 15:54:48.949257   59701 predicates.go:1645] All PVCs found matches for pod default/bb-65fd577957-cddxl, node "127.0.0.1"
I0125 15:54:48.949268   59701 scheduler_binder.go:256] AssumePodVolumes for pod "default/bb-65fd577957-cddxl", node "127.0.0.1"
I0125 15:54:48.949273   59701 scheduler_binder.go:571] PVC "default/pvc-vault-ro" is fully bound to PV "pv-vault-ro"
I0125 15:54:48.949277   59701 scheduler_binder.go:266] AssumePodVolumes for pod "default/bb-65fd577957-cddxl", node "127.0.0.1": all PVCs bound and nothing to do
I0125 15:54:48.949286   59701 scheduling_queue.go:821] About to try and schedule pod default/bb-65fd577957-z28hj
I0125 15:54:48.949290   59701 scheduler.go:451] Attempting to schedule pod: default/bb-65fd577957-z28hj
I0125 15:54:48.949313   59701 scheduler_binder.go:173] FindPodVolumes for pod "default/bb-65fd577957-z28hj", node "127.0.0.1"
I0125 15:54:48.949322   59701 scheduler_binder.go:571] PVC "default/pvc-vault-ro" is fully bound to PV "pv-vault-ro"
I0125 15:54:48.949326   59701 scheduler_binder.go:646] PersistentVolume "pv-vault-ro", Node "127.0.0.1" matches for Pod "default/bb-65fd577957-z28hj"
I0125 15:54:48.949330   59701 scheduler_binder.go:649] All bound volumes for Pod "default/bb-65fd577957-z28hj" match with Node "127.0.0.1"
I0125 15:54:48.949335   59701 predicates.go:1645] All PVCs found matches for pod default/bb-65fd577957-z28hj, node "127.0.0.1"
I0125 15:54:48.949347   59701 scheduler_binder.go:256] AssumePodVolumes for pod "default/bb-65fd577957-z28hj", node "127.0.0.1"
I0125 15:54:48.949351   59701 scheduler_binder.go:571] PVC "default/pvc-vault-ro" is fully bound to PV "pv-vault-ro"
I0125 15:54:48.949355   59701 scheduler_binder.go:266] AssumePodVolumes for pod "default/bb-65fd577957-z28hj", node "127.0.0.1": all PVCs bound and nothing to do
I0125 15:54:48.949364   59701 scheduling_queue.go:821] About to try and schedule pod default/bb-65fd577957-lvzk8
I0125 15:54:48.949368   59701 scheduler.go:451] Attempting to schedule pod: default/bb-65fd577957-lvzk8
I0125 15:54:48.949461   59701 scheduler_binder.go:173] FindPodVolumes for pod "default/bb-65fd577957-lvzk8", node "127.0.0.1"
I0125 15:54:48.949475   59701 scheduler_binder.go:571] PVC "default/pvc-vault-ro" is fully bound to PV "pv-vault-ro"
I0125 15:54:48.949480   59701 scheduler_binder.go:646] PersistentVolume "pv-vault-ro", Node "127.0.0.1" matches for Pod "default/bb-65fd577957-lvzk8"
I0125 15:54:48.949484   59701 scheduler_binder.go:649] All bound volumes for Pod "default/bb-65fd577957-lvzk8" match with Node "127.0.0.1"
I0125 15:54:48.949490   59701 predicates.go:1645] All PVCs found matches for pod default/bb-65fd577957-lvzk8, node "127.0.0.1"
I0125 15:54:48.949504   59701 scheduler_binder.go:256] AssumePodVolumes for pod "default/bb-65fd577957-lvzk8", node "127.0.0.1"
I0125 15:54:48.949508   59701 scheduler_binder.go:571] PVC "default/pvc-vault-ro" is fully bound to PV "pv-vault-ro"
I0125 15:54:48.949512   59701 scheduler_binder.go:266] AssumePodVolumes for pod "default/bb-65fd577957-lvzk8", node "127.0.0.1": all PVCs bound and nothing to do
I0125 15:54:48.949524   59701 scheduling_queue.go:821] About to try and schedule pod default/bb-65fd577957-vlvq5
I0125 15:54:48.949528   59701 scheduler.go:451] Attempting to schedule pod: default/bb-65fd577957-vlvq5
I0125 15:54:48.949552   59701 scheduler_binder.go:173] FindPodVolumes for pod "default/bb-65fd577957-vlvq5", node "127.0.0.1"
I0125 15:54:48.949561   59701 scheduler_binder.go:571] PVC "default/pvc-vault-ro" is fully bound to PV "pv-vault-ro"
I0125 15:54:48.949565   59701 scheduler_binder.go:646] PersistentVolume "pv-vault-ro", Node "127.0.0.1" matches for Pod "default/bb-65fd577957-vlvq5"
I0125 15:54:48.949568   59701 scheduler_binder.go:649] All bound volumes for Pod "default/bb-65fd577957-vlvq5" match with Node "127.0.0.1"
I0125 15:54:48.949576   59701 predicates.go:1645] All PVCs found matches for pod default/bb-65fd577957-vlvq5, node "127.0.0.1"
I0125 15:54:48.949588   59701 scheduler_binder.go:256] AssumePodVolumes for pod "default/bb-65fd577957-vlvq5", node "127.0.0.1"
I0125 15:54:48.949593   59701 scheduler_binder.go:571] PVC "default/pvc-vault-ro" is fully bound to PV "pv-vault-ro"
I0125 15:54:48.949597   59701 scheduler_binder.go:266] AssumePodVolumes for pod "default/bb-65fd577957-vlvq5", node "127.0.0.1": all PVCs bound and nothing to do
I0125 15:54:48.949606   59701 scheduling_queue.go:821] About to try and schedule pod default/bb-65fd577957-z458j
I0125 15:54:48.949609   59701 scheduler.go:451] Attempting to schedule pod: default/bb-65fd577957-z458j
I0125 15:54:48.949632   59701 scheduler_binder.go:173] FindPodVolumes for pod "default/bb-65fd577957-z458j", node "127.0.0.1"
I0125 15:54:48.949641   59701 scheduler_binder.go:571] PVC "default/pvc-vault-ro" is fully bound to PV "pv-vault-ro"
I0125 15:54:48.949645   59701 scheduler_binder.go:646] PersistentVolume "pv-vault-ro", Node "127.0.0.1" matches for Pod "default/bb-65fd577957-z458j"
I0125 15:54:48.949649   59701 scheduler_binder.go:649] All bound volumes for Pod "default/bb-65fd577957-z458j" match with Node "127.0.0.1"
I0125 15:54:48.949654   59701 predicates.go:1645] All PVCs found matches for pod default/bb-65fd577957-z458j, node "127.0.0.1"
I0125 15:54:48.949666   59701 scheduler_binder.go:256] AssumePodVolumes for pod "default/bb-65fd577957-z458j", node "127.0.0.1"
I0125 15:54:48.949670   59701 scheduler_binder.go:571] PVC "default/pvc-vault-ro" is fully bound to PV "pv-vault-ro"
I0125 15:54:48.949674   59701 scheduler_binder.go:266] AssumePodVolumes for pod "default/bb-65fd577957-z458j", node "127.0.0.1": all PVCs bound and nothing to do
I0125 15:54:48.949682   59701 scheduling_queue.go:821] About to try and schedule pod default/bb-65fd577957-vqdgt
I0125 15:54:48.949686   59701 scheduler.go:451] Attempting to schedule pod: default/bb-65fd577957-vqdgt
I0125 15:54:48.949710   59701 scheduler_binder.go:173] FindPodVolumes for pod "default/bb-65fd577957-vqdgt", node "127.0.0.1"
I0125 15:54:48.949719   59701 scheduler_binder.go:571] PVC "default/pvc-vault-ro" is fully bound to PV "pv-vault-ro"
I0125 15:54:48.949723   59701 scheduler_binder.go:646] PersistentVolume "pv-vault-ro", Node "127.0.0.1" matches for Pod "default/bb-65fd577957-vqdgt"
I0125 15:54:48.949727   59701 scheduler_binder.go:649] All bound volumes for Pod "default/bb-65fd577957-vqdgt" match with Node "127.0.0.1"
I0125 15:54:48.949734   59701 predicates.go:1645] All PVCs found matches for pod default/bb-65fd577957-vqdgt, node "127.0.0.1"
I0125 15:54:48.949745   59701 scheduler_binder.go:256] AssumePodVolumes for pod "default/bb-65fd577957-vqdgt", node "127.0.0.1"
I0125 15:54:48.949750   59701 scheduler_binder.go:571] PVC "default/pvc-vault-ro" is fully bound to PV "pv-vault-ro"
I0125 15:54:48.949754   59701 scheduler_binder.go:266] AssumePodVolumes for pod "default/bb-65fd577957-vqdgt", node "127.0.0.1": all PVCs bound and nothing to do
I0125 15:54:48.949763   59701 scheduling_queue.go:821] About to try and schedule pod default/bb-65fd577957-8tstx
I0125 15:54:48.949766   59701 scheduler.go:451] Attempting to schedule pod: default/bb-65fd577957-8tstx
I0125 15:54:48.949788   59701 scheduler_binder.go:173] FindPodVolumes for pod "default/bb-65fd577957-8tstx", node "127.0.0.1"
I0125 15:54:48.949797   59701 scheduler_binder.go:571] PVC "default/pvc-vault-ro" is fully bound to PV "pv-vault-ro"
I0125 15:54:48.949802   59701 scheduler_binder.go:646] PersistentVolume "pv-vault-ro", Node "127.0.0.1" matches for Pod "default/bb-65fd577957-8tstx"
I0125 15:54:48.949805   59701 scheduler_binder.go:649] All bound volumes for Pod "default/bb-65fd577957-8tstx" match with Node "127.0.0.1"
I0125 15:54:48.949810   59701 predicates.go:1645] All PVCs found matches for pod default/bb-65fd577957-8tstx, node "127.0.0.1"
I0125 15:54:48.949820   59701 scheduler_binder.go:256] AssumePodVolumes for pod "default/bb-65fd577957-8tstx", node "127.0.0.1"
I0125 15:54:48.949827   59701 scheduler_binder.go:571] PVC "default/pvc-vault-ro" is fully bound to PV "pv-vault-ro"
I0125 15:54:48.949831   59701 scheduler_binder.go:266] AssumePodVolumes for pod "default/bb-65fd577957-8tstx", node "127.0.0.1": all PVCs bound and nothing to do
I0125 15:54:48.949840   59701 scheduling_queue.go:821] About to try and schedule pod default/bb-65fd577957-xktdz
I0125 15:54:48.949844   59701 scheduler.go:451] Attempting to schedule pod: default/bb-65fd577957-xktdz
I0125 15:54:48.949868   59701 scheduler_binder.go:173] FindPodVolumes for pod "default/bb-65fd577957-xktdz", node "127.0.0.1"
I0125 15:54:48.949877   59701 scheduler_binder.go:571] PVC "default/pvc-vault-ro" is fully bound to PV "pv-vault-ro"
I0125 15:54:48.949882   59701 scheduler_binder.go:646] PersistentVolume "pv-vault-ro", Node "127.0.0.1" matches for Pod "default/bb-65fd577957-xktdz"
I0125 15:54:48.949886   59701 scheduler_binder.go:649] All bound volumes for Pod "default/bb-65fd577957-xktdz" match with Node "127.0.0.1"
I0125 15:54:48.949891   59701 predicates.go:1645] All PVCs found matches for pod default/bb-65fd577957-xktdz, node "127.0.0.1"
I0125 15:54:48.949902   59701 scheduler_binder.go:256] AssumePodVolumes for pod "default/bb-65fd577957-xktdz", node "127.0.0.1"
I0125 15:54:48.949907   59701 scheduler_binder.go:571] PVC "default/pvc-vault-ro" is fully bound to PV "pv-vault-ro"
I0125 15:54:48.949911   59701 scheduler_binder.go:266] AssumePodVolumes for pod "default/bb-65fd577957-xktdz", node "127.0.0.1": all PVCs bound and nothing to do
I0125 15:54:48.949920   59701 scheduling_queue.go:821] About to try and schedule pod default/bb-65fd577957-jm62w
I0125 15:54:48.949923   59701 scheduler.go:451] Attempting to schedule pod: default/bb-65fd577957-jm62w
I0125 15:54:48.949945   59701 scheduler_binder.go:173] FindPodVolumes for pod "default/bb-65fd577957-jm62w", node "127.0.0.1"
I0125 15:54:48.949954   59701 scheduler_binder.go:571] PVC "default/pvc-vault-ro" is fully bound to PV "pv-vault-ro"
I0125 15:54:48.949958   59701 scheduler_binder.go:646] PersistentVolume "pv-vault-ro", Node "127.0.0.1" matches for Pod "default/bb-65fd577957-jm62w"
I0125 15:54:48.949962   59701 scheduler_binder.go:649] All bound volumes for Pod "default/bb-65fd577957-jm62w" match with Node "127.0.0.1"
I0125 15:54:48.949967   59701 predicates.go:1645] All PVCs found matches for pod default/bb-65fd577957-jm62w, node "127.0.0.1"
I0125 15:54:48.949977   59701 scheduler_binder.go:256] AssumePodVolumes for pod "default/bb-65fd577957-jm62w", node "127.0.0.1"
I0125 15:54:48.949981   59701 scheduler_binder.go:571] PVC "default/pvc-vault-ro" is fully bound to PV "pv-vault-ro"
I0125 15:54:48.949986   59701 scheduler_binder.go:266] AssumePodVolumes for pod "default/bb-65fd577957-jm62w", node "127.0.0.1": all PVCs bound and nothing to do
I0125 15:54:48.949995   59701 scheduling_queue.go:821] About to try and schedule pod default/bb-65fd577957-6njf6
I0125 15:54:48.949998   59701 scheduler.go:451] Attempting to schedule pod: default/bb-65fd577957-6njf6
I0125 15:54:48.950019   59701 scheduler_binder.go:173] FindPodVolumes for pod "default/bb-65fd577957-6njf6", node "127.0.0.1"
I0125 15:54:48.950028   59701 scheduler_binder.go:571] PVC "default/pvc-vault-ro" is fully bound to PV "pv-vault-ro"
I0125 15:54:48.950033   59701 scheduler_binder.go:646] PersistentVolume "pv-vault-ro", Node "127.0.0.1" matches for Pod "default/bb-65fd577957-6njf6"
I0125 15:54:48.950036   59701 scheduler_binder.go:649] All bound volumes for Pod "default/bb-65fd577957-6njf6" match with Node "127.0.0.1"
I0125 15:54:48.950042   59701 predicates.go:1645] All PVCs found matches for pod default/bb-65fd577957-6njf6, node "127.0.0.1"
I0125 15:54:48.950053   59701 scheduler_binder.go:256] AssumePodVolumes for pod "default/bb-65fd577957-6njf6", node "127.0.0.1"
I0125 15:54:48.950058   59701 scheduler_binder.go:571] PVC "default/pvc-vault-ro" is fully bound to PV "pv-vault-ro"
I0125 15:54:48.950062   59701 scheduler_binder.go:266] AssumePodVolumes for pod "default/bb-65fd577957-6njf6", node "127.0.0.1": all PVCs bound and nothing to do
I0125 15:54:48.950072   59701 scheduling_queue.go:821] About to try and schedule pod default/bb-65fd577957-nbncn
I0125 15:54:48.950076   59701 scheduler.go:451] Attempting to schedule pod: default/bb-65fd577957-nbncn
I0125 15:54:48.950098   59701 scheduler_binder.go:173] FindPodVolumes for pod "default/bb-65fd577957-nbncn", node "127.0.0.1"
I0125 15:54:48.950107   59701 scheduler_binder.go:571] PVC "default/pvc-vault-ro" is fully bound to PV "pv-vault-ro"
I0125 15:54:48.950111   59701 scheduler_binder.go:646] PersistentVolume "pv-vault-ro", Node "127.0.0.1" matches for Pod "default/bb-65fd577957-nbncn"
I0125 15:54:48.950115   59701 scheduler_binder.go:649] All bound volumes for Pod "default/bb-65fd577957-nbncn" match with Node "127.0.0.1"
I0125 15:54:48.950120   59701 predicates.go:1645] All PVCs found matches for pod default/bb-65fd577957-nbncn, node "127.0.0.1"
I0125 15:54:48.950132   59701 scheduler_binder.go:256] AssumePodVolumes for pod "default/bb-65fd577957-nbncn", node "127.0.0.1"
I0125 15:54:48.950137   59701 scheduler_binder.go:571] PVC "default/pvc-vault-ro" is fully bound to PV "pv-vault-ro"
I0125 15:54:48.950141   59701 scheduler_binder.go:266] AssumePodVolumes for pod "default/bb-65fd577957-nbncn", node "127.0.0.1": all PVCs bound and nothing to do
I0125 15:54:48.950149   59701 scheduling_queue.go:821] About to try and schedule pod default/bb-65fd577957-dg54f
I0125 15:54:48.950152   59701 scheduler.go:451] Attempting to schedule pod: default/bb-65fd577957-dg54f
I0125 15:54:48.950175   59701 scheduler_binder.go:173] FindPodVolumes for pod "default/bb-65fd577957-dg54f", node "127.0.0.1"
I0125 15:54:48.950184   59701 scheduler_binder.go:571] PVC "default/pvc-vault-ro" is fully bound to PV "pv-vault-ro"
I0125 15:54:48.950188   59701 scheduler_binder.go:646] PersistentVolume "pv-vault-ro", Node "127.0.0.1" matches for Pod "default/bb-65fd577957-dg54f"
I0125 15:54:48.950192   59701 scheduler_binder.go:649] All bound volumes for Pod "default/bb-65fd577957-dg54f" match with Node "127.0.0.1"
I0125 15:54:48.950197   59701 predicates.go:1645] All PVCs found matches for pod default/bb-65fd577957-dg54f, node "127.0.0.1"
I0125 15:54:48.950208   59701 scheduler_binder.go:256] AssumePodVolumes for pod "default/bb-65fd577957-dg54f", node "127.0.0.1"
I0125 15:54:48.950212   59701 scheduler_binder.go:571] PVC "default/pvc-vault-ro" is fully bound to PV "pv-vault-ro"
I0125 15:54:48.950216   59701 scheduler_binder.go:266] AssumePodVolumes for pod "default/bb-65fd577957-dg54f", node "127.0.0.1": all PVCs bound and nothing to do
I0125 15:54:48.950224   59701 scheduling_queue.go:821] About to try and schedule pod default/bb-65fd577957-jtbpw
I0125 15:54:48.950227   59701 scheduler.go:451] Attempting to schedule pod: default/bb-65fd577957-jtbpw
I0125 15:54:48.950249   59701 scheduler_binder.go:173] FindPodVolumes for pod "default/bb-65fd577957-jtbpw", node "127.0.0.1"
I0125 15:54:48.950258   59701 scheduler_binder.go:571] PVC "default/pvc-vault-ro" is fully bound to PV "pv-vault-ro"
I0125 15:54:48.950262   59701 scheduler_binder.go:646] PersistentVolume "pv-vault-ro", Node "127.0.0.1" matches for Pod "default/bb-65fd577957-jtbpw"
I0125 15:54:48.950266   59701 scheduler_binder.go:649] All bound volumes for Pod "default/bb-65fd577957-jtbpw" match with Node "127.0.0.1"
I0125 15:54:48.950271   59701 predicates.go:1645] All PVCs found matches for pod default/bb-65fd577957-jtbpw, node "127.0.0.1"
I0125 15:54:48.950280   59701 scheduler_binder.go:256] AssumePodVolumes for pod "default/bb-65fd577957-jtbpw", node "127.0.0.1"
I0125 15:54:48.950285   59701 scheduler_binder.go:571] PVC "default/pvc-vault-ro" is fully bound to PV "pv-vault-ro"
I0125 15:54:48.950289   59701 scheduler_binder.go:266] AssumePodVolumes for pod "default/bb-65fd577957-jtbpw", node "127.0.0.1": all PVCs bound and nothing to do
I0125 15:54:48.950380   59701 backoff_utils.go:79] Backing off 2s
I0125 15:54:48.950606   59701 factory.go:1161] Attempting to bind bb-65fd577957-l8c52 to 127.0.0.1
I0125 15:54:48.950737   59701 factory.go:1161] Attempting to bind bb-65fd577957-l9llg to 127.0.0.1
I0125 15:54:48.950817   59701 factory.go:1161] Attempting to bind bb-65fd577957-g85fs to 127.0.0.1
I0125 15:54:48.950888   59701 factory.go:1161] Attempting to bind bb-65fd577957-qhg7m to 127.0.0.1
I0125 15:54:48.950948   59701 factory.go:1161] Attempting to bind bb-65fd577957-gqwk5 to 127.0.0.1
I0125 15:54:48.951001   59701 factory.go:1161] Attempting to bind bb-65fd577957-ndj6t to 127.0.0.1
I0125 15:54:48.951050   59701 factory.go:1161] Attempting to bind bb-65fd577957-5hmdw to 127.0.0.1
I0125 15:54:48.951070   59701 factory.go:1161] Attempting to bind bb-65fd577957-b6xmp to 127.0.0.1
I0125 15:54:48.951111   59701 factory.go:1161] Attempting to bind bb-65fd577957-t77cf to 127.0.0.1
I0125 15:54:48.951141   59701 factory.go:1161] Attempting to bind bb-65fd577957-7mdpb to 127.0.0.1
I0125 15:54:48.951164   59701 factory.go:1161] Attempting to bind bb-65fd577957-6bjzp to 127.0.0.1
I0125 15:54:48.951186   59701 factory.go:1161] Attempting to bind bb-65fd577957-qhw28 to 127.0.0.1
I0125 15:54:48.951198   59701 factory.go:1161] Attempting to bind bb-65fd577957-btnr8 to 127.0.0.1
I0125 15:54:48.951210   59701 factory.go:1161] Attempting to bind bb-65fd577957-tg5wt to 127.0.0.1
I0125 15:54:48.951234   59701 factory.go:1161] Attempting to bind bb-65fd577957-k7xx6 to 127.0.0.1
I0125 15:54:48.951236   59701 factory.go:1161] Attempting to bind bb-65fd577957-xhgt7 to 127.0.0.1
I0125 15:54:48.951258   59701 factory.go:1161] Attempting to bind bb-65fd577957-t9wcq to 127.0.0.1
I0125 15:54:48.951265   59701 factory.go:1161] Attempting to bind bb-65fd577957-s8f8k to 127.0.0.1
I0125 15:54:48.951281   59701 factory.go:1161] Attempting to bind bb-65fd577957-cddxl to 127.0.0.1
I0125 15:54:48.951294   59701 factory.go:1161] Attempting to bind bb-65fd577957-29tb5 to 127.0.0.1
I0125 15:54:48.951304   59701 factory.go:1161] Attempting to bind bb-65fd577957-z28hj to 127.0.0.1
I0125 15:54:48.951318   59701 factory.go:1161] Attempting to bind bb-65fd577957-dzqkl to 127.0.0.1
I0125 15:54:48.951328   59701 factory.go:1161] Attempting to bind bb-65fd577957-lvzk8 to 127.0.0.1
I0125 15:54:48.951343   59701 factory.go:1161] Attempting to bind bb-65fd577957-ph2ct to 127.0.0.1
I0125 15:54:48.951351   59701 factory.go:1161] Attempting to bind bb-65fd577957-vlvq5 to 127.0.0.1
I0125 15:54:48.951367   59701 factory.go:1161] Attempting to bind bb-65fd577957-jflrz to 127.0.0.1
I0125 15:54:48.951375   59701 factory.go:1161] Attempting to bind bb-65fd577957-z458j to 127.0.0.1
I0125 15:54:48.951392   59701 factory.go:1161] Attempting to bind bb-65fd577957-q2jcl to 127.0.0.1
I0125 15:54:48.951399   59701 factory.go:1161] Attempting to bind bb-65fd577957-vqdgt to 127.0.0.1
I0125 15:54:48.951415   59701 factory.go:1161] Attempting to bind bb-65fd577957-q9p8j to 127.0.0.1
I0125 15:54:48.951421   59701 factory.go:1161] Attempting to bind bb-65fd577957-8tstx to 127.0.0.1
I0125 15:54:48.951440   59701 factory.go:1161] Attempting to bind bb-65fd577957-qfmf5 to 127.0.0.1
I0125 15:54:48.951446   59701 factory.go:1161] Attempting to bind bb-65fd577957-xktdz to 127.0.0.1
I0125 15:54:48.951465   59701 factory.go:1161] Attempting to bind bb-65fd577957-c2cnl to 127.0.0.1
I0125 15:54:48.951469   59701 factory.go:1161] Attempting to bind bb-65fd577957-jm62w to 127.0.0.1
I0125 15:54:48.951488   59701 factory.go:1161] Attempting to bind bb-65fd577957-2lj99 to 127.0.0.1
I0125 15:54:48.951494   59701 factory.go:1161] Attempting to bind bb-65fd577957-6njf6 to 127.0.0.1
I0125 15:54:48.951510   59701 factory.go:1161] Attempting to bind bb-65fd577957-gtvtl to 127.0.0.1
I0125 15:54:48.951516   59701 factory.go:1161] Attempting to bind bb-65fd577957-nbncn to 127.0.0.1
I0125 15:54:48.951533   59701 factory.go:1161] Attempting to bind bb-65fd577957-knpvn to 127.0.0.1
I0125 15:54:48.951539   59701 factory.go:1161] Attempting to bind bb-65fd577957-dg54f to 127.0.0.1
I0125 15:54:48.951555   59701 factory.go:1161] Attempting to bind bb-65fd577957-9kqpw to 127.0.0.1
I0125 15:54:48.951561   59701 factory.go:1161] Attempting to bind bb-65fd577957-jtbpw to 127.0.0.1
I0125 15:54:48.951578   59701 factory.go:1161] Attempting to bind bb-65fd577957-8npmd to 127.0.0.1
I0125 15:54:48.951601   59701 factory.go:1161] Attempting to bind bb-65fd577957-92x9g to 127.0.0.1
I0125 15:54:48.951625   59701 factory.go:1161] Attempting to bind bb-65fd577957-rd7w2 to 127.0.0.1
I0125 15:54:48.951649   59701 factory.go:1161] Attempting to bind bb-65fd577957-7vs4j to 127.0.0.1
I0125 15:54:48.951665   59701 factory.go:1161] Attempting to bind bb-65fd577957-l5g6b to 127.0.0.1
I0125 15:54:48.951697   59701 factory.go:1161] Attempting to bind bb-65fd577957-qfgh6 to 127.0.0.1
I0125 15:54:48.954061   59701 cache.go:209] Finished binding for pod 77e42803-2076-11e9-b9a0-000c299a5e15. Can be expired.
I0125 15:54:48.954094   59701 scheduler.go:569] pod default/bb-65fd577957-qhg7m is bound successfully on node 127.0.0.1, 1 nodes evaluated, 1 nodes were found feasible
I0125 15:54:48.954469   59701 cache.go:209] Finished binding for pod 7818f12d-2076-11e9-b9a0-000c299a5e15. Can be expired.
I0125 15:54:48.954524   59701 scheduler.go:569] pod default/bb-65fd577957-gqwk5 is bound successfully on node 127.0.0.1, 1 nodes evaluated, 1 nodes were found feasible
I0125 15:54:48.954647   59701 cache.go:209] Finished binding for pod 77eb09be-2076-11e9-b9a0-000c299a5e15. Can be expired.
I0125 15:54:48.954672   59701 scheduler.go:569] pod default/bb-65fd577957-ndj6t is bound successfully on node 127.0.0.1, 1 nodes evaluated, 1 nodes were found feasible
I0125 15:54:48.956446   59701 cache.go:209] Finished binding for pod 77e42e04-2076-11e9-b9a0-000c299a5e15. Can be expired.
I0125 15:54:48.956477   59701 scheduler.go:569] pod default/bb-65fd577957-g85fs is bound successfully on node 127.0.0.1, 1 nodes evaluated, 1 nodes were found feasible
I0125 15:54:48.958364   59701 cache.go:209] Finished binding for pod 78a9d1a4-2076-11e9-b9a0-000c299a5e15. Can be expired.
I0125 15:54:48.958393   59701 scheduler.go:569] pod default/bb-65fd577957-tg5wt is bound successfully on node 127.0.0.1, 1 nodes evaluated, 1 nodes were found feasible
I0125 15:54:48.970491   59701 cache.go:209] Finished binding for pod 78374af8-2076-11e9-b9a0-000c299a5e15. Can be expired.
I0125 15:54:48.970509   59701 cache.go:209] Finished binding for pod 77f2b064-2076-11e9-b9a0-000c299a5e15. Can be expired.
I0125 15:54:48.970526   59701 scheduler.go:569] pod default/bb-65fd577957-l8c52 is bound successfully on node 127.0.0.1, 1 nodes evaluated, 1 nodes were found feasible
I0125 15:54:48.970536   59701 scheduler.go:569] pod default/bb-65fd577957-l9llg is bound successfully on node 127.0.0.1, 1 nodes evaluated, 1 nodes were found feasible
I0125 15:54:48.970810   59701 cache.go:209] Finished binding for pod 784e4522-2076-11e9-b9a0-000c299a5e15. Can be expired.
I0125 15:54:48.970810   59701 cache.go:209] Finished binding for pod 78022ac2-2076-11e9-b9a0-000c299a5e15. Can be expired.
I0125 15:54:48.970853   59701 cache.go:209] Finished binding for pod 77e5fada-2076-11e9-b9a0-000c299a5e15. Can be expired.
I0125 15:54:48.970832   59701 scheduler.go:569] pod default/bb-65fd577957-btnr8 is bound successfully on node 127.0.0.1, 1 nodes evaluated, 1 nodes were found feasible
I0125 15:54:48.970878   59701 scheduler.go:569] pod default/bb-65fd577957-5hmdw is bound successfully on node 127.0.0.1, 1 nodes evaluated, 1 nodes were found feasible
I0125 15:54:48.970853   59701 scheduler.go:569] pod default/bb-65fd577957-t77cf is bound successfully on node 127.0.0.1, 1 nodes evaluated, 1 nodes were found feasible
I0125 15:54:48.970952   59701 cache.go:209] Finished binding for pod 78b15fb9-2076-11e9-b9a0-000c299a5e15. Can be expired.
I0125 15:54:48.970972   59701 scheduler.go:569] pod default/bb-65fd577957-cddxl is bound successfully on node 127.0.0.1, 1 nodes evaluated, 1 nodes were found feasible
I0125 15:54:48.970980   59701 cache.go:209] Finished binding for pod 77e4b883-2076-11e9-b9a0-000c299a5e15. Can be expired.
I0125 15:54:48.970995   59701 cache.go:209] Finished binding for pod 7855d6fa-2076-11e9-b9a0-000c299a5e15. Can be expired.
I0125 15:54:48.971002   59701 scheduler.go:569] pod default/bb-65fd577957-c2cnl is bound successfully on node 127.0.0.1, 1 nodes evaluated, 1 nodes were found feasible
I0125 15:54:48.971005   59701 scheduler.go:569] pod default/bb-65fd577957-z458j is bound successfully on node 127.0.0.1, 1 nodes evaluated, 1 nodes were found feasible
I0125 15:54:48.970954   59701 cache.go:209] Finished binding for pod 7811447d-2076-11e9-b9a0-000c299a5e15. Can be expired.
I0125 15:54:48.971028   59701 scheduler.go:569] pod default/bb-65fd577957-jflrz is bound successfully on node 127.0.0.1, 1 nodes evaluated, 1 nodes were found feasible
I0125 15:54:48.971140   59701 cache.go:209] Finished binding for pod 77e42b16-2076-11e9-b9a0-000c299a5e15. Can be expired.
I0125 15:54:48.971157   59701 cache.go:209] Finished binding for pod 78b90972-2076-11e9-b9a0-000c299a5e15. Can be expired.
I0125 15:54:48.971175   59701 cache.go:209] Finished binding for pod 77e4aa04-2076-11e9-b9a0-000c299a5e15. Can be expired.
I0125 15:54:48.971181   59701 scheduler.go:569] pod default/bb-65fd577957-z28hj is bound successfully on node 127.0.0.1, 1 nodes evaluated, 1 nodes were found feasible
I0125 15:54:48.971191   59701 cache.go:209] Finished binding for pod 78a22082-2076-11e9-b9a0-000c299a5e15. Can be expired.
I0125 15:54:48.971200   59701 scheduler.go:569] pod default/bb-65fd577957-t9wcq is bound successfully on node 127.0.0.1, 1 nodes evaluated, 1 nodes were found feasible
I0125 15:54:48.971207   59701 cache.go:209] Finished binding for pod 77e4b2aa-2076-11e9-b9a0-000c299a5e15. Can be expired.
I0125 15:54:48.971219   59701 scheduler.go:569] pod default/bb-65fd577957-qfgh6 is bound successfully on node 127.0.0.1, 1 nodes evaluated, 1 nodes were found feasible
I0125 15:54:48.971160   59701 scheduler.go:569] pod default/bb-65fd577957-b6xmp is bound successfully on node 127.0.0.1, 1 nodes evaluated, 1 nodes were found feasible
I0125 15:54:48.971207   59701 scheduler.go:569] pod default/bb-65fd577957-k7xx6 is bound successfully on node 127.0.0.1, 1 nodes evaluated, 1 nodes were found feasible
I0125 15:54:48.971232   59701 cache.go:209] Finished binding for pod 786cc92c-2076-11e9-b9a0-000c299a5e15. Can be expired.
I0125 15:54:48.971248   59701 scheduler.go:569] pod default/bb-65fd577957-lvzk8 is bound successfully on node 127.0.0.1, 1 nodes evaluated, 1 nodes were found feasible
I0125 15:54:48.971310   59701 cache.go:209] Finished binding for pod 77e5e947-2076-11e9-b9a0-000c299a5e15. Can be expired.
I0125 15:54:48.971316   59701 cache.go:209] Finished binding for pod 78746da0-2076-11e9-b9a0-000c299a5e15. Can be expired.
I0125 15:54:48.971328   59701 scheduler.go:569] pod default/bb-65fd577957-l5g6b is bound successfully on node 127.0.0.1, 1 nodes evaluated, 1 nodes were found feasible
I0125 15:54:48.971334   59701 scheduler.go:569] pod default/bb-65fd577957-jm62w is bound successfully on node 127.0.0.1, 1 nodes evaluated, 1 nodes were found feasible
I0125 15:54:48.971351   59701 cache.go:209] Finished binding for pod 77e5fba9-2076-11e9-b9a0-000c299a5e15. Can be expired.
I0125 15:54:48.971359   59701 cache.go:209] Finished binding for pod 789abe08-2076-11e9-b9a0-000c299a5e15. Can be expired.
I0125 15:54:48.971365   59701 scheduler.go:569] pod default/bb-65fd577957-dzqkl is bound successfully on node 127.0.0.1, 1 nodes evaluated, 1 nodes were found feasible
I0125 15:54:48.971372   59701 cache.go:209] Finished binding for pod 77e58c6c-2076-11e9-b9a0-000c299a5e15. Can be expired.
I0125 15:54:48.971392   59701 cache.go:209] Finished binding for pod 77e5f71c-2076-11e9-b9a0-000c299a5e15. Can be expired.
I0125 15:54:48.971397   59701 cache.go:209] Finished binding for pod 78c09d1c-2076-11e9-b9a0-000c299a5e15. Can be expired.
I0125 15:54:48.971404   59701 scheduler.go:569] pod default/bb-65fd577957-xhgt7 is bound successfully on node 127.0.0.1, 1 nodes evaluated, 1 nodes were found feasible
I0125 15:54:48.971406   59701 scheduler.go:569] pod default/bb-65fd577957-gtvtl is bound successfully on node 127.0.0.1, 1 nodes evaluated, 1 nodes were found feasible
I0125 15:54:48.971373   59701 scheduler.go:569] pod default/bb-65fd577957-6bjzp is bound successfully on node 127.0.0.1, 1 nodes evaluated, 1 nodes were found feasible
I0125 15:54:48.971413   59701 scheduler.go:569] pod default/bb-65fd577957-vqdgt is bound successfully on node 127.0.0.1, 1 nodes evaluated, 1 nodes were found feasible
I0125 15:54:48.971429   59701 cache.go:209] Finished binding for pod 77e5f9e6-2076-11e9-b9a0-000c299a5e15. Can be expired.
I0125 15:54:48.971433   59701 cache.go:209] Finished binding for pod 77fa90f4-2076-11e9-b9a0-000c299a5e15. Can be expired.
I0125 15:54:48.971446   59701 scheduler.go:569] pod default/bb-65fd577957-q2jcl is bound successfully on node 127.0.0.1, 1 nodes evaluated, 1 nodes were found feasible
I0125 15:54:48.971447   59701 scheduler.go:569] pod default/bb-65fd577957-ph2ct is bound successfully on node 127.0.0.1, 1 nodes evaluated, 1 nodes were found feasible
I0125 15:54:48.971546   59701 cache.go:209] Finished binding for pod 77e351cd-2076-11e9-b9a0-000c299a5e15. Can be expired.
I0125 15:54:48.971585   59701 scheduler.go:569] pod default/bb-65fd577957-vlvq5 is bound successfully on node 127.0.0.1, 1 nodes evaluated, 1 nodes were found feasible
I0125 15:54:48.971614   59701 cache.go:209] Finished binding for pod 77e3c47b-2076-11e9-b9a0-000c299a5e15. Can be expired.
I0125 15:54:48.971625   59701 scheduler.go:569] pod default/bb-65fd577957-q9p8j is bound successfully on node 127.0.0.1, 1 nodes evaluated, 1 nodes were found feasible
I0125 15:54:48.971648   59701 cache.go:209] Finished binding for pod 787bf88f-2076-11e9-b9a0-000c299a5e15. Can be expired.
I0125 15:54:48.971657   59701 scheduler.go:569] pod default/bb-65fd577957-6njf6 is bound successfully on node 127.0.0.1, 1 nodes evaluated, 1 nodes were found feasible
I0125 15:54:48.971675   59701 cache.go:209] Finished binding for pod 77e49d84-2076-11e9-b9a0-000c299a5e15. Can be expired.
I0125 15:54:48.971683   59701 scheduler.go:569] pod default/bb-65fd577957-s8f8k is bound successfully on node 127.0.0.1, 1 nodes evaluated, 1 nodes were found feasible
I0125 15:54:48.971701   59701 cache.go:209] Finished binding for pod 77e4b22c-2076-11e9-b9a0-000c299a5e15. Can be expired.
I0125 15:54:48.971709   59701 scheduler.go:569] pod default/bb-65fd577957-2lj99 is bound successfully on node 127.0.0.1, 1 nodes evaluated, 1 nodes were found feasible
I0125 15:54:48.971750   59701 cache.go:209] Finished binding for pod 77e3c865-2076-11e9-b9a0-000c299a5e15. Can be expired.
I0125 15:54:48.971766   59701 scheduler.go:569] pod default/bb-65fd577957-29tb5 is bound successfully on node 127.0.0.1, 1 nodes evaluated, 1 nodes were found feasible
I0125 15:54:48.971782   59701 cache.go:209] Finished binding for pod 78931a71-2076-11e9-b9a0-000c299a5e15. Can be expired.
I0125 15:54:48.971790   59701 scheduler.go:569] pod default/bb-65fd577957-qhw28 is bound successfully on node 127.0.0.1, 1 nodes evaluated, 1 nodes were found feasible
I0125 15:54:48.971804   59701 cache.go:209] Finished binding for pod 788b442e-2076-11e9-b9a0-000c299a5e15. Can be expired.
I0125 15:54:48.971812   59701 scheduler.go:569] pod default/bb-65fd577957-8tstx is bound successfully on node 127.0.0.1, 1 nodes evaluated, 1 nodes were found feasible
I0125 15:54:48.971835   59701 cache.go:209] Finished binding for pod 78654018-2076-11e9-b9a0-000c299a5e15. Can be expired.
I0125 15:54:48.971844   59701 scheduler.go:569] pod default/bb-65fd577957-xktdz is bound successfully on node 127.0.0.1, 1 nodes evaluated, 1 nodes were found feasible
I0125 15:54:48.977309   59701 cache.go:209] Finished binding for pod 77e5ef3f-2076-11e9-b9a0-000c299a5e15. Can be expired.
I0125 15:54:48.977338   59701 scheduler.go:569] pod default/bb-65fd577957-jtbpw is bound successfully on node 127.0.0.1, 1 nodes evaluated, 1 nodes were found feasible
I0125 15:54:48.977365   59701 cache.go:209] Finished binding for pod 77e50ec0-2076-11e9-b9a0-000c299a5e15. Can be expired.
I0125 15:54:48.977375   59701 scheduler.go:569] pod default/bb-65fd577957-knpvn is bound successfully on node 127.0.0.1, 1 nodes evaluated, 1 nodes were found feasible
I0125 15:54:48.977429   59701 cache.go:209] Finished binding for pod 785d764e-2076-11e9-b9a0-000c299a5e15. Can be expired.
I0125 15:54:48.977453   59701 scheduler.go:569] pod default/bb-65fd577957-dg54f is bound successfully on node 127.0.0.1, 1 nodes evaluated, 1 nodes were found feasible
I0125 15:54:48.977620   59701 cache.go:209] Finished binding for pod 7809a310-2076-11e9-b9a0-000c299a5e15. Can be expired.
I0125 15:54:48.977636   59701 scheduler.go:569] pod default/bb-65fd577957-rd7w2 is bound successfully on node 127.0.0.1, 1 nodes evaluated, 1 nodes were found feasible
I0125 15:54:48.978229   59701 cache.go:209] Finished binding for pod 78838f7c-2076-11e9-b9a0-000c299a5e15. Can be expired.
I0125 15:54:48.978250   59701 scheduler.go:569] pod default/bb-65fd577957-nbncn is bound successfully on node 127.0.0.1, 1 nodes evaluated, 1 nodes were found feasible
I0125 15:54:48.978274   59701 cache.go:209] Finished binding for pod 7846aa77-2076-11e9-b9a0-000c299a5e15. Can be expired.
I0125 15:54:48.978284   59701 scheduler.go:569] pod default/bb-65fd577957-8npmd is bound successfully on node 127.0.0.1, 1 nodes evaluated, 1 nodes were found feasible
I0125 15:54:48.978298   59701 cache.go:209] Finished binding for pod 783ee6e2-2076-11e9-b9a0-000c299a5e15. Can be expired.
I0125 15:54:48.978307   59701 scheduler.go:569] pod default/bb-65fd577957-92x9g is bound successfully on node 127.0.0.1, 1 nodes evaluated, 1 nodes were found feasible
I0125 15:54:48.978354   59701 cache.go:209] Finished binding for pod 77e5f9c6-2076-11e9-b9a0-000c299a5e15. Can be expired.
I0125 15:54:48.978367   59701 scheduler.go:569] pod default/bb-65fd577957-9kqpw is bound successfully on node 127.0.0.1, 1 nodes evaluated, 1 nodes were found feasible
I0125 15:54:48.978526   59701 cache.go:209] Finished binding for pod 77e4a7e5-2076-11e9-b9a0-000c299a5e15. Can be expired.
I0125 15:54:48.978543   59701 scheduler.go:569] pod default/bb-65fd577957-7vs4j is bound successfully on node 127.0.0.1, 1 nodes evaluated, 1 nodes were found feasible
I0125 15:54:48.978560   59701 cache.go:209] Finished binding for pod 77e4289a-2076-11e9-b9a0-000c299a5e15. Can be expired.
I0125 15:54:48.978568   59701 scheduler.go:569] pod default/bb-65fd577957-qfmf5 is bound successfully on node 127.0.0.1, 1 nodes evaluated, 1 nodes were found feasible
I0125 15:54:48.978655   59701 cache.go:209] Finished binding for pod 7828110d-2076-11e9-b9a0-000c299a5e15. Can be expired.
I0125 15:54:48.978665   59701 scheduler.go:569] pod default/bb-65fd577957-7mdpb is bound successfully on node 127.0.0.1, 1 nodes evaluated, 1 nodes were found feasible
